Workbook
Name Average_emission_factor: '[1]Electricity emissions'!$H$38
Name BIDR: [2]Conversions!$E$76

Sheet About
A1: BASoBC BAU Amount Spent on Building Components
A2: Source:
A3: 1. BASoBC for US model | B3: Amount Spent on Components(Sheets:Commercial, Residential) | D3: Urban vs. Rural Residential Households
B4: Energy Information Administration | D4: Energy Information Administration
B5: 2015 | D5: 2013
B6: National Energy Modeling System 2015 Output Data | D6: Residential Energy Consumption Survey (RECS)
B7: Available upon request from EIA (no download link) | D7: http://www.eia.gov/consumption/residential/data/2009/
D8: Table HC2.1
A10: 2.Population | B10: HK Population Estimates (History data) | D10: HK Population Projections for 2017-2066 | F10: U.S. Historical Population (2014 and before) | H10: U.S. Population Projections (2015+)
B11: Census and Statistics Department, HK | D11: Census and Statistics Department, HK | F11: U.S. Census Bureau | H11: U.S. Census Bureau
B12: 2022 | D12: 2023 | F12: 2015 | H12: 2014
B13: Table 1.1 Mid Year Population by Age Group and Sex | D13: Table 150-11001 : Projected Mid-Year Population by Sex and Age Group | F13: Population Estimates: National Totals (Vintage 2015) | H13: National Population Projectons
B14: https://www.censtatd.gov.hk/en/data/stat_report/product/B1130303/att/B11303032022AN22B0100.pdf | D14: https://www.censtatd.gov.hk/en/web_table.html?id=150-11001 | F14: https://www.census.gov/popest/data/national/totals/2015/index.html | H14: https://www.census.gov/population/projections/files/summary/NP2014-T1.xls
D15: Annex Page | H15: Table 1
A17: 3. Energy Consumption | B17: HK Residential BAU Components Energy Use (Resi Ener HK) | D17: HK Commercial BAU Components Energy Use (Cmrc Ener HK) | F17: US Residential BAU Components Energy Use (Resi Ener US) | H17: US Commercial BAU Components Energy Use (Cmrc Ener US)
B18: InputData for HK EPS Model | D18: InputData for HK EPS Model | F18: InputData for HK EPS Model | H18: InputData for HK EPS Model
B19: bldg-BCEU | D19: bldg-BCEU | F19: bldg-BCEU | H19: bldg-BCEU
B20: Sheet: Residential_Final | D20: Sheet: Commercial_Final | F20: Copied from different sheets(colored darkblue) | H20: Copied from different sheets(colored darkblue)
A22: 4.Building Area | B22: HK Residential Area History Data | D22: HK Residential Area Prediction | F22: HK Commercial Area Prediction
B23: Census and Statistics Department, HK | D23: Census and Statistics Department, HK | F23: Rating and Valuation Department
B24: 2019 | D24: 2023 | F24: 2023
B25: Table 005 : Statistics on Domestic Households | D25: Table E485 : Hong Kong Domestic Household Projections | F25: Hong Kong Property Review 2023 - Preliminary Findings
B26: https://www.censtatd.gov.hk/en/scode190.html | D26: https://www.censtatd.gov.hk/en/web_table.html?id=150-12001k/hkstat/sub/sp190.jsp?productCode=D5320185 | F26: https://www.rvd.gov.hk/doc/en/HKPR2023_Preliminary_Findings_Eng.pdf
B28: US Residential Building Area (AEO T4) | D28: US Commercial Building Area (AEO T5)
B29: EIA | D29: EIA
B30: 2017 | D30: 2017
B31: Annual Energy Outlook 2017 | D31: Annual Energy Outlook 2017
B32: https://www.eia.gov/outlooks/aeo/excel/aeotab_4.xlsx | D32: https://www.eia.gov/outlooks/aeo/excel/aeotab_5.xlsx
B33: 4. Residential Sector Key Indicators and Consumption | D33: 5. Commercial Sector Key Indicators and Consumption
A35: 5. Urban vs Rural(HK) | B35: Building 2016 Data
B36: From Xiaoqian Jiang
B37: 2017
B38: From Excel "Copy of HK 2016 end use energy consumption rough 20190226 (added the building waste) revised2 lawrence.xlsx", Sheet"Building"
A40: 6.GDP | B40: HK National Income(GDP_Histo_census) | D40: U.S. GDP ,historical and projection (sheet: US Data) | F40: U.S. GDP (for checking the GDP from the left souce) | H40: U.S. GDP (also for checking)
B41: Census and Statistics Department, HK | D41: From Wenyi XI | F41: IIASA SSP database | H41: EIU Countrydata
B42: 2019 | D42: 2019 | F42: 2019 | H42: 2018
B43: Table 030: National Income | D43: Excel:"scaling-factors" | F43: SSP2 Scenario GDP projections | H43: Long term GDP projections for US
B44: https://www.censtatd.gov.hk/gb/?param=b5uniS&url=http://www.censtatd.gov.hk/hkstat/sub/sp250_tc.jsp?tableID=030&ID=0&productType=8 | F44: https://tntcat.iiasa.ac.at/SspDb/dsd?Action=htmlpage&page=about | H44: http://country.eiu.com/article.aspx?articleid=1647186748&Country=United%20States&topic=Economy&subtopic=Long-term+outlook&subsubtopic=Summary
B45: "Download longer data series" at the bottom of the page
A47: 7.CPI | B47: US CPI(1990-2018) | D47: US CPI(Only future estimation is used)
...

Sheet CPI
A1: Year | B1: CPI-U | C1: Multiply by to get 2018 Dollars
A2: 1990 | B2: 130.7 | C2: =B$30/B2 -> 1.9212471
A3: 1991 | B3: 136.2 | C3: =B$30/B3 -> 1.8436637 | G3: Historical Data | H3: From U.S. Bureau of Labor Statistics
A4: 1992 | B4: 140.3 | C4: =B$30/B4 -> 1.7897862 | G4: Estimation | H4: From EIU Countrydata Database
A5: 1993 | B5: 144.5 | C5: =B$30/B5 -> 1.7377647
A6: 1994 | B6: 148.2 | C6: =B$30/B6 -> 1.6943792
A7: 1995 | B7: 152.4 | C7: =B$30/B7 -> 1.6476837
A8: 1996 | B8: 156.9 | C8: =B$30/B8 -> 1.600427
A9: 1997 | B9: 160.5 | C9: =B$30/B9 -> 1.5645296
A10: 1998 | B10: 163 | C10: =B$30/B10 -> 1.5405337
A11: 1999 | B11: 166.6 | C11: =B$30/B11 -> 1.5072449
A12: 2000 | B12: 172.2 | C12: =B$30/B12 -> 1.4582288
A13: 2001 | B13: 177.1 | C13: =B$30/B13 -> 1.4178826
A14: 2002 | B14: 179.9 | C14: =B$30/B14 -> 1.3958143
A15: 2003 | B15: 184 | C15: =B$30/B15 -> 1.364712
A16: 2004 | B16: 188.9 | C16: =B$30/B16 -> 1.3293118
... A30: 2018 | B30: 251.107 | C30: =B$30/B30 -> 1
A31: 2019 | B31: ='CPI-EIU'!F46 -> 256.5 | C31: =B$30/B31 -> 0.97897466
A32: 2020 | B32: ='CPI-EIU'!F47 -> 260.1 | C32: =B$30/B32 -> 0.96542484
A33: 2021 | B33: ='CPI-EIU'!F48 -> 265.8 | C33: =B$30/B33 -> 0.9447216
A34: 2022 | B34: ='CPI-EIU'!F49 -> 271.3 | C34: =B$30/B34 -> 0.92556948
A35: 2023 | B35: ='CPI-EIU'!F50 -> 276.3 | C35: =B$30/B35 -> 0.90882012
A36: 2024 | B36: ='CPI-EIU'!F51 -> 280.9 | C36: =B$30/B36 -> 0.89393734
A37: 2025 | B37: ='CPI-EIU'!F52 -> 285.7 | C37: =B$30/B37 -> 0.87891845
A38: 2026 | B38: ='CPI-EIU'!F53 -> 290.6 | C38: =B$30/B38 -> 0.86409842
A39: 2027 | B39: ='CPI-EIU'!F54 -> 295.6 | C39: =B$30/B39 -> 0.84948241
A40: 2028 | B40: ='CPI-EIU'!F55 -> 300.7 | C40: =B$30/B40 -> 0.83507483
A41: 2029 | B41: ='CPI-EIU'!F56 -> 306 | C41: =B$30/B41 -> 0.82061111
A42: 2030 | B42: ='CPI-EIU'!F57 -> 311.5 | C42: =B$30/B42 -> 0.80612199
... A62: 2050 | B62: ='CPI-EIU'!F77 -> 458.6 | C62: =B$30/B62 -> 0.54755124

Sheet CPI-EIU
A4: United States of America
A6: Year | C6: Unit | F6: LCPI
A7: 1980 | F7: 82.383
A8: 1981 | F8: 90.933
A9: 1982 | F9: 96.533
A10: 1983 | F10: 99.583
A11: 1984 | F11: 103.933
A12: 1985 | F12: 107.6
A13: 1986 | F13: 109.692
A14: 1987 | F14: 113.617
A15: 1988 | F15: 118.275
A16: 1989 | F16: 123.942
A17: 1990 | F17: 130.658
A18: 1991 | F18: 136.167
... A77: 2050 | F77: 458.6
B79: Actual | E79: Forecast
A82: Consumer price index (av) - LCPI

Sheet Commercial
B2: Billions of 2013$
B4: Capital Invest: total installed capital cost of major end-use equipment paid by consumer (excludes federal or utility incentives)
B5: Subsidy Invest: federal equipment subsidies (e.g., investment tax credits for solar water heaters and ground-source heat pumps)
B7: Sum of Amount | E7: Year
B8: Division | C8: EndUse | D8: Label | E8: 2004 | F8: 2005 | G8: 2006 | H8: 2007 | I8: 2008 | J8: 2009 | K8: 2010 | L8: 2011 | M8: 2012 | N8: 2013 | O8: 2014 | P8: 2015 | Q8: 2016 | R8: 2017 | S8: 2018 | T8: 2019 | U8: 2020 | V8: 2021 | W8: 2022 | X8: 2023 | Y8: 2024 | Z8: 2025 | AA8: 2026 | AB8: 2027 | AC8: 2028 | AD8: 2029 | AE8: 2030 | AF8: 2031 | AG8: 2032 | AH8: 2033 | AI8: 2034 | AJ8: 2035 | AK8: 2036 | AL8: 2037 | AM8: 2038 | AN8: 2039 | AO8: 2040
B9: 1 New England | C9: 1 Heating | D9: Capital Invest | E9: 0.355 | F9: 0.377 | G9: 0.389 | H9: 0.38 | I9: 0.406 | J9: 0.339 | K9: 0.323 | L9: 0.317 | M9: 0.324 | N9: 0.317 | O9: 0.313 | P9: 0.31 | Q9: 0.31 | R9: 0.321 | S9: 0.322 | T9: 0.322 | U9: 0.318 | V9: 0.317 | W9: 0.316 | X9: 0.314 | Y9: 0.311 | Z9: 0.31 | AA9: 0.308 | AB9: 0.307 | AC9: 0.305 | AD9: 0.304 | AE9: 0.304 | AF9: 0.302 | AG9: 0.303 | AH9: 0.303 | AI9: 0.303 | AJ9: 0.304 | AK9: 0.306 | AL9: 0.305 | AM9: 0.305 | AN9: 0.304 | AO9: 0.302
D10: Subsidy Invest | E10: 0 | F10: 0 | G10: 0 | H10: 0 | I10: 0.012 | J10: 0.011 | K10: 0.01 | L10: 0.01 | M10: 0.01 | N10: 0.009 | O10: 0.009 | P10: 0.009 | Q10: 0.009 | R10: 0 | S10: 0 | T10: 0 | U10: 0 | V10: 0 | W10: 0 | X10: 0 | Y10: 0 | Z10: 0 | AA10: 0 | AB10: 0 | AC10: 0 | AD10: 0 | AE10: 0 | AF10: 0 | AG10: 0 | AH10: 0 | AI10: 0 | AJ10: 0 | AK10: 0 | AL10: 0 | AM10: 0 | AN10: 0 | AO10: 0
C11: 1 Heating Total | E11: 0.355 | F11: 0.377 | G11: 0.389 | H11: 0.38 | I11: 0.418 | J11: 0.35 | K11: 0.333 | L11: 0.327 | M11: 0.334 | N11: 0.326 | O11: 0.322 | P11: 0.319 | Q11: 0.319 | R11: 0.321 | S11: 0.322 | T11: 0.322 | U11: 0.318 | V11: 0.317 | W11: 0.316 | X11: 0.314 | Y11: 0.311 | Z11: 0.31 | AA11: 0.308 | AB11: 0.307 | AC11: 0.305 | AD11: 0.304 | AE11: 0.304 | AF11: 0.302 | AG11: 0.303 | AH11: 0.303 | AI11: 0.303 | AJ11: 0.304 | AK11: 0.306 | AL11: 0.305 | AM11: 0.305 | AN11: 0.304 | AO11: 0.302
C12: 2 Cooling | D12: Capital Invest | E12: 0.273 | F12: 0.231 | G12: 0.235 | H12: 0.234 | I12: 0.233 | J12: 0.231 | K12: 0.29 | L12: 0.279 | M12: 0.285 | N12: 0.272 | O12: 0.285 | P12: 0.277 | Q12: 0.277 | R12: 0.28 | S12: 0.28 | T12: 0.279 | U12: 0.278 | V12: 0.277 | W12: 0.276 | X12: 0.274 | Y12: 0.272 | Z12: 0.271 | AA12: 0.27 | AB12: 0.268 | AC12: 0.268 | AD12: 0.267 | AE12: 0.266 | AF12: 0.266 | AG12: 0.267 | AH12: 0.267 | AI12: 0.268 | AJ12: 0.269 | AK12: 0.27 | AL12: 0.269 | AM12: 0.269 | AN12: 0.267 | AO12: 0.266
D13: Subsidy Invest | E13: 0 | F13: 0 | G13: 0 | H13: 0 | I13: 0 | J13: 0 | K13: 0 | L13: 0 | M13: 0 | N13: 0 | O13: 0 | P13: 0 | Q13: 0 | R13: 0 | S13: 0 | T13: 0 | U13: 0 | V13: 0 | W13: 0 | X13: 0 | Y13: 0 | Z13: 0 | AA13: 0 | AB13: 0 | AC13: 0 | AD13: 0 | AE13: 0 | AF13: 0 | AG13: 0 | AH13: 0 | AI13: 0 | AJ13: 0 | AK13: 0 | AL13: 0 | AM13: 0 | AN13: 0 | AO13: 0
C14: 2 Cooling Total | E14: 0.273 | F14: 0.231 | G14: 0.235 | H14: 0.234 | I14: 0.233 | J14: 0.231 | K14: 0.29 | L14: 0.279 | M14: 0.285 | N14: 0.272 | O14: 0.285 | P14: 0.277 | Q14: 0.277 | R14: 0.28 | S14: 0.28 | T14: 0.279 | U14: 0.278 | V14: 0.277 | W14: 0.276 | X14: 0.274 | Y14: 0.272 | Z14: 0.271 | AA14: 0.27 | AB14: 0.268 | AC14: 0.268 | AD14: 0.267 | AE14: 0.266 | AF14: 0.266 | AG14: 0.267 | AH14: 0.267 | AI14: 0.268 | AJ14: 0.269 | AK14: 0.27 | AL14: 0.269 | AM14: 0.269 | AN14: 0.267 | AO14: 0.266
C15: 3 Water Heating | D15: Capital Invest | E15: 0.026 | F15: 0.027 | G15: 0.031 | H15: 0.031 | I15: 0.036 | J15: 0.033 | K15: 0.032 | L15: 0.031 | M15: 0.032 | N15: 0.033 | O15: 0.032 | P15: 0.032 | Q15: 0.031 | R15: 0.031 | S15: 0.031 | T15: 0.032 | U15: 0.033 | V15: 0.034 | W15: 0.034 | X15: 0.035 | Y15: 0.036 | Z15: 0.036 | AA15: 0.036 | AB15: 0.036 | AC15: 0.036 | AD15: 0.037 | AE15: 0.036 | AF15: 0.037 | AG15: 0.037 | AH15: 0.038 | AI15: 0.038 | AJ15: 0.039 | AK15: 0.039 | AL15: 0.039 | AM15: 0.04 | AN15: 0.04 | AO15: 0.04
D16: Subsidy Invest | E16: 0 | F16: 0 | G16: 0.003 | H16: 0.003 | I16: 0.007 | J16: 0.006 | K16: 0.006 | L16: 0.005 | M16: 0.005 | N16: 0.005 | O16: 0.005 | P16: 0.005 | Q16: 0.004 | R16: 0.001 | S16: 0.001 | T16: 0.001 | U16: 0.001 | V16: 0.001 | W16: 0.001 | X16: 0.001 | Y16: 0.001 | Z16: 0.001 | AA16: 0.001 | AB16: 0.001 | AC16: 0.001 | AD16: 0.001 | AE16: 0.001 | AF16: 0.001 | AG16: 0.001 | AH16: 0.001 | AI16: 0.001 | AJ16: 0.001 | AK16: 0.001 | AL16: 0.001 | AM16: 0.001 | AN16: 0.001 | AO16: 0.001
C17: 3 Water Heating Total | E17: 0.026 | F17: 0.027 | G17: 0.034 | H17: 0.034 | I17: 0.043 | J17: 0.039 | K17: 0.038 | L17: 0.036 | M17: 0.037 | N17: 0.038 | O17: 0.037 | P17: 0.037 | Q17: 0.035 | R17: 0.032 | S17: 0.032 | T17: 0.033 | U17: 0.034 | V17: 0.035 | W17: 0.035 | X17: 0.036 | Y17: 0.037 | Z17: 0.037 | AA17: 0.037 | AB17: 0.037 | AC17: 0.037 | AD17: 0.038 | AE17: 0.037 | AF17: 0.038 | AG17: 0.038 | AH17: 0.039 | AI17: 0.039 | AJ17: 0.04 | AK17: 0.04 | AL17: 0.04 | AM17: 0.041 | AN17: 0.041 | AO17: 0.041
C18: 4 Ventilation | D18: Capital Invest | E18: 0.723 | F18: 0.732 | G18: 0.762 | H18: 0.744 | I18: 0.775 | J18: 0.743 | K18: 0.717 | L18: 0.695 | M18: 0.721 | N18: 0.709 | O18: 0.716 | P18: 0.727 | Q18: 0.733 | R18: 0.749 | S18: 0.76 | T18: 0.775 | U18: 0.782 | V18: 0.789 | W18: 0.794 | X18: 0.796 | Y18: 0.798 | Z18: 0.8 | AA18: 0.801 | AB18: 0.802 | AC18: 0.804 | AD18: 0.809 | AE18: 0.814 | AF18: 0.823 | AG18: 0.836 | AH18: 0.849 | AI18: 0.865 | AJ18: 0.882 | AK18: 0.9 | AL18: 0.912 | AM18: 0.922 | AN18: 0.928 | AO18: 0.934
D19: Subsidy Invest | E19: 0 | F19: 0 | G19: 0 | H19: 0 | I19: 0 | J19: 0 | K19: 0 | L19: 0 | M19: 0 | N19: 0 | O19: 0 | P19: 0 | Q19: 0 | R19: 0 | S19: 0 | T19: 0 | U19: 0 | V19: 0 | W19: 0 | X19: 0 | Y19: 0 | Z19: 0 | AA19: 0 | AB19: 0 | AC19: 0 | AD19: 0 | AE19: 0 | AF19: 0 | AG19: 0 | AH19: 0 | AI19: 0 | AJ19: 0 | AK19: 0 | AL19: 0 | AM19: 0 | AN19: 0 | AO19: 0
C20: 4 Ventilation Total | E20: 0.723 | F20: 0.732 | G20: 0.762 | H20: 0.744 | I20: 0.775 | J20: 0.743 | K20: 0.717 | L20: 0.695 | M20: 0.721 | N20: 0.709 | O20: 0.716 | P20: 0.727 | Q20: 0.733 | R20: 0.749 | S20: 0.76 | T20: 0.775 | U20: 0.782 | V20: 0.789 | W20: 0.794 | X20: 0.796 | Y20: 0.798 | Z20: 0.8 | AA20: 0.801 | AB20: 0.802 | AC20: 0.804 | AD20: 0.809 | AE20: 0.814 | AF20: 0.823 | AG20: 0.836 | AH20: 0.849 | AI20: 0.865 | AJ20: 0.882 | AK20: 0.9 | AL20: 0.912 | AM20: 0.922 | AN20: 0.928 | AO20: 0.934
C21: 5 Cooking | D21: Capital Invest | E21: 0.017 | F21: 0.017 | G21: 0.018 | H21: 0.018 | I21: 0.019 | J21: 0.018 | K21: 0.018 | L21: 0.018 | M21: 0.018 | N21: 0.017 | O21: 0.017 | P21: 0.017 | Q21: 0.017 | R21: 0.018 | S21: 0.018 | T21: 0.018 | U21: 0.018 | V21: 0.019 | W21: 0.019 | X21: 0.019 | Y21: 0.019 | Z21: 0.019 | AA21: 0.019 | AB21: 0.019 | AC21: 0.019 | AD21: 0.019 | AE21: 0.019 | AF21: 0.02 | AG21: 0.02 | AH21: 0.02 | AI21: 0.02 | AJ21: 0.02 | AK21: 0.021 | AL21: 0.021 | AM21: 0.021 | AN21: 0.021 | AO21: 0.021
D22: Subsidy Invest | E22: 0 | F22: 0 | G22: 0 | H22: 0 | I22: 0 | J22: 0 | K22: 0 | L22: 0 | M22: 0 | N22: 0 | O22: 0 | P22: 0 | Q22: 0 | R22: 0 | S22: 0 | T22: 0 | U22: 0 | V22: 0 | W22: 0 | X22: 0 | Y22: 0 | Z22: 0 | AA22: 0 | AB22: 0 | AC22: 0 | AD22: 0 | AE22: 0 | AF22: 0 | AG22: 0 | AH22: 0 | AI22: 0 | AJ22: 0 | AK22: 0 | AL22: 0 | AM22: 0 | AN22: 0 | AO22: 0
C23: 5 Cooking Total | E23: 0.017 | F23: 0.017 | G23: 0.018 | H23: 0.018 | I23: 0.019 | J23: 0.018 | K23: 0.018 | L23: 0.018 | M23: 0.018 | N23: 0.017 | O23: 0.017 | P23: 0.017 | Q23: 0.017 | R23: 0.018 | S23: 0.018 | T23: 0.018 | U23: 0.018 | V23: 0.019 | W23: 0.019 | X23: 0.019 | Y23: 0.019 | Z23: 0.019 | AA23: 0.019 | AB23: 0.019 | AC23: 0.019 | AD23: 0.019 | AE23: 0.019 | AF23: 0.02 | AG23: 0.02 | AH23: 0.02 | AI23: 0.02 | AJ23: 0.02 | AK23: 0.021 | AL23: 0.021 | AM23: 0.021 | AN23: 0.021 | AO23: 0.021
C24: 6 Lighting | D24: Capital Invest | E24: 0.062 | F24: 0.066 | G24: 0.073 | H24: 0.066 | I24: 0.089 | J24: 0.083 | K24: 0.079 | L24: 0.072 | M24: 0.072 | N24: 0.066 | O24: 0.064 | P24: 0.062 | Q24: 0.059 | R24: 0.06 | S24: 0.061 | T24: 0.063 | U24: 0.071 | V24: 0.072 | W24: 0.073 | X24: 0.073 | Y24: 0.073 | Z24: 0.073 | AA24: 0.073 | AB24: 0.073 | AC24: 0.073 | AD24: 0.074 | AE24: 0.073 | AF24: 0.072 | AG24: 0.073 | AH24: 0.073 | AI24: 0.074 | AJ24: 0.075 | AK24: 0.076 | AL24: 0.076 | AM24: 0.077 | AN24: 0.078 | AO24: 0.079
D25: Subsidy Invest | E25: 0 | F25: 0 | G25: 0 | H25: 0 | I25: 0 | J25: 0 | K25: 0 | L25: 0 | M25: 0 | N25: 0 | O25: 0 | P25: 0 | Q25: 0 | R25: 0 | S25: 0 | T25: 0 | U25: 0 | V25: 0 | W25: 0 | X25: 0 | Y25: 0 | Z25: 0 | AA25: 0 | AB25: 0 | AC25: 0 | AD25: 0 | AE25: 0 | AF25: 0 | AG25: 0 | AH25: 0 | AI25: 0 | AJ25: 0 | AK25: 0 | AL25: 0 | AM25: 0 | AN25: 0 | AO25: 0
C26: 6 Lighting Total | E26: 0.062 | F26: 0.066 | G26: 0.073 | H26: 0.066 | I26: 0.089 | J26: 0.083 | K26: 0.079 | L26: 0.072 | M26: 0.072 | N26: 0.066 | O26: 0.064 | P26: 0.062 | Q26: 0.059 | R26: 0.06 | S26: 0.061 | T26: 0.063 | U26: 0.071 | V26: 0.072 | W26: 0.073 | X26: 0.073 | Y26: 0.073 | Z26: 0.073 | AA26: 0.073 | AB26: 0.073 | AC26: 0.073 | AD26: 0.074 | AE26: 0.073 | AF26: 0.072 | AG26: 0.073 | AH26: 0.073 | AI26: 0.074 | AJ26: 0.075 | AK26: 0.076 | AL26: 0.076 | AM26: 0.077 | AN26: 0.078 | AO26: 0.079
C27: 7 Refrigeration | D27: Capital Invest | E27: 1.259 | F27: 1.315 | G27: 1.337 | H27: 1.33 | I27: 1.362 | J27: 1.464 | K27: 2.103 | L27: 2.013 | M27: 2.139 | N27: 2.038 | O27: 2.012 | P27: 2.008 | Q27: 2.011 | R27: 2.111 | S27: 2.114 | T27: 2.113 | U27: 2.112 | V27: 2.113 | W27: 2.113 | X27: 2.114 | Y27: 2.119 | Z27: 2.128 | AA27: 2.136 | AB27: 2.145 | AC27: 2.156 | AD27: 2.168 | AE27: 2.18 | AF27: 2.192 | AG27: 2.208 | AH27: 2.224 | AI27: 2.245 | AJ27: 2.269 | AK27: 2.289 | AL27: 2.307 | AM27: 2.321 | AN27: 2.329 | AO27: 2.334
D28: Subsidy Invest | E28: 0 | F28: 0 | G28: 0 | H28: 0 | I28: 0 | J28: 0 | K28: 0 | L28: 0 | M28: 0 | N28: 0 | O28: 0 | P28: 0 | Q28: 0 | R28: 0 | S28: 0 | T28: 0 | U28: 0 | V28: 0 | W28: 0 | X28: 0 | Y28: 0 | Z28: 0 | AA28: 0 | AB28: 0 | AC28: 0 | AD28: 0 | AE28: 0 | AF28: 0 | AG28: 0 | AH28: 0 | AI28: 0 | AJ28: 0 | AK28: 0 | AL28: 0 | AM28: 0 | AN28: 0 | AO28: 0
C29: 7 Refrigeration Total | E29: 1.259 | F29: 1.315 | G29: 1.337 | H29: 1.33 | I29: 1.362 | J29: 1.464 | K29: 2.103 | L29: 2.013 | M29: 2.139 | N29: 2.038 | O29: 2.012 | P29: 2.008 | Q29: 2.011 | R29: 2.111 | S29: 2.114 | T29: 2.113 | U29: 2.112 | V29: 2.113 | W29: 2.113 | X29: 2.114 | Y29: 2.119 | Z29: 2.128 | AA29: 2.136 | AB29: 2.145 | AC29: 2.156 | AD29: 2.168 | AE29: 2.18 | AF29: 2.192 | AG29: 2.208 | AH29: 2.224 | AI29: 2.245 | AJ29: 2.269 | AK29: 2.289 | AL29: 2.307 | AM29: 2.321 | AN29: 2.329 | AO29: 2.334
B30: 1 New England Total | E30: 2.715 | F30: 2.765 | G30: 2.848 | H30: 2.806 | I30: 2.939 | J30: 2.928 | K30: 3.578 | L30: 3.44 | M30: 3.606 | N30: 3.466 | O30: 3.453 | P30: 3.447 | Q30: 3.451 | R30: 3.571 | S30: 3.587 | T30: 3.603 | U30: 3.613 | V30: 3.622 | W30: 3.626 | X30: 3.626 | Y30: 3.629 | Z30: 3.638 | AA30: 3.644 | AB30: 3.651 | AC30: 3.662 | AD30: 3.679 | AE30: 3.693 | AF30: 3.713 | AG30: 3.745 | AH30: 3.775 | AI30: 3.814 | AJ30: 3.859 | AK30: 3.902 | AL30: 3.93 | AM30: 3.956 | AN30: 3.968 | AO30: 3.977
B31: 2 Middle Atlantic | C31: 1 Heating | D31: Capital Invest | E31: 1.049 | F31: 1.067 | G31: 1.075 | H31: 1.067 | I31: 1.128 | J31: 1.021 | K31: 0.961 | L31: 0.942 | M31: 0.932 | N31: 0.914 | O31: 0.898 | P31: 0.894 | Q31: 0.894 | R31: 0.911 | S31: 0.909 | T31: 0.908 | U31: 0.896 | V31: 0.893 | W31: 0.887 | X31: 0.878 | Y31: 0.869 | Z31: 0.862 | AA31: 0.856 | AB31: 0.849 | AC31: 0.843 | AD31: 0.838 | AE31: 0.833 | AF31: 0.827 | AG31: 0.827 | AH31: 0.824 | AI31: 0.821 | AJ31: 0.82 | AK31: 0.821 | AL31: 0.817 | AM31: 0.814 | AN31: 0.809 | AO31: 0.804
D32: Subsidy Invest | E32: 0 | F32: 0 | G32: 0 | H32: 0 | I32: 0.024 | J32: 0.022 | K32: 0.02 | L32: 0.019 | M32: 0.019 | N32: 0.017 | O32: 0.017 | P32: 0.017 | Q32: 0.016 | R32: 0 | S32: 0 | T32: 0 | U32: 0 | V32: 0 | W32: 0 | X32: 0 | Y32: 0 | Z32: 0 | AA32: 0 | AB32: 0 | AC32: 0 | AD32: 0 | AE32: 0 | AF32: 0 | AG32: 0 | AH32: 0 | AI32: 0 | AJ32: 0 | AK32: 0 | AL32: 0 | AM32: 0 | AN32: 0 | AO32: 0
C33: 1 Heating Total | E33: 1.049 | F33: 1.067 | G33: 1.075 | H33: 1.067 | I33: 1.152 | J33: 1.043 | K33: 0.981 | L33: 0.961 | M33: 0.951 | N33: 0.931 | O33: 0.915 | P33: 0.911 | Q33: 0.91 | R33: 0.911 | S33: 0.909 | T33: 0.908 | U33: 0.896 | V33: 0.893 | W33: 0.887 | X33: 0.878 | Y33: 0.869 | Z33: 0.862 | AA33: 0.856 | AB33: 0.849 | AC33: 0.843 | AD33: 0.838 | AE33: 0.833 | AF33: 0.827 | AG33: 0.827 | AH33: 0.824 | AI33: 0.821 | AJ33: 0.82 | AK33: 0.821 | AL33: 0.817 | AM33: 0.814 | AN33: 0.809 | AO33: 0.804
C34: 2 Cooling | D34: Capital Invest | E34: 0.916 | F34: 0.74 | G34: 0.752 | H34: 0.759 | I34: 0.751 | J34: 0.753 | K34: 0.763 | L34: 0.758 | M34: 0.745 | N34: 0.768 | O34: 0.776 | P34: 0.762 | Q34: 0.761 | R34: 0.764 | S34: 0.764 | T34: 0.764 | U34: 0.76 | V34: 0.757 | W34: 0.754 | X34: 0.748 | Y34: 0.742 | Z34: 0.738 | AA34: 0.734 | AB34: 0.729 | AC34: 0.726 | AD34: 0.723 | AE34: 0.721 | AF34: 0.72 | AG34: 0.722 | AH34: 0.725 | AI34: 0.728 | AJ34: 0.733 | AK34: 0.739 | AL34: 0.742 | AM34: 0.744 | AN34: 0.744 | AO34: 0.744
D35: Subsidy Invest | E35: 0 | F35: 0 | G35: 0 | H35: 0 | I35: 0 | J35: 0 | K35: 0 | L35: 0 | M35: 0 | N35: 0 | O35: 0 | P35: 0 | Q35: 0 | R35: 0 | S35: 0 | T35: 0 | U35: 0 | V35: 0 | W35: 0 | X35: 0 | Y35: 0 | Z35: 0 | AA35: 0 | AB35: 0 | AC35: 0 | AD35: 0 | AE35: 0 | AF35: 0 | AG35: 0 | AH35: 0 | AI35: 0 | AJ35: 0 | AK35: 0 | AL35: 0 | AM35: 0 | AN35: 0 | AO35: 0
C36: 2 Cooling Total | E36: 0.916 | F36: 0.74 | G36: 0.752 | H36: 0.759 | I36: 0.751 | J36: 0.753 | K36: 0.763 | L36: 0.758 | M36: 0.745 | N36: 0.768 | O36: 0.776 | P36: 0.762 | Q36: 0.761 | R36: 0.764 | S36: 0.764 | T36: 0.764 | U36: 0.76 | V36: 0.757 | W36: 0.754 | X36: 0.748 | Y36: 0.742 | Z36: 0.738 | AA36: 0.734 | AB36: 0.729 | AC36: 0.726 | AD36: 0.723 | AE36: 0.721 | AF36: 0.72 | AG36: 0.722 | AH36: 0.725 | AI36: 0.728 | AJ36: 0.733 | AK36: 0.739 | AL36: 0.742 | AM36: 0.744 | AN36: 0.744 | AO36: 0.744
C37: 3 Water Heating | D37: Capital Invest | E37: 0.084 | F37: 0.085 | G37: 0.09 | H37: 0.092 | I37: 0.099 | J37: 0.097 | K37: 0.093 | L37: 0.091 | M37: 0.091 | N37: 0.094 | O37: 0.09 | P37: 0.091 | Q37: 0.091 | R37: 0.091 | S37: 0.092 | T37: 0.093 | U37: 0.095 | V37: 0.096 | W37: 0.096 | X37: 0.097 | Y37: 0.097 | Z37: 0.098 | AA37: 0.098 | AB37: 0.098 | AC37: 0.098 | AD37: 0.098 | AE37: 0.099 | AF37: 0.1 | AG37: 0.101 | AH37: 0.102 | AI37: 0.102 | AJ37: 0.103 | AK37: 0.105 | AL37: 0.107 | AM37: 0.108 | AN37: 0.108 | AO37: 0.109
D38: Subsidy Invest | E38: 0 | F38: 0 | G38: 0.004 | H38: 0.004 | I38: 0.007 | J38: 0.007 | K38: 0.007 | L38: 0.007 | M38: 0.007 | N38: 0.006 | O38: 0.005 | P38: 0.005 | Q38: 0.005 | R38: 0.001 | S38: 0.001 | T38: 0.001 | U38: 0.001 | V38: 0.001 | W38: 0.001 | X38: 0.001 | Y38: 0.001 | Z38: 0.001 | AA38: 0.001 | AB38: 0.001 | AC38: 0.001 | AD38: 0.001 | AE38: 0.001 | AF38: 0.001 | AG38: 0.001 | AH38: 0.001 | AI38: 0.001 | AJ38: 0.001 | AK38: 0.001 | AL38: 0.001 | AM38: 0.001 | AN38: 0.001 | AO38: 0.001
C39: 3 Water Heating Total | E39: 0.084 | F39: 0.085 | G39: 0.094 | H39: 0.096 | I39: 0.106 | J39: 0.104 | K39: 0.1 | L39: 0.098 | M39: 0.098 | N39: 0.1 | O39: 0.095 | P39: 0.096 | Q39: 0.096 | R39: 0.092 | S39: 0.093 | T39: 0.094 | U39: 0.096 | V39: 0.097 | W39: 0.097 | X39: 0.098 | Y39: 0.098 | Z39: 0.099 | AA39: 0.099 | AB39: 0.099 | AC39: 0.099 | AD39: 0.099 | AE39: 0.1 | AF39: 0.101 | AG39: 0.102 | AH39: 0.103 | AI39: 0.103 | AJ39: 0.104 | AK39: 0.106 | AL39: 0.108 | AM39: 0.109 | AN39: 0.109 | AO39: 0.11
C40: 4 Ventilation | D40: Capital Invest | E40: 3.15 | F40: 3.119 | G40: 3.169 | H40: 3.214 | I40: 3.278 | J40: 3.208 | K40: 3.07 | L40: 3.012 | M40: 3.014 | N40: 2.976 | O40: 2.97 | P40: 3.009 | Q40: 3.046 | R40: 3.093 | S40: 3.124 | T40: 3.156 | U40: 3.172 | V40: 3.193 | W40: 3.207 | X40: 3.21 | Y40: 3.219 | Z40: 3.226 | AA40: 3.234 | AB40: 3.238 | AC40: 3.252 | AD40: 3.266 | AE40: 3.282 | AF40: 3.308 | AG40: 3.352 | AH40: 3.401 | AI40: 3.45 | AJ40: 3.506 | AK40: 3.566 | AL40: 3.61 | AM40: 3.648 | AN40: 3.677 | AO40: 3.702
D41: Subsidy Invest | E41: 0 | F41: 0 | G41: 0 | H41: 0 | I41: 0 | J41: 0 | K41: 0 | L41: 0 | M41: 0 | N41: 0 | O41: 0 | P41: 0 | Q41: 0 | R41: 0 | S41: 0 | T41: 0 | U41: 0 | V41: 0 | W41: 0 | X41: 0 | Y41: 0 | Z41: 0 | AA41: 0 | AB41: 0 | AC41: 0 | AD41: 0 | AE41: 0 | AF41: 0 | AG41: 0 | AH41: 0 | AI41: 0 | AJ41: 0 | AK41: 0 | AL41: 0 | AM41: 0 | AN41: 0 | AO41: 0
C42: 4 Ventilation Total | E42: 3.15 | F42: 3.119 | G42: 3.169 | H42: 3.214 | I42: 3.278 | J42: 3.208 | K42: 3.07 | L42: 3.012 | M42: 3.014 | N42: 2.976 | O42: 2.97 | P42: 3.009 | Q42: 3.046 | R42: 3.093 | S42: 3.124 | T42: 3.156 | U42: 3.172 | V42: 3.193 | W42: 3.207 | X42: 3.21 | Y42: 3.219 | Z42: 3.226 | AA42: 3.234 | AB42: 3.238 | AC42: 3.252 | AD42: 3.266 | AE42: 3.282 | AF42: 3.308 | AG42: 3.352 | AH42: 3.401 | AI42: 3.45 | AJ42: 3.506 | AK42: 3.566 | AL42: 3.61 | AM42: 3.648 | AN42: 3.677 | AO42: 3.702
C43: 5 Cooking | D43: Capital Invest | E43: 0.072 | F43: 0.073 | G43: 0.073 | H43: 0.074 | I43: 0.079 | J43: 0.074 | K43: 0.072 | L43: 0.071 | M43: 0.07 | N43: 0.071 | O43: 0.067 | P43: 0.068 | Q43: 0.068 | R43: 0.069 | S43: 0.07 | T43: 0.07 | U43: 0.071 | V43: 0.074 | W43: 0.074 | X43: 0.074 | Y43: 0.075 | Z43: 0.075 | AA43: 0.075 | AB43: 0.076 | AC43: 0.076 | AD43: 0.077 | AE43: 0.077 | AF43: 0.077 | AG43: 0.078 | AH43: 0.078 | AI43: 0.079 | AJ43: 0.079 | AK43: 0.08 | AL43: 0.081 | AM43: 0.081 | AN43: 0.082 | AO43: 0.082
...

Sheet Residential
B2: Displays Investment and Subsidy on the Shell and Investment Tables -- note total expenditures on equipment or shell = consumer investment ("Investment") + subsidy.
B3: i.e., total investment = totinvest + totsubsidy
I5: YEAR
B6: CDIV | C6: BLDG | D6: ENDUSE | E6: Filled Column Name | F6: FUEL | G6: EQPTYPE | H6: Data | I6: 2010 | J6: 2011 | K6: 2012 | L6: 2013 | M6: 2014 | N6: 2015 | O6: 2016 | P6: 2017 | Q6: 2018 | R6: 2019 | S6: 2020 | T6: 2021 | U6: 2022 | V6: 2023 | W6: 2024 | X6: 2025 | Y6: 2026 | Z6: 2027 | AA6: 2028 | AB6: 2029 | AC6: 2030 | AD6: 2031 | AE6: 2032 | AF6: 2033 | AG6: 2034 | AH6: 2035 | AI6: 2036 | AJ6: 2037 | AK6: 2038 | AL6: 2039 | AM6: 2040
B7: 1 New England | C7: Single Family | D7: Refrigeration | E7: =IF(D7="",E6,D7) -> Refrigeration | F7: Electricity | G7: RefBF#1 | H7: Sum of TOTSUBSIDY | I7: 0 | J7: 0 | K7: 0 | L7: 0 | M7: 0 | N7: 0 | O7: 0 | P7: 0 | Q7: 0 | R7: 0 | S7: 0 | T7: 0 | U7: 0 | V7: 0 | W7: 0 | X7: 0 | Y7: 0 | Z7: 0 | AA7: 0 | AB7: 0 | AC7: 0 | AD7: 0 | AE7: 0 | AF7: 0 | AG7: 0 | AH7: 0 | AI7: 0 | AJ7: 0 | AK7: 0 | AL7: 0 | AM7: 0
B8: 2 New England | C8: Single Family | D8: Refrigeration | E8: =IF(D8="",E7,D8) -> Refrigeration | F8: Electricity | H8: Sum of TOTPURCHASE | I8: 7641 | J8: 8277 | K8: 9322 | L8: 9515 | M8: 16192 | N8: 18638 | O8: 21440 | P8: 23650 | Q8: 22661 | R8: 21330 | S8: 20392 | T8: 19560 | U8: 19123 | V8: 18742 | W8: 18631 | X8: 18254 | Y8: 18246 | Z8: 18296 | AA8: 17978 | AB8: 18077 | AC8: 18041 | AD8: 18148 | AE8: 17803 | AF8: 17644 | AG8: 17295 | AH8: 16890 | AI8: 16364 | AJ8: 16912 | AK8: 16969 | AL8: 16848 | AM8: 16886
B9: 3 New England | C9: Single Family | D9: Refrigeration | E9: =IF(D9="",E8,D9) -> Refrigeration | F9: Electricity | H9: Sum of TOTINVEST | I9: 7106539 | J9: 7698489 | K9: 8670550 | L9: 8849066 | M9: 15868566 | N9: 18265744 | O9: 21012184 | P9: 23177772 | Q9: 22209051 | R9: 20903899 | S9: 19985670 | T9: 19170027 | U9: 18741917 | V9: 18368449 | W9: 18259277 | X9: 17890627 | Y9: 17882375 | Z9: 17931390 | AA9: 17619678 | AB9: 17715945 | AC9: 17681312 | AD9: 17785703 | AE9: 17448370 | AF9: 17292400 | AG9: 16950256 | AH9: 16552681 | AI9: 16037627 | AJ9: 16574633 | AK9: 16630497 | AL9: 16511926 | AM9: 16549458
B10: 4 New England | C10: Single Family | D10: Refrigeration | E10: =IF(D10="",E9,D10) -> Refrigeration | F10: Electricity | G10: RefBF#2 | H10: Sum of TOTSUBSIDY | I10: 0 | J10: 0 | K10: 0 | L10: 0 | M10: 0 | N10: 0 | O10: 0 | P10: 0 | Q10: 0 | R10: 0 | S10: 0 | T10: 0 | U10: 0 | V10: 0 | W10: 0 | X10: 0 | Y10: 0 | Z10: 0 | AA10: 0 | AB10: 0 | AC10: 0 | AD10: 0 | AE10: 0 | AF10: 0 | AG10: 0 | AH10: 0 | AI10: 0 | AJ10: 0 | AK10: 0 | AL10: 0 | AM10: 0
B11: 5 New England | C11: Single Family | D11: Refrigeration | E11: =IF(D11="",E10,D11) -> Refrigeration | F11: Electricity | H11: Sum of TOTPURCHASE | I11: 48537 | J11: 47630 | K11: 50302 | L11: 53524 | M11: 49460 | N11: 51317 | O11: 53089 | P11: 56065 | Q11: 56839 | R11: 57422 | S11: 58129 | T11: 58577 | U11: 59160 | V11: 60044 | W11: 60634 | X11: 61227 | Y11: 61552 | Z11: 61566 | AA11: 61503 | AB11: 61443 | AC11: 61470 | AD11: 61124 | AE11: 60410 | AF11: 59803 | AG11: 58923 | AH11: 57614 | AI11: 56047 | AJ11: 57376 | AK11: 58932 | AL11: 60278 | AM11: 61406
B12: 6 New England | C12: Single Family | D12: Refrigeration | E12: =IF(D12="",E11,D12) -> Refrigeration | F12: Electricity | H12: Sum of TOTINVEST | I12: 48537800 | J12: 47631566 | K12: 50303211 | L12: 53524902 | M12: 49461022 | N12: 51318107 | O12: 53090386 | P12: 56066387 | Q12: 56839291 | R12: 57423022 | S12: 58130268 | T12: 58578720 | U12: 59161552 | V12: 60045224 | W12: 60635246 | X12: 61228121 | Y12: 61552603 | Z12: 61566808 | AA12: 61503654 | AB12: 61444409 | AC12: 61471848 | AD12: 61124636 | AE12: 60410271 | AF12: 59803728 | AG12: 58924256 | AH12: 57615525 | AI12: 56047545 | AJ12: 57377648 | AK12: 58933707 | AL12: 60279583 | AM12: 61406659
B13: 7 New England | C13: Single Family | D13: Refrigeration | E13: =IF(D13="",E12,D13) -> Refrigeration | F13: Electricity | G13: RefSF#1 | H13: Sum of TOTSUBSIDY | I13: 0 | J13: 0 | K13: 0 | L13: 0 | M13: 0 | N13: 0 | O13: 0 | P13: 0 | Q13: 0 | R13: 0 | S13: 0 | T13: 0 | U13: 0 | V13: 0 | W13: 0 | X13: 0 | Y13: 0 | Z13: 0 | AA13: 0 | AB13: 0 | AC13: 0 | AD13: 0 | AE13: 0 | AF13: 0 | AG13: 0 | AH13: 0 | AI13: 0 | AJ13: 0 | AK13: 0 | AL13: 0 | AM13: 0
B14: 8 New England | C14: Single Family | D14: Refrigeration | E14: =IF(D14="",E13,D14) -> Refrigeration | F14: Electricity | H14: Sum of TOTPURCHASE | I14: 5969 | J14: 6469 | K14: 7288 | L14: 7436 | M14: 40275 | N14: 45498 | O14: 51154 | P14: 55843 | Q14: 54228 | R14: 51833 | S14: 50116 | T14: 48495 | U14: 47663 | V14: 46960 | W14: 46785 | X14: 46023 | Y14: 46035 | Z14: 46147 | AA14: 45435 | AB14: 45649 | AC14: 45573 | AD14: 45777 | AE14: 44950 | AF14: 44541 | AG14: 43687 | AH14: 42669 | AI14: 41361 | AJ14: 42698 | AK14: 42959 | AL14: 42681 | AM14: 42778
B15: 9 New England | C15: Single Family | D15: Refrigeration | E15: =IF(D15="",E14,D15) -> Refrigeration | F15: Electricity | H15: Sum of TOTINVEST | I15: 6746147 | J15: 7310906 | K15: 8237360 | L15: 8404614 | M15: 47122359 | N15: 53233937 | O15: 59851761 | P15: 65337419 | Q15: 63448254 | R15: 60645844 | S15: 58636743 | T15: 56739854 | U15: 55767337 | V15: 54944606 | W15: 54739233 | X15: 53847841 | Y15: 53861670 | Z15: 53992513 | AA15: 53160446 | AB15: 53409935 | AC15: 53321047 | AD15: 53560148 | AE15: 52592075 | AF15: 52114937 | AG15: 51115676 | AH15: 49924401 | AI15: 48394100 | AJ15: 49957719 | AK15: 50263408 | AL15: 49937693 | AM15: 50051741
B16: 10 New England | C16: Single Family | D16: Refrigeration | E16: =IF(D16="",E15,D16) -> Refrigeration | F16: Electricity | G16: RefSF#2 | H16: Sum of TOTSUBSIDY | I16: 0 | J16: 0 | K16: 0 | L16: 0 | M16: 0 | N16: 0 | O16: 0 | P16: 0 | Q16: 0 | R16: 0 | S16: 0 | T16: 0 | U16: 0 | V16: 0 | W16: 0 | X16: 0 | Y16: 0 | Z16: 0 | AA16: 0 | AB16: 0 | AC16: 0 | AD16: 0 | AE16: 0 | AF16: 0 | AG16: 0 | AH16: 0 | AI16: 0 | AJ16: 0 | AK16: 0 | AL16: 0 | AM16: 0
B17: 11 New England | C17: Single Family | D17: Refrigeration | E17: =IF(D17="",E16,D17) -> Refrigeration | F17: Electricity | H17: Sum of TOTPURCHASE | I17: 50208 | J17: 49439 | K17: 52336 | L17: 55601 | M17: 25377 | N17: 24456 | O17: 23375 | P17: 23872 | Q17: 25272 | R17: 26918 | S17: 28406 | T17: 29643 | U17: 30620 | V17: 31826 | W17: 32481 | X17: 33459 | Y17: 33763 | Z17: 33715 | AA17: 34045 | AB17: 33872 | AC17: 33939 | AD17: 33495 | AE17: 33263 | AF17: 32905 | AG17: 32530 | AH17: 31835 | AI17: 31049 | AJ17: 31591 | AK17: 32942 | AL17: 34445 | AM17: 35513
B18: 12 New England | C18: Single Family | D18: Refrigeration | E18: =IF(D18="",E17,D18) -> Refrigeration | F18: Electricity | H18: Sum of TOTINVEST | I18: 58744763 | J18: 57844425 | K18: 61233928 | L18: 65054706 | M18: 35021529 | N18: 33751387 | O18: 32258938 | P18: 32945042 | Q18: 34875787 | R18: 37148882 | S18: 39201580 | T18: 40909227 | U18: 42257760 | V18: 43921730 | W18: 44824465 | X18: 46174899 | Y18: 46594751 | Z18: 46529042 | AA18: 46984353 | AB18: 46743883 | AC18: 46837836 | AD18: 46223664 | AE18: 45904647 | AF18: 45410770 | AG18: 44893926 | AH18: 43933124 | AI18: 42848983 | AJ18: 43596456 | AK18: 45461919 | AL18: 47536440 | AM18: 49010152
B19: 13 New England | C19: Single Family | D19: Refrigeration | E19: =IF(D19="",E18,D19) -> Refrigeration | F19: Electricity | G19: RefTF#1 | H19: Sum of TOTSUBSIDY | I19: 0 | J19: 0 | K19: 0 | L19: 0 | M19: 0 | N19: 0 | O19: 0 | P19: 0 | Q19: 0 | R19: 0 | S19: 0 | T19: 0 | U19: 0 | V19: 0 | W19: 0 | X19: 0 | Y19: 0 | Z19: 0 | AA19: 0 | AB19: 0 | AC19: 0 | AD19: 0 | AE19: 0 | AF19: 0 | AG19: 0 | AH19: 0 | AI19: 0 | AJ19: 0 | AK19: 0 | AL19: 0 | AM19: 0
B20: 14 New England | C20: Single Family | D20: Refrigeration | E20: =IF(D20="",E19,D20) -> Refrigeration | F20: Electricity | H20: Sum of TOTPURCHASE | I20: 12395 | J20: 9192 | K20: 10593 | L20: 10652 | M20: 90886 | N20: 98724 | O20: 107161 | P20: 115466 | Q20: 114056 | R20: 111589 | S20: 110117 | T20: 108578 | U20: 108112 | V20: 108075 | W20: 108398 | X20: 108050 | Y20: 108355 | Z20: 108497 | AA20: 107622 | AB20: 107813 | AC20: 107751 | AD20: 107673 | AE20: 106078 | AF20: 105064 | AG20: 103290 | AH20: 100941 | AI20: 98025 | AJ20: 100759 | AK20: 102464 | AL20: 103295 | AM20: 104385
B21: 15 New England | C21: Single Family | D21: Refrigeration | E21: =IF(D21="",E20,D21) -> Refrigeration | F21: Electricity | H21: Sum of TOTINVEST | I21: 6570190 | J21: 4872550 | K21: 5614349 | L21: 5645999 | M21: 58167696 | N21: 63184200 | O21: 68584258 | P21: 73899346 | Q21: 72996754 | R21: 71417518 | S21: 70475828 | T21: 69490601 | U21: 69192543 | V21: 69168761 | W21: 69375333 | X21: 69152165 | Y21: 69347694 | Z21: 69438250 | AA21: 68878761 | AB21: 69001286 | AC21: 68961234 | AD21: 68911414 | AE21: 67890891 | AF21: 67241238 | AG21: 66106089 | AH21: 64602620 | AI21: 62736773 | AJ21: 64486344 | AK21: 65577097 | AL21: 66109194 | AM21: 66806897
B22: 16 New England | C22: Single Family | D22: Refrigeration | E22: =IF(D22="",E21,D22) -> Refrigeration | F22: Electricity | G22: RefTF#2 | H22: Sum of TOTSUBSIDY | I22: 0 | J22: 0 | K22: 0 | L22: 0 | M22: 0 | N22: 0 | O22: 0 | P22: 0 | Q22: 0 | R22: 0 | S22: 0 | T22: 0 | U22: 0 | V22: 0 | W22: 0 | X22: 0 | Y22: 0 | Z22: 0 | AA22: 0 | AB22: 0 | AC22: 0 | AD22: 0 | AE22: 0 | AF22: 0 | AG22: 0 | AH22: 0 | AI22: 0 | AJ22: 0 | AK22: 0 | AL22: 0 | AM22: 0
B23: 17 New England | C23: Single Family | D23: Refrigeration | E23: =IF(D23="",E22,D23) -> Refrigeration | F23: Electricity | H23: Sum of TOTPURCHASE | I23: 52693 | J23: 35293 | K23: 38057 | L23: 39952 | M23: 24317 | N23: 25195 | O23: 26061 | P23: 27530 | Q23: 27900 | R23: 28189 | S23: 28550 | T23: 28789 | U23: 29092 | V23: 29548 | W23: 29849 | X23: 30163 | Y23: 30328 | Z23: 30332 | AA23: 30315 | AB23: 30280 | AC23: 30296 | AD23: 30115 | AE23: 29769 | AF23: 29469 | AG23: 29040 | AH23: 28396 | AI23: 27627 | AJ23: 28275 | AK23: 29060 | AL23: 29835 | AM23: 30460
B24: 18 New England | C24: Single Family | D24: Refrigeration | E24: =IF(D24="",E23,D24) -> Refrigeration | F24: Electricity | H24: Sum of TOTINVEST | I24: 33723842 | J24: 22587672 | K24: 24356898 | L24: 25569733 | M24: 19453713 | N24: 20157305 | O24: 20849660 | P24: 22025093 | Q24: 22320892 | R24: 22552062 | S24: 22840451 | T24: 23032104 | U24: 23274475 | V24: 23639089 | W24: 23879883 | X24: 24131330 | Y24: 24262833 | Z24: 24266824 | AA24: 24252692 | AB24: 24225076 | AC24: 24237447 | AD24: 24093179 | AE24: 23816242 | AF24: 23576422 | AG24: 23232940 | AH24: 22717720 | AI24: 22101855 | AJ24: 22620585 | AK24: 23249063 | AL24: 23869179 | AM24: 24369094
B25: 19 New England | C25: Single Family | D25: Refrigeration | E25: =IF(D25="",E24,D25) -> Refrigeration | F25: Electricity | G25: RefTF#3 | H25: Sum of TOTSUBSIDY | I25: 4726838 | J25: 13466458 | K25: 14120400 | L25: 15094907 | M25: 0 | N25: 0 | O25: 0 | P25: 0 | Q25: 0 | R25: 0 | S25: 0 | T25: 0 | U25: 0 | V25: 0 | W25: 0 | X25: 0 | Y25: 0 | Z25: 0 | AA25: 0 | AB25: 0 | AC25: 0 | AD25: 0 | AE25: 0 | AF25: 0 | AG25: 0 | AH25: 0 | AI25: 0 | AJ25: 0 | AK25: 0 | AL25: 0 | AM25: 0
B26: 20 New England | C26: Single Family | D26: Refrigeration | E26: =IF(D26="",E25,D26) -> Refrigeration | F26: Electricity | H26: Sum of TOTPURCHASE | I26: 47267 | J26: 67331 | K26: 70601 | L26: 75473 | M26: 16102 | N26: 15991 | O26: 15837 | P26: 16434 | Q26: 17043 | R26: 17726 | S26: 18377 | T26: 18910 | U26: 19364 | V26: 19951 | W26: 20284 | X26: 20752 | Y26: 20915 | Z26: 20897 | AA26: 21026 | AB26: 20947 | AC26: 20978 | AD26: 20756 | AE26: 20579 | AF26: 20362 | AG26: 20108 | AH26: 19672 | AI26: 19170 | AJ26: 19544 | AK26: 20280 | AL26: 21124 | AM26: 21740
B27: 21 New England | C27: Single Family | D27: Refrigeration | E27: =IF(D27="",E26,D27) -> Refrigeration | F27: Electricity | H27: Sum of TOTINVEST | I27: 37814717 | J27: 59252418 | K27: 62129760 | L27: 66417593 | M27: 14170394 | N27: 14072334 | O27: 13937270 | P27: 14463015 | Q27: 14999293 | R27: 15599860 | S27: 16173149 | T27: 16641469 | U27: 17041615 | V27: 17557802 | W27: 17851260 | X27: 18262908 | Y27: 18405666 | Z27: 18389813 | AA27: 18503654 | AB27: 18434177 | AC27: 18461750 | AD27: 18265331 | AE27: 18110078 | AF27: 17919548 | AG27: 17695871 | AH27: 17312488 | AI27: 16870838 | AJ27: 17199974 | AK27: 17847856 | AL27: 18589902 | AM27: 19131718
B28: 22 New England | C28: Single Family | D28: Cooling | E28: =IF(D28="",E27,D28) -> Cooling | F28: Electricity | G28: CT_AIR#1 | H28: Sum of TOTSUBSIDY | I28: 0 | J28: 0 | K28: 0 | L28: 0 | M28: 0 | N28: 0 | O28: 0 | P28: 0 | Q28: 0 | R28: 0 | S28: 0 | T28: 0 | U28: 0 | V28: 0 | W28: 0 | X28: 0 | Y28: 0 | Z28: 0 | AA28: 0 | AB28: 0 | AC28: 0 | AD28: 0 | AE28: 0 | AF28: 0 | AG28: 0 | AH28: 0 | AI28: 0 | AJ28: 0 | AK28: 0 | AL28: 0 | AM28: 0
B29: 23 New England | C29: Single Family | D29: Cooling | E29: =IF(D29="",E28,D29) -> Cooling | F29: Electricity | H29: Sum of TOTPURCHASE | I29: 22254 | J29: 49768 | K29: 53717 | L29: 56009 | M29: 38471 | N29: 40976 | O29: 43875 | P29: 48472 | Q29: 48636 | R29: 48247 | S29: 47974 | T29: 47327 | U29: 46959 | V29: 47038 | W29: 47036 | X29: 47158 | Y29: 47283 | Z29: 47303 | AA29: 46507 | AB29: 46214 | AC29: 45608 | AD29: 44253 | AE29: 45143 | AF29: 46206 | AG29: 47071 | AH29: 47848 | AI29: 48330 | AJ29: 48818 | AK29: 48814 | AL29: 48702 | AM29: 48783
B30: 24 New England | C30: Single Family | D30: Cooling | E30: =IF(D30="",E29,D30) -> Cooling | F30: Electricity | H30: Sum of TOTINVEST | I30: 37832347 | J30: 84608767 | K30: 91320638 | L30: 95217437 | M30: 65403420 | N30: 69659933 | O30: 74588578 | P30: 82403952 | Q30: 82682896 | R30: 82020312 | S30: 81557980 | T30: 80456438 | U30: 79831972 | V30: 79965356 | W30: 79962086 | X30: 80171486 | Y30: 80382804 | Z30: 80415866 | AA30: 79063114 | AB30: 78564992 | AC30: 77534424 | AD30: 75230450 | AE30: 76745696 | AF30: 78552862 | AG30: 80021869 | AH30: 81343775 | AI30: 82162557 | AJ30: 82992508 | AK30: 82985931 | AL30: 82795979 | AM30: 82933594
B31: 25 New England | C31: Single Family | D31: Cooling | E31: =IF(D31="",E30,D31) -> Cooling | F31: Electricity | G31: CT_AIR#2 | H31: Sum of TOTSUBSIDY | I31: 0 | J31: 0 | K31: 0 | L31: 0 | M31: 0 | N31: 0 | O31: 0 | P31: 0 | Q31: 0 | R31: 0 | S31: 0 | T31: 0 | U31: 0 | V31: 0 | W31: 0 | X31: 0 | Y31: 0 | Z31: 0 | AA31: 0 | AB31: 0 | AC31: 0 | AD31: 0 | AE31: 0 | AF31: 0 | AG31: 0 | AH31: 0 | AI31: 0 | AJ31: 0 | AK31: 0 | AL31: 0 | AM31: 0
B32: 26 New England | C32: Single Family | D32: Cooling | E32: =IF(D32="",E31,D32) -> Cooling | F32: Electricity | H32: Sum of TOTPURCHASE | I32: 22954 | J32: 0 | K32: 0 | L32: 0 | M32: 19975 | N32: 21273 | O32: 22772 | P32: 24465 | Q32: 24485 | R32: 24662 | S32: 24837 | T32: 25093 | U32: 25336 | V32: 25865 | W32: 26184 | X32: 26457 | Y32: 26680 | Z32: 27056 | AA32: 27290 | AB32: 27277 | AC32: 27017 | AD32: 26237 | AE32: 27555 | AF32: 28692 | AG32: 29700 | AH32: 30494 | AI32: 31127 | AJ32: 31520 | AK32: 32192 | AL32: 32686 | AM32: 33081
B33: 27 New England | C33: Single Family | D33: Cooling | E33: =IF(D33="",E32,D33) -> Cooling | F33: Electricity | H33: Sum of TOTINVEST | I33: 41891684 | J33: 0 | K33: 0 | L33: 0 | M33: 37952576 | N33: 40419676 | O33: 43267468 | P33: 46484712 | Q33: 46522100 | R33: 46858356 | S33: 47191012 | T33: 47677744 | U33: 48139504 | V33: 49145228 | W33: 49750296 | X33: 50268464 | Y33: 50693012 | Z33: 51408148 | AA33: 51852300 | AB33: 51826828 | AC33: 51333524 | AD33: 49851680 | AE33: 52355352 | AF33: 54516108 | AG33: 56431748 | AH33: 57938696 | AI33: 59143124 | AJ33: 59889428 | AK33: 61164988 | AL33: 62104516 | AM33: 62854900
B34: 28 New England | C34: Single Family | D34: Cooling | E34: =IF(D34="",E33,D34) -> Cooling | F34: Electricity | G34: CT_AIR#3 | H34: Sum of TOTSUBSIDY | I34: 5646 | J34: 128 | K34: 2187 | L34: 8506 | M34: 0 | N34: 0 | O34: 0 | P34: 0 | Q34: 0 | R34: 0 | S34: 0 | T34: 0 | U34: 0 | V34: 0 | W34: 0 | X34: 0 | Y34: 0 | Z34: 0 | AA34: 0 | AB34: 0 | AC34: 0 | AD34: 0 | AE34: 0 | AF34: 0 | AG34: 0 | AH34: 0 | AI34: 0 | AJ34: 0 | AK34: 0 | AL34: 0 | AM34: 0
B35: 29 New England | C35: Single Family | D35: Cooling | E35: =IF(D35="",E34,D35) -> Cooling | F35: Electricity | H35: Sum of TOTPURCHASE | I35: 6 | J35: 0 | K35: 12 | L35: 47 | M35: 14 | N35: 14 | O35: 17 | P35: 23 | Q35: 27 | R35: 29 | S35: 31 | T35: 34 | U35: 36 | V35: 40 | W35: 44 | X35: 49 | Y35: 54 | Z35: 59 | AA35: 61 | AB35: 66 | AC35: 68 | AD35: 72 | AE35: 73 | AF35: 77 | AG35: 81 | AH35: 85 | AI35: 89 | AJ35: 91 | AK35: 95 | AL35: 97 | AM35: 95
B36: 30 New England | C36: Single Family | D36: Cooling | E36: =IF(D36="",E35,D36) -> Cooling | F36: Electricity | H36: Sum of TOTINVEST | I36: 27986 | J36: 3256 | K36: 55302 | L36: 215036 | M36: 65623 | N36: 66144 | O36: 79626 | P36: 106755 | Q36: 123487 | R36: 135681 | S36: 145408 | T36: 155092 | U36: 167902 | V36: 183492 | W36: 200490 | X36: 225457 | Y36: 249294 | Z36: 269591 | AA36: 281942 | AB36: 301586 | AC36: 312714 | AD36: 329309 | AE36: 334245 | AF36: 351133 | AG36: 370491 | AH36: 391173 | AI36: 405154 | AJ36: 417252 | AK36: 433704 | AL36: 441501 | AM36: 435067
B37: 31 New England | C37: Single Family | D37: Cooling | E37: =IF(D37="",E36,D37) -> Cooling | F37: Electricity | G37: CT_AIR#4 | H37: Sum of TOTSUBSIDY | I37: 1088995 | J37: 12209 | K37: 25941 | L37: 63211 | M37: 0 | N37: 0 | O37: 0 | P37: 0 | Q37: 0 | R37: 0 | S37: 0 | T37: 0 | U37: 0 | V37: 0 | W37: 0 | X37: 0 | Y37: 0 | Z37: 0 | AA37: 0 | AB37: 0 | AC37: 0 | AD37: 0 | AE37: 0 | AF37: 0 | AG37: 0 | AH37: 0 | AI37: 0 | AJ37: 0 | AK37: 0 | AL37: 0 | AM37: 0
B38: 32 New England | C38: Single Family | D38: Cooling | E38: =IF(D38="",E37,D38) -> Cooling | F38: Electricity | H38: Sum of TOTPURCHASE | I38: 720 | J38: 42 | K38: 116 | L38: 325 | M38: 94 | N38: 112 | O38: 131 | P38: 161 | Q38: 188 | R38: 213 | S38: 242 | T38: 261 | U38: 285 | V38: 313 | W38: 343 | X38: 385 | Y38: 422 | Z38: 450 | AA38: 464 | AB38: 488 | AC38: 522 | AD38: 545 | AE38: 551 | AF38: 578 | AG38: 608 | AH38: 642 | AI38: 663 | AJ38: 682 | AK38: 717 | AL38: 739 | AM38: 775
B39: 33 New England | C39: Single Family | D39: Cooling | E39: =IF(D39="",E38,D39) -> Cooling | F39: Electricity | H39: Sum of TOTINVEST | I39: 3281026 | J39: 192668 | K39: 533419 | L39: 1484459 | M39: 434025 | N39: 513136 | O39: 598459 | P39: 737053 | Q39: 861272 | R39: 971738 | S39: 1104053 | T39: 1195194 | U39: 1302828 | V39: 1429228 | W39: 1561565 | X39: 1756364 | Y39: 1924352 | Z39: 2051486 | AA39: 2113720 | AB39: 2221917 | AC39: 2381253 | AD39: 2480946 | AE39: 2511575 | AF39: 2634854 | AG39: 2770319 | AH39: 2926128 | AI39: 3022314 | AJ39: 3109767 | AK39: 3266187 | AL39: 3365957 | AM39: 3527816
B40: 34 New England | C40: Single Family | D40: Cooling | E40: =IF(D40="",E39,D40) -> Cooling | F40: Electricity | G40: ELEC_HP1 | H40: Sum of TOTSUBSIDY | I40: 0 | J40: 0 | K40: 0 | L40: 0 | M40: 0 | N40: 0 | O40: 0 | P40: 0 | Q40: 0 | R40: 0 | S40: 0 | T40: 0 | U40: 0 | V40: 0 | W40: 0 | X40: 0 | Y40: 0 | Z40: 0 | AA40: 0 | AB40: 0 | AC40: 0 | AD40: 0 | AE40: 0 | AF40: 0 | AG40: 0 | AH40: 0 | AI40: 0 | AJ40: 0 | AK40: 0 | AL40: 0 | AM40: 0
B41: 35 New England | C41: Single Family | D41: Cooling | E41: =IF(D41="",E40,D41) -> Cooling | F41: Electricity | H41: Sum of TOTPURCHASE | I41: 906 | J41: 6191 | K41: 6523 | L41: 6509 | M41: 8406 | N41: 8545 | O41: 8780 | P41: 9102 | Q41: 9490 | R41: 10010 | S41: 10227 | T41: 10674 | U41: 11159 | V41: 11549 | W41: 12027 | X41: 12633 | Y41: 13305 | Z41: 13952 | AA41: 14603 | AB41: 15230 | AC41: 18257 | AD41: 18437 | AE41: 18597 | AF41: 18817 | AG41: 18981 | AH41: 19241 | AI41: 19675 | AJ41: 20086 | AK41: 20370 | AL41: 20490 | AM41: 21943
B42: 36 New England | C42: Single Family | D42: Cooling | E42: =IF(D42="",E41,D42) -> Cooling | F42: Electricity | H42: Sum of TOTINVEST | I42: 0 | J42: 0 | K42: 0 | L42: 0 | M42: 0 | N42: 0 | O42: 0 | P42: 0 | Q42: 0 | R42: 0 | S42: 0 | T42: 0 | U42: 0 | V42: 0 | W42: 0 | X42: 0 | Y42: 0 | Z42: 0 | AA42: 0 | AB42: 0 | AC42: 0 | AD42: 0 | AE42: 0 | AF42: 0 | AG42: 0 | AH42: 0 | AI42: 0 | AJ42: 0 | AK42: 0 | AL42: 0 | AM42: 0
...

Sheet RECS HC2.1
A1: Preliminary Release: March 28, 2011
A2: Final Release: April 2013
A3: Table HC2.1 Structural and Geographic Characteristics of U.S. Homes, By Housing Unit Type, 2009
A4: Million Housing Units, Final
C5: Housing Unit Type
C7: Single-Family Units | E7: Apartments in Buildings With
B8: Total U.S.1 (millions)
A9: Structural and Geographic Characteristics | E9: 2 to 4 Units | F9: 5 or More Units | G9: Mobile Homes
C10: Detached | D10: Attached
A12: Total Homes | B12: 113.6 | C12: 71.8 | D12: 6.7 | E12: 9 | F12: 19.1 | G12: 6.9
A14: Census Region and Division
A15: Northeast | B15: 20.8 | C15: 10.9 | D15: 1.8 | E15: 3.1 | F15: 4.4 | G15: 0.5
A16: New England | B16: 5.5 | C16: 3.1 | D16: 0.3 | E16: 1 | F16: 1 | G16: 0.1
A17: Middle Atlantic | B17: 15.3 | C17: 7.8 | D17: 1.5 | E17: 2.1 | F17: 3.4 | G17: 0.4
A18: Midwest | B18: 25.9 | C18: 18 | D18: 1.2 | E18: 1.9 | F18: 3.7 | G18: 1.1
A19: East North Central | B19: 17.9 | C19: 12.3 | D19: 0.8 | E19: 1.5 | F19: 2.7 | G19: 0.6
A20: West North Central | B20: 8.1 | C20: 5.7 | D20: 0.4 | E20: 0.4 | F20: 1 | G20: 0.5
A21: South | B21: 42.1 | C21: 27.6 | D21: 2.1 | E21: 2.2 | F21: 6.2 | G21: 3.9
A22: South Atlantic | B22: 22.2 | C22: 13.8 | D22: 1.3 | E22: 1.1 | F22: 3.5 | G22: 2.4
A23: East South Central | B23: 7.1 | C23: 5.2 | D23: 0.2 | E23: 0.3 | F23: 0.7 | G23: 0.7
A24: West South Central | B24: 12.8 | C24: 8.5 | D24: 0.6 | E24: 0.8 | F24: 2 | G24: 0.9
A25: West | B25: 24.8 | C25: 15.4 | D25: 1.5 | E25: 1.7 | F25: 4.7 | G25: 1.4
A26: Mountain | B26: 7.9 | C26: 5.5 | D26: 0.5 | E26: 0.3 | F26: 0.9 | G26: 0.7
... A29: Pacific | B29: 16.9 | C29: 9.9 | D29: 1 | E29: 1.4 | F29: 3.8 | G29: 0.8
A31: Urban and Rural2
A32: Urban | B32: 88.1 | C32: 51.3 | D32: 6.3 | E32: 8.5 | F32: 18.5 | G32: 3.5
A33: Rural | B33: 25.5 | C33: 20.5 | D33: 0.4 | E33: 0.5 | F33: 0.7 | G33: 3.5
A35: Metropolitan and Micropolitan
A36: Statistical Area
A37: In metropolitan statistical area | B37: 94 | C37: 57.3 | D37: 6.2 | E37: 7.9 | F37: 18.1 | G37: 4.5
A38: In micropolitan statistical area | B38: 12.4 | C38: 9.1 | D38: 0.4 | E38: 0.7 | F38: 0.7 | G38: 1.4
A39: Not in metropolitan or micropolitan
A40: statistical area | B40: 7.2 | C40: 5.4 | D40: 0.1 | E40: 0.3 | F40: 0.2 | G40: 1.1
A42: Climate Region3
A43: Very Cold/Cold | B43: 38.8 | C43: 25.1 | D43: 2.4 | E43: 3.9 | F43: 5.8 | G43: 1.6
A44: Mixed-Humid | B44: 35.4 | C44: 22.1 | D44: 2.3 | E44: 2.4 | F44: 6.2 | G44: 2.4
A45: Mixed-Dry/Hot-Dry | B45: 14.1 | C45: 8.8 | D45: 0.7 | E45: 1 | F45: 2.8 | G45: 0.8
A46: Hot-Humid | B46: 19.1 | C46: 12.2 | D46: 0.9 | E46: 1.2 | F46: 2.8 | G46: 2
A47: Marine | B47: 6.3 | C47: 3.6 | D47: 0.5 | E47: 0.5 | F47: 1.5 | G47: 0.2
A49: Year of Construction
...

Sheet Calculations
A1: Residential
A2: Capital Expenditures in 2013 USD (total cost of components) | B2: 2014 | C2: 2015 | D2: 2016 | E2: 2017 | F2: 2018 | G2: 2019 | H2: 2020 | I2: 2021 | J2: 2022 | K2: 2023 | L2: 2024 | M2: 2025 | N2: 2026 | O2: 2027 | P2: 2028 | Q2: 2029 | R2: 2030 | S2: 2031 | T2: 2032 | U2: 2033 | V2: 2034 | W2: 2035 | X2: 2036 | Y2: 2037 | Z2: 2038 | AA2: 2039 | AB2: 2040 | AC2: 2041 | AD2: 2042 | AE2: 2043 | AF2: 2044 | AG2: 2045 | AH2: 2046 | AI2: 2047 | AJ2: 2048 | AK2: 2049 | AL2: 2050
A3: Heating | B3: =SUMIFS(Residential!M$7:M$7701,Residential!$E$7:$E$7701,"Heating",Residential!$H$7:$H$7701,"Sum of TOTINVEST") -> 9667720853 | C3: =SUMIFS(Residential!N$7:N$7701,Residential!$E$7:$E$7701,"Heating",Residential!$H$7:$H$7701,"Sum of TOTINVEST") -> 10050593045 | D3: =SUMIFS(Residential!O$7:O$7701,Residential!$E$7:$E$7701,"Heating",Residential!$H$7:$H$7701,"Sum of TOTINVEST") -> 10474442706 | E3: =SUMIFS(Residential!P$7:P$7701,Residential!$E$7:$E$7701,"Heating",Residential!$H$7:$H$7701,"Sum of TOTINVEST") -> 11268459465 | F3: =SUMIFS(Residential!Q$7:Q$7701,Residential!$E$7:$E$7701,"Heating",Residential!$H$7:$H$7701,"Sum of TOTINVEST") -> 11523907673 | G3: =SUMIFS(Residential!R$7:R$7701,Residential!$E$7:$E$7701,"Heating",Residential!$H$7:$H$7701,"Sum of TOTINVEST") -> 11767252466 | H3: =SUMIFS(Residential!S$7:S$7701,Residential!$E$7:$E$7701,"Heating",Residential!$H$7:$H$7701,"Sum of TOTINVEST") -> 12079708291 | I3: =SUMIFS(Residential!T$7:T$7701,Residential!$E$7:$E$7701,"Heating",Residential!$H$7:$H$7701,"Sum of TOTINVEST") -> 11938293473 | ... AB3: =SUMIFS(Residential!AM$7:AM$7701,Residential!$E$7:$E$7701,"Heating",Residential!$H$7:$H$7701,"Sum of TOTINVEST") -> 13264868416 | AC3: =TREND($P3:$AB3,$P$2:$AB$2,AC$2) -> 1.3194396e+10 | AD3: =TREND($P3:$AB3,$P$2:$AB$2,AD$2) -> 1.3273872e+10 | AE3: =TREND($P3:$AB3,$P$2:$AB$2,AE$2) -> 1.3353348e+10 | AF3: =TREND($P3:$AB3,$P$2:$AB$2,AF$2) -> 1.3432824e+10 | AG3: =TREND($P3:$AB3,$P$2:$AB$2,AG$2) -> 1.35123e+10 | AH3: =TREND($P3:$AB3,$P$2:$AB$2,AH$2) -> 1.3591775e+10 | AI3: =TREND($P3:$AB3,$P$2:$AB$2,AI$2) -> 1.3671251e+10 | AJ3: =TREND($P3:$AB3,$P$2:$AB$2,AJ$2) -> 1.3750727e+10 | ... AL3: =TREND($P3:$AB3,$P$2:$AB$2,AL$2) -> 1.3909679e+10
A4: Cooling and Ventilation | B4: =SUMIFS(Residential!M$7:M$7701,Residential!$E$7:$E$7701,"Cooling",Residential!$H$7:$H$7701,"Sum of TOTINVEST") -> 10937041372 | C4: =SUMIFS(Residential!N$7:N$7701,Residential!$E$7:$E$7701,"Cooling",Residential!$H$7:$H$7701,"Sum of TOTINVEST") -> 11697373294 | D4: =SUMIFS(Residential!O$7:O$7701,Residential!$E$7:$E$7701,"Cooling",Residential!$H$7:$H$7701,"Sum of TOTINVEST") -> 12495065905 | E4: =SUMIFS(Residential!P$7:P$7701,Residential!$E$7:$E$7701,"Cooling",Residential!$H$7:$H$7701,"Sum of TOTINVEST") -> 13483327925 | F4: =SUMIFS(Residential!Q$7:Q$7701,Residential!$E$7:$E$7701,"Cooling",Residential!$H$7:$H$7701,"Sum of TOTINVEST") -> 13722922776 | G4: =SUMIFS(Residential!R$7:R$7701,Residential!$E$7:$E$7701,"Cooling",Residential!$H$7:$H$7701,"Sum of TOTINVEST") -> 13742684670 | H4: =SUMIFS(Residential!S$7:S$7701,Residential!$E$7:$E$7701,"Cooling",Residential!$H$7:$H$7701,"Sum of TOTINVEST") -> 13741481995 | I4: =SUMIFS(Residential!T$7:T$7701,Residential!$E$7:$E$7701,"Cooling",Residential!$H$7:$H$7701,"Sum of TOTINVEST") -> 13675658941 | ... AB4: =SUMIFS(Residential!AM$7:AM$7701,Residential!$E$7:$E$7701,"Cooling",Residential!$H$7:$H$7701,"Sum of TOTINVEST") -> 15582119604 | AC4: =TREND($P4:$AB4,$P$2:$AB$2,AC$2) -> 1.5632483e+10 | AD4: =TREND($P4:$AB4,$P$2:$AB$2,AD$2) -> 1.5797578e+10 | AE4: =TREND($P4:$AB4,$P$2:$AB$2,AE$2) -> 1.5962672e+10 | AF4: =TREND($P4:$AB4,$P$2:$AB$2,AF$2) -> 1.6127766e+10 | AG4: =TREND($P4:$AB4,$P$2:$AB$2,AG$2) -> 1.6292861e+10 | AH4: =TREND($P4:$AB4,$P$2:$AB$2,AH$2) -> 1.6457955e+10 | AI4: =TREND($P4:$AB4,$P$2:$AB$2,AI$2) -> 1.662305e+10 | AJ4: =TREND($P4:$AB4,$P$2:$AB$2,AJ$2) -> 1.6788144e+10 | ... AL4: =TREND($P4:$AB4,$P$2:$AB$2,AL$2) -> 1.7118333e+10
A5: Envelope | B5: 0 | C5: 0 | D5: 0 | E5: 0 | F5: 0 | G5: 0 | H5: 0 | I5: 0 | J5: 0 | K5: 0 | L5: 0 | M5: 0 | N5: 0 | O5: 0 | P5: 0 | Q5: 0 | R5: 0 | S5: 0 | T5: 0 | U5: 0 | V5: 0 | W5: 0 | X5: 0 | Y5: 0 | Z5: 0 | AA5: 0 | AB5: 0 | AC5: =TREND($P5:$AB5,$P$2:$AB$2,AC$2) -> 0 | AD5: =TREND($P5:$AB5,$P$2:$AB$2,AD$2) -> 0 | AE5: =TREND($P5:$AB5,$P$2:$AB$2,AE$2) -> 0 | AF5: =TREND($P5:$AB5,$P$2:$AB$2,AF$2) -> 0 | AG5: =TREND($P5:$AB5,$P$2:$AB$2,AG$2) -> 0 | AH5: =TREND($P5:$AB5,$P$2:$AB$2,AH$2) -> 0 | AI5: =TREND($P5:$AB5,$P$2:$AB$2,AI$2) -> 0 | AJ5: =TREND($P5:$AB5,$P$2:$AB$2,AJ$2) -> 0 | ... AL5: =TREND($P5:$AB5,$P$2:$AB$2,AL$2) -> 0
A6: Lighting | B6: =SUMIFS(Residential!M$7:M$7701,Residential!$E$7:$E$7701,"Lighting",Residential!$H$7:$H$7701,"Sum of TOTINVEST") -> 5670571439 | C6: =SUMIFS(Residential!N$7:N$7701,Residential!$E$7:$E$7701,"Lighting",Residential!$H$7:$H$7701,"Sum of TOTINVEST") -> 5261095781 | D6: =SUMIFS(Residential!O$7:O$7701,Residential!$E$7:$E$7701,"Lighting",Residential!$H$7:$H$7701,"Sum of TOTINVEST") -> 5289787910 | E6: =SUMIFS(Residential!P$7:P$7701,Residential!$E$7:$E$7701,"Lighting",Residential!$H$7:$H$7701,"Sum of TOTINVEST") -> 5402620127 | F6: =SUMIFS(Residential!Q$7:Q$7701,Residential!$E$7:$E$7701,"Lighting",Residential!$H$7:$H$7701,"Sum of TOTINVEST") -> 5523361877 | G6: =SUMIFS(Residential!R$7:R$7701,Residential!$E$7:$E$7701,"Lighting",Residential!$H$7:$H$7701,"Sum of TOTINVEST") -> 5609671925 | H6: =SUMIFS(Residential!S$7:S$7701,Residential!$E$7:$E$7701,"Lighting",Residential!$H$7:$H$7701,"Sum of TOTINVEST") -> 8480695965 | I6: =SUMIFS(Residential!T$7:T$7701,Residential!$E$7:$E$7701,"Lighting",Residential!$H$7:$H$7701,"Sum of TOTINVEST") -> 6999952890 | ... AB6: =SUMIFS(Residential!AM$7:AM$7701,Residential!$E$7:$E$7701,"Lighting",Residential!$H$7:$H$7701,"Sum of TOTINVEST") -> 2716481490 | AC6: =TREND($P6:$AB6,$P$2:$AB$2,AC$2) -> 2.3861552e+09 | AD6: =TREND($P6:$AB6,$P$2:$AB$2,AD$2) -> 2.201026e+09 | AE6: =TREND($P6:$AB6,$P$2:$AB$2,AE$2) -> 2.0158967e+09 | AF6: =TREND($P6:$AB6,$P$2:$AB$2,AF$2) -> 1.8307675e+09 | AG6: =TREND($P6:$AB6,$P$2:$AB$2,AG$2) -> 1.6456382e+09 | AH6: =TREND($P6:$AB6,$P$2:$AB$2,AH$2) -> 1.460509e+09 | AI6: =TREND($P6:$AB6,$P$2:$AB$2,AI$2) -> 1.2753797e+09 | AJ6: =TREND($P6:$AB6,$P$2:$AB$2,AJ$2) -> 1.0902505e+09 | ... AL6: =TREND($P6:$AB6,$P$2:$AB$2,AL$2) -> 7.1999197e+08
