Workbook
Name Fraction_coal: [1]About!$C$50
Name Percent_rural: [1]About!$A$77
Name Percent_urban: [1]About!$A$76
Name quadrillion: [1]About!$B$79
Name Table4: #REF!
Name Table5: #REF!

Sheet About
A1: ICpUEfEBE Incremental Cost per Unit Energy for Electrified Building Equipment
A3: Sources: | B3: Cost of technologies except commerial heat pumps | D3: Commercial heating and water heating heat pump costs
B4: EIA | D4: NREL
B5: 2018 | D5: 2018
B6: Updated Buildings Sector Appliance and Equipment Costs and Efficiencies | D6: Electrification Futures Study Technology Report Figure Data
B7: https://www.eia.gov/analysis/studies/buildings/equipcosts/pdf/full.pdf | D7: https://data.nrel.gov/system/files/93/EFS_70485_figure_data.xlsx
B8: p. 9, 12, 29, 46, 51, 54, 58, 90, 92, 120, 123 | D8: Tables 22 and 23
B10: Residential building equipment stock and average annual energy consumption | D10: Commercial building equipment load factors
B11: EIA | D11: NREL
B12: 2021 | D12: 2018
B13: AEO 2021 | D13: Electrification Futures Study: End-Use Electric Technology Cost and Performance Projections through 2050
B14: https://www.eia.gov/outlooks/aeo/tables_side.php | D14: https://www.nrel.gov/docs/fy18osti/70485.pdf
B15: Tables 4 and 21 | D15: P.90
A17: Notes:
A18: All policy-driven electrification in the EPS is assumed to rely on heat pumps,
A19: not electric resistance heating
A21: Methodology:
A22: For residential buildings, we calculate the average energy used by equipment
A23: of different types, which allows us to find a $/BTU value. We then estimate
A24: the cost of switching to heat pump equipment based on the data from EIA
A25: and annual energy consumption.
A27: For commercial buildings, we lack data on annual energy use, but the NREL
A28: report provides data on annual heating and water heating utilization rates
A29: and the costs are normalized to $/(kBTU/hr) input, so we standardize the costs
A30: from EIA and then estimate the cost per BTU shifted using the annual load factors.
... A52: 2017 to 2012 USD
A53: 0.9366596
A54: 2016 to 2012 USD
A55: 0.95661377

Sheet EIA Costs
A1: Residential Gas Fired Furnaces
A2: DATA | B2: 2009 | C2: 2015 | D2: 2017 | H2: 2020 | J2: 2030 | L2: 2040 | N2: 2050 | P2: 2060
B3: Installed Base | C3: Installed Base | D3: Current Standard | E3: Typical | F3: ENERGY STAR (South) | G3: High | H3: Typical | I3: High | J3: Typical | K3: High | L3: Typical | M3: High | N3: Typical | O3: High | P3: Typical | Q3: High
A4: Typical Input Capacity (kBtu/h) | B4: 80 | C4: 80 | D4: 80 | E4: 80 | F4: 80 | G4: 80 | H4: 80 | I4: 80 | J4: 80 | K4: 80 | L4: 80 | M4: 80 | N4: 80 | O4: 80 | P4: 80 | Q4: 80
A5: AFUE (%) | B5: 80 | C5: 80 | D5: 80 | E5: 80 | F5: 90 | G5: 99 | H5: 80 | I5: 99 | J5: 80 | K5: 99 | L5: 80 | M5: 99 | N5: 80 | O5: 99 | P5: 80 | Q5: 99
A6: Electric Consumption (kWh/yr)* | B6: 548 | C6: 522 | D6: 470 | E6: 470 | F6: 408 | G6: 418 | H6: 329 | I6: 334 | J6: 329 | K6: 334 | L6: 329 | M6: 334 | N6: 329 | O6: 334 | P6: 329 | Q6: 334
A7: Average Life (yrs)** | B7: 16 | C7: 16 | D7: 16 | E7: 16 | F7: 16 | G7: 16 | H7: 16 | I7: 16 | J7: 16 | K7: 16 | L7: 16 | M7: 16 | N7: 16 | O7: 16 | P7: 16 | Q7: 16
B8: 27 | C8: 27 | D8: 27 | E8: 27 | F8: 27 | G8: 27 | H8: 27 | I8: 27 | J8: 27 | K8: 27 | L8: 27 | M8: 27 | N8: 27 | O8: 27 | P8: 27 | Q8: 27
A9: Retail Equipment Cost (2017$) | B9: 840 | C9: 860 | D9: 890 | E9: 890 | F9: 1150 | G9: 1620 | H9: 1080 | I9: 1620 | J9: 1080 | K9: 1620 | L9: 1080 | M9: 1620 | N9: 1080 | O9: 1620 | P9: 1080 | Q9: 1620
A10: Total Installed Cost (2017$) | B10: 2000 | C10: 2020 | D10: 2050 | E10: 2050 | F10: 2560 | G10: 3040 | H10: 2240 | I10: 3040 | J10: 2240 | K10: 3040 | L10: 2240 | M10: 3040 | N10: 2240 | O10: 3040 | P10: 2240 | Q10: 3040
A11: Annual Maintenance Cost (2017$) | B11: 40 | C11: 40 | D11: 40 | E11: 40 | F11: 40 | G11: 40 | H11: 40 | I11: 40 | J11: 40 | K11: 40 | L11: 40 | M11: 40 | N11: 40 | O11: 40 | P11: 40 | Q11: 40
A13: Residential Oil Fired Furnaces
A14: DATA | B14: 2009 | C14: 2015 | D14: 2017 | H14: 2020 | J14: 2030 | L14: 2040 | N14: 2050 | P14: 2060
B15: Installed Base | C15: Installed Base | D15: Current Standard | E15: Typical | F15: ENERGY STAR | G15: High | H15: Typical | I15: High Typical | K15: High | L15: Typical | M15: High | N15: Typical | O15: High | P15: Typical | Q15: High
A16: Typical Input Capacity (kBtu/h) | B16: 105 | C16: 105 | D16: 105 | E16: 105 | F16: 105 | G16: 105 | H16: 105 | I16: 105 | J16: 105 | K16: 105 | L16: 105 | M16: 105 | N16: 105 | O16: 105 | P16: 105 | Q16: 105
A17: AFUE (%) | B17: 80 | C17: 83 | D17: 83 | E17: 83 | F17: 85 | G17: 97 | H17: 83 | I17: 97 | J17: 84 | K17: 97 | L17: 84 | M17: 97 | N17: 84 | O17: 97 | P17: 84 | Q17: 97
A18: Electric Consumption (kWh/yr)* | B18: 490 | C18: 477 | D18: 477 | E18: 477 | F18: 466 | G18: 410 | H18: 477 | I18: 410 | J18: 472 | K18: 410 | L18: 472 | M18: 410 | N18: 472 | O18: 410 | P18: 472 | Q18: 410
A19: Average Life (yrs)** | B19: 20 | C19: 20 | D19: 20 | E19: 20 | F19: 20 | G19: 20 | H19: 20 | I19: 20 | J19: 20 | K19: 20 | L19: 20 | M19: 20 | N19: 20 | O19: 20 | P19: 20 | Q19: 20
B20: 33 | C20: 33 | D20: 33 | E20: 33 | F20: 33 | G20: 33 | H20: 33 | I20: 33 | J20: 33 | K20: 33 | L20: 33 | M20: 33 | N20: 33 | O20: 33 | P20: 33 | Q20: 33
A21: Retail Equipment Cost (2017$) | B21: 2150 | C21: 2200 | D21: 2200 | E21: 2200 | F21: 2250 | G21: 2700 | H21: 2200 | I21: 2700 | J21: 2250 | K21: 2700 | L21: 2250 | M21: 2700 | N21: 2250 | O21: 2700 | P21: 2250 | Q21: 2700
B22: 2350 | C22: 2900 | D22: 2900 | E22: 2900 | F22: 2950 | G22: 3450 | H22: 2900 | I22: 3450 | J22: 2950 | K22: 3450 | L22: 2950 | M22: 3450 | N22: 2950 | O22: 3450 | P22: 2950 | Q22: 3450
A23: Total Installed Cost (2017$) | B23: 2700 | C23: 2750 | D23: 2750 | E23: 2750 | F23: 2950 | G23: 4350 | H23: 2750 | I23: 4350 | J23: 2750 | K23: 4350 | L23: 2750 | M23: 4350 | N23: 2750 | O23: 4350 | P23: 2750 | Q23: 4350
B24: 3400 | C24: 5500 | D24: 5500 | E24: 5500 | F24: 5750 | G24: 8550 | H24: 5500 | I24: 8550 | J24: 5700 | K24: 8550 | L24: 5700 | M24: 8550 | N24: 5700 | O24: 8550 | P24: 5700 | Q24: 8550
A25: Annual Maintenance Cost (2017$) | B25: 70 | C25: 70 | D25: 70 | E25: 70 | F25: 70 | G25: 200 | H25: 70 | I25: 200 | J25: 70 | K25: 200 | L25: 70 | M25: 200 | N25: 70 | O25: 200 | P25: 70 | Q25: 200
A27: Residential Wood Pellet Stoves
A28: DATA | B28: 2009 | C28: 2015 | D28: 2017 | F28: 2020 | H28: 2030 | J28: 2040 | L28: 2050 | N28: 2060
B29: Installed Base | C29: Installed Base | D29: Typical | E29: High | F29: Typical | G29: High | H29: Typical | I29: High | J29: Typical | K29: High | L29: Typical | M29: High | N29: Typical | O29: High
A30: Typical Capacity (kBtu/h) | B30: 50 | C30: 50 | D30: 50 | E30: 50 | F30: 50 | G30: 50 | H30: 50 | I30: 50 | J30: 50 | K30: 50 | L30: 50 | M30: 50 | N30: 50 | O30: 50
A31: Efficiency (HHV) | B31: 65 | C31: 70 | D31: 76 | E31: 87 | F31: 76 | G31: 87 | H31: 77 | I31: 87 | J31: 78 | K31: 88 | L31: 79 | M31: 89 | N31: 79 | O31: 89
A32: Annual Electricity Consumption (kWh) | B32: 600 | C32: 600 | D32: 600 | E32: 600 | F32: 600 | G32: 600 | H32: 600 | I32: 600 | J32: 600 | K32: 600 | L32: 600 | M32: 600 | N32: 600 | O32: 600
A33: Average Life (yrs) | B33: 12 | C33: 12 | D33: 12 | E33: 12 | F33: 12 | G33: 12 | H33: 12 | I33: 12 | J33: 12 | K33: 12 | L33: 12 | M33: 12 | N33: 12 | O33: 12
B34: 25 | C34: 25 | D34: 25 | E34: 25 | F34: 25 | G34: 25 | H34: 25 | I34: 25 | J34: 25 | K34: 25 | L34: 25 | M34: 25 | N34: 25 | O34: 25
A35: Retail Equipment Cost (2017$) | B35: 3300 | C35: 3300 | D35: 3300 | E35: 4000 | F35: 3300 | G35: 4000 | H35: 3400 | I35: 4000 | J35: 3500 | K35: 4100 | L35: 3600 | M35: 4200 | N35: 3600 | O35: 4200
A36: Total Installed Cost (2017$) | B36: 4700 | C36: 4700 | D36: 4700 | E36: 5400 | F36: 4700 | G36: 5400 | H36: 4800 | I36: 5400 | J36: 4900 | K36: 5500 | L36: 5000 | M36: 5600 | N36: 5000 | O36: 5600
A37: Annual Maintenance Cost (2017$) | B37: 260 | C37: 260 | D37: 260 | E37: 260 | F37: 260 | G37: 260 | H37: 260 | I37: 260 | J37: 260 | K37: 260 | L37: 260 | M37: 260 | N37: 260 | O37: 260
A39: Residential Air Source Heat Pumps
A40: DATA | B40: 2009 | C40: 2015 | D40: 2017 | H40: 2020 | J40: 2030** | L40: 2040 | N40: 2050 | P40: 2060
B41: Installed Base | C41: Installed Base | D41: Current Standard | E41: Typical | F41: ENERGY STAR | G41: High | H41: Typical | I41: High | J41: Typical | K41: High | L41: Typical | M41: High | N41: Typical | O41: High | P41: Typical | Q41: High
A42: Typical Capacity (kBtu/h) | B42: 36 | C42: 36 | D42: 36 | E42: 36 | F42: 36 | G42: 36 | H42: 36 | I42: 36 | J42: 36 | K42: 36 | L42: 36 | M42: 36 | N42: 36 | O42: 36 | P42: 36 | Q42: 36
A43: SEER (Cooling)* | B43: 12 | C43: 13.1 | D43: 14 | E43: 15.3 | F43: 15 | G43: 19 | H43: 15.3 | I43: 19 | J43: 15.8 | K43: 19 | L43: 15.8 | M43: 19 | N43: 15.8 | O43: 19 | P43: 15.8 | Q43: 19
...

Sheet EIA AEO Table 4
B1: highogs.d120120a | C1: 2020 | D1: 2021 | E1: 2022 | F1: 2023 | G1: 2024 | H1: 2025 | I1: 2026 | J1: 2027 | K1: 2028 | L1: 2029 | M1: 2030 | N1: 2031 | O1: 2032 | P1: 2033 | Q1: 2034 | R1: 2035 | S1: 2036 | T1: 2037 | U1: 2038 | V1: 2039 | W1: 2040 | X1: 2041 | Y1: 2042 | Z1: 2043 | AA1: 2044 | AB1: 2045 | AC1: 2046 | AD1: 2047 | AE1: 2048 | AF1: 2049 | AG1: 2050
C3: Report | D3: Annual Energy Outlook 2021
C4: Scenario | D4: ref2021 | G4: Reference case
C5: Datekey | D5: d113020a
C6: Release Date | E6: January 2021
A10: RKI000 | B10: 4. Residential Sector Key Indicators and Consumption | AR10: Compound
B11: (quadrillion Btu, unless otherwise noted) | AR11: Growth
AH12: 2051-2060年数据用2020-2050年增速计算 | AR12: 2020-2050
B13: Key Indicators and Consumption | C13: 2020 | D13: 2021 | E13: 2022 | F13: 2023 | G13: 2024 | H13: 2025 | I13: 2026 | J13: 2027 | K13: 2028 | L13: 2029 | M13: 2030 | N13: 2031 | O13: 2032 | P13: 2033 | Q13: 2034 | R13: 2035 | S13: 2036 | T13: 2037 | U13: 2038 | V13: 2039 | W13: 2040 | X13: 2041 | Y13: 2042 | Z13: 2043 | AA13: 2044 | AB13: 2045 | AC13: 2046 | AD13: 2047 | AE13: 2048 | AF13: 2049 | AG13: 2050 | AH13: 2051 | AI13: 2052 | AJ13: 2053 | AK13: 2054 | AL13: 2055 | AM13: 2056 | AN13: 2057 | AO13: 2058 | AP13: 2059 | AQ13: 2060 | AR13: (percent)
B15: Key Indicators
B16: Households (millions)
A17: RKI000:ba_Single-Family | B17: Single-Family | C17: 84.750443 | D17: 85.593651 | E17: 86.439354 | F17: 87.273476 | G17: 88.112289 | H17: 88.984467 | I17: 89.856285 | J17: 90.700256 | K17: 91.51667 | L17: 92.31514 | M17: 93.093277 | N17: 93.847504 | O17: 94.588799 | P17: 95.310699 | Q17: 96.006424 | R17: 96.697853 | S17: 97.37767 | T17: 98.047127 | U17: 98.708321 | V17: 99.360046 | W17: 100.01558 | X17: 100.67042 | Y17: 101.32133 | Z17: 101.97403 | AA17: 102.632 | AB17: 103.29288 | AC17: 103.95903 | AD17: 104.62138 | AE17: 105.2791 | AF17: 105.93704 | AG17: 106.59597 | AH17: =AG17*(1+$AR17) -> 107.41399 | AI17: =AH17*(1+$AR17) -> 108.23828 | AJ17: =AI17*(1+$AR17) -> 109.0689 | AK17: =AJ17*(1+$AR17) -> 109.9059 | AL17: =AK17*(1+$AR17) -> 110.74932 | AM17: =AL17*(1+$AR17) -> 111.59921 | AN17: =AM17*(1+$AR17) -> 112.45562 | AO17: =AN17*(1+$AR17) -> 113.3186 | ... AQ17: =AP17*(1+$AR17) -> 115.06449 | AR17: 0.007674
A18: RKI000:ba_Multifamily | B18: Multifamily | C18: 31.968704 | D18: 32.227837 | E18: 32.484608 | F18: 32.738888 | G18: 33.007179 | H18: 33.292564 | I18: 33.572525 | J18: 33.83012 | K18: 34.072906 | L18: 34.306412 | M18: 34.532425 | N18: 34.747349 | O18: 34.956161 | P18: 35.154221 | Q18: 35.343121 | R18: 35.533417 | S18: 35.72086 | T18: 35.907597 | U18: 36.095905 | V18: 36.288265 | W18: 36.482738 | X18: 36.677246 | Y18: 36.872318 | Z18: 37.067024 | AA18: 37.256569 | AB18: 37.445789 | AC18: 37.632339 | AD18: 37.817364 | AE18: 38.004612 | AF18: 38.195267 | AG18: 38.390739 | AH18: =AG18*(1+$AR18) -> 38.625729 | AI18: =AH18*(1+$AR18) -> 38.862157 | AJ18: =AI18*(1+$AR18) -> 39.100032 | AK18: =AJ18*(1+$AR18) -> 39.339363 | AL18: =AK18*(1+$AR18) -> 39.58016 | AM18: =AL18*(1+$AR18) -> 39.82243 | AN18: =AM18*(1+$AR18) -> 40.066183 | AO18: =AN18*(1+$AR18) -> 40.311428 | ... AQ18: =AP18*(1+$AR18) -> 40.806431 | AR18: 0.006121
A19: RKI000:ba_MobileHomes | B19: Mobile Homes | C19: 6.663464 | D19: 6.648326 | E19: 6.634981 | F19: 6.627098 | G19: 6.630111 | H19: 6.643839 | I19: 6.664732 | J19: 6.675515 | K19: 6.675215 | L19: 6.664383 | M19: 6.643749 | N19: 6.616388 | O19: 6.58721 | P19: 6.557878 | Q19: 6.529199 | R19: 6.505653 | S19: 6.485949 | T19: 6.466928 | U19: 6.447885 | V19: 6.43115 | W19: 6.419676 | X19: 6.411514 | Y19: 6.40536 | Z19: 6.400518 | AA19: 6.396067 | AB19: 6.392113 | AC19: 6.388073 | AD19: 6.381184 | AE19: 6.37248 | AF19: 6.363905 | AG19: 6.35391 | AH19: =AG19*(1+$AR19) -> 6.3438454 | AI19: =AH19*(1+$AR19) -> 6.3337968 | AJ19: =AI19*(1+$AR19) -> 6.323764 | AK19: =AJ19*(1+$AR19) -> 6.3137472 | AL19: =AK19*(1+$AR19) -> 6.3037462 | AM19: =AL19*(1+$AR19) -> 6.2937611 | AN19: =AM19*(1+$AR19) -> 6.2837918 | AO19: =AN19*(1+$AR19) -> 6.2738382 | ... AQ19: =AP19*(1+$AR19) -> 6.2539784 | AR19: -0.001584
A20: RKI000:ba_Total | B20: Total | C20: 123.38261 | D20: 124.46981 | E20: 125.55894 | F20: 126.63946 | G20: 127.74958 | H20: 128.92087 | I20: 130.09354 | J20: 131.2059 | K20: 132.26479 | L20: 133.28593 | M20: 134.26945 | N20: 135.21124 | O20: 136.13216 | P20: 137.0228 | Q20: 137.87875 | R20: 138.73691 | S20: 139.58447 | T20: 140.42166 | U20: 141.25212 | V20: 142.07947 | W20: 142.918 | X20: 143.75919 | Y20: 144.59901 | Z20: 145.44156 | AA20: 146.28465 | AB20: 147.1308 | AC20: 147.97945 | AD20: 148.81992 | AE20: 149.65619 | AF20: 150.49622 | AG20: 151.34062 | AH20: =AG20*(1+$AR20) -> 152.37443 | AI20: =AH20*(1+$AR20) -> 153.4153 | AJ20: =AI20*(1+$AR20) -> 154.46328 | AK20: =AJ20*(1+$AR20) -> 155.51842 | AL20: =AK20*(1+$AR20) -> 156.58076 | AM20: =AL20*(1+$AR20) -> 157.65037 | AN20: =AM20*(1+$AR20) -> 158.72728 | AO20: =AN20*(1+$AR20) -> 159.81154 | ... AQ20: =AP20*(1+$AR20) -> 162.00235 | AR20: 0.006831
A22: RKI000:ca_AverageHouseS | B22: Average House Square Footage | C22: 1789.3104 | D22: 1795.358 | E22: 1801.3766 | F22: 1807.3268 | G22: 1813.0863 | H22: 1818.6857 | I22: 1824.2563 | J22: 1829.9603 | K22: 1835.7445 | L22: 1841.579 | M22: 1847.4465 | N22: 1853.3517 | O22: 1859.2565 | P22: 1865.1763 | Q22: 1871.0797 | R22: 1876.913 | S22: 1882.7009 | T22: 1888.4429 | U22: 1894.134 | V22: 1899.7411 | W22: 1905.2928 | X22: 1910.8062 | Y22: 1916.274 | Z22: 1921.7234 | AA22: 1927.2003 | AB22: 1932.6646 | AC22: 1938.1436 | AD22: 1943.6198 | AE22: 1949.0584 | AF22: 1954.4558 | AG22: 1959.8108 | AH22: =AG22*(1+$AR22) -> 1965.7667 | AI22: =AH22*(1+$AR22) -> 1971.7406 | AJ22: =AI22*(1+$AR22) -> 1977.7327 | AK22: =AJ22*(1+$AR22) -> 1983.7431 | AL22: =AK22*(1+$AR22) -> 1989.7717 | AM22: =AL22*(1+$AR22) -> 1995.8186 | AN22: =AM22*(1+$AR22) -> 2001.8839 | AO22: =AN22*(1+$AR22) -> 2007.9676 | ... AQ22: =AP22*(1+$AR22) -> 2020.1906 | AR22: 0.003039
B24: Energy Intensity
B25: (million Btu per household)
A26: RKI000:da_DeliveredEner | B26: Gross End-use Consumption 1/ | C26: 92.738052 | D26: 91.586494 | E26: 91.932487 | F26: 91.31826 | G26: 90.823273 | H26: 90.223351 | I26: 89.61335 | J26: 88.99015 | K26: 88.42942 | L26: 87.893829 | M26: 87.318878 | N26: 86.789642 | O26: 86.329742 | P26: 85.926926 | Q26: 85.607529 | R26: 85.342171 | S26: 85.099846 | T26: 84.88208 | U26: 84.683701 | V26: 84.499214 | W26: 84.319466 | X26: 84.135582 | Y26: 83.962128 | Z26: 83.800156 | AA26: 83.656654 | AB26: 83.525162 | AC26: 83.412842 | AD26: 83.307243 | AE26: 83.24379 | AF26: 83.194534 | AG26: 83.15329 | AH26: =AG26*(1+$AR26) -> 82.851444 | AI26: =AH26*(1+$AR26) -> 82.550693 | AJ26: =AI26*(1+$AR26) -> 82.251034 | AK26: =AJ26*(1+$AR26) -> 81.952463 | AL26: =AK26*(1+$AR26) -> 81.654975 | AM26: =AL26*(1+$AR26) -> 81.358568 | AN26: =AM26*(1+$AR26) -> 81.063236 | AO26: =AN26*(1+$AR26) -> 80.768976 | ... AQ26: =AP26*(1+$AR26) -> 80.183658 | AR26: -0.00363
A27: RKI000:da_TotalEnergyCo | B27: Delivered Energy Consumption | C27: 92.104782 | D27: 90.867767 | E27: 91.143921 | F27: 90.463226 | G27: 89.904442 | H27: 89.241905 | I27: 88.56897 | J27: 87.883224 | K27: 87.260002 | L27: 86.662102 | M27: 86.023964 | N27: 85.430344 | O27: 84.905266 | P27: 84.436523 | Q27: 84.050179 | R27: 83.717567 | S27: 83.407295 | T27: 83.12088 | U27: 82.852921 | V27: 82.598061 | W27: 82.347038 | X27: 82.090897 | Y27: 81.843887 | Z27: 81.606949 | AA27: 81.386993 | AB27: 81.177185 | AC27: 80.98513 | AD27: 80.798256 | AE27: 80.651489 | AF27: 80.517357 | AG27: 80.389618 | AH27: =AG27*(1+$AR27) -> 80.025935 | AI27: =AH27*(1+$AR27) -> 79.663898 | AJ27: =AI27*(1+$AR27) -> 79.303499 | AK27: =AJ27*(1+$AR27) -> 78.94473 | AL27: =AK27*(1+$AR27) -> 78.587584 | AM27: =AL27*(1+$AR27) -> 78.232053 | AN27: =AM27*(1+$AR27) -> 77.878132 | AO27: =AN27*(1+$AR27) -> 77.525811 | ... AQ27: =AP27*(1+$AR27) -> 76.825944 | AR27: -0.004524
B28: (thousand Btu per square foot) | AH28: =AG28*(1+$AR28) -> 0 | AI28: =AH28*(1+$AR28) -> 0 | AJ28: =AI28*(1+$AR28) -> 0 | AK28: =AJ28*(1+$AR28) -> 0 | AL28: =AK28*(1+$AR28) -> 0 | AM28: =AL28*(1+$AR28) -> 0 | AN28: =AM28*(1+$AR28) -> 0 | AO28: =AN28*(1+$AR28) -> 0 | ... AQ28: =AP28*(1+$AR28) -> 0
A29: RKI000:ea_DeliveredEner | B29: Gross End-use Consumption 1/ | C29: 51.828938 | D29: 51.012939 | E29: 51.034573 | F29: 50.526699 | G29: 50.093189 | H29: 49.609097 | I29: 49.123222 | J29: 48.629551 | K29: 48.170876 | L29: 47.727428 | M29: 47.264633 | N29: 46.82848 | O29: 46.432404 | P29: 46.069065 | Q29: 45.75301 | R29: 45.469433 | S29: 45.200935 | T29: 44.948185 | U29: 44.708401 | V29: 44.479332 | W29: 44.255383 | X29: 44.03146 | Y29: 43.815304 | Z29: 43.606773 | AA29: 43.408386 | AB29: 43.217617 | AC29: 43.037495 | AD29: 42.861904 | AE29: 42.709747 | AF29: 42.566597 | AG29: 42.429241 | AH29: =AG29*(1+$AR29) -> 42.147171 | AI29: =AH29*(1+$AR29) -> 41.866977 | AJ29: =AI29*(1+$AR29) -> 41.588645 | AK29: =AJ29*(1+$AR29) -> 41.312164 | AL29: =AK29*(1+$AR29) -> 41.037521 | AM29: =AL29*(1+$AR29) -> 40.764703 | AN29: =AM29*(1+$AR29) -> 40.4937 | AO29: =AN29*(1+$AR29) -> 40.224497 | ... AQ29: =AP29*(1+$AR29) -> 39.69145 | AR29: -0.006648
A30: RKI000:ea_TotalEnergyCo | B30: Delivered Energy Consumption | C30: 51.475014 | D30: 50.612617 | E30: 50.596817 | F30: 50.053608 | G30: 49.586411 | H30: 49.06945 | I30: 48.550724 | J30: 48.024662 | K30: 47.533848 | L30: 47.058586 | M30: 46.563709 | N30: 46.095051 | O30: 45.666248 | P30: 45.269997 | Q30: 44.920685 | R30: 44.603863 | S30: 44.301933 | T30: 44.015564 | U30: 43.741848 | V30: 43.478588 | W30: 43.220146 | X30: 42.961391 | Y30: 42.709908 | Z30: 42.4655 | AA30: 42.230686 | AB30: 42.002731 | AC30: 41.784897 | AD30: 41.571022 | AE30: 41.379719 | AF30: 41.196815 | AG30: 41.01907 | AH30: =AG30*(1+$AR30) -> 40.709786 | AI30: =AH30*(1+$AR30) -> 40.402834 | AJ30: =AI30*(1+$AR30) -> 40.098197 | AK30: =AJ30*(1+$AR30) -> 39.795857 | AL30: =AK30*(1+$AR30) -> 39.495796 | AM30: =AL30*(1+$AR30) -> 39.197998 | AN30: =AM30*(1+$AR30) -> 38.902445 | AO30: =AN30*(1+$AR30) -> 38.60912 | ... AQ30: =AP30*(1+$AR30) -> 38.02909 | AR30: -0.00754
B32: Energy Consumption by Fuel
B33: Electricity 1/
A34: RKI000:fa_SpaceHeating | B34: Space Heating | C34: 0.648984 | D34: 0.698291 | E34: 0.706468 | F34: 0.702827 | G34: 0.701007 | H34: 0.69955 | I34: 0.697172 | J34: 0.693818 | K34: 0.690231 | L34: 0.68634 | M34: 0.68221 | N34: 0.677813 | O34: 0.673331 | P34: 0.669098 | Q34: 0.665025 | R34: 0.661573 | S34: 0.658052 | T34: 0.654504 | U34: 0.650834 | V34: 0.647063 | W34: 0.643497 | X34: 0.639746 | Y34: 0.635992 | Z34: 0.63249 | AA34: 0.628953 | AB34: 0.625267 | AC34: 0.621895 | AD34: 0.618506 | AE34: 0.615298 | AF34: 0.61255 | AG34: 0.609983 | AH34: =AG34*(1+$AR34) -> 0.608724 | AI34: =AH34*(1+$AR34) -> 0.60746759 | AJ34: =AI34*(1+$AR34) -> 0.60621378 | AK34: =AJ34*(1+$AR34) -> 0.60496255 | AL34: =AK34*(1+$AR34) -> 0.60371391 | AM34: =AL34*(1+$AR34) -> 0.60246784 | AN34: =AM34*(1+$AR34) -> 0.60122435 | AO34: =AN34*(1+$AR34) -> 0.59998342 | ... AQ34: =AP34*(1+$AR34) -> 0.59750925 | AR34: -0.002064
A35: RKI000:fa_SpaceCooling | B35: Space Cooling | C35: 0.805383 | D35: 0.7663 | E35: 0.862066 | F35: 0.87731 | G35: 0.893665 | H35: 0.910851 | I35: 0.927645 | J35: 0.943833 | K35: 0.959908 | L35: 0.975957 | M35: 0.991661 | N35: 1.00764 | O35: 1.024417 | P35: 1.041983 | Q35: 1.060664 | R35: 1.0811 | S35: 1.10211 | T35: 1.124333 | U35: 1.146319 | V35: 1.168238 | W35: 1.190837 | X35: 1.213056 | Y35: 1.236301 | Z35: 1.259563 | AA35: 1.283829 | AB35: 1.307854 | AC35: 1.33271 | AD35: 1.357816 | AE35: 1.384607 | AF35: 1.411898 | AG35: 1.440232 | AH35: =AG35*(1+$AR35) -> 1.4684087 | AI35: =AH35*(1+$AR35) -> 1.4971366 | AJ35: =AI35*(1+$AR35) -> 1.5264266 | AK35: =AJ35*(1+$AR35) -> 1.5562896 | AL35: =AK35*(1+$AR35) -> 1.5867369 | AM35: =AL35*(1+$AR35) -> 1.6177798 | AN35: =AM35*(1+$AR35) -> 1.6494301 | AO35: =AN35*(1+$AR35) -> 1.6816995 | ... AQ35: =AP35*(1+$AR35) -> 1.7481447 | AR35: 0.019564
A36: RKI000:fa_WaterHeating | B36: Water Heating | C36: 0.607547 | D36: 0.610144 | E36: 0.613074 | F36: 0.61509 | G36: 0.617846 | H36: 0.620172 | I36: 0.621656 | J36: 0.622656 | K36: 0.623322 | L36: 0.6239 | M36: 0.624483 | N36: 0.625003 | O36: 0.625859 | P36: 0.627114 | Q36: 0.628819 | R36: 0.631185 | S36: 0.633851 | T36: 0.636678 | U36: 0.639551 | V36: 0.642161 | W36: 0.644696 | X36: 0.647135 | Y36: 0.649634 | Z36: 0.65233 | AA36: 0.655174 | AB36: 0.658088 | AC36: 0.661325 | AD36: 0.664806 | AE36: 0.668643 | AF36: 0.672985 | AG36: 0.677571 | AH36: =AG36*(1+$AR36) -> 0.68003939 | AI36: =AH36*(1+$AR36) -> 0.68251677 | AJ36: =AI36*(1+$AR36) -> 0.68500318 | AK36: =AJ36*(1+$AR36) -> 0.68749865 | AL36: =AK36*(1+$AR36) -> 0.69000321 | AM36: =AL36*(1+$AR36) -> 0.69251689 | AN36: =AM36*(1+$AR36) -> 0.69503973 | AO36: =AN36*(1+$AR36) -> 0.69757176 | ... AQ36: =AP36*(1+$AR36) -> 0.70266352 | AR36: 0.003643
A37: RKI000:fa_Refrigeration | B37: Refrigeration | C37: 0.297571 | D37: 0.295346 | E37: 0.293794 | F37: 0.292089 | G37: 0.290616 | H37: 0.289474 | I37: 0.288541 | J37: 0.287696 | K37: 0.286959 | L37: 0.286376 | M37: 0.28598 | N37: 0.285826 | O37: 0.285965 | P37: 0.286393 | Q37: 0.287106 | R37: 0.288174 | S37: 0.289567 | T37: 0.291258 | U37: 0.293256 | V37: 0.295533 | W37: 0.298126 | X37: 0.301018 | Y37: 0.30418 | Z37: 0.307324 | AA37: 0.31044 | AB37: 0.31352 | AC37: 0.316558 | AD37: 0.319522 | AE37: 0.322411 | AF37: 0.325241 | AG37: 0.328011 | AH37: =AG37*(1+$AR37) -> 0.32907769 | AI37: =AH37*(1+$AR37) -> 0.33014785 | AJ37: =AI37*(1+$AR37) -> 0.33122149 | AK37: =AJ37*(1+$AR37) -> 0.33229863 | AL37: =AK37*(1+$AR37) -> 0.33337926 | AM37: =AL37*(1+$AR37) -> 0.33446341 | AN37: =AM37*(1+$AR37) -> 0.33555109 | AO37: =AN37*(1+$AR37) -> 0.3366423 | ... AQ37: =AP37*(1+$AR37) -> 0.33883538 | AR37: 0.003252
A38: RKI000:fa_Cooking | B38: Cooking | C38: 0.055007 | D38: 0.055161 | E38: 0.05546 | F38: 0.05575 | G38: 0.056045 | H38: 0.056357 | I38: 0.056663 | J38: 0.056938 | K38: 0.057183 | L38: 0.057389 | M38: 0.057556 | N38: 0.057676 | O38: 0.057755 | P38: 0.057841 | Q38: 0.057947 | R38: 0.058089 | S38: 0.058269 | T38: 0.058488 | U38: 0.058698 | V38: 0.058899 | W38: 0.059098 | X38: 0.05929 | Y38: 0.059473 | Z38: 0.059649 | AA38: 0.059818 | AB38: 0.05998 | AC38: 0.060139 | AD38: 0.06029 | AE38: 0.06044 | AF38: 0.060595 | AG38: 0.060756 | AH38: =AG38*(1+$AR38) -> 0.060957649 | AI38: =AH38*(1+$AR38) -> 0.061159968 | AJ38: =AI38*(1+$AR38) -> 0.061362958 | AK38: =AJ38*(1+$AR38) -> 0.061566621 | AL38: =AK38*(1+$AR38) -> 0.061770961 | AM38: =AL38*(1+$AR38) -> 0.061975979 | AN38: =AM38*(1+$AR38) -> 0.062181677 | AO38: =AN38*(1+$AR38) -> 0.062388058 | ... AQ38: =AP38*(1+$AR38) -> 0.062802877 | AR38: 0.003319
A39: RKI000:fa_ClothesDryers | B39: Clothes Dryers | C39: 0.21642 | D39: 0.220336 | E39: 0.224132 | F39: 0.227692 | G39: 0.231622 | H39: 0.235607 | I39: 0.239343 | J39: 0.242757 | K39: 0.246061 | L39: 0.249326 | M39: 0.252545 | N39: 0.255598 | O39: 0.258678 | P39: 0.261852 | Q39: 0.265235 | R39: 0.268841 | S39: 0.27257 | T39: 0.276244 | U39: 0.279829 | V39: 0.283363 | W39: 0.286891 | X39: 0.29037 | Y39: 0.293837 | Z39: 0.29735 | AA39: 0.300874 | AB39: 0.304347 | AC39: 0.307894 | AD39: 0.311491 | AE39: 0.315186 | AF39: 0.319055 | AG39: 0.322998 | AH39: =AG39*(1+$AR39) -> 0.32733812 | AI39: =AH39*(1+$AR39) -> 0.33173657 | AJ39: =AI39*(1+$AR39) -> 0.33619411 | AK39: =AJ39*(1+$AR39) -> 0.34071155 | AL39: =AK39*(1+$AR39) -> 0.34528969 | AM39: =AL39*(1+$AR39) -> 0.34992935 | AN39: =AM39*(1+$AR39) -> 0.35463135 | AO39: =AN39*(1+$AR39) -> 0.35939653 | ... AQ39: =AP39*(1+$AR39) -> 0.36911984 | AR39: 0.013437
A40: RKI000:fa_Freezers | B40: Freezers | C40: 0.069181 | D40: 0.068847 | E40: 0.068698 | F40: 0.068526 | G40: 0.06834 | H40: 0.068157 | I40: 0.067953 | J40: 0.067707 | K40: 0.067461 | L40: 0.067224 | M40: 0.066995 | N40: 0.066774 | O40: 0.06657 | P40: 0.066383 | Q40: 0.066214 | R40: 0.066077 | S40: 0.065975 | T40: 0.065902 | U40: 0.065862 | V40: 0.065855 | W40: 0.065888 | X40: 0.065966 | Y40: 0.066082 | Z40: 0.066247 | AA40: 0.066465 | AB40: 0.066737 | AC40: 0.067063 | AD40: 0.067429 | AE40: 0.06779 | AF40: 0.068152 | AG40: 0.068514 | AH40: =AG40*(1+$AR40) -> 0.06849187 | AI40: =AH40*(1+$AR40) -> 0.068469747 | AJ40: =AI40*(1+$AR40) -> 0.068447631 | AK40: =AJ40*(1+$AR40) -> 0.068425523 | AL40: =AK40*(1+$AR40) -> 0.068403421 | AM40: =AL40*(1+$AR40) -> 0.068381327 | AN40: =AM40*(1+$AR40) -> 0.06835924 | AO40: =AN40*(1+$AR40) -> 0.06833716 | ... AQ40: =AP40*(1+$AR40) -> 0.068293021 | AR40: -0.000323
A41: RKI000:fa_Lighting | B41: Lighting | C41: 0.211245 | D41: 0.204658 | E41: 0.202521 | F41: 0.20193 | G41: 0.202401 | H41: 0.201491 | I41: 0.200873 | J41: 0.200838 | K41: 0.201379 | L41: 0.202196 | M41: 0.200463 | N41: 0.199204 | O41: 0.198392 | P41: 0.197965 | Q41: 0.197945 | R41: 0.198286 | S41: 0.198748 | T41: 0.199251 | U41: 0.199757 | V41: 0.200288 | W41: 0.197496 | X41: 0.195328 | Y41: 0.193641 | Z41: 0.192433 | AA41: 0.191624 | AB41: 0.191038 | AC41: 0.190629 | AD41: 0.190303 | AE41: 0.190083 | AF41: 0.190014 | AG41: 0.190188 | AH41: =AG41*(1+$AR41) -> 0.18952348 | AI41: =AH41*(1+$AR41) -> 0.18886129 | AJ41: =AI41*(1+$AR41) -> 0.18820141 | AK41: =AJ41*(1+$AR41) -> 0.18754383 | AL41: =AK41*(1+$AR41) -> 0.18688855 | AM41: =AL41*(1+$AR41) -> 0.18623556 | AN41: =AM41*(1+$AR41) -> 0.18558486 | AO41: =AN41*(1+$AR41) -> 0.18493642 | ... AQ41: =AP41*(1+$AR41) -> 0.18364635 | AR41: -0.003494
A42: RKI000:fa_ClothesWasher | B42: Clothes Washers 2/ | C42: 0.036779 | D42: 0.037026 | E42: 0.037375 | F42: 0.037721 | G42: 0.038075 | H42: 0.038449 | I42: 0.038824 | J42: 0.03918 | K42: 0.039523 | L42: 0.039855 | M42: 0.040193 | N42: 0.040519 | O42: 0.040839 | P42: 0.041152 | Q42: 0.041455 | R42: 0.041759 | S42: 0.04206 | T42: 0.042358 | U42: 0.042653 | V42: 0.042945 | W42: 0.04324 | X42: 0.043535 | Y42: 0.043829 | Z42: 0.044122 | AA42: 0.044416 | AB42: 0.044709 | AC42: 0.045004 | AD42: 0.045295 | AE42: 0.045585 | AF42: 0.045875 | AG42: 0.046168 | AH42: =AG42*(1+$AR42) -> 0.0465192 | AI42: =AH42*(1+$AR42) -> 0.046873072 | AJ42: =AI42*(1+$AR42) -> 0.047229635 | AK42: =AJ42*(1+$AR42) -> 0.047588911 | AL42: =AK42*(1+$AR42) -> 0.04795092 | AM42: =AL42*(1+$AR42) -> 0.048315682 | AN42: =AM42*(1+$AR42) -> 0.04868322 | AO42: =AN42*(1+$AR42) -> 0.049053553 | ... AQ42: =AP42*(1+$AR42) -> 0.049802692 | AR42: 0.007607
A43: RKI000:fa_Dishwashers | B43: Dishwashers 2/ | C43: 0.026617 | D43: 0.026992 | E43: 0.027431 | F43: 0.027859 | G43: 0.028283 | H43: 0.028709 | I43: 0.029123 | J43: 0.029508 | K43: 0.029918 | L43: 0.03036 | M43: 0.03083 | N43: 0.03133 | O43: 0.031868 | P43: 0.032445 | Q43: 0.033062 | R43: 0.033677 | S43: 0.034289 | T43: 0.034896 | U43: 0.035501 | V43: 0.036103 | W43: 0.036706 | X43: 0.037309 | Y43: 0.03791 | Z43: 0.03851 | AA43: 0.03911 | AB43: 0.03971 | AC43: 0.040309 | AD43: 0.040905 | AE43: 0.041499 | AF43: 0.042093 | AG43: 0.042686 | AH43: =AG43*(1+$AR43) -> 0.043363427 | AI43: =AH43*(1+$AR43) -> 0.044051604 | AJ43: =AI43*(1+$AR43) -> 0.044750703 | AK43: =AJ43*(1+$AR43) -> 0.045460897 | AL43: =AK43*(1+$AR43) -> 0.046182361 | AM43: =AL43*(1+$AR43) -> 0.046915276 | AN43: =AM43*(1+$AR43) -> 0.047659821 | AO43: =AN43*(1+$AR43) -> 0.048416182 | ... AQ43: =AP43*(1+$AR43) -> 0.049965106 | AR43: 0.01587
A44: RKI000:fa_ColorTelevisi | B44: Televisions and Related Equipment 3/ | C44: 0.20913 | D44: 0.205162 | E44: 0.202737 | F44: 0.200828 | G44: 0.199926 | H44: 0.199812 | I44: 0.20026 | J44: 0.201233 | K44: 0.20279 | L44: 0.20499 | M44: 0.207745 | N44: 0.210879 | O44: 0.214516 | P44: 0.218628 | Q44: 0.223129 | R44: 0.228027 | S44: 0.233134 | T44: 0.23827 | U44: 0.243305 | V44: 0.248126 | W44: 0.252637 | X44: 0.256616 | Y44: 0.260069 | Z44: 0.263242 | AA44: 0.266345 | AB44: 0.26934 | AC44: 0.272296 | AD44: 0.275205 | AE44: 0.27813 | AF44: 0.281099 | AG44: 0.284057 | AH44: =AG44*(1+$AR44) -> 0.28697142 | AI44: =AH44*(1+$AR44) -> 0.28991575 | AJ44: =AI44*(1+$AR44) -> 0.29289029 | AK44: =AJ44*(1+$AR44) -> 0.29589534 | AL44: =AK44*(1+$AR44) -> 0.29893123 | AM44: =AL44*(1+$AR44) -> 0.30199826 | AN44: =AM44*(1+$AR44) -> 0.30509676 | AO44: =AN44*(1+$AR44) -> 0.30822706 | ... AQ44: =AP44*(1+$AR44) -> 0.31458432 | AR44: 0.01026
A45: RKI000:fa_PersonalCompu | B45: Computers and Related Equipment 4/ | C45: 0.086663 | D45: 0.083815 | E45: 0.081571 | F45: 0.079481 | G45: 0.077709 | H45: 0.076122 | I45: 0.074639 | J45: 0.073224 | K45: 0.071899 | L45: 0.07067 | M45: 0.069487 | N45: 0.068284 | O45: 0.0671 | P45: 0.06591 | Q45: 0.064687 | R45: 0.063421 | S45: 0.062059 | T45: 0.060712 | U45: 0.059373 | V45: 0.058027 | W45: 0.056675 | X45: 0.055295 | Y45: 0.053887 | Z45: 0.052461 | AA45: 0.051003 | AB45: 0.049484 | AC45: 0.047905 | AD45: 0.046248 | AE45: 0.044522 | AF45: 0.042687 | AG45: 0.040729 | AH45: =AG45*(1+$AR45) -> 0.039716681 | AI45: =AH45*(1+$AR45) -> 0.038729523 | AJ45: =AI45*(1+$AR45) -> 0.0377669 | AK45: =AJ45*(1+$AR45) -> 0.036828204 | AL45: =AK45*(1+$AR45) -> 0.035912839 | AM45: =AL45*(1+$AR45) -> 0.035020225 | AN45: =AM45*(1+$AR45) -> 0.034149798 | AO45: =AN45*(1+$AR45) -> 0.033301004 | ... AQ45: =AP45*(1+$AR45) -> 0.031666184 | AR45: -0.024855
... A50: RKI000:fa_PurchasedElec | B50: Purchased Electricity | C50: 5.052812 | D50: 5.085637 | E50: 5.095811 | F50: 5.116436 | G50: 5.142391 | H50: 5.170817 | I50: 5.205887 | J50: 5.237628 | K50: 5.270442 | L50: 5.303538 | M50: 5.333761 | N50: 5.36293 | O50: 5.394765 | P50: 5.428938 | Q50: 5.470158 | R50: 5.515707 | S50: 5.562729 | T50: 5.610796 | U50: 5.65801 | V50: 5.705455 | W50: 5.750833 | X50: 5.795556 | Y50: 5.841669 | Z50: 5.888741 | AA50: 5.936951 | AB50: 5.985407 | AC50: 6.035119 | AD50: 6.084916 | AE50: 6.139284 | AF50: 6.195721 | AG50: 6.253851 | AH50: =AG50*(1+$AR50) -> 6.298466 | AI50: =AH50*(1+$AR50) -> 6.3433992 | AJ50: =AI50*(1+$AR50) -> 6.388653 | AK50: =AJ50*(1+$AR50) -> 6.4342297 | AL50: =AK50*(1+$AR50) -> 6.4801315 | AM50: =AL50*(1+$AR50) -> 6.5263607 | AN50: =AM50*(1+$AR50) -> 6.5729198 | AO50: =AN50*(1+$AR50) -> 6.619811 | ... AQ50: =AP50*(1+$AR50) -> 6.7145994 | AR50: 0.007134
B52: Natural Gas
A53: RKI000:ga_SpaceHeating | B53: Space Heating | C53: 3.527198 | D53: 3.406817 | E53: 3.538172 | F53: 3.535602 | G53: 3.539818 | H53: 3.535704 | I53: 3.522943 | J53: 3.505328 | K53: 3.488243 | L53: 3.469637 | M53: 3.44763 | N53: 3.428068 | O53: 3.411065 | P53: 3.395152 | Q53: 3.380025 | R53: 3.367227 | S53: 3.35518 | T53: 3.343377 | U53: 3.333029 | V53: 3.323643 | W53: 3.315649 | X53: 3.307149 | Y53: 3.298006 | Z53: 3.288577 | AA53: 3.279139 | AB53: 3.269643 | AC53: 3.260687 | AD53: 3.251623 | AE53: 3.243194 | AF53: 3.234245 | AG53: 3.224808 | AH53: =AG53*(1+$AR53) -> 3.2151884 | AI53: =AH53*(1+$AR53) -> 3.2055975 | AJ53: =AI53*(1+$AR53) -> 3.1960352 | AK53: =AJ53*(1+$AR53) -> 3.1865014 | AL53: =AK53*(1+$AR53) -> 3.1769961 | AM53: =AL53*(1+$AR53) -> 3.1675191 | AN53: =AM53*(1+$AR53) -> 3.1580704 | AO53: =AN53*(1+$AR53) -> 3.1486499 | ... AQ53: =AP53*(1+$AR53) -> 3.129893 | AR53: -0.002983
...

Sheet EIA AEO Table 21
A1: Table 21. Residential Sector Equipment Stock and Efficiency, and Distributed Generation
A2: https://www.eia.gov/outlooks/aeo/data/browser/#/?id=30-AEO2021&region=0-0&cases=highogs&start=2019&end=2050&f=A&sourcekey=0
A3: Wed Mar 03 2021 12:12:30 GMT-0800 (Pacific Standard Time)
A4: Source: U.S. Energy Information Administration | AK4: 2051-2060年数据用2050年增速计算得到
B5: full name | C5: api key | D5: units | E5: 2019 | F5: 2020 | G5: 2021 | H5: 2022 | I5: 2023 | J5: 2024 | K5: 2025 | L5: 2026 | M5: 2027 | N5: 2028 | O5: 2029 | P5: 2030 | Q5: 2031 | R5: 2032 | S5: 2033 | T5: 2034 | U5: 2035 | V5: 2036 | W5: 2037 | X5: 2038 | Y5: 2039 | Z5: 2040 | AA5: 2041 | AB5: 2042 | AC5: 2043 | AD5: 2044 | AE5: 2045 | AF5: 2046 | AG5: 2047 | AH5: 2048 | AI5: 2049 | AJ5: 2050 | AK5: 2051 | AL5: 2052 | AM5: 2053 | AN5: 2054 | AO5: 2055 | AP5: 2056 | AQ5: 2057 | AR5: 2058 | AS5: 2059 | AT5: 2060 | AU5: 年增速 | AV5: Growth (2020-2050)
A6: Equipment Stock (million units) | C6: 30-AEO2021.2.
A7: Main Space Heaters | C7: 30-AEO2021.3.
A8: Electric Heat Pumps | B8: Residential Equipment: Equipment Stock: Main Space Heaters: Electric Heat Pumps: High oil and gas supply | C8: 30-AEO2021.4.highogs-d120120a | D8: millions | F8: 12.588214 | G8: 12.817233 | H8: 13.044524 | I8: 13.267048 | J8: 13.49545 | K8: 13.736792 | L8: 13.979751 | M8: 14.211932 | N8: 14.434669 | O8: 14.650879 | P8: 14.860855 | Q8: 15.063206 | R8: 15.261859 | S8: 15.455095 | T8: 15.642369 | U8: 15.83092 | V8: 16.018835 | W8: 16.206322 | X8: 16.391668 | Y8: 16.575872 | Z8: 16.761606 | AA8: 16.947832 | AB8: 17.134937 | AC8: 17.323729 | AD8: 17.513716 | AE8: 17.705347 | AF8: 17.898474 | AG8: 18.091597 | AH8: 18.28528 | AI8: 18.480938 | AJ8: 18.678591 | AK8: =AJ8*(1+$AU8) -> 18.878358 | AL8: =AK8*(1+$AU8) -> 19.080261 | AM8: =AL8*(1+$AU8) -> 19.284324 | AN8: =AM8*(1+$AU8) -> 19.490569 | AO8: =AN8*(1+$AU8) -> 19.69902 | AP8: =AO8*(1+$AU8) -> 19.909701 | AQ8: =AP8*(1+$AU8) -> 20.122634 | AR8: =AQ8*(1+$AU8) -> 20.337845 | ... AT8: =AS8*(1+$AU8) -> 20.775196 | AU8: =AJ8/AI8-1 -> 0.010694966 | AV8: 0.013
A9: Electric Other | B9: Residential Equipment: Equipment Stock: Main Space Heaters: Electric Other: High oil and gas supply | C9: 30-AEO2021.5.highogs-d120120a | D9: millions | F9: 30.217646 | G9: 30.352442 | H9: 30.489107 | I9: 30.626911 | J9: 30.775251 | K9: 30.93782 | L9: 31.102098 | M9: 31.252998 | N9: 31.392506 | O9: 31.52371 | P9: 31.647842 | Q9: 31.763769 | R9: 31.876602 | S9: 31.984751 | T9: 32.088398 | U9: 32.195225 | V9: 32.302486 | W9: 32.409527 | X9: 32.517002 | Y9: 32.626743 | Z9: 32.740696 | AA9: 32.856911 | AB9: 32.974445 | AC9: 33.093201 | AD9: 33.21143 | AE9: 33.330669 | AF9: 33.450096 | AG9: 33.567921 | AH9: 33.685921 | AI9: 33.805984 | AJ9: 33.927921 | AK9: =AJ9*(1+$AU9) -> 34.050298 | AL9: =AK9*(1+$AU9) -> 34.173116 | AM9: =AL9*(1+$AU9) -> 34.296377 | AN9: =AM9*(1+$AU9) -> 34.420083 | AO9: =AN9*(1+$AU9) -> 34.544235 | AP9: =AO9*(1+$AU9) -> 34.668835 | AQ9: =AP9*(1+$AU9) -> 34.793884 | AR9: =AQ9*(1+$AU9) -> 34.919385 | ... AT9: =AS9*(1+$AU9) -> 35.171745 | AU9: =AJ9/AI9-1 -> 0.003606965 | AV9: 0.004
A10: Natural Gas Heat Pumps | B10: Residential Equipment: Equipment Stock: Main Space Heaters: Natural Gas Heat Pumps: High oil and gas supply | C10: 30-AEO2021.6.highogs-d120120a | D10: millions | F10: 1.311724 | G10: 1.309614 | H10: 1.307512 | I10: 1.305418 | J10: 1.303333 | K10: 1.301256 | L10: 1.299187 | M10: 1.297126 | N10: 1.295073 | O10: 1.293028 | P10: 1.29099 | Q10: 1.288961 | R10: 1.286939 | S10: 1.284924 | T10: 1.282917 | U10: 1.280917 | V10: 1.278925 | W10: 1.27694 | X10: 1.274962 | Y10: 1.272991 | Z10: 1.271027 | AA10: 1.26907 | AB10: 1.26712 | AC10: 1.265176 | AD10: 1.263239 | AE10: 1.261309 | AF10: 1.259386 | AG10: 1.257469 | AH10: 1.255558 | AI10: 1.253654 | AJ10: 1.251756 | AK10: =AJ10*(1+$AU10) -> 1.2498609 | AL10: =AK10*(1+$AU10) -> 1.2479686 | AM10: =AL10*(1+$AU10) -> 1.2460792 | AN10: =AM10*(1+$AU10) -> 1.2441927 | AO10: =AN10*(1+$AU10) -> 1.242309 | AP10: =AO10*(1+$AU10) -> 1.2404282 | AQ10: =AP10*(1+$AU10) -> 1.2385502 | AR10: =AQ10*(1+$AU10) -> 1.2366751 | ... AT10: =AS10*(1+$AU10) -> 1.2329333 | AU10: =AJ10/AI10-1 -> -0.0015139744 | AV10: -0.002
A11: Natural Gas Other | B11: Residential Equipment: Equipment Stock: Main Space Heaters: Natural Gas Other: High oil and gas supply | C11: 30-AEO2021.7.highogs-d120120a | D11: millions | F11: 60.555111 | G11: 61.300755 | H11: 62.047543 | I11: 62.788345 | J11: 63.539452 | K11: 64.319839 | L11: 65.096298 | M11: 65.83799 | N11: 66.549057 | O11: 67.237877 | P11: 67.903763 | Q11: 68.544914 | R11: 69.171463 | S11: 69.777695 | T11: 70.360138 | U11: 70.938538 | V11: 71.50589 | W11: 72.063133 | X11: 72.615173 | Y11: 73.162819 | Z11: 73.714096 | AA11: 74.264648 | AB11: 74.813858 | AC11: 75.364723 | AD11: 75.916847 | AE11: 76.470596 | AF11: 77.026077 | AG11: 77.577576 | AH11: 78.126053 | AI11: 78.675049 | AJ11: 79.225029 | AK11: =AJ11*(1+$AU11) -> 79.778854 | AL11: =AK11*(1+$AU11) -> 80.33655 | AM11: =AL11*(1+$AU11) -> 80.898145 | AN11: =AM11*(1+$AU11) -> 81.463665 | AO11: =AN11*(1+$AU11) -> 82.033139 | AP11: =AO11*(1+$AU11) -> 82.606594 | AQ11: =AP11*(1+$AU11) -> 83.184057 | AR11: =AQ11*(1+$AU11) -> 83.765558 | ... AT11: =AS11*(1+$AU11) -> 84.940782 | AU11: =AJ11/AI11-1 -> 0.0069905263 | AV11: 0.009
A12: Distillate Fuel Oil | B12: Residential Equipment: Equipment Stock: Main Space Heaters: Distillate Fuel Oil: High oil and gas supply | C12: 30-AEO2021.8.highogs-d120120a | D12: millions | F12: 5.548133 | G12: 5.496151 | H12: 5.445325 | I12: 5.39556 | J12: 5.346739 | K12: 5.298432 | L12: 5.250475 | M12: 5.204051 | N12: 5.159433 | O12: 5.116981 | P12: 5.076789 | Q12: 5.038133 | R12: 5.001117 | S12: 4.96543 | T12: 4.93077 | U12: 4.897096 | V12: 4.864147 | W12: 4.832564 | X12: 4.802089 | Y12: 4.772426 | Z12: 4.743561 | AA12: 4.714861 | AB12: 4.684665 | AC12: 4.653028 | AD12: 4.620164 | AE12: 4.586325 | AF12: 4.551681 | AG12: 4.515605 | AH12: 4.478509 | AI12: 4.440822 | AJ12: 4.402934 | AK12: =AJ12*(1+$AU12) -> 4.3653693 | AL12: =AK12*(1+$AU12) -> 4.328125 | AM12: =AL12*(1+$AU12) -> 4.2911985 | AN12: =AM12*(1+$AU12) -> 4.254587 | AO12: =AN12*(1+$AU12) -> 4.218288 | AP12: =AO12*(1+$AU12) -> 4.1822986 | AQ12: =AP12*(1+$AU12) -> 4.1466162 | AR12: =AQ12*(1+$AU12) -> 4.1112383 | ... AT12: =AS12*(1+$AU12) -> 4.0413854 | AU12: =AJ12/AI12-1 -> -0.0085317538 | AV12: -0.008
A13: Propane | B13: Residential Equipment: Equipment Stock: Main Space Heaters: Propane: High oil and gas supply | C13: 30-AEO2021.9.highogs-d120120a | D13: millions | F13: 5.19486 | G13: 5.207179 | H13: 5.218678 | I13: 5.23048 | J13: 5.243737 | K13: 5.259387 | L13: 5.276538 | M13: 5.292049 | N13: 5.305241 | O13: 5.316492 | P13: 5.325163 | Q13: 5.332108 | R13: 5.338496 | S13: 5.344443 | T13: 5.349902 | U13: 5.356181 | V13: 5.362693 | W13: 5.368529 | X13: 5.373667 | Y13: 5.378528 | Z13: 5.383961 | AA13: 5.389707 | AB13: 5.394711 | AC13: 5.399234 | AD13: 5.4032 | AE13: 5.406765 | AF13: 5.409881 | AG13: 5.412031 | AH13: 5.413425 | AI13: 5.414567 | AJ13: 5.415322 | AK13: =AJ13*(1+$AU13) -> 5.4160771 | AL13: =AK13*(1+$AU13) -> 5.4168323 | AM13: =AL13*(1+$AU13) -> 5.4175876 | AN13: =AM13*(1+$AU13) -> 5.4183431 | AO13: =AN13*(1+$AU13) -> 5.4190986 | AP13: =AO13*(1+$AU13) -> 5.4198542 | AQ13: =AP13*(1+$AU13) -> 5.4206099 | AR13: =AQ13*(1+$AU13) -> 5.4213658 | ... AT13: =AS13*(1+$AU13) -> 5.4228778 | AU13: =AJ13/AI13-1 -> 0.00013943867 | AV13: 0.001
A14: Kerosene | B14: Residential Equipment: Equipment Stock: Main Space Heaters: Kerosene: High oil and gas supply | C14: 30-AEO2021.10.highogs-d120120a | D14: millions | F14: 0.002897 | G14: 0.005475 | H14: 0.008003 | I14: 0.01057 | J14: 0.013306 | K14: 0.016211 | L14: 0.019194 | M14: 0.021853 | N14: 0.024175 | O14: 0.026187 | P14: 0.027912 | Q14: 0.029431 | R14: 0.030854 | S14: 0.032223 | T14: 0.033555 | U14: 0.034948 | V14: 0.036373 | W14: 0.037762 | X14: 0.0391 | Y14: 0.040437 | Z14: 0.041835 | AA14: 0.043241 | AB14: 0.044628 | AC14: 0.045982 | AD14: 0.047285 | AE14: 0.04854 | AF14: 0.049738 | AG14: 0.050831 | AH14: 0.051844 | AI14: 0.052813 | AJ14: 0.053714 | AK14: =AJ14*(1+$AU14) -> 0.054630371 | AL14: =AK14*(1+$AU14) -> 0.055562376 | AM14: =AL14*(1+$AU14) -> 0.056510281 | AN14: =AM14*(1+$AU14) -> 0.057474357 | AO14: =AN14*(1+$AU14) -> 0.058454881 | AP14: =AO14*(1+$AU14) -> 0.059452132 | AQ14: =AP14*(1+$AU14) -> 0.060466397 | AR14: =AQ14*(1+$AU14) -> 0.061497966 | ... AT14: =AS14*(1+$AU14) -> 0.063614199 | AU14: =AJ14/AI14-1 -> 0.017060194 | AV14: 0.102
A15: Wood Stoves | B15: Residential Equipment: Equipment Stock: Main Space Heaters: Wood Stoves: High oil and gas supply | C15: 30-AEO2021.11.highogs-d120120a | D15: millions | F15: 3.344913 | G15: 3.319362 | H15: 3.294424 | I15: 3.270416 | J15: 3.247226 | K15: 3.223904 | L15: 3.200468 | M15: 3.176886 | N15: 3.153061 | O15: 3.128717 | P15: 3.103658 | Q15: 3.077978 | R15: 3.051444 | S15: 3.024014 | T15: 2.995715 | U15: 2.966784 | V15: 2.937014 | W15: 2.908106 | X15: 2.880246 | Y15: 2.853318 | Z15: 2.826585 | AA15: 2.80106 | AB15: 2.776755 | AC15: 2.753703 | AD15: 2.731991 | AE15: 2.711658 | AF15: 2.692641 | AG15: 2.673467 | AH15: 2.654179 | AI15: 2.634693 | AJ15: 2.614983 | AK15: =AJ15*(1+$AU15) -> 2.5954204 | AL15: =AK15*(1+$AU15) -> 2.5760042 | AM15: =AL15*(1+$AU15) -> 2.5567333 | AN15: =AM15*(1+$AU15) -> 2.5376065 | AO15: =AN15*(1+$AU15) -> 2.5186228 | AP15: =AO15*(1+$AU15) -> 2.4997811 | AQ15: =AP15*(1+$AU15) -> 2.4810804 | AR15: =AQ15*(1+$AU15) -> 2.4625196 | ... AT15: =AS15*(1+$AU15) -> 2.4258134 | AU15: =AJ15/AI15-1 -> -0.0074809475 | AV15: -0.008
A16: Geothermal Heat Pumps | B16: Residential Equipment: Equipment Stock: Main Space Heaters: Geothermal Heat Pumps: High oil and gas supply | C16: 30-AEO2021.12.highogs-d120120a | D16: millions | F16: 0.659973 | G16: 0.716466 | H16: 0.772579 | I16: 0.827264 | J16: 0.881329 | K16: 0.937041 | L16: 0.992897 | M16: 1.047697 | N16: 1.101563 | O16: 1.155224 | P16: 1.208774 | Q16: 1.261961 | R16: 1.315501 | S16: 1.369143 | T16: 1.422559 | U16: 1.476487 | V16: 1.530798 | W16: 1.583866 | X16: 1.635591 | Y16: 1.686028 | Z16: 1.73649 | AA16: 1.785776 | AB16: 1.833722 | AC16: 1.88055 | AD16: 1.926325 | AE16: 1.970899 | AF16: 2.014432 | AG16: 2.057983 | AH16: 2.101467 | AI16: 2.145185 | AJ16: 2.189195 | AK16: =AJ16*(1+$AU16) -> 2.2341079 | AL16: =AK16*(1+$AU16) -> 2.2799422 | AM16: =AL16*(1+$AU16) -> 2.3267169 | AN16: =AM16*(1+$AU16) -> 2.3744511 | AO16: =AN16*(1+$AU16) -> 2.4231647 | AP16: =AO16*(1+$AU16) -> 2.4728776 | AQ16: =AP16*(1+$AU16) -> 2.5236105 | AR16: =AQ16*(1+$AU16) -> 2.5753841 | ... AT16: =AS16*(1+$AU16) -> 2.6821398 | AU16: =AJ16/AI16-1 -> 0.020515713 | AV16: 0.041
A17: Total | B17: Residential Equipment: Equipment Stock: Main Space Heaters: Total: High oil and gas supply | C17: 30-AEO2021.13.highogs-d120120a | D17: millions | F17: 119.42348 | G17: 120.52468 | H17: 121.6277 | I17: 122.72201 | J17: 123.84583 | K17: 125.03069 | L17: 126.2169 | M17: 127.34258 | N17: 128.41479 | O17: 129.4491 | P17: 130.44574 | Q17: 131.40045 | R17: 132.33427 | S17: 133.23772 | T17: 134.10632 | U17: 134.9771 | V17: 135.83714 | W17: 136.68675 | X17: 137.52949 | Y17: 138.36917 | Z17: 139.21986 | AA17: 140.0731 | AB17: 140.92485 | AC17: 141.77933 | AD17: 142.6342 | AE17: 143.49211 | AF17: 144.35242 | AG17: 145.20448 | AH17: 146.05225 | AI17: 146.9037 | AJ17: 147.75946 | AK17: =AJ17*(1+$AU17) -> 148.6202 | AL17: =AK17*(1+$AU17) -> 149.48596 | AM17: =AL17*(1+$AU17) -> 150.35676 | AN17: =AM17*(1+$AU17) -> 151.23263 | AO17: =AN17*(1+$AU17) -> 152.11361 | AP17: =AO17*(1+$AU17) -> 152.99972 | AQ17: =AP17*(1+$AU17) -> 153.89099 | AR17: =AQ17*(1+$AU17) -> 154.78745 | ... AT17: =AS17*(1+$AU17) -> 156.59607 | AU17: =AJ17/AI17-1 -> 0.0058252991 | AV17: 0.007
A18: Space Cooling (million units) | C18: 30-AEO2021.15.
A19: Electric Heat Pumps | B19: Residential Equipment: Equipment Stock: Space Cooling: Electric Heat Pumps: High oil and gas supply | C19: 30-AEO2021.16.highogs-d120120a | D19: millions | F19: 12.58821 | G19: 12.817232 | H19: 13.044521 | I19: 13.267052 | J19: 13.495453 | K19: 13.736794 | L19: 13.979755 | M19: 14.211934 | N19: 14.434671 | O19: 14.650883 | P19: 14.860855 | Q19: 15.063212 | R19: 15.261856 | S19: 15.455102 | T19: 15.642369 | U19: 15.830916 | V19: 16.018831 | W19: 16.20632 | X19: 16.391672 | Y19: 16.575872 | Z19: 16.761606 | AA19: 16.947832 | AB19: 17.13493 | AC19: 17.323732 | AD19: 17.513723 | AE19: 17.705347 | AF19: 17.898479 | AG19: 18.0916 | AH19: 18.28528 | AI19: 18.480938 | AJ19: 18.678596 | AK19: =AJ19*(1+$AU19) -> 18.878368 | AL19: =AK19*(1+$AU19) -> 19.080277 | AM19: =AL19*(1+$AU19) -> 19.284345 | AN19: =AM19*(1+$AU19) -> 19.490595 | AO19: =AN19*(1+$AU19) -> 19.699052 | AP19: =AO19*(1+$AU19) -> 19.909738 | AQ19: =AP19*(1+$AU19) -> 20.122677 | AR19: =AQ19*(1+$AU19) -> 20.337894 | ... AT19: =AS19*(1+$AU19) -> 20.775258 | AU19: =AJ19/AI19-1 -> 0.010695236 | AV19: 0.013
A20: Natural Gas Heat Pumps | B20: Residential Equipment: Equipment Stock: Space Cooling: Natural Gas Heat Pumps: High oil and gas supply | C20: 30-AEO2021.17.highogs-d120120a | D20: millions | F20: 1.311724 | G20: 1.309614 | H20: 1.307512 | I20: 1.305418 | J20: 1.303333 | K20: 1.301256 | L20: 1.299187 | M20: 1.297126 | N20: 1.295073 | O20: 1.293028 | P20: 1.29099 | Q20: 1.288961 | R20: 1.286939 | S20: 1.284924 | T20: 1.282917 | U20: 1.280917 | V20: 1.278925 | W20: 1.27694 | X20: 1.274962 | Y20: 1.272991 | Z20: 1.271027 | AA20: 1.26907 | AB20: 1.26712 | AC20: 1.265176 | AD20: 1.263239 | AE20: 1.261309 | AF20: 1.259386 | AG20: 1.257469 | AH20: 1.255558 | AI20: 1.253654 | AJ20: 1.251756 | AK20: =AJ20*(1+$AU20) -> 1.2498609 | AL20: =AK20*(1+$AU20) -> 1.2479686 | AM20: =AL20*(1+$AU20) -> 1.2460792 | AN20: =AM20*(1+$AU20) -> 1.2441927 | AO20: =AN20*(1+$AU20) -> 1.242309 | AP20: =AO20*(1+$AU20) -> 1.2404282 | AQ20: =AP20*(1+$AU20) -> 1.2385502 | AR20: =AQ20*(1+$AU20) -> 1.2366751 | ... AT20: =AS20*(1+$AU20) -> 1.2329333 | AU20: =AJ20/AI20-1 -> -0.0015139744 | AV20: -0.002
A21: Geothermal Heat Pumps | B21: Residential Equipment: Equipment Stock: Space Cooling: Geothermal Heat Pumps: High oil and gas supply | C21: 30-AEO2021.18.highogs-d120120a | D21: millions | F21: 0.659973 | G21: 0.716466 | H21: 0.772579 | I21: 0.827264 | J21: 0.881329 | K21: 0.93704 | L21: 0.992898 | M21: 1.047698 | N21: 1.101564 | O21: 1.155224 | P21: 1.208774 | Q21: 1.26196 | R21: 1.315501 | S21: 1.369144 | T21: 1.422559 | U21: 1.476488 | V21: 1.530799 | W21: 1.583866 | X21: 1.635591 | Y21: 1.686028 | Z21: 1.73649 | AA21: 1.785776 | AB21: 1.833722 | AC21: 1.880549 | AD21: 1.926325 | AE21: 1.970899 | AF21: 2.014432 | AG21: 2.057982 | AH21: 2.101467 | AI21: 2.145186 | AJ21: 2.189197 | AK21: =AJ21*(1+$AU21) -> 2.2341109 | AL21: =AK21*(1+$AU21) -> 2.2799463 | AM21: =AL21*(1+$AU21) -> 2.3267221 | AN21: =AM21*(1+$AU21) -> 2.3744575 | AO21: =AN21*(1+$AU21) -> 2.4231723 | AP21: =AO21*(1+$AU21) -> 2.4728865 | AQ21: =AP21*(1+$AU21) -> 2.5236207 | AR21: =AQ21*(1+$AU21) -> 2.5753957 | ... AT21: =AS21*(1+$AU21) -> 2.6821542 | AU21: =AJ21/AI21-1 -> 0.02051617 | AV21: 0.041
A22: Central Air Conditioners | B22: Residential Equipment: Equipment Stock: Space Cooling: Central Air Conditioners: High oil and gas supply | C22: 30-AEO2021.19.highogs-d120120a | D22: millions | F22: 62.428101 | G22: 63.953739 | H22: 65.478302 | I22: 66.994934 | J22: 68.527229 | K22: 70.095711 | L22: 71.662971 | M22: 73.190346 | N22: 74.681778 | O22: 76.147041 | P22: 77.586067 | Q22: 78.996407 | R22: 80.391296 | S22: 81.764877 | T22: 83.114212 | U22: 84.46244 | V22: 85.801651 | W22: 87.13192 | X22: 88.455452 | Y22: 89.774467 | Z22: 91.098305 | AA22: 92.421654 | AB22: 93.741837 | AC22: 95.061737 | AD22: 96.380211 | AE22: 97.698593 | AF22: 99.016754 | AG22: 100.32771 | AH22: 101.63374 | AI22: 102.93985 | AJ22: 104.24644 | AK22: =AJ22*(1+$AU22) -> 105.56961 | AL22: =AK22*(1+$AU22) -> 106.90957 | AM22: =AL22*(1+$AU22) -> 108.26655 | AN22: =AM22*(1+$AU22) -> 109.64074 | AO22: =AN22*(1+$AU22) -> 111.03238 | AP22: =AO22*(1+$AU22) -> 112.44169 | AQ22: =AP22*(1+$AU22) -> 113.86888 | AR22: =AQ22*(1+$AU22) -> 115.31419 | ... AT22: =AS22*(1+$AU22) -> 118.26006 | AU22: =AJ22/AI22-1 -> 0.012692723 | AV22: 0.017
A23: Room Air Conditioners | B23: Residential Equipment: Equipment Stock: Space Cooling: Room Air Conditioners: High oil and gas supply | C23: 30-AEO2021.20.highogs-d120120a | D23: millions | F23: 57.979027 | G23: 57.968586 | H23: 57.959606 | I23: 57.95211 | J23: 57.951488 | K23: 57.960857 | L23: 57.973194 | M23: 57.977226 | N23: 57.973316 | O23: 57.963169 | P23: 57.946999 | Q23: 57.925327 | R23: 57.901684 | S23: 57.875652 | T23: 57.847012 | U23: 57.82074 | V23: 57.795208 | W23: 57.769428 | X23: 57.743534 | Y23: 57.718586 | Z23: 57.696892 | AA23: 57.677017 | AB23: 57.658131 | AC23: 57.640438 | AD23: 57.62347 | AE23: 57.607464 | AF23: 57.592182 | AG23: 57.575733 | AH23: 57.558784 | AI23: 57.54269 | AJ23: 57.527027 | AK23: =AJ23*(1+$AU23) -> 57.511368 | AL23: =AK23*(1+$AU23) -> 57.495714 | AM23: =AL23*(1+$AU23) -> 57.480064 | AN23: =AM23*(1+$AU23) -> 57.464418 | AO23: =AN23*(1+$AU23) -> 57.448776 | AP23: =AO23*(1+$AU23) -> 57.433138 | AQ23: =AP23*(1+$AU23) -> 57.417505 | AR23: =AQ23*(1+$AU23) -> 57.401876 | ... AT23: =AS23*(1+$AU23) -> 57.370631 | AU23: =AJ23/AI23-1 -> -0.00027219791 | AV23: 0
A24: Total | B24: Residential Equipment: Equipment Stock: Space Cooling: Total: High oil and gas supply | C24: 30-AEO2021.21.highogs-d120120a | D24: millions | F24: 134.96704 | G24: 136.76564 | H24: 138.56251 | I24: 140.34677 | J24: 142.15883 | K24: 144.03166 | L24: 145.90801 | M24: 147.72433 | N24: 149.4864 | O24: 151.20935 | P24: 152.89368 | Q24: 154.53587 | R24: 156.15727 | S24: 157.7497 | T24: 159.30907 | U24: 160.87151 | V24: 162.42541 | W24: 163.96848 | X24: 165.5012 | Y24: 167.02794 | Z24: 168.56433 | AA24: 170.10135 | AB24: 171.63574 | AC24: 173.17163 | AD24: 174.70697 | AE24: 176.24361 | AF24: 177.78124 | AG24: 179.3105 | AH24: 180.83482 | AI24: 182.36232 | AJ24: 183.89302 | AK24: =AJ24*(1+$AU24) -> 185.43657 | AL24: =AK24*(1+$AU24) -> 186.99308 | AM24: =AL24*(1+$AU24) -> 188.56265 | AN24: =AM24*(1+$AU24) -> 190.14539 | AO24: =AN24*(1+$AU24) -> 191.74142 | AP24: =AO24*(1+$AU24) -> 193.35085 | AQ24: =AP24*(1+$AU24) -> 194.97378 | AR24: =AQ24*(1+$AU24) -> 196.61034 | ... AT24: =AS24*(1+$AU24) -> 199.92478 | AU24: =AJ24/AI24-1 -> 0.0083937351 | AV24: 0.01
A25: Water Heaters (million units) | C25: 30-AEO2021.23.
A26: Electric | B26: Residential Equipment: Equipment Stock: Water Heaters: Electric: High oil and gas supply | C26: 30-AEO2021.24.highogs-d120120a | D26: millions | F26: 59.144028 | G26: 59.619999 | H26: 60.176491 | I26: 60.701748 | J26: 61.2099 | K26: 61.717579 | L26: 62.202168 | M26: 62.647766 | N26: 63.054695 | O26: 63.432339 | P26: 63.788673 | Q26: 64.143646 | R26: 64.507957 | S26: 64.874107 | T26: 65.239677 | U26: 65.619102 | V26: 66.004692 | W26: 66.394569 | X26: 66.788284 | Y26: 67.176643 | Z26: 67.565285 | AA26: 67.950615 | AB26: 68.332207 | AC26: 68.711609 | AD26: 69.088249 | AE26: 69.464256 | AF26: 69.840889 | AG26: 70.214859 | AH26: 70.589462 | AI26: 70.970284 | AJ26: 71.357269 | AK26: =AJ26*(1+$AU26) -> 71.746364 | AL26: =AK26*(1+$AU26) -> 72.137581 | AM26: =AL26*(1+$AU26) -> 72.530931 | AN26: =AM26*(1+$AU26) -> 72.926426 | AO26: =AN26*(1+$AU26) -> 73.324077 | AP26: =AO26*(1+$AU26) -> 73.723897 | AQ26: =AP26*(1+$AU26) -> 74.125897 | AR26: =AQ26*(1+$AU26) -> 74.530089 | ... AT26: =AS26*(1+$AU26) -> 75.345096 | AU26: =AJ26/AI26-1 -> 0.0054527751 | AV26: 0.006
A27: Natural Gas | B27: Residential Equipment: Equipment Stock: Water Heaters: Natural Gas: High oil and gas supply | C27: 30-AEO2021.25.highogs-d120120a | D27: millions | F27: 60.065723 | G27: 60.660275 | H27: 61.304443 | I27: 61.960426 | J27: 62.648998 | K27: 63.384193 | L27: 64.132782 | M27: 64.852921 | N27: 65.551575 | O27: 66.234795 | P27: 66.894508 | Q27: 67.521645 | R27: 68.124603 | S27: 68.699837 | T27: 69.24427 | U27: 69.778008 | V27: 70.294899 | W27: 70.797226 | X27: 71.288422 | Y27: 71.778992 | Z27: 72.277077 | AA27: 72.777733 | AB27: 73.277695 | AC27: 73.779533 | AD27: 74.282188 | AE27: 74.786438 | AF27: 75.290825 | AG27: 75.789009 | AH27: 76.281776 | AI27: 76.771454 | AJ27: 77.258736 | AK27: =AJ27*(1+$AU27) -> 77.749111 | AL27: =AK27*(1+$AU27) -> 78.242598 | AM27: =AL27*(1+$AU27) -> 78.739218 | AN27: =AM27*(1+$AU27) -> 79.23899 | AO27: =AN27*(1+$AU27) -> 79.741933 | AP27: =AO27*(1+$AU27) -> 80.24807 | AQ27: =AP27*(1+$AU27) -> 80.757418 | AR27: =AQ27*(1+$AU27) -> 81.27 | ... AT27: =AS27*(1+$AU27) -> 82.304944 | AU27: =AJ27/AI27-1 -> 0.0063471769 | AV27: 0.008
A28: Distillate Fuel Oil | B28: Residential Equipment: Equipment Stock: Water Heaters: Distillate Fuel Oil: High oil and gas supply | C28: 30-AEO2021.26.highogs-d120120a | D28: millions | F28: 2.645688 | G28: 2.600587 | H28: 2.557136 | I28: 2.513456 | J28: 2.472345 | K28: 2.435079 | L28: 2.399654 | M28: 2.36718 | N28: 2.337591 | O28: 2.310858 | P28: 2.286937 | Q28: 2.261104 | R28: 2.233402 | S28: 2.20452 | T28: 2.174745 | U28: 2.144583 | V28: 2.11454 | W28: 2.084679 | X28: 2.05522 | Y28: 2.026759 | Z28: 1.998826 | AA28: 1.971788 | AB28: 1.945657 | AC28: 1.920432 | AD28: 1.895941 | AE28: 1.871992 | AF28: 1.848593 | AG28: 1.825595 | AH28: 1.802938 | AI28: 1.780446 | AJ28: 1.758198 | AK28: =AJ28*(1+$AU28) -> 1.736228 | AL28: =AK28*(1+$AU28) -> 1.7145325 | AM28: =AL28*(1+$AU28) -> 1.6931082 | AN28: =AM28*(1+$AU28) -> 1.6719515 | AO28: =AN28*(1+$AU28) -> 1.6510593 | AP28: =AO28*(1+$AU28) -> 1.630428 | AQ28: =AP28*(1+$AU28) -> 1.6100546 | AR28: =AQ28*(1+$AU28) -> 1.5899358 | ... AT28: =AS28*(1+$AU28) -> 1.5504492 | AU28: =AJ28/AI28-1 -> -0.012495745 | AV28: -0.014
A29: Propane | B29: Residential Equipment: Equipment Stock: Water Heaters: Propane: High oil and gas supply | C29: 30-AEO2021.27.highogs-d120120a | D29: millions | F29: 4.054796 | G29: 3.961836 | H29: 3.878141 | I29: 3.804585 | J29: 3.742667 | K29: 3.69157 | L29: 3.649184 | M29: 3.611273 | N29: 3.577413 | O29: 3.547936 | P29: 3.522523 | Q29: 3.491105 | R29: 3.455376 | S29: 3.416478 | T29: 3.375241 | U29: 3.333834 | V29: 3.292641 | W29: 3.251569 | X29: 3.211201 | Y29: 3.172485 | Z29: 3.136445 | AA29: 3.102795 | AB29: 3.07125 | AC29: 3.041861 | AD29: 3.014236 | AE29: 2.988221 | AF29: 2.963415 | AG29: 2.939012 | AH29: 2.914999 | AI29: 2.891638 | AJ29: 2.868669 | AK29: =AJ29*(1+$AU29) -> 2.8458824 | AL29: =AK29*(1+$AU29) -> 2.8232769 | AM29: =AL29*(1+$AU29) -> 2.8008509 | AN29: =AM29*(1+$AU29) -> 2.778603 | AO29: =AN29*(1+$AU29) -> 2.7565319 | AP29: =AO29*(1+$AU29) -> 2.7346361 | AQ29: =AP29*(1+$AU29) -> 2.7129142 | AR29: =AQ29*(1+$AU29) -> 2.6913648 | ... AT29: =AS29*(1+$AU29) -> 2.6487783 | AU29: =AJ29/AI29-1 -> -0.0079432488 | AV29: -0.011
A30: Solar Thermal | B30: Residential Equipment: Equipment Stock: Water Heaters: Solar Thermal: High oil and gas supply | C30: 30-AEO2021.28.highogs-d120120a | D30: millions | F30: 1.619339 | G30: 1.767752 | H30: 1.777033 | I30: 1.787264 | J30: 1.79747 | K30: 1.808034 | L30: 1.819156 | M30: 1.830038 | N30: 1.840685 | O30: 1.851122 | P30: 1.861841 | Q30: 1.872775 | R30: 1.883872 | S30: 1.894988 | T30: 1.906009 | U30: 1.916758 | V30: 1.927217 | W30: 1.937276 | X30: 1.946888 | Y30: 1.956742 | Z30: 1.96678 | AA30: 1.976967 | AB30: 1.987235 | AC30: 1.997509 | AD30: 2.007803 | AE30: 2.0181 | AF30: 2.028332 | AG30: 2.038509 | AH30: 2.048583 | AI30: 2.058523 | AJ30: 2.068366 | AK30: =AJ30*(1+$AU30) -> 2.0782561 | AL30: =AK30*(1+$AU30) -> 2.0881934 | AM30: =AL30*(1+$AU30) -> 2.0981783 | AN30: =AM30*(1+$AU30) -> 2.1082109 | AO30: =AN30*(1+$AU30) -> 2.1182915 | AP30: =AO30*(1+$AU30) -> 2.1284203 | AQ30: =AP30*(1+$AU30) -> 2.1385975 | AR30: =AQ30*(1+$AU30) -> 2.1488234 | ... AT30: =AS30*(1+$AU30) -> 2.1694221 | AU30: =AJ30/AI30-1 -> 0.0047815837 | AV30: 0.008
A31: Total | B31: Residential Equipment: Equipment Stock: Water Heaters: Total: High oil and gas supply | C31: 30-AEO2021.29.highogs-d120120a | D31: millions | F31: 127.52957 | G31: 128.61044 | H31: 129.69325 | I31: 130.76747 | J31: 131.87138 | K31: 133.03645 | L31: 134.20294 | M31: 135.30917 | N31: 136.36194 | O31: 137.37705 | P31: 138.35449 | Q31: 139.29027 | R31: 140.20522 | S31: 141.08992 | T31: 141.93994 | U31: 142.79228 | V31: 143.63399 | W31: 144.46533 | X31: 145.29001 | Y31: 146.11162 | Z31: 146.94441 | AA31: 147.77991 | AB31: 148.61403 | AC31: 149.45094 | AD31: 150.28841 | AE31: 151.12901 | AF31: 151.97205 | AG31: 152.80699 | AH31: 153.63776 | AI31: 154.47232 | AJ31: 155.31122 | AK31: =AJ31*(1+$AU31) -> 156.15467 | AL31: =AK31*(1+$AU31) -> 157.0027 | AM31: =AL31*(1+$AU31) -> 157.85534 | AN31: =AM31*(1+$AU31) -> 158.71261 | AO31: =AN31*(1+$AU31) -> 159.57454 | AP31: =AO31*(1+$AU31) -> 160.44114 | AQ31: =AP31*(1+$AU31) -> 161.31245 | AR31: =AQ31*(1+$AU31) -> 162.1885 | ... AT31: =AS31*(1+$AU31) -> 163.95489 | AU31: =AJ31/AI31-1 -> 0.005430727 | AV31: 0.007
A32: Cooking Equipment (million units) | C32: 30-AEO2021.31.
A33: Electric | B33: Residential Equipment: Equipment Stock: Cooking Equipment: Electric: High oil and gas supply | C33: 30-AEO2021.32.highogs-d120120a | D33: millions | F33: 96.368851 | G33: 96.942863 | H33: 97.507462 | I33: 98.056366 | J33: 98.616669 | K33: 99.209564 | L33: 99.791199 | M33: 100.31636 | N33: 100.78964 | O33: 101.19668 | P33: 101.53636 | Q33: 101.79644 | R33: 101.98789 | S33: 102.18788 | T33: 102.41907 | U33: 102.71017 | V33: 103.06227 | W33: 103.47982 | X33: 103.88201 | Y33: 104.27118 | Z33: 104.65609 | AA33: 105.03009 | AB33: 105.38992 | AC33: 105.73807 | AD33: 106.07283 | AE33: 106.39809 | AF33: 106.71592 | AG33: 107.02323 | AH33: 107.32764 | AI33: 107.63994 | AJ33: 107.96524 | AK33: =AJ33*(1+$AU33) -> 108.29153 | AL33: =AK33*(1+$AU33) -> 108.6188 | AM33: =AL33*(1+$AU33) -> 108.94706 | AN33: =AM33*(1+$AU33) -> 109.27631 | AO33: =AN33*(1+$AU33) -> 109.60656 | AP33: =AO33*(1+$AU33) -> 109.9378 | AQ33: =AP33*(1+$AU33) -> 110.27005 | AR33: =AQ33*(1+$AU33) -> 110.6033 | ... AT33: =AS33*(1+$AU33) -> 111.27282 | AU33: =AJ33/AI33-1 -> 0.0030221311 | AV33: 0.004
A34: Natural Gas | B34: Residential Equipment: Equipment Stock: Cooking Equipment: Natural Gas: High oil and gas supply | C34: 30-AEO2021.33.highogs-d120120a | D34: millions | F34: 47.877865 | G34: 48.362202 | H34: 48.858322 | I34: 49.361767 | J34: 49.882469 | K34: 50.43058 | L34: 50.992687 | M34: 51.556805 | N34: 52.125301 | O34: 52.727886 | P34: 53.365761 | Q34: 54.045799 | R34: 54.776047 | S34: 55.464073 | T34: 56.082935 | U34: 56.639286 | V34: 57.11982 | W34: 57.520824 | X34: 57.932938 | Y34: 58.357018 | Z34: 58.798096 | AA34: 59.254616 | AB34: 59.725677 | AC34: 60.212387 | AD34: 60.713413 | AE34: 61.226475 | AF34: 61.748219 | AG34: 62.271156 | AH34: 62.791275 | AI34: 63.305855 | AJ34: 63.811348 | AK34: =AJ34*(1+$AU34) -> 64.320877 | AL34: =AK34*(1+$AU34) -> 64.834475 | AM34: =AL34*(1+$AU34) -> 65.352174 | AN34: =AM34*(1+$AU34) -> 65.874007 | AO34: =AN34*(1+$AU34) -> 66.400006 | AP34: =AO34*(1+$AU34) -> 66.930206 | AQ34: =AP34*(1+$AU34) -> 67.464639 | AR34: =AQ34*(1+$AU34) -> 68.00334 | ... AT34: =AS34*(1+$AU34) -> 69.09368 | AU34: =AJ34/AI34-1 -> 0.0079849328 | AV34: 0.01
