Workbook

Sheet About
A1: BESP BAU EV Subsidy Percentage
A3: Sources: | B3: Federal Tax Credit Methodology
B4: Ernst and Young
B5: 2019
B6: Federal revenue estimates for potential changes to the plug-in electric drive vehicle tax credit
B7: https://www.afpm.org/sites/default/files/issue_resources/EV-Tax-May2019.pdf
B9: Historial Sales by Manufacturer
B10: Argonne National Laboratory
B11: 2022
B12: Data provided on request
B14: State Rebate Amounts
B15: EnergySage
B16: 2021
B17: Electric car tax credits and incentives
B18: https://www.energysage.com/electric-vehicles/costs-and-benefits-evs/ev-tax-credits/
B20: Tesla
B21: 2022
B22: Electric Vehicle & Solar Incentives
B23: https://www.tesla.com/support/incentives
A26: Notes
A27: The U.S. only has BAU subsidies for passenger LDVs, not other vehicle types.
A28: We account for both federal and state-level subsidies for EVs but not for
A29: charging equipment.
A31: For assumptions governing EV tax credit phase-out, see the "Data" tab.
A33: 2020 to 2012 USD (see cpi.xlsx) | B33: 0.88711067

Sheet Summary - HK
A1: Federal EV Subsidy Amount
A2: 2020 | B2: 2021 | C2: 2022 | D2: 2023 | E2: 2024 | F2: 2025 | G2: 2026 | H2: 2027 | I2: 2028 | J2: 2029 | K2: 2030 | L2: 2031 | M2: 2032 | N2: 2033 | O2: 2034 | P2: 2035 | Q2: 2036 | R2: 2037 | S2: 2038 | T2: 2039 | U2: 2040 | V2: 2041 | W2: 2042 | X2: 2043 | Y2: 2044 | Z2: 2045 | AA2: 2046 | AB2: 2047 | AC2: 2048 | AD2: 2049 | AE2: 2050
A3: ='Baseline Calculations'!C104 -> 1066.1677 | B3: ='Baseline Calculations'!D104 -> 1856.0233 | C3: ='Baseline Calculations'!E104 -> 1578.301 | D3: ='Baseline Calculations'!F104 -> 1230.8383 | E3: ='Baseline Calculations'!G104 -> 626.81537 | F3: ='Baseline Calculations'!H104 -> 144.46747 | G3: ='Baseline Calculations'!I104 -> 33.447892 | H3: ='Baseline Calculations'!J104 -> 33.447892 | ... AE3: ='Baseline Calculations'!AG104 -> 9.0924722
A5: State EV Subsidy Amounts
A6: This list only includes rebates on the EV itself, not on charging equipment.
A7: It also omits states that do not offer a rebate but do exempt EVs from sales, use, or excise taxes.
A8: State Rebates + Tax Credits Updated 8/11/2021
A9: TC | C9: https://www.energysage.com/electric-vehicles/costs-and-benefits-evs/ev-tax-credits/
A10: Rebates | C10: https://www.tesla.com/support/incentives
A11: Note: Could be an optimistic estimate
A12: State | B12: Population, millions (June 2022) | C12: Category | D12: 2020 | E12: =D12+1 -> 2021 | F12: =E12+1 -> 2022 | G12: =F12+1 -> 2023 | H12: =G12+1 -> 2024 | I12: =H12+1 -> 2025 | J12: =I12+1 -> 2026
A13: CO | B13: 5.685 | C13: LDV | D13: 4750 | E13: 4750 | F13: 3000 | G13: 3000 | H13: 2400 | I13: 2400 | J13: 2400 | K13: Note: average of cars and truck subsidies, which are different
A14: CT | B14: 3.571 | C14: LDV | D14: 2250 | E14: 2250 | F14: 2250 | G14: 2250 | H14: 2250 | I14: 2250 | J14: 2250 | R14: https://afdc.energy.gov/laws/11609
A15: DE | B15: 0.968 | C15: LDV | D15: 2500 | E15: 2500 | F15: 2500 | G15: 2500 | H15: 2500 | I15: 2500 | J15: 2500
A16: NY | B16: 8.38 | C16: LDV | D16: 2000 | E16: 2000 | F16: 2000 | G16: 2000 | H16: 2000 | I16: 2000 | J16: 2000 | K16: Subsidy goes up to 2000 based on battery
A17: TX | B17: 28.64 | C17: LDV | D17: 2500 | E17: 0 | F17: 0 | G17: 0 | H17: 0 | I17: 0 | J17: 0 | K17: Note: only 1 year program
A18: CA | B18: 39.35 | C18: LDV | D18: 2500 | E18: 2500 | F18: 2500 | G18: 2500 | H18: 2500 | I18: 2500 | J18: 2500
A19: LA | B19: 4.665 | C19: LDV | D19: 1500 | E19: 1500 | F19: 1500 | G19: 1500 | H19: 1500 | I19: 1500 | J19: 1500
A20: ME | B20: 1.341 | C20: LDV | D20: 2000 | E20: 2000 | F20: 2000 | G20: 2000 | H20: 2000 | I20: 2000 | J20: 2000
A21: MD | B21: 6.038 | C21: LDV | D21: 2500 | E21: 2500 | F21: 2500 | G21: 2500 | H21: 2500 | I21: 2500 | J21: 2500
A22: MA | B22: 6.873 | C22: LDV | D22: 2500 | E22: 2500 | F22: 2500 | G22: 2500 | H22: 2500 | I22: 2500 | J22: 2500
A23: NJ | B23: 8.885 | C23: LDV | D23: 5000 | E23: 5000 | F23: 5000 | G23: 5000 | H23: 5000 | I23: 5000 | J23: 5000
A24: OR | B24: 4.176 | C24: LDV | D24: 2500 | E24: 2500 | F24: 2500 | G24: 2500 | H24: 2500 | I24: 2500 | J24: 2500
A25: VT | B25: 0.624 | C25: LDV | D25: 4000 | E25: 4000 | F25: 4000 | G25: 4000 | H25: 4000 | I25: 4000 | J25: 4000 | K25: Note: Up to 4000
A26: Rest of country | B26: =B27-SUM(B13:B25) -> 210.304 | D26: 0 | E26: 0 | F26: 0 | G26: 0 | H26: 0 | I26: 0 | J26: 0
A27: USA | B27: 329.5
A29: Note: Pennsylvania offers a $1750 rebate, but only to the first 250 qualified applicants.
A31: Pop-Weighted State Avg Tax Credit
C32: 2020 | D32: 2021 | E32: 2022 | F32: 2023 | G32: 2024 | H32: 2025 | I32: 2026 | J32: 2027 | K32: 2028 | L32: 2029 | M32: 2030 | N32: 2031 | O32: 2032 | P32: 2033 | Q32: 2034 | R32: 2035 | S32: 2036 | T32: 2037 | U32: 2038 | V32: 2039 | W32: 2040 | X32: 2041 | Y32: 2042 | Z32: 2043 | AA32: 2044 | AB32: 2045 | AC32: 2046 | AD32: 2047 | AE32: 2048 | AF32: 2049 | AG32: 2050
C33: =SUMPRODUCT(D13:D26,$B$13:$B$26)/SUM($B$13:$B$26) -> 981.82549 | D33: =SUMPRODUCT(E13:E26,$B$13:$B$26)/SUM($B$13:$B$26) -> 764.52656 | E33: =SUMPRODUCT(F13:F26,$B$13:$B$26)/SUM($B$13:$B$26) -> 734.33308 | F33: =SUMPRODUCT(G13:G26,$B$13:$B$26)/SUM($B$13:$B$26) -> 734.33308 | G33: =SUMPRODUCT(H13:H26,$B$13:$B$26)/SUM($B$13:$B$26) -> 723.98103 | H33: =SUMPRODUCT(I13:I26,$B$13:$B$26)/SUM($B$13:$B$26) -> 723.98103 | I33: =SUMPRODUCT(J13:J26,$B$13:$B$26)/SUM($B$13:$B$26) -> 723.98103 | J33: =I33 -> 723.98103 | K33: =J33 -> 723.98103 | L33: =K33 -> 723.98103 | M33: =L33 -> 723.98103 | N33: =M33 -> 723.98103 | O33: =N33 -> 723.98103 | P33: =O33 -> 723.98103 | Q33: =P33 -> 723.98103 | ... AG33: =AF33 -> 723.98103
A35: Total Tax Credit (2012$)
C36: 2020 | D36: 2021 | E36: 2022 | F36: 2023 | G36: 2024 | H36: 2025 | I36: 2026 | J36: 2027 | K36: 2028 | L36: 2029 | M36: 2030 | N36: 2031 | O36: 2032 | P36: 2033 | Q36: 2034 | R36: 2035 | S36: 2036 | T36: 2037 | U36: 2038 | V36: 2039 | W36: 2040 | X36: 2041 | Y36: 2042 | Z36: 2043 | AA36: 2044 | AB36: 2045 | AC36: 2046 | AD36: 2047 | AE36: 2048 | AF36: 2049 | AG36: 2050
C37: =(A3+$C$33)*About!$B$33 -> 1816.7966 | D37: =(B3+$C$33)*About!$B$33 -> 2517.486 | E37: =(C3+$C$33)*About!$B$33 -> 2271.1155 | F37: =(D3+$C$33)*About!$B$33 -> 1962.8777 | G37: =(E3+$C$33)*About!$B$33 -> 1427.0425 | H37: =(F3+$C$33)*About!$B$33 -> 999.1465 | I37: =(G3+$C$33)*About!$B$33 -> 900.65985 | J37: =(H3+$C$33)*About!$B$33 -> 900.65985 | ... AG37: =(AE3+$C$33)*About!$B$33 -> 879.0539
A39: Time (Year) | C39: 2020 | D39: 2021 | E39: 2022 | F39: 2023 | G39: 2024 | H39: 2025 | I39: 2026 | J39: 2027 | K39: 2028 | L39: 2029 | M39: 2030 | N39: 2031 | O39: 2032 | P39: 2033 | Q39: 2034 | R39: 2035 | S39: 2036 | T39: 2037 | U39: 2038 | V39: 2039 | W39: 2040 | X39: 2041 | Y39: 2042 | Z39: 2043 | AA39: 2044 | AB39: 2045 | AC39: 2046 | AD39: 2047 | AE39: 2048 | AF39: 2049 | AG39: 2050
A40: New Vehicle Price after RnD[LDVs,passenger,battery electric vehicle] : MostRecentRun | C40: 49824 | D40: 46173.6 | E40: 43530.5 | F40: 41513.3 | G40: 39946.3 | H40: 38679.5 | I40: 37326.7 | J40: 36099.2 | K40: 34664.5 | L40: 33628.9 | M40: 32666.3 | N40: 32118.8 | O40: 31643.2 | P40: 31237.2 | Q40: 30885.3 | R40: 30578 | S40: 30305.7 | T40: 30065.9 | U40: 29852.9 | V40: 29660.9 | W40: 29486.9 | X40: 29330.6 | Y40: 29189.2 | Z40: 29060.4 | AA40: 28942.9 | AB40: 28835.1 | AC40: 28735.8 | AD40: 28643.9 | AE40: 28558.5 | AF40: 28478.6 | AG40: 28404.1
A42: Approximate EV Subsidy Percentage
C43: 2020 | D43: 2021 | E43: 2022 | F43: 2023 | G43: 2024 | H43: 2025 | I43: 2026 | J43: 2027 | K43: 2028 | L43: 2029 | M43: 2030 | N43: 2031 | O43: 2032 | P43: 2033 | Q43: 2034 | R43: 2035 | S43: 2036 | T43: 2037 | U43: 2038 | V43: 2039 | W43: 2040 | X43: 2041 | Y43: 2042 | Z43: 2043 | AA43: 2044 | AB43: 2045 | AC43: 2046 | AD43: 2047 | AE43: 2048 | AF43: 2049 | AG43: 2050
C44: =C37/C40 -> 0.036464286 | D44: =D37/D40 -> 0.054522194 | E44: =E37/E40 -> 0.052172971 | F44: =F37/F40 -> 0.047283104 | G44: =G37/G40 -> 0.035724021 | H44: =H37/H40 -> 0.025831422 | I44: =I37/I40 -> 0.024129105 | J44: =J37/J40 -> 0.024949579 | ... AG44: =AG37/AG40 -> 0.030948134
A46: Government EV Subsidy (First Registration Tax Scheme)
C47: 2018 | D47: 2019 | E47: 2020 | F47: 2021 | G47: 2022 | H47: 2023 | I47: 2024
...

Sheet Summary - US
A1: Federal EV Subsidy Amount
A2: 2020 | B2: 2021 | C2: 2022 | D2: 2023 | E2: 2024 | F2: 2025 | G2: 2026 | H2: 2027 | I2: 2028 | J2: 2029 | K2: 2030 | L2: 2031 | M2: 2032 | N2: 2033 | O2: 2034 | P2: 2035 | Q2: 2036 | R2: 2037 | S2: 2038 | T2: 2039 | U2: 2040 | V2: 2041 | W2: 2042 | X2: 2043 | Y2: 2044 | Z2: 2045 | AA2: 2046 | AB2: 2047 | AC2: 2048 | AD2: 2049 | AE2: 2050
A3: ='Baseline Calculations'!C104 -> 1066.1677 | B3: ='Baseline Calculations'!D104 -> 1856.0233 | C3: ='Baseline Calculations'!E104 -> 1578.301 | D3: ='Baseline Calculations'!F104 -> 1230.8383 | E3: ='Baseline Calculations'!G104 -> 626.81537 | F3: ='Baseline Calculations'!H104 -> 144.46747 | G3: ='Baseline Calculations'!I104 -> 33.447892 | H3: ='Baseline Calculations'!J104 -> 33.447892 | ... AE3: ='Baseline Calculations'!AG104 -> 9.0924722
A5: State EV Subsidy Amounts
A6: This list only includes rebates on the EV itself, not on charging equipment.
A7: It also omits states that do not offer a rebate but do exempt EVs from sales, use, or excise taxes.
A8: State Rebates + Tax Credits Updated 8/11/2021
A9: TC | C9: https://www.energysage.com/electric-vehicles/costs-and-benefits-evs/ev-tax-credits/
A10: Rebates | C10: https://www.tesla.com/support/incentives
A11: Note: Could be an optimistic estimate
A12: State | B12: Population, millions (June 2022) | C12: Category | D12: 2020 | E12: =D12+1 -> 2021 | F12: =E12+1 -> 2022 | G12: =F12+1 -> 2023 | H12: =G12+1 -> 2024 | I12: =H12+1 -> 2025 | J12: =I12+1 -> 2026
A13: CO | B13: 5.685 | C13: LDV | D13: 4750 | E13: 4750 | F13: 3000 | G13: 3000 | H13: 2400 | I13: 2400 | J13: 2400 | K13: Note: average of cars and truck subsidies, which are different
A14: CT | B14: 3.571 | C14: LDV | D14: 2250 | E14: 2250 | F14: 2250 | G14: 2250 | H14: 2250 | I14: 2250 | J14: 2250 | R14: https://afdc.energy.gov/laws/11609
A15: DE | B15: 0.968 | C15: LDV | D15: 2500 | E15: 2500 | F15: 2500 | G15: 2500 | H15: 2500 | I15: 2500 | J15: 2500
A16: NY | B16: 8.38 | C16: LDV | D16: 2000 | E16: 2000 | F16: 2000 | G16: 2000 | H16: 2000 | I16: 2000 | J16: 2000 | K16: Subsidy goes up to 2000 based on battery
A17: TX | B17: 28.64 | C17: LDV | D17: 2500 | E17: 0 | F17: 0 | G17: 0 | H17: 0 | I17: 0 | J17: 0 | K17: Note: only 1 year program
A18: CA | B18: 39.35 | C18: LDV | D18: 2500 | E18: 2500 | F18: 2500 | G18: 2500 | H18: 2500 | I18: 2500 | J18: 2500
A19: LA | B19: 4.665 | C19: LDV | D19: 1500 | E19: 1500 | F19: 1500 | G19: 1500 | H19: 1500 | I19: 1500 | J19: 1500
A20: ME | B20: 1.341 | C20: LDV | D20: 2000 | E20: 2000 | F20: 2000 | G20: 2000 | H20: 2000 | I20: 2000 | J20: 2000
A21: MD | B21: 6.038 | C21: LDV | D21: 2500 | E21: 2500 | F21: 2500 | G21: 2500 | H21: 2500 | I21: 2500 | J21: 2500
A22: MA | B22: 6.873 | C22: LDV | D22: 2500 | E22: 2500 | F22: 2500 | G22: 2500 | H22: 2500 | I22: 2500 | J22: 2500
A23: NJ | B23: 8.885 | C23: LDV | D23: 5000 | E23: 5000 | F23: 5000 | G23: 5000 | H23: 5000 | I23: 5000 | J23: 5000
A24: OR | B24: 4.176 | C24: LDV | D24: 2500 | E24: 2500 | F24: 2500 | G24: 2500 | H24: 2500 | I24: 2500 | J24: 2500
A25: VT | B25: 0.624 | C25: LDV | D25: 4000 | E25: 4000 | F25: 4000 | G25: 4000 | H25: 4000 | I25: 4000 | J25: 4000 | K25: Note: Up to 4000
A26: Rest of country | B26: =B27-SUM(B13:B25) -> 210.304 | D26: 0 | E26: 0 | F26: 0 | G26: 0 | H26: 0 | I26: 0 | J26: 0
A27: USA | B27: 329.5
A29: Note: Pennsylvania offers a $1750 rebate, but only to the first 250 qualified applicants.
A31: Pop-Weighted State Avg Tax Credit
C32: 2020 | D32: 2021 | E32: 2022 | F32: 2023 | G32: 2024 | H32: 2025 | I32: 2026 | J32: 2027 | K32: 2028 | L32: 2029 | M32: 2030 | N32: 2031 | O32: 2032 | P32: 2033 | Q32: 2034 | R32: 2035 | S32: 2036 | T32: 2037 | U32: 2038 | V32: 2039 | W32: 2040 | X32: 2041 | Y32: 2042 | Z32: 2043 | AA32: 2044 | AB32: 2045 | AC32: 2046 | AD32: 2047 | AE32: 2048 | AF32: 2049 | AG32: 2050
C33: =SUMPRODUCT(D13:D26,$B$13:$B$26)/SUM($B$13:$B$26) -> 981.82549 | D33: =SUMPRODUCT(E13:E26,$B$13:$B$26)/SUM($B$13:$B$26) -> 764.52656 | E33: =SUMPRODUCT(F13:F26,$B$13:$B$26)/SUM($B$13:$B$26) -> 734.33308 | F33: =SUMPRODUCT(G13:G26,$B$13:$B$26)/SUM($B$13:$B$26) -> 734.33308 | G33: =SUMPRODUCT(H13:H26,$B$13:$B$26)/SUM($B$13:$B$26) -> 723.98103 | H33: =SUMPRODUCT(I13:I26,$B$13:$B$26)/SUM($B$13:$B$26) -> 723.98103 | I33: =SUMPRODUCT(J13:J26,$B$13:$B$26)/SUM($B$13:$B$26) -> 723.98103 | J33: =I33 -> 723.98103 | K33: =J33 -> 723.98103 | L33: =K33 -> 723.98103 | M33: =L33 -> 723.98103 | N33: =M33 -> 723.98103 | O33: =N33 -> 723.98103 | P33: =O33 -> 723.98103 | Q33: =P33 -> 723.98103 | ... AG33: =AF33 -> 723.98103
A35: Total Tax Credit (2012$)
C36: 2020 | D36: 2021 | E36: 2022 | F36: 2023 | G36: 2024 | H36: 2025 | I36: 2026 | J36: 2027 | K36: 2028 | L36: 2029 | M36: 2030 | N36: 2031 | O36: 2032 | P36: 2033 | Q36: 2034 | R36: 2035 | S36: 2036 | T36: 2037 | U36: 2038 | V36: 2039 | W36: 2040 | X36: 2041 | Y36: 2042 | Z36: 2043 | AA36: 2044 | AB36: 2045 | AC36: 2046 | AD36: 2047 | AE36: 2048 | AF36: 2049 | AG36: 2050
C37: =(A3+$C$33)*About!$B$33 -> 1816.7966 | D37: =(B3+$C$33)*About!$B$33 -> 2517.486 | E37: =(C3+$C$33)*About!$B$33 -> 2271.1155 | F37: =(D3+$C$33)*About!$B$33 -> 1962.8777 | G37: =(E3+$C$33)*About!$B$33 -> 1427.0425 | H37: =(F3+$C$33)*About!$B$33 -> 999.1465 | I37: =(G3+$C$33)*About!$B$33 -> 900.65985 | J37: =(H3+$C$33)*About!$B$33 -> 900.65985 | ... AG37: =(AE3+$C$33)*About!$B$33 -> 879.0539
A39: Time (Year) | C39: 2020 | D39: 2021 | E39: 2022 | F39: 2023 | G39: 2024 | H39: 2025 | I39: 2026 | J39: 2027 | K39: 2028 | L39: 2029 | M39: 2030 | N39: 2031 | O39: 2032 | P39: 2033 | Q39: 2034 | R39: 2035 | S39: 2036 | T39: 2037 | U39: 2038 | V39: 2039 | W39: 2040 | X39: 2041 | Y39: 2042 | Z39: 2043 | AA39: 2044 | AB39: 2045 | AC39: 2046 | AD39: 2047 | AE39: 2048 | AF39: 2049 | AG39: 2050
A40: New Vehicle Price after RnD[LDVs,passenger,battery electric vehicle] : MostRecentRun | C40: 49824 | D40: 46173.6 | E40: 43530.5 | F40: 41513.3 | G40: 39946.3 | H40: 38679.5 | I40: 37326.7 | J40: 36099.2 | K40: 34664.5 | L40: 33628.9 | M40: 32666.3 | N40: 32118.8 | O40: 31643.2 | P40: 31237.2 | Q40: 30885.3 | R40: 30578 | S40: 30305.7 | T40: 30065.9 | U40: 29852.9 | V40: 29660.9 | W40: 29486.9 | X40: 29330.6 | Y40: 29189.2 | Z40: 29060.4 | AA40: 28942.9 | AB40: 28835.1 | AC40: 28735.8 | AD40: 28643.9 | AE40: 28558.5 | AF40: 28478.6 | AG40: 28404.1
A42: Approximate EV Subsidy Percentage
C43: 2020 | D43: 2021 | E43: 2022 | F43: 2023 | G43: 2024 | H43: 2025 | I43: 2026 | J43: 2027 | K43: 2028 | L43: 2029 | M43: 2030 | N43: 2031 | O43: 2032 | P43: 2033 | Q43: 2034 | R43: 2035 | S43: 2036 | T43: 2037 | U43: 2038 | V43: 2039 | W43: 2040 | X43: 2041 | Y43: 2042 | Z43: 2043 | AA43: 2044 | AB43: 2045 | AC43: 2046 | AD43: 2047 | AE43: 2048 | AF43: 2049 | AG43: 2050
C44: =C37/C40 -> 0.036464286 | D44: =D37/D40 -> 0.054522194 | E44: =E37/E40 -> 0.052172971 | F44: =F37/F40 -> 0.047283104 | G44: =G37/G40 -> 0.035724021 | H44: =H37/H40 -> 0.025831422 | I44: =I37/I40 -> 0.024129105 | J44: =J37/J40 -> 0.024949579 | ... AG44: =AG37/AG40 -> 0.030948134

Sheet Baseline Calculations
D1: Projected Cumulative Sales
B2: 2020 | C2: 2021 | D2: 2022 | E2: 2023 | F2: 2024 | G2: 2025 | H2: 2026 | I2: 2027 | J2: 2028 | K2: 2029 | L2: 2030 | M2: 2031 | N2: 2032 | O2: 2033 | P2: 2034 | Q2: 2035 | R2: 2036 | S2: 2037 | T2: 2038 | U2: 2039 | V2: 2040 | W2: 2041 | X2: 2042 | Y2: 2043 | Z2: 2044 | AA2: 2045 | AB2: 2046 | AC2: 2047 | AD2: 2048 | AE2: 2049 | AF2: 2050
A3: Tesla | B3: =SUM('PEV Sales by Manufacturer'!D4:M4) -> 687269 | C3: =SUM('PEV Sales by Manufacturer'!D4:N4) -> 1008187 | D3: =C3+D32+D56 -> 1775770.6 | E3: =D3+E32+E56 -> 2893800.1 | F3: =E3+F32+F56 -> 4437118.6 | G3: =F3+G32+G56 -> 6399691.3 | H3: =G3+H32+H56 -> 8714085.8 | I3: =H3+I32+I56 -> 11395467 | J3: =I3+J32+J56 -> 14460255 | K3: =J3+K32+K56 -> 17883738 | ... AF3: =AE3+AF32+AF56 -> 1.4609994e+08
A4: GM (Cadillac and Chevrolet) | B4: =SUM('PEV Sales by Manufacturer'!D5:M5) -> 246675 | C4: =SUM('PEV Sales by Manufacturer'!D5:N5) -> 271520 | D4: =C4+D33+D57 -> 330946.81 | E4: =D4+E33+E57 -> 417505.81 | F4: =E4+F33+F57 -> 536991.86 | G4: =F4+G33+G57 -> 688934.15 | H4: =G4+H33+H57 -> 868108.02 | I4: =H4+I33+I57 -> 1075681.8 | J4: =I4+J33+J57 -> 1312920.8 | K4: =J4+K33+K57 -> 1577912.5 | ... AF4: =AE4+AF33+AF57 -> 11500099
A5: Nissan | B5: =SUM('PEV Sales by Manufacturer'!D6:M6) -> 151452 | C5: =SUM('PEV Sales by Manufacturer'!D6:N6) -> 165691 | D5: =C5+D34+D58 -> 199748.37 | E5: =D5+E34+E58 -> 249354.88 | F5: =E5+F34+F58 -> 317831.29 | G5: =F5+G34+G58 -> 404909.83 | H5: =G5+H34+H58 -> 507598.57 | I5: =H5+I34+I58 -> 626570.33 | J5: =I5+J34+J58 -> 762553.73 | K5: =J5+K34+K58 -> 914452.29 | ... AF5: =AE5+AF34+AF58 -> 6603352.5
A6: Toyota | B6: =SUM('PEV Sales by Manufacturer'!D7:M7) -> 135451 | C6: =SUM('PEV Sales by Manufacturer'!D7:N7) -> 188218 | D6: =C6+D35+D59 -> 319773.88 | E6: =D6+E35+E59 -> 512815.07 | F6: =E6+F35+F59 -> 781733.99 | G6: =F6+G35+G59 -> 1113667.8 | H6: =G6+H35+H59 -> 1483791.5 | I6: =H6+I35+I59 -> 1875885.4 | J6: =I6+J35+J59 -> 2273077.7 | K6: =J6+K35+K59 -> 2673237.5 | ... AF6: =AE6+AF35+AF59 -> 10157425
A7: Ford | B7: =SUM('PEV Sales by Manufacturer'!D8:M8) -> 126312 | C7: =SUM('PEV Sales by Manufacturer'!D8:N8) -> 159546 | D7: =C7+D36+D60 -> 239645.49 | E7: =D7+E36+E60 -> 356477.09 | F7: =E7+F36+F60 -> 518029.24 | G7: =F7+G36+G60 -> 722324.26 | H7: =G7+H36+H60 -> 960813.52 | I7: =H7+I36+I60 -> 1232935 | J7: =I7+J36+J60 -> 1538158.9 | K7: =J7+K36+K60 -> 1874146.3 | ... AF7: =AE7+AF36+AF60 -> 13602590
A8: BMW N. America | B8: =SUM('PEV Sales by Manufacturer'!D9:M9) -> 109611 | C8: =SUM('PEV Sales by Manufacturer'!D9:N9) -> 132675 | D8: =C8+D37+D61 -> 189823.87 | E8: =D8+E37+E61 -> 273592.3 | F8: =E8+F37+F61 -> 390133.3 | G8: =F8+G37+G61 -> 534608.6 | H8: =G8+H37+H61 -> 697074.75 | I8: =H8+I37+I61 -> 871678.1 | J8: =I8+J37+J61 -> 1052336.8 | K8: =J8+K37+K61 -> 1237991.9 | ... AF8: =AE8+AF37+AF61 -> 5407332.1
A9: FCA (Chrysler and Fiat) | B9: =SUM('PEV Sales by Manufacturer'!D10:M10) -> 37707 | C9: =SUM('PEV Sales by Manufacturer'!D10:N10) -> 86430 | D9: =C9+D38+D62 -> 207903.59 | E9: =D9+E38+E62 -> 386150.34 | F9: =E9+F38+F62 -> 634459.63 | G9: =F9+G38+G62 -> 940954.39 | H9: =G9+H38+H62 -> 1282712.3 | I9: =H9+I38+I62 -> 1644756.6 | J9: =I9+J38+J62 -> 2011508.5 | K9: =J9+K38+K62 -> 2381000.6 | ... AF9: =AE9+AF38+AF62 -> 9291608.6
A10: Honda | B10: =SUM('PEV Sales by Manufacturer'!D11:M11) -> 39002 | C10: =SUM('PEV Sales by Manufacturer'!D11:N11) -> 41317 | D10: =C10+D39+D63 -> 47088.534 | E10: =D10+E39+E63 -> 55557.485 | F10: =E10+F39+F63 -> 67355.24 | G10: =F10+G39+G63 -> 81917.702 | H10: =G10+H39+H63 -> 98156.013 | I10: =H10+I39+I63 -> 115358.92 | J10: =I10+J39+J63 -> 132786.62 | K10: =J10+K39+K63 -> 150345.56 | ... AF10: =AE10+AF39+AF63 -> 478950.39
A11: Audi | B11: =SUM('PEV Sales by Manufacturer'!D12:M12) -> 26628 | C11: =SUM('PEV Sales by Manufacturer'!D12:N12) -> 46647 | D11: =C11+D40+D64 -> 95435.2 | E11: =D11+E40+E64 -> 166739.1 | F11: =E11+F40+F64 -> 265581.04 | G11: =F11+G40+G64 -> 389572.71 | H11: =G11+H40+H64 -> 532179.46 | I11: =H11+I40+I64 -> 691175.69 | J11: =I11+J40+J64 -> 864268.75 | K11: =J11+K40+K64 -> 1050244.6 | ... AF11: =AE11+AF40+AF64 -> 6743860
A12: Hyundai | B12: =SUM('PEV Sales by Manufacturer'!D13:M13) -> 25223 | C12: =SUM('PEV Sales by Manufacturer'!D13:N13) -> 42236 | D12: =C12+D41+D65 -> 83552.19 | E12: =D12+E41+E65 -> 143897.6 | F12: =E12+F41+F65 -> 227483.4 | G12: =F12+G41+G65 -> 332604.35 | H12: =G12+H41+H65 -> 454082.46 | I12: =H12+I41+I65 -> 590537.77 | J12: =I12+J41+J65 -> 740556.77 | K12: =J12+K41+K65 -> 903054.89 | ... AF12: =AE12+AF41+AF65 -> 6113364.9
A13: Kia | B13: =SUM('PEV Sales by Manufacturer'!D14:M14) -> 24512 | C13: =SUM('PEV Sales by Manufacturer'!D14:N14) -> 39129 | D13: =C13+D42+D66 -> 74688.211 | E13: =D13+E42+E66 -> 126641.29 | F13: =E13+F42+F66 -> 198630.44 | G13: =F13+G42+G66 -> 289053.5 | H13: =G13+H42+H66 -> 393303.1 | I13: =H13+I42+I66 -> 509977.56 | J13: =I13+J42+J66 -> 637636.48 | K13: =J13+K42+K66 -> 775370.34 | ... AF13: =AE13+AF42+AF66 -> 5094893
A14: Volvo | B14: =SUM('PEV Sales by Manufacturer'!D15:M15) -> 19669 | C14: =SUM('PEV Sales by Manufacturer'!D15:N15) -> 45138 | D14: =C14+D43+D67 -> 107636.74 | E14: =D14+E43+E67 -> 199090.45 | F14: =E14+F43+F67 -> 326055.93 | G14: =F14+G43+G67 -> 484543.48 | H14: =G14+H43+H67 -> 665138.64 | I14: =H14+I43+I67 -> 863510.35 | J14: =I14+J43+J67 -> 1075173.5 | K14: =J14+K43+K67 -> 1298738.3 | ... AF14: =AE14+AF43+AF67 -> 7452768.6
... A24: Mazda | B24: =SUM('PEV Sales by Manufacturer'!D25:M25) -> 0 | C24: =SUM('PEV Sales by Manufacturer'!D25:N25) -> 116 | D24: =C24+D53+D77 -> 393.45311 | E24: =D24+E53+E77 -> 797.57947 | F24: =E24+F53+F77 -> 1355.4321 | G24: =F24+G53+G77 -> 2064.8296 | H24: =G24+H53+H77 -> 2901.3977 | I24: =H24+I53+I77 -> 3870.6178 | J24: =I24+J53+J77 -> 4978.4255 | K24: =J24+K53+K77 -> 6215.8883 | ... AF24: =AE24+AF53+AF77 -> 52561.308
A26: BAU Projected Sales in EPS
A27: Time (Year) | B27: 2020 | C27: 2021 | D27: 2022 | E27: 2023 | F27: 2024 | G27: 2025 | H27: 2026 | I27: 2027 | J27: 2028 | K27: 2029 | L27: 2030 | M27: 2031 | N27: 2032 | O27: 2033 | P27: 2034 | Q27: 2035 | R27: 2036 | S27: 2037 | T27: 2038 | U27: 2039 | V27: 2040 | W27: 2041 | X27: 2042 | Y27: 2043 | Z27: 2044 | AA27: 2045 | AB27: 2046 | AC27: 2047 | AD27: 2048 | AE27: 2049 | AF27: 2050
A28: New Vehicles[LDVs,passenger,battery electric vehicle] : MostRecentRun | B28: 349182 | C28: 603744 | D28: 1098920 | E28: 1600640 | F28: 2209510 | G28: 2809740 | H28: 3313430 | I28: 3838830 | J28: 4387740 | K28: 4901270 | L28: 5460140 | M28: 5896040 | N28: 6271520 | O28: 6625100 | P28: 6942390 | Q28: 7274900 | R28: 7567320 | S28: 7866920 | T28: 8176700 | U28: 8461000 | V28: 8757100 | W28: 9060000 | X28: 9346980 | Y28: 9657430 | Z28: 9970180 | AA28: 10265600 | AB28: 10577800 | AC28: 10885700 | AD28: 11185100 | AE28: 11495700 | AF28: 11818600
A29: New Vehicles[LDVs,passenger,plugin hybrid vehicle] : MostRecentRun | B29: 86889 | C29: 248313 | D29: 434007 | E29: 636849 | F29: 887172 | G29: 1095060 | H29: 1221050 | I29: 1293530 | J29: 1310350 | K29: 1320140 | L29: 1310940 | M29: 1306520 | N29: 1289590 | O29: 1270880 | P29: 1252620 | Q29: 1235240 | R29: 1219780 | S29: 1204400 | T29: 1191940 | U29: 1177850 | V29: 1166230 | W29: 1155260 | X29: 1143250 | Y29: 1133420 | Z29: 1123340 | AA29: 1112470 | AB29: 1102060 | AC29: 1091130 | AD29: 1079340 | AE29: 1067910 | AF29: 1056400
A31: Projected Annual BEV Sales by Manufacturer | B31: 2020 | C31: 2021 | D31: 2022 | E31: 2023 | F31: 2024 | G31: 2025 | H31: 2026 | I31: 2027 | J31: 2028 | K31: 2029 | L31: 2030 | M31: 2031 | N31: 2032 | O31: 2033 | P31: 2034 | Q31: 2035 | R31: 2036 | S31: 2037 | T31: 2038 | U31: 2039 | V31: 2040 | W31: 2041 | X31: 2042 | Y31: 2043 | Z31: 2044 | AA31: 2045 | AB31: 2046 | AC31: 2047 | AD31: 2048 | AE31: 2049 | AF31: 2050
A32: Tesla | B32: ='PEV Sales by Manufacturer'!M31 -> 183829 | C32: ='PEV Sales by Manufacturer'!N31 -> 320918 | D32: =D$28*'PEV Sales by Manufacturer'!$S31 -> 767583.59 | E32: =E$28*'PEV Sales by Manufacturer'!$S31 -> 1118029.5 | F32: =F$28*'PEV Sales by Manufacturer'!$S31 -> 1543318.5 | G32: =G$28*'PEV Sales by Manufacturer'!$S31 -> 1962572.6 | H32: =H$28*'PEV Sales by Manufacturer'!$S31 -> 2314394.6 | I32: =I$28*'PEV Sales by Manufacturer'!$S31 -> 2681380.7 | J32: =J$28*'PEV Sales by Manufacturer'!$S31 -> 3064788.3 | K32: =K$28*'PEV Sales by Manufacturer'!$S31 -> 3423483.4 | ... AF32: =AF$28*'PEV Sales by Manufacturer'!$S31 -> 8255162.7
A33: GM (Cadillac and Chevrolet) | B33: ='PEV Sales by Manufacturer'!M32 -> 20754 | C33: ='PEV Sales by Manufacturer'!N32 -> 24829 | D33: =D$28*'PEV Sales by Manufacturer'!$S32 -> 59386.924 | E33: =E$28*'PEV Sales by Manufacturer'!$S32 -> 86500.46 | F33: =F$28*'PEV Sales by Manufacturer'!$S32 -> 119404.51 | G33: =G$28*'PEV Sales by Manufacturer'!$S32 -> 151841.64 | H33: =H$28*'PEV Sales by Manufacturer'!$S32 -> 179061.64 | I33: =I$28*'PEV Sales by Manufacturer'!$S32 -> 207454.87 | J33: =J$28*'PEV Sales by Manufacturer'!$S32 -> 237118.61 | K33: =K$28*'PEV Sales by Manufacturer'!$S32 -> 264870.37 | ... AF33: =AF$28*'PEV Sales by Manufacturer'!$S32 -> 638690.99
A34: Nissan | B34: ='PEV Sales by Manufacturer'!M33 -> 9564 | C34: ='PEV Sales by Manufacturer'!N33 -> 14239 | D34: =D$28*'PEV Sales by Manufacturer'!$S33 -> 34057.369 | E34: =E$28*'PEV Sales by Manufacturer'!$S33 -> 49606.511 | F34: =F$28*'PEV Sales by Manufacturer'!$S33 -> 68476.41 | G34: =G$28*'PEV Sales by Manufacturer'!$S33 -> 87078.542 | H34: =H$28*'PEV Sales by Manufacturer'!$S33 -> 102688.74 | I34: =I$28*'PEV Sales by Manufacturer'!$S33 -> 118971.76 | J34: =J$28*'PEV Sales by Manufacturer'!$S33 -> 135983.4 | K34: =K$28*'PEV Sales by Manufacturer'!$S33 -> 151898.56 | ... AF34: =AF$28*'PEV Sales by Manufacturer'!$S33 -> 366278.18
A35: Toyota | B35: ='PEV Sales by Manufacturer'!M34 -> 0 | C35: ='PEV Sales by Manufacturer'!N34 -> 0 | D35: =D$28*'PEV Sales by Manufacturer'!$S34 -> 0 | E35: =E$28*'PEV Sales by Manufacturer'!$S34 -> 0 | F35: =F$28*'PEV Sales by Manufacturer'!$S34 -> 0 | G35: =G$28*'PEV Sales by Manufacturer'!$S34 -> 0 | H35: =H$28*'PEV Sales by Manufacturer'!$S34 -> 0 | I35: =I$28*'PEV Sales by Manufacturer'!$S34 -> 0 | J35: =J$28*'PEV Sales by Manufacturer'!$S34 -> 0 | K35: =K$28*'PEV Sales by Manufacturer'!$S34 -> 0 | ... AF35: =AF$28*'PEV Sales by Manufacturer'!$S34 -> 0
A36: Ford | B36: ='PEV Sales by Manufacturer'!M35 -> 3 | C36: ='PEV Sales by Manufacturer'!N35 -> 27221 | D36: =D$28*'PEV Sales by Manufacturer'!$S35 -> 65108.198 | E36: =E$28*'PEV Sales by Manufacturer'!$S35 -> 94833.825 | F36: =F$28*'PEV Sales by Manufacturer'!$S35 -> 130907.81 | G36: =G$28*'PEV Sales by Manufacturer'!$S35 -> 166469.91 | H36: =H$28*'PEV Sales by Manufacturer'!$S35 -> 196312.25 | I36: =I$28*'PEV Sales by Manufacturer'!$S35 -> 227440.86 | J36: =J$28*'PEV Sales by Manufacturer'!$S35 -> 259962.37 | K36: =K$28*'PEV Sales by Manufacturer'!$S35 -> 290387.71 | ... AF36: =AF$28*'PEV Sales by Manufacturer'!$S35 -> 700221.81
A37: BMW N. America | B37: ='PEV Sales by Manufacturer'!M36 -> 2640 | C37: ='PEV Sales by Manufacturer'!N36 -> 3485 | D37: =D$28*'PEV Sales by Manufacturer'!$S36 -> 8335.5524 | E37: =E$28*'PEV Sales by Manufacturer'!$S36 -> 12141.21 | F37: =F$28*'PEV Sales by Manufacturer'!$S36 -> 16759.624 | G37: =G$28*'PEV Sales by Manufacturer'!$S36 -> 21312.502 | H37: =H$28*'PEV Sales by Manufacturer'!$S36 -> 25133.103 | I37: =I$28*'PEV Sales by Manufacturer'!$S36 -> 29118.379 | J37: =J$28*'PEV Sales by Manufacturer'!$S36 -> 33281.983 | K37: =K$28*'PEV Sales by Manufacturer'!$S36 -> 37177.222 | ... AF37: =AF$28*'PEV Sales by Manufacturer'!$S36 -> 89646.707
A38: FCA (Chrysler and Fiat) | B38: ='PEV Sales by Manufacturer'!M37 -> 70 | C38: ='PEV Sales by Manufacturer'!N37 -> 0 | D38: =D$28*'PEV Sales by Manufacturer'!$S37 -> 0 | E38: =E$28*'PEV Sales by Manufacturer'!$S37 -> 0 | F38: =F$28*'PEV Sales by Manufacturer'!$S37 -> 0 | G38: =G$28*'PEV Sales by Manufacturer'!$S37 -> 0 | H38: =H$28*'PEV Sales by Manufacturer'!$S37 -> 0 | I38: =I$28*'PEV Sales by Manufacturer'!$S37 -> 0 | J38: =J$28*'PEV Sales by Manufacturer'!$S37 -> 0 | K38: =K$28*'PEV Sales by Manufacturer'!$S37 -> 0 | ... AF38: =AF$28*'PEV Sales by Manufacturer'!$S37 -> 0
A39: Honda | B39: ='PEV Sales by Manufacturer'!M38 -> 45 | C39: ='PEV Sales by Manufacturer'!N38 -> 1 | D39: =D$28*'PEV Sales by Manufacturer'!$S38 -> 2.3918371 | E39: =E$28*'PEV Sales by Manufacturer'!$S38 -> 3.4838479 | F39: =F$28*'PEV Sales by Manufacturer'!$S38 -> 4.8090744 | G39: =G$28*'PEV Sales by Manufacturer'!$S38 -> 6.1154956 | H39: =H$28*'PEV Sales by Manufacturer'!$S38 -> 7.2117942 | I39: =I$28*'PEV Sales by Manufacturer'!$S38 -> 8.3553454 | J39: =J$28*'PEV Sales by Manufacturer'!$S38 -> 9.5500668 | K39: =K$28*'PEV Sales by Manufacturer'!$S38 -> 10.667783 | ... AF39: =AF$28*'PEV Sales by Manufacturer'!$S38 -> 25.723589
A40: Audi | B40: ='PEV Sales by Manufacturer'!M39 -> 7202 | C40: ='PEV Sales by Manufacturer'!N39 -> 11076 | D40: =D$28*'PEV Sales by Manufacturer'!$S39 -> 26491.988 | E40: =E$28*'PEV Sales by Manufacturer'!$S39 -> 38587.1 | F40: =F$28*'PEV Sales by Manufacturer'!$S39 -> 53265.308 | G40: =G$28*'PEV Sales by Manufacturer'!$S39 -> 67735.229 | H40: =H$28*'PEV Sales by Manufacturer'!$S39 -> 79877.833 | I40: =I$28*'PEV Sales by Manufacturer'!$S39 -> 92543.805 | J40: =J$28*'PEV Sales by Manufacturer'!$S39 -> 105776.54 | K40: =K$28*'PEV Sales by Manufacturer'!$S39 -> 118156.36 | ... AF40: =AF$28*'PEV Sales by Manufacturer'!$S39 -> 284914.47
A41: Hyundai | B41: ='PEV Sales by Manufacturer'!M40 -> 4556 | C41: ='PEV Sales by Manufacturer'!N40 -> 10855 | D41: =D$28*'PEV Sales by Manufacturer'!$S40 -> 25963.392 | E41: =E$28*'PEV Sales by Manufacturer'!$S40 -> 37817.169 | F41: =F$28*'PEV Sales by Manufacturer'!$S40 -> 52202.503 | G41: =G$28*'PEV Sales by Manufacturer'!$S40 -> 66383.705 | H41: =H$28*'PEV Sales by Manufacturer'!$S40 -> 78284.026 | I41: =I$28*'PEV Sales by Manufacturer'!$S40 -> 90697.274 | J41: =J$28*'PEV Sales by Manufacturer'!$S40 -> 103665.98 | K41: =K$28*'PEV Sales by Manufacturer'!$S40 -> 115798.78 | ... AF41: =AF$28*'PEV Sales by Manufacturer'!$S40 -> 279229.56
A42: Kia | B42: ='PEV Sales by Manufacturer'!M41 -> 2848 | C42: ='PEV Sales by Manufacturer'!N41 -> 8717 | D42: =D$28*'PEV Sales by Manufacturer'!$S41 -> 20849.644 | E42: =E$28*'PEV Sales by Manufacturer'!$S41 -> 30368.702 | F42: =F$28*'PEV Sales by Manufacturer'!$S41 -> 41920.702 | G42: =G$28*'PEV Sales by Manufacturer'!$S41 -> 53308.775 | H42: =H$28*'PEV Sales by Manufacturer'!$S41 -> 62865.21 | I42: =I$28*'PEV Sales by Manufacturer'!$S41 -> 72833.545 | J42: =J$28*'PEV Sales by Manufacturer'!$S41 -> 83247.932 | K42: =K$28*'PEV Sales by Manufacturer'!$S41 -> 92991.06 | ... AF42: =AF$28*'PEV Sales by Manufacturer'!$S41 -> 224232.52
A43: Volvo | B43: ='PEV Sales by Manufacturer'!M42 -> 135 | C43: ='PEV Sales by Manufacturer'!N42 -> 9863 | D43: =D$28*'PEV Sales by Manufacturer'!$S42 -> 23590.69 | E43: =E$28*'PEV Sales by Manufacturer'!$S42 -> 34361.192 | F43: =F$28*'PEV Sales by Manufacturer'!$S42 -> 47431.901 | G43: =G$28*'PEV Sales by Manufacturer'!$S42 -> 60317.133 | H43: =H$28*'PEV Sales by Manufacturer'!$S42 -> 71129.926 | I43: =I$28*'PEV Sales by Manufacturer'!$S42 -> 82408.771 | J43: =J$28*'PEV Sales by Manufacturer'!$S42 -> 94192.309 | K43: =K$28*'PEV Sales by Manufacturer'!$S42 -> 105216.34 | ... AF43: =AF$28*'PEV Sales by Manufacturer'!$S42 -> 253711.76
... A53: Mazda | B53: ='PEV Sales by Manufacturer'!M52 -> 0 | C53: ='PEV Sales by Manufacturer'!N52 -> 116 | D53: =D$28*'PEV Sales by Manufacturer'!$S52 -> 277.45311 | E53: =E$28*'PEV Sales by Manufacturer'!$S52 -> 404.12636 | F53: =F$28*'PEV Sales by Manufacturer'!$S52 -> 557.85263 | G53: =G$28*'PEV Sales by Manufacturer'!$S52 -> 709.39749 | H53: =H$28*'PEV Sales by Manufacturer'!$S52 -> 836.56813 | I53: =I$28*'PEV Sales by Manufacturer'!$S52 -> 969.22006 | J53: =J$28*'PEV Sales by Manufacturer'!$S52 -> 1107.8078 | K53: =K$28*'PEV Sales by Manufacturer'!$S52 -> 1237.4628 | ... AF53: =AF$28*'PEV Sales by Manufacturer'!$S52 -> 2983.9363
A55: Projected Annual PHEV Sales by Manufacturer | B55: 2020 | C55: 2021 | D55: 2022 | E55: 2023 | F55: 2024 | G55: 2025 | H55: 2026 | I55: 2027 | J55: 2028 | K55: 2029 | L55: 2030 | M55: 2031 | N55: 2032 | O55: 2033 | P55: 2034 | Q55: 2035 | R55: 2036 | S55: 2037 | T55: 2038 | U55: 2039 | V55: 2040 | W55: 2041 | X55: 2042 | Y55: 2043 | Z55: 2044 | AA55: 2045 | AB55: 2046 | AC55: 2047 | AD55: 2048 | AE55: 2049 | AF55: 2050
A56: Tesla | B56: ='PEV Sales by Manufacturer'!M58 -> 0 | C56: ='PEV Sales by Manufacturer'!N58 -> 0 | D56: =D$29*'PEV Sales by Manufacturer'!$S58 -> 0 | E56: =E$29*'PEV Sales by Manufacturer'!$S58 -> 0 | F56: =F$29*'PEV Sales by Manufacturer'!$S58 -> 0 | G56: =G$29*'PEV Sales by Manufacturer'!$S58 -> 0 | H56: =H$29*'PEV Sales by Manufacturer'!$S58 -> 0 | I56: =I$29*'PEV Sales by Manufacturer'!$S58 -> 0 | J56: =J$29*'PEV Sales by Manufacturer'!$S58 -> 0 | K56: =K$29*'PEV Sales by Manufacturer'!$S58 -> 0 | ... AF56: =AF$29*'PEV Sales by Manufacturer'!$S58 -> 0
A57: GM (Cadillac and Chevrolet) | B57: ='PEV Sales by Manufacturer'!M59 -> 81 | C57: ='PEV Sales by Manufacturer'!N59 -> 16 | D57: =D$29*'PEV Sales by Manufacturer'!$S59 -> 39.890349 | E57: =E$29*'PEV Sales by Manufacturer'!$S59 -> 58.533915 | F57: =F$29*'PEV Sales by Manufacturer'!$S59 -> 81.541544 | G57: =G$29*'PEV Sales by Manufacturer'!$S59 -> 100.6489 | H57: =H$29*'PEV Sales by Manufacturer'!$S59 -> 112.22886 | I57: =I$29*'PEV Sales by Manufacturer'!$S59 -> 118.89062 | J57: =J$29*'PEV Sales by Manufacturer'!$S59 -> 120.43658 | K57: =K$29*'PEV Sales by Manufacturer'!$S59 -> 121.3364 | ... AF57: =AF$29*'PEV Sales by Manufacturer'!$S59 -> 97.095588
A58: Nissan | B58: ='PEV Sales by Manufacturer'!M60 -> 0 | C58: ='PEV Sales by Manufacturer'!N60 -> 0 | D58: =D$29*'PEV Sales by Manufacturer'!$S60 -> 0 | E58: =E$29*'PEV Sales by Manufacturer'!$S60 -> 0 | F58: =F$29*'PEV Sales by Manufacturer'!$S60 -> 0 | G58: =G$29*'PEV Sales by Manufacturer'!$S60 -> 0 | H58: =H$29*'PEV Sales by Manufacturer'!$S60 -> 0 | I58: =I$29*'PEV Sales by Manufacturer'!$S60 -> 0 | J58: =J$29*'PEV Sales by Manufacturer'!$S60 -> 0 | K58: =K$29*'PEV Sales by Manufacturer'!$S60 -> 0 | ... AF58: =AF$29*'PEV Sales by Manufacturer'!$S60 -> 0
A59: Toyota | B59: ='PEV Sales by Manufacturer'!M61 -> 17898 | C59: ='PEV Sales by Manufacturer'!N61 -> 52767 | D59: =D$29*'PEV Sales by Manufacturer'!$S61 -> 131555.88 | E59: =E$29*'PEV Sales by Manufacturer'!$S61 -> 193041.19 | F59: =F$29*'PEV Sales by Manufacturer'!$S61 -> 268918.92 | G59: =G$29*'PEV Sales by Manufacturer'!$S61 -> 331933.77 | H59: =H$29*'PEV Sales by Manufacturer'!$S61 -> 370123.77 | I59: =I$29*'PEV Sales by Manufacturer'!$S61 -> 392093.85 | J59: =J$29*'PEV Sales by Manufacturer'!$S61 -> 397192.32 | K59: =K$29*'PEV Sales by Manufacturer'!$S61 -> 400159.85 | ... AF59: =AF$29*'PEV Sales by Manufacturer'!$S61 -> 320215.18
A60: Ford | B60: ='PEV Sales by Manufacturer'!M62 -> 5565 | C60: ='PEV Sales by Manufacturer'!N62 -> 6013 | D60: =D$29*'PEV Sales by Manufacturer'!$S62 -> 14991.292 | E60: =E$29*'PEV Sales by Manufacturer'!$S62 -> 21997.777 | F60: =F$29*'PEV Sales by Manufacturer'!$S62 -> 30644.332 | G60: =G$29*'PEV Sales by Manufacturer'!$S62 -> 37825.114 | H60: =H$29*'PEV Sales by Manufacturer'!$S62 -> 42177.009 | I60: =I$29*'PEV Sales by Manufacturer'!$S62 -> 44680.583 | J60: =J$29*'PEV Sales by Manufacturer'!$S62 -> 45261.573 | K60: =K$29*'PEV Sales by Manufacturer'!$S62 -> 45599.735 | ... AF60: =AF$29*'PEV Sales by Manufacturer'!$S62 -> 36489.736
A61: BMW N. America | B61: ='PEV Sales by Manufacturer'!M63 -> 7999 | C61: ='PEV Sales by Manufacturer'!N63 -> 19579 | D61: =D$29*'PEV Sales by Manufacturer'!$S63 -> 48813.322 | E61: =E$29*'PEV Sales by Manufacturer'!$S63 -> 71627.221 | F61: =F$29*'PEV Sales by Manufacturer'!$S63 -> 99781.368 | G61: =G$29*'PEV Sales by Manufacturer'!$S63 -> 123162.8 | H61: =H$29*'PEV Sales by Manufacturer'!$S63 -> 137333.05 | I61: =I$29*'PEV Sales by Manufacturer'!$S63 -> 145484.97 | J61: =J$29*'PEV Sales by Manufacturer'!$S63 -> 147376.74 | K61: =K$29*'PEV Sales by Manufacturer'!$S63 -> 148477.83 | ... AF61: =AF$29*'PEV Sales by Manufacturer'!$S63 -> 118814.66
...

Sheet Baseline Calculations - HK
D1: Projected Cumulative Sales
B2: 2020 | C2: 2021 | D2: 2022 | E2: 2023 | F2: 2024 | G2: 2025 | H2: 2026 | I2: 2027 | J2: 2028 | K2: 2029 | L2: 2030 | M2: 2031 | N2: 2032 | O2: 2033 | P2: 2034 | Q2: 2035 | R2: 2036 | S2: 2037 | T2: 2038 | U2: 2039 | V2: 2040 | W2: 2041 | X2: 2042 | Y2: 2043 | Z2: 2044 | AA2: 2045 | AB2: 2046 | AC2: 2047 | AD2: 2048 | AE2: 2049 | AF2: 2050
A3: Tesla | B3: =SUM('PEV Sales by Manufacturer'!D4:M4) -> 687269 | C3: =SUM('PEV Sales by Manufacturer'!D4:N4) -> 1008187 | D3: =C3+D32+D56 -> 1775770.6 | E3: =D3+E32+E56 -> 2893800.1 | F3: =E3+F32+F56 -> 4437118.6 | G3: =F3+G32+G56 -> 6399691.3 | H3: =G3+H32+H56 -> 8714085.8 | I3: =H3+I32+I56 -> 11395467 | J3: =I3+J32+J56 -> 14460255 | K3: =J3+K32+K56 -> 17883738 | ... AF3: =AE3+AF32+AF56 -> 1.4609994e+08
A4: GM (Cadillac and Chevrolet) | B4: =SUM('PEV Sales by Manufacturer'!D5:M5) -> 246675 | C4: =SUM('PEV Sales by Manufacturer'!D5:N5) -> 271520 | D4: =C4+D33+D57 -> 330946.81 | E4: =D4+E33+E57 -> 417505.81 | F4: =E4+F33+F57 -> 536991.86 | G4: =F4+G33+G57 -> 688934.15 | H4: =G4+H33+H57 -> 868108.02 | I4: =H4+I33+I57 -> 1075681.8 | J4: =I4+J33+J57 -> 1312920.8 | K4: =J4+K33+K57 -> 1577912.5 | ... AF4: =AE4+AF33+AF57 -> 11500099
A5: Nissan | B5: =SUM('PEV Sales by Manufacturer'!D6:M6) -> 151452 | C5: =SUM('PEV Sales by Manufacturer'!D6:N6) -> 165691 | D5: =C5+D34+D58 -> 199748.37 | E5: =D5+E34+E58 -> 249354.88 | F5: =E5+F34+F58 -> 317831.29 | G5: =F5+G34+G58 -> 404909.83 | H5: =G5+H34+H58 -> 507598.57 | I5: =H5+I34+I58 -> 626570.33 | J5: =I5+J34+J58 -> 762553.73 | K5: =J5+K34+K58 -> 914452.29 | ... AF5: =AE5+AF34+AF58 -> 6603352.5
A6: Toyota | B6: =SUM('PEV Sales by Manufacturer'!D7:M7) -> 135451 | C6: =SUM('PEV Sales by Manufacturer'!D7:N7) -> 188218 | D6: =C6+D35+D59 -> 319773.88 | E6: =D6+E35+E59 -> 512815.07 | F6: =E6+F35+F59 -> 781733.99 | G6: =F6+G35+G59 -> 1113667.8 | H6: =G6+H35+H59 -> 1483791.5 | I6: =H6+I35+I59 -> 1875885.4 | J6: =I6+J35+J59 -> 2273077.7 | K6: =J6+K35+K59 -> 2673237.5 | ... AF6: =AE6+AF35+AF59 -> 10157425
A7: Ford | B7: =SUM('PEV Sales by Manufacturer'!D8:M8) -> 126312 | C7: =SUM('PEV Sales by Manufacturer'!D8:N8) -> 159546 | D7: =C7+D36+D60 -> 239645.49 | E7: =D7+E36+E60 -> 356477.09 | F7: =E7+F36+F60 -> 518029.24 | G7: =F7+G36+G60 -> 722324.26 | H7: =G7+H36+H60 -> 960813.52 | I7: =H7+I36+I60 -> 1232935 | J7: =I7+J36+J60 -> 1538158.9 | K7: =J7+K36+K60 -> 1874146.3 | ... AF7: =AE7+AF36+AF60 -> 13602590
A8: BMW N. America | B8: =SUM('PEV Sales by Manufacturer'!D9:M9) -> 109611 | C8: =SUM('PEV Sales by Manufacturer'!D9:N9) -> 132675 | D8: =C8+D37+D61 -> 189823.87 | E8: =D8+E37+E61 -> 273592.3 | F8: =E8+F37+F61 -> 390133.3 | G8: =F8+G37+G61 -> 534608.6 | H8: =G8+H37+H61 -> 697074.75 | I8: =H8+I37+I61 -> 871678.1 | J8: =I8+J37+J61 -> 1052336.8 | K8: =J8+K37+K61 -> 1237991.9 | ... AF8: =AE8+AF37+AF61 -> 5407332.1
A9: FCA (Chrysler and Fiat) | B9: =SUM('PEV Sales by Manufacturer'!D10:M10) -> 37707 | C9: =SUM('PEV Sales by Manufacturer'!D10:N10) -> 86430 | D9: =C9+D38+D62 -> 207903.59 | E9: =D9+E38+E62 -> 386150.34 | F9: =E9+F38+F62 -> 634459.63 | G9: =F9+G38+G62 -> 940954.39 | H9: =G9+H38+H62 -> 1282712.3 | I9: =H9+I38+I62 -> 1644756.6 | J9: =I9+J38+J62 -> 2011508.5 | K9: =J9+K38+K62 -> 2381000.6 | ... AF9: =AE9+AF38+AF62 -> 9291608.6
A10: Honda | B10: =SUM('PEV Sales by Manufacturer'!D11:M11) -> 39002 | C10: =SUM('PEV Sales by Manufacturer'!D11:N11) -> 41317 | D10: =C10+D39+D63 -> 47088.534 | E10: =D10+E39+E63 -> 55557.485 | F10: =E10+F39+F63 -> 67355.24 | G10: =F10+G39+G63 -> 81917.702 | H10: =G10+H39+H63 -> 98156.013 | I10: =H10+I39+I63 -> 115358.92 | J10: =I10+J39+J63 -> 132786.62 | K10: =J10+K39+K63 -> 150345.56 | ... AF10: =AE10+AF39+AF63 -> 478950.39
A11: Audi | B11: =SUM('PEV Sales by Manufacturer'!D12:M12) -> 26628 | C11: =SUM('PEV Sales by Manufacturer'!D12:N12) -> 46647 | D11: =C11+D40+D64 -> 95435.2 | E11: =D11+E40+E64 -> 166739.1 | F11: =E11+F40+F64 -> 265581.04 | G11: =F11+G40+G64 -> 389572.71 | H11: =G11+H40+H64 -> 532179.46 | I11: =H11+I40+I64 -> 691175.69 | J11: =I11+J40+J64 -> 864268.75 | K11: =J11+K40+K64 -> 1050244.6 | ... AF11: =AE11+AF40+AF64 -> 6743860
A12: Hyundai | B12: =SUM('PEV Sales by Manufacturer'!D13:M13) -> 25223 | C12: =SUM('PEV Sales by Manufacturer'!D13:N13) -> 42236 | D12: =C12+D41+D65 -> 83552.19 | E12: =D12+E41+E65 -> 143897.6 | F12: =E12+F41+F65 -> 227483.4 | G12: =F12+G41+G65 -> 332604.35 | H12: =G12+H41+H65 -> 454082.46 | I12: =H12+I41+I65 -> 590537.77 | J12: =I12+J41+J65 -> 740556.77 | K12: =J12+K41+K65 -> 903054.89 | ... AF12: =AE12+AF41+AF65 -> 6113364.9
A13: Kia | B13: =SUM('PEV Sales by Manufacturer'!D14:M14) -> 24512 | C13: =SUM('PEV Sales by Manufacturer'!D14:N14) -> 39129 | D13: =C13+D42+D66 -> 74688.211 | E13: =D13+E42+E66 -> 126641.29 | F13: =E13+F42+F66 -> 198630.44 | G13: =F13+G42+G66 -> 289053.5 | H13: =G13+H42+H66 -> 393303.1 | I13: =H13+I42+I66 -> 509977.56 | J13: =I13+J42+J66 -> 637636.48 | K13: =J13+K42+K66 -> 775370.34 | ... AF13: =AE13+AF42+AF66 -> 5094893
A14: Volvo | B14: =SUM('PEV Sales by Manufacturer'!D15:M15) -> 19669 | C14: =SUM('PEV Sales by Manufacturer'!D15:N15) -> 45138 | D14: =C14+D43+D67 -> 107636.74 | E14: =D14+E43+E67 -> 199090.45 | F14: =E14+F43+F67 -> 326055.93 | G14: =F14+G43+G67 -> 484543.48 | H14: =G14+H43+H67 -> 665138.64 | I14: =H14+I43+I67 -> 863510.35 | J14: =I14+J43+J67 -> 1075173.5 | K14: =J14+K43+K67 -> 1298738.3 | ... AF14: =AE14+AF43+AF67 -> 7452768.6
... A24: Mazda | B24: =SUM('PEV Sales by Manufacturer'!D25:M25) -> 0 | C24: =SUM('PEV Sales by Manufacturer'!D25:N25) -> 116 | D24: =C24+D53+D77 -> 393.45311 | E24: =D24+E53+E77 -> 797.57947 | F24: =E24+F53+F77 -> 1355.4321 | G24: =F24+G53+G77 -> 2064.8296 | H24: =G24+H53+H77 -> 2901.3977 | I24: =H24+I53+I77 -> 3870.6178 | J24: =I24+J53+J77 -> 4978.4255 | K24: =J24+K53+K77 -> 6215.8883 | ... AF24: =AE24+AF53+AF77 -> 52561.308
A26: BAU Projected Sales in EPS
A27: Time (Year) | B27: 2020 | C27: 2021 | D27: 2022 | E27: 2023 | F27: 2024 | G27: 2025 | H27: 2026 | I27: 2027 | J27: 2028 | K27: 2029 | L27: 2030 | M27: 2031 | N27: 2032 | O27: 2033 | P27: 2034 | Q27: 2035 | R27: 2036 | S27: 2037 | T27: 2038 | U27: 2039 | V27: 2040 | W27: 2041 | X27: 2042 | Y27: 2043 | Z27: 2044 | AA27: 2045 | AB27: 2046 | AC27: 2047 | AD27: 2048 | AE27: 2049 | AF27: 2050
A28: New Vehicles[LDVs,passenger,battery electric vehicle] : MostRecentRun | B28: 349182 | C28: 603744 | D28: 1098920 | E28: 1600640 | F28: 2209510 | G28: 2809740 | H28: 3313430 | I28: 3838830 | J28: 4387740 | K28: 4901270 | L28: 5460140 | M28: 5896040 | N28: 6271520 | O28: 6625100 | P28: 6942390 | Q28: 7274900 | R28: 7567320 | S28: 7866920 | T28: 8176700 | U28: 8461000 | V28: 8757100 | W28: 9060000 | X28: 9346980 | Y28: 9657430 | Z28: 9970180 | AA28: 10265600 | AB28: 10577800 | AC28: 10885700 | AD28: 11185100 | AE28: 11495700 | AF28: 11818600
A29: New Vehicles[LDVs,passenger,plugin hybrid vehicle] : MostRecentRun | B29: 86889 | C29: 248313 | D29: 434007 | E29: 636849 | F29: 887172 | G29: 1095060 | H29: 1221050 | I29: 1293530 | J29: 1310350 | K29: 1320140 | L29: 1310940 | M29: 1306520 | N29: 1289590 | O29: 1270880 | P29: 1252620 | Q29: 1235240 | R29: 1219780 | S29: 1204400 | T29: 1191940 | U29: 1177850 | V29: 1166230 | W29: 1155260 | X29: 1143250 | Y29: 1133420 | Z29: 1123340 | AA29: 1112470 | AB29: 1102060 | AC29: 1091130 | AD29: 1079340 | AE29: 1067910 | AF29: 1056400
A31: Projected Annual BEV Sales by Manufacturer | B31: 2020 | C31: 2021 | D31: 2022 | E31: 2023 | F31: 2024 | G31: 2025 | H31: 2026 | I31: 2027 | J31: 2028 | K31: 2029 | L31: 2030 | M31: 2031 | N31: 2032 | O31: 2033 | P31: 2034 | Q31: 2035 | R31: 2036 | S31: 2037 | T31: 2038 | U31: 2039 | V31: 2040 | W31: 2041 | X31: 2042 | Y31: 2043 | Z31: 2044 | AA31: 2045 | AB31: 2046 | AC31: 2047 | AD31: 2048 | AE31: 2049 | AF31: 2050
A32: Tesla | B32: ='PEV Sales by Manufacturer'!M31 -> 183829 | C32: ='PEV Sales by Manufacturer'!N31 -> 320918 | D32: =D$28*'PEV Sales by Manufacturer'!$S31 -> 767583.59 | E32: =E$28*'PEV Sales by Manufacturer'!$S31 -> 1118029.5 | F32: =F$28*'PEV Sales by Manufacturer'!$S31 -> 1543318.5 | G32: =G$28*'PEV Sales by Manufacturer'!$S31 -> 1962572.6 | H32: =H$28*'PEV Sales by Manufacturer'!$S31 -> 2314394.6 | I32: =I$28*'PEV Sales by Manufacturer'!$S31 -> 2681380.7 | J32: =J$28*'PEV Sales by Manufacturer'!$S31 -> 3064788.3 | K32: =K$28*'PEV Sales by Manufacturer'!$S31 -> 3423483.4 | ... AF32: =AF$28*'PEV Sales by Manufacturer'!$S31 -> 8255162.7
A33: GM (Cadillac and Chevrolet) | B33: ='PEV Sales by Manufacturer'!M32 -> 20754 | C33: ='PEV Sales by Manufacturer'!N32 -> 24829 | D33: =D$28*'PEV Sales by Manufacturer'!$S32 -> 59386.924 | E33: =E$28*'PEV Sales by Manufacturer'!$S32 -> 86500.46 | F33: =F$28*'PEV Sales by Manufacturer'!$S32 -> 119404.51 | G33: =G$28*'PEV Sales by Manufacturer'!$S32 -> 151841.64 | H33: =H$28*'PEV Sales by Manufacturer'!$S32 -> 179061.64 | I33: =I$28*'PEV Sales by Manufacturer'!$S32 -> 207454.87 | J33: =J$28*'PEV Sales by Manufacturer'!$S32 -> 237118.61 | K33: =K$28*'PEV Sales by Manufacturer'!$S32 -> 264870.37 | ... AF33: =AF$28*'PEV Sales by Manufacturer'!$S32 -> 638690.99
A34: Nissan | B34: ='PEV Sales by Manufacturer'!M33 -> 9564 | C34: ='PEV Sales by Manufacturer'!N33 -> 14239 | D34: =D$28*'PEV Sales by Manufacturer'!$S33 -> 34057.369 | E34: =E$28*'PEV Sales by Manufacturer'!$S33 -> 49606.511 | F34: =F$28*'PEV Sales by Manufacturer'!$S33 -> 68476.41 | G34: =G$28*'PEV Sales by Manufacturer'!$S33 -> 87078.542 | H34: =H$28*'PEV Sales by Manufacturer'!$S33 -> 102688.74 | I34: =I$28*'PEV Sales by Manufacturer'!$S33 -> 118971.76 | J34: =J$28*'PEV Sales by Manufacturer'!$S33 -> 135983.4 | K34: =K$28*'PEV Sales by Manufacturer'!$S33 -> 151898.56 | ... AF34: =AF$28*'PEV Sales by Manufacturer'!$S33 -> 366278.18
A35: Toyota | B35: ='PEV Sales by Manufacturer'!M34 -> 0 | C35: ='PEV Sales by Manufacturer'!N34 -> 0 | D35: =D$28*'PEV Sales by Manufacturer'!$S34 -> 0 | E35: =E$28*'PEV Sales by Manufacturer'!$S34 -> 0 | F35: =F$28*'PEV Sales by Manufacturer'!$S34 -> 0 | G35: =G$28*'PEV Sales by Manufacturer'!$S34 -> 0 | H35: =H$28*'PEV Sales by Manufacturer'!$S34 -> 0 | I35: =I$28*'PEV Sales by Manufacturer'!$S34 -> 0 | J35: =J$28*'PEV Sales by Manufacturer'!$S34 -> 0 | K35: =K$28*'PEV Sales by Manufacturer'!$S34 -> 0 | ... AF35: =AF$28*'PEV Sales by Manufacturer'!$S34 -> 0
A36: Ford | B36: ='PEV Sales by Manufacturer'!M35 -> 3 | C36: ='PEV Sales by Manufacturer'!N35 -> 27221 | D36: =D$28*'PEV Sales by Manufacturer'!$S35 -> 65108.198 | E36: =E$28*'PEV Sales by Manufacturer'!$S35 -> 94833.825 | F36: =F$28*'PEV Sales by Manufacturer'!$S35 -> 130907.81 | G36: =G$28*'PEV Sales by Manufacturer'!$S35 -> 166469.91 | H36: =H$28*'PEV Sales by Manufacturer'!$S35 -> 196312.25 | I36: =I$28*'PEV Sales by Manufacturer'!$S35 -> 227440.86 | J36: =J$28*'PEV Sales by Manufacturer'!$S35 -> 259962.37 | K36: =K$28*'PEV Sales by Manufacturer'!$S35 -> 290387.71 | ... AF36: =AF$28*'PEV Sales by Manufacturer'!$S35 -> 700221.81
A37: BMW N. America | B37: ='PEV Sales by Manufacturer'!M36 -> 2640 | C37: ='PEV Sales by Manufacturer'!N36 -> 3485 | D37: =D$28*'PEV Sales by Manufacturer'!$S36 -> 8335.5524 | E37: =E$28*'PEV Sales by Manufacturer'!$S36 -> 12141.21 | F37: =F$28*'PEV Sales by Manufacturer'!$S36 -> 16759.624 | G37: =G$28*'PEV Sales by Manufacturer'!$S36 -> 21312.502 | H37: =H$28*'PEV Sales by Manufacturer'!$S36 -> 25133.103 | I37: =I$28*'PEV Sales by Manufacturer'!$S36 -> 29118.379 | J37: =J$28*'PEV Sales by Manufacturer'!$S36 -> 33281.983 | K37: =K$28*'PEV Sales by Manufacturer'!$S36 -> 37177.222 | ... AF37: =AF$28*'PEV Sales by Manufacturer'!$S36 -> 89646.707
A38: FCA (Chrysler and Fiat) | B38: ='PEV Sales by Manufacturer'!M37 -> 70 | C38: ='PEV Sales by Manufacturer'!N37 -> 0 | D38: =D$28*'PEV Sales by Manufacturer'!$S37 -> 0 | E38: =E$28*'PEV Sales by Manufacturer'!$S37 -> 0 | F38: =F$28*'PEV Sales by Manufacturer'!$S37 -> 0 | G38: =G$28*'PEV Sales by Manufacturer'!$S37 -> 0 | H38: =H$28*'PEV Sales by Manufacturer'!$S37 -> 0 | I38: =I$28*'PEV Sales by Manufacturer'!$S37 -> 0 | J38: =J$28*'PEV Sales by Manufacturer'!$S37 -> 0 | K38: =K$28*'PEV Sales by Manufacturer'!$S37 -> 0 | ... AF38: =AF$28*'PEV Sales by Manufacturer'!$S37 -> 0
A39: Honda | B39: ='PEV Sales by Manufacturer'!M38 -> 45 | C39: ='PEV Sales by Manufacturer'!N38 -> 1 | D39: =D$28*'PEV Sales by Manufacturer'!$S38 -> 2.3918371 | E39: =E$28*'PEV Sales by Manufacturer'!$S38 -> 3.4838479 | F39: =F$28*'PEV Sales by Manufacturer'!$S38 -> 4.8090744 | G39: =G$28*'PEV Sales by Manufacturer'!$S38 -> 6.1154956 | H39: =H$28*'PEV Sales by Manufacturer'!$S38 -> 7.2117942 | I39: =I$28*'PEV Sales by Manufacturer'!$S38 -> 8.3553454 | J39: =J$28*'PEV Sales by Manufacturer'!$S38 -> 9.5500668 | K39: =K$28*'PEV Sales by Manufacturer'!$S38 -> 10.667783 | ... AF39: =AF$28*'PEV Sales by Manufacturer'!$S38 -> 25.723589
A40: Audi | B40: ='PEV Sales by Manufacturer'!M39 -> 7202 | C40: ='PEV Sales by Manufacturer'!N39 -> 11076 | D40: =D$28*'PEV Sales by Manufacturer'!$S39 -> 26491.988 | E40: =E$28*'PEV Sales by Manufacturer'!$S39 -> 38587.1 | F40: =F$28*'PEV Sales by Manufacturer'!$S39 -> 53265.308 | G40: =G$28*'PEV Sales by Manufacturer'!$S39 -> 67735.229 | H40: =H$28*'PEV Sales by Manufacturer'!$S39 -> 79877.833 | I40: =I$28*'PEV Sales by Manufacturer'!$S39 -> 92543.805 | J40: =J$28*'PEV Sales by Manufacturer'!$S39 -> 105776.54 | K40: =K$28*'PEV Sales by Manufacturer'!$S39 -> 118156.36 | ... AF40: =AF$28*'PEV Sales by Manufacturer'!$S39 -> 284914.47
A41: Hyundai | B41: ='PEV Sales by Manufacturer'!M40 -> 4556 | C41: ='PEV Sales by Manufacturer'!N40 -> 10855 | D41: =D$28*'PEV Sales by Manufacturer'!$S40 -> 25963.392 | E41: =E$28*'PEV Sales by Manufacturer'!$S40 -> 37817.169 | F41: =F$28*'PEV Sales by Manufacturer'!$S40 -> 52202.503 | G41: =G$28*'PEV Sales by Manufacturer'!$S40 -> 66383.705 | H41: =H$28*'PEV Sales by Manufacturer'!$S40 -> 78284.026 | I41: =I$28*'PEV Sales by Manufacturer'!$S40 -> 90697.274 | J41: =J$28*'PEV Sales by Manufacturer'!$S40 -> 103665.98 | K41: =K$28*'PEV Sales by Manufacturer'!$S40 -> 115798.78 | ... AF41: =AF$28*'PEV Sales by Manufacturer'!$S40 -> 279229.56
A42: Kia | B42: ='PEV Sales by Manufacturer'!M41 -> 2848 | C42: ='PEV Sales by Manufacturer'!N41 -> 8717 | D42: =D$28*'PEV Sales by Manufacturer'!$S41 -> 20849.644 | E42: =E$28*'PEV Sales by Manufacturer'!$S41 -> 30368.702 | F42: =F$28*'PEV Sales by Manufacturer'!$S41 -> 41920.702 | G42: =G$28*'PEV Sales by Manufacturer'!$S41 -> 53308.775 | H42: =H$28*'PEV Sales by Manufacturer'!$S41 -> 62865.21 | I42: =I$28*'PEV Sales by Manufacturer'!$S41 -> 72833.545 | J42: =J$28*'PEV Sales by Manufacturer'!$S41 -> 83247.932 | K42: =K$28*'PEV Sales by Manufacturer'!$S41 -> 92991.06 | ... AF42: =AF$28*'PEV Sales by Manufacturer'!$S41 -> 224232.52
A43: Volvo | B43: ='PEV Sales by Manufacturer'!M42 -> 135 | C43: ='PEV Sales by Manufacturer'!N42 -> 9863 | D43: =D$28*'PEV Sales by Manufacturer'!$S42 -> 23590.69 | E43: =E$28*'PEV Sales by Manufacturer'!$S42 -> 34361.192 | F43: =F$28*'PEV Sales by Manufacturer'!$S42 -> 47431.901 | G43: =G$28*'PEV Sales by Manufacturer'!$S42 -> 60317.133 | H43: =H$28*'PEV Sales by Manufacturer'!$S42 -> 71129.926 | I43: =I$28*'PEV Sales by Manufacturer'!$S42 -> 82408.771 | J43: =J$28*'PEV Sales by Manufacturer'!$S42 -> 94192.309 | K43: =K$28*'PEV Sales by Manufacturer'!$S42 -> 105216.34 | ... AF43: =AF$28*'PEV Sales by Manufacturer'!$S42 -> 253711.76
... A53: Mazda | B53: ='PEV Sales by Manufacturer'!M52 -> 0 | C53: ='PEV Sales by Manufacturer'!N52 -> 116 | D53: =D$28*'PEV Sales by Manufacturer'!$S52 -> 277.45311 | E53: =E$28*'PEV Sales by Manufacturer'!$S52 -> 404.12636 | F53: =F$28*'PEV Sales by Manufacturer'!$S52 -> 557.85263 | G53: =G$28*'PEV Sales by Manufacturer'!$S52 -> 709.39749 | H53: =H$28*'PEV Sales by Manufacturer'!$S52 -> 836.56813 | I53: =I$28*'PEV Sales by Manufacturer'!$S52 -> 969.22006 | J53: =J$28*'PEV Sales by Manufacturer'!$S52 -> 1107.8078 | K53: =K$28*'PEV Sales by Manufacturer'!$S52 -> 1237.4628 | ... AF53: =AF$28*'PEV Sales by Manufacturer'!$S52 -> 2983.9363
A55: Projected Annual PHEV Sales by Manufacturer | B55: 2020 | C55: 2021 | D55: 2022 | E55: 2023 | F55: 2024 | G55: 2025 | H55: 2026 | I55: 2027 | J55: 2028 | K55: 2029 | L55: 2030 | M55: 2031 | N55: 2032 | O55: 2033 | P55: 2034 | Q55: 2035 | R55: 2036 | S55: 2037 | T55: 2038 | U55: 2039 | V55: 2040 | W55: 2041 | X55: 2042 | Y55: 2043 | Z55: 2044 | AA55: 2045 | AB55: 2046 | AC55: 2047 | AD55: 2048 | AE55: 2049 | AF55: 2050
A56: Tesla | B56: ='PEV Sales by Manufacturer'!M58 -> 0 | C56: ='PEV Sales by Manufacturer'!N58 -> 0 | D56: =D$29*'PEV Sales by Manufacturer'!$S58 -> 0 | E56: =E$29*'PEV Sales by Manufacturer'!$S58 -> 0 | F56: =F$29*'PEV Sales by Manufacturer'!$S58 -> 0 | G56: =G$29*'PEV Sales by Manufacturer'!$S58 -> 0 | H56: =H$29*'PEV Sales by Manufacturer'!$S58 -> 0 | I56: =I$29*'PEV Sales by Manufacturer'!$S58 -> 0 | J56: =J$29*'PEV Sales by Manufacturer'!$S58 -> 0 | K56: =K$29*'PEV Sales by Manufacturer'!$S58 -> 0 | ... AF56: =AF$29*'PEV Sales by Manufacturer'!$S58 -> 0
A57: GM (Cadillac and Chevrolet) | B57: ='PEV Sales by Manufacturer'!M59 -> 81 | C57: ='PEV Sales by Manufacturer'!N59 -> 16 | D57: =D$29*'PEV Sales by Manufacturer'!$S59 -> 39.890349 | E57: =E$29*'PEV Sales by Manufacturer'!$S59 -> 58.533915 | F57: =F$29*'PEV Sales by Manufacturer'!$S59 -> 81.541544 | G57: =G$29*'PEV Sales by Manufacturer'!$S59 -> 100.6489 | H57: =H$29*'PEV Sales by Manufacturer'!$S59 -> 112.22886 | I57: =I$29*'PEV Sales by Manufacturer'!$S59 -> 118.89062 | J57: =J$29*'PEV Sales by Manufacturer'!$S59 -> 120.43658 | K57: =K$29*'PEV Sales by Manufacturer'!$S59 -> 121.3364 | ... AF57: =AF$29*'PEV Sales by Manufacturer'!$S59 -> 97.095588
A58: Nissan | B58: ='PEV Sales by Manufacturer'!M60 -> 0 | C58: ='PEV Sales by Manufacturer'!N60 -> 0 | D58: =D$29*'PEV Sales by Manufacturer'!$S60 -> 0 | E58: =E$29*'PEV Sales by Manufacturer'!$S60 -> 0 | F58: =F$29*'PEV Sales by Manufacturer'!$S60 -> 0 | G58: =G$29*'PEV Sales by Manufacturer'!$S60 -> 0 | H58: =H$29*'PEV Sales by Manufacturer'!$S60 -> 0 | I58: =I$29*'PEV Sales by Manufacturer'!$S60 -> 0 | J58: =J$29*'PEV Sales by Manufacturer'!$S60 -> 0 | K58: =K$29*'PEV Sales by Manufacturer'!$S60 -> 0 | ... AF58: =AF$29*'PEV Sales by Manufacturer'!$S60 -> 0
A59: Toyota | B59: ='PEV Sales by Manufacturer'!M61 -> 17898 | C59: ='PEV Sales by Manufacturer'!N61 -> 52767 | D59: =D$29*'PEV Sales by Manufacturer'!$S61 -> 131555.88 | E59: =E$29*'PEV Sales by Manufacturer'!$S61 -> 193041.19 | F59: =F$29*'PEV Sales by Manufacturer'!$S61 -> 268918.92 | G59: =G$29*'PEV Sales by Manufacturer'!$S61 -> 331933.77 | H59: =H$29*'PEV Sales by Manufacturer'!$S61 -> 370123.77 | I59: =I$29*'PEV Sales by Manufacturer'!$S61 -> 392093.85 | J59: =J$29*'PEV Sales by Manufacturer'!$S61 -> 397192.32 | K59: =K$29*'PEV Sales by Manufacturer'!$S61 -> 400159.85 | ... AF59: =AF$29*'PEV Sales by Manufacturer'!$S61 -> 320215.18
A60: Ford | B60: ='PEV Sales by Manufacturer'!M62 -> 5565 | C60: ='PEV Sales by Manufacturer'!N62 -> 6013 | D60: =D$29*'PEV Sales by Manufacturer'!$S62 -> 14991.292 | E60: =E$29*'PEV Sales by Manufacturer'!$S62 -> 21997.777 | F60: =F$29*'PEV Sales by Manufacturer'!$S62 -> 30644.332 | G60: =G$29*'PEV Sales by Manufacturer'!$S62 -> 37825.114 | H60: =H$29*'PEV Sales by Manufacturer'!$S62 -> 42177.009 | I60: =I$29*'PEV Sales by Manufacturer'!$S62 -> 44680.583 | J60: =J$29*'PEV Sales by Manufacturer'!$S62 -> 45261.573 | K60: =K$29*'PEV Sales by Manufacturer'!$S62 -> 45599.735 | ... AF60: =AF$29*'PEV Sales by Manufacturer'!$S62 -> 36489.736
A61: BMW N. America | B61: ='PEV Sales by Manufacturer'!M63 -> 7999 | C61: ='PEV Sales by Manufacturer'!N63 -> 19579 | D61: =D$29*'PEV Sales by Manufacturer'!$S63 -> 48813.322 | E61: =E$29*'PEV Sales by Manufacturer'!$S63 -> 71627.221 | F61: =F$29*'PEV Sales by Manufacturer'!$S63 -> 99781.368 | G61: =G$29*'PEV Sales by Manufacturer'!$S63 -> 123162.8 | H61: =H$29*'PEV Sales by Manufacturer'!$S63 -> 137333.05 | I61: =I$29*'PEV Sales by Manufacturer'!$S63 -> 145484.97 | J61: =J$29*'PEV Sales by Manufacturer'!$S63 -> 147376.74 | K61: =K$29*'PEV Sales by Manufacturer'!$S63 -> 148477.83 | ... AF61: =AF$29*'PEV Sales by Manufacturer'!$S63 -> 118814.66
...

Sheet PEV Sales by Manufacturer
A1: Data summarized by Argonne National Laboratory, 6/22/2022, contact yzhou@anl.gov
A2: PEV
A3: Manufacturer | D3: 2011 | E3: 2012 | F3: 2013 | G3: 2014 | H3: 2015 | I3: 2016 | J3: 2017 | K3: 2018 | L3: 2019 | M3: 2020 | N3: 2021 | O3: 2022* | Q3: Total | R3: Percentage of Total, 2021
A4: Tesla | E4: 2400 | F4: 19400 | G4: 16750 | H4: 26408 | I4: 49800 | J4: 49970 | K4: 161123 | L4: 177589 | M4: 183829 | N4: 320918 | O4: 180520 | Q4: 1188707 | R4: =N4/$N$27 -> 0.50655853
A5: GM (Cadillac and Chevrolet) | D5: 7671 | E5: 23461 | F5: 23660 | G5: 21260 | H5: 19046 | I5: 28887 | J5: 43891 | K5: 36594 | L5: 21370 | M5: 20835 | N5: 24845 | O5: 3680 | Q5: 275200 | R5: =N5/$N$27 -> 0.039217017
A6: Nissan | D6: 9674 | E6: 9819 | F6: 22610 | G6: 30200 | H6: 17269 | I6: 14006 | J6: 11230 | K6: 14715 | L6: 12365 | M6: 9564 | N6: 14239 | O6: 7037 | Q6: 172728 | R6: =N6/$N$27 -> 0.022475794
A7: Toyota | E7: 12941 | F7: 13093 | G7: 14448 | H7: 4209 | I7: 2474 | J7: 20936 | K7: 27596 | L7: 21856 | M7: 17898 | N7: 52767 | O7: 13578 | Q7: 201796 | R7: =N7/$N$27 -> 0.083290978
A8: Ford | E8: 3057 | F8: 14981 | G8: 21947 | H8: 18923 | I8: 24796 | J8: 19589 | K8: 9216 | L8: 8235 | M8: 5568 | N8: 33234 | O8: 23819 | Q8: 183365 | R8: =N8/$N$27 -> 0.052458778
A9: BMW N. America | E9: 673 | F9: 0 | G9: 6647 | H9: 14181 | I9: 16117 | J9: 21195 | K9: 26092 | L9: 14067 | M9: 10639 | N9: 23064 | O9: 7611 | Q9: 140286 | R9: =N9/$N$27 -> 0.036405767
A10: FCA (Chrysler and Fiat) | F10: 260 | G10: 1503 | H10: 3477 | I10: 3737 | J10: 6317 | K10: 9897 | L10: 6850 | M10: 5666 | N10: 48723 | O10: 30098 | Q10: 116528 | R10: =N10/$N$27 -> 0.076907657
A11: Honda | E11: 93 | F11: 1095 | G11: 856 | H11: 66 | I11: 0 | J11: 2024 | K11: 19550 | L11: 11334 | M11: 3984 | N11: 2315 | O11: 2 | Q11: 41319 | R11: =N11/$N$27 -> 0.0036541515
A12: Audi | I12: 4280 | J12: 2877 | K12: 2391 | L12: 5410 | M12: 11670 | N12: 20019 | O12: 9704 | Q12: 56351 | R12: =N12/$N$27 -> 0.031599335
A13: Hyundai | H13: 15 | I13: 3000 | J13: 2686 | K13: 2684 | L13: 8045 | M13: 8793 | N13: 17013 | O13: 17215 | Q13: 59451 | R13: =N13/$N$27 -> 0.026854462
A14: Kia | G14: 359 | H14: 1015 | I14: 1728 | J14: 3669 | K14: 5670 | L14: 6769 | M14: 5302 | N14: 14617 | O14: 19481 | Q14: 58610 | R14: =N14/$N$27 -> 0.023072455
A15: Volvo | H15: 86 | I15: 2015 | J15: 2826 | K15: 3818 | L15: 3683 | M15: 7241 | N15: 25469 | O15: 13813 | Q15: 58951 | R15: =N15/$N$27 -> 0.040201981
A16: Porsche | F16: 51 | G16: 991 | H16: 1570 | I16: 2504 | J16: 1592 | K16: 2152 | L16: 2705 | M16: 6935 | N16: 11931 | O16: 4760 | Q16: 35191 | R16: =N16/$N$27 -> 0.018832692
A17: Volkswagon | G17: 357 | H17: 4232 | I17: 3937 | J17: 3534 | K17: 1354 | L17: 4863 | M17: 767 | N17: 16775 | O17: 3820 | Q17: 39639 | R17: =N17/$N$27 -> 0.026478787
A18: Merdeces-Benz | G18: 774 | H18: 2024 | I18: 1584 | J18: 2690 | K18: 2336 | L18: 5389 | M18: 1236 | N18: 507 | O18: 3280 | Q18: 19820 | R18: =N18/$N$27 -> 0.00080028286
A19: Mitsubishi | D19: 76 | E19: 588 | F19: 1029 | G19: 196 | H19: 115 | I19: 94 | J19: 105 | K19: 4166 | L19: 2810 | M19: 1964 | N19: 2250 | O19: 1158 | Q19: 14551 | R19: =N19/$N$27 -> 0.0035515512
A20: Smart USA | D20: 342 | E20: 139 | F20: 923 | G20: 2594 | H20: 1387 | I20: 657 | J20: 544 | K20: 1198 | L20: 680 | M20: 0 | N20: 0 | O20: 0 | Q20: 8464 | R20: =N20/$N$27 -> 0
A21: Jaguar Land Rover | K21: 393 | L21: 3002 | M21: 3129 | N21: 1665 | O21: 251 | Q21: 8440 | R21: =N21/$N$27 -> 0.0026281479
A22: Subaru | K22: 0 | L22: 2591 | M22: 2514 | N22: 2618 | O22: 947 | Q22: 8670 | R22: =N22/$N$27 -> 0.0041324271
A23: Rivian | N23: 376 | O23: 3551 | Q23: 3927 | R23: =N23/$N$27 -> 0.00059350366
A24: Lucid | N24: 65 | O24: 600 | Q24: 665 | R24: =N24/$N$27 -> 0.00010260037
A25: Mazda | N25: 116 | O25: 293 | Q25: 409 | R25: =N25/$N$27 -> 0.00018310219
A27: Total | D27: 17763 | E27: 53171 | F27: 97102 | G27: 118882 | H27: 114023 | I27: 159616 | J27: 195675 | K27: 330945 | L27: 319613 | M27: 307534 | N27: 633526 | O27: 345218 | Q27: 2693068
A29: BEV Only
