Workbook
Name gigwatts_to_megawatts: About!$A$31

Sheet About
A1: GBSC BAU Grid Battery Storage Capacity
A2: GBSB Potential Additional Grid Battery Storage Capacity
A3: GBSC Start Year Grid Battery Storage Capacity
A5: Source: | B5: BAU Grid Battery Storage Capacity
B6: Energy Information Administration
B7: 2022
B8: Annual Energy Outlook 2022
B9: https://www.eia.gov/outlooks/aeo/tables_side.php
B10: Row "Diurnal Storage"
B12: Potential Additional Battery Storage Capacity
B13: GSPP, GridLab, Energy Innovation
B14: 2020
B15: The 2035 Report
B16: https://www.2035report.com/data-explorer/
B18: Start Year Battery Storage Capacity
B19: Energy Information Administration
B20: 2020
B21: Annual Energy Outlook 2020
B22: https://www.eia.gov/outlooks/archive/aeo20/tables_side.php
B23: Row "Diurnal Storage"
A25: Notes
A26: We assume BAU diurnal storage is all battery storage
A28: The "Start Year" is the year prior to the first simulated year.
A30: Unit Conversion
A31: 1000 | B31: gigawatts to megawatts
A33: We take battery storage deployments from the 2035 report, which evaluates a pathway to 90%
A34: clean electricity by 2035. We adjust these values upward through 2035 to achieve the same ratio
A35: of storage capacity to wind and solar capacity as in the 2035 report (using our 1.5 degree scenario).
A36: Post-2035, we assume annual deployment can reach roughly 20 GW per year, the maximum
A37: deployment in the 2035 report.

Sheet 2035 Report Deployment
B1: 2019 | C1: 2020 | D1: 2021 | E1: 2022 | F1: 2023 | G1: 2024 | H1: 2025 | I1: 2026 | J1: 2027 | K1: 2028 | L1: 2029 | M1: 2030 | N1: 2031 | O1: 2032 | P1: 2033 | Q1: 2034 | R1: 2035 | S1: 2036 | T1: 2037 | U1: 2038 | V1: 2039 | W1: 2040 | X1: 2041 | Y1: 2042 | Z1: 2043 | AA1: 2044 | AB1: 2045 | AC1: 2046 | AD1: 2047 | AE1: 2048 | AF1: 2049 | AG1: 2050
A2: Existing battery storage | B2: ='AEO Table 9 (2020)'!C23 -> 1.3702
A3: New battery storage capacity (GW) | C3: =GETPIVOTDATA("newCapacityMW",'2035 Report Data'!$J$6,"year",C1,"tech","battery")/1000 -> 0.791035 | D3: =GETPIVOTDATA("newCapacityMW",'2035 Report Data'!$J$6,"year",D1,"tech","battery")/1000 -> 1.54701 | E3: =GETPIVOTDATA("newCapacityMW",'2035 Report Data'!$J$6,"year",E1,"tech","battery")/1000 -> 1.54701 | F3: =GETPIVOTDATA("newCapacityMW",'2035 Report Data'!$J$6,"year",F1,"tech","battery")/1000 -> 5.00969 | G3: =GETPIVOTDATA("newCapacityMW",'2035 Report Data'!$J$6,"year",G1,"tech","battery")/1000 -> 5.00969 | H3: =GETPIVOTDATA("newCapacityMW",'2035 Report Data'!$J$6,"year",H1,"tech","battery")/1000 -> 5.90658 | I3: =GETPIVOTDATA("newCapacityMW",'2035 Report Data'!$J$6,"year",I1,"tech","battery")/1000 -> 5.90658 | J3: =GETPIVOTDATA("newCapacityMW",'2035 Report Data'!$J$6,"year",J1,"tech","battery")/1000 -> 5.36563 | ... R3: =GETPIVOTDATA("newCapacityMW",'2035 Report Data'!$J$6,"year",R1,"tech","battery")/1000 -> 19.6115 | S3: =$R$3 -> 19.6115 | T3: =$R$3 -> 19.6115 | U3: =$R$3 -> 19.6115 | V3: =$R$3 -> 19.6115 | W3: =$R$3 -> 19.6115 | X3: =$R$3 -> 19.6115 | Y3: =$R$3 -> 19.6115 | Z3: =$R$3 -> 19.6115 | ... AG3: =$R$3 -> 19.6115
A4: Cumulative battery storage additions (GW) | D4: =B2+C3+D3 -> 3.708245 | E4: =E3+D4 -> 5.255255 | F4: =F3+E4 -> 10.264945 | G4: =G3+F4 -> 15.274635 | H4: =H3+G4 -> 21.181215 | I4: =I3+H4 -> 27.087795 | J4: =J3+I4 -> 32.453425 | K4: =K3+J4 -> 37.819055 | L4: =L3+K4 -> 46.318885 | ... R4: =R3+Q4 -> 144.83402 | S4: =R4+S3 -> 164.44552 | T4: =S4+T3 -> 184.05702 | U4: =T4+U3 -> 203.66852 | V4: =U4+V3 -> 223.28002 | W4: =V4+W3 -> 242.89152 | X4: =W4+X3 -> 262.50302 | Y4: =X4+Y3 -> 282.11452 | Z4: =Y4+Z3 -> 301.72602 | ... AG4: =AF4+AG3 -> 439.00651
A5: Additional Multiplier | D5: 0.15 | E5: 0.15 | F5: 0.15 | G5: 0.15 | H5: 0.25 | I5: 0.25 | J5: 0.25 | K5: 0.25 | L5: 0.25 | M5: 0.5 | N5: 0.5 | O5: 0.5 | P5: 0.5 | Q5: 0.5 | R5: 0.5
A6: Adjusted Amount (MW) | D6: =D4*(1+D5)*1000 -> 4264.4817 | E6: =E4*(1+E5)*1000 -> 6043.5432 | F6: =F4*(1+F5)*1000 -> 11804.687 | G6: =G4*(1+G5)*1000 -> 17565.83 | H6: =H4*(1+H5)*1000 -> 26476.519 | I6: =I4*(1+I5)*1000 -> 33859.744 | J6: =J4*(1+J5)*1000 -> 40566.781 | K6: =K4*(1+K5)*1000 -> 47273.819 | ... R6: =R4*(1+R5)*1000 -> 217251.02 | S6: =R6+S3*1000 -> 236862.52 | T6: =S6+T3*1000 -> 256474.02 | U6: =T6+U3*1000 -> 276085.52 | V6: =U6+V3*1000 -> 295697.02 | W6: =V6+W3*1000 -> 315308.52 | X6: =W6+X3*1000 -> 334920.02 | Y6: =X6+Y3*1000 -> 354531.52 | Z6: =Y6+Z3*1000 -> 374143.02 | ... AG6: =AF6+AG3*1000 -> 511423.52

Sheet 2035 Report Data
A1: year | B1: tech | C1: newCapacityMW | D1: cleanEnergyPolicy | E1: financingCosts | F1: gasPrices | G1: technologyCosts | J1: cleanEnergyPolicy | K1: CES90
A2: 2020 | B2: battery | C2: 783.405 | D2: CarbonTax | E2: Base | F2: AEO | G2: ATBLow | J2: financingCosts | K2: Base
A3: 2020 | B3: battery | C3: 795.702 | D3: CarbonTax | E3: Base | F3: AEO | G3: ATBMid | J3: gasPrices | K3: AEO
A4: 2020 | B4: battery | C4: 783.405 | D4: CarbonTax | E4: Base | F4: AEO | G4: ATBModified | J4: technologyCosts | K4: ATBMid
A5: 2020 | B5: battery | C5: 783.405 | D5: CarbonTax | E5: Base | F5: NYMEX | G5: ATBLow
A6: 2020 | B6: battery | C6: 786.283 | D6: CarbonTax | E6: Base | F6: NYMEX | G6: ATBMid | J6: Sum of newCapacityMW | K6: Column Labels
A7: 2020 | B7: battery | C7: 783.405 | D7: CarbonTax | E7: Base | F7: NYMEX | G7: ATBModified | J7: Row Labels | K7: 2020 | L7: 2021 | M7: 2022 | N7: 2023 | O7: 2024 | P7: 2025 | Q7: 2026 | R7: 2027 | S7: 2028 | T7: 2029 | U7: 2030 | V7: 2031 | W7: 2032 | X7: 2033 | Y7: 2034 | Z7: 2035 | AA7: Grand Total
A8: 2020 | B8: battery | C8: 876.419 | D8: CarbonTax | E8: High | F8: AEO | G8: ATBLow | J8: battery | K8: 791.035 | L8: 1547.01 | M8: 1547.01 | N8: 5009.69 | O8: 5009.69 | P8: 5906.58 | Q8: 5906.58 | R8: 5365.63 | S8: 5365.63 | T8: 8499.83 | U8: 8499.83 | V8: 15590.4 | W8: 15590.4 | X8: 19611.5 | Y8: 19611.5 | Z8: 19611.5 | AA8: 143463.82
A9: 2020 | B9: battery | C9: 784.911 | D9: CarbonTax | E9: High | F9: AEO | G9: ATBMid | J9: biopower | K9: 102.45 | L9: 9.5 | M9: 9.5 | N9: 0 | O9: 0 | P9: 0 | Q9: 0 | R9: 0 | S9: 0 | T9: 0 | U9: 0 | V9: 0 | W9: 0 | X9: 0 | Y9: 0 | Z9: 0 | AA9: 121.45
A10: 2020 | B10: battery | C10: 857.369 | D10: CarbonTax | E10: High | F10: AEO | G10: ATBModified | J10: coal | K10: 0 | L10: 0 | M10: 0 | N10: 0 | O10: 0 | P10: 0 | Q10: 0 | R10: 0 | S10: 0 | T10: 0 | U10: 0 | V10: 0 | W10: 0 | X10: 0 | Y10: 0 | Z10: 0 | AA10: 0
A11: 2020 | B11: battery | C11: 911.678 | D11: CarbonTax | E11: High | F11: NYMEX | G11: ATBLow | J11: gas | K11: 11059.73 | L11: 0 | M11: 0 | N11: 0 | O11: 0 | P11: 0 | Q11: 0 | R11: 0 | S11: 0 | T11: 0 | U11: 0 | V11: 0 | W11: 0 | X11: 0 | Y11: 0 | Z11: 0 | AA11: 11059.73
A12: 2020 | B12: battery | C12: 783.846 | D12: CarbonTax | E12: High | F12: NYMEX | G12: ATBMid | J12: geothermal | K12: 0 | L12: 0 | M12: 0 | N12: 0 | O12: 0 | P12: 0 | Q12: 0 | R12: 0 | S12: 0 | T12: 0 | U12: 0 | V12: 0 | W12: 0 | X12: 0 | Y12: 0 | Z12: 0 | AA12: 0
A13: 2020 | B13: battery | C13: 881.486 | D13: CarbonTax | E13: High | F13: NYMEX | G13: ATBModified | J13: hydro | K13: 3796.81 | L13: 1 | M13: 1 | N13: 59 | O13: 59 | P13: 66.5 | Q13: 66.5 | R13: 37.895 | S13: 37.895 | T13: 11.5 | U13: 11.5 | V13: 13 | W13: 13 | X13: 19.8333 | Y13: 19.8333 | Z13: 19.8333 | AA13: 4234.0999
A14: 2020 | B14: battery | C14: 942.07 | D14: CES90 | E14: Base | F14: AEO | G14: ATBLow | J14: nuclear | K14: 232.5 | L14: 1100 | M14: 1100 | N14: 0 | O14: 0 | P14: 0 | Q14: 0 | R14: 0 | S14: 0 | T14: 0 | U14: 0 | V14: 0 | W14: 0 | X14: 0 | Y14: 0 | Z14: 0 | AA14: 2432.5
A15: 2020 | B15: battery | C15: 791.035 | D15: CES90 | E15: Base | F15: AEO | G15: ATBMid | J15: other | K15: 14.85 | L15: 0 | M15: 0 | N15: 0 | O15: 0 | P15: 0 | Q15: 0 | R15: 0 | S15: 0 | T15: 0 | U15: 0 | V15: 0 | W15: 0 | X15: 0 | Y15: 0 | Z15: 0 | AA15: 14.85
A16: 2020 | B16: battery | C16: 929.682 | D16: CES90 | E16: Base | F16: AEO | G16: ATBModified | J16: solar | K16: 13026.4 | L16: 32983.6 | M16: 32983.6 | N16: 30498.8 | O16: 30498.8 | P16: 21718.2 | Q16: 21718.2 | R16: 30857.2 | S16: 30857.2 | T16: 31380.4 | U16: 31380.4 | V16: 15860.9 | W16: 15860.9 | X16: 32889.2 | Y16: 32889.2 | Z16: 32889.2 | AA16: 438292.2
A17: 2020 | B17: battery | C17: 909.726 | D17: CES90 | E17: Base | F17: NYMEX | G17: ATBLow | J17: wind | K17: 13350.8 | L17: 25891 | M17: 25891 | N17: 21768.3 | O17: 21768.3 | P17: 36012 | Q17: 36012 | R17: 33005.5 | S17: 33005.5 | T17: 32996.4 | U17: 32996.4 | V17: 55468.3 | W17: 55468.3 | X17: 53885.9 | Y17: 53885.9 | Z17: 53885.9 | AA17: 585291.5
A18: 2020 | B18: battery | C18: 792.379 | D18: CES90 | E18: Base | F18: NYMEX | G18: ATBMid | J18: Grand Total | K18: 42374.575 | L18: 61532.11 | M18: 61532.11 | N18: 57335.79 | O18: 57335.79 | P18: 63703.28 | Q18: 63703.28 | R18: 69266.225 | S18: 69266.225 | T18: 72888.13 | U18: 72888.13 | V18: 86932.6 | W18: 86932.6 | X18: 106406.43 | Y18: 106406.43 | Z18: 106406.43 | AA18: 1184910.1
A19: 2020 | B19: battery | C19: 896.168 | D19: CES90 | E19: Base | F19: NYMEX | G19: ATBModified
A20: 2020 | B20: battery | C20: 938.939 | D20: CES90 | E20: High | F20: AEO | G20: ATBLow | J20: Cumulative wind | K20: ='AEO Table 16'!C23*1000+K17 -> 120129.86 | L20: =K20+L17 -> 146020.86 | M20: =L20+M17 -> 171911.86 | N20: =M20+N17 -> 193680.16 | O20: =N20+O17 -> 215448.46 | P20: =O20+P17 -> 251460.46 | Q20: =P20+Q17 -> 287472.46 | R20: =Q20+R17 -> 320477.96 | S20: =R20+S17 -> 353483.46 | ... Z20: =Y20+Z17 -> 692070.56
A21: 2020 | B21: battery | C21: 801.013 | D21: CES90 | E21: High | F21: AEO | G21: ATBMid | J21: Cumulative solar | K21: ='AEO Table 16'!C22*1000+K16 -> 48676.436 | L21: =K21+L16 -> 81660.036 | M21: =L21+M16 -> 114643.64 | N21: =M21+N16 -> 145142.44 | O21: =N21+O16 -> 175641.24 | P21: =O21+P16 -> 197359.44 | Q21: =P21+Q16 -> 219077.64 | R21: =Q21+R16 -> 249934.84 | S21: =R21+S16 -> 280792.04 | ... Z21: =Y21+Z16 -> 473942.24
A22: 2020 | B22: battery | C22: 895.313 | D22: CES90 | E22: High | F22: AEO | G22: ATBModified | J22: Cumulative storage | K22: ='AEO Table 9 (2020)'!C23*1000+K8 -> 2161.235 | L22: =K22+L8 -> 3708.245 | M22: =L22+M8 -> 5255.255 | N22: =M22+N8 -> 10264.945 | O22: =N22+O8 -> 15274.635 | P22: =O22+P8 -> 21181.215 | Q22: =P22+Q8 -> 27087.795 | R22: =Q22+R8 -> 32453.425 | S22: =R22+S8 -> 37819.055 | ... Z22: =Y22+Z8 -> 144834.02
A23: 2020 | B23: battery | C23: 901.978 | D23: CES90 | E23: High | F23: NYMEX | G23: ATBLow | J23: Ratio of battery storage to wind and solar capacity | K23: =K22/SUM(K20:K21) -> 0.012803047 | L23: =L22/SUM(L20:L21) -> 0.016287027 | M23: =M22/SUM(M20:M21) -> 0.018339397 | N23: =N22/SUM(N20:N21) -> 0.030295928 | O23: =O22/SUM(O20:O21) -> 0.039056603 | P23: =P22/SUM(P20:P21) -> 0.047193128 | Q23: =Q22/SUM(Q20:Q21) -> 0.053475056 | R23: =R22/SUM(R20:R21) -> 0.05689463 | ... Z23: =Z22/SUM(Z20:Z21) -> 0.12421306
A24: 2020 | B24: battery | C24: 798.031 | D24: CES90 | E24: High | F24: NYMEX | G24: ATBMid
A25: 2020 | B25: battery | C25: 881.508 | D25: CES90 | E25: High | F25: NYMEX | G25: ATBModified
A26: 2020 | B26: battery | C26: 783.405 | D26: Unconstrained | E26: Base | F26: AEO | G26: ATBLow
A27: 2020 | B27: battery | C27: 783.405 | D27: Unconstrained | E27: Base | F27: AEO | G27: ATBMid
A28: 2020 | B28: battery | C28: 783.405 | D28: Unconstrained | E28: Base | F28: AEO | G28: ATBModified
A29: 2020 | B29: battery | C29: 783.405 | D29: Unconstrained | E29: Base | F29: NYMEX | G29: ATBLow
A30: 2020 | B30: battery | C30: 783.405 | D30: Unconstrained | E30: Base | F30: NYMEX | G30: ATBMid
A31: 2020 | B31: battery | C31: 783.405 | D31: Unconstrained | E31: Base | F31: NYMEX | G31: ATBModified
A32: 2020 | B32: battery | C32: 783.405 | D32: Unconstrained | E32: High | F32: AEO | G32: ATBLow
A33: 2020 | B33: battery | C33: 783.405 | D33: Unconstrained | E33: High | F33: AEO | G33: ATBMid
A34: 2020 | B34: battery | C34: 783.405 | D34: Unconstrained | E34: High | F34: AEO | G34: ATBModified
A35: 2020 | B35: battery | C35: 783.405 | D35: Unconstrained | E35: High | F35: NYMEX | G35: ATBLow
... A5761: 2035 | B5761: wind | C5761: 2651.02 | D5761: Unconstrained | E5761: High | F5761: NYMEX | G5761: ATBModified

Sheet EPS Output
A1: Time (Year) | B1: 2019 | C1: 2020 | D1: 2021 | E1: 2022 | F1: 2023 | G1: 2024 | H1: 2025 | I1: 2026 | J1: 2027 | K1: 2028 | L1: 2029 | M1: 2030 | N1: 2031 | O1: 2032 | P1: 2033 | Q1: 2034 | R1: 2035 | S1: 2036 | T1: 2037 | U1: 2038 | V1: 2039 | W1: 2040 | X1: 2041 | Y1: 2042 | Z1: 2043 | AA1: 2044 | AB1: 2045 | AC1: 2046 | AD1: 2047 | AE1: 2048 | AF1: 2049 | AG1: 2050
A2: Grid Battery Storage Capacity : MostRecentRun | B2: 1370 | C2: 2629 | D2: 5629 | E2: 6260 | F2: 11805 | G2: 17566 | H2: 26477 | I2: 33860 | J2: 40567 | K2: 47274 | L2: 57899 | M2: 82228 | N2: 105614 | O2: 128999 | P2: 158417 | Q2: 187834 | R2: 217251 | S2: 236862 | T2: 254513 | U2: 270202 | V2: 283930 | W2: 295697 | X2: 305503 | Y2: 315308 | Z2: 325114 | AA2: 334920 | AB2: 344726 | AC2: 354532 | AD2: 364338 | AE2: 374143 | AF2: 383949 | AG2: 393755
A4: Time (Year) | B4: 2019 | C4: 2020 | D4: 2021 | E4: 2022 | F4: 2023 | G4: 2024 | H4: 2025 | I4: 2026 | J4: 2027 | K4: 2028 | L4: 2029 | M4: 2030 | N4: 2031 | O4: 2032 | P4: 2033 | Q4: 2034 | R4: 2035 | S4: 2036 | T4: 2037 | U4: 2038 | V4: 2039 | W4: 2040 | X4: 2041 | Y4: 2042 | Z4: 2043 | AA4: 2044 | AB4: 2045 | AC4: 2046 | AD4: 2047 | AE4: 2048 | AF4: 2049 | AG4: 2050
A5: Output Electricity Generation Capacity[hard coal es] : MostRecentRun | B5: 226.058 | C5: 218.576 | D5: 205.418 | E5: 178.586 | F5: 146.594 | G5: 114.602 | H5: 73.322 | I5: 58.616 | J5: 43.652 | K5: 28.43 | L5: 12.434 | M5: 0 | N5: 0 | O5: 0 | P5: 0 | Q5: 0 | R5: 0 | S5: 0 | T5: 0 | U5: 0 | V5: 0 | W5: 0 | X5: 0 | Y5: 0 | Z5: 0 | AA5: 0 | AB5: 0 | AC5: 0 | AD5: 0 | AE5: 0 | AF5: 0 | AG5: 0
A6: Output Electricity Generation Capacity[natural gas nonpeaker es] : MostRecentRun | B6: 255.38 | C6: 255.226 | D6: 256.304 | E6: 260.924 | F6: 260.154 | G6: 253.84 | H6: 249.066 | I6: 246.756 | J6: 242.444 | K6: 237.824 | L6: 233.358 | M6: 229.354 | N6: 224.734 | O6: 220.576 | P6: 215.494 | Q6: 210.104 | R6: 210.104 | S6: 210.104 | T6: 209.95 | U6: 209.95 | V6: 209.334 | W6: 209.334 | X6: 209.334 | Y6: 208.872 | Z6: 208.872 | AA6: 208.872 | AB6: 208.256 | AC6: 208.256 | AD6: 207.794 | AE6: 207.024 | AF6: 207.024 | AG6: 206.716
A7: Output Electricity Generation Capacity[nuclear es] : MostRecentRun | B7: 98.294 | C7: 98.294 | D7: 94.877 | E7: 92.599 | F7: 90.321 | G7: 88.043 | H7: 83.487 | I7: 74.375 | J7: 72.097 | K7: 69.819 | L7: 67.541 | M7: 66.402 | N7: 65.263 | O7: 64.124 | P7: 59.568 | Q7: 55.012 | R7: 55.012 | S7: 55.012 | T7: 55.012 | U7: 55.012 | V7: 55.012 | W7: 53.873 | X7: 53.873 | Y7: 53.873 | Z7: 52.734 | AA7: 52.734 | AB7: 52.734 | AC7: 52.734 | AD7: 52.734 | AE7: 52.734 | AF7: 52.734 | AG7: 52.734
A8: Output Electricity Generation Capacity[hydro es] : MostRecentRun | B8: 79.655 | C8: 79.792 | D8: 79.968 | E8: 80.126 | F8: 80.437 | G8: 80.545 | H8: 80.661 | I8: 80.781 | J8: 80.895 | K8: 80.985 | L8: 81.011 | M8: 81.111 | N8: 81.158 | O8: 81.271 | P8: 81.388 | Q8: 80.133 | R8: 80.279 | S8: 80.374 | T8: 80.425 | U8: 80.525 | V8: 80.618 | W8: 80.716 | X8: 80.809 | Y8: 80.886 | Z8: 80.974 | AA8: 80.956 | AB8: 81.011 | AC8: 81.094 | AD8: 81.051 | AE8: 81.109 | AF8: 81.159 | AG8: 81.155
A9: Output Electricity Generation Capacity[onshore wind es] : MostRecentRun | B9: 99.045 | C9: 99.045 | D9: 135.825 | E9: 176.55 | F9: 208.985 | G9: 236.87 | H9: 265.285 | I9: 296.755 | J9: 322.255 | K9: 349.47 | L9: 376.8 | M9: 402.08 | N9: 439.905 | O9: 490.31 | P9: 551.35 | Q9: 620.195 | R9: 684.395 | S9: 690.225 | T9: 701.79 | U9: 712.755 | V9: 718.665 | W9: 728.665 | X9: 735.935 | Y9: 741.23 | Z9: 746.09 | AA9: 750.31 | AB9: 754.99 | AC9: 758.365 | AD9: 762.555 | AE9: 766.11 | AF9: 769.21 | AG9: 772.705
A10: Output Electricity Generation Capacity[solar PV es] : MostRecentRun | B10: 29.763 | C10: 39.915 | D10: 64.783 | E10: 101.819 | F10: 141.979 | G10: 190.899 | H10: 254.539 | I10: 334.095 | J10: 409.885 | K10: 494.473 | L10: 582.525 | M10: 670.919 | N10: 760.195 | O10: 849.471 | P10: 938.577 | Q10: 1027.67 | R10: 1117.67 | S10: 1201.57 | T10: 1291.3 | U10: 1381.04 | V10: 1467.05 | W10: 1556.72 | X10: 1645.14 | Y10: 1730.64 | Z10: 1814.45 | AA10: 1895.33 | AB10: 1978.6 | AC10: 2053.12 | AD10: 2133.71 | AE10: 2210.11 | AF10: 2281.28 | AG10: 2356.73
A11: Output Electricity Generation Capacity[solar thermal es] : MostRecentRun | B11: 1.758 | C11: 1.758 | D11: 1.758 | E11: 0.354 | F11: 0.198 | G11: 0.198 | H11: 0.198 | I11: 0.198 | J11: 0.198 | K11: 0.198 | L11: 0.198 | M11: 0.042 | N11: 0.042 | O11: 0.042 | P11: 0.042 | Q11: 0.042 | R11: 0.042 | S11: 0.042 | T11: 0.042 | U11: 0.042 | V11: 0.042 | W11: 0.042 | X11: 0.042 | Y11: 0.042 | Z11: 0.042 | AA11: 0.042 | AB11: 0.042 | AC11: 0.042 | AD11: 0.042 | AE11: 0.042 | AF11: 0.042 | AG11: 0.042
A12: Output Electricity Generation Capacity[biomass es] : MostRecentRun | B12: 5.233 | C12: 5.287 | D12: 4.549 | E12: 0.067 | F12: 0.031 | G12: 0.013 | H12: 0.013 | I12: 0.013 | J12: 0.013 | K12: 0.013 | L12: 0.013 | M12: 0.013 | N12: 0.013 | O12: 0.013 | P12: 0.013 | Q12: 0.013 | R12: 0.013 | S12: 0.013 | T12: 0.013 | U12: 0.013 | V12: 0.013 | W12: 0.013 | X12: 0.013 | Y12: 0.013 | Z12: 0.013 | AA12: 0.013 | AB12: 0.013 | AC12: 0.013 | AD12: 0.013 | AE12: 0.013 | AF12: 0.013 | AG12: 0.013
A13: Output Electricity Generation Capacity[geothermal es] : MostRecentRun | B13: 2.395 | C13: 2.395 | D13: 2.455 | E13: 2.455 | F13: 2.455 | G13: 2.455 | H13: 2.455 | I13: 2.455 | J13: 2.455 | K13: 0.685 | L13: 0.005 | M13: 0.005 | N13: 0.005 | O13: 0.005 | P13: 0.005 | Q13: 0.005 | R13: 0.005 | S13: 0.005 | T13: 0.005 | U13: 0.005 | V13: 0.005 | W13: 0.005 | X13: 0.005 | Y13: 0.005 | Z13: 0.005 | AA13: 0.005 | AB13: 0.005 | AC13: 0.005 | AD13: 0.005 | AE13: 0.005 | AF13: 0.005 | AG13: 0.005
... A20: Output Electricity Generation Capacity[municipal solid waste es] : MostRecentRun | B20: 1.81 | C20: 1.81 | D20: 1.712 | E20: 0.942 | F20: 0.004 | G20: 0.004 | H20: 0.004 | I20: 0.004 | J20: 0.004 | K20: 0.004 | L20: 0.004 | M20: 0.004 | N20: 0.004 | O20: 0.004 | P20: 0.004 | Q20: 0.004 | R20: 0.004 | S20: 0.004 | T20: 0.004 | U20: 0.004 | V20: 0.004 | W20: 0.004 | X20: 0.004 | Y20: 0.004 | Z20: 0.004 | AA20: 0.004 | AB20: 0.004 | AC20: 0.004 | AD20: 0.004 | AE20: 0.004 | AF20: 0.004 | AG20: 0.004
A22: Ratio of battery storage to wind and solar capacity | B22: =(B2/1000)/SUM(B9:B10) -> 0.010635985 | C22: =(C2/1000)/SUM(C9:C10) -> 0.018919113 | D22: =(D2/1000)/SUM(D9:D10) -> 0.028059699 | E22: =(E2/1000)/SUM(E9:E10) -> 0.022488136 | F22: =(F2/1000)/SUM(F9:F10) -> 0.033635928 | G22: =(G2/1000)/SUM(G9:G10) -> 0.041064219 | H22: =(H2/1000)/SUM(H9:H10) -> 0.050934547 | I22: =(I2/1000)/SUM(I9:I10) -> 0.053673615 | ... AG22: =(AG2/1000)/SUM(AG9:AG10) -> 0.12582303
C23: 0.012803047 | D23: 0.016287027 | E23: 0.018339397 | F23: 0.030295928 | G23: 0.039056603 | H23: 0.047193128 | I23: 0.053475056 | J23: 0.05689463 | K23: 0.059625597 | L23: 0.066297478 | M23: 0.071843545 | N23: 0.084387146 | O23: 0.094954955 | P23: 0.10641309 | Q23: 0.11602867 | R23: 0.12421306

Sheet AEO Table 9 (2020)
B1: ref2020.d112119a | C1: 2019 | D1: 2020 | E1: 2021 | F1: 2022 | G1: 2023 | H1: 2024 | I1: 2025 | J1: 2026 | K1: 2027 | L1: 2028 | M1: 2029 | N1: 2030 | O1: 2031 | P1: 2032 | Q1: 2033 | R1: 2034 | S1: 2035 | T1: 2036 | U1: 2037 | V1: 2038 | W1: 2039 | X1: 2040 | Y1: 2041 | Z1: 2042 | AA1: 2043 | AB1: 2044 | AC1: 2045 | AD1: 2046 | AE1: 2047 | AF1: 2048 | AG1: 2049 | AH1: 2050
C3: Report | D3: Annual Energy Outlook 2020
C4: Scenario | D4: ref2020 | G4: Reference case
C5: Datekey | D5: d112119a
C6: Release Date | E6: January 2020
A10: EGC000 | B10: 9. Electricity Generating Capacity
B11: (gigawatts)
AI12: 2019-
B13: Net Summer Capacity 1/ | C13: 2019 | D13: 2020 | E13: 2021 | F13: 2022 | G13: 2023 | H13: 2024 | I13: 2025 | J13: 2026 | K13: 2027 | L13: 2028 | M13: 2029 | N13: 2030 | O13: 2031 | P13: 2032 | Q13: 2033 | R13: 2034 | S13: 2035 | T13: 2036 | U13: 2037 | V13: 2038 | W13: 2039 | X13: 2040 | Y13: 2041 | Z13: 2042 | AA13: 2043 | AB13: 2044 | AC13: 2045 | AD13: 2046 | AE13: 2047 | AF13: 2048 | AG13: 2049 | AH13: 2050 | AI13: 2050
B15: Electric Power Sector 2/
B16: Power Only 3/
A17: EGC000:ba_CoalSteam | B17: Coal 4/ | C17: 231.08414 | D17: 223.79623 | E17: 221.06181 | F17: 207.50491 | G17: 190.04248 | H17: 172.30737 | I17: 138.29921 | J17: 135.3732 | K17: 134.09552 | L17: 132.76051 | M17: 130.82552 | N17: 130.19051 | O17: 129.95851 | P17: 129.86621 | Q17: 129.86621 | R17: 128.70792 | S17: 127.8319 | T17: 127.14941 | U17: 126.6149 | V17: 124.96141 | W17: 124.62241 | X17: 124.62241 | Y17: 124.28241 | Z17: 124.28241 | AA17: 124.28241 | AB17: 124.28241 | AC17: 123.8674 | AD17: 123.8674 | AE17: 123.63541 | AF17: 123.63541 | AG17: 123.41041 | AH17: 123.41041 | AI17: -0.020031
A18: EGC000:ba_OtherFossilSt | B18: Oil and Natural Gas Steam 4, 5/ | C18: 75.206711 | D18: 72.773109 | E18: 66.741508 | F18: 61.672409 | G18: 59.380302 | H18: 56.946198 | I18: 60.158005 | J18: 58.542809 | K18: 58.025803 | L18: 57.491806 | M18: 55.735405 | N18: 55.287407 | O18: 54.269211 | P18: 52.41721 | Q18: 51.148808 | R18: 50.620708 | S18: 49.641712 | T18: 49.641712 | U18: 49.641712 | V18: 49.310711 | W18: 49.310711 | X18: 49.310711 | Y18: 49.310711 | Z18: 49.310711 | AA18: 49.310711 | AB18: 49.310711 | AC18: 49.310711 | AD18: 49.310711 | AE18: 49.310711 | AF18: 49.230709 | AG18: 49.230709 | AH18: 49.230709 | AI18: -0.013575
A19: EGC000:ba_CombinedCycle | B19: Combined Cycle | C19: 239.8858 | D19: 244.90321 | E19: 254.7644 | F19: 269.49536 | G19: 280.39185 | H19: 289.07001 | I19: 301.34296 | J19: 309.6572 | K19: 312.92664 | L19: 316.25357 | M19: 320.89716 | N19: 322.81482 | O19: 327.72052 | P19: 330.2009 | Q19: 333.93457 | R19: 337.6329 | S19: 341.53003 | T19: 346.66101 | U19: 351.82873 | V19: 357.31 | W19: 362.72366 | X19: 367.03781 | Y19: 370.36438 | Z19: 373.62997 | AA19: 377.41656 | AB19: 378.862 | AC19: 381.45685 | AD19: 385.46112 | AE19: 389.47742 | AF19: 392.11798 | AG19: 397.56342 | AH19: 400.95282 | AI19: 0.016708
A20: EGC000:ba_CombustionTur | B20: Combustion Turbine/Diesel | C20: 140.49271 | D20: 147.97757 | E20: 153.15196 | F20: 156.03604 | G20: 159.43466 | H20: 163.24979 | I20: 167.95743 | J20: 172.69608 | K20: 175.56021 | L20: 180.78302 | M20: 184.12144 | N20: 189.52707 | O20: 195.74348 | P20: 202.89238 | Q20: 207.31116 | R20: 211.76163 | S20: 218.32164 | T20: 223.14461 | U20: 229.9198 | V20: 234.47052 | W20: 241.51596 | X20: 246.68021 | Y20: 253.76321 | Z20: 259.46979 | AA20: 267.01703 | AB20: 275.69638 | AC20: 282.17578 | AD20: 291.15888 | AE20: 296.65949 | AF20: 305.957 | AG20: 313.3967 | AH20: 323.01959 | AI20: 0.027221
A21: EGC000:ba_NuclearPower | B21: Nuclear Power 6/ | C21: 98.110115 | D21: 97.091614 | E21: 94.744415 | F21: 95.087219 | G21: 95.131218 | H21: 95.182007 | I21: 91.920135 | J21: 83.109558 | K21: 83.14473 | L21: 83.179893 | M21: 83.224869 | N21: 83.310944 | O21: 83.449646 | P21: 83.545952 | Q21: 81.662491 | R21: 79.616547 | S21: 79.794891 | T21: 79.927475 | U21: 79.954239 | V21: 79.980988 | W21: 79.980988 | X21: 78.85672 | Y21: 79.01564 | Z21: 79.13063 | AA21: 78.089554 | AB21: 78.185455 | AC21: 78.289337 | AD21: 78.343445 | AE21: 78.397537 | AF21: 78.431229 | AG21: 78.471939 | AH21: 78.534271 | AI21: -0.007154
A22: EGC000:ba_PumpedStorage | B22: Pumped Storage | C22: 22.830204 | D22: 22.830204 | E22: 22.830204 | F22: 22.830204 | G22: 22.830204 | H22: 22.830204 | I22: 22.830204 | J22: 22.830204 | K22: 22.830204 | L22: 22.830204 | M22: 22.830204 | N22: 22.830204 | O22: 22.830204 | P22: 22.830204 | Q22: 22.830204 | R22: 22.830204 | S22: 22.830204 | T22: 22.830204 | U22: 22.830204 | V22: 22.830204 | W22: 22.830204 | X22: 22.830204 | Y22: 22.830204 | Z22: 22.830204 | AA22: 22.830204 | AB22: 22.830204 | AC22: 22.830204 | AD22: 22.830204 | AE22: 22.830204 | AF22: 22.830204 | AG22: 22.830204 | AH22: 22.830204 | AI22: 0
A23: EGC000:ba_DiurnalStorag | B23: Diurnal Storage | C23: 1.3702 | D23: 2.62886 | E23: 5.62886 | F23: 6.25986 | G23: 6.890861 | H23: 7.520861 | I23: 7.963861 | J23: 8.374861 | K23: 8.785861 | L23: 9.196861 | M23: 9.658842 | N23: 10.069842 | O23: 10.069842 | P23: 10.069842 | Q23: 10.356866 | R23: 10.804548 | S23: 10.804548 | T23: 10.872132 | U23: 10.872132 | V23: 10.886932 | W23: 10.886932 | X23: 10.974281 | Y23: 11.41368 | Z23: 12.008404 | AA23: 12.008404 | AB23: 12.008404 | AC23: 12.642261 | AD23: 13.321657 | AE23: 15.081673 | AF23: 16.082682 | AG23: 17.366106 | AH23: 17.400896 | AI23: 0.085441
A24: EGC000:ba_FuelCells | B24: Fuel Cells | C24: 0.1491 | D24: 0.1731 | E24: 0.1768 | F24: 0.184427 | G24: 0.185699 | H24: 0.185699 | I24: 0.185699 | J24: 0.185699 | K24: 0.185699 | L24: 0.215561 | M24: 0.215561 | N24: 0.215561 | O24: 0.215561 | P24: 0.215561 | Q24: 0.215561 | R24: 0.215561 | S24: 0.215561 | T24: 0.215561 | U24: 0.215561 | V24: 0.215561 | W24: 0.215561 | X24: 0.215561 | Y24: 0.215561 | Z24: 0.215561 | AA24: 0.215561 | AB24: 0.215561 | AC24: 0.215561 | AD24: 0.215561 | AE24: 0.215561 | AF24: 0.215561 | AG24: 0.215561 | AH24: 0.215561 | AI24: 0.011962
A25: EGC000:ba_RenewableSour | B25: Renewable Sources 7/ | C25: 231.45772 | D25: 258.35748 | E25: 277.13541 | F25: 310.87705 | G25: 331.81784 | H25: 344.99237 | I25: 362.63211 | J25: 376.4545 | K25: 385.75336 | L25: 394.84076 | M25: 408.56665 | N25: 424.56018 | O25: 425.74161 | P25: 427.539 | Q25: 429.74127 | R25: 431.20206 | S25: 443.32996 | T25: 450.23541 | U25: 457.24945 | V25: 466.10828 | W25: 474.70233 | X25: 485.57074 | Y25: 498.04614 | Z25: 512.4292 | AA25: 528.9306 | AB25: 546.75122 | AC25: 564.91028 | AD25: 576.6991 | AE25: 587.45465 | AF25: 594.93799 | AG25: 603.5221 | AH25: 612.45575 | AI25: 0.031888
A26: EGC000:ba_DistributedGe | B26: Distributed Generation (Natural Gas) 8/ | C26: 0 | D26: 0 | E26: 3.713591 | F26: 4.16767 | G26: 4.547616 | H26: 4.986972 | I26: 5.449234 | J26: 5.961385 | K26: 6.592154 | L26: 7.471827 | M26: 8.539021 | N26: 9.53553 | O26: 10.636311 | P26: 11.831466 | Q26: 12.989717 | R26: 14.554209 | S26: 16.432066 | T26: 18.254663 | U26: 20.558561 | V26: 22.902798 | W26: 25.320221 | X26: 27.838015 | Y26: 30.430658 | Z26: 32.999897 | AA26: 35.882656 | AB26: 38.735401 | AC26: 41.726345 | AD26: 44.878906 | AE26: 47.995968 | AF26: 51.195477 | AG26: 54.537045 | AH26: 57.978287 | AI26: - -
A27: EGC000:ba_Total | B27: Total | C27: 1040.5867 | D27: 1070.5314 | E27: 1099.9491 | F27: 1134.1152 | G27: 1150.6527 | H27: 1157.2715 | I27: 1158.7388 | J27: 1173.1855 | K27: 1187.9001 | L27: 1205.024 | M27: 1224.6146 | N27: 1248.342 | O27: 1260.6349 | P27: 1271.4087 | Q27: 1280.0568 | R27: 1287.9463 | S27: 1310.7325 | T27: 1328.9323 | U27: 1349.6854 | V27: 1368.9775 | W27: 1392.109 | X27: 1413.9365 | Y27: 1439.6726 | Z27: 1466.3068 | AA27: 1495.9838 | AB27: 1526.8777 | AC27: 1557.4247 | AD27: 1586.087 | AE27: 1611.0586 | AF27: 1634.6343 | AG27: 1660.5441 | AH27: 1686.0286 | AI27: 0.015689
B28: Combined Heat and Power 9/
A29: EGC000:ca_CoalSteam | B29: Coal | C29: 2.6815 | D29: 2.3181 | E29: 2.3181 | F29: 2.3181 | G29: 2.3181 | H29: 2.3181 | I29: 2.3181 | J29: 2.3181 | K29: 2.3181 | L29: 2.3181 | M29: 1.9981 | N29: 1.9981 | O29: 1.9981 | P29: 1.9981 | Q29: 1.9981 | R29: 1.9981 | S29: 1.9981 | T29: 1.9981 | U29: 1.9981 | V29: 1.9981 | W29: 1.9981 | X29: 1.9981 | Y29: 1.9981 | Z29: 1.9981 | AA29: 1.9981 | AB29: 1.9981 | AC29: 1.9981 | AD29: 1.9981 | AE29: 1.9981 | AF29: 1.9981 | AG29: 1.9981 | AH29: 1.9981 | AI29: -0.009445
A30: EGC000:ca_OtherFossilSt | B30: Oil and Natural Gas Steam 5/ | C30: 0.5668 | D30: 0.5668 | E30: 0.5668 | F30: 0.5668 | G30: 0.5668 | H30: 0.5668 | I30: 0.5668 | J30: 0.5668 | K30: 0.5668 | L30: 0.5668 | M30: 0.5668 | N30: 0.5668 | O30: 0.5668 | P30: 0.5668 | Q30: 0.5668 | R30: 0.5668 | S30: 0.5668 | T30: 0.5668 | U30: 0.5668 | V30: 0.5668 | W30: 0.5668 | X30: 0.5668 | Y30: 0.5668 | Z30: 0.5668 | AA30: 0.5668 | AB30: 0.5668 | AC30: 0.5668 | AD30: 0.5668 | AE30: 0.5668 | AF30: 0.5668 | AG30: 0.5668 | AH30: 0.5668 | AI30: 0
A31: EGC000:ca_CombinedCycle | B31: Combined Cycle | C31: 22.372604 | D31: 22.372604 | E31: 22.372604 | F31: 22.372604 | G31: 22.194006 | H31: 22.194006 | I31: 22.194006 | J31: 22.194006 | K31: 22.194006 | L31: 22.194006 | M31: 22.194006 | N31: 22.194006 | O31: 22.194006 | P31: 22.194006 | Q31: 22.194006 | R31: 22.194006 | S31: 22.194006 | T31: 22.194006 | U31: 22.194006 | V31: 22.194006 | W31: 22.194006 | X31: 22.194006 | Y31: 22.194006 | Z31: 22.194006 | AA31: 22.194006 | AB31: 22.194006 | AC31: 22.194006 | AD31: 22.194006 | AE31: 22.194006 | AF31: 22.194006 | AG31: 22.194006 | AH31: 22.194006 | AI31: -0.000259
A32: EGC000:ca_CombustionTur | B32: Combustion Turbine/Diesel | C32: 3.2564 | D32: 3.2069 | E32: 3.2069 | F32: 3.2069 | G32: 3.2069 | H32: 3.2069 | I32: 3.2069 | J32: 3.2069 | K32: 3.2069 | L32: 3.2069 | M32: 3.2069 | N32: 3.2069 | O32: 3.2069 | P32: 3.2069 | Q32: 3.2069 | R32: 3.2069 | S32: 3.2069 | T32: 3.2069 | U32: 3.2069 | V32: 3.2069 | W32: 3.2069 | X32: 3.2069 | Y32: 3.2069 | Z32: 3.2069 | AA32: 3.2069 | AB32: 3.2069 | AC32: 3.2069 | AD32: 3.2069 | AE32: 3.2069 | AF32: 3.2069 | AG32: 3.2069 | AH32: 3.2069 | AI32: -0.000494
A33: EGC000:ca_RenewableSour | B33: Renewable Sources 7/ | C33: 0.8592 | D33: 0.8547 | E33: 0.8547 | F33: 0.8547 | G33: 0.8547 | H33: 0.8547 | I33: 0.8547 | J33: 0.8547 | K33: 0.8547 | L33: 0.8547 | M33: 0.8547 | N33: 0.8547 | O33: 0.8547 | P33: 0.8547 | Q33: 0.8547 | R33: 0.8547 | S33: 0.8547 | T33: 0.8547 | U33: 0.8547 | V33: 0.8547 | W33: 0.8547 | X33: 0.8547 | Y33: 0.8547 | Z33: 0.8547 | AA33: 0.8547 | AB33: 0.8547 | AC33: 0.8547 | AD33: 0.8547 | AE33: 0.8547 | AF33: 0.8547 | AG33: 0.8547 | AH33: 0.8547 | AI33: -0.000169
A34: EGC000:ca_Total | B34: Total | C34: 29.736504 | D34: 29.319103 | E34: 29.319103 | F34: 29.319103 | G34: 29.140507 | H34: 29.140507 | I34: 29.140507 | J34: 29.140507 | K34: 29.140507 | L34: 29.140507 | M34: 28.820505 | N34: 28.820505 | O34: 28.820505 | P34: 28.820505 | Q34: 28.820505 | R34: 28.820505 | S34: 28.820505 | T34: 28.820505 | U34: 28.820505 | V34: 28.820505 | W34: 28.820505 | X34: 28.820505 | Y34: 28.820505 | Z34: 28.820505 | AA34: 28.820505 | AB34: 28.820505 | AC34: 28.820505 | AD34: 28.820505 | AE34: 28.820505 | AF34: 28.820505 | AG34: 28.820505 | AH34: 28.820505 | AI34: -0.001009
B36: Cumulative Planned Additions 10/
A37: EGC000:da_CoalSteam | B37: Coal | C37: - - | D37: 0 | E37: 0 | F37: 0 | G37: 0 | H37: 0 | I37: 0 | J37: 0 | K37: 0 | L37: 0 | M37: 0 | N37: 0 | O37: 0 | P37: 0 | Q37: 0 | R37: 0 | S37: 0 | T37: 0 | U37: 0 | V37: 0 | W37: 0 | X37: 0 | Y37: 0 | Z37: 0 | AA37: 0 | AB37: 0 | AC37: 0 | AD37: 0 | AE37: 0 | AF37: 0 | AG37: 0 | AH37: 0 | AI37: - -
A38: EGC000:da_OtherFossilSt | B38: Oil and Natural Gas Steam 5/ | C38: - - | D38: 0 | E38: 0.1985 | F38: 0.1985 | G38: 0.1985 | H38: 0.1985 | I38: 0.1985 | J38: 0.1985 | K38: 0.1985 | L38: 0.1985 | M38: 0.1985 | N38: 0.1985 | O38: 0.1985 | P38: 0.1985 | Q38: 0.1985 | R38: 0.1985 | S38: 0.1985 | T38: 0.1985 | U38: 0.1985 | V38: 0.1985 | W38: 0.1985 | X38: 0.1985 | Y38: 0.1985 | Z38: 0.1985 | AA38: 0.1985 | AB38: 0.1985 | AC38: 0.1985 | AD38: 0.1985 | AE38: 0.1985 | AF38: 0.1985 | AG38: 0.1985 | AH38: 0.1985 | AI38: - -
A39: EGC000:da_CombinedCycle | B39: Combined Cycle | C39: - - | D39: 5.755002 | E39: 16.178204 | F39: 17.324203 | G39: 17.324203 | H39: 17.324203 | I39: 17.324203 | J39: 17.324203 | K39: 17.324203 | L39: 17.324203 | M39: 17.324203 | N39: 17.324203 | O39: 17.324203 | P39: 17.324203 | Q39: 17.324203 | R39: 17.324203 | S39: 17.324203 | T39: 17.324203 | U39: 17.324203 | V39: 17.324203 | W39: 17.324203 | X39: 17.324203 | Y39: 17.324203 | Z39: 17.324203 | AA39: 17.324203 | AB39: 17.324203 | AC39: 17.324203 | AD39: 17.324203 | AE39: 17.324203 | AF39: 17.324203 | AG39: 17.324203 | AH39: 17.324203 | AI39: - -
A40: EGC000:da_CombustionTur | B40: Combustion Turbine/Diesel | C40: - - | D40: 2.9402 | E40: 5.484501 | F40: 5.484501 | G40: 5.484501 | H40: 5.484501 | I40: 5.484501 | J40: 5.484501 | K40: 5.484501 | L40: 5.484501 | M40: 5.484501 | N40: 5.484501 | O40: 5.484501 | P40: 5.484501 | Q40: 5.484501 | R40: 5.484501 | S40: 5.484501 | T40: 5.484501 | U40: 5.484501 | V40: 5.484501 | W40: 5.484501 | X40: 5.484501 | Y40: 5.484501 | Z40: 5.484501 | AA40: 5.484501 | AB40: 5.484501 | AC40: 5.484501 | AD40: 5.484501 | AE40: 5.484501 | AF40: 5.484501 | AG40: 5.484501 | AH40: 5.484501 | AI40: - -
A41: EGC000:da_NuclearPower | B41: Nuclear Power | C41: - - | D41: 0 | E41: 1.1 | F41: 2.2 | G41: 2.2 | H41: 2.2 | I41: 2.2 | J41: 2.2 | K41: 2.2 | L41: 2.2 | M41: 2.2 | N41: 2.2 | O41: 2.2 | P41: 2.2 | Q41: 2.2 | R41: 2.2 | S41: 2.2 | T41: 2.2 | U41: 2.2 | V41: 2.2 | W41: 2.2 | X41: 2.2 | Y41: 2.2 | Z41: 2.2 | AA41: 2.2 | AB41: 2.2 | AC41: 2.2 | AD41: 2.2 | AE41: 2.2 | AF41: 2.2 | AG41: 2.2 | AH41: 2.2 | AI41: - -
A42: EGC000:da_PumpedStorage | B42: Pumped Storage | C42: - - | D42: 0 | E42: 0 | F42: 0 | G42: 0 | H42: 0 | I42: 0 | J42: 0 | K42: 0 | L42: 0 | M42: 0 | N42: 0 | O42: 0 | P42: 0 | Q42: 0 | R42: 0 | S42: 0 | T42: 0 | U42: 0 | V42: 0 | W42: 0 | X42: 0 | Y42: 0 | Z42: 0 | AA42: 0 | AB42: 0 | AC42: 0 | AD42: 0 | AE42: 0 | AF42: 0 | AG42: 0 | AH42: 0 | AI42: - -
A43: EGC000:da_DiurnalStorag | B43: Diurnal Storage | C43: - - | D43: 1.0671 | E43: 3.3636 | F43: 3.9946 | G43: 4.6256 | H43: 5.2566 | I43: 5.699601 | J43: 6.1106 | K43: 6.521601 | L43: 6.9326 | M43: 7.343601 | N43: 7.754601 | O43: 7.754601 | P43: 7.754601 | Q43: 7.754601 | R43: 7.754601 | S43: 7.754601 | T43: 7.754601 | U43: 7.754601 | V43: 7.754601 | W43: 7.754601 | X43: 7.754601 | Y43: 7.754601 | Z43: 7.754601 | AA43: 7.754601 | AB43: 7.754601 | AC43: 7.754601 | AD43: 7.754601 | AE43: 7.754601 | AF43: 7.754601 | AG43: 7.754601 | AH43: 7.754601 | AI43: - -
A44: EGC000:da_FuelCells | B44: Fuel Cells | C44: - - | D44: 0.0251 | E44: 0.0288 | F44: 0.0288 | G44: 0.0288 | H44: 0.0288 | I44: 0.0288 | J44: 0.0288 | K44: 0.0288 | L44: 0.0288 | M44: 0.0288 | N44: 0.0288 | O44: 0.0288 | P44: 0.0288 | Q44: 0.0288 | R44: 0.0288 | S44: 0.0288 | T44: 0.0288 | U44: 0.0288 | V44: 0.0288 | W44: 0.0288 | X44: 0.0288 | Y44: 0.0288 | Z44: 0.0288 | AA44: 0.0288 | AB44: 0.0288 | AC44: 0.0288 | AD44: 0.0288 | AE44: 0.0288 | AF44: 0.0288 | AG44: 0.0288 | AH44: 0.0288 | AI44: - -
A45: EGC000:da_RenewableSour | B45: Renewable Sources 7/ | C45: - - | D45: 26.973803 | E45: 34.927605 | F45: 35.848305 | G45: 36.748302 | H45: 37.248302 | I45: 37.248302 | J45: 37.248302 | K45: 37.248302 | L45: 39.248306 | M45: 39.248306 | N45: 46.348309 | O45: 46.348309 | P45: 46.348309 | Q45: 46.348309 | R45: 46.348309 | S45: 54.548302 | T45: 54.548302 | U45: 54.548302 | V45: 54.548302 | W45: 54.548302 | X45: 54.548302 | Y45: 54.548302 | Z45: 54.548302 | AA45: 54.548302 | AB45: 54.548302 | AC45: 54.548302 | AD45: 54.548302 | AE45: 54.548302 | AF45: 54.548302 | AG45: 54.548302 | AH45: 54.548302 | AI45: - -
A46: EGC000:da_DistributedGe | B46: Distributed Generation 8/ | C46: - - | D46: 0 | E46: 0 | F46: 0 | G46: 0 | H46: 0 | I46: 0 | J46: 0 | K46: 0 | L46: 0 | M46: 0 | N46: 0 | O46: 0 | P46: 0 | Q46: 0 | R46: 0 | S46: 0 | T46: 0 | U46: 0 | V46: 0 | W46: 0 | X46: 0 | Y46: 0 | Z46: 0 | AA46: 0 | AB46: 0 | AC46: 0 | AD46: 0 | AE46: 0 | AF46: 0 | AG46: 0 | AH46: 0 | AI46: - -
...

Sheet AEO Table 9 (2019)
B1: ref2019.d111618a | C1: 2017 | D1: 2018 | E1: 2019 | F1: 2020 | G1: 2021 | H1: 2022 | I1: 2023 | J1: 2024 | K1: 2025 | L1: 2026 | M1: 2027 | N1: 2028 | O1: 2029 | P1: 2030 | Q1: 2031 | R1: 2032 | S1: 2033 | T1: 2034 | U1: 2035 | V1: 2036 | W1: 2037 | X1: 2038 | Y1: 2039 | Z1: 2040 | AA1: 2041 | AB1: 2042 | AC1: 2043 | AD1: 2044 | AE1: 2045 | AF1: 2046 | AG1: 2047 | AH1: 2048 | AI1: 2049 | AJ1: 2050
C3: Report | D3: Annual Energy Outlook 2019
C4: Scenario | D4: ref2019 | G4: Reference case
C5: Datekey | D5: d111618a
C6: Release Date | E6: January 2019
A10: EGC000 | B10: 9. Electricity Generating Capacity
B11: (gigawatts)
AK12: 2018-
B13: Net Summer Capacity 1/ | C13: 2017 | D13: 2018 | E13: 2019 | F13: 2020 | G13: 2021 | H13: 2022 | I13: 2023 | J13: 2024 | K13: 2025 | L13: 2026 | M13: 2027 | N13: 2028 | O13: 2029 | P13: 2030 | Q13: 2031 | R13: 2032 | S13: 2033 | T13: 2034 | U13: 2035 | V13: 2036 | W13: 2037 | X13: 2038 | Y13: 2039 | Z13: 2040 | AA13: 2041 | AB13: 2042 | AC13: 2043 | AD13: 2044 | AE13: 2045 | AF13: 2046 | AG13: 2047 | AH13: 2048 | AI13: 2049 | AJ13: 2050 | AK13: 2050
B15: Electric Power Sector 2/
B16: Power Only 3/
A17: EGC000:ba_CoalSteam | B17: Coal 4/ | C17: 249.06146 | D17: 236.69867 | E17: 229.95035 | F17: 227.71237 | G17: 219.57416 | H17: 211.28442 | I17: 199.18562 | J17: 186.92104 | K17: 176.33551 | L17: 171.035 | M17: 167.38042 | N17: 165.30002 | O17: 164.75401 | P17: 161.84201 | Q17: 159.19803 | R17: 154.03201 | S17: 154.03201 | T17: 151.13092 | U17: 151.13092 | V17: 151.13092 | W17: 149.96681 | X17: 149.96681 | Y17: 149.96681 | Z17: 149.96681 | AA17: 148.74982 | AB17: 148.74982 | AC17: 148.18581 | AD17: 148.18581 | AE17: 148.18581 | AF17: 148.18581 | AG17: 148.18581 | AH17: 148.18581 | AI17: 148.18581 | AJ17: 148.18581 | AK17: -0.014528
A18: EGC000:ba_OtherFossilSt | B18: Oil and Natural Gas Steam 4, 5/ | C18: 86.23291 | D18: 82.614105 | E18: 80.766106 | F18: 79.24321 | G18: 72.473808 | H18: 70.327507 | I18: 68.559906 | J18: 65.484306 | K18: 64.027115 | L18: 60.366714 | M18: 59.844711 | N18: 59.045212 | O18: 57.401909 | P18: 57.401909 | Q18: 57.291908 | R18: 57.62291 | S18: 57.387909 | T18: 57.307907 | U18: 57.208908 | V18: 56.908905 | W18: 56.908905 | X18: 56.686905 | Y18: 56.686905 | Z18: 56.686905 | AA18: 56.464905 | AB18: 56.067909 | AC18: 56.067909 | AD18: 56.067909 | AE18: 55.94191 | AF18: 55.94191 | AG18: 55.94191 | AH18: 55.94191 | AI18: 55.94191 | AJ18: 55.94191 | AK18: -0.012109
A19: EGC000:ba_CombinedCycle | B19: Combined Cycle | C19: 215.54413 | D19: 233.12274 | E19: 239.77252 | F19: 249.41815 | G19: 264.58447 | H19: 270.8075 | I19: 280.61087 | J19: 293.17587 | K19: 307.1662 | L19: 315.12601 | M19: 323.8457 | N19: 328.71765 | O19: 333.69891 | P19: 343.76288 | Q19: 349.28546 | R19: 359.42764 | S19: 366.74774 | T19: 377.36493 | U19: 380.44986 | V19: 386.4592 | W19: 396.43655 | X19: 399.53067 | Y19: 405.84891 | Z19: 412.29587 | AA19: 420.32761 | AB19: 425.83252 | AC19: 432.41736 | AD19: 439.58905 | AE19: 447.87683 | AF19: 454.92938 | AG19: 458.05414 | AH19: 464.36188 | AI19: 468.72095 | AJ19: 475.17969 | AK19: 0.022503
A20: EGC000:ba_CombustionTur | B20: Combustion Turbine/Diesel | C20: 137.23004 | D20: 138.84142 | E20: 146.10204 | F20: 152.69632 | G20: 151.33931 | H20: 151.80185 | I20: 151.59367 | J20: 151.94437 | K20: 152.63406 | L20: 153.4108 | M20: 155.21005 | N20: 156.07605 | O20: 155.95046 | P20: 156.04567 | Q20: 156.9455 | R20: 157.26398 | S20: 157.68308 | T20: 157.70822 | U20: 158.82886 | V20: 159.68265 | W20: 159.68265 | X20: 160.39127 | Y20: 161.88388 | Z20: 163.28613 | AA20: 163.7605 | AB20: 165.28421 | AC20: 165.60088 | AD20: 167.21106 | AE20: 168.97247 | AF20: 170.98743 | AG20: 173.50467 | AH20: 176.40558 | AI20: 179.74164 | AJ20: 181.77669 | AK20: 0.008456
A21: EGC000:ba_NuclearPower | B21: Nuclear Power 6/ | C21: 99.628906 | D21: 99.06221 | E21: 98.047211 | F21: 96.152817 | G21: 92.892105 | H21: 89.331314 | I21: 85.948807 | J21: 85.948807 | K21: 82.725403 | L21: 81.607407 | M21: 81.607407 | N21: 81.607407 | O21: 81.632431 | P21: 81.682457 | Q21: 81.757538 | R21: 80.424637 | S21: 80.549774 | T21: 80.674896 | U21: 80.800034 | V21: 80.925156 | W21: 81.050285 | X21: 81.175415 | Y21: 81.300552 | Z21: 81.425674 | AA21: 81.550812 | AB21: 81.675934 | AC21: 81.801071 | AD21: 81.926193 | AE21: 82.051331 | AF21: 82.176453 | AG21: 82.30159 | AH21: 82.426712 | AI21: 82.551849 | AJ21: 82.676979 | AK21: -0.005634
A22: EGC000:ba_PumpedStorage | B22: Pumped Storage | C22: 22.810404 | D22: 22.810404 | E22: 22.810404 | F22: 22.810404 | G22: 22.810404 | H22: 22.810404 | I22: 22.810404 | J22: 22.810404 | K22: 22.810404 | L22: 22.810404 | M22: 22.810404 | N22: 22.810404 | O22: 22.810404 | P22: 22.810404 | Q22: 22.810404 | R22: 22.810404 | S22: 22.810404 | T22: 22.810404 | U22: 22.810404 | V22: 22.810404 | W22: 22.810404 | X22: 22.810404 | Y22: 22.810404 | Z22: 22.810404 | AA22: 22.810404 | AB22: 22.810404 | AC22: 22.810404 | AD22: 22.810404 | AE22: 22.810404 | AF22: 22.810404 | AG22: 22.810404 | AH22: 22.810404 | AI22: 22.810404 | AJ22: 22.810404 | AK22: 0
A23: EGC000:ba_DiurnalStorag | B23: Diurnal Storage | C23: 0.5922 | D23: 0.7525 | E23: 0.7985 | F23: 0.9195 | G23: 1.1695 | H23: 1.4195 | I23: 1.6695 | J23: 1.9185 | K23: 1.9185 | L23: 1.9185 | M23: 1.9185 | N23: 1.9185 | O23: 1.9185 | P23: 1.9185 | Q23: 4.7155 | R23: 5.71344 | S23: 5.71344 | T23: 6.47543 | U23: 8.001458 | V23: 9.272899 | W23: 9.281306 | X23: 12.197307 | Y23: 12.439215 | Z23: 15.457274 | AA23: 18.583275 | AB23: 18.818813 | AC23: 20.16357 | AD23: 20.803711 | AE23: 21.957172 | AF23: 23.104578 | AG23: 26.104578 | AH23: 27.820377 | AI23: 27.820377 | AJ23: 30.820377 | AK23: 0.123014
A24: EGC000:ba_FuelCells | B24: Fuel Cells | C24: 0.101 | D24: 0.1024 | E24: 0.1176 | F24: 0.1165 | G24: 0.116581 | H24: 0.116662 | I24: 0.116743 | J24: 0.116824 | K24: 0.116905 | L24: 0.116986 | M24: 0.117067 | N24: 0.117148 | O24: 0.117229 | P24: 0.11731 | Q24: 0.117391 | R24: 0.117472 | S24: 0.117554 | T24: 0.11761 | U24: 0.117636 | V24: 0.117647 | W24: 0.117653 | X24: 0.117659 | Y24: 0.11766 | Z24: 0.117661 | AA24: 0.117662 | AB24: 0.117663 | AC24: 0.117664 | AD24: 0.117665 | AE24: 0.117666 | AF24: 0.119976 | AG24: 0.121998 | AH24: 0.121998 | AI24: 0.121998 | AJ24: 0.123569 | AK24: 0.00589
A25: EGC000:ba_RenewableSour | B25: Renewable Sources 7/ | C25: 201.2106 | D25: 214.30002 | E25: 229.26296 | F25: 241.68622 | G25: 256.39145 | H25: 267.14679 | I25: 278.43472 | J25: 281.96027 | K25: 285.54477 | L25: 288.06873 | M25: 291.60843 | N25: 295.24518 | O25: 301.88184 | P25: 304.16019 | Q25: 310.39307 | R25: 311.0546 | S25: 314.80356 | T25: 320.61948 | U25: 327.44125 | V25: 336.38538 | W25: 344.79001 | X25: 354.46924 | Y25: 365.72253 | Z25: 366.69189 | AA25: 377.93118 | AB25: 379.31778 | AC25: 391.2876 | AD25: 393.42416 | AE25: 397.17783 | AF25: 409.83667 | AG25: 423.1261 | AH25: 425.9631 | AI25: 438.77341 | AJ25: 446.2323 | AK25: 0.023185
A26: EGC000:ba_DistributedGe | B26: Distributed Generation (Natural Gas) 8/ | C26: 0 | D26: 0 | E26: 0 | F26: 1.549955 | G26: 1.737015 | H26: 1.921614 | I26: 2.130025 | J26: 2.381044 | K26: 2.674073 | L26: 3.043898 | M26: 3.439239 | N26: 3.898479 | O26: 4.413876 | P26: 4.959581 | Q26: 5.466499 | R26: 6.112264 | S26: 6.757843 | T26: 7.521287 | U26: 8.406585 | V26: 9.365047 | W26: 10.470657 | X26: 11.609406 | Y26: 12.832676 | Z26: 14.179006 | AA26: 15.613872 | AB26: 17.131451 | AC26: 18.72057 | AD26: 20.528061 | AE26: 22.37632 | AF26: 24.270847 | AG26: 26.195223 | AH26: 27.978928 | AI26: 29.72471 | AJ26: 31.575861 | AK26: - -
A27: EGC000:ba_Total | B27: Total | C27: 1012.4117 | D27: 1028.3044 | E27: 1047.6278 | F27: 1072.3055 | G27: 1083.0889 | H27: 1086.9677 | I27: 1091.0604 | J27: 1092.6614 | K27: 1095.9529 | L27: 1097.5044 | M27: 1107.7819 | N27: 1114.736 | O27: 1124.5796 | P27: 1134.7009 | Q27: 1147.9813 | R27: 1154.5795 | S27: 1166.6034 | T27: 1181.7311 | U27: 1195.1959 | V27: 1213.0582 | W27: 1231.5153 | X27: 1248.9551 | Y27: 1269.6095 | Z27: 1282.9176 | AA27: 1305.91 | AB27: 1315.8065 | AC27: 1337.173 | AD27: 1350.6641 | AE27: 1367.4678 | AF27: 1392.3635 | AG27: 1416.3464 | AH27: 1432.0167 | AI27: 1454.3931 | AJ27: 1475.3236 | AK27: 0.011344
B28: Combined Heat and Power 9/
A29: EGC000:ca_CoalSteam | B29: Coal | C29: 3.1323 | D29: 2.9877 | E29: 2.9877 | F29: 2.6821 | G29: 2.6821 | H29: 2.6821 | I29: 2.6821 | J29: 2.6821 | K29: 2.6821 | L29: 2.6821 | M29: 2.6821 | N29: 2.6821 | O29: 2.6821 | P29: 2.6821 | Q29: 2.6821 | R29: 2.6821 | S29: 2.6821 | T29: 2.6821 | U29: 2.6821 | V29: 2.6821 | W29: 2.6821 | X29: 2.6821 | Y29: 2.6821 | Z29: 2.6821 | AA29: 2.6821 | AB29: 2.6821 | AC29: 2.6821 | AD29: 2.6821 | AE29: 2.6821 | AF29: 2.6821 | AG29: 2.6821 | AH29: 2.6821 | AI29: 2.6821 | AJ29: 2.6821 | AK29: -0.003366
A30: EGC000:ca_OtherFossilSt | B30: Oil and Natural Gas Steam 5/ | C30: 0.6062 | D30: 0.6062 | E30: 0.6062 | F30: 0.6062 | G30: 0.6062 | H30: 0.6062 | I30: 0.6062 | J30: 0.6062 | K30: 0.6062 | L30: 0.6062 | M30: 0.6062 | N30: 0.6062 | O30: 0.6062 | P30: 0.6062 | Q30: 0.6062 | R30: 0.6062 | S30: 0.6062 | T30: 0.6062 | U30: 0.6062 | V30: 0.6062 | W30: 0.6062 | X30: 0.6062 | Y30: 0.6062 | Z30: 0.6062 | AA30: 0.6062 | AB30: 0.6062 | AC30: 0.6062 | AD30: 0.6062 | AE30: 0.6062 | AF30: 0.6062 | AG30: 0.6062 | AH30: 0.6062 | AI30: 0.6062 | AJ30: 0.6062 | AK30: 0
A31: EGC000:ca_CombinedCycle | B31: Combined Cycle | C31: 23.5755 | D31: 23.386599 | E31: 23.336599 | F31: 23.564598 | G31: 23.564598 | H31: 23.564598 | I31: 23.385998 | J31: 23.385998 | K31: 23.385998 | L31: 23.385998 | M31: 23.385998 | N31: 23.385998 | O31: 23.385998 | P31: 23.385998 | Q31: 23.385998 | R31: 23.385998 | S31: 23.385998 | T31: 23.385998 | U31: 23.385998 | V31: 23.385998 | W31: 23.385998 | X31: 23.385998 | Y31: 23.385998 | Z31: 23.385998 | AA31: 23.385998 | AB31: 23.385998 | AC31: 23.385998 | AD31: 23.385998 | AE31: 23.385998 | AF31: 23.385998 | AG31: 23.385998 | AH31: 23.385998 | AI31: 23.385998 | AJ31: 23.385998 | AK31: -1e-06
A32: EGC000:ca_CombustionTur | B32: Combustion Turbine/Diesel | C32: 3.1941 | D32: 3.1941 | E32: 3.1461 | F32: 3.0966 | G32: 3.0966 | H32: 3.0966 | I32: 3.0966 | J32: 3.0966 | K32: 3.0966 | L32: 3.0966 | M32: 3.0966 | N32: 3.0966 | O32: 3.0966 | P32: 3.0966 | Q32: 3.0966 | R32: 3.0966 | S32: 3.0966 | T32: 3.0966 | U32: 3.0966 | V32: 3.0966 | W32: 3.0966 | X32: 3.0966 | Y32: 3.0966 | Z32: 3.0966 | AA32: 3.0966 | AB32: 3.0966 | AC32: 3.0966 | AD32: 3.0966 | AE32: 3.0966 | AF32: 3.0966 | AG32: 3.0966 | AH32: 3.0966 | AI32: 3.0966 | AJ32: 3.0966 | AK32: -0.000968
A33: EGC000:ca_RenewableSour | B33: Renewable Sources 7/ | C33: 0.95 | D33: 0.9431 | E33: 0.9451 | F33: 0.9451 | G33: 0.9451 | H33: 0.9451 | I33: 0.9451 | J33: 0.9451 | K33: 0.9451 | L33: 0.9451 | M33: 0.9451 | N33: 0.9451 | O33: 0.9451 | P33: 0.9451 | Q33: 0.9451 | R33: 0.9451 | S33: 0.9451 | T33: 0.9451 | U33: 0.9451 | V33: 0.9451 | W33: 0.9451 | X33: 0.9451 | Y33: 0.9451 | Z33: 0.9451 | AA33: 0.9451 | AB33: 0.9451 | AC33: 0.9451 | AD33: 0.9451 | AE33: 0.9451 | AF33: 0.9451 | AG33: 0.9451 | AH33: 0.9451 | AI33: 0.9451 | AJ33: 0.9451 | AK33: 6.6e-05
A34: EGC000:ca_Total | B34: Total | C34: 31.458103 | D34: 31.117699 | E34: 31.0217 | F34: 30.894598 | G34: 30.894598 | H34: 30.894598 | I34: 30.715998 | J34: 30.715998 | K34: 30.715998 | L34: 30.715998 | M34: 30.715998 | N34: 30.715998 | O34: 30.715998 | P34: 30.715998 | Q34: 30.715998 | R34: 30.715998 | S34: 30.715998 | T34: 30.715998 | U34: 30.715998 | V34: 30.715998 | W34: 30.715998 | X34: 30.715998 | Y34: 30.715998 | Z34: 30.715998 | AA34: 30.715998 | AB34: 30.715998 | AC34: 30.715998 | AD34: 30.715998 | AE34: 30.715998 | AF34: 30.715998 | AG34: 30.715998 | AH34: 30.715998 | AI34: 30.715998 | AJ34: 30.715998 | AK34: -0.000406
B36: Cumulative Planned Additions 10/
A37: EGC000:da_CoalSteam | B37: Coal | C37: - - | D37: - - | E37: 0 | F37: 0 | G37: 0 | H37: 0 | I37: 0 | J37: 0 | K37: 0 | L37: 0 | M37: 0 | N37: 0 | O37: 0 | P37: 0 | Q37: 0 | R37: 0 | S37: 0 | T37: 0 | U37: 0 | V37: 0 | W37: 0 | X37: 0 | Y37: 0 | Z37: 0 | AA37: 0 | AB37: 0 | AC37: 0 | AD37: 0 | AE37: 0 | AF37: 0 | AG37: 0 | AH37: 0 | AI37: 0 | AJ37: 0 | AK37: - -
A38: EGC000:da_OtherFossilSt | B38: Oil and Natural Gas Steam 5/ | C38: - - | D38: - - | E38: 0 | F38: 0 | G38: 0 | H38: 0 | I38: 0 | J38: 0 | K38: 0 | L38: 0 | M38: 0 | N38: 0 | O38: 0 | P38: 0 | Q38: 0 | R38: 0 | S38: 0 | T38: 0 | U38: 0 | V38: 0 | W38: 0 | X38: 0 | Y38: 0 | Z38: 0 | AA38: 0 | AB38: 0 | AC38: 0 | AD38: 0 | AE38: 0 | AF38: 0 | AG38: 0 | AH38: 0 | AI38: 0 | AJ38: 0 | AK38: - -
A39: EGC000:da_CombinedCycle | B39: Combined Cycle | C39: - - | D39: - - | E39: 6.649801 | F39: 16.523401 | G39: 16.523401 | H39: 16.523401 | I39: 16.523401 | J39: 16.523401 | K39: 16.523401 | L39: 16.523401 | M39: 16.523401 | N39: 16.523401 | O39: 16.523401 | P39: 16.523401 | Q39: 16.523401 | R39: 16.523401 | S39: 16.523401 | T39: 16.523401 | U39: 16.523401 | V39: 16.523401 | W39: 16.523401 | X39: 16.523401 | Y39: 16.523401 | Z39: 16.523401 | AA39: 16.523401 | AB39: 16.523401 | AC39: 16.523401 | AD39: 16.523401 | AE39: 16.523401 | AF39: 16.523401 | AG39: 16.523401 | AH39: 16.523401 | AI39: 16.523401 | AJ39: 16.523401 | AK39: - -
A40: EGC000:da_CombustionTur | B40: Combustion Turbine/Diesel | C40: - - | D40: - - | E40: 2.508 | F40: 6.9856 | G40: 6.9856 | H40: 6.9856 | I40: 6.9856 | J40: 6.9856 | K40: 6.9856 | L40: 6.9856 | M40: 6.9856 | N40: 6.9856 | O40: 6.9856 | P40: 6.9856 | Q40: 6.9856 | R40: 6.9856 | S40: 6.9856 | T40: 6.9856 | U40: 6.9856 | V40: 6.9856 | W40: 6.9856 | X40: 6.9856 | Y40: 6.9856 | Z40: 6.9856 | AA40: 6.9856 | AB40: 6.9856 | AC40: 6.9856 | AD40: 6.9856 | AE40: 6.9856 | AF40: 6.9856 | AG40: 6.9856 | AH40: 6.9856 | AI40: 6.9856 | AJ40: 6.9856 | AK40: - -
A41: EGC000:da_NuclearPower | B41: Nuclear Power | C41: - - | D41: - - | E41: 0 | F41: 0 | G41: 2.2 | H41: 2.2 | I41: 2.2 | J41: 2.2 | K41: 2.2 | L41: 2.2 | M41: 2.2 | N41: 2.2 | O41: 2.2 | P41: 2.2 | Q41: 2.2 | R41: 2.2 | S41: 2.2 | T41: 2.2 | U41: 2.2 | V41: 2.2 | W41: 2.2 | X41: 2.2 | Y41: 2.2 | Z41: 2.2 | AA41: 2.2 | AB41: 2.2 | AC41: 2.2 | AD41: 2.2 | AE41: 2.2 | AF41: 2.2 | AG41: 2.2 | AH41: 2.2 | AI41: 2.2 | AJ41: 2.2 | AK41: - -
A42: EGC000:da_PumpedStorage | B42: Pumped Storage | C42: - - | D42: - - | E42: 0 | F42: 0 | G42: 0 | H42: 0 | I42: 0 | J42: 0 | K42: 0 | L42: 0 | M42: 0 | N42: 0 | O42: 0 | P42: 0 | Q42: 0 | R42: 0 | S42: 0 | T42: 0 | U42: 0 | V42: 0 | W42: 0 | X42: 0 | Y42: 0 | Z42: 0 | AA42: 0 | AB42: 0 | AC42: 0 | AD42: 0 | AE42: 0 | AF42: 0 | AG42: 0 | AH42: 0 | AI42: 0 | AJ42: 0 | AK42: - -
A43: EGC000:da_DiurnalStorag | B43: Diurnal Storage | C43: - - | D43: - - | E43: 0.046 | F43: 0.167 | G43: 0.417 | H43: 0.667 | I43: 0.917 | J43: 1.167 | K43: 1.167 | L43: 1.167 | M43: 1.167 | N43: 1.167 | O43: 1.167 | P43: 1.167 | Q43: 1.167 | R43: 1.167 | S43: 1.167 | T43: 1.167 | U43: 1.167 | V43: 1.167 | W43: 1.167 | X43: 1.167 | Y43: 1.167 | Z43: 1.167 | AA43: 1.167 | AB43: 1.167 | AC43: 1.167 | AD43: 1.167 | AE43: 1.167 | AF43: 1.167 | AG43: 1.167 | AH43: 1.167 | AI43: 1.167 | AJ43: 1.167 | AK43: - -
A44: EGC000:da_FuelCells | B44: Fuel Cells | C44: - - | D44: - - | E44: 0.0152 | F44: 0.0152 | G44: 0.0152 | H44: 0.0152 | I44: 0.0152 | J44: 0.0152 | K44: 0.0152 | L44: 0.0152 | M44: 0.0152 | N44: 0.0152 | O44: 0.0152 | P44: 0.0152 | Q44: 0.0152 | R44: 0.0152 | S44: 0.0152 | T44: 0.0152 | U44: 0.0152 | V44: 0.0152 | W44: 0.0152 | X44: 0.0152 | Y44: 0.0152 | Z44: 0.0152 | AA44: 0.0152 | AB44: 0.0152 | AC44: 0.0152 | AD44: 0.0152 | AE44: 0.0152 | AF44: 0.0152 | AG44: 0.0152 | AH44: 0.0152 | AI44: 0.0152 | AJ44: 0.0152 | AK44: - -
A45: EGC000:da_RenewableSour | B45: Renewable Sources 7/ | C45: - - | D45: - - | E45: 14.974111 | F45: 23.394007 | G45: 23.605005 | H45: 23.605005 | I45: 23.605005 | J45: 23.605005 | K45: 23.605005 | L45: 23.605005 | M45: 23.605005 | N45: 23.605005 | O45: 23.605005 | P45: 23.605005 | Q45: 23.605005 | R45: 23.605005 | S45: 23.605005 | T45: 23.605005 | U45: 23.605005 | V45: 23.605005 | W45: 23.605005 | X45: 23.605005 | Y45: 23.605005 | Z45: 23.605005 | AA45: 23.605005 | AB45: 23.605005 | AC45: 23.605005 | AD45: 23.605005 | AE45: 23.605005 | AF45: 23.605005 | AG45: 23.605005 | AH45: 23.605005 | AI45: 23.605005 | AJ45: 23.605005 | AK45: - -
A46: EGC000:da_DistributedGe | B46: Distributed Generation 8/ | C46: - - | D46: - - | E46: 0 | F46: 0 | G46: 0 | H46: 0 | I46: 0 | J46: 0 | K46: 0 | L46: 0 | M46: 0 | N46: 0 | O46: 0 | P46: 0 | Q46: 0 | R46: 0 | S46: 0 | T46: 0 | U46: 0 | V46: 0 | W46: 0 | X46: 0 | Y46: 0 | Z46: 0 | AA46: 0 | AB46: 0 | AC46: 0 | AD46: 0 | AE46: 0 | AF46: 0 | AG46: 0 | AH46: 0 | AI46: 0 | AJ46: 0 | AK46: - -
...

Sheet AEO Table 9 (2021)
B1: highogs.d120120a | C1: 2020 | D1: 2021 | E1: 2022 | F1: 2023 | G1: 2024 | H1: 2025 | I1: 2026 | J1: 2027 | K1: 2028 | L1: 2029 | M1: 2030 | N1: 2031 | O1: 2032 | P1: 2033 | Q1: 2034 | R1: 2035 | S1: 2036 | T1: 2037 | U1: 2038 | V1: 2039 | W1: 2040 | X1: 2041 | Y1: 2042 | Z1: 2043 | AA1: 2044 | AB1: 2045 | AC1: 2046 | AD1: 2047 | AE1: 2048 | AF1: 2049 | AG1: 2050
C3: Report | D3: Annual Energy Outlook 2021
C4: Scenario | D4: ref2021 | G4: Reference case
C5: Datekey | D5: d113020a
C6: Release Date | E6: January 2021
A10: EGC000 | B10: 9. Electricity Generating Capacity | AH10: Compound
B11: (gigawatts) | AH11: Growth
AH12: 2020-2050
B13: Net Summer Capacity 1/ | C13: 2020 | D13: 2021 | E13: 2022 | F13: 2023 | G13: 2024 | H13: 2025 | I13: 2026 | J13: 2027 | K13: 2028 | L13: 2029 | M13: 2030 | N13: 2031 | O13: 2032 | P13: 2033 | Q13: 2034 | R13: 2035 | S13: 2036 | T13: 2037 | U13: 2038 | V13: 2039 | W13: 2040 | X13: 2041 | Y13: 2042 | Z13: 2043 | AA13: 2044 | AB13: 2045 | AC13: 2046 | AD13: 2047 | AE13: 2048 | AF13: 2049 | AG13: 2050 | AH13: (percent)
B15: Electric Power Sector 2/
B16: Power Only 3/
A17: EGC000:ba_CoalSteam | B17: Coal 4/ | C17: 217.31993 | D17: 212.9165 | E17: 208.20419 | F17: 187.9456 | G17: 177.84901 | H17: 111.62372 | I17: 107.49852 | J17: 99.09462 | K17: 95.793617 | L17: 93.304123 | M17: 90.772118 | N17: 89.354118 | O17: 86.515114 | P17: 84.896118 | Q17: 82.760315 | R17: 81.14431 | S17: 81.14431 | T17: 80.805313 | U17: 78.68531 | V17: 78.346306 | W17: 78.346306 | X17: 78.00631 | Y17: 78.00631 | Z17: 78.00631 | AA17: 77.985306 | AB17: 75.056305 | AC17: 74.376312 | AD17: 74.376312 | AE17: 73.266312 | AF17: 73.266312 | AG17: 73.266312 | AH17: -0.035593
A18: EGC000:ba_OtherFossilSt | B18: Oil and Natural Gas Steam 4, 5/ | C18: 72.645203 | D18: 71.450104 | E18: 66.598999 | F18: 62.020508 | G18: 56.8395 | H18: 69.829697 | I18: 65.723 | J18: 64.680496 | K18: 63.032501 | L18: 56.303104 | M18: 56.258102 | N18: 55.284603 | O18: 55.041599 | P18: 54.297802 | Q18: 53.794804 | R18: 52.824299 | S18: 51.914299 | T18: 51.914299 | U18: 51.914299 | V18: 51.7883 | W18: 51.7883 | X18: 51.7883 | Y18: 51.7883 | Z18: 51.7883 | AA18: 51.7883 | AB18: 51.682301 | AC18: 51.682301 | AD18: 51.682301 | AE18: 51.682301 | AF18: 51.129299 | AG18: 51.129299 | AH18: -0.011639
A19: EGC000:ba_CombinedCycle | B19: Combined Cycle | C19: 245.41911 | D19: 248.74231 | E19: 261.34235 | F19: 266.80924 | G19: 275.23621 | H19: 295.5976 | I19: 316.2475 | J19: 340.65677 | K19: 347.02155 | L19: 351.84 | M19: 356.66968 | N19: 362.06024 | O19: 368.02655 | P19: 372.73224 | Q19: 377.60669 | R19: 382.26901 | S19: 387.8067 | T19: 394.61877 | U19: 400.82574 | V19: 405.36829 | W19: 411.04443 | X19: 416.14801 | Y19: 421.73791 | Z19: 430.15918 | AA19: 439.63422 | AB19: 444.72955 | AC19: 450.20056 | AD19: 455.42334 | AE19: 462.29407 | AF19: 466.41812 | AG19: 472.56198 | AH19: 0.02208
A20: EGC000:ba_CombustionTur | B20: Combustion Turbine/Diesel | C20: 139.99884 | D20: 151.966 | E20: 157.28397 | F20: 163.12407 | G20: 170.05273 | H20: 186.36914 | I20: 195.86475 | J20: 201.53641 | K20: 206.65286 | L20: 210.36844 | M20: 214.01863 | N20: 217.90662 | O20: 221.90842 | P20: 224.93639 | Q20: 229.371 | R20: 234.94542 | S20: 239.25157 | T20: 243.65843 | U20: 246.74908 | V20: 250.24753 | W20: 255.83899 | X20: 259.13599 | Y20: 265.74377 | Z20: 271.13489 | AA20: 275.76062 | AB20: 283.54571 | AC20: 289.10193 | AD20: 293.97659 | AE20: 298.95785 | AF20: 302.97553 | AG20: 310.84103 | AH20: 0.026945
A21: EGC000:ba_NuclearPower | B21: Nuclear Power 6/ | C21: 97.120911 | D21: 92.484604 | E21: 92.860008 | F21: 92.904007 | G21: 92.954803 | H21: 91.86393 | I21: 78.538353 | J21: 70.422722 | K21: 68.100891 | L21: 61.715469 | M21: 61.801544 | N21: 59.645149 | O21: 58.45676 | P21: 57.484283 | Q21: 55.438354 | R21: 55.616707 | S21: 54.627182 | T21: 52.646942 | U21: 51.831886 | V21: 51.831886 | W21: 51.875618 | X21: 52.034546 | Y21: 52.149536 | Z21: 49.878754 | AA21: 44.363968 | AB21: 44.467846 | AC21: 44.521946 | AD21: 43.665047 | AE21: 41.858734 | AF21: 41.899445 | AG21: 41.961777 | AH21: -0.027586
A22: EGC000:ba_PumpedStorage | B22: Pumped Storage | C22: 22.778303 | D22: 22.778303 | E22: 22.778303 | F22: 22.778303 | G22: 22.778303 | H22: 22.778303 | I22: 22.778303 | J22: 22.778303 | K22: 22.778303 | L22: 22.778303 | M22: 22.778303 | N22: 22.778303 | O22: 22.778303 | P22: 22.778303 | Q22: 22.778303 | R22: 22.778303 | S22: 22.778303 | T22: 22.778303 | U22: 22.778303 | V22: 22.778303 | W22: 22.778303 | X22: 22.778303 | Y22: 22.778303 | Z22: 22.778303 | AA22: 22.778303 | AB22: 22.778303 | AC22: 22.778303 | AD22: 22.778303 | AE22: 22.778303 | AF22: 22.778303 | AG22: 22.778303 | AH22: 0
A23: EGC000:ba_DiurnalStorag | B23: Diurnal Storage | C23: 3.151 | D23: 6.9255 | E23: 8.623799 | F23: 9.5348 | G23: 10.196526 | H23: 11.049868 | I23: 11.467272 | J23: 11.890328 | K23: 12.301329 | L23: 12.712328 | M23: 13.123329 | N23: 13.123329 | O23: 13.128527 | P23: 13.128527 | Q23: 13.128527 | R23: 16.083761 | S23: 16.161716 | T23: 16.159718 | U23: 16.159718 | V23: 16.159718 | W23: 16.409718 | X23: 16.409718 | Y23: 16.409718 | Z23: 16.409718 | AA23: 16.409718 | AB23: 16.659718 | AC23: 16.659718 | AD23: 16.739216 | AE23: 17.035295 | AF23: 17.258429 | AG23: 17.777584 | AH23: 0.05937
A24: EGC000:ba_FuelCells | B24: Fuel Cells | C24: 0.2042 | D24: 0.2303 | E24: 0.2303 | F24: 0.231397 | G24: 0.232498 | H24: 0.232498 | I24: 0.232498 | J24: 0.232498 | K24: 0.232498 | L24: 0.232498 | M24: 0.232498 | N24: 0.231398 | O24: 0.231398 | P24: 0.231398 | Q24: 0.231398 | R24: 0.232443 | S24: 0.232443 | T24: 0.232443 | U24: 0.232443 | V24: 0.232443 | W24: 0.232443 | X24: 0.232443 | Y24: 0.232443 | Z24: 0.232443 | AA24: 0.232443 | AB24: 0.232443 | AC24: 0.232443 | AD24: 0.233445 | AE24: 0.233445 | AF24: 0.233445 | AG24: 0.233445 | AH24: 0.004472
A25: EGC000:ba_RenewableSour | B25: Renewable Sources 7/ | C25: 263.93091 | D25: 283.68082 | E25: 302.70618 | F25: 334.72897 | G25: 369.97696 | H25: 389.30862 | I25: 402.99243 | J25: 409.72995 | K25: 416.53796 | L25: 427.15076 | M25: 435.90375 | N25: 439.85443 | O25: 445.55588 | P25: 452.2225 | Q25: 463.27234 | R25: 476.52661 | S25: 486.44336 | T25: 493.01562 | U25: 502.82404 | V25: 508.07126 | W25: 514.43146 | X25: 519.57922 | Y25: 524.2912 | Z25: 531.30829 | AA25: 540.67932 | AB25: 550.00958 | AC25: 563.00537 | AD25: 580.09589 | AE25: 601.65747 | AF25: 626.57434 | AG25: 637.31628 | AH25: 0.029822
A26: EGC000:ba_DistributedGe | B26: Distributed Generation (Natural Gas) 8/ | C26: 0 | D26: 0 | E26: 1.557683 | F26: 2.029814 | G26: 2.589538 | H26: 3.788425 | I26: 4.369585 | J26: 5.052324 | K26: 5.972651 | L26: 6.829225 | M26: 7.551871 | N26: 8.336995 | O26: 9.196261 | P26: 10.102161 | Q26: 11.118253 | R26: 12.202368 | S26: 13.468646 | T26: 14.828192 | U26: 16.063656 | V26: 17.33741 | W26: 18.650297 | X26: 19.995911 | Y26: 21.409273 | Z26: 23.142252 | AA26: 24.906137 | AB26: 26.691204 | AC26: 28.452904 | AD26: 30.297573 | AE26: 32.29063 | AF26: 34.308743 | AG26: 36.505852 | AH26: - -
A27: EGC000:ba_Total | B27: Total | C27: 1062.5685 | D27: 1091.1744 | E27: 1122.1857 | F27: 1142.1067 | G27: 1178.7061 | H27: 1182.4419 | I27: 1205.7122 | J27: 1226.0745 | K27: 1238.4241 | L27: 1243.2341 | M27: 1259.1097 | N27: 1268.5752 | O27: 1280.8389 | P27: 1292.8097 | Q27: 1309.5 | R27: 1334.6233 | S27: 1353.8286 | T27: 1370.6581 | U27: 1388.0643 | V27: 1402.1615 | W27: 1421.3959 | X27: 1436.1086 | Y27: 1454.5468 | Z27: 1474.8383 | AA27: 1494.5382 | AB27: 1515.8528 | AC27: 1541.0117 | AD27: 1569.2681 | AE27: 1602.0544 | AF27: 1636.842 | AG27: 1664.3718 | AH27: 0.015071
B28: Combined Heat and Power 9/
