Workbook

Sheet About
A1: BPHC BAU Pumped Hydro Capacity
A3: Source: | B3: Energy Information Administration
B4: 2018
B5: Annual Energy Outlook 2018
B6: http://www.eia.gov/forecasts/aeo/excel/aeotab_9.xlsx
B7: Table 9, Row "Pumped Storage"

Sheet AEO Table 9
B1: ref2018.d121317a | C1: 2020 | D1: 2021 | E1: 2022 | F1: 2023 | G1: 2024 | H1: 2025 | I1: 2026 | J1: 2027 | K1: 2028 | L1: 2029 | M1: 2030 | N1: 2031 | O1: 2032 | P1: 2033 | Q1: 2034 | R1: 2035 | S1: 2036 | T1: 2037 | U1: 2038 | V1: 2039 | W1: 2040 | X1: 2041 | Y1: 2042 | Z1: 2043 | AA1: 2045 | AB1: 2046 | AC1: 2047 | AD1: 2048 | AE1: 2049 | AF1: 2050 | AG1: 2050
C3: Report | D3: Annual Energy Outlook 2018
C4: Scenario | D4: ref2018 | G4: Reference case
C5: Datekey | D5: d121317a
C6: Release Date | E6: 44197
A10: EGC000 | B10: 9. Electricity Generating Capacity
B11: (gigawatts)
AG12: 2017-
B13: Net Summer Capacity 1/ | C13: 2020 | D13: 2021 | E13: 2022 | F13: 2023 | G13: 2024 | H13: 2025 | I13: 2026 | J13: 2027 | K13: 2028 | L13: 2029 | M13: 2030 | N13: 2031 | O13: 2032 | P13: 2033 | Q13: 2034 | R13: 2035 | S13: 2036 | T13: 2037 | U13: 2038 | V13: 2039 | W13: 2040 | X13: 2041 | Y13: 2042 | Z13: 2043 | AA13: 2045 | AB13: 2046 | AC13: 2047 | AD13: 2048 | AE13: 2049 | AF13: 2050 | AG13: 2050
B15: Electric Power Sector 2/
B16: Power Only 3/
A17: EGC000:ba_CoalSteam | B17: Coal 4/ | C17: 217.3 | D17: 212.9 | E17: 208.2 | F17: 188.3 | G17: 176.8 | H17: 136 | I17: 131.6 | J17: 125.5 | K17: 122.9 | L17: 120.5 | M17: 117.9 | N17: 116.5 | O17: 114.5 | P17: 113.3 | Q17: 112.7 | R17: 110.5 | S17: 110.5 | T17: 109.3 | U17: 106.2 | V17: 105.4 | W17: 105.4 | X17: 105.1 | Y17: 105.1 | Z17: 105.1 | AA17: 105.1 | AB17: 102.6 | AC17: 102.6 | AD17: 102.1 | AE17: 102.1 | AF17: 102.1 | AG17: 102.1 | AH17: -0.025
A18: EGC000:ba_OtherFossilSt | B18: Oil and Natural Gas Steam 4, 5/ | C18: 72.6 | D18: 71.5 | E18: 66.6 | F18: 61.9 | G18: 56.5 | H18: 56.3 | I18: 52 | J18: 51.5 | K18: 49.5 | L18: 47.5 | M18: 47 | N18: 45.3 | O18: 45.1 | P18: 44.2 | Q18: 43.7 | R18: 42.7 | S18: 42.7 | T18: 43.4 | U18: 43.4 | V18: 43.4 | W18: 43.4 | X18: 43.4 | Y18: 43.4 | Z18: 43.4 | AA18: 43.3 | AB18: 43.3 | AC18: 43.3 | AD18: 43.3 | AE18: 43.3 | AF18: 43.3 | AG18: 43.3 | AH18: -0.017
A19: EGC000:ba_CombinedCycle | B19: Combined Cycle | C19: 245.4 | D19: 248.7 | E19: 261.3 | F19: 264.7 | G19: 268.7 | H19: 282.7 | I19: 295.2 | J19: 301 | K19: 304.3 | L19: 307.3 | M19: 308.4 | N19: 313 | O19: 317.6 | P19: 321 | Q19: 324.9 | R19: 329.1 | S19: 332.3 | T19: 336.5 | U19: 340.4 | V19: 342.8 | W19: 348 | X19: 351.3 | Y19: 353.6 | Z19: 359.4 | AA19: 363.6 | AB19: 367.8 | AC19: 370.8 | AD19: 375.4 | AE19: 380.8 | AF19: 388.6 | AG19: 394.7 | AH19: 0.016
A20: EGC000:ba_CombustionTur | B20: Combustion Turbine/Diesel | C20: 140 | D20: 151.4 | E20: 157.5 | F20: 163.4 | G20: 167.7 | H20: 179.7 | I20: 184.2 | J20: 188.9 | K20: 192 | L20: 195 | M20: 197.2 | N20: 200.9 | O20: 203.1 | P20: 206 | Q20: 210.8 | R20: 215.3 | S20: 219.7 | T20: 225.1 | U20: 229.1 | V20: 235.6 | W20: 239.1 | X20: 243.5 | Y20: 250.7 | Z20: 259.8 | AA20: 265.3 | AB20: 271.4 | AC20: 276.6 | AD20: 282.9 | AE20: 291.9 | AF20: 297.9 | AG20: 304.3 | AH20: 0.026
A21: EGC000:ba_NuclearPower | B21: Nuclear Power 6/ | C21: 97.1 | D21: 92.5 | E21: 92.9 | F21: 92.9 | G21: 93 | H21: 91.9 | I21: 80.7 | J21: 78.8 | K21: 78.8 | L21: 76.8 | M21: 76.9 | N21: 77 | O21: 77.1 | P21: 76.1 | Q21: 74.1 | R21: 74.3 | S21: 73.5 | T21: 73.5 | U21: 73.6 | V21: 73.6 | W21: 72.4 | X21: 72.6 | Y21: 72.7 | Z21: 72.8 | AA21: 72.9 | AB21: 73 | AC21: 73.1 | AD21: 72.2 | AE21: 72.2 | AF21: 72.2 | AG21: 72.3 | AH21: -0.01
A22: EGC000:ba_PumpedStorage | B22: Pumped Storage | C22: 22.8 | D22: 22.8 | E22: 22.8 | F22: 22.8 | G22: 22.8 | H22: 22.8 | I22: 22.8 | J22: 22.8 | K22: 22.8 | L22: 22.8 | M22: 22.8 | N22: 22.8 | O22: 22.8 | P22: 22.8 | Q22: 22.8 | R22: 22.8 | S22: 22.8 | T22: 22.8 | U22: 22.8 | V22: 22.8 | W22: 22.8 | X22: 22.8 | Y22: 22.8 | Z22: 22.8 | AA22: 22.8 | AB22: 22.8 | AC22: 22.8 | AD22: 22.8 | AE22: 22.8 | AF22: 22.8 | AG22: 22.8 | AH22: 0
A23: EGC000:ba_DiurnalStorag | B23: Diurnal Storage | C23: 3.2 | D23: 6.9 | E23: 8.6 | F23: 9.5 | G23: 10.2 | H23: 10.6 | I23: 11 | J23: 11.6 | K23: 12 | L23: 12.4 | M23: 12.8 | N23: 12.8 | O23: 12.9 | P23: 12.9 | Q23: 13 | R23: 16 | S23: 16.1 | T23: 16.1 | U23: 16.1 | V23: 16.1 | W23: 16.4 | X23: 16.6 | Y23: 16.6 | Z23: 17.1 | AA23: 17.4 | AB23: 17.7 | AC23: 19.4 | AD23: 19.6 | AE23: 19.9 | AF23: 20.4 | AG23: 20.6 | AH23: 0.065
A24: EGC000:ba_FuelCells | B24: Fuel Cells | C24: 0.2 | D24: 0.2 | E24: 0.2 | F24: 0.2 | G24: 0.2 | H24: 0.2 | I24: 0.2 | J24: 0.2 | K24: 0.2 | L24: 0.2 | M24: 0.2 | N24: 0.2 | O24: 0.2 | P24: 0.2 | Q24: 0.2 | R24: 0.2 | S24: 0.2 | T24: 0.2 | U24: 0.2 | V24: 0.2 | W24: 0.2 | X24: 0.2 | Y24: 0.2 | Z24: 0.2 | AA24: 0.2 | AB24: 0.2 | AC24: 0.2 | AD24: 0.2 | AE24: 0.2 | AF24: 0.2 | AG24: 0.2 | AH24: 0.004
A25: EGC000:ba_RenewableSour | B25: Renewable Sources 7/ | C25: 263.9 | D25: 283.7 | E25: 302.7 | F25: 335.4 | G25: 379.1 | H25: 397.7 | I25: 418.7 | J25: 435.5 | K25: 445.5 | L25: 460.5 | M25: 476.2 | N25: 485 | O25: 496.5 | P25: 507.4 | Q25: 520.4 | R25: 539.4 | S25: 547.1 | T25: 555.2 | U25: 564.7 | V25: 570 | W25: 576 | X25: 587.2 | Y25: 593.3 | Z25: 601 | AA25: 610.7 | AB25: 624.7 | AC25: 639.7 | AD25: 655.8 | AE25: 664.1 | AF25: 676.4 | AG25: 688.2 | AH25: 0.032
A26: EGC000:ba_DistributedGe | B26: Distributed Generation (Natural Gas) 8/ | C26: 0 | D26: 0 | E26: 1.1 | F26: 1.5 | G26: 2 | H26: 2.8 | I26: 3.3 | J26: 3.8 | K26: 4.4 | L26: 5.1 | M26: 5.8 | N26: 6.5 | O26: 7.3 | P26: 8.1 | Q26: 8.9 | R26: 9.8 | S26: 10.9 | T26: 12.2 | U26: 13.4 | V26: 14.7 | W26: 16.1 | X26: 17.4 | Y26: 18.9 | Z26: 20.4 | AA26: 22 | AB26: 23.6 | AC26: 25.3 | AD26: 27.1 | AE26: 28.9 | AF26: 30.9 | AG26: 33 | AH26: --
A27: EGC000:ba_Total | B27: Total | C27: 1062.6 | D27: 1090.6 | E27: 1121.9 | F27: 1140.8 | G27: 1176.9 | H27: 1180.7 | I27: 1199.8 | J27: 1219.5 | K27: 1232.5 | L27: 1248 | M27: 1265.2 | N27: 1280 | O27: 1296.9 | P27: 1312 | Q27: 1331.4 | R27: 1360.2 | S27: 1375.8 | T27: 1394.3 | U27: 1410 | V27: 1424.6 | W27: 1440 | X27: 1460.1 | Y27: 1477.4 | Z27: 1502.1 | AA27: 1523.3 | AB27: 1547.2 | AC27: 1573.8 | AD27: 1601.3 | AE27: 1626.4 | AF27: 1654.8 | AG27: 1681.5 | AH27: 0.015
B28: Combined Heat and Power 9/
A29: EGC000:ca_CoalSteam | B29: Coal | C29: 1.9 | D29: 1.8 | E29: 1.8 | F29: 1.8 | G29: 1.8 | H29: 1.8 | I29: 1.8 | J29: 1.8 | K29: 1.8 | L29: 1.8 | M29: 1.8 | N29: 1.8 | O29: 1.8 | P29: 1.8 | Q29: 1.8 | R29: 1.8 | S29: 1.8 | T29: 1.8 | U29: 1.8 | V29: 1.8 | W29: 1.8 | X29: 1.8 | Y29: 1.8 | Z29: 1.8 | AA29: 1.8 | AB29: 1.8 | AC29: 1.8 | AD29: 1.8 | AE29: 1.8 | AF29: 1.8 | AG29: 1.8 | AH29: -0.002
A30: EGC000:ca_OtherFossilSt | B30: Oil and Natural Gas Steam 5/ | C30: 0.6 | D30: 0.6 | E30: 0.6 | F30: 0.6 | G30: 0.6 | H30: 0.6 | I30: 0.6 | J30: 0.6 | K30: 0.6 | L30: 0.6 | M30: 0.6 | N30: 0.6 | O30: 0.6 | P30: 0.6 | Q30: 0.6 | R30: 0.6 | S30: 0.6 | T30: 0.6 | U30: 0.6 | V30: 0.6 | W30: 0.6 | X30: 0.6 | Y30: 0.6 | Z30: 0.6 | AA30: 0.6 | AB30: 0.6 | AC30: 0.6 | AD30: 0.6 | AE30: 0.6 | AF30: 0.6 | AG30: 0.6 | AH30: 0
A31: EGC000:ca_CombinedCycle | B31: Combined Cycle | C31: 22 | D31: 22 | E31: 22 | F31: 21.8 | G31: 21.8 | H31: 21.8 | I31: 21.8 | J31: 21.8 | K31: 21.8 | L31: 21.8 | M31: 21.8 | N31: 21.8 | O31: 21.8 | P31: 21.8 | Q31: 21.8 | R31: 21.8 | S31: 21.8 | T31: 21.8 | U31: 21.8 | V31: 21.8 | W31: 21.8 | X31: 21.8 | Y31: 21.8 | Z31: 21.8 | AA31: 21.8 | AB31: 21.8 | AC31: 21.8 | AD31: 21.8 | AE31: 21.8 | AF31: 21.8 | AG31: 21.8 | AH31: 0
A32: EGC000:ca_CombustionTur | B32: Combustion Turbine/Diesel | C32: 3.1 | D32: 3.1 | E32: 3.1 | F32: 3.1 | G32: 3.1 | H32: 3.1 | I32: 3.1 | J32: 3.1 | K32: 3.1 | L32: 3.1 | M32: 3.1 | N32: 3.1 | O32: 3.1 | P32: 3.1 | Q32: 3.1 | R32: 3.1 | S32: 3.1 | T32: 3.1 | U32: 3.1 | V32: 3.1 | W32: 3.1 | X32: 3.1 | Y32: 3.1 | Z32: 3.1 | AA32: 3.1 | AB32: 3.1 | AC32: 3.1 | AD32: 3.1 | AE32: 3.1 | AF32: 3.1 | AG32: 3.1 | AH32: 0
A33: EGC000:ca_RenewableSour | B33: Renewable Sources 7/ | C33: 1 | D33: 1 | E33: 1 | F33: 1 | G33: 1 | H33: 1 | I33: 1 | J33: 1 | K33: 1 | L33: 1 | M33: 1 | N33: 1 | O33: 1 | P33: 1 | Q33: 1 | R33: 1 | S33: 1 | T33: 1 | U33: 1 | V33: 1 | W33: 1 | X33: 1 | Y33: 1 | Z33: 1 | AA33: 1 | AB33: 1 | AC33: 1 | AD33: 1 | AE33: 1 | AF33: 1 | AG33: 1 | AH33: 0
A34: EGC000:ca_Total | B34: Total | C34: 28.6 | D34: 28.5 | E34: 28.5 | F34: 28.3 | G34: 28.3 | H34: 28.3 | I34: 28.3 | J34: 28.3 | K34: 28.3 | L34: 28.3 | M34: 28.3 | N34: 28.3 | O34: 28.3 | P34: 28.3 | Q34: 28.3 | R34: 28.3 | S34: 28.3 | T34: 28.3 | U34: 28.3 | V34: 28.3 | W34: 28.3 | X34: 28.3 | Y34: 28.3 | Z34: 28.3 | AA34: 28.3 | AB34: 28.3 | AC34: 28.3 | AD34: 28.3 | AE34: 28.3 | AF34: 28.3 | AG34: 28.3 | AH34: 0
B36: Cumulative Planned Additions 10/
A37: EGC000:da_CoalSteam | B37: Coal | C37: -- | D37: 0 | E37: 0 | F37: 0 | G37: 0 | H37: 0 | I37: 0 | J37: 0 | K37: 0 | L37: 0 | M37: 0 | N37: 0 | O37: 0 | P37: 0 | Q37: 0 | R37: 0 | S37: 0 | T37: 0 | U37: 0 | V37: 0 | W37: 0 | X37: 0 | Y37: 0 | Z37: 0 | AA37: 0 | AB37: 0 | AC37: 0 | AD37: 0 | AE37: 0 | AF37: 0 | AG37: 0 | AH37: --
A38: EGC000:da_OtherFossilSt | B38: Oil and Natural Gas Steam 5/ | C38: -- | D38: 0 | E38: 0 | F38: 0 | G38: 0 | H38: 0 | I38: 0 | J38: 0 | K38: 0 | L38: 0 | M38: 0 | N38: 0 | O38: 0 | P38: 0 | Q38: 0 | R38: 0 | S38: 0 | T38: 0 | U38: 0 | V38: 0 | W38: 0 | X38: 0 | Y38: 0 | Z38: 0 | AA38: 0 | AB38: 0 | AC38: 0 | AD38: 0 | AE38: 0 | AF38: 0 | AG38: 0 | AH38: --
A39: EGC000:da_CombinedCycle | B39: Combined Cycle | C39: -- | D39: 3.4 | E39: 17 | F39: 17 | G39: 17 | H39: 17 | I39: 17 | J39: 17 | K39: 17 | L39: 17 | M39: 17 | N39: 17 | O39: 17 | P39: 17 | Q39: 17 | R39: 17 | S39: 17 | T39: 17 | U39: 17 | V39: 17 | W39: 17 | X39: 17 | Y39: 17 | Z39: 17 | AA39: 17 | AB39: 17 | AC39: 17 | AD39: 17 | AE39: 17 | AF39: 17 | AG39: 17 | AH39: --
A40: EGC000:da_CombustionTur | B40: Combustion Turbine/Diesel | C40: -- | D40: 3.3 | E40: 4 | F40: 4 | G40: 4.5 | H40: 4.5 | I40: 4.5 | J40: 4.5 | K40: 4.5 | L40: 4.5 | M40: 4.5 | N40: 4.5 | O40: 4.5 | P40: 4.5 | Q40: 4.5 | R40: 4.5 | S40: 4.5 | T40: 4.5 | U40: 4.5 | V40: 4.5 | W40: 4.5 | X40: 4.5 | Y40: 4.5 | Z40: 4.5 | AA40: 4.5 | AB40: 4.5 | AC40: 4.5 | AD40: 4.5 | AE40: 4.5 | AF40: 4.5 | AG40: 4.5 | AH40: --
A41: EGC000:da_NuclearPower | B41: Nuclear Power | C41: -- | D41: 1.1 | E41: 2.2 | F41: 2.2 | G41: 2.2 | H41: 2.2 | I41: 2.2 | J41: 2.2 | K41: 2.2 | L41: 2.2 | M41: 2.2 | N41: 2.2 | O41: 2.2 | P41: 2.2 | Q41: 2.2 | R41: 2.2 | S41: 2.2 | T41: 2.2 | U41: 2.2 | V41: 2.2 | W41: 2.2 | X41: 2.2 | Y41: 2.2 | Z41: 2.2 | AA41: 2.2 | AB41: 2.2 | AC41: 2.2 | AD41: 2.2 | AE41: 2.2 | AF41: 2.2 | AG41: 2.2 | AH41: --
A42: EGC000:da_PumpedStorage | B42: Pumped Storage | C42: -- | D42: 0 | E42: 0 | F42: 0 | G42: 0 | H42: 0 | I42: 0 | J42: 0 | K42: 0 | L42: 0 | M42: 0 | N42: 0 | O42: 0 | P42: 0 | Q42: 0 | R42: 0 | S42: 0 | T42: 0 | U42: 0 | V42: 0 | W42: 0 | X42: 0 | Y42: 0 | Z42: 0 | AA42: 0 | AB42: 0 | AC42: 0 | AD42: 0 | AE42: 0 | AF42: 0 | AG42: 0 | AH42: --
A43: EGC000:da_DiurnalStorag | B43: Diurnal Storage | C43: -- | D43: 3.8 | E43: 5.5 | F43: 6.4 | G43: 7 | H43: 7.5 | I43: 7.9 | J43: 8.3 | K43: 8.7 | L43: 9.1 | M43: 9.5 | N43: 9.5 | O43: 9.5 | P43: 9.5 | Q43: 9.5 | R43: 12.5 | S43: 12.5 | T43: 12.5 | U43: 12.5 | V43: 12.5 | W43: 12.7 | X43: 12.7 | Y43: 12.7 | Z43: 12.7 | AA43: 12.7 | AB43: 13 | AC43: 13 | AD43: 13 | AE43: 13 | AF43: 13 | AG43: 13 | AH43: --
A44: EGC000:da_FuelCells | B44: Fuel Cells | C44: -- | D44: 0 | E44: 0 | F44: 0 | G44: 0 | H44: 0 | I44: 0 | J44: 0 | K44: 0 | L44: 0 | M44: 0 | N44: 0 | O44: 0 | P44: 0 | Q44: 0 | R44: 0 | S44: 0 | T44: 0 | U44: 0 | V44: 0 | W44: 0 | X44: 0 | Y44: 0 | Z44: 0 | AA44: 0 | AB44: 0 | AC44: 0 | AD44: 0 | AE44: 0 | AF44: 0 | AG44: 0 | AH44: --
A45: EGC000:da_RenewableSour | B45: Renewable Sources 7/ | C45: -- | D45: 19.7 | E45: 29.9 | F45: 32.9 | G45: 33.4 | H45: 33.4 | I45: 33.4 | J45: 33.4 | K45: 35.4 | L45: 35.4 | M45: 42.5 | N45: 42.5 | O45: 42.5 | P45: 42.5 | Q45: 47.7 | R45: 55.9 | S45: 55.9 | T45: 55.9 | U45: 55.9 | V45: 55.9 | W45: 55.9 | X45: 55.9 | Y45: 55.9 | Z45: 55.9 | AA45: 55.9 | AB45: 55.9 | AC45: 55.9 | AD45: 55.9 | AE45: 55.9 | AF45: 55.9 | AG45: 55.9 | AH45: --
A46: EGC000:da_DistributedGe | B46: Distributed Generation 8/ | C46: -- | D46: 0 | E46: 0 | F46: 0 | G46: 0 | H46: 0 | I46: 0 | J46: 0 | K46: 0 | L46: 0 | M46: 0 | N46: 0 | O46: 0 | P46: 0 | Q46: 0 | R46: 0 | S46: 0 | T46: 0 | U46: 0 | V46: 0 | W46: 0 | X46: 0 | Y46: 0 | Z46: 0 | AA46: 0 | AB46: 0 | AC46: 0 | AD46: 0 | AE46: 0 | AF46: 0 | AG46: 0 | AH46: --
...

Sheet BPHC
A1: Year | B1: 2016 | C1: 2017 | D1: 2018 | E1: 2019 | F1: 2020 | G1: 2021 | H1: 2022 | I1: 2023 | J1: 2024 | K1: 2025 | L1: 2026 | M1: 2027 | N1: 2028 | O1: 2029 | P1: 2030 | Q1: 2031 | R1: 2032 | S1: 2033 | T1: 2034 | U1: 2035 | V1: 2036 | W1: 2037 | X1: 2038 | Y1: 2039 | Z1: 2040 | AA1: 2041 | AB1: 2042 | AC1: 2043 | AD1: 2044 | AE1: 2045 | AF1: 2046 | AG1: 2047 | AH1: 2048 | AI1: 2049 | AJ1: 2050
A2: Pumped Storage Capacity (MW) | B2: ='AEO Table 9'!C22*1000 -> 22800 | C2: ='AEO Table 9'!D22*1000 -> 22800 | D2: ='AEO Table 9'!E22*1000 -> 22800 | E2: ='AEO Table 9'!F22*1000 -> 22800 | F2: ='AEO Table 9'!G22*1000 -> 22800 | G2: ='AEO Table 9'!H22*1000 -> 22800 | H2: ='AEO Table 9'!I22*1000 -> 22800 | I2: ='AEO Table 9'!J22*1000 -> 22800 | ... AE2: ='AEO Table 9'!AF22*1000 -> 22800 | AF2: ='AEO Table 9'!#REF!*1000 -> #REF! | AG2: ='AEO Table 9'!#REF!*1000 -> #REF! | AH2: ='AEO Table 9'!#REF!*1000 -> #REF! | AI2: ='AEO Table 9'!#REF!*1000 -> #REF! | AJ2: ='AEO Table 9'!#REF!*1000 -> #REF!
