Workbook
Name _56F9DC9755BA473782653E2940F9FormId: "H6xrR7I22UqGmc2mutH4Yq3_1cZmZKxHmcZ_ItVFhVdUOEtSUDhYTjJWOVVBSkQ2R0Y2U041STNMMiQlQCN0PWcu"
Name _56F9DC9755BA473782653E2940F9ResponseSheet: "Form1"
Name _56F9DC9755BA473782653E2940F9SourceDocId: "{3e8ee12f-b9ec-4a22-8587-d20e6899a3d9}"
Name internet_4a: 'HK TD Cars'!#REF!
Name internet_4a: 'HK TD Motorcycles'!#REF!
Name internet_4a: #REF!
Name internet_4b: #REF!
Name internet_4c: #REF!
Name internet_4d: #REF!
Name internet_4e: #REF!

Sheet About
A1: SYVbT Start Year Vehicles by Technology
A3: Sources: | B3: Motorcycles, private cars, taxis, buses, goods (freight)
B4: HK Transport Department
B5: 2023
B6: Registration and Licensing of Vehicles by Class of Vehicles
B7: https://www.td.gov.hk/filemanager/en/content_5217/2307_e.pdf
B8: Tables T4.1a-T4.1k
B10: Division of cars, buses and goods into Diesel and petrol
B11: Competition Commission
B12: 2017
B13: Report on Study into Hong Kong's Auto-fuel Market
B14: https://www.compcomm.hk/en/media/press/files/Full_Report_Auto_fuel_Market_Study_Report_Eng.pdf
B15: Table 1
B17: aircraft
B18: Cathay Pacific Group Fact Sheet
B19: 2023
B20: Corporate Affairs Department
B21: https://news.cathaypacific.com/fact-sheet
B22: https://www.cathaypacific.com/content/dam/cx/about-us/investor-relations/interim-annual-reports/en/2023_cx_interim_report_en.pdf
B26: passenger rail
B27: MTR Business Overview
B28: 2021
B29: MTR Number of Train Cars
B30: https://www.mtr.com.hk/archive/corporate/en/publications/images/business_overview_e.pdf
B31: Table Page 7
B33: freight rail
B34: Checkerboardhill
B35: 2011
B36: Blog entry
B37: https://www.checkerboardhill.com/2011/09/demise-of-hong-kong-rail-freight/
B39: Electric Vehicles
B40: Hong Kong Environmental Protection Department
B41: 2023
B42: Promotion of Electric Vehicles
B43: https://www.epd.gov.hk/epd/english/environmentinhk/air/prob_solutions/promotion_ev.html
B44: number under section "EV Models in Hong Kong"
B45: https://www.td.gov.hk/filemanager/en/content_5217/2307_e.pdf
B48: Vehicle Licensing by Fuel Type
B49: Registration and Licensing of Vehicles by Fuel Type
B50: 2018
...

Sheet Air
A1: Cathay Pacific Freighters (Air Hong Kong) | E1: https://www.cathaypacific.com/content/dam/cx/about-us/investor-relations/interim-annual-reports/en/2023_cx_interim_report_en.pdf
A2: Airbus A300-600F | C2: 8
A3: A330-243F | C3: 2
A4: A330-300P2F | C4: 5
C5: =SUM(C2:C4) -> 15
A7: HK Express
A8: Airbus A320-200 | C8: 5
A9: A321-200 | C9: 11
A10: A320-200neo | C10: 10
A11: A321-200neo | C11: 1
C12: =SUM(C8:C11) -> 27
A14: Cathay Pacific
A15: A320-200 | C15: 4
A16: A321-200 | C16: 2
A17: A321-200neo | C17: 12
A18: A330-300 | C18: 43
A19: A350-900 | C19: 28
A20: A350 -1000 | C20: 18
A21: 747-400ERF | C21: 6
A22: 747-8F | C22: 14
A23: 777-300 | C23: 17
A24: 777-300ER | C24: 39
C25: =SUM(C15:C24) -> 183
A27: Passenger Aircrafts | C27: =SUM(C25,C12) -> 210

Sheet HK TD Motorcycles
A4: 表 4.1(a) | C4: : 按車輛種類劃分的車輛登記及領牌統計數字 (1) (2) (3)
A5: Table 4.1(a) | C5: : Registration and Licensing of Vehicles by Class of Vehicles (1) (2) (3) | P5: 202307
C7: 電單車
C8: Motor Cycles
C9: 無邊卡 | G9: 連邊卡 | H9: 機動三輪車 | K9: 機動三輪車 | L9: 私家車 | N9: 小計
C10: Solo | G10: Combo | K10: Motor Tricycles | N10: Sub-total
A11: 年 / 月 | C11: 首次登記 | E11: 登記總數 | F11: 領牌總數 | G11: 首次登記 | H11: 登記總數 | J11: 領牌總數 | K11: 首次登記 | L11: 登記總數 | M11: 領牌總數 | N11: 首次登記 | O11: 登記總數 | P11: 領牌總數
A12: Year/Month | C12: First Registration | E12: Total Registration | F12: Total Licensed | G12: First Registration | H12: Total Registration | J12: Total Licensed | K12: First Registration | L12: Total Registration | M12: Total Licensed | N12: First Registration | O12: Total Registration | P12: Total Licensed
A15: 2018 | C15: 5129 | E15: 79165 | F15: 54856 | G15: 11 | H15: 84 | J15: 64 | K15: 146 | L15: 671 | M15: 625 | N15: 5286 | O15: 79920 | P15: 55545
A16: 2019 | C16: 6302 | E16: 83510 | F16: 58109 | G16: 27 | H16: 111 | J16: 83 | K16: 139 | L16: 805 | M16: 745 | N16: 6468 | O16: 84426 | P16: 58937
A17: 2020 | C17: 9212 | E17: 92505 | F17: 64608 | G17: 5 | H17: 117 | J17: 75 | K17: 151 | L17: 956 | M17: 864 | N17: 9368 | O17: 93578 | P17: 65547
A18: 2021 | C18: 8988 | E18: 99386 | F18: 70843 | G18: 9 | H18: 126 | J18: 94 | K18: 95 | L18: 1045 | M18: 960 | N18: 9092 | O18: 100557 | P18: 71897
A19: 2022 | C19: 7567 | E19: 104967 | F19: 74175 | G19: 0 | H19: 125 | J19: 84 | K19: 73 | L19: 1113 | M19: 970 | N19: 7640 | O19: 106205 | P19: 75229
A24: 2022 | B24: 2 | C24: 430 | E24: 100473 | F24: 70998 | G24: 0 | H24: 126 | J24: 87 | K24: 2 | L24: 1058 | M24: 955 | N24: 432 | O24: 101657 | P24: 72040
B25: 3 | C25: 722 | E25: 101187 | F25: 70696 | G25: 0 | H25: 126 | J25: 85 | K25: 4 | L25: 1062 | M25: 943 | N25: 726 | O25: 102375 | P25: 71724
B26: 4 | C26: 682 | E26: 101865 | F26: 71375 | G26: 0 | H26: 126 | J26: 85 | K26: 6 | L26: 1068 | M26: 955 | N26: 688 | O26: 103059 | P26: 72415
B27: 5 | C27: 629 | E27: 101715 | F27: 71850 | G27: 0 | H27: 125 | J27: 86 | K27: 4 | L27: 1070 | M27: 961 | N27: 633 | O27: 102910 | P27: 72897
B28: 6 | C28: 674 | E28: 102372 | F28: 72583 | G28: 0 | H28: 125 | J28: 86 | K28: 3 | L28: 1073 | M28: 968 | N28: 677 | O28: 103570 | P28: 73637
B29: 7 | C29: 703 | E29: 103033 | F29: 72895 | G29: 0 | H29: 125 | J29: 83 | K29: 6 | L29: 1079 | M29: 964 | N29: 709 | O29: 104237 | P29: 73942
B30: 8 | C30: 571 | E30: 102584 | F30: 73145 | G30: 0 | H30: 125 | J30: 84 | K30: 4 | L30: 1080 | M30: 961 | N30: 575 | O30: 103789 | P30: 74190
B31: 9 | C31: 631 | E31: 103192 | F31: 73445 | G31: 0 | H31: 125 | J31: 84 | K31: 6 | L31: 1086 | M31: 964 | N31: 637 | O31: 104403 | P31: 74493
B32: 10 | C32: 605 | E32: 103747 | F32: 73680 | G32: 0 | H32: 125 | J32: 81 | K32: 10 | L32: 1096 | M32: 973 | N32: 615 | O32: 104968 | P32: 74734
B33: 11 | C33: 699 | E33: 104429 | F33: 73989 | G33: 0 | H33: 125 | J33: 81 | K33: 8 | L33: 1104 | M33: 974 | N33: 707 | O33: 105658 | P33: 75044
B34: 12 | C34: 556 | E34: 104967 | F34: 74175 | G34: 0 | H34: 125 | J34: 84 | K34: 9 | L34: 1113 | M34: 970 | N34: 565 | O34: 106205 | P34: 75229
A36: 2023 | B36: 1 | C36: 348 | E36: 105290 | F36: 74071 | G36: 0 | H36: 125 | J36: 83 | K36: 4 | L36: 1117 | M36: 974 | N36: 352 | O36: 106532 | P36: 75128
B37: 2 | C37: 432 | E37: 105694 | F37: 74730 | G37: 0 | H37: 125 | J37: 85 | K37: 3 | L37: 1120 | M37: 974 | N37: 435 | O37: 106939 | P37: 75789
B38: 3 | C38: 502 | E38: 106114 | F38: 74835 | G38: 1 | H38: 126 | J38: 85 | K38: 2 | L38: 1122 | M38: 970 | N38: 505 | O38: 107362 | P38: 75890
B39: 4 | C39: 363 | E39: 106450 | F39: 74174 | G39: 0 | H39: 126 | J39: 80 | K39: 5 | L39: 1127 | M39: 962 | N39: 368 | O39: 107703 | P39: 75216
B40: 5 | C40: 452 | E40: 106787 | F40: 74113 | G40: 1 | H40: 127 | J40: 85 | K40: 4 | L40: 1130 | M40: 967 | N40: 457 | O40: 108044 | P40: 75165
B41: 6 | C41: 492 | E41: 107237 | F41: 73925 | G41: 0 | H41: 127 | J41: 85 | K41: 4 | L41: 1134 | M41: 959 | N41: 496 | O41: 108498 | P41: 74969
B42: 7 | C42: 403 | E42: 107613 | F42: 73655 | G42: 0 | H42: 127 | J42: 85 | K42: 5 | L42: 1139 | M42: 949 | N42: 408 | O42: 108879 | P42: 74689
A45: 註：(1) | B45: 車輛登記 - | D45: 車輛登記是指由運輸署編配車輛登記號碼(車牌)，並將車輛予以適當分類。一部車通常只需登記一次。「首次登記」車輛數字指該期間所登記的車輛數目。「登記總數」指期末已登記的車輛總數。 | J45: Notes : (1) | K45: Vehicle Registration - | L45: Motor vehicle registration, which is normally a one-off matter, means giving the vehicle a registration mark and putting it into its appropriate class. "First registration" refers to registration during the period. "Total registration" refers to the total number of vehicles registered as at end of the period.
A49: (2) | B49: 車輛牌照 - | D49: 車輛牌照給予車輛在道路上行駛的權利，有效期分為四個月及一年兩種。「領牌總數」指期末的已領牌車輛數字。 | J49: (2) | K49: Vehicle Licence - | L49: Motor vehicle licensing conveys the right for a vehicle to be driven on a road. The valid period is either four months or a year. "Total licensed" figure refers to the total number of vehicles licensed as at end of the period.
A51: (3) | B51: 自2019年1月2日開始，有關車輛登記類別已更改；詳情請參考表格4.1(d)至(h)。 | J51: (3) | K51: The categorization of the vehicle registration status has been changed since 2.1.2019. For detailed breakdown, please refer to tables 4.1 (d) to (h).

Sheet HK TD Cars
A3: 表 4.1(a) | C3: (續) | Q3: 202307
A4: Table 4.1(a) | C4: (cont'd)
C6: 私家車
C7: Private Cars
C8: 汽油 | F8: 電力 | I8: 柴油 | L8: 其他(4) | O8: 小計
C9: Petrol | F9: Electric | I9: Diesel | L9: Other(4) | O9: Sub-total
A10: 年 / 月 | C10: 首次登記 | D10: 登記總數 | E10: 領牌總數 | F10: 首次登記 | G10: 登記總數 | H10: 領牌總數 | I10: 首次登記 | J10: 登記總數 | K10: 領牌總數 | L10: 首次登記 | M10: 登記總數 | N10: 領牌總數 | O10: 首次登記 | P10: 登記總數 | Q10: 領牌總數
A11: Year/Month | C11: First Registration | D11: Total Registration | E11: Total Licensed | F11: First Registration | G11: Total Registration | H11: Total Licensed | I11: First Registration | J11: Total Registration | K11: Total Licensed | L11: First Registration | M11: Total Registration | N11: Total Licensed | O11: First Registration | P11: Total Registration | Q11: Total Licensed
A14: 2018 | C14: 41551 | D14: 594526 | E14: 543084 | F14: 471 | G14: 11080 | H14: 10670 | I14: 265 | J14: 11999 | K14: 11399 | L14: 0 | M14: 78 | N14: 60 | O14: 42287 | P14: 617683 | Q14: 565213
A15: 2019 | C15: 35858 | D15: 602708 | E15: 549435 | F15: 2423 | G15: 13447 | H15: 13120 | I15: 28 | J15: 11981 | K15: 11312 | L15: 0 | M15: 94 | N15: 65 | O15: 38309 | P15: 628230 | Q15: 573932
A16: 2020 | C16: 32441 | D16: 621288 | E16: 544375 | F16: 4595 | G16: 17998 | H16: 17352 | I16: 0 | J16: 11968 | K16: 11197 | L16: 0 | M16: 104 | N16: 79 | O16: 37036 | P16: 651358 | Q16: 573003
A17: 2021 | C17: 29724 | D17: 617599 | E17: 542951 | F17: 9583 | G17: 27358 | H17: 26833 | I17: 2 | J17: 11906 | K17: 11150 | L17: 0 | M17: 110 | N17: 78 | O17: 39309 | P17: 656973 | Q17: 581012
A18: 2022 | C18: 17683 | D18: 591012 | E18: 514700 | F18: 19795 | G18: 46565 | H18: 45726 | I18: 0 | J18: 11849 | K18: 10919 | L18: 0 | M18: 114 | N18: 67 | O18: 37478 | P18: 649540 | Q18: 571412
A23: 2022 | B23: 2 | C23: 1047 | D23: 616790 | E23: 536260 | F23: 894 | G23: 28742 | H23: 27877 | I23: 0 | J23: 11904 | K23: 11038 | L23: 0 | M23: 111 | N23: 78 | O23: 1941 | P23: 657547 | Q23: 575253
B24: 3 | C24: 1164 | D24: 616526 | E24: 530363 | F24: 1829 | G24: 30517 | H24: 29347 | I24: 0 | J24: 11904 | K24: 10951 | L24: 0 | M24: 112 | N24: 75 | O24: 2993 | P24: 659059 | Q24: 570736
B25: 4 | C25: 1522 | D25: 616730 | E25: 531243 | F25: 407 | G25: 30854 | H25: 30089 | I25: 0 | J25: 11905 | K25: 10986 | L25: 0 | M25: 112 | N25: 69 | O25: 1929 | P25: 659601 | Q25: 572387
B26: 5 | C26: 1793 | D26: 608698 | E26: 530386 | F26: 357 | G26: 31184 | H26: 30519 | I26: 0 | J26: 11891 | K26: 10999 | L26: 0 | M26: 111 | N26: 67 | O26: 2150 | P26: 651884 | Q26: 571971
B27: 6 | C27: 1682 | D27: 608328 | E27: 529513 | F27: 1328 | G27: 32493 | H27: 31854 | I27: 0 | J27: 11885 | K27: 10980 | L27: 0 | M27: 111 | N27: 71 | O27: 3010 | P27: 652817 | Q27: 572418
B28: 7 | C28: 1562 | D28: 606967 | E28: 527377 | F28: 992 | G28: 33467 | H28: 32848 | I28: 0 | J28: 11881 | K28: 10964 | L28: 0 | M28: 111 | N28: 68 | O28: 2554 | P28: 652426 | Q28: 571257
B29: 8 | C29: 1633 | D29: 597979 | E29: 525223 | F29: 2268 | G29: 35645 | H29: 34987 | I29: 0 | J29: 11856 | K29: 10954 | L29: 0 | M29: 111 | N29: 69 | O29: 3901 | P29: 645591 | Q29: 571233
B30: 9 | C30: 1668 | D30: 596222 | E30: 522496 | F30: 2779 | G30: 38353 | H30: 37583 | I30: 0 | J30: 11855 | K30: 10905 | L30: 0 | M30: 112 | N30: 66 | O30: 4447 | P30: 646542 | Q30: 571050
B31: 10 | C31: 1448 | D31: 594055 | E31: 519595 | F31: 2955 | G31: 41259 | H31: 40422 | I31: 0 | J31: 11853 | K31: 10913 | L31: 0 | M31: 112 | N31: 65 | O31: 4403 | P31: 647279 | Q31: 570995
B32: 11 | C32: 1399 | D32: 591859 | E32: 516510 | F32: 2823 | G32: 43970 | H32: 43118 | I32: 0 | J32: 11851 | K32: 10915 | L32: 0 | M32: 114 | N32: 70 | O32: 4222 | P32: 647794 | Q32: 570613
B33: 12 | C33: 1208 | D33: 591012 | E33: 514700 | F33: 2652 | G33: 46565 | H33: 45726 | I33: 0 | J33: 11849 | K33: 10919 | L33: 0 | M33: 114 | N33: 67 | O33: 3860 | P33: 649540 | Q33: 571412
A35: 2023 | B35: 1 | C35: 1009 | D35: 589341 | E35: 513631 | F35: 1521 | G35: 48068 | H35: 47154 | I35: 0 | J35: 11847 | K35: 10944 | L35: 0 | M35: 114 | N35: 68 | O35: 2530 | P35: 649370 | Q35: 571797
B36: 2 | C36: 1278 | D36: 587503 | E36: 516744 | F36: 2613 | G36: 50665 | H36: 49912 | I36: 0 | J36: 11842 | K36: 10978 | L36: 0 | M36: 116 | N36: 69 | O36: 3891 | P36: 650126 | Q36: 577703
B37: 3 | C37: 1427 | D37: 585963 | E37: 517362 | F37: 2251 | G37: 52902 | H37: 51998 | I37: 0 | J37: 11833 | K37: 10978 | L37: 0 | M37: 118 | N37: 69 | O37: 3678 | P37: 650816 | Q37: 580407
B38: 4 | C38: 1163 | D38: 584509 | E38: 514596 | F38: 1700 | G38: 54598 | H38: 53686 | I38: 0 | J38: 11831 | K38: 10932 | L38: 0 | M38: 118 | N38: 67 | O38: 2863 | P38: 651056 | Q38: 579281
B39: 5 | C39: 1325 | D39: 581935 | E39: 512276 | F39: 2675 | G39: 57261 | H39: 56328 | I39: 0 | J39: 11818 | K39: 10913 | L39: 0 | M39: 118 | N39: 68 | O39: 4000 | P39: 651132 | Q39: 579585
B40: 6 | C40: 1410 | D40: 580159 | E40: 510605 | F40: 2544 | G40: 59796 | H40: 58798 | I40: 0 | J40: 11810 | K40: 10906 | L40: 0 | M40: 118 | N40: 67 | O40: 3954 | P40: 651883 | Q40: 580376
B41: 7 | C41: 1288 | D41: 578215 | E41: 507581 | F41: 2276 | G41: 62056 | H41: 60986 | I41: 0 | J41: 11808 | K41: 10905 | L41: 0 | M41: 119 | N41: 65 | O41: 3564 | P41: 652198 | Q41: 579537
A44: 註 : | B44: (4) | C44: 包括各種其發動機為「渦輪引擎」、「燃油電池車」等的車輛，它們的燃料種類不能進一步被劃分。 | J44: Note: | K44: (4) | L44: Including various vehicles with power plants such as turbine engines, fuel cell vehicles, etc. of which fuel types cannot be further classified.
A51: 表 4.1(a) | C51: (續)
A52: Table 4.1(a) | C52: (cont'd) | N52: 202307
C54: 的士
C55: Taxis
C56: 市區 | F56: 新界 | I56: 大嶼山 | L56: 小計
C57: Urban | F57: New Territories | I57: Lantau | L57: Sub-total
A58: 年 / 月 | C58: 首次登記 | D58: 登記總數 | E58: 領牌總數 | F58: 首次登記 | G58: 登記總數 | H58: 領牌總數 | I58: 首次登記 | J58: 登記總數 | K58: 領牌總數 | L58: 首次登記 | M58: 登記總數 | N58: 領牌總數
A59: Year/Month | C59: First Registration | D59: Total Registration | E59: Total Licensed | F59: First Registration | G59: Total Registration | H59: Total Licensed | I59: First Registration | J59: Total Registration | K59: Total Licensed | L59: First Registration | M59: Total Registration | N59: Total Licensed
...

Sheet HK TD Buses
A5: 表 4.1(a) | C5: (續)
A6: Table 4.1(a) | C6: (cont'd) | H6: 202307
C8: 公共巴士 Public Buses
C9: 專營 Franchised
C10: 九巴 KMB
C11: 單層 Single Deck | F11: 雙層 Double Deck
A12: 年 / 月 | C12: 首次登記 | D12: 登記總數 | E12: 領牌總數 | F12: 首次登記 | G12: 登記總數 | H12: 領牌總數
A13: Year/Month | C13: First Registration | D13: Total Registration | E13: Total Licensed | F13: First Registration | G13: Total Registration | H13: Total Licensed
A16: 2018 | C16: 3 | D16: 148 | E16: 147 | F16: 467 | G16: 3973 | H16: 3947
A17: 2019 | C17: 1 | D17: 144 | E17: 141 | F17: 217 | G17: 4078 | H17: 3924
A18: 2020 | C18: 0 | D18: 143 | E18: 140 | F18: 221 | G18: 3885 | H18: 3857
A19: 2021 | C19: 0 | D19: 143 | E19: 136 | F19: 142 | G19: 3892 | H19: 3865
A20: 2022 | C20: 16 | D20: 158 | E20: 149 | F20: 189 | G20: 3887 | H20: 3752
A25: 2022 | B25: 2 | C25: 0 | D25: 144 | E25: 136 | F25: 11 | G25: 3903 | H25: 3880
B26: 3 | C26: 0 | D26: 144 | E26: 136 | F26: 0 | G26: 3892 | H26: 3864
B27: 4 | C27: 1 | D27: 145 | E27: 137 | F27: 13 | G27: 3889 | H27: 3867
B28: 5 | C28: 14 | D28: 158 | E28: 150 | F28: 54 | G28: 3916 | H28: 3863
B29: 6 | C29: 0 | D29: 158 | E29: 147 | F29: 35 | G29: 3903 | H29: 3863
B30: 7 | C30: 0 | D30: 158 | E30: 149 | F30: 17 | G30: 3899 | H30: 3850
B31: 8 | C31: 0 | D31: 158 | E31: 151 | F31: 5 | G31: 3879 | H31: 3810
B32: 9 | C32: 0 | D32: 158 | E32: 151 | F32: 8 | G32: 3874 | H32: 3749
B33: 10 | C33: 0 | D33: 158 | E33: 150 | F33: 16 | G33: 3873 | H33: 3766
B34: 11 | C34: 0 | D34: 158 | E34: 149 | F34: 2 | G34: 3866 | H34: 3739
B35: 12 | C35: 0 | D35: 158 | E35: 149 | F35: 23 | G35: 3887 | H35: 3752
A37: 2023 | B37: 1 | C37: 0 | D37: 158 | E37: 147 | F37: 6 | G37: 3889 | H37: 3730
B38: 2 | C38: 0 | D38: 158 | E38: 147 | F38: 13 | G38: 3887 | H38: 3807
B39: 3 | C39: 0 | D39: 158 | E39: 150 | F39: 28 | G39: 3909 | H39: 3839
B40: 4 | C40: 0 | D40: 157 | E40: 150 | F40: 15 | G40: 3915 | H40: 3832
B41: 5 | C41: 0 | D41: 157 | E41: 147 | F41: 0 | G41: 3908 | H41: 3774
B42: 6 | C42: 0 | D42: 157 | E42: 144 | F42: 3 | G42: 3898 | H42: 3689
B43: 7 | C43: 0 | D43: 157 | E43: 147 | F43: 14 | G43: 3909 | H43: 3694
A49: 表 4.1(a) | C49: (續)
A50: Table 4.1(a) | C50: (cont'd) | N50: 202307
C52: 公共巴士 Public Buses
C53: 專營 Franchised
C54: 城巴專營 (港島及過海巴士) / 城巴專營 (市區及新界) (5) Citybus Franchise (HK & XHT) / Citybus Franchise (U & NT) (5) | I54: 城巴專營 (大嶼山) Citybus Franchise (Lantau)
C55: 單層 Single Deck | F55: 雙層 Double Deck | I55: 單層 Single Deck | L55: 雙層 Double Deck
A56: 年 / 月 | C56: 首次登記 | D56: 登記總數 | E56: 領牌總數 | F56: 首次登記 | G56: 登記總數 | H56: 領牌總數 | I56: 首次登記 | J56: 登記總數 | K56: 領牌總數 | L56: 首次登記 | M56: 登記總數 | N56: 領牌總數
A57: Year/Month | C57: First Registration | D57: Total Registration | E57: Total Licensed | F57: First Registration | G57: Total Registration | H57: Total Licensed | I57: First Registration | J57: Total Registration | K57: Total Licensed | L57: First Registration | M57: Total Registration | N57: Total Licensed
A60: 2018 | C60: 0 | D60: 38 | E60: 38 | F60: 26 | G60: 736 | H60: 707 | I60: 0 | J60: 0 | K60: 0 | L60: 28 | M60: 233 | N60: 233
...

Sheet HK TD Freight
A6: 表 4.1(a) | C6: (續)
A7: Table 4.1(a) | C7: (cont'd) | N7: 202307
C9: 貨車
C10: Goods Vehicles
C11: 輕型貨車 (8) | F11: 中型貨車 (9) | I11: 重型貨車 (10) | L11: 小計
C12: Light Goods Vehicles (8) | F12: Medium Goods Vehicles (9) | I12: Heavy Goods Vehicles (10) | L12: Sub-total
A13: 年 / 月 | C13: 首次登記 | D13: 登記總數 | E13: 領牌總數 | F13: 首次登記 | G13: 登記總數 | H13: 領牌總數 | I13: 首次登記 | J13: 登記總數 | K13: 領牌總數 | L13: 首次登記 | M13: 登記總數 | N13: 領牌總數
A14: Year/Month | C14: First Registration | D14: Total Registration | E14: Total Licensed | F14: First Registration | G14: Total Registration | H14: Total Licensed | I14: First Registration | J14: Total Registration | K14: Total Licensed | L14: First Registration | M14: Total Registration | N14: Total Licensed
A17: 2018 | C17: 6377 | D17: 74772 | E17: 72704 | F17: 2936 | G17: 37690 | H17: 36702 | I17: 552 | J17: 6609 | K17: 6398 | L17: 9865 | M17: 119071 | N17: 115804
A18: 2019 | C18: 6578 | D18: 74146 | E18: 71610 | F18: 2177 | G18: 36410 | H18: 35322 | I18: 236 | J18: 6643 | K18: 6393 | L18: 8991 | M18: 117199 | N18: 113325
A19: 2020 | C19: 4109 | D19: 76079 | E19: 74275 | F19: 1061 | G19: 36154 | H19: 35380 | I19: 257 | J19: 6810 | K19: 6634 | L19: 5427 | M19: 119043 | N19: 116289
A20: 2021 | C20: 4865 | D20: 77174 | E20: 75568 | F20: 1764 | G20: 35635 | H20: 34992 | I20: 473 | J20: 7086 | K20: 6883 | L20: 7102 | M20: 119895 | N20: 117443
A21: 2022 | C21: 5025 | D21: 78018 | E21: 75919 | F21: 1483 | G21: 35095 | H21: 33473 | I21: 485 | J21: 7362 | K21: 7004 | L21: 6993 | M21: 120475 | N21: 116396
A26: 2022 | B26: 2 | C26: 336 | D26: 77454 | E26: 75452 | F26: 80 | G26: 35676 | H26: 34927 | I26: 32 | J26: 7138 | K26: 6908 | L26: 448 | M26: 120268 | N26: 117287
B27: 3 | C27: 449 | D27: 77660 | E27: 75089 | F27: 117 | G27: 35658 | H27: 34534 | I27: 41 | J27: 7169 | K27: 6880 | L27: 607 | M27: 120487 | N27: 116503
B28: 4 | C28: 412 | D28: 77730 | E28: 75528 | F28: 82 | G28: 35584 | H28: 34320 | I28: 34 | J28: 7186 | K28: 6906 | L28: 528 | M28: 120500 | N28: 116754
B29: 5 | C29: 516 | D29: 77696 | E29: 75730 | F29: 106 | G29: 35483 | H29: 34101 | I29: 41 | J29: 7218 | K29: 6923 | L29: 663 | M29: 120397 | N29: 116754
B30: 6 | C30: 438 | D30: 77740 | E30: 75855 | F30: 171 | G30: 35462 | H30: 33995 | I30: 36 | J30: 7243 | K30: 6959 | L30: 645 | M30: 120445 | N30: 116809
B31: 7 | C31: 328 | D31: 77706 | E31: 75688 | F31: 164 | G31: 35425 | H31: 33846 | I31: 45 | J31: 7264 | K31: 6961 | L31: 537 | M31: 120395 | N31: 116495
B32: 8 | C32: 496 | D32: 77730 | E32: 75827 | F32: 144 | G32: 35348 | H32: 33752 | I32: 63 | J32: 7299 | K32: 7000 | L32: 703 | M32: 120377 | N32: 116579
B33: 9 | C33: 426 | D33: 77678 | E33: 75717 | F33: 151 | G33: 35267 | H33: 33634 | I33: 37 | J33: 7317 | K33: 7009 | L33: 614 | M33: 120262 | N33: 116360
B34: 10 | C34: 437 | D34: 77796 | E34: 75730 | F34: 112 | G34: 35219 | H34: 33603 | I34: 33 | J34: 7325 | K34: 6997 | L34: 582 | M34: 120340 | N34: 116330
B35: 11 | C35: 476 | D35: 77987 | E35: 75895 | F35: 108 | G35: 35147 | H35: 33508 | I35: 40 | J35: 7351 | K35: 7012 | L35: 624 | M35: 120485 | N35: 116415
B36: 12 | C36: 371 | D36: 78018 | E36: 75919 | F36: 115 | G36: 35095 | H36: 33473 | I36: 35 | J36: 7362 | K36: 7004 | L36: 521 | M36: 120475 | N36: 116396
A38: 2023 | B38: 1 | C38: 245 | D38: 78084 | E38: 75834 | F38: 91 | G38: 35074 | H38: 33428 | I38: 34 | J38: 7390 | K38: 7025 | L38: 370 | M38: 120548 | N38: 116287
B39: 2 | C39: 295 | D39: 78164 | E39: 76027 | F39: 73 | G39: 35037 | H39: 33790 | I39: 47 | J39: 7427 | K39: 7088 | L39: 415 | M39: 120628 | N39: 116905
B40: 3 | C40: 359 | D40: 78157 | E40: 75971 | F40: 153 | G40: 35009 | H40: 33844 | I40: 55 | J40: 7467 | K40: 7098 | L40: 567 | M40: 120633 | N40: 116913
B41: 4 | C41: 293 | D41: 78136 | E41: 75726 | F41: 100 | G41: 34976 | H41: 33813 | I41: 46 | J41: 7491 | K41: 7103 | L41: 439 | M41: 120603 | N41: 116642
B42: 5 | C42: 282 | D42: 78090 | E42: 75575 | F42: 139 | G42: 34930 | H42: 33691 | I42: 54 | J42: 7524 | K42: 7133 | L42: 475 | M42: 120544 | N42: 116399
B43: 6 | C43: 246 | D43: 78079 | E43: 75551 | F43: 129 | G43: 34907 | H43: 33629 | I43: 55 | J43: 7566 | K43: 7188 | L43: 430 | M43: 120552 | N43: 116368
B44: 7 | C44: 270 | D44: 78036 | E44: 75389 | F44: 88 | G44: 34855 | H44: 33548 | I44: 61 | J44: 7617 | K44: 7223 | L44: 419 | M44: 120508 | N44: 116160
A47: 註 : | B47: (8) | C47: 輕型貨車 - 許可車輛總重量不超過5.5公噸的貨車。 | H47: Notes : | I47: (8) | J47: Light Goods Vehicles - Goods vehicles of permitted gross vehicle weight not exceeding 5.5 tonnes.
B48: (9) | C48: 中型貨車 - 許可車輛總重量超過5.5公噸而在24公噸及以下的貨車。 | I48: (9) | J48: Medium Goods Vehicles - Goods vehicles of permitted gross vehicle weight exceeding 5.5 tonnes but not exceeding 24 tonnes.
B50: (10) | C50: 重型貨車 - 許可車輛總重量超過24公噸而在38公噸及以下的貨車。 | I50: (10) | J50: Heavy Goods Vehicles - Goods vehicles of permitted gross vehicle weight exceeding 24 tonnes but not exceeding 38 tonnes.

Sheet HD TD Gov vehicles
A6: 表 4.1(a) | C6: (續)
A7: Table 4.1(a) | C7: (cont'd) | N7: 202307
F9: 政府車輛 (12)
C10: 特別用途車輛 (11) | F10: Government Vehicles (12)
C11: Special Purpose Vehicles (11) | F11: 電單車 | I11: 其他車輛 | L11: 小計
F12: Motor Cycles | I12: Other Vehicles | L12: Sub-total
A13: 年 / 月 | C13: 首次登記 | D13: 登記總數 | E13: 領牌總數 | F13: 首次登記 | G13: 登記總數 | H13: 領牌總數 | I13: 首次登記 | J13: 登記總數 | K13: 領牌總數 | L13: 首次登記 | M13: 登記總數 | N13: 領牌總數
A14: Year/Month | C14: First Registration | D14: Total Registration | E14: Total Licensed | F14: First Registration | G14: Total Registration | H14: Total Licensed | I14: First Registration | J14: Total Registration | K14: Total Licensed | L14: First Registration | M14: Total Registration | N14: Total Licensed
A17: 2018 | C17: 169 | D17: 1970 | E17: 1763 | F17: 4 | G17: 658 | H17: 658 | I17: 922 | J17: 5716 | K17: 5716 | L17: 926 | M17: 6374 | N17: 6374
A18: 2019 | C18: 146 | D18: 2009 | E18: 1828 | F18: 0 | G18: 615 | H18: 615 | I18: 519 | J18: 5768 | K18: 5768 | L18: 519 | M18: 6383 | N18: 6383
A19: 2020 | C19: 119 | D19: 2101 | E19: 1861 | F19: 212 | G19: 687 | H19: 687 | I19: 348 | J19: 5857 | K19: 5857 | L19: 560 | M19: 6544 | N19: 6544
A20: 2021 | C20: 115 | D20: 2163 | E20: 1931 | F20: 146 | G20: 696 | H20: 696 | I20: 776 | J20: 5992 | K20: 5992 | L20: 922 | M20: 6688 | N20: 6688
A21: 2022 | C21: 137 | D21: 2233 | E21: 1981 | F21: 225 | G21: 695 | H21: 695 | I21: 553 | J21: 6120 | K21: 6120 | L21: 778 | M21: 6815 | N21: 6815
A26: 2022 | B26: 2 | C26: 7 | D26: 2181 | E26: 1935 | F26: 1 | G26: 697 | H26: 697 | I26: 10 | J26: 5999 | K26: 5999 | L26: 11 | M26: 6696 | N26: 6696
B27: 3 | C27: 16 | D27: 2197 | E27: 1916 | F27: 32 | G27: 696 | H27: 696 | I27: 100 | J27: 6050 | K27: 6050 | L27: 132 | M27: 6746 | N27: 6746
B28: 4 | C28: 12 | D28: 2208 | E28: 1944 | F28: 36 | G28: 712 | H28: 712 | I28: 85 | J28: 6105 | K28: 6105 | L28: 121 | M28: 6817 | N28: 6817
B29: 5 | C29: 7 | D29: 2192 | E29: 1956 | F29: 33 | G29: 724 | H29: 724 | I29: 54 | J29: 6125 | K29: 6125 | L29: 87 | M29: 6849 | N29: 6849
B30: 6 | C30: 13 | D30: 2205 | E30: 1970 | F30: 44 | G30: 785 | H30: 785 | I30: 45 | J30: 6151 | K30: 6151 | L30: 89 | M30: 6936 | N30: 6936
B31: 7 | C31: 14 | D31: 2219 | E31: 1973 | F31: 33 | G31: 760 | H31: 760 | I31: 23 | J31: 6141 | K31: 6141 | L31: 56 | M31: 6901 | N31: 6901
B32: 8 | C32: 18 | D32: 2197 | E32: 1979 | F32: 18 | G32: 750 | H32: 750 | I32: 33 | J32: 6136 | K32: 6136 | L32: 51 | M32: 6886 | N32: 6886
B33: 9 | C33: 10 | D33: 2208 | E33: 1979 | F33: 0 | G33: 706 | H33: 706 | I33: 34 | J33: 6130 | K33: 6130 | L33: 34 | M33: 6836 | N33: 6836
B34: 10 | C34: 11 | D34: 2216 | E34: 1979 | F34: 0 | G34: 705 | H34: 705 | I34: 38 | J34: 6131 | K34: 6131 | L34: 38 | M34: 6836 | N34: 6836
B35: 11 | C35: 8 | D35: 2222 | E35: 1980 | F35: 0 | G35: 694 | H35: 694 | I35: 30 | J35: 6112 | K35: 6112 | L35: 30 | M35: 6806 | N35: 6806
B36: 12 | C36: 10 | D36: 2233 | E36: 1981 | F36: 6 | G36: 695 | H36: 695 | I36: 57 | J36: 6120 | K36: 6120 | L36: 63 | M36: 6815 | N36: 6815
A38: 2023 | B38: 1 | C38: 3 | D38: 2236 | E38: 1968 | F38: 13 | G38: 692 | H38: 692 | I38: 37 | J38: 6146 | K38: 6146 | L38: 50 | M38: 6838 | N38: 6838
B39: 2 | C39: 6 | D39: 2239 | E39: 1975 | F39: 0 | G39: 696 | H39: 696 | I39: 34 | J39: 6153 | K39: 6153 | L39: 34 | M39: 6849 | N39: 6849
B40: 3 | C40: 13 | D40: 2251 | E40: 1983 | F40: 5 | G40: 698 | H40: 698 | I40: 68 | J40: 6164 | K40: 6164 | L40: 73 | M40: 6862 | N40: 6862
B41: 4 | C41: 11 | D41: 2261 | E41: 1971 | F41: 28 | G41: 718 | H41: 718 | I41: 79 | J41: 6159 | K41: 6159 | L41: 107 | M41: 6877 | N41: 6877
B42: 5 | C42: 11 | D42: 2271 | E42: 1968 | F42: 8 | G42: 725 | H42: 725 | I42: 51 | J42: 6159 | K42: 6159 | L42: 59 | M42: 6884 | N42: 6884
B43: 6 | C43: 7 | D43: 2278 | E43: 1964 | F43: 0 | G43: 725 | H43: 725 | I43: 62 | J43: 6165 | K43: 6165 | L43: 62 | M43: 6890 | N43: 6890
B44: 7 | C44: 8 | D44: 2285 | E44: 1960 | F44: 0 | G44: 723 | H44: 723 | I44: 35 | J44: 6172 | K44: 6172 | L44: 35 | M44: 6895 | N44: 6895
A48: 註 : | B48: (11) | C48: 不包括只在工業用地及建築用地內使用的貨車。 | H48: Notes : | I48: (11) | J48: Excluding goods vehicles used solely within industrial and construction sites.
B49: (12) | C49: 不包括軍部車輛。 | I49: (12) | J49: Excluding military vehicles.

Sheet EV
A1: https://www.epd.gov.hk/epd/english/environmentinhk/air/prob_solutions/promotion_ev.html
A2: https://www.td.gov.hk/filemanager/en/content_5217/2307_e.pdf
A4: As of the end of August 2023, the total number of EVs has risen to 65,935, which represents 7.1% of the vehicle fleet in Hong Kong.
A5: As of the time of updating, July 2023 is the most updated Traffic Digest avaiable and provides the breakdown of registsered electric vehicles is as follows:
C6: Motorcycles | E6: 400
C7: Taxis | E7: 5
C8: Buses | E8: 66
C9: Goods Vehicles | E9: 437
C10: Special Purpose | E10: 133
C11: Government | E11: 127
A16: NOTE --> these figures only take into account pure electric vehicles and not hybrid cars

Sheet Diesel Gasoline split
C42: Fraction of Diesel cars: | F42: =10905/('HK TD Cars'!Q18+'HK TD Cars'!N66+'HD TD Gov vehicles'!K20) -> 0.018318618
C43: Fraction of gasoline cars: | F43: =1-F42 -> 0.98168138
C45: Fraction of Diesel buses: | F45: =(13106+3002)/('HK TD Buses'!K205 + 'HK TD Buses'!K253 +'HK TD Buses'!K297+'HK TD Buses'!N297) -> 0.77974635
C46: Fraction of gasoline buses: | F46: =1-F45 -> 0.22025365

Sheet Vehicle Fuel Type
A1: 表 4.4 | B1: : 按燃料種類劃分的車輛登記及領牌統計數字 (二零一七年六月)
A2: Table 4.4 : Registration and Licensing of Vehicles by Fuel Type (July 2023)
C3: =SUM('Vehicle Fuel Type'!H15:H22) -> 60991 | E3: ='Vehicle Fuel Type'!H15+'Vehicle Fuel Type'!H17 -> 60991
C5: 汽油 | E5: 柴油 | G5: 電力 | I5: 石油氣 | K5: 其他 | M5: 總計
C6: Petrol | E6: Diesel | G6: Electric | I6: LP Gas | K6: Others (1) | M6: Total
C7: 登記總數 | D7: 領牌總數 | E7: 登記總數 | F7: 領牌總數 | G7: 登記總數 | H7: 領牌總數 | I7: 登記總數 | J7: 領牌總數 | K7: 登記總數 | L7: 領牌總數 | M7: 登記總數 | N7: 領牌總數
C8: Registered | D8: Licensed | E8: Registered | F8: Licensed | G8: Registered | H8: Licensed | I8: Registered | J8: Licensed | K8: Registered | L8: Licensed | M8: Registered | N8: Licensed
A9: 電單車 (無邊卡) | C9: 107224 | D9: 73287 | E9: - | F9: - | G9: 389 | H9: 368 | I9: - | J9: - | K9: - | L9: - | M9: 107613 | N9: 73655
A10: Motor Cycles (Solo)
A11: 電單車 (連邊卡) | C11: 127 | D11: 85 | E11: - | F11: - | G11: - | H11: - | I11: - | J11: - | K11: - | L11: - | M11: 127 | N11: 65
A12: Motor Cycles (Combo)
A13: 機動三輪車 | C13: 1128 | D13: 938 | E13: - | F13: - | G13: 11 | H13: 11 | I13: - | J13: - | K13: - | L13: - | M13: 1139 | N13: 949
A14: Motor Tricycles
A15: 私家車 | C15: 578215 | D15: 507581 | E15: 11808 | F15: 10905 | G15: 62056 | H15: 60986 | I15: - | J15: - | K15: 119 | L15: 65 | M15: 652198 | N15: 579537
A16: Private Cars
A17: 的士 (市區) | C17: 11 | D17: 11 | E17: - | F17: - | G17: 5 | H17: 5 | I17: 15234 | J17: 15000 | K17: - | L17: - | M17: 15250 | N17: 15016
A18: Taxis (Urban)
A19: 的士 (新界) | C19: 3 | D19: 3 | E19: - | F19: - | G19: - | H19: - | I19: 2835 | J19: 2718 | K19: - | L19: - | M19: 2838 | N19: 2721
A20: Taxis (NT)
A21: 的士 (大嶼山) | C21: - | D21: - | E21: - | F21: - | G21: - | H21: - | I21: 75 | J21: 74 | K21: - | L21: - | M21: 75 | N21: 74
A22: Taxis (Lantau)
A23: 九巴 | B23: 單層 SD | C23: - | D23: - | E23: 125 | F23: 123 | G23: 32 | H23: 24 | I23: - | J23: - | K23: - | L23: - | M23: 157 | N23: 147
A24: KMB | B24: 雙層 DD | C24: - | D24: - | E24: 3907 | F24: 3692 | G24: 2 | H24: 2 | I24: - | J24: - | K24: - | L24: - | M24: 3909 | N24: 3694
A25: 城巴 | B25: 單層 SD | C25: - | D25: - | E25: 41 | F25: 17 | G25: 7 | H25: 4 | I25: - | J25: - | K25: - | L25: - | M25: 48 | N25: 21
A26: Citybus | B26: 雙層 DD | C26: - | D26: - | E26: 1685 | F26: 1490 | G26: 1 | H26: 1 | I26: - | J26: - | K26: - | L26: - | M26: 1686 | N26: 1491
A27: 龍運 | B27: 單層 SD | C27: - | D27: - | E27: - | F27: - | G27: 4 | H27: 4 | I27: - | J27: - | K27: - | L27: - | M27: 4 | N27: 4
A28: LWB | B28: 雙層 DD | C28: - | D28: - | E28: 284 | F28: 275 | G28: - | H28: - | I28: - | J28: - | K28: - | L28: - | M28: 284 | N28: 275
A29: 新大嶼山巴士 | B29: 單層 SD | C29: - | D29: - | E29: 90 | F29: 77 | G29: 4 | H29: 4 | I29: - | J29: - | K29: - | L29: - | M29: 94 | N29: 81
A30: NLB | B30: 雙層 DD | C30: - | D30: - | E30: 59 | F30: 59 | G30: - | H30: - | I30: - | J30: - | K30: - | L30: - | M30: 59 | N30: 59
A31: 港鐵巴士 (西鐵線/輕鐵) | B31: 單層 SD | C31: - | D31: - | E31: 11 | F31: 11 | G31: - | H31: - | I31: - | J31: - | K31: - | L31: - | M31: 11 | N31: 11
A32: MTR Buses (for West Rail Line/Light
A33: Rail) | B33: 雙層 DD | C33: - | D33: - | E33: 140 | F33: 138 | G33: 0 | H33: - | I33: - | J33: - | K33: - | L33: - | M33: 140 | N33: 138
A34: 其他非專營公共巴士 | B34: 單層 SD | C34: - | D34: - | E34: 6549 | F34: 6223 | G34: 10 | H34: 5 | I34: - | J34: - | K34: - | L34: - | M34: 6559 | N34: 6228
A35: Other Non-franchised Public Buses | B35: 雙層 DD | C35: - | D35: - | E35: 178 | F35: 176 | G35: - | H35: - | I35: - | J35: - | K35: - | L35: - | M35: 178 | N35: 176
A36: 私家巴士 | B36: 單層 SD | C36: - | D36: - | E36: 814 | F36: 800 | G36: 2 | H36: 2 | I36: - | J36: - | K36: - | L36: - | M36: 816 | N36: 800
A37: Private Buses | B37: 雙層 DD | C37: - | D37: - | E37: 29 | F37: 28 | G37: - | H37: - | I37: - | J37: - | K37: - | L37: - | M37: 29 | N37: 28
A38: 公共小型巴士 | C38: - | D38: - | E38: 75 | F38: 716 | G38: - | H38: - | I38: 3594 | J38: 3392 | K38: - | L38: - | M38: 4349 | N38: 4108
A39: Public Light Buses
A40: 私家小型巴士 | C40: - | D40: - | E40: 2332 | F40: 2286 | G40: 6 | H40: 3 | I40: 1122 | J40: 1116 | K40: - | L40: - | M40: 3460 | N40: 3405
A41: Private Light Buses
...

Sheet MTR
A1: Railway Operations | C1: 2019 | D1: 2020 | E1: 2021 | G1: 1 | H1: MW | I1: = | J1: 3412141.6 | K1: btu
A2: Electricity Consumption in Hong Kong (MWh) | B2: Heavy Rail | C2: 1559734 | D2: 1484030 | E2: 1503677 | G2: 0.000293071 | H2: KWh | I2: = | J2: 1 | K2: btu
B3: Light Rail | C3: 53341 | D3: 50461 | E3: 51534
A5: Electricity Consumption in Hong Kong (BTU) | B5: Domestic and Cross-boundary services | C5: =C2*$J$1 -> 5.3220333e+12 | D5: =D2*$J$1 -> 5.0637205e+12 | E5: =E2*$J$1 -> 5.1307589e+12
B6: Light Rail | C6: =C3*$J$1 -> 1.8200705e+11 | D6: =D3*$J$1 -> 1.7218008e+11 | E6: =E3*$J$1 -> 1.7584131e+11
A8: Revenue car-km operated (thousand) | B8: Domestic and Cross-boundary services | C8: 301552 | D8: 268492 | E8: 268050
B9: Airport Express | C9: 22971 | D9: 12631 | E9: 12328
B10: Heavy Rail | C10: =C8+C9 -> 324523 | D10: =D8+D9 -> 281123 | E10: =E8+E9 -> 280378
B11: Light Rail | C11: 10592 | D11: 10385 | E11: 9727
A13: Total number of passengers (thousand) | B13: Domestic and Cross-boundary services | C13: =1568196+104183 -> 1672379 | D13: =1145035+7647 -> 1152682 | E13: =1334591+486 -> 1335077
B14: Airport Express | C14: 15764 | D14: 3070 | E14: 3102
B15: Heavy Rail | C15: =C13+C14 -> 1688143 | D15: =D13+D14 -> 1155752 | E15: =E13+E14 -> 1338179
B16: Light Rail | C16: 155885 | D16: 111865 | E16: 141581
A18: Average passenger km travelled | B18: Domestic and Cross-boundary services | C18: 10.6 | D18: 10.5 | E18: 10.7
B19: Airport Express | C19: 28.2 | D19: 25.8 | E19: 23.7
B20: Light Rail | C20: 2.7 | D20: 2.8 | E20: 2.6
A22: Average car occupancy (number of passengers) | B22: Domestic and Cross-boundary services | C22: 59 | D22: 45 | E22: 54
B23: Airport Express | C23: 19 | D23: 6 | E23: 5
B24: Light Rail | C24: 40 | D24: 30 | E24: 37
A26: Number of train cars | B26: Domestic and Cross-boundary services | C26: 2083 | D26: 2083 | E26: 2083
B27: Airport Express | C27: 88 | D27: 88 | E27: 88
B28: Heavy Rail | C28: =C26+C27 -> 2171 | D28: =D26+D27 -> 2171 | E28: =E26+E27 -> 2171
B29: Light Rail | C29: 146 | D29: 146 | E29: 146
A31: Number of train (assume 8 car per train, except light rail) | B31: Domestic and Cross-boundary services | C31: =C26/8 -> 260.375 | D31: =D26/8 -> 260.375 | E31: =E26/8 -> 260.375
B32: Airport Express | C32: =C27/8 -> 11 | D32: =D27/8 -> 11 | E32: =E27/8 -> 11
B33: Heavy Rail | C33: =C32+C31 -> 271.375 | D33: =D32+D31 -> 271.375 | E33: =E32+E31 -> 271.375
B34: Light Rail | C34: =C29 -> 146 | D34: =D29 -> 146 | E34: =E29 -> 146
A36: Revenue car-km operated (thousand) | B36: Domestic and Cross-boundary services | C36: =C8/C26 -> 144.76812 | D36: =D8/D26 -> 128.89678 | E36: =E8/E26 -> 128.68459
B37: Airport Express | C37: =C9/C27 -> 261.03409 | D37: =D9/D27 -> 143.53409 | E37: =E9/E27 -> 140.09091
B38: Heavy Rail | C38: =C37+C36 -> 405.80221 | D38: =D37+D36 -> 272.43087 | E38: =E37+E36 -> 268.7755
B39: Light Rail | C39: =C11/C29 -> 72.547945 | D39: =D11/D29 -> 71.130137 | E39: =E11/E29 -> 66.623288
A41: Energy consumption train BTU/ km/car | B41: Domestic and Cross-boundary services | C41: =C5/C8/1000 -> 17648.808 | D41: =D5/D8/1000 -> 18859.856 | E41: =E5/E8/1000 -> 19141.052
B42: Light Rail | C42: =C6/C9/1000 -> 7923.3402 | D42: =D6/D9/1000 -> 13631.548 | E42: =E6/E9/1000 -> 14263.571
A44: Energy consumption train BTU/ km / train | B44: Domestic and Cross-boundary services | C44: =C41*8 -> 141190.46 | D44: =D41*8 -> 150878.85 | E44: =E41*8 -> 153128.41
A45: (assume 8 car per train, except light rail) | B45: Light Rail | C45: =C42 -> 7923.3402 | D45: =D42 -> 13631.548 | E45: =E42 -> 14263.571
A47: Energy consumption train KWh/ km / train | B47: Domestic and Cross-boundary services | C47: =C44*$G$2 -> 41.37883 | D47: =D44*$G$2 -> 44.218216 | E47: =E44*$G$2 -> 44.877497
A48: (assume 8 car per train, except light rail) | B48: Light Rail | C48: =C45*$G$2 -> 2.3221012 | D48: =D45*$G$2 -> 3.9950113 | E48: =E45*$G$2 -> 4.1802391
A50: Total cargo distance (thousand KM * people) | B50: Domestic and Cross-boundary services | C50: =C26*C22*C36 -> 17791568 | D50: =D26*D22*D36 -> 12082140 | E50: =E26*E22*E36 -> 14474700
B51: Airport Express | C51: =C27*C23*C37 -> 436449 | D51: =D27*D23*D37 -> 75786 | E51: =E27*E23*E37 -> 61640
B52: Heavy Rail | C52: =C50+C51 -> 18228017 | D52: =D50+D51 -> 12157926 | E52: =E50+E51 -> 14536340
...

Sheet Non-road Vehicles
B1: Passenger | C1: Freight
A2: Ships | B2: 14174 | C2: 2014
A3: Aircrafts | B3: 174 | C3: 20

Sheet Ferries
S27: ›
B62: We use the number of dangerous goods carriers and dry cargo vessel as proxy for the number of freight boats.
C64: Year Taken from: 2022
C65: =27+111 -> 138

Sheet Fuel Type
C1: Petrol | D1: Diesel | E1: Electric | F1: LP Gas | G1: Others (1) | H1: Total
A2: Motorcycles (P) | C2: ='Vehicle Fuel Type'!C9+'Vehicle Fuel Type'!C11+'Vehicle Fuel Type'!C13 -> 108479 | E2: ='Vehicle Fuel Type'!G9 -> 389
A3: Motorcycles (F) | B3: Taxis | C3: ='Vehicle Fuel Type'!C17 -> 11 | E3: ='Vehicle Fuel Type'!G17 -> 5 | F3: ='Vehicle Fuel Type'!I17+'Vehicle Fuel Type'!I19+'Vehicle Fuel Type'!I21 -> 18144
A4: LDVs (P) | C4: ='Vehicle Fuel Type'!C15 -> 578215 | D4: ='Vehicle Fuel Type'!E15 -> 11808 | E4: ='Vehicle Fuel Type'!G15+'Vehicle Fuel Type'!G17 -> 62061 | G4: ='Vehicle Fuel Type'!K15 -> 119
A5: HDVs (P) | D5: =SUM('Vehicle Fuel Type'!E23:E40) -> 16319 | E5: =SUM('Vehicle Fuel Type'!G23:G40) -> 68 | F5: =SUM('Vehicle Fuel Type'!I23:I40) -> 4716
A6: LDVs (F) | C6: ='Vehicle Fuel Type'!C42 -> 480 | D6: ='Vehicle Fuel Type'!E42 -> 77122 | E6: ='Vehicle Fuel Type'!G42 -> 434
A7: HDVs (F) | C7: ='Vehicle Fuel Type'!C48 -> 53 | D7: ='Vehicle Fuel Type'!E44+'Vehicle Fuel Type'!E46+'Vehicle Fuel Type'!E48 -> 44384 | E7: ='Vehicle Fuel Type'!G48 -> 133 | F7: ='Vehicle Fuel Type'!I48 -> 182 | G7: ='Vehicle Fuel Type'!K48 -> 2
A8: Ships (P) | H8: =Ships!B28 -> 14174
A9: Air (P) | H9: =Air!C27 -> 210
A10: Ships (F) | H10: =Ships!B33 -> 2014
A11: Air (F) | H11: =Air!C5 -> 15
A13: Note: We use Freight Motorcycles category for taxis

Sheet Ships
A1: Vessel | B1: Number | C1: Type (G, I, C)
A2: Ferry Vessel | B2: 46 | C2: IP
A3: Launch | B3: 365 | C3: IP
A4: Multi-purpose Vessel | B4: 15 | C4: IF
A5: Tug | B5: 188 | C5: IF
A6: Dangerous Goods Carrier | B6: 27 | C6: IF
A7: Dredger | B7: 3 | C7: IF
A8: Dry Cargo Vessel | B8: 111 | C8: IF
A9: Edible Oil Carrier | B9: 10 | C9: IF
A10: Noxious Liquid Substance Carrier | B10: 0 | C10: IF
A11: Oil Carrier | B11: 161 | C11: IF
A12: Pilot Boat | B12: 24 | C12: IF
A13: Special Purpose Vessel | B13: 72 | C13: IF
... A23: Governmnet Launch | B23: 1002 | C23: GP
A24: Total | B24: =SUM(B2:B23) -> 16188
A26: **113 government marine
A28: Passenger Ships | B28: =SUM(B20:B22,B14:B17,B2:B3,B23) -> 14174
A29: Freight Ships | B29: =SUM(B18:B19,B4:B13) -> 2014
A30: Consumer Passenger | B30: =SUM(B20:B22) -> 12378
A31: Industry Passenger | B31: =SUM(B14:B17,B2:B3) -> 794
A32: Government Passenger | B32: =B23 -> 1002
A33: Industry Ferry | B33: =SUM(B18:B19,B4:B13) -> 2014

Sheet SYVbT-passenger
B1: battery electric vehicle | C1: natural gas vehicle | D1: gasoline vehicle | E1: diesel vehicle | F1: plugin hybrid vehicle | G1: LPG vehicle | H1: hydrogen vehicle
A2: LDVs | B2: ='Fuel Type'!E4 -> 62061 | C2: 0 | D2: ='Fuel Type'!C4 -> 578215 | E2: ='Fuel Type'!D4 -> 11808 | F2: ='Fuel Type'!G4 -> 119 | G2: ='Fuel Type'!F3 -> 18144 | H2: 0
A3: HDVs | B3: ='Fuel Type'!E5 -> 68 | C3: 0 | D3: 0 | E3: ='Fuel Type'!D5 -> 16319 | F3: 0 | G3: ='Fuel Type'!F5 -> 4716 | H3: 0
A4: aircraft | B4: 0 | C4: 0 | D4: 0 | E4: 0 | F4: 0 | G4: 0 | H4: 0
A5: rail | B5: =MTR!E33 -> 271.375 | C5: 0 | D5: 0 | E5: 0 | F5: 0 | G5: 0 | H5: 0
A6: ships | B6: 0 | C6: 0 | D6: 0 | E6: 0 | F6: 0 | G6: 0 | H6: 0
A7: motorbikes | B7: ='Fuel Type'!E2 -> 389 | C7: 0 | D7: ='Fuel Type'!C2 -> 108479 | E7: 0 | F7: 0 | G7: 0 | H7: 0

Sheet SYVbT-freight
B1: battery electric vehicle | C1: natural gas vehicle | D1: gasoline vehicle | E1: diesel vehicle | F1: plugin hybrid vehicle | G1: LPG vehicle | H1: hydrogen vehicle
A2: LDVs | B2: ='Fuel Type'!E6 -> 434 | C2: 0 | D2: ='Fuel Type'!C6 -> 480 | E2: ='Fuel Type'!D6 -> 77122 | F2: ='Fuel Type'!G6 -> 0 | G2: ='Fuel Type'!F6 -> 0 | H2: 0
A3: HDVs | B3: ='Fuel Type'!E7 -> 133 | C3: 0 | D3: ='Fuel Type'!C7 -> 53 | E3: ='Fuel Type'!D7 -> 44384 | F3: ='Fuel Type'!G7 -> 2 | G3: ='Fuel Type'!F7 -> 182 | H3: 0
A4: aircraft | B4: 0 | C4: 0 | D4: 0 | E4: 0 | F4: 0 | G4: 0 | H4: 0
A5: rail | B5: 0 | C5: 0 | D5: 0 | E5: 0 | F5: 0 | G5: 0 | H5: 0
A6: ships | B6: 0 | C6: 0 | D6: 0 | E6: 0 | F6: 0 | G6: 0 | H6: 0
A7: motorbikes | B7: ='Fuel Type'!E3 -> 5 | C7: 0 | D7: ='Fuel Type'!C3 -> 11 | E7: 0 | F7: 0 | G7: ='Fuel Type'!F3 -> 18144 | H7: 0

Sheet _56F9DC9755BA473782653E2940F9
A1: H6xrR7I22UqGmc2mutH4Yq3_1cZmZKxHmcZ_ItVFhVdUMjU0QUpHQldKVTlUUzNUVDhBU1VMUjk4NCQlQCN0PWcu
A2: Form2
A3: {3e8ee12f-b9ec-4a22-8587-d20e6899a3d9}
