Workbook

Sheet About
A1: BLAPE BAU LULUCF Anthropogenic Pollutant Emissions
A3: Source: | B3: US EPA
B4: 2021
B5: Draft Inventory of US Greenhouse Gas Emissions Emissions and Sinks
B6: https://www.epa.gov/sites/production/files/2021-02/documents/us-ghg-inventory-2021-main-text.pdf
B7: Table 6-1, page 6-3 (467)
A9: CH4 GWP | B9: 28
A10: N2O GWP | B10: 265
A12: Notes
A13: We project the 1990-2020 trend forward to 2050.
A15: Hong Kong data
A16: The People’s Republic of China Third Biennial Update Report on Climate Change
A17: 2023
A18: P.41
A19: https://unfccc.int/sites/default/files/resource/China_BUR3_English.pdf
B21: follow the us trend

Sheet Calcs
A1: Excerpt from Table 3:
A2: Emissions (Tg CO2e)
B3: 2018 | C3: 2019 | D3: 2020 | E3: 2021 | F3: 2022 | G3: 2023 | H3: 2024 | I3: 2025 | J3: 2026 | K3: 2027 | L3: 2028 | M3: 2029 | N3: 2030 | O3: 2031 | P3: 2032 | Q3: 2033 | R3: 2034 | S3: 2035 | T3: 2036 | U3: 2037 | V3: 2038 | W3: 2039 | X3: 2040 | Y3: 2041 | Z3: 2042 | AA3: 2043 | AB3: 2044 | AC3: 2045 | AD3: 2046 | AE3: 2047 | AF3: 2048 | AG3: 2049 | AH3: 2050
A4: Land Use and Forestry (CO2) | B4: -0.4632 | C4: -0.4632 | D4: -0.4632 | E4: -0.4632 | F4: -0.4632 | G4: -0.4632 | H4: -0.4632 | I4: -0.4632 | J4: -0.4632 | K4: -0.4632 | L4: -0.4632 | M4: -0.4632 | N4: -0.4632 | O4: -0.4632 | P4: -0.4632 | Q4: -0.4632 | R4: -0.4632 | S4: -0.4632 | T4: -0.4632 | U4: -0.4632 | V4: -0.4632 | W4: -0.4632 | X4: -0.4632 | Y4: -0.4632 | Z4: -0.4632 | AA4: -0.4632 | AB4: -0.4632 | AC4: -0.4632 | AD4: -0.4632 | AE4: -0.4632 | AF4: -0.4632 | AG4: -0.4632 | AH4: -0.4632
A5: Land Use and Forestry (CH4) | B5: 0 | C5: 0 | D5: 0 | E5: 0 | F5: 0 | G5: 0 | H5: 0 | I5: 0 | J5: 0 | K5: 0 | L5: 0 | M5: 0 | N5: 0 | O5: 0 | P5: 0 | Q5: 0 | R5: 0 | S5: 0 | T5: 0 | U5: 0 | V5: 0 | W5: 0 | X5: 0 | Y5: 0 | Z5: 0 | AA5: 0 | AB5: 0 | AC5: 0 | AD5: 0 | AE5: 0 | AF5: 0 | AG5: 0 | AH5: 0
A6: Land Use and Forestry (N2O) | B6: 0 | C6: 0 | D6: 0 | E6: 0 | F6: 0 | G6: 0 | H6: 0 | I6: 0 | J6: 0 | K6: 0 | L6: 0 | M6: 0 | N6: 0 | O6: 0 | P6: 0 | Q6: 0 | R6: 0 | S6: 0 | T6: 0 | U6: 0 | V6: 0 | W6: 0 | X6: 0 | Y6: 0 | Z6: 0 | AA6: 0 | AB6: 0 | AC6: 0 | AD6: 0 | AE6: 0 | AF6: 0 | AG6: 0 | AH6: 0
A9: We assume that all of the sequestered CO2e in the Land Use and Forestry sector is in the form of
A10: CO2, not other GHGs.
AF11: Start Year Forecast
A12: EPS | B12: 1990 | C12: 1991 | D12: 1992 | E12: 1993 | F12: 1994 | G12: 1995 | H12: 1996 | I12: 1997 | J12: 1998 | K12: 1999 | L12: 2000 | M12: 2001 | N12: 2002 | O12: 2003 | P12: 2004 | Q12: 2005 | R12: 2006 | S12: 2007 | T12: 2008 | U12: 2009 | V12: 2010 | W12: 2011 | X12: 2012 | Y12: 2013 | Z12: 2014 | AA12: 2015 | AB12: 2016 | AC12: 2017 | AD12: 2018 | AE12: 2019 | AF12: 2020
A13: CO2 | B13: ='EPA Table 6-1'!B42 -> -892 | C13: ='EPA Table 6-1'!C42 -> -900.6 | D13: ='EPA Table 6-1'!D42 -> -891.2 | E13: ='EPA Table 6-1'!E42 -> -873 | F13: ='EPA Table 6-1'!F42 -> -889.6 | G13: ='EPA Table 6-1'!G42 -> -860.3 | H13: ='EPA Table 6-1'!H42 -> -883.3 | I13: ='EPA Table 6-1'!I42 -> -861.5 | ... AF13: ='EPA Table 6-1'!AF42 -> -812.2
A14: CH4 | B14: ='EPA Table 6-1'!B40 -> 27.2 | C14: ='EPA Table 6-1'!C40 -> 26.5 | D14: ='EPA Table 6-1'!D40 -> 25.4 | E14: ='EPA Table 6-1'!E40 -> 25.3 | F14: ='EPA Table 6-1'!F40 -> 26.8 | G14: ='EPA Table 6-1'!G40 -> 25 | H14: ='EPA Table 6-1'!H40 -> 26.2 | I14: ='EPA Table 6-1'!I40 -> 24.7 | ... AF14: ='EPA Table 6-1'!AF40 -> 38.1
A15: N2O | B15: ='EPA Table 6-1'!B41 -> 4.2 | C15: ='EPA Table 6-1'!C41 -> 4.2 | D15: ='EPA Table 6-1'!D41 -> 3.4 | E15: ='EPA Table 6-1'!E41 -> 3.5 | F15: ='EPA Table 6-1'!F41 -> 5.2 | G15: ='EPA Table 6-1'!G41 -> 3.5 | H15: ='EPA Table 6-1'!H41 -> 5 | I15: ='EPA Table 6-1'!I41 -> 3.4 | ... AF15: ='EPA Table 6-1'!AF41 -> 15.2

Sheet EPA Table 6-1
A1: Table 6-1: Emissions and Removals (Net Flux) from Land Use, Land-Use Change, and Forestry (MMT CO2 Eq.)
A3: Land-Use Category | B3: 1990 | C3: 1991 | D3: 1992 | E3: 1993 | F3: 1994 | G3: 1995 | H3: 1996 | I3: 1997 | J3: 1998 | K3: 1999 | L3: 2000 | M3: 2001 | N3: 2002 | O3: 2003 | P3: 2004 | Q3: 2005 | R3: 2006 | S3: 2007 | T3: 2008 | U3: 2009 | V3: 2010 | W3: 2011 | X3: 2012 | Y3: 2013 | Z3: 2014 | AA3: 2015 | AB3: 2016 | AC3: 2017 | AD3: 2018 | AE3: 2019 | AF3: 2020
A4: Forest Land Remaining Forest Land | B4: -769.7 | C4: -774.3 | D4: -776.4 | E4: -773.5 | F4: -763.9 | G4: -757.1 | H4: -757.8 | I4: -753.7 | J4: -748.1 | K4: -732.9 | L4: -706.8 | M4: -715 | N4: -668.9 | O4: -705 | P4: -615.8 | Q4: -674 | R4: -699.3 | S4: -668.3 | T4: -658.8 | U4: -635.5 | V4: -672 | W4: -683.1 | X4: -674.2 | Y4: -666.9 | Z4: -692.8 | AA4: -606.6 | AB4: -717.3 | AC4: -670.1 | AD4: -664.6 | AE4: -631.8 | AF4: -642.2
A5: Changes in Forest Carbon Stocksa | B5: -774 | C5: -778 | D5: -777.8 | E5: -774.9 | F5: -768.3 | G5: -758.2 | H5: -760.9 | I5: -754.6 | J5: -749.8 | K5: -737.9 | L5: -716.2 | M5: -719.2 | N5: -682.6 | O5: -714.4 | P5: -634.5 | Q5: -687.3 | R5: -708.1 | S5: -682.2 | T5: -667 | U5: -645.5 | V5: -675.7 | W5: -690.5 | X5: -684.5 | Y5: -677.2 | Z5: -698.6 | AA5: -628.4 | AB5: -725.6 | AC5: -688.3 | AD5: -677.1 | AE5: -634.8 | AF5: -668.1
A6: Non-CO2 Emissions from Forest Firesb | B6: 4.1 | C6: 3.5 | D6: 1.2 | E6: 1.1 | F6: 4.2 | G6: 0.8 | H6: 2.6 | I6: 0.4 | J6: 1.2 | K6: 4.4 | L6: 8.8 | M6: 3.6 | N6: 13.1 | O6: 8.8 | P6: 18.2 | Q6: 12.8 | R6: 8.3 | S6: 13.3 | T6: 7.6 | U6: 9.5 | V6: 3.2 | W6: 6.9 | X6: 9.8 | Y6: 9.8 | Z6: 5.3 | AA6: 21.3 | AB6: 7.8 | AC6: 17.7 | AD6: 11.9 | AE6: 2.5 | AF6: 25.3
A7: N2O Emissions from Forest Soilsc | B7: 0.1 | C7: 0.1 | D7: 0.1 | E7: 0.2 | F7: 0.2 | G7: 0.3 | H7: 0.4 | I7: 0.4 | J7: 0.4 | K7: 0.6 | L7: 0.5 | M7: 0.5 | N7: 0.6 | O7: 0.5 | P7: 0.5 | Q7: 0.5 | R7: 0.5 | S7: 0.5 | T7: 0.5 | U7: 0.5 | V7: 0.5 | W7: 0.5 | X7: 0.5 | Y7: 0.5 | Z7: 0.5 | AA7: 0.5 | AB7: 0.5 | AC7: 0.5 | AD7: 0.5 | AE7: 0.5 | AF7: 0.5
A8: Non-CO2 Emissions from Drained Organic Soilsd | B8: 0.1 | C8: 0.1 | D8: 0.1 | E8: 0.1 | F8: 0.1 | G8: 0.1 | H8: 0.1 | I8: 0.1 | J8: 0.1 | K8: 0.1 | L8: 0.1 | M8: 0.1 | N8: 0.1 | O8: 0.1 | P8: 0.1 | Q8: 0.1 | R8: 0.1 | S8: 0.1 | T8: 0.1 | U8: 0.1 | V8: 0.1 | W8: 0.1 | X8: 0.1 | Y8: 0.1 | Z8: 0.1 | AA8: 0.1 | AB8: 0.1 | AC8: 0.1 | AD8: 0.1 | AE8: 0.1 | AF8: 0.1
A9: Land Converted to Forest Land | B9: -98.6 | C9: -98.6 | D9: -98.6 | E9: -98.6 | F9: -98.7 | G9: -98.7 | H9: -98.7 | I9: -98.7 | J9: -98.8 | K9: -98.8 | L9: -98.8 | M9: -98.9 | N9: -98.9 | O9: -99 | P9: -99 | Q9: -99.1 | R9: -99.1 | S9: -99.1 | T9: -99.2 | U9: -99.2 | V9: -99.2 | W9: -99.3 | X9: -99.3 | Y9: -99.3 | Z9: -99.3 | AA9: -99.4 | AB9: -99.5 | AC9: -99.5 | AD9: -99.5 | AE9: -99.5 | AF9: -99.5
A10: Changes in Forest Carbon Stockse | B10: -98.6 | C10: -98.6 | D10: -98.6 | E10: -98.6 | F10: -98.7 | G10: -98.7 | H10: -98.7 | I10: -98.7 | J10: -98.8 | K10: -98.8 | L10: -98.8 | M10: -98.9 | N10: -98.9 | O10: -99 | P10: -99 | Q10: -99.1 | R10: -99.1 | S10: -99.1 | T10: -99.2 | U10: -99.2 | V10: -99.2 | W10: -99.3 | X10: -99.3 | Y10: -99.3 | Z10: -99.3 | AA10: -99.4 | AB10: -99.5 | AC10: -99.5 | AD10: -99.5 | AE10: -99.5 | AF10: -99.5
A11: Cropland Remaining Cropland | B11: -23.2 | C11: -29 | D11: -25.5 | E11: -11.6 | F11: -19.3 | G11: -12.1 | H11: -27.5 | I11: -19.1 | J11: -9.9 | K11: -18 | L11: -23.7 | M11: -27.2 | N11: -32 | O11: -24.1 | P11: -26.2 | Q11: -29 | R11: -25.2 | S11: -29.2 | T11: -23 | U11: -14 | V11: -18.6 | W11: -31.8 | X11: -26.4 | Y11: -15.3 | Z11: -12.2 | AA11: -12.8 | AB11: -22.7 | AC11: -22.3 | AD11: -16.6 | AE11: -14.5 | AF11: -23.3
A12: Changes in Mineral and Organic Soil Carbon Stocks | B12: -23.2 | C12: -29 | D12: -25.5 | E12: -11.6 | F12: -19.3 | G12: -12.1 | H12: -27.5 | I12: -19.1 | J12: -9.9 | K12: -18 | L12: -23.7 | M12: -27.2 | N12: -32 | O12: -24.1 | P12: -26.2 | Q12: -29 | R12: -25.2 | S12: -29.2 | T12: -23 | U12: -14 | V12: -18.6 | W12: -31.8 | X12: -26.4 | Y12: -15.3 | Z12: -12.2 | AA12: -12.8 | AB12: -22.7 | AC12: -22.3 | AD12: -16.6 | AE12: -14.5 | AF12: -23.3
A13: Land Converted to Cropland | B13: 51.8 | C13: 52.6 | D13: 53.2 | E13: 52.5 | F13: 52.8 | G13: 57.1 | H13: 56.1 | I13: 59.2 | J13: 55.9 | K13: 56.1 | L13: 55.3 | M13: 55.8 | N13: 53.4 | O13: 53.2 | P13: 52 | Q13: 52 | R13: 50.9 | S13: 51.1 | T13: 53.3 | U13: 53.5 | V13: 54.9 | W13: 52 | X13: 53.2 | Y13: 54.1 | Z13: 55.2 | AA13: 55.8 | AB13: 54.1 | AC13: 54.3 | AD13: 54 | AE13: 53.9 | AF13: 54.4
A14: Changes in all Ecosystem Carbon Stocksf | B14: 51.8 | C14: 52.6 | D14: 53.2 | E14: 52.5 | F14: 52.8 | G14: 57.1 | H14: 56.1 | I14: 59.2 | J14: 55.9 | K14: 56.1 | L14: 55.3 | M14: 55.8 | N14: 53.4 | O14: 53.2 | P14: 52 | Q14: 52 | R14: 50.9 | S14: 51.1 | T14: 53.3 | U14: 53.5 | V14: 54.9 | W14: 52 | X14: 53.2 | Y14: 54.1 | Z14: 55.2 | AA14: 55.8 | AB14: 54.1 | AC14: 54.3 | AD14: 54 | AE14: 53.9 | AF14: 54.4
... A21: Changes in Organic Soil Carbon Stocks in Peatlands | B21: 1.1 | C21: 1 | D21: 0.9 | E21: 1 | F21: 0.9 | G21: 1.1 | H21: 0.9 | I21: 1.1 | J21: 1.1 | K21: 1.2 | L21: 1.3 | M21: 1.2 | N21: 1 | O21: 1 | P21: 1.2 | Q21: 1.1 | R21: 0.9 | S21: 1 | T21: 1 | U21: 1 | V21: 1 | W21: 0.9 | X21: 0.8 | Y21: 0.8 | Z21: 0.8 | AA21: 0.8 | AB21: 0.7 | AC21: 0.8 | AD21: 0.8 | AE21: 0.8 | AF21: 0.7
A22: Non-CO2 Emissions from Peatlands Remaining Peatlands | B22: + | C22: + | D22: + | E22: + | F22: + | G22: + | H22: + | I22: + | J22: + | K22: + | L22: + | M22: + | N22: + | O22: + | P22: + | Q22: + | R22: + | S22: + | T22: + | U22: + | V22: + | W22: + | X22: + | Y22: + | Z22: + | AA22: + | AB22: + | AC22: + | AD22: + | AE22: + | AF22: +
A23: Changes in Biomass, DOM, and Soil Carbon Stocks in Coastal Wetlands | B23: -8.5 | C23: -8.5 | D23: -8.5 | E23: -8.5 | F23: -8.5 | G23: -8.5 | H23: -8.5 | I23: -8.5 | J23: -8.5 | K23: -8.5 | L23: -8.5 | M23: -7.7 | N23: -7.7 | O23: -7.7 | P23: -7.7 | Q23: -7.6 | R23: 1.3 | S23: 1.5 | T23: 1.5 | U23: 1.5 | V23: 1.5 | W23: -8.5 | X23: -8.8 | Y23: -8.8 | Z23: -8.8 | AA23: -8.8 | AB23: -8.8 | AC23: -8.8 | AD23: -8.8 | AE23: -8.8 | AF23: -8.8
A24: CH4 Emissions from Coastal Wetlands Remaining Coastal Wetlands | B24: 3.7 | C24: 3.7 | D24: 3.7 | E24: 3.8 | F24: 3.8 | G24: 3.8 | H24: 3.8 | I24: 3.8 | J24: 3.8 | K24: 3.8 | L24: 3.8 | M24: 3.8 | N24: 3.8 | O24: 3.8 | P24: 3.8 | Q24: 3.8 | R24: 3.8 | S24: 3.8 | T24: 3.8 | U24: 3.8 | V24: 3.8 | W24: 3.8 | X24: 3.8 | Y24: 3.8 | Z24: 3.8 | AA24: 3.8 | AB24: 3.8 | AC24: 3.8 | AD24: 3.8 | AE24: 3.8 | AF24: 3.8
A25: N2O Emissions from Coastal Wetlands Remaining Coastal Wetlands | B25: 0.1 | C25: 0.1 | D25: 0.2 | E25: 0.1 | F25: 0.1 | G25: 0.2 | H25: 0.2 | I25: 0.2 | J25: 0.2 | K25: 0.2 | L25: 0.2 | M25: 0.2 | N25: 0.2 | O25: 0.2 | P25: 0.2 | Q25: 0.2 | R25: 0.2 | S25: 0.2 | T25: 0.2 | U25: 0.2 | V25: 0.2 | W25: 0.1 | X25: 0.1 | Y25: 0.1 | Z25: 0.1 | AA25: 0.1 | AB25: 0.1 | AC25: 0.1 | AD25: 0.2 | AE25: 0.2 | AF25: 0.2
A26: CH4 Emissions from Flooded Land Remaining Flooded Land | B26: 18.2 | C26: 18.4 | D26: 18.5 | E26: 18.6 | F26: 18.8 | G26: 18.9 | H26: 18.9 | I26: 19 | J26: 19.2 | K26: 19.3 | L26: 19.3 | M26: 19.5 | N26: 19.7 | O26: 19.7 | P26: 19.8 | Q26: 19.8 | R26: 19.8 | S26: 19.8 | T26: 19.9 | U26: 19.9 | V26: 19.9 | W26: 19.9 | X26: 19.9 | Y26: 19.9 | Z26: 19.9 | AA26: 19.9 | AB26: 19.9 | AC26: 19.9 | AD26: 19.9 | AE26: 19.9 | AF26: 19.9
A27: Land Converted to Wetlands | B27: 7.2 | C27: 6.5 | D27: 6.1 | E27: 5.7 | F27: 5 | G27: 4.7 | H27: 4.6 | I27: 4.3 | J27: 3.6 | K27: 3.4 | L27: 3.3 | M27: 2.4 | N27: 1.6 | O27: 1.6 | P27: 1.3 | Q27: 1.3 | R27: 1.2 | S27: 1.2 | T27: 1 | U27: 0.9 | V27: 0.9 | W27: 0.4 | X27: 0.3 | Y27: 0.3 | Z27: 0.3 | AA27: 0.6 | AB27: 0.6 | AC27: 0.6 | AD27: 0.6 | AE27: 0.6 | AF27: 0.6
A28: Changes in Biomass, DOM, and Soil Carbon Stocks in Land Converted to Coastal Wetlands | B28: 0.5 | C28: 0.5 | D28: 0.5 | E28: 0.5 | F28: 0.5 | G28: 0.5 | H28: 0.5 | I28: 0.5 | J28: 0.5 | K28: 0.5 | L28: 0.5 | M28: 0.5 | N28: 0.5 | O28: 0.5 | P28: 0.5 | Q28: 0.5 | R28: 0.5 | S28: 0.5 | T28: 0.5 | U28: 0.5 | V28: 0.5 | W28: -0.1 | X28: -0.1 | Y28: -0.1 | Z28: -0.1 | AA28: -0.1 | AB28: (+) | AC28: (+) | AD28: (+) | AE28: (+) | AF28: (+)
A29: CH4 Emissions from Land Converted to Coastal Wetlands | B29: 0.2 | C29: 0.2 | D29: 0.2 | E29: 0.2 | F29: 0.2 | G29: 0.2 | H29: 0.2 | I29: 0.2 | J29: 0.2 | K29: 0.2 | L29: 0.2 | M29: 0.2 | N29: 0.2 | O29: 0.2 | P29: 0.2 | Q29: 0.2 | R29: 0.2 | S29: 0.2 | T29: 0.2 | U29: 0.3 | V29: 0.3 | W29: 0.2 | X29: 0.2 | Y29: 0.2 | Z29: 0.2 | AA29: 0.2 | AB29: 0.2 | AC29: 0.2 | AD29: 0.2 | AE29: 0.2 | AF29: 0.2
A30: Changes in Land Converted to Flooded Land | B30: 3.9 | C30: 3.5 | D30: 3.2 | E30: 3 | F30: 2.6 | G30: 2.4 | H30: 2.3 | I30: 2.2 | J30: 1.7 | K30: 1.6 | L30: 1.6 | M30: 1 | N30: 0.5 | O30: 0.5 | P30: 0.3 | Q30: 0.3 | R30: 0.3 | S30: 0.3 | T30: 0.2 | U30: 0.1 | V30: 0.1 | W30: 0.1 | X30: 0.1 | Y30: 0.1 | Z30: 0.1 | AA30: 0.3 | AB30: 0.3 | AC30: 0.3 | AD30: 0.3 | AE30: 0.3 | AF30: 0.3
A31: CH4 Emissions from Land Converted to Flooded Land | B31: 2.6 | C31: 2.3 | D31: 2.1 | E31: 2 | F31: 1.7 | G31: 1.6 | H31: 1.5 | I31: 1.4 | J31: 1.1 | K31: 1 | L31: 1 | M31: 0.6 | N31: 0.4 | O31: 0.3 | P31: 0.2 | Q31: 0.2 | R31: 0.2 | S31: 0.2 | T31: 0.1 | U31: 0.1 | V31: 0.1 | W31: 0.1 | X31: 0.1 | Y31: 0.1 | Z31: 0.1 | AA31: 0.2 | AB31: 0.2 | AC31: 0.2 | AD31: 0.2 | AE31: 0.2 | AF31: 0.2
A32: Settlements Remaining Settlements | B32: -107.6 | C32: -108.2 | D32: -106.1 | E32: -105.1 | F32: -103.5 | G32: -103.2 | H32: -104.1 | I32: -104.5 | J32: -106.7 | K32: -109.1 | L32: -110 | M32: -111.3 | N32: -110.7 | O32: -111.5 | P32: -112.2 | Q32: -113.5 | R32: -114 | S32: -115.2 | T32: -118.2 | U32: -120.1 | V32: -121.6 | W32: -121.9 | X32: -121.9 | Y32: -123.2 | Z32: -124.3 | AA32: -123.7 | AB32: -121.5 | AC32: -125.3 | AD32: -124.9 | AE32: -124.5 | AF32: -123.7
A33: Changes in Organic Soil Carbon Stocks | B33: 11.3 | C33: 11.3 | D33: 11.3 | E33: 11.2 | F33: 11.2 | G33: 11.2 | H33: 11.2 | I33: 11.2 | J33: 11.2 | K33: 11.2 | L33: 11.2 | M33: 11.2 | N33: 11.2 | O33: 11.6 | P33: 11.9 | Q33: 12.2 | R33: 12.4 | S33: 12.7 | T33: 13.1 | U33: 13.4 | V33: 13.7 | W33: 14 | X33: 14.3 | Y33: 14.7 | Z33: 15.1 | AA33: 15.7 | AB33: 16 | AC33: 16 | AD33: 15.9 | AE33: 15.9 | AF33: 15.9
A34: Changes in Settlement Tree Carbon Stocks | B34: -96.4 | C34: -97.6 | D34: -98.6 | E34: -100.2 | F34: -101.7 | G34: -103.3 | H34: -104.8 | I34: -106.4 | J34: -107.7 | K34: -109 | L34: -110.4 | M34: -111.4 | N34: -112.3 | O34: -114.1 | P34: -115.8 | Q34: -117.4 | R34: -118.9 | S34: -120.4 | T34: -121.9 | U34: -123.3 | V34: -124.6 | W34: -126 | X34: -126.7 | Y34: -128 | Z34: -129.4 | AA34: -130.4 | AB34: -129.8 | AC34: -129.8 | AD34: -129.8 | AE34: -129.8 | AF34: -129.8
A35: N2O Emissions from Settlement Soilsh | B35: 2 | C35: 2 | D35: 2.3 | E35: 2.5 | F35: 2.4 | G35: 2.4 | H35: 2.5 | I35: 2.4 | J35: 2 | K35: 2.1 | L35: 2.6 | M35: 2.5 | N35: 2.2 | O35: 2.4 | P35: 3.1 | Q35: 3.1 | R35: 3.2 | S35: 3.2 | T35: 3.2 | U35: 3 | V35: 2.1 | W35: 2.4 | X35: 2.1 | Y35: 2.2 | Z35: 2.2 | AA35: 2.2 | AB35: 2.2 | AC35: 2.3 | AD35: 2.4 | AE35: 2.4 | AF35: 2.5
A36: Changes in Yard Trimming and Food Scrap Carbon Stocks in Landfills | B36: -24.5 | C36: -24 | D36: -21 | E36: -18.6 | F36: -15.5 | G36: -13.5 | H36: -13 | I36: -11.8 | J36: -12.2 | K36: -13.4 | L36: -13.4 | M36: -13.6 | N36: -11.8 | O36: -11.3 | P36: -11.4 | Q36: -11.4 | R36: -10.7 | S36: -10.7 | T36: -12.6 | U36: -13.3 | V36: -12.7 | W36: -12.3 | X36: -11.7 | Y36: -12.1 | Z36: -12.3 | AA36: -11.1 | AB36: -10 | AC36: -13.8 | AD36: -13.4 | AE36: -13.1 | AF36: -12.2
A37: Land Converted to Settlements | B37: 60.8 | C37: 62.3 | D37: 63.9 | E37: 65.7 | F37: 67.5 | G37: 69.5 | H37: 71.4 | I37: 73.6 | J37: 75.4 | K37: 77.1 | L37: 79.1 | M37: 80.7 | N37: 81.8 | O37: 82.3 | P37: 82.5 | Q37: 82.8 | R37: 82.9 | S37: 82.8 | T37: 82.6 | U37: 82.3 | V37: 81.9 | W37: 81.4 | X37: 80.9 | Y37: 80.2 | Z37: 79.4 | AA37: 78.3 | AB37: 77.8 | AC37: 77.9 | AD37: 78 | AE37: 77.9 | AF37: 77.9
A38: Changes in all Ecosystem Carbon Stocksf | B38: 60.8 | C38: 62.3 | D38: 63.9 | E38: 65.7 | F38: 67.5 | G38: 69.5 | H38: 71.4 | I38: 73.6 | J38: 75.4 | K38: 77.1 | L38: 79.1 | M38: 80.7 | N38: 81.8 | O38: 82.3 | P38: 82.5 | Q38: 82.8 | R38: 82.9 | S38: 82.8 | T38: 82.6 | U38: 82.3 | V38: 81.9 | W38: 81.4 | X38: 80.9 | Y38: 80.2 | Z38: 79.4 | AA38: 78.3 | AB38: 77.8 | AC38: 77.9 | AD38: 78 | AE38: 77.9 | AF38: 77.9
A39: LULUCF Emissionsi | B39: 31.4 | C39: 30.7 | D39: 28.8 | E39: 28.8 | F39: 32.1 | G39: 28.5 | H39: 31.2 | I39: 28.1 | J39: 28.6 | K39: 32.5 | L39: 37.4 | M39: 31.6 | N39: 40.7 | O39: 36.5 | P39: 46.3 | Q39: 41.3 | R39: 37.9 | S39: 42.4 | T39: 36 | U39: 38 | V39: 30.4 | W39: 35.6 | X39: 37.8 | Y39: 37.1 | Z39: 33 | AA39: 48.9 | AB39: 35.4 | AC39: 45.5 | AD39: 39.8 | AE39: 30.3 | AF39: 53.2
A40: CH4 | B40: 27.2 | C40: 26.5 | D40: 25.4 | E40: 25.3 | F40: 26.8 | G40: 25 | H40: 26.2 | I40: 24.7 | J40: 25.1 | K40: 27 | L40: 29.4 | M40: 26.2 | N40: 31.2 | O40: 28.9 | P40: 33.2 | Q40: 30.9 | R40: 29 | S40: 31.6 | T40: 28 | U40: 29.1 | V40: 25.4 | W40: 27.9 | X40: 29.3 | Y40: 29.3 | Z40: 26.9 | AA40: 36 | AB40: 28.3 | AC40: 34 | AD40: 30.7 | AE40: 25.5 | AF40: 38.1
... A43: LULUCF Sector Net Totalk | B43: -860.6 | C43: -869.9 | D43: -862.4 | E43: -844.2 | F43: -857.5 | G43: -831.8 | H43: -852.1 | I43: -833.4 | J43: -835.3 | K43: -828 | L43: -825.2 | M43: -828.8 | N43: -790.5 | O43: -820.8 | P43: -729.5 | Q43: -789.8 | R43: -817.2 | S43: -776.4 | T43: -766.5 | U43: -734.5 | V43: -761 | W43: -800.7 | X43: -799.9 | Y43: -767.4 | Z43: -781.4 | AA43: -700.1 | AB43: -826.6 | AC43: -781.2 | AD43: -769.3 | AE43: -730.5 | AF43: -758.9
A44: + Absolute value does not exceed 0.05 MMT CO2 Eq.
A45: a Includes the net changes to carbon stocks stored in all forest ecosystem pools (estimates include C stock changes from drained organic soils from both Forest Land Remaining Forest Land and Land Converted to Forest Land) and harvested wood products.
A46: b Estimates include CH4 and N2O emissions from fires on both Forest Land Remaining Forest Land and Land Converted to Forest Land.
A47: c Estimates include N2O emissions from N fertilizer additions on both Forest Land Remaining Forest Land and Land Converted to Forest Land.
A48: d Estimates include CH4 and N2O emissions from drained organic soils on both Forest Land Remaining Forest Land and Land Converted to Forest Land. Carbon stock changes from drained organic soils are included with the Forest Land Remaining Forest Land forest ecosystem pools.
A49: e Includes the net changes to carbon stocks stored in all forest ecosystem pools.
...

Sheet BLAPE
A1: Year | B1: 2020 | C1: 2021 | D1: 2022 | E1: 2023 | F1: 2024 | G1: 2025 | H1: 2026 | I1: 2027 | J1: 2028 | K1: 2029 | L1: 2030 | M1: 2031 | N1: 2032 | O1: 2033 | P1: 2034 | Q1: 2035 | R1: 2036 | S1: 2037 | T1: 2038 | U1: 2039 | V1: 2040 | W1: 2041 | X1: 2042 | Y1: 2043 | Z1: 2044 | AA1: 2045 | AB1: 2046 | AC1: 2047 | AD1: 2048 | AE1: 2049 | AF1: 2050
A2: CO2 (g) | B2: =Calcs!B4*10^12 -> -463200000000 | C2: =Calcs!C4*10^12 -> -463200000000 | D2: =Calcs!D4*10^12 -> -463200000000 | E2: =Calcs!E4*10^12 -> -463200000000 | F2: =Calcs!F4*10^12 -> -463200000000 | G2: =Calcs!G4*10^12 -> -463200000000 | H2: =Calcs!H4*10^12 -> -463200000000 | I2: =Calcs!I4*10^12 -> -463200000000 | ... AF2: =Calcs!AF4*10^12 -> -463200000000
A3: VOCs (g) | B3: 0 | C3: 0 | D3: 0 | E3: 0 | F3: 0 | G3: 0 | H3: 0 | I3: 0 | J3: 0 | K3: 0 | L3: 0 | M3: 0 | N3: 0 | O3: 0 | P3: 0 | Q3: 0 | R3: 0 | S3: 0 | T3: 0 | U3: 0 | V3: 0 | W3: 0 | X3: 0 | Y3: 0 | Z3: 0 | AA3: 0 | AB3: 0 | AC3: 0 | AD3: 0 | AE3: 0 | AF3: 0
A4: CO (g) | B4: 0 | C4: 0 | D4: 0 | E4: 0 | F4: 0 | G4: 0 | H4: 0 | I4: 0 | J4: 0 | K4: 0 | L4: 0 | M4: 0 | N4: 0 | O4: 0 | P4: 0 | Q4: 0 | R4: 0 | S4: 0 | T4: 0 | U4: 0 | V4: 0 | W4: 0 | X4: 0 | Y4: 0 | Z4: 0 | AA4: 0 | AB4: 0 | AC4: 0 | AD4: 0 | AE4: 0 | AF4: 0
A5: NOx (g) | B5: 0 | C5: 0 | D5: 0 | E5: 0 | F5: 0 | G5: 0 | H5: 0 | I5: 0 | J5: 0 | K5: 0 | L5: 0 | M5: 0 | N5: 0 | O5: 0 | P5: 0 | Q5: 0 | R5: 0 | S5: 0 | T5: 0 | U5: 0 | V5: 0 | W5: 0 | X5: 0 | Y5: 0 | Z5: 0 | AA5: 0 | AB5: 0 | AC5: 0 | AD5: 0 | AE5: 0 | AF5: 0
A6: PM10 (g) | B6: 0 | C6: 0 | D6: 0 | E6: 0 | F6: 0 | G6: 0 | H6: 0 | I6: 0 | J6: 0 | K6: 0 | L6: 0 | M6: 0 | N6: 0 | O6: 0 | P6: 0 | Q6: 0 | R6: 0 | S6: 0 | T6: 0 | U6: 0 | V6: 0 | W6: 0 | X6: 0 | Y6: 0 | Z6: 0 | AA6: 0 | AB6: 0 | AC6: 0 | AD6: 0 | AE6: 0 | AF6: 0
A7: PM25 (g) | B7: 0 | C7: 0 | D7: 0 | E7: 0 | F7: 0 | G7: 0 | H7: 0 | I7: 0 | J7: 0 | K7: 0 | L7: 0 | M7: 0 | N7: 0 | O7: 0 | P7: 0 | Q7: 0 | R7: 0 | S7: 0 | T7: 0 | U7: 0 | V7: 0 | W7: 0 | X7: 0 | Y7: 0 | Z7: 0 | AA7: 0 | AB7: 0 | AC7: 0 | AD7: 0 | AE7: 0 | AF7: 0
A8: SOx (g) | B8: 0 | C8: 0 | D8: 0 | E8: 0 | F8: 0 | G8: 0 | H8: 0 | I8: 0 | J8: 0 | K8: 0 | L8: 0 | M8: 0 | N8: 0 | O8: 0 | P8: 0 | Q8: 0 | R8: 0 | S8: 0 | T8: 0 | U8: 0 | V8: 0 | W8: 0 | X8: 0 | Y8: 0 | Z8: 0 | AA8: 0 | AB8: 0 | AC8: 0 | AD8: 0 | AE8: 0 | AF8: 0
A9: BC (g) | B9: 0 | C9: 0 | D9: 0 | E9: 0 | F9: 0 | G9: 0 | H9: 0 | I9: 0 | J9: 0 | K9: 0 | L9: 0 | M9: 0 | N9: 0 | O9: 0 | P9: 0 | Q9: 0 | R9: 0 | S9: 0 | T9: 0 | U9: 0 | V9: 0 | W9: 0 | X9: 0 | Y9: 0 | Z9: 0 | AA9: 0 | AB9: 0 | AC9: 0 | AD9: 0 | AE9: 0 | AF9: 0
A10: OC (g) | B10: 0 | C10: 0 | D10: 0 | E10: 0 | F10: 0 | G10: 0 | H10: 0 | I10: 0 | J10: 0 | K10: 0 | L10: 0 | M10: 0 | N10: 0 | O10: 0 | P10: 0 | Q10: 0 | R10: 0 | S10: 0 | T10: 0 | U10: 0 | V10: 0 | W10: 0 | X10: 0 | Y10: 0 | Z10: 0 | AA10: 0 | AB10: 0 | AC10: 0 | AD10: 0 | AE10: 0 | AF10: 0
A11: CH4 (g) | B11: =Calcs!B5*10^12/About!$B$9 -> 0 | C11: =Calcs!C5*10^12/About!$B$9 -> 0 | D11: =Calcs!D5*10^12/About!$B$9 -> 0 | E11: =Calcs!E5*10^12/About!$B$9 -> 0 | F11: =Calcs!F5*10^12/About!$B$9 -> 0 | G11: =Calcs!G5*10^12/About!$B$9 -> 0 | H11: =Calcs!H5*10^12/About!$B$9 -> 0 | I11: =Calcs!I5*10^12/About!$B$9 -> 0 | ... AF11: =Calcs!AF5*10^12/About!$B$9 -> 0
A12: N2O (g) | B12: =Calcs!B6*10^12/About!$B$10 -> 0 | C12: =Calcs!C6*10^12/About!$B$10 -> 0 | D12: =Calcs!D6*10^12/About!$B$10 -> 0 | E12: =Calcs!E6*10^12/About!$B$10 -> 0 | F12: =Calcs!F6*10^12/About!$B$10 -> 0 | G12: =Calcs!G6*10^12/About!$B$10 -> 0 | H12: =Calcs!H6*10^12/About!$B$10 -> 0 | I12: =Calcs!I6*10^12/About!$B$10 -> 0 | ... AF12: =Calcs!AF6*10^12/About!$B$10 -> 0
A13: F gases (g CO2e) | B13: 0 | C13: 0 | D13: 0 | E13: 0 | F13: 0 | G13: 0 | H13: 0 | I13: 0 | J13: 0 | K13: 0 | L13: 0 | M13: 0 | N13: 0 | O13: 0 | P13: 0 | Q13: 0 | R13: 0 | S13: 0 | T13: 0 | U13: 0 | V13: 0 | W13: 0 | X13: 0 | Y13: 0 | Z13: 0 | AA13: 0 | AB13: 0 | AC13: 0 | AD13: 0 | AE13: 0 | AF13: 0
