Workbook

Sheet About
A1: DLIM Domestic Leontief Inverse Matrix
A3: Source: | B3: Most Data
B4: OECD
B5: 2018
B6: Input-Output Tables 2018 Edition (ISIC Rev. 4)
B7: https://stats.oecd.org/Index.aspx?DataSetCode=IOTSI4_2018
B8: Variable: LEONTFD
B10: ISIC Code Splits
B11: U.S. Bureau of Economic Analysis
B12: 2012
B13: Input-Output Accounts Data
B14: https://www.bea.gov/industry/input-output-accounts-data
B15: "'Industry-by-Industry Domestic Requirements" table, 405-industry breakdown
B16: "Use of Commodities by Industry" table, 405-industry breakdown
A18: Notes
A19: OECD Stat directly provides Leontief inverse matrices, both total and domestic-only, for
A20: 64 countries and regions.
A22: A domestic-only Leontief matrix filters out payments to foreign suppliers from the respending
A23: calculations. This type of Leontief matrix must be multiplied by a change in domestic (not total)
A24: output by ISIC code, as it does not filter the direct output changes by which it is multiplied.
A25: Conversely, a "Total" Leontief matrix must be multiplied by a change in total (not domestic)
A26: output by ISIC code, as it cannot restore imports that were removed from the direct output changes
A27: by which it is multiplied.
A29: Splitting OECD Joined ISIC Codes
A30: The OECD tables group several industries that are broken out in the EPS.
A31: Therefore, we calculate these rows and columns using a separate data source.
... A76: before creating a Leontief Inverse Matrix.

Sheet OECD LEONTFD
A1: =DotStatQuery(B1) -> #NAME? | B1: Sorry, the query is too large to fit into the Excel cell. You will not be able to update your table with the .Stat Populator.
A2: Dataset: Input-Output Tables (IOTs) 2018 ed.
A3: Variable | C3: LEONTFD: Leontief inverse matrix (domestic)
A4: Country | C4: HKG: Hong Kong, China
A5: Time | C5: 2015
A6: Unit | C6: Index
A7: To: (sector in column) | C7: D01T03: Agriculture, forestry and fishing | D7: D05T06: Mining and extraction of energy producing products | E7: D07T08: Mining and quarrying of non-energy producing products | F7: D09: Mining support service activities | G7: D10T12: Food products, beverages and tobacco | H7: D13T15: Textiles, wearing apparel, leather and related products | I7: D16: Wood and products of wood and cork | J7: D17T18: Paper products and printing | K7: D19: Coke and refined petroleum products | L7: D20T21: Chemicals and pharmaceutical products | M7: D22: Rubber and plastic products | N7: D23: Other non-metallic mineral products | O7: D24: Basic metals | P7: D25: Fabricated metal products | Q7: D26: Computer, electronic and optical products | R7: D27: Electrical equipment | S7: D28: Machinery and equipment, nec | T7: D29: Motor vehicles, trailers and semi-trailers | U7: D30: Other transport equipment | V7: D31T33: Other manufacturing; repair and installation of machinery and equipment | W7: D35T39: Electricity, gas, water supply, sewerage, waste and remediation services | X7: D41T43: Construction | Y7: D45T47: Wholesale and retail trade; repair of motor vehicles | Z7: D49T53: Transportation and storage | AA7: D55T56: Accomodation and food services | AB7: D58T60: Publishing, audiovisual and broadcasting activities | AC7: D61: Telecommunications | AD7: D62T63: IT and other information services | AE7: D64T66: Financial and insurance activities | AF7: D68: Real estate activities | AG7: D69T82: Other business sector services | AH7: D84: Public admin. and defence; compulsory social security | AI7: D85: Education | AJ7: D86T88: Human health and social work | AK7: D90T96: Arts, entertainment, recreation and other service activities | AL7: D97T98: Private households with employed persons
A8: From: (sector in row)
A9: DOM_01T03: Agriculture, forestry and fishing | C9: 1.03 | D9: 0.001 | E9: 0.001 | F9: 0.001 | G9: 0.028 | H9: 0.002 | I9: 0.003 | J9: 0.001 | K9: 0.001 | L9: 0.002 | M9: 0.001 | N9: 0.001 | O9: 0.001 | P9: 0 | Q9: 0 | R9: 0 | S9: 0 | T9: 0 | U9: 0 | V9: 0 | W9: 0.001 | X9: 0 | Y9: 0.001 | Z9: 0 | AA9: 0.009 | AB9: 0 | AC9: 0 | AD9: 0 | AE9: 0 | AF9: 0 | AG9: 0 | AH9: 0.001 | AI9: 0.001 | AJ9: 0.001 | AK9: 0.002 | AL9: 0
A10: DOM_05T06: Mining and extraction of energy producing products | C10: 0.001 | D10: 1.004 | E10: 0.003 | F10: 0.005 | G10: 0 | H10: 0.001 | I10: 0.001 | J10: 0.001 | K10: 0.034 | L10: 0.002 | M10: 0.001 | N10: 0.002 | O10: 0.002 | P10: 0 | Q10: 0 | R10: 0 | S10: 0 | T10: 0 | U10: 0 | V10: 0 | W10: 0.004 | X10: 0.001 | Y10: 0 | Z10: 0.002 | AA10: 0 | AB10: 0 | AC10: 0 | AD10: 0 | AE10: 0 | AF10: 0 | AG10: 0.001 | AH10: 0 | AI10: 0 | AJ10: 0 | AK10: 0 | AL10: 0
A11: DOM_07T08: Mining and quarrying of non-energy producing products | C11: 0.003 | D11: 0.008 | E11: 1.142 | F11: 0.026 | G11: 0.001 | H11: 0.002 | I11: 0.004 | J11: 0.007 | K11: 0.005 | L11: 0.03 | M11: 0.006 | N11: 0.166 | O11: 0.024 | P11: 0.002 | Q11: 0.001 | R11: 0.001 | S11: 0.003 | T11: 0.002 | U11: 0.002 | V11: 0.005 | W11: 0.003 | X11: 0.036 | Y11: 0.001 | Z11: 0.001 | AA11: 0 | AB11: 0 | AC11: 0 | AD11: 0 | AE11: 0 | AF11: 0.002 | AG11: 0.001 | AH11: 0.002 | AI11: 0.001 | AJ11: 0.001 | AK11: 0.001 | AL11: 0
A12: DOM_09: Mining support service activities | C12: 0.002 | D12: 0.01 | E12: 0.006 | F12: 1.016 | G12: 0 | H12: 0 | I12: 0 | J12: 0 | K12: 0.001 | L12: 0 | M12: 0 | N12: 0.001 | O12: 0 | P12: 0 | Q12: 0 | R12: 0 | S12: 0 | T12: 0 | U12: 0 | V12: 0 | W12: 0 | X12: 0.001 | Y12: 0 | Z12: 0 | AA12: 0 | AB12: 0 | AC12: 0 | AD12: 0 | AE12: 0 | AF12: 0 | AG12: 0 | AH12: 0 | AI12: 0 | AJ12: 0 | AK12: 0 | AL12: 0
A13: DOM_10T12: Food products, beverages and tobacco | C13: 0.274 | D13: 0.012 | E13: 0.012 | F13: 0.016 | G13: 1.43 | H13: 0.049 | I13: 0.032 | J13: 0.032 | K13: 0.017 | L13: 0.073 | M13: 0.02 | N13: 0.013 | O13: 0.006 | P13: 0.004 | Q13: 0.006 | R13: 0.003 | S13: 0.006 | T13: 0.006 | U13: 0.007 | V13: 0.009 | W13: 0.01 | X13: 0.01 | Y13: 0.018 | Z13: 0.008 | AA13: 0.317 | AB13: 0.011 | AC13: 0.004 | AD13: 0.006 | AE13: 0.004 | AF13: 0.002 | AG13: 0.014 | AH13: 0.032 | AI13: 0.024 | AJ13: 0.046 | AK13: 0.064 | AL13: 0
A14: DOM_13T15: Textiles, wearing apparel, leather and related products | C14: 0.013 | D14: 0.02 | E14: 0.015 | F14: 0.025 | G14: 0.015 | H14: 1.221 | I14: 0.04 | J14: 0.01 | K14: 0.01 | L14: 0.011 | M14: 0.017 | N14: 0.011 | O14: 0.009 | P14: 0.006 | Q14: 0.01 | R14: 0.006 | S14: 0.01 | T14: 0.017 | U14: 0.017 | V14: 0.032 | W14: 0.008 | X14: 0.01 | Y14: 0.015 | Z14: 0.008 | AA14: 0.011 | AB14: 0.014 | AC14: 0.006 | AD14: 0.008 | AE14: 0.003 | AF14: 0.001 | AG14: 0.014 | AH14: 0.01 | AI14: 0.005 | AJ14: 0.015 | AK14: 0.016 | AL14: 0
A15: DOM_16: Wood and of products of wood and cork (except furniture) | C15: 0.002 | D15: 0.011 | E15: 0.005 | F15: 0.005 | G15: 0.001 | H15: 0.002 | I15: 1.36 | J15: 0.016 | K15: 0.002 | L15: 0.003 | M15: 0.005 | N15: 0.008 | O15: 0.001 | P15: 0.002 | Q15: 0.002 | R15: 0.001 | S15: 0.002 | T15: 0.004 | U15: 0.006 | V15: 0.046 | W15: 0.003 | X15: 0.03 | Y15: 0.001 | Z15: 0.001 | AA15: 0.001 | AB15: 0.001 | AC15: 0.001 | AD15: 0.001 | AE15: 0 | AF15: 0.003 | AG15: 0.002 | AH15: 0.001 | AI15: 0.001 | AJ15: 0.001 | AK15: 0.002 | AL15: 0
A16: DOM_17T18: Paper products and printing | C16: 0 | D16: 0 | E16: 0 | F16: 0 | G16: 0 | H16: 0 | I16: 0.001 | J16: 1.006 | K16: 0 | L16: 0 | M16: 0 | N16: 0 | O16: 0 | P16: 0 | Q16: 0 | R16: 0 | S16: 0 | T16: 0 | U16: 0 | V16: 0 | W16: 0 | X16: 0 | Y16: 0 | Z16: 0 | AA16: 0 | AB16: 0.002 | AC16: 0 | AD16: 0 | AE16: 0 | AF16: 0 | AG16: 0 | AH16: 0 | AI16: 0 | AJ16: 0 | AK16: 0 | AL16: 0
A17: DOM_19: Coke and refined petroleum products | C17: 0.03 | D17: 0.053 | E17: 0.082 | F17: 0.066 | G17: 0.008 | H17: 0.013 | I17: 0.033 | J17: 0.018 | K17: 1.154 | L17: 0.051 | M17: 0.02 | N17: 0.05 | O17: 0.03 | P17: 0.006 | Q17: 0.008 | R17: 0.004 | S17: 0.009 | T17: 0.008 | U17: 0.007 | V17: 0.009 | W17: 0.035 | X17: 0.024 | Y17: 0.008 | Z17: 0.05 | AA17: 0.006 | AB17: 0.008 | AC17: 0.005 | AD17: 0.006 | AE17: 0.004 | AF17: 0.003 | AG17: 0.017 | AH17: 0.01 | AI17: 0.006 | AJ17: 0.008 | AK17: 0.009 | AL17: 0
A18: DOM_20T21: Chemicals and pharmaceutical products | C18: 0.014 | D18: 0.02 | E18: 0.021 | F18: 0.015 | G18: 0.005 | H18: 0.035 | I18: 0.04 | J18: 0.03 | K18: 0.041 | L18: 1.118 | M18: 0.136 | N18: 0.025 | O18: 0.013 | P18: 0.005 | Q18: 0.009 | R18: 0.005 | S18: 0.007 | T18: 0.01 | U18: 0.009 | V18: 0.011 | W18: 0.006 | X18: 0.009 | Y18: 0.002 | Z18: 0.003 | AA18: 0.002 | AB18: 0.004 | AC18: 0.001 | AD18: 0.001 | AE18: 0.001 | AF18: 0.001 | AG18: 0.004 | AH18: 0.004 | AI18: 0.003 | AJ18: 0.036 | AK18: 0.006 | AL18: 0
A19: DOM_22: Rubber and plastics products | C19: 0.002 | D19: 0.005 | E19: 0.004 | F19: 0.004 | G19: 0.003 | H19: 0.004 | I19: 0.006 | J19: 0.005 | K19: 0.002 | L19: 0.004 | M19: 1.031 | N19: 0.004 | O19: 0.001 | P19: 0.001 | Q19: 0.005 | R19: 0.002 | S19: 0.004 | T19: 0.009 | U19: 0.003 | V19: 0.004 | W19: 0.001 | X19: 0.006 | Y19: 0.001 | Z19: 0.001 | AA19: 0.001 | AB19: 0.001 | AC19: 0.001 | AD19: 0 | AE19: 0 | AF19: 0 | AG19: 0.001 | AH19: 0.001 | AI19: 0 | AJ19: 0.001 | AK19: 0.001 | AL19: 0
A20: DOM_23: Other non-metallic mineral products | C20: 0 | D20: 0.001 | E20: 0.005 | F20: 0.002 | G20: 0.001 | H20: 0 | I20: 0.004 | J20: 0 | K20: 0 | L20: 0.001 | M20: 0.002 | N20: 1.022 | O20: 0.001 | P20: 0.001 | Q20: 0.002 | R20: 0 | S20: 0.001 | T20: 0.001 | U20: 0.001 | V20: 0.001 | W20: 0.001 | X20: 0.015 | Y20: 0 | Z20: 0 | AA20: 0 | AB20: 0 | AC20: 0 | AD20: 0 | AE20: 0 | AF20: 0.001 | AG20: 0 | AH20: 0 | AI20: 0 | AJ20: 0 | AK20: 0 | AL20: 0
... A45: TOTAL: Total | C45: 1.746 | D45: 2.07 | E45: 2.063 | F45: 2.054 | G45: 1.889 | H45: 1.754 | I45: 2.48 | J45: 1.624 | K45: 1.738 | L45: 1.78 | M45: 1.689 | N45: 1.879 | O45: 1.587 | P45: 1.282 | Q45: 1.571 | R45: 1.213 | S45: 1.478 | T45: 1.547 | U45: 1.374 | V45: 1.431 | W45: 1.613 | X45: 1.733 | Y45: 1.436 | Z45: 1.444 | AA45: 1.653 | AB45: 1.62 | AC45: 1.423 | AD45: 1.427 | AE45: 1.432 | AF45: 1.228 | AG45: 1.687 | AH45: 1.377 | AI45: 1.29 | AJ45: 1.432 | AK45: 1.538 | AL45: 1
A46: Data extracted on 18 Jan 2024 09:29 UTC (GMT) from OECD.Stat

Sheet DLIM
B1: ISIC 01T03 | C1: ISIC 05 | D1: ISIC 06 | E1: ISIC 07T08 | F1: ISIC 09 | G1: ISIC 10T12 | H1: ISIC 13T15 | I1: ISIC 16 | J1: ISIC 17T18 | K1: ISIC 19 | L1: ISIC 20 | M1: ISIC 21 | N1: ISIC 22 | O1: ISIC 231 | P1: ISIC 239 | Q1: ISIC 241 | R1: ISIC 242 | S1: ISIC 25 | T1: ISIC 26 | U1: ISIC 27 | V1: ISIC 28 | W1: ISIC 29 | X1: ISIC 30 | Y1: ISIC 31T33 | Z1: ISIC 351 | AA1: ISIC 352T353 | AB1: ISIC 36T39 | AC1: ISIC 41T43 | AD1: ISIC 45T47 | AE1: ISIC 49T53 | AF1: ISIC 55T56 | AG1: ISIC 58T60 | AH1: ISIC 61 | AI1: ISIC 62T63 | AJ1: ISIC 64T66 | AK1: ISIC 68 | AL1: ISIC 69T82 | AM1: ISIC 84 | AN1: ISIC 85 | AO1: ISIC 86T88 | AP1: ISIC 90T96 | AQ1: ISIC 97T98
A2: ISIC 01T03 | B2: ='OECD LEONTFD'!C9 -> 1.03 | C2: ='Weighted Avg BEA Multipliers'!E472 -> 0.00035354395 | D2: ='Weighted Avg BEA Multipliers'!F472 -> 0.00022726856 | E2: ='OECD LEONTFD'!E9 -> 0.001 | F2: ='OECD LEONTFD'!F9 -> 0.001 | G2: ='OECD LEONTFD'!G9 -> 0.028 | H2: ='OECD LEONTFD'!H9 -> 0.002 | I2: ='OECD LEONTFD'!I9 -> 0.003 | J2: ='OECD LEONTFD'!J9 -> 0.001 | K2: ='OECD LEONTFD'!K9 -> 0.001 | L2: ='Weighted Avg BEA Multipliers'!N472 -> 0.011445709 | M2: ='Weighted Avg BEA Multipliers'!O472 -> 0.0021397938 | N2: ='OECD LEONTFD'!M9 -> 0.001 | O2: ='Weighted Avg BEA Multipliers'!Q472 -> 0.00048540449 | P2: ='Weighted Avg BEA Multipliers'!R472 -> 0.00093341524 | Q2: ='Weighted Avg BEA Multipliers'!S472 -> 0.00044179799 | R2: ='Weighted Avg BEA Multipliers'!T472 -> 0.00026023 | S2: ='OECD LEONTFD'!P9 -> 0 | T2: ='OECD LEONTFD'!Q9 -> 0 | U2: ='OECD LEONTFD'!R9 -> 0 | V2: ='OECD LEONTFD'!S9 -> 0 | W2: ='OECD LEONTFD'!T9 -> 0 | X2: ='OECD LEONTFD'!U9 -> 0 | Y2: ='OECD LEONTFD'!V9 -> 0 | Z2: ='Weighted Avg BEA Multipliers'!AB472 -> 0.00022348092 | AA2: ='Weighted Avg BEA Multipliers'!AC472 -> 0.00010431067 | AB2: ='Weighted Avg BEA Multipliers'!AD472 -> 0.00036695052 | AC2: ='OECD LEONTFD'!X9 -> 0 | AD2: ='OECD LEONTFD'!Y9 -> 0.001 | AE2: ='OECD LEONTFD'!Z9 -> 0 | AF2: ='OECD LEONTFD'!AA9 -> 0.009 | AG2: ='OECD LEONTFD'!AB9 -> 0 | AH2: ='OECD LEONTFD'!AC9 -> 0 | AI2: ='OECD LEONTFD'!AD9 -> 0 | AJ2: ='OECD LEONTFD'!AE9 -> 0 | ... AQ2: ='OECD LEONTFD'!AL9 -> 0
A3: ISIC 05 | B3: ='Weighted Avg BEA Multipliers'!D473 -> 0.0026402269 | C3: ='Weighted Avg BEA Multipliers'!E473 -> 1.08927 | D3: ='Weighted Avg BEA Multipliers'!F473 -> 0.0019034 | E3: ='Weighted Avg BEA Multipliers'!G473 -> 0.0057258045 | F3: ='Weighted Avg BEA Multipliers'!H473 -> 0.0009259352 | G3: ='Weighted Avg BEA Multipliers'!I473 -> 0.0044641371 | H3: ='Weighted Avg BEA Multipliers'!J473 -> 0.0037795621 | I3: ='Weighted Avg BEA Multipliers'!K473 -> 0.0023969017 | ... AQ3: ='Weighted Avg BEA Multipliers'!AS473 -> 0
A4: ISIC 06 | B4: ='Weighted Avg BEA Multipliers'!D474 -> 0.013743178 | C4: ='Weighted Avg BEA Multipliers'!E474 -> 0.0243075 | D4: ='Weighted Avg BEA Multipliers'!F474 -> 1.08943 | E4: ='Weighted Avg BEA Multipliers'!G474 -> 0.030401592 | F4: ='Weighted Avg BEA Multipliers'!H474 -> 0.01000578 | G4: ='Weighted Avg BEA Multipliers'!I474 -> 0.013314126 | H4: ='Weighted Avg BEA Multipliers'!J474 -> 0.015175169 | I4: ='Weighted Avg BEA Multipliers'!K474 -> 0.013443327 | ... AQ4: ='Weighted Avg BEA Multipliers'!AS474 -> 0
A5: ISIC 07T08 | B5: ='OECD LEONTFD'!C11 -> 0.003 | C5: ='Weighted Avg BEA Multipliers'!E475 -> 0.0031371967 | D5: ='Weighted Avg BEA Multipliers'!F475 -> 0.000430351 | E5: ='OECD LEONTFD'!E11 -> 1.142 | F5: ='OECD LEONTFD'!F11 -> 0.026 | G5: ='OECD LEONTFD'!G11 -> 0.001 | H5: ='OECD LEONTFD'!H11 -> 0.002 | I5: ='OECD LEONTFD'!I11 -> 0.004 | J5: ='OECD LEONTFD'!J11 -> 0.007 | K5: ='OECD LEONTFD'!K11 -> 0.005 | L5: ='Weighted Avg BEA Multipliers'!N475 -> 0.0030763197 | M5: ='Weighted Avg BEA Multipliers'!O475 -> 0.00014922534 | N5: ='OECD LEONTFD'!M11 -> 0.006 | O5: ='Weighted Avg BEA Multipliers'!Q475 -> 0.0045476308 | P5: ='Weighted Avg BEA Multipliers'!R475 -> 0.015960324 | Q5: ='Weighted Avg BEA Multipliers'!S475 -> 0.013433242 | R5: ='Weighted Avg BEA Multipliers'!T475 -> 0.017955051 | S5: ='OECD LEONTFD'!P11 -> 0.002 | T5: ='OECD LEONTFD'!Q11 -> 0.001 | U5: ='OECD LEONTFD'!R11 -> 0.001 | V5: ='OECD LEONTFD'!S11 -> 0.003 | W5: ='OECD LEONTFD'!T11 -> 0.002 | X5: ='OECD LEONTFD'!U11 -> 0.002 | Y5: ='OECD LEONTFD'!V11 -> 0.005 | Z5: ='Weighted Avg BEA Multipliers'!AB475 -> 0.00046307766 | AA5: ='Weighted Avg BEA Multipliers'!AC475 -> 0.00015519656 | AB5: ='Weighted Avg BEA Multipliers'!AD475 -> 0.00083755886 | AC5: ='OECD LEONTFD'!X11 -> 0.036 | AD5: ='OECD LEONTFD'!Y11 -> 0.001 | AE5: ='OECD LEONTFD'!Z11 -> 0.001 | AF5: ='OECD LEONTFD'!AA11 -> 0 | AG5: ='OECD LEONTFD'!AB11 -> 0 | AH5: ='OECD LEONTFD'!AC11 -> 0 | AI5: ='OECD LEONTFD'!AD11 -> 0 | AJ5: ='OECD LEONTFD'!AE11 -> 0 | ... AQ5: ='OECD LEONTFD'!AL11 -> 0
A6: ISIC 09 | B6: ='OECD LEONTFD'!C12 -> 0.002 | C6: ='Weighted Avg BEA Multipliers'!E476 -> 0.012285152 | D6: ='Weighted Avg BEA Multipliers'!F476 -> 0.03117161 | E6: ='OECD LEONTFD'!E12 -> 0.006 | F6: ='OECD LEONTFD'!F12 -> 1.016 | G6: ='OECD LEONTFD'!G12 -> 0 | H6: ='OECD LEONTFD'!H12 -> 0 | I6: ='OECD LEONTFD'!I12 -> 0 | J6: ='OECD LEONTFD'!J12 -> 0 | K6: ='OECD LEONTFD'!K12 -> 0.001 | L6: ='Weighted Avg BEA Multipliers'!N476 -> 0.0019003888 | M6: ='Weighted Avg BEA Multipliers'!O476 -> 0.0002180874 | N6: ='OECD LEONTFD'!M12 -> 0 | O6: ='Weighted Avg BEA Multipliers'!Q476 -> 0.0011593057 | P6: ='Weighted Avg BEA Multipliers'!R476 -> 0.0020320267 | Q6: ='Weighted Avg BEA Multipliers'!S476 -> 0.0019424567 | R6: ='Weighted Avg BEA Multipliers'!T476 -> 0.0018622353 | S6: ='OECD LEONTFD'!P12 -> 0 | T6: ='OECD LEONTFD'!Q12 -> 0 | U6: ='OECD LEONTFD'!R12 -> 0 | V6: ='OECD LEONTFD'!S12 -> 0 | W6: ='OECD LEONTFD'!T12 -> 0 | X6: ='OECD LEONTFD'!U12 -> 0 | Y6: ='OECD LEONTFD'!V12 -> 0 | Z6: ='Weighted Avg BEA Multipliers'!AB476 -> 0.0016405896 | AA6: ='Weighted Avg BEA Multipliers'!AC476 -> 0.00519324 | AB6: ='Weighted Avg BEA Multipliers'!AD476 -> 0.00039759986 | AC6: ='OECD LEONTFD'!X12 -> 0.001 | AD6: ='OECD LEONTFD'!Y12 -> 0 | AE6: ='OECD LEONTFD'!Z12 -> 0 | AF6: ='OECD LEONTFD'!AA12 -> 0 | AG6: ='OECD LEONTFD'!AB12 -> 0 | AH6: ='OECD LEONTFD'!AC12 -> 0 | AI6: ='OECD LEONTFD'!AD12 -> 0 | AJ6: ='OECD LEONTFD'!AE12 -> 0 | ... AQ6: ='OECD LEONTFD'!AL12 -> 0
A7: ISIC 10T12 | B7: ='OECD LEONTFD'!C13 -> 0.274 | C7: ='Weighted Avg BEA Multipliers'!E477 -> 4.8390044e-05 | D7: ='Weighted Avg BEA Multipliers'!F477 -> 3.5728165e-05 | E7: ='OECD LEONTFD'!E13 -> 0.012 | F7: ='OECD LEONTFD'!F13 -> 0.016 | G7: ='OECD LEONTFD'!G13 -> 1.43 | H7: ='OECD LEONTFD'!H13 -> 0.049 | I7: ='OECD LEONTFD'!I13 -> 0.032 | J7: ='OECD LEONTFD'!J13 -> 0.032 | K7: ='OECD LEONTFD'!K13 -> 0.017 | L7: ='Weighted Avg BEA Multipliers'!N477 -> 0.00039934201 | M7: ='Weighted Avg BEA Multipliers'!O477 -> 0.00073157925 | N7: ='OECD LEONTFD'!M13 -> 0.02 | O7: ='Weighted Avg BEA Multipliers'!Q477 -> 6.416523e-05 | P7: ='Weighted Avg BEA Multipliers'!R477 -> 9.254891e-05 | Q7: ='Weighted Avg BEA Multipliers'!S477 -> 0.00018007689 | R7: ='Weighted Avg BEA Multipliers'!T477 -> 4.5765354e-05 | S7: ='OECD LEONTFD'!P13 -> 0.004 | T7: ='OECD LEONTFD'!Q13 -> 0.006 | U7: ='OECD LEONTFD'!R13 -> 0.003 | V7: ='OECD LEONTFD'!S13 -> 0.006 | W7: ='OECD LEONTFD'!T13 -> 0.006 | X7: ='OECD LEONTFD'!U13 -> 0.007 | Y7: ='OECD LEONTFD'!V13 -> 0.009 | Z7: ='Weighted Avg BEA Multipliers'!AB477 -> 4.7515498e-05 | AA7: ='Weighted Avg BEA Multipliers'!AC477 -> 4.2581032e-05 | AB7: ='Weighted Avg BEA Multipliers'!AD477 -> 8.6533041e-05 | AC7: ='OECD LEONTFD'!X13 -> 0.01 | AD7: ='OECD LEONTFD'!Y13 -> 0.018 | AE7: ='OECD LEONTFD'!Z13 -> 0.008 | AF7: ='OECD LEONTFD'!AA13 -> 0.317 | AG7: ='OECD LEONTFD'!AB13 -> 0.011 | AH7: ='OECD LEONTFD'!AC13 -> 0.004 | AI7: ='OECD LEONTFD'!AD13 -> 0.006 | AJ7: ='OECD LEONTFD'!AE13 -> 0.004 | ... AQ7: ='OECD LEONTFD'!AL13 -> 0
A8: ISIC 13T15 | B8: ='OECD LEONTFD'!C14 -> 0.013 | C8: ='Weighted Avg BEA Multipliers'!E478 -> 8.3947041e-05 | D8: ='Weighted Avg BEA Multipliers'!F478 -> 3.2868661e-05 | E8: ='OECD LEONTFD'!E14 -> 0.015 | F8: ='OECD LEONTFD'!F14 -> 0.025 | G8: ='OECD LEONTFD'!G14 -> 0.015 | H8: ='OECD LEONTFD'!H14 -> 1.221 | I8: ='OECD LEONTFD'!I14 -> 0.04 | J8: ='OECD LEONTFD'!J14 -> 0.01 | K8: ='OECD LEONTFD'!K14 -> 0.01 | L8: ='Weighted Avg BEA Multipliers'!N478 -> 0.00014256418 | M8: ='Weighted Avg BEA Multipliers'!O478 -> 5.3661775e-05 | N8: ='OECD LEONTFD'!M14 -> 0.017 | O8: ='Weighted Avg BEA Multipliers'!Q478 -> 0.00012484643 | P8: ='Weighted Avg BEA Multipliers'!R478 -> 0.00058237112 | Q8: ='Weighted Avg BEA Multipliers'!S478 -> 0.00013648352 | R8: ='Weighted Avg BEA Multipliers'!T478 -> 7.6744028e-05 | S8: ='OECD LEONTFD'!P14 -> 0.006 | T8: ='OECD LEONTFD'!Q14 -> 0.01 | U8: ='OECD LEONTFD'!R14 -> 0.006 | V8: ='OECD LEONTFD'!S14 -> 0.01 | W8: ='OECD LEONTFD'!T14 -> 0.017 | X8: ='OECD LEONTFD'!U14 -> 0.017 | Y8: ='OECD LEONTFD'!V14 -> 0.032 | Z8: ='Weighted Avg BEA Multipliers'!AB478 -> 2.7894273e-05 | AA8: ='Weighted Avg BEA Multipliers'!AC478 -> 2.9689394e-05 | AB8: ='Weighted Avg BEA Multipliers'!AD478 -> 0.00034328169 | AC8: ='OECD LEONTFD'!X14 -> 0.01 | AD8: ='OECD LEONTFD'!Y14 -> 0.015 | AE8: ='OECD LEONTFD'!Z14 -> 0.008 | AF8: ='OECD LEONTFD'!AA14 -> 0.011 | AG8: ='OECD LEONTFD'!AB14 -> 0.014 | AH8: ='OECD LEONTFD'!AC14 -> 0.006 | AI8: ='OECD LEONTFD'!AD14 -> 0.008 | AJ8: ='OECD LEONTFD'!AE14 -> 0.003 | ... AQ8: ='OECD LEONTFD'!AL14 -> 0
A9: ISIC 16 | B9: ='OECD LEONTFD'!C15 -> 0.002 | C9: ='Weighted Avg BEA Multipliers'!E479 -> 0.00097287326 | D9: ='Weighted Avg BEA Multipliers'!F479 -> 0.00020176302 | E9: ='OECD LEONTFD'!E15 -> 0.005 | F9: ='OECD LEONTFD'!F15 -> 0.005 | G9: ='OECD LEONTFD'!G15 -> 0.001 | H9: ='OECD LEONTFD'!H15 -> 0.002 | I9: ='OECD LEONTFD'!I15 -> 1.36 | J9: ='OECD LEONTFD'!J15 -> 0.016 | K9: ='OECD LEONTFD'!K15 -> 0.002 | L9: ='Weighted Avg BEA Multipliers'!N479 -> 0.00060753085 | M9: ='Weighted Avg BEA Multipliers'!O479 -> 0.00021991061 | N9: ='OECD LEONTFD'!M15 -> 0.005 | O9: ='Weighted Avg BEA Multipliers'!Q479 -> 0.0012505455 | P9: ='Weighted Avg BEA Multipliers'!R479 -> 0.0019075598 | Q9: ='Weighted Avg BEA Multipliers'!S479 -> 0.00098361309 | R9: ='Weighted Avg BEA Multipliers'!T479 -> 0.0013599078 | S9: ='OECD LEONTFD'!P15 -> 0.002 | T9: ='OECD LEONTFD'!Q15 -> 0.002 | U9: ='OECD LEONTFD'!R15 -> 0.001 | V9: ='OECD LEONTFD'!S15 -> 0.002 | W9: ='OECD LEONTFD'!T15 -> 0.004 | X9: ='OECD LEONTFD'!U15 -> 0.006 | Y9: ='OECD LEONTFD'!V15 -> 0.046 | Z9: ='Weighted Avg BEA Multipliers'!AB479 -> 0.0003975535 | AA9: ='Weighted Avg BEA Multipliers'!AC479 -> 0.00017855317 | AB9: ='Weighted Avg BEA Multipliers'!AD479 -> 0.00035079213 | AC9: ='OECD LEONTFD'!X15 -> 0.03 | AD9: ='OECD LEONTFD'!Y15 -> 0.001 | AE9: ='OECD LEONTFD'!Z15 -> 0.001 | AF9: ='OECD LEONTFD'!AA15 -> 0.001 | AG9: ='OECD LEONTFD'!AB15 -> 0.001 | AH9: ='OECD LEONTFD'!AC15 -> 0.001 | AI9: ='OECD LEONTFD'!AD15 -> 0.001 | AJ9: ='OECD LEONTFD'!AE15 -> 0 | ... AQ9: ='OECD LEONTFD'!AL15 -> 0
A10: ISIC 17T18 | B10: ='OECD LEONTFD'!C16 -> 0 | C10: ='Weighted Avg BEA Multipliers'!E480 -> 0.0011755592 | D10: ='Weighted Avg BEA Multipliers'!F480 -> 0.00069282355 | E10: ='OECD LEONTFD'!E16 -> 0 | F10: ='OECD LEONTFD'!F16 -> 0 | G10: ='OECD LEONTFD'!G16 -> 0 | H10: ='OECD LEONTFD'!H16 -> 0 | I10: ='OECD LEONTFD'!I16 -> 0.001 | J10: ='OECD LEONTFD'!J16 -> 1.006 | K10: ='OECD LEONTFD'!K16 -> 0 | L10: ='Weighted Avg BEA Multipliers'!N480 -> 0.0037505594 | M10: ='Weighted Avg BEA Multipliers'!O480 -> 0.0031215902 | N10: ='OECD LEONTFD'!M16 -> 0 | O10: ='Weighted Avg BEA Multipliers'!Q480 -> 0.0061699358 | P10: ='Weighted Avg BEA Multipliers'!R480 -> 0.00329503 | Q10: ='Weighted Avg BEA Multipliers'!S480 -> 0.0043331966 | R10: ='Weighted Avg BEA Multipliers'!T480 -> 0.0028407013 | S10: ='OECD LEONTFD'!P16 -> 0 | T10: ='OECD LEONTFD'!Q16 -> 0 | U10: ='OECD LEONTFD'!R16 -> 0 | V10: ='OECD LEONTFD'!S16 -> 0 | W10: ='OECD LEONTFD'!T16 -> 0 | X10: ='OECD LEONTFD'!U16 -> 0 | Y10: ='OECD LEONTFD'!V16 -> 0 | Z10: ='Weighted Avg BEA Multipliers'!AB480 -> 0.00058671539 | AA10: ='Weighted Avg BEA Multipliers'!AC480 -> 0.00058980351 | AB10: ='Weighted Avg BEA Multipliers'!AD480 -> 0.001422224 | AC10: ='OECD LEONTFD'!X16 -> 0 | AD10: ='OECD LEONTFD'!Y16 -> 0 | AE10: ='OECD LEONTFD'!Z16 -> 0 | AF10: ='OECD LEONTFD'!AA16 -> 0 | AG10: ='OECD LEONTFD'!AB16 -> 0.002 | AH10: ='OECD LEONTFD'!AC16 -> 0 | AI10: ='OECD LEONTFD'!AD16 -> 0 | AJ10: ='OECD LEONTFD'!AE16 -> 0 | ... AQ10: ='OECD LEONTFD'!AL16 -> 0
A11: ISIC 19 | B11: ='OECD LEONTFD'!C17 -> 0.03 | C11: ='Weighted Avg BEA Multipliers'!E481 -> 0.060065732 | D11: ='Weighted Avg BEA Multipliers'!F481 -> 0.022708045 | E11: ='OECD LEONTFD'!E17 -> 0.082 | F11: ='OECD LEONTFD'!F17 -> 0.066 | G11: ='OECD LEONTFD'!G17 -> 0.008 | H11: ='OECD LEONTFD'!H17 -> 0.013 | I11: ='OECD LEONTFD'!I17 -> 0.033 | J11: ='OECD LEONTFD'!J17 -> 0.018 | K11: ='OECD LEONTFD'!K17 -> 1.154 | L11: ='Weighted Avg BEA Multipliers'!N481 -> 0.10586097 | M11: ='Weighted Avg BEA Multipliers'!O481 -> 0.013940628 | N11: ='OECD LEONTFD'!M17 -> 0.02 | O11: ='Weighted Avg BEA Multipliers'!Q481 -> 0.033651967 | P11: ='Weighted Avg BEA Multipliers'!R481 -> 0.038328871 | Q11: ='Weighted Avg BEA Multipliers'!S481 -> 0.036553834 | R11: ='Weighted Avg BEA Multipliers'!T481 -> 0.022056971 | S11: ='OECD LEONTFD'!P17 -> 0.006 | T11: ='OECD LEONTFD'!Q17 -> 0.008 | U11: ='OECD LEONTFD'!R17 -> 0.004 | V11: ='OECD LEONTFD'!S17 -> 0.009 | W11: ='OECD LEONTFD'!T17 -> 0.008 | X11: ='OECD LEONTFD'!U17 -> 0.007 | Y11: ='OECD LEONTFD'!V17 -> 0.009 | Z11: ='Weighted Avg BEA Multipliers'!AB481 -> 0.038776857 | AA11: ='Weighted Avg BEA Multipliers'!AC481 -> 0.0092523058 | AB11: ='Weighted Avg BEA Multipliers'!AD481 -> 0.025155287 | AC11: ='OECD LEONTFD'!X17 -> 0.024 | AD11: ='OECD LEONTFD'!Y17 -> 0.008 | AE11: ='OECD LEONTFD'!Z17 -> 0.05 | AF11: ='OECD LEONTFD'!AA17 -> 0.006 | AG11: ='OECD LEONTFD'!AB17 -> 0.008 | AH11: ='OECD LEONTFD'!AC17 -> 0.005 | AI11: ='OECD LEONTFD'!AD17 -> 0.006 | AJ11: ='OECD LEONTFD'!AE17 -> 0.004 | ... AQ11: ='OECD LEONTFD'!AL17 -> 0
A12: ISIC 20 | B12: ='Weighted Avg BEA Multipliers'!D482 -> 0.0073918355 | C12: ='Weighted Avg BEA Multipliers'!E482 -> 0.0036617919 | D12: ='Weighted Avg BEA Multipliers'!F482 -> 0.003173782 | E12: ='Weighted Avg BEA Multipliers'!G482 -> 0.0061211696 | F12: ='Weighted Avg BEA Multipliers'!H482 -> 0.0026872515 | G12: ='Weighted Avg BEA Multipliers'!I482 -> 0.0086131234 | H12: ='Weighted Avg BEA Multipliers'!J482 -> 0.023532605 | I12: ='Weighted Avg BEA Multipliers'!K482 -> 0.0070279062 | ... AQ12: ='Weighted Avg BEA Multipliers'!AS482 -> 0
A13: ISIC 21 | B13: ='Weighted Avg BEA Multipliers'!D483 -> 0.00079814151 | C13: ='Weighted Avg BEA Multipliers'!E483 -> 1.3889469e-05 | D13: ='Weighted Avg BEA Multipliers'!F483 -> 8.2287732e-06 | E13: ='Weighted Avg BEA Multipliers'!G483 -> 2.1035717e-05 | F13: ='Weighted Avg BEA Multipliers'!H483 -> 1.463426e-05 | G13: ='Weighted Avg BEA Multipliers'!I483 -> 0.00047078027 | H13: ='Weighted Avg BEA Multipliers'!J483 -> 4.4867472e-05 | I13: ='Weighted Avg BEA Multipliers'!K483 -> 0.00013963272 | ... AQ13: ='Weighted Avg BEA Multipliers'!AS483 -> 0
A14: ISIC 22 | B14: ='OECD LEONTFD'!C19 -> 0.002 | C14: ='Weighted Avg BEA Multipliers'!E484 -> 0.0020630093 | D14: ='Weighted Avg BEA Multipliers'!F484 -> 0.00064982598 | E14: ='OECD LEONTFD'!E19 -> 0.004 | F14: ='OECD LEONTFD'!F19 -> 0.004 | G14: ='OECD LEONTFD'!G19 -> 0.003 | H14: ='OECD LEONTFD'!H19 -> 0.004 | I14: ='OECD LEONTFD'!I19 -> 0.006 | J14: ='OECD LEONTFD'!J19 -> 0.005 | K14: ='OECD LEONTFD'!K19 -> 0.002 | L14: ='Weighted Avg BEA Multipliers'!N484 -> 0.0042839434 | M14: ='Weighted Avg BEA Multipliers'!O484 -> 0.002758145 | N14: ='OECD LEONTFD'!M19 -> 1.031 | O14: ='Weighted Avg BEA Multipliers'!Q484 -> 0.004173762 | P14: ='Weighted Avg BEA Multipliers'!R484 -> 0.0040823381 | Q14: ='Weighted Avg BEA Multipliers'!S484 -> 0.0021917177 | R14: ='Weighted Avg BEA Multipliers'!T484 -> 0.001571186 | S14: ='OECD LEONTFD'!P19 -> 0.001 | T14: ='OECD LEONTFD'!Q19 -> 0.005 | U14: ='OECD LEONTFD'!R19 -> 0.002 | V14: ='OECD LEONTFD'!S19 -> 0.004 | W14: ='OECD LEONTFD'!T19 -> 0.009 | X14: ='OECD LEONTFD'!U19 -> 0.003 | Y14: ='OECD LEONTFD'!V19 -> 0.004 | Z14: ='Weighted Avg BEA Multipliers'!AB484 -> 0.00053201899 | AA14: ='Weighted Avg BEA Multipliers'!AC484 -> 0.00038799534 | AB14: ='Weighted Avg BEA Multipliers'!AD484 -> 0.0014438811 | AC14: ='OECD LEONTFD'!X19 -> 0.006 | AD14: ='OECD LEONTFD'!Y19 -> 0.001 | AE14: ='OECD LEONTFD'!Z19 -> 0.001 | AF14: ='OECD LEONTFD'!AA19 -> 0.001 | AG14: ='OECD LEONTFD'!AB19 -> 0.001 | AH14: ='OECD LEONTFD'!AC19 -> 0.001 | AI14: ='OECD LEONTFD'!AD19 -> 0 | AJ14: ='OECD LEONTFD'!AE19 -> 0 | ... AQ14: ='OECD LEONTFD'!AL19 -> 0
A15: ISIC 231 | B15: ='Weighted Avg BEA Multipliers'!D485 -> 0.00045576164 | C15: ='Weighted Avg BEA Multipliers'!E485 -> 0.0001691 | D15: ='Weighted Avg BEA Multipliers'!F485 -> 0.0001226 | E15: ='Weighted Avg BEA Multipliers'!G485 -> 0.00020333799 | F15: ='Weighted Avg BEA Multipliers'!H485 -> 0.00018517648 | G15: ='Weighted Avg BEA Multipliers'!I485 -> 0.0052564122 | H15: ='Weighted Avg BEA Multipliers'!J485 -> 0.0019710091 | I15: ='Weighted Avg BEA Multipliers'!K485 -> 0.0020262942 | ... AQ15: ='Weighted Avg BEA Multipliers'!AS485 -> 0
A16: ISIC 239 | B16: ='Weighted Avg BEA Multipliers'!D486 -> 0.00016508363 | C16: ='Weighted Avg BEA Multipliers'!E486 -> 0.0005374531 | D16: ='Weighted Avg BEA Multipliers'!F486 -> 0.00031293118 | E16: ='Weighted Avg BEA Multipliers'!G486 -> 0.00070986614 | F16: ='Weighted Avg BEA Multipliers'!H486 -> 0.00040121696 | G16: ='Weighted Avg BEA Multipliers'!I486 -> 0.0001467997 | H16: ='Weighted Avg BEA Multipliers'!J486 -> 0.00012835261 | I16: ='Weighted Avg BEA Multipliers'!K486 -> 0.00059090674 | ... AQ16: ='Weighted Avg BEA Multipliers'!AS486 -> 0
A17: ISIC 241 | B17: ='Weighted Avg BEA Multipliers'!D487 -> 0.0017905589 | C17: ='Weighted Avg BEA Multipliers'!E487 -> 0.0061225663 | D17: ='Weighted Avg BEA Multipliers'!F487 -> 0.010847028 | E17: ='Weighted Avg BEA Multipliers'!G487 -> 0.012659595 | F17: ='Weighted Avg BEA Multipliers'!H487 -> 0.0052851986 | G17: ='Weighted Avg BEA Multipliers'!I487 -> 0.0034720234 | H17: ='Weighted Avg BEA Multipliers'!J487 -> 0.0042326015 | I17: ='Weighted Avg BEA Multipliers'!K487 -> 0.0069278629 | ... AQ17: ='Weighted Avg BEA Multipliers'!AS487 -> 0
A18: ISIC 242 | B18: ='Weighted Avg BEA Multipliers'!D488 -> 0.00023665584 | C18: ='Weighted Avg BEA Multipliers'!E488 -> 0.00053333216 | D18: ='Weighted Avg BEA Multipliers'!F488 -> 0.00048998175 | E18: ='Weighted Avg BEA Multipliers'!G488 -> 0.00061785833 | F18: ='Weighted Avg BEA Multipliers'!H488 -> 0.0004682479 | G18: ='Weighted Avg BEA Multipliers'!I488 -> 0.0025664241 | H18: ='Weighted Avg BEA Multipliers'!J488 -> 0.00036653095 | I18: ='Weighted Avg BEA Multipliers'!K488 -> 0.00091787669 | ... AQ18: ='Weighted Avg BEA Multipliers'!AS488 -> 0
A19: ISIC 25 | B19: ='OECD LEONTFD'!C22 -> 0 | C19: ='Weighted Avg BEA Multipliers'!E489 -> 0.0016006963 | D19: ='Weighted Avg BEA Multipliers'!F489 -> 0.0018839264 | E19: ='OECD LEONTFD'!E22 -> 0.001 | F19: ='OECD LEONTFD'!F22 -> 0.001 | G19: ='OECD LEONTFD'!G22 -> 0 | H19: ='OECD LEONTFD'!H22 -> 0 | I19: ='OECD LEONTFD'!I22 -> 0.002 | J19: ='OECD LEONTFD'!J22 -> 0 | K19: ='OECD LEONTFD'!K22 -> 0 | L19: ='Weighted Avg BEA Multipliers'!N489 -> 0.0019514917 | M19: ='Weighted Avg BEA Multipliers'!O489 -> 0.00030849987 | N19: ='OECD LEONTFD'!M22 -> 0.001 | O19: ='Weighted Avg BEA Multipliers'!Q489 -> 0.0021242907 | P19: ='Weighted Avg BEA Multipliers'!R489 -> 0.0032473687 | Q19: ='Weighted Avg BEA Multipliers'!S489 -> 0.0054401042 | R19: ='Weighted Avg BEA Multipliers'!T489 -> 0.004059456 | S19: ='OECD LEONTFD'!P22 -> 1.002 | T19: ='OECD LEONTFD'!Q22 -> 0.001 | U19: ='OECD LEONTFD'!R22 -> 0 | V19: ='OECD LEONTFD'!S22 -> 0.002 | W19: ='OECD LEONTFD'!T22 -> 0.002 | X19: ='OECD LEONTFD'!U22 -> 0.001 | Y19: ='OECD LEONTFD'!V22 -> 0.001 | Z19: ='Weighted Avg BEA Multipliers'!AB489 -> 0.00044786765 | AA19: ='Weighted Avg BEA Multipliers'!AC489 -> 0.00073460885 | AB19: ='Weighted Avg BEA Multipliers'!AD489 -> 0.0025920701 | AC19: ='OECD LEONTFD'!X22 -> 0.002 | AD19: ='OECD LEONTFD'!Y22 -> 0 | AE19: ='OECD LEONTFD'!Z22 -> 0 | AF19: ='OECD LEONTFD'!AA22 -> 0 | AG19: ='OECD LEONTFD'!AB22 -> 0 | AH19: ='OECD LEONTFD'!AC22 -> 0 | AI19: ='OECD LEONTFD'!AD22 -> 0 | AJ19: ='OECD LEONTFD'!AE22 -> 0 | ... AQ19: ='OECD LEONTFD'!AL22 -> 0
A20: ISIC 26 | B20: ='OECD LEONTFD'!C23 -> 0.001 | C20: ='Weighted Avg BEA Multipliers'!E490 -> 0.00020746635 | D20: ='Weighted Avg BEA Multipliers'!F490 -> 0.00014001358 | E20: ='OECD LEONTFD'!E23 -> 0.002 | F20: ='OECD LEONTFD'!F23 -> 0.003 | G20: ='OECD LEONTFD'!G23 -> 0 | H20: ='OECD LEONTFD'!H23 -> 0.001 | I20: ='OECD LEONTFD'!I23 -> 0.002 | J20: ='OECD LEONTFD'!J23 -> 0.002 | K20: ='OECD LEONTFD'!K23 -> 0.001 | L20: ='Weighted Avg BEA Multipliers'!N490 -> 0.00080928569 | M20: ='Weighted Avg BEA Multipliers'!O490 -> 0.00012078361 | N20: ='OECD LEONTFD'!M23 -> 0.002 | O20: ='Weighted Avg BEA Multipliers'!Q490 -> 0.0011022202 | P20: ='Weighted Avg BEA Multipliers'!R490 -> 0.00090920837 | Q20: ='Weighted Avg BEA Multipliers'!S490 -> 0.00065263018 | R20: ='Weighted Avg BEA Multipliers'!T490 -> 0.001225647 | S20: ='OECD LEONTFD'!P23 -> 0.001 | T20: ='OECD LEONTFD'!Q23 -> 1.1 | U20: ='OECD LEONTFD'!R23 -> 0.004 | V20: ='OECD LEONTFD'!S23 -> 0.006 | W20: ='OECD LEONTFD'!T23 -> 0.006 | X20: ='OECD LEONTFD'!U23 -> 0.003 | Y20: ='OECD LEONTFD'!V23 -> 0.002 | Z20: ='Weighted Avg BEA Multipliers'!AB490 -> 7.4960734e-05 | AA20: ='Weighted Avg BEA Multipliers'!AC490 -> 7.9689758e-05 | AB20: ='Weighted Avg BEA Multipliers'!AD490 -> 0.00041158355 | AC20: ='OECD LEONTFD'!X23 -> 0.002 | AD20: ='OECD LEONTFD'!Y23 -> 0.001 | AE20: ='OECD LEONTFD'!Z23 -> 0.001 | AF20: ='OECD LEONTFD'!AA23 -> 0.001 | AG20: ='OECD LEONTFD'!AB23 -> 0.002 | AH20: ='OECD LEONTFD'!AC23 -> 0.01 | AI20: ='OECD LEONTFD'!AD23 -> 0.006 | AJ20: ='OECD LEONTFD'!AE23 -> 0.001 | ... AQ20: ='OECD LEONTFD'!AL23 -> 0
A21: ISIC 27 | B21: ='OECD LEONTFD'!C24 -> 0.001 | C21: ='Weighted Avg BEA Multipliers'!E491 -> 0.00011552758 | D21: ='Weighted Avg BEA Multipliers'!F491 -> 0.00011759371 | E21: ='OECD LEONTFD'!E24 -> 0.004 | F21: ='OECD LEONTFD'!F24 -> 0.004 | G21: ='OECD LEONTFD'!G24 -> 0.001 | H21: ='OECD LEONTFD'!H24 -> 0.001 | I21: ='OECD LEONTFD'!I24 -> 0.003 | J21: ='OECD LEONTFD'!J24 -> 0.002 | K21: ='OECD LEONTFD'!K24 -> 0.002 | L21: ='Weighted Avg BEA Multipliers'!N491 -> 0.00016310068 | M21: ='Weighted Avg BEA Multipliers'!O491 -> 4.0447786e-05 | N21: ='OECD LEONTFD'!M24 -> 0.003 | O21: ='Weighted Avg BEA Multipliers'!Q491 -> 0.00027939343 | P21: ='Weighted Avg BEA Multipliers'!R491 -> 0.00015065807 | Q21: ='Weighted Avg BEA Multipliers'!S491 -> 0.00041634698 | R21: ='Weighted Avg BEA Multipliers'!T491 -> 0.0013445855 | S21: ='OECD LEONTFD'!P24 -> 0.002 | T21: ='OECD LEONTFD'!Q24 -> 0.022 | U21: ='OECD LEONTFD'!R24 -> 1.023 | V21: ='OECD LEONTFD'!S24 -> 0.014 | W21: ='OECD LEONTFD'!T24 -> 0.014 | X21: ='OECD LEONTFD'!U24 -> 0.007 | Y21: ='OECD LEONTFD'!V24 -> 0.003 | Z21: ='Weighted Avg BEA Multipliers'!AB491 -> 9.5767037e-05 | AA21: ='Weighted Avg BEA Multipliers'!AC491 -> 6.3517369e-05 | AB21: ='Weighted Avg BEA Multipliers'!AD491 -> 0.0002685632 | AC21: ='OECD LEONTFD'!X24 -> 0.012 | AD21: ='OECD LEONTFD'!Y24 -> 0.001 | AE21: ='OECD LEONTFD'!Z24 -> 0.001 | AF21: ='OECD LEONTFD'!AA24 -> 0.001 | AG21: ='OECD LEONTFD'!AB24 -> 0.001 | AH21: ='OECD LEONTFD'!AC24 -> 0.003 | AI21: ='OECD LEONTFD'!AD24 -> 0.002 | AJ21: ='OECD LEONTFD'!AE24 -> 0 | ... AQ21: ='OECD LEONTFD'!AL24 -> 0
A22: ISIC 28 | B22: ='OECD LEONTFD'!C25 -> 0.002 | C22: ='Weighted Avg BEA Multipliers'!E492 -> 0.0017958815 | D22: ='Weighted Avg BEA Multipliers'!F492 -> 0.0007153966 | E22: ='OECD LEONTFD'!E25 -> 0.01 | F22: ='OECD LEONTFD'!F25 -> 0.015 | G22: ='OECD LEONTFD'!G25 -> 0.001 | H22: ='OECD LEONTFD'!H25 -> 0.002 | I22: ='OECD LEONTFD'!I25 -> 0.004 | J22: ='OECD LEONTFD'!J25 -> 0.003 | K22: ='OECD LEONTFD'!K25 -> 0.002 | L22: ='Weighted Avg BEA Multipliers'!N492 -> 0.00026613648 | M22: ='Weighted Avg BEA Multipliers'!O492 -> 4.853261e-05 | N22: ='OECD LEONTFD'!M25 -> 0.002 | O22: ='Weighted Avg BEA Multipliers'!Q492 -> 0.00022507237 | P22: ='Weighted Avg BEA Multipliers'!R492 -> 0.00023821033 | Q22: ='Weighted Avg BEA Multipliers'!S492 -> 0.00050787413 | R22: ='Weighted Avg BEA Multipliers'!T492 -> 0.00035941281 | S22: ='OECD LEONTFD'!P25 -> 0.002 | T22: ='OECD LEONTFD'!Q25 -> 0.002 | U22: ='OECD LEONTFD'!R25 -> 0.001 | V22: ='OECD LEONTFD'!S25 -> 1.02 | W22: ='OECD LEONTFD'!T25 -> 0.007 | X22: ='OECD LEONTFD'!U25 -> 0.007 | Y22: ='OECD LEONTFD'!V25 -> 0.002 | Z22: ='Weighted Avg BEA Multipliers'!AB492 -> 0.00017106672 | AA22: ='Weighted Avg BEA Multipliers'!AC492 -> 0.00016021804 | AB22: ='Weighted Avg BEA Multipliers'!AD492 -> 0.00085774693 | AC22: ='OECD LEONTFD'!X25 -> 0.004 | AD22: ='OECD LEONTFD'!Y25 -> 0.001 | AE22: ='OECD LEONTFD'!Z25 -> 0.001 | AF22: ='OECD LEONTFD'!AA25 -> 0 | AG22: ='OECD LEONTFD'!AB25 -> 0 | AH22: ='OECD LEONTFD'!AC25 -> 0 | AI22: ='OECD LEONTFD'!AD25 -> 0 | AJ22: ='OECD LEONTFD'!AE25 -> 0 | ... AQ22: ='OECD LEONTFD'!AL25 -> 0
A23: ISIC 29 | B23: ='OECD LEONTFD'!C26 -> 0.001 | C23: ='Weighted Avg BEA Multipliers'!E493 -> 0.00053780033 | D23: ='Weighted Avg BEA Multipliers'!F493 -> 0.0001966581 | E23: ='OECD LEONTFD'!E26 -> 0.004 | F23: ='OECD LEONTFD'!F26 -> 0.004 | G23: ='OECD LEONTFD'!G26 -> 0.001 | H23: ='OECD LEONTFD'!H26 -> 0.001 | I23: ='OECD LEONTFD'!I26 -> 0.004 | J23: ='OECD LEONTFD'!J26 -> 0.001 | K23: ='OECD LEONTFD'!K26 -> 0.001 | L23: ='Weighted Avg BEA Multipliers'!N493 -> 0.00027873548 | M23: ='Weighted Avg BEA Multipliers'!O493 -> 8.5801045e-05 | N23: ='OECD LEONTFD'!M26 -> 0.002 | O23: ='Weighted Avg BEA Multipliers'!Q493 -> 0.00035797055 | P23: ='Weighted Avg BEA Multipliers'!R493 -> 0.00049138317 | Q23: ='Weighted Avg BEA Multipliers'!S493 -> 0.0013908673 | R23: ='Weighted Avg BEA Multipliers'!T493 -> 0.00034280753 | S23: ='OECD LEONTFD'!P26 -> 0.001 | T23: ='OECD LEONTFD'!Q26 -> 0.001 | U23: ='OECD LEONTFD'!R26 -> 0.001 | V23: ='OECD LEONTFD'!S26 -> 0.005 | W23: ='OECD LEONTFD'!T26 -> 1.113 | X23: ='OECD LEONTFD'!U26 -> 0.002 | Y23: ='OECD LEONTFD'!V26 -> 0.001 | Z23: ='Weighted Avg BEA Multipliers'!AB493 -> 8.2545019e-05 | AA23: ='Weighted Avg BEA Multipliers'!AC493 -> 7.8661737e-05 | AB23: ='Weighted Avg BEA Multipliers'!AD493 -> 0.0011674874 | AC23: ='OECD LEONTFD'!X26 -> 0.002 | AD23: ='OECD LEONTFD'!Y26 -> 0.004 | AE23: ='OECD LEONTFD'!Z26 -> 0.003 | AF23: ='OECD LEONTFD'!AA26 -> 0.001 | AG23: ='OECD LEONTFD'!AB26 -> 0.001 | AH23: ='OECD LEONTFD'!AC26 -> 0.001 | AI23: ='OECD LEONTFD'!AD26 -> 0.001 | AJ23: ='OECD LEONTFD'!AE26 -> 0 | ... AQ23: ='OECD LEONTFD'!AL26 -> 0
A24: ISIC 30 | B24: ='OECD LEONTFD'!C27 -> 0.001 | C24: ='Weighted Avg BEA Multipliers'!E494 -> 0.0001137889 | D24: ='Weighted Avg BEA Multipliers'!F494 -> 2.7788818e-05 | E24: ='OECD LEONTFD'!E27 -> 0 | F24: ='OECD LEONTFD'!F27 -> 0 | G24: ='OECD LEONTFD'!G27 -> 0 | H24: ='OECD LEONTFD'!H27 -> 0 | I24: ='OECD LEONTFD'!I27 -> 0 | J24: ='OECD LEONTFD'!J27 -> 0 | K24: ='OECD LEONTFD'!K27 -> 0 | L24: ='Weighted Avg BEA Multipliers'!N494 -> 3.4596057e-05 | M24: ='Weighted Avg BEA Multipliers'!O494 -> 8.7361854e-06 | N24: ='OECD LEONTFD'!M27 -> 0 | O24: ='Weighted Avg BEA Multipliers'!Q494 -> 5.6719701e-05 | P24: ='Weighted Avg BEA Multipliers'!R494 -> 5.7203362e-05 | Q24: ='Weighted Avg BEA Multipliers'!S494 -> 0.00021402426 | R24: ='Weighted Avg BEA Multipliers'!T494 -> 3.2848821e-05 | S24: ='OECD LEONTFD'!P27 -> 0 | T24: ='OECD LEONTFD'!Q27 -> 0 | U24: ='OECD LEONTFD'!R27 -> 0 | V24: ='OECD LEONTFD'!S27 -> 0 | W24: ='OECD LEONTFD'!T27 -> 0 | X24: ='OECD LEONTFD'!U27 -> 1.021 | Y24: ='OECD LEONTFD'!V27 -> 0 | Z24: ='Weighted Avg BEA Multipliers'!AB494 -> 4.2190161e-05 | AA24: ='Weighted Avg BEA Multipliers'!AC494 -> 1.6617532e-05 | AB24: ='Weighted Avg BEA Multipliers'!AD494 -> 3.7731154e-05 | AC24: ='OECD LEONTFD'!X27 -> 0 | AD24: ='OECD LEONTFD'!Y27 -> 0 | AE24: ='OECD LEONTFD'!Z27 -> 0.002 | AF24: ='OECD LEONTFD'!AA27 -> 0 | AG24: ='OECD LEONTFD'!AB27 -> 0 | AH24: ='OECD LEONTFD'!AC27 -> 0 | AI24: ='OECD LEONTFD'!AD27 -> 0 | AJ24: ='OECD LEONTFD'!AE27 -> 0 | ... AQ24: ='OECD LEONTFD'!AL27 -> 0
A25: ISIC 31T33 | B25: ='OECD LEONTFD'!C28 -> 0.001 | C25: ='Weighted Avg BEA Multipliers'!E495 -> 0.00043596239 | D25: ='Weighted Avg BEA Multipliers'!F495 -> 0.00029847403 | E25: ='OECD LEONTFD'!E28 -> 0.001 | F25: ='OECD LEONTFD'!F28 -> 0.001 | G25: ='OECD LEONTFD'!G28 -> 0.003 | H25: ='OECD LEONTFD'!H28 -> 0.002 | I25: ='OECD LEONTFD'!I28 -> 0.002 | J25: ='OECD LEONTFD'!J28 -> 0.004 | K25: ='OECD LEONTFD'!K28 -> 0 | L25: ='Weighted Avg BEA Multipliers'!N495 -> 0.0009299995 | M25: ='Weighted Avg BEA Multipliers'!O495 -> 0.00038375538 | N25: ='OECD LEONTFD'!M28 -> 0.001 | O25: ='Weighted Avg BEA Multipliers'!Q495 -> 0.0011721956 | P25: ='Weighted Avg BEA Multipliers'!R495 -> 0.0010637019 | Q25: ='Weighted Avg BEA Multipliers'!S495 -> 0.0010085308 | R25: ='Weighted Avg BEA Multipliers'!T495 -> 0.00075036502 | S25: ='OECD LEONTFD'!P28 -> 0 | T25: ='OECD LEONTFD'!Q28 -> 0 | U25: ='OECD LEONTFD'!R28 -> 0 | V25: ='OECD LEONTFD'!S28 -> 0.001 | W25: ='OECD LEONTFD'!T28 -> 0.001 | X25: ='OECD LEONTFD'!U28 -> 0.001 | Y25: ='OECD LEONTFD'!V28 -> 1.002 | Z25: ='Weighted Avg BEA Multipliers'!AB495 -> 0.00024495313 | AA25: ='Weighted Avg BEA Multipliers'!AC495 -> 0.00034327994 | AB25: ='Weighted Avg BEA Multipliers'!AD495 -> 0.0026707233 | AC25: ='OECD LEONTFD'!X28 -> 0.001 | AD25: ='OECD LEONTFD'!Y28 -> 0 | AE25: ='OECD LEONTFD'!Z28 -> 0 | AF25: ='OECD LEONTFD'!AA28 -> 0.001 | AG25: ='OECD LEONTFD'!AB28 -> 0.001 | AH25: ='OECD LEONTFD'!AC28 -> 0 | AI25: ='OECD LEONTFD'!AD28 -> 0 | AJ25: ='OECD LEONTFD'!AE28 -> 0 | ... AQ25: ='OECD LEONTFD'!AL28 -> 0
A26: ISIC 351 | B26: ='Weighted Avg BEA Multipliers'!D496 -> 0.014465011 | C26: ='Weighted Avg BEA Multipliers'!E496 -> 0.0295842 | D26: ='Weighted Avg BEA Multipliers'!F496 -> 0.0137376 | E26: ='Weighted Avg BEA Multipliers'!G496 -> 0.047963592 | F26: ='Weighted Avg BEA Multipliers'!H496 -> 0.0048063029 | G26: ='Weighted Avg BEA Multipliers'!I496 -> 0.020639786 | H26: ='Weighted Avg BEA Multipliers'!J496 -> 0.02940217 | I26: ='Weighted Avg BEA Multipliers'!K496 -> 0.029479147 | ... AQ26: ='Weighted Avg BEA Multipliers'!AS496 -> 0
A27: ISIC 352T353 | B27: ='Weighted Avg BEA Multipliers'!D497 -> 0.0072812674 | C27: ='Weighted Avg BEA Multipliers'!E497 -> 0.0021629 | D27: ='Weighted Avg BEA Multipliers'!F497 -> 0.0028386 | E27: ='Weighted Avg BEA Multipliers'!G497 -> 0.0072437037 | F27: ='Weighted Avg BEA Multipliers'!H497 -> 0.0011110647 | G27: ='Weighted Avg BEA Multipliers'!I497 -> 0.0062433237 | H27: ='Weighted Avg BEA Multipliers'!J497 -> 0.0054971923 | I27: ='Weighted Avg BEA Multipliers'!K497 -> 0.0041364979 | ... AQ27: ='Weighted Avg BEA Multipliers'!AS497 -> 0
A28: ISIC 36T39 | B28: ='Weighted Avg BEA Multipliers'!D498 -> 0.0025254014 | C28: ='Weighted Avg BEA Multipliers'!E498 -> 0.0041167778 | D28: ='Weighted Avg BEA Multipliers'!F498 -> 0.0048645842 | E28: ='Weighted Avg BEA Multipliers'!G498 -> 0.0043939941 | F28: ='Weighted Avg BEA Multipliers'!H498 -> 0.0030532597 | G28: ='Weighted Avg BEA Multipliers'!I498 -> 0.0036674741 | H28: ='Weighted Avg BEA Multipliers'!J498 -> 0.0034480994 | I28: ='Weighted Avg BEA Multipliers'!K498 -> 0.0032139013 | ... AQ28: ='Weighted Avg BEA Multipliers'!AS498 -> 0
A29: ISIC 41T43 | B29: ='OECD LEONTFD'!C30 -> 0.007 | C29: ='Weighted Avg BEA Multipliers'!E499 -> 0.0036870845 | D29: ='Weighted Avg BEA Multipliers'!F499 -> 0.0012603734 | E29: ='OECD LEONTFD'!E30 -> 0.027 | F29: ='OECD LEONTFD'!F30 -> 0.028 | G29: ='OECD LEONTFD'!G30 -> 0.003 | H29: ='OECD LEONTFD'!H30 -> 0.006 | I29: ='OECD LEONTFD'!I30 -> 0.017 | J29: ='OECD LEONTFD'!J30 -> 0.009 | K29: ='OECD LEONTFD'!K30 -> 0.011 | L29: ='Weighted Avg BEA Multipliers'!N499 -> 0.0017360658 | M29: ='Weighted Avg BEA Multipliers'!O499 -> 0.00058217776 | N29: ='OECD LEONTFD'!M30 -> 0.008 | O29: ='Weighted Avg BEA Multipliers'!Q499 -> 0.0019127665 | P29: ='Weighted Avg BEA Multipliers'!R499 -> 0.0020527366 | Q29: ='Weighted Avg BEA Multipliers'!S499 -> 0.0019592694 | R29: ='Weighted Avg BEA Multipliers'!T499 -> 0.0014092481 | S29: ='OECD LEONTFD'!P30 -> 0.004 | T29: ='OECD LEONTFD'!Q30 -> 0.005 | U29: ='OECD LEONTFD'!R30 -> 0.002 | V29: ='OECD LEONTFD'!S30 -> 0.006 | W29: ='OECD LEONTFD'!T30 -> 0.005 | X29: ='OECD LEONTFD'!U30 -> 0.003 | Y29: ='OECD LEONTFD'!V30 -> 0.005 | Z29: ='Weighted Avg BEA Multipliers'!AB499 -> 0.0046834165 | AA29: ='Weighted Avg BEA Multipliers'!AC499 -> 0.0015327566 | AB29: ='Weighted Avg BEA Multipliers'!AD499 -> 0.0011292778 | AC29: ='OECD LEONTFD'!X30 -> 1.115 | AD29: ='OECD LEONTFD'!Y30 -> 0.006 | AE29: ='OECD LEONTFD'!Z30 -> 0.006 | AF29: ='OECD LEONTFD'!AA30 -> 0.004 | AG29: ='OECD LEONTFD'!AB30 -> 0.005 | AH29: ='OECD LEONTFD'!AC30 -> 0.009 | AI29: ='OECD LEONTFD'!AD30 -> 0.004 | AJ29: ='OECD LEONTFD'!AE30 -> 0.004 | ... AQ29: ='OECD LEONTFD'!AL30 -> 0
A30: ISIC 45T47 | B30: ='OECD LEONTFD'!C31 -> 0.168 | C30: ='Weighted Avg BEA Multipliers'!E500 -> 0.004640983 | D30: ='Weighted Avg BEA Multipliers'!F500 -> 0.0019476673 | E30: ='OECD LEONTFD'!E31 -> 0.171 | F30: ='OECD LEONTFD'!F31 -> 0.182 | G30: ='OECD LEONTFD'!G31 -> 0.236 | H30: ='OECD LEONTFD'!H31 -> 0.169 | I30: ='OECD LEONTFD'!I31 -> 0.404 | J30: ='OECD LEONTFD'!J31 -> 0.104 | K30: ='OECD LEONTFD'!K31 -> 0.135 | L30: ='Weighted Avg BEA Multipliers'!N500 -> 0.0081993582 | M30: ='Weighted Avg BEA Multipliers'!O500 -> 0.0059061112 | N30: ='OECD LEONTFD'!M31 -> 0.113 | O30: ='Weighted Avg BEA Multipliers'!Q500 -> 0.0058505657 | P30: ='Weighted Avg BEA Multipliers'!R500 -> 0.0054245734 | Q30: ='Weighted Avg BEA Multipliers'!S500 -> 0.01141489 | R30: ='Weighted Avg BEA Multipliers'!T500 -> 0.0085038659 | S30: ='OECD LEONTFD'!P31 -> 0.089 | T30: ='OECD LEONTFD'!Q31 -> 0.11 | U30: ='OECD LEONTFD'!R31 -> 0.082 | V30: ='OECD LEONTFD'!S31 -> 0.147 | W30: ='OECD LEONTFD'!T31 -> 0.134 | X30: ='OECD LEONTFD'!U31 -> 0.097 | Y30: ='OECD LEONTFD'!V31 -> 0.128 | Z30: ='Weighted Avg BEA Multipliers'!AB500 -> 0.0015073034 | AA30: ='Weighted Avg BEA Multipliers'!AC500 -> 0.0010742262 | AB30: ='Weighted Avg BEA Multipliers'!AD500 -> 0.0030731854 | AC30: ='OECD LEONTFD'!X31 -> 0.133 | AD30: ='OECD LEONTFD'!Y31 -> 1.191 | AE30: ='OECD LEONTFD'!Z31 -> 0.09 | AF30: ='OECD LEONTFD'!AA31 -> 0.159 | AG30: ='OECD LEONTFD'!AB31 -> 0.174 | AH30: ='OECD LEONTFD'!AC31 -> 0.082 | AI30: ='OECD LEONTFD'!AD31 -> 0.103 | AJ30: ='OECD LEONTFD'!AE31 -> 0.029 | ... AQ30: ='OECD LEONTFD'!AL31 -> 0
A31: ISIC 49T53 | B31: ='OECD LEONTFD'!C32 -> 0.026 | C31: ='Weighted Avg BEA Multipliers'!E501 -> 0.008224352 | D31: ='Weighted Avg BEA Multipliers'!F501 -> 0.0035527366 | E31: ='OECD LEONTFD'!E32 -> 0.101 | F31: ='OECD LEONTFD'!F32 -> 0.122 | G31: ='OECD LEONTFD'!G32 -> 0.022 | H31: ='OECD LEONTFD'!H32 -> 0.028 | I31: ='OECD LEONTFD'!I32 -> 0.068 | J31: ='OECD LEONTFD'!J32 -> 0.047 | K31: ='OECD LEONTFD'!K32 -> 0.043 | L31: ='Weighted Avg BEA Multipliers'!N501 -> 0.010157017 | M31: ='Weighted Avg BEA Multipliers'!O501 -> 0.0039118209 | N31: ='OECD LEONTFD'!M32 -> 0.041 | O31: ='Weighted Avg BEA Multipliers'!Q501 -> 0.014475468 | P31: ='Weighted Avg BEA Multipliers'!R501 -> 0.016363018 | Q31: ='Weighted Avg BEA Multipliers'!S501 -> 0.018867352 | R31: ='Weighted Avg BEA Multipliers'!T501 -> 0.013550617 | S31: ='OECD LEONTFD'!P32 -> 0.014 | T31: ='OECD LEONTFD'!Q32 -> 0.058 | U31: ='OECD LEONTFD'!R32 -> 0.009 | V31: ='OECD LEONTFD'!S32 -> 0.028 | W31: ='OECD LEONTFD'!T32 -> 0.023 | X31: ='OECD LEONTFD'!U32 -> 0.022 | Y31: ='OECD LEONTFD'!V32 -> 0.022 | Z31: ='Weighted Avg BEA Multipliers'!AB501 -> 0.0078474047 | AA31: ='Weighted Avg BEA Multipliers'!AC501 -> 0.0049009467 | AB31: ='Weighted Avg BEA Multipliers'!AD501 -> 0.0074264982 | AC31: ='OECD LEONTFD'!X32 -> 0.053 | AD31: ='OECD LEONTFD'!Y32 -> 0.029 | AE31: ='OECD LEONTFD'!Z32 -> 1.074 | AF31: ='OECD LEONTFD'!AA32 -> 0.019 | AG31: ='OECD LEONTFD'!AB32 -> 0.069 | AH31: ='OECD LEONTFD'!AC32 -> 0.035 | AI31: ='OECD LEONTFD'!AD32 -> 0.044 | AJ31: ='OECD LEONTFD'!AE32 -> 0.024 | ... AQ31: ='OECD LEONTFD'!AL32 -> 0
A32: ISIC 55T56 | B32: ='OECD LEONTFD'!C33 -> 0.002 | C32: ='Weighted Avg BEA Multipliers'!E502 -> 0.0012620637 | D32: ='Weighted Avg BEA Multipliers'!F502 -> 0.0010472053 | E32: ='OECD LEONTFD'!E33 -> 0.006 | F32: ='OECD LEONTFD'!F33 -> 0.014 | G32: ='OECD LEONTFD'!G33 -> 0.002 | H32: ='OECD LEONTFD'!H33 -> 0.003 | I32: ='OECD LEONTFD'!I33 -> 0.008 | J32: ='OECD LEONTFD'!J33 -> 0.004 | K32: ='OECD LEONTFD'!K33 -> 0.003 | L32: ='Weighted Avg BEA Multipliers'!N502 -> 0.0014422221 | M32: ='Weighted Avg BEA Multipliers'!O502 -> 0.00087531674 | N32: ='OECD LEONTFD'!M33 -> 0.004 | O32: ='Weighted Avg BEA Multipliers'!Q502 -> 0.002600068 | P32: ='Weighted Avg BEA Multipliers'!R502 -> 0.002964328 | Q32: ='Weighted Avg BEA Multipliers'!S502 -> 0.0030217047 | R32: ='Weighted Avg BEA Multipliers'!T502 -> 0.0018633807 | S32: ='OECD LEONTFD'!P33 -> 0.002 | T32: ='OECD LEONTFD'!Q33 -> 0.003 | U32: ='OECD LEONTFD'!R33 -> 0.001 | V32: ='OECD LEONTFD'!S33 -> 0.003 | W32: ='OECD LEONTFD'!T33 -> 0.003 | X32: ='OECD LEONTFD'!U33 -> 0.004 | Y32: ='OECD LEONTFD'!V33 -> 0.002 | Z32: ='Weighted Avg BEA Multipliers'!AB502 -> 0.0028574402 | AA32: ='Weighted Avg BEA Multipliers'!AC502 -> 0.0024128822 | AB32: ='Weighted Avg BEA Multipliers'!AD502 -> 0.0043578938 | AC32: ='OECD LEONTFD'!X33 -> 0.004 | AD32: ='OECD LEONTFD'!Y33 -> 0.004 | AE32: ='OECD LEONTFD'!Z33 -> 0.005 | AF32: ='OECD LEONTFD'!AA33 -> 1.003 | AG32: ='OECD LEONTFD'!AB33 -> 0.005 | AH32: ='OECD LEONTFD'!AC33 -> 0.002 | AI32: ='OECD LEONTFD'!AD33 -> 0.006 | AJ32: ='OECD LEONTFD'!AE33 -> 0.004 | ... AQ32: ='OECD LEONTFD'!AL33 -> 0
A33: ISIC 58T60 | B33: ='OECD LEONTFD'!C34 -> 0.003 | C33: ='Weighted Avg BEA Multipliers'!E503 -> 0.00070406259 | D33: ='Weighted Avg BEA Multipliers'!F503 -> 0.00087983943 | E33: ='OECD LEONTFD'!E34 -> 0.004 | F33: ='OECD LEONTFD'!F34 -> 0.004 | G33: ='OECD LEONTFD'!G34 -> 0.004 | H33: ='OECD LEONTFD'!H34 -> 0.003 | I33: ='OECD LEONTFD'!I34 -> 0.007 | J33: ='OECD LEONTFD'!J34 -> 0.014 | K33: ='OECD LEONTFD'!K34 -> 0.005 | L33: ='Weighted Avg BEA Multipliers'!N503 -> 0.00076180824 | M33: ='Weighted Avg BEA Multipliers'!O503 -> 0.0015166397 | N33: ='OECD LEONTFD'!M34 -> 0.004 | O33: ='Weighted Avg BEA Multipliers'!Q503 -> 0.00087082367 | P33: ='Weighted Avg BEA Multipliers'!R503 -> 0.00095973146 | Q33: ='Weighted Avg BEA Multipliers'!S503 -> 0.00092466783 | R33: ='Weighted Avg BEA Multipliers'!T503 -> 0.00070005885 | S33: ='OECD LEONTFD'!P34 -> 0.002 | T33: ='OECD LEONTFD'!Q34 -> 0.005 | U33: ='OECD LEONTFD'!R34 -> 0.001 | V33: ='OECD LEONTFD'!S34 -> 0.003 | W33: ='OECD LEONTFD'!T34 -> 0.003 | X33: ='OECD LEONTFD'!U34 -> 0.002 | Y33: ='OECD LEONTFD'!V34 -> 0.003 | Z33: ='Weighted Avg BEA Multipliers'!AB503 -> 0.00068808523 | AA33: ='Weighted Avg BEA Multipliers'!AC503 -> 0.00093861492 | AB33: ='Weighted Avg BEA Multipliers'!AD503 -> 0.00098919786 | AC33: ='OECD LEONTFD'!X34 -> 0.004 | AD33: ='OECD LEONTFD'!Y34 -> 0.005 | AE33: ='OECD LEONTFD'!Z34 -> 0.003 | AF33: ='OECD LEONTFD'!AA34 -> 0.003 | AG33: ='OECD LEONTFD'!AB34 -> 1.087 | AH33: ='OECD LEONTFD'!AC34 -> 0.013 | AI33: ='OECD LEONTFD'!AD34 -> 0.014 | AJ33: ='OECD LEONTFD'!AE34 -> 0.005 | ... AQ33: ='OECD LEONTFD'!AL34 -> 0
A34: ISIC 61 | B34: ='OECD LEONTFD'!C35 -> 0.004 | C34: ='Weighted Avg BEA Multipliers'!E504 -> 0.0032787871 | D34: ='Weighted Avg BEA Multipliers'!F504 -> 0.0031680007 | E34: ='OECD LEONTFD'!E35 -> 0.011 | F34: ='OECD LEONTFD'!F35 -> 0.013 | G34: ='OECD LEONTFD'!G35 -> 0.003 | H34: ='OECD LEONTFD'!H35 -> 0.007 | I34: ='OECD LEONTFD'!I35 -> 0.012 | J34: ='OECD LEONTFD'!J35 -> 0.007 | K34: ='OECD LEONTFD'!K35 -> 0.006 | L34: ='Weighted Avg BEA Multipliers'!N504 -> 0.00257378 | M34: ='Weighted Avg BEA Multipliers'!O504 -> 0.0031589718 | N34: ='OECD LEONTFD'!M35 -> 0.007 | O34: ='Weighted Avg BEA Multipliers'!Q504 -> 0.0039005617 | P34: ='Weighted Avg BEA Multipliers'!R504 -> 0.0044618168 | Q34: ='Weighted Avg BEA Multipliers'!S504 -> 0.0038392476 | R34: ='Weighted Avg BEA Multipliers'!T504 -> 0.0028075878 | S34: ='OECD LEONTFD'!P35 -> 0.003 | T34: ='OECD LEONTFD'!Q35 -> 0.007 | U34: ='OECD LEONTFD'!R35 -> 0.002 | V34: ='OECD LEONTFD'!S35 -> 0.006 | W34: ='OECD LEONTFD'!T35 -> 0.005 | X34: ='OECD LEONTFD'!U35 -> 0.004 | Y34: ='OECD LEONTFD'!V35 -> 0.004 | Z34: ='Weighted Avg BEA Multipliers'!AB504 -> 0.0035017566 | AA34: ='Weighted Avg BEA Multipliers'!AC504 -> 0.0028642505 | AB34: ='Weighted Avg BEA Multipliers'!AD504 -> 0.0055137235 | AC34: ='OECD LEONTFD'!X35 -> 0.006 | AD34: ='OECD LEONTFD'!Y35 -> 0.006 | AE34: ='OECD LEONTFD'!Z35 -> 0.007 | AF34: ='OECD LEONTFD'!AA35 -> 0.004 | AG34: ='OECD LEONTFD'!AB35 -> 0.018 | AH34: ='OECD LEONTFD'!AC35 -> 1.109 | AI34: ='OECD LEONTFD'!AD35 -> 0.016 | AJ34: ='OECD LEONTFD'!AE35 -> 0.01 | ... AQ34: ='OECD LEONTFD'!AL35 -> 0
A35: ISIC 62T63 | B35: ='OECD LEONTFD'!C36 -> 0.002 | C35: ='Weighted Avg BEA Multipliers'!E505 -> 0.0017580418 | D35: ='Weighted Avg BEA Multipliers'!F505 -> 0.0031120665 | E35: ='OECD LEONTFD'!E36 -> 0.006 | F35: ='OECD LEONTFD'!F36 -> 0.006 | G35: ='OECD LEONTFD'!G36 -> 0.003 | H35: ='OECD LEONTFD'!H36 -> 0.004 | I35: ='OECD LEONTFD'!I36 -> 0.008 | J35: ='OECD LEONTFD'!J36 -> 0.006 | K35: ='OECD LEONTFD'!K36 -> 0.006 | L35: ='Weighted Avg BEA Multipliers'!N505 -> 0.0018681741 | M35: ='Weighted Avg BEA Multipliers'!O505 -> 0.0024096243 | N35: ='OECD LEONTFD'!M36 -> 0.005 | O35: ='Weighted Avg BEA Multipliers'!Q505 -> 0.0031599722 | P35: ='Weighted Avg BEA Multipliers'!R505 -> 0.0032622859 | Q35: ='Weighted Avg BEA Multipliers'!S505 -> 0.0026682217 | R35: ='Weighted Avg BEA Multipliers'!T505 -> 0.0021926603 | S35: ='OECD LEONTFD'!P36 -> 0.002 | T35: ='OECD LEONTFD'!Q36 -> 0.007 | U35: ='OECD LEONTFD'!R36 -> 0.002 | V35: ='OECD LEONTFD'!S36 -> 0.004 | W35: ='OECD LEONTFD'!T36 -> 0.004 | X35: ='OECD LEONTFD'!U36 -> 0.002 | Y35: ='OECD LEONTFD'!V36 -> 0.003 | Z35: ='Weighted Avg BEA Multipliers'!AB505 -> 0.0022622014 | AA35: ='Weighted Avg BEA Multipliers'!AC505 -> 0.0030934146 | AB35: ='Weighted Avg BEA Multipliers'!AD505 -> 0.0032840922 | AC35: ='OECD LEONTFD'!X36 -> 0.005 | AD35: ='OECD LEONTFD'!Y36 -> 0.004 | AE35: ='OECD LEONTFD'!Z36 -> 0.005 | AF35: ='OECD LEONTFD'!AA36 -> 0.002 | AG35: ='OECD LEONTFD'!AB36 -> 0.013 | AH35: ='OECD LEONTFD'!AC36 -> 0.012 | AI35: ='OECD LEONTFD'!AD36 -> 1.044 | AJ35: ='OECD LEONTFD'!AE36 -> 0.01 | ... AQ35: ='OECD LEONTFD'!AL36 -> 0
A36: ISIC 64T66 | B36: ='OECD LEONTFD'!C37 -> 0.078 | C36: ='Weighted Avg BEA Multipliers'!E506 -> 0.0078961847 | D36: ='Weighted Avg BEA Multipliers'!F506 -> 0.0083567583 | E36: ='OECD LEONTFD'!E37 -> 0.155 | F36: ='OECD LEONTFD'!F37 -> 0.166 | G36: ='OECD LEONTFD'!G37 -> 0.044 | H36: ='OECD LEONTFD'!H37 -> 0.087 | I36: ='OECD LEONTFD'!I37 -> 0.181 | J36: ='OECD LEONTFD'!J37 -> 0.097 | K36: ='OECD LEONTFD'!K37 -> 0.103 | L36: ='Weighted Avg BEA Multipliers'!N506 -> 0.0051531083 | M36: ='Weighted Avg BEA Multipliers'!O506 -> 0.003676114 | N36: ='OECD LEONTFD'!M37 -> 0.095 | O36: ='Weighted Avg BEA Multipliers'!Q506 -> 0.0089828445 | P36: ='Weighted Avg BEA Multipliers'!R506 -> 0.0093666114 | Q36: ='Weighted Avg BEA Multipliers'!S506 -> 0.0071484624 | R36: ='Weighted Avg BEA Multipliers'!T506 -> 0.0075003286 | S36: ='OECD LEONTFD'!P37 -> 0.036 | T36: ='OECD LEONTFD'!Q37 -> 0.065 | U36: ='OECD LEONTFD'!R37 -> 0.022 | V36: ='OECD LEONTFD'!S37 -> 0.064 | W36: ='OECD LEONTFD'!T37 -> 0.062 | X36: ='OECD LEONTFD'!U37 -> 0.055 | Y36: ='OECD LEONTFD'!V37 -> 0.051 | Z36: ='Weighted Avg BEA Multipliers'!AB506 -> 0.0059160994 | AA36: ='Weighted Avg BEA Multipliers'!AC506 -> 0.011396811 | AB36: ='Weighted Avg BEA Multipliers'!AD506 -> 0.0071022565 | AC36: ='OECD LEONTFD'!X37 -> 0.093 | AD36: ='OECD LEONTFD'!Y37 -> 0.061 | AE36: ='OECD LEONTFD'!Z37 -> 0.074 | AF36: ='OECD LEONTFD'!AA37 -> 0.038 | AG36: ='OECD LEONTFD'!AB37 -> 0.06 | AH36: ='OECD LEONTFD'!AC37 -> 0.048 | AI36: ='OECD LEONTFD'!AD37 -> 0.056 | AJ36: ='OECD LEONTFD'!AE37 -> 1.275 | ... AQ36: ='OECD LEONTFD'!AL37 -> 0
A37: ISIC 68 | B37: ='OECD LEONTFD'!C38 -> 0.003 | C37: ='Weighted Avg BEA Multipliers'!E507 -> 0.0051939573 | D37: ='Weighted Avg BEA Multipliers'!F507 -> 0.0047951833 | E37: ='OECD LEONTFD'!E38 -> 0.005 | F37: ='OECD LEONTFD'!F38 -> 0.004 | G37: ='OECD LEONTFD'!G38 -> 0.003 | H37: ='OECD LEONTFD'!H38 -> 0.005 | I37: ='OECD LEONTFD'!I38 -> 0.008 | J37: ='OECD LEONTFD'!J38 -> 0.005 | K37: ='OECD LEONTFD'!K38 -> 0.004 | L37: ='Weighted Avg BEA Multipliers'!N507 -> 0.007571106 | M37: ='Weighted Avg BEA Multipliers'!O507 -> 0.0041015911 | N37: ='OECD LEONTFD'!M38 -> 0.005 | O37: ='Weighted Avg BEA Multipliers'!Q507 -> 0.0067028348 | P37: ='Weighted Avg BEA Multipliers'!R507 -> 0.0070450685 | Q37: ='Weighted Avg BEA Multipliers'!S507 -> 0.0069297603 | R37: ='Weighted Avg BEA Multipliers'!T507 -> 0.0056498962 | S37: ='OECD LEONTFD'!P38 -> 0.002 | T37: ='OECD LEONTFD'!Q38 -> 0.003 | U37: ='OECD LEONTFD'!R38 -> 0.001 | V37: ='OECD LEONTFD'!S38 -> 0.003 | W37: ='OECD LEONTFD'!T38 -> 0.004 | X37: ='OECD LEONTFD'!U38 -> 0.002 | Y37: ='OECD LEONTFD'!V38 -> 0.003 | Z37: ='Weighted Avg BEA Multipliers'!AB507 -> 0.0046115452 | AA37: ='Weighted Avg BEA Multipliers'!AC507 -> 0.006740697 | AB37: ='Weighted Avg BEA Multipliers'!AD507 -> 0.011399677 | AC37: ='OECD LEONTFD'!X38 -> 0.005 | AD37: ='OECD LEONTFD'!Y38 -> 0.007 | AE37: ='OECD LEONTFD'!Z38 -> 0.003 | AF37: ='OECD LEONTFD'!AA38 -> 0.006 | AG37: ='OECD LEONTFD'!AB38 -> 0.006 | AH37: ='OECD LEONTFD'!AC38 -> 0.005 | AI37: ='OECD LEONTFD'!AD38 -> 0.005 | AJ37: ='OECD LEONTFD'!AE38 -> 0.004 | ... AQ37: ='OECD LEONTFD'!AL38 -> 0
A38: ISIC 69T82 | B38: ='OECD LEONTFD'!C39 -> 0.029 | C38: ='Weighted Avg BEA Multipliers'!E508 -> 0.014461791 | D38: ='Weighted Avg BEA Multipliers'!F508 -> 0.015063558 | E38: ='OECD LEONTFD'!E39 -> 0.11 | F38: ='OECD LEONTFD'!F39 -> 0.157 | G38: ='OECD LEONTFD'!G39 -> 0.028 | H38: ='OECD LEONTFD'!H39 -> 0.036 | I38: ='OECD LEONTFD'!I39 -> 0.076 | J38: ='OECD LEONTFD'!J39 -> 0.055 | K38: ='OECD LEONTFD'!K39 -> 0.046 | L38: ='Weighted Avg BEA Multipliers'!N508 -> 0.0098413299 | M38: ='Weighted Avg BEA Multipliers'!O508 -> 0.010483138 | N38: ='OECD LEONTFD'!M39 -> 0.055 | O38: ='Weighted Avg BEA Multipliers'!Q508 -> 0.011471519 | P38: ='Weighted Avg BEA Multipliers'!R508 -> 0.012236422 | Q38: ='Weighted Avg BEA Multipliers'!S508 -> 0.0096771507 | R38: ='Weighted Avg BEA Multipliers'!T508 -> 0.0078905752 | S38: ='OECD LEONTFD'!P39 -> 0.018 | T38: ='OECD LEONTFD'!Q39 -> 0.087 | U38: ='OECD LEONTFD'!R39 -> 0.013 | V38: ='OECD LEONTFD'!S39 -> 0.036 | W38: ='OECD LEONTFD'!T39 -> 0.034 | X38: ='OECD LEONTFD'!U39 -> 0.029 | Y38: ='OECD LEONTFD'!V39 -> 0.028 | Z38: ='Weighted Avg BEA Multipliers'!AB508 -> 0.0083309385 | AA38: ='Weighted Avg BEA Multipliers'!AC508 -> 0.0096662516 | AB38: ='Weighted Avg BEA Multipliers'!AD508 -> 0.014337375 | AC38: ='OECD LEONTFD'!X39 -> 0.071 | AD38: ='OECD LEONTFD'!Y39 -> 0.031 | AE38: ='OECD LEONTFD'!Z39 -> 0.059 | AF38: ='OECD LEONTFD'!AA39 -> 0.024 | AG38: ='OECD LEONTFD'!AB39 -> 0.07 | AH38: ='OECD LEONTFD'!AC39 -> 0.037 | AI38: ='OECD LEONTFD'!AD39 -> 0.058 | AJ38: ='OECD LEONTFD'!AE39 -> 0.022 | ... AQ38: ='OECD LEONTFD'!AL39 -> 0
A39: ISIC 84 | B39: ='OECD LEONTFD'!C40 -> 0.003 | C39: ='Weighted Avg BEA Multipliers'!E509 -> 0.00067194945 | D39: ='Weighted Avg BEA Multipliers'!F509 -> 0.00098929021 | E39: ='OECD LEONTFD'!E40 -> 0.007 | F39: ='OECD LEONTFD'!F40 -> 0.008 | G39: ='OECD LEONTFD'!G40 -> 0.002 | H39: ='OECD LEONTFD'!H40 -> 0.004 | I39: ='OECD LEONTFD'!I40 -> 0.008 | J39: ='OECD LEONTFD'!J40 -> 0.005 | K39: ='OECD LEONTFD'!K40 -> 0.006 | L39: ='Weighted Avg BEA Multipliers'!N509 -> 0.0011651151 | M39: ='Weighted Avg BEA Multipliers'!O509 -> 0.0004271523 | N39: ='OECD LEONTFD'!M40 -> 0.005 | O39: ='Weighted Avg BEA Multipliers'!Q509 -> 0.0010458544 | P39: ='Weighted Avg BEA Multipliers'!R509 -> 0.0010968162 | Q39: ='Weighted Avg BEA Multipliers'!S509 -> 0.014470081 | R39: ='Weighted Avg BEA Multipliers'!T509 -> 0.00091039267 | S39: ='OECD LEONTFD'!P40 -> 0.002 | T39: ='OECD LEONTFD'!Q40 -> 0.003 | U39: ='OECD LEONTFD'!R40 -> 0.001 | V39: ='OECD LEONTFD'!S40 -> 0.003 | W39: ='OECD LEONTFD'!T40 -> 0.003 | X39: ='OECD LEONTFD'!U40 -> 0.002 | Y39: ='OECD LEONTFD'!V40 -> 0.002 | Z39: ='Weighted Avg BEA Multipliers'!AB509 -> 0.002896624 | AA39: ='Weighted Avg BEA Multipliers'!AC509 -> 0.00071969047 | AB39: ='Weighted Avg BEA Multipliers'!AD509 -> 0.0036146367 | AC39: ='OECD LEONTFD'!X40 -> 0.004 | AD39: ='OECD LEONTFD'!Y40 -> 0.002 | AE39: ='OECD LEONTFD'!Z40 -> 0.004 | AF39: ='OECD LEONTFD'!AA40 -> 0.002 | AG39: ='OECD LEONTFD'!AB40 -> 0.004 | AH39: ='OECD LEONTFD'!AC40 -> 0.003 | AI39: ='OECD LEONTFD'!AD40 -> 0.003 | AJ39: ='OECD LEONTFD'!AE40 -> 0.002 | ... AQ39: ='OECD LEONTFD'!AL40 -> 0
