Workbook

Sheet About
A1: DRC Annual Cost per Unit Demand Response Capacity
A2: DRC Share of DR by Provider
A4: Source: | B4: EIA
B5: 2018
B6: Form 861 with data from 2016
B7: https://www.eia.gov/electricity/data/eia861/
B8: Demand_Response_2016.xlsx
A10: Notes
A11: Utilities pay to procure DR services. They often pay energy service companies (ESCOs),
A12: who themselves pass most of the payments on to the electricity consumers who are the
A13: suppliers of the DR. Other utilities may not use ESCOs and may pay the DR providers
A14: directly.
A16: Our data source provides the ultimate suppliers of the DR and the cost of that DR, but
A17: doesn't deal with the share taken by ESCOs. We do not model any share of the money
A18: taken by ESCOs and assign all of the cash flows from utilities to the ultimate DR providers
A19: (the "nonenergy industries" or "consumers" cash flow entities in the EPS).
A21: In the EPS, the "nonenergy industries" cash flow entity encompasses both industrial facilities and
A22: commercial buildings, so we calculate accordingly in this spreadsheet.
A24: We do not have any data on DR services provided by government buildings, so we
... A30: demand shifting they called upon.

Sheet Demand Response_States
A1: Utility Characteristics | E1: Cost Calculations | I1: Yearly Energy and Demand Savings | AC1: Program Costs | AM1: DSM Program
I2: Number of Customers Enrolled | N2: Energy Savings (MWh) | S2: Potential Peak Demand Savings (MW) | X2: Actual Peak Demand Savings (MW) | AC2: Customer Incentives (Thousand Dollars) | AH2: All Other Costs (Thousand Dollars) | AM2: Grid Connected
A3: Data Year | B3: Utility Number | C3: Utility Name | D3: State | E3: Residential Avg Cost ($/MW) | F3: Commercial Avg Cost ($/MW) | G3: Industrial Avg Cost ($/MW) | H3: Transportation Avg Cost ($/MW) | I3: Residential | J3: Commercial | K3: Industrial | L3: Transportation | M3: Total | N3: Residential | O3: Commercial | P3: Industrial | Q3: Transportation | R3: Total | S3: Residential | T3: Commercial | U3: Industrial | V3: Transportation | W3: Total | X3: Residential | Y3: Commercial | Z3: Industrial | AA3: Transportation | AB3: Total | AC3: Residential | AD3: Commercial | AE3: Industrial | AF3: Transportation | AG3: Total | AH3: Residential | AI3: Commercial | AJ3: Industrial | AK3: Transportation | AL3: Total | AM3: Water Heater
A4: 2016 | B4: 84 | C4: A & N Electric Coop | D4: MD | E4: =IFERROR(SUM(AC4,AH4)*10^3/S4,"") -> 2000 | F4: =IFERROR(SUM(AD4,AI4)*10^3/T4,"") | G4: =IFERROR(SUM(AE4,AJ4)*10^3/U4,"") | H4: =IFERROR(SUM(AF4,AK4)*10^3/V4,"") | I4: 35 | J4: 0 | K4: 0 | L4: 0 | M4: 35 | N4: 1 | O4: 0 | P4: 0 | Q4: 0 | R4: 1 | S4: 0.5 | T4: 0 | U4: 0 | V4: 0 | W4: 0.5 | X4: 0.4 | Y4: 0 | Z4: 0 | AA4: 0 | AB4: 0.4 | AC4: 0 | AD4: 0 | AE4: 0 | AF4: 0 | AG4: 0 | AH4: 1 | AI4: 0 | AJ4: 0 | AK4: 0 | AL4: 1 | AM4: .
A5: 2016 | B5: 84 | C5: A & N Electric Coop | D5: VA | E5: =IFERROR(SUM(AC5,AH5)*10^3/S5,"") -> 7500 | F5: =IFERROR(SUM(AD5,AI5)*10^3/T5,"") | G5: =IFERROR(SUM(AE5,AJ5)*10^3/U5,"") | H5: =IFERROR(SUM(AF5,AK5)*10^3/V5,"") | I5: 2471 | J5: 0 | K5: 0 | L5: 0 | M5: 2471 | N5: 110 | O5: 0 | P5: 0 | Q5: 0 | R5: 110 | S5: 2 | T5: 0 | U5: 0 | V5: 0 | W5: 2 | X5: 1 | Y5: 0 | Z5: 0 | AA5: 0 | AB5: 1 | AC5: 0 | AD5: 0 | AE5: 0 | AF5: 0 | AG5: 0 | AH5: 15 | AI5: 0 | AJ5: 0 | AK5: 0 | AL5: 15 | AM5: .
A6: 2016 | B6: 97 | C6: Adams Electric Coop | D6: IL | E6: =IFERROR(SUM(AC6,AH6)*10^3/S6,"") -> 19250 | F6: =IFERROR(SUM(AD6,AI6)*10^3/T6,"") -> 0 | G6: =IFERROR(SUM(AE6,AJ6)*10^3/U6,"") | H6: =IFERROR(SUM(AF6,AK6)*10^3/V6,"") | I6: 4263 | J6: 67 | K6: 0 | L6: 0 | M6: 4330 | N6: 0 | O6: 0 | P6: 0 | Q6: 0 | R6: 0 | S6: 4 | T6: 4 | U6: 0 | V6: 0 | W6: 8 | X6: 4 | Y6: 0 | Z6: 0 | AA6: 0 | AB6: 4 | AC6: 68 | AD6: 0 | AE6: 0 | AF6: 0 | AG6: 68 | AH6: 9 | AI6: 0 | AJ6: 0 | AK6: 0 | AL6: 9 | AM6: 43
A7: 2016 | B7: 108 | C7: Adams-Columbia Electric Coop | D7: WI | E7: =IFERROR(SUM(AC7,AH7)*10^3/S7,"") -> 18071.066 | F7: =IFERROR(SUM(AD7,AI7)*10^3/T7,"") | G7: =IFERROR(SUM(AE7,AJ7)*10^3/U7,"") -> 1537.2168 | H7: =IFERROR(SUM(AF7,AK7)*10^3/V7,"") | I7: 3906 | J7: 0 | K7: 951 | L7: 0 | M7: 4857 | N7: 1400 | O7: 0 | P7: 14681 | Q7: 0 | R7: 16081 | S7: 19.7 | T7: 0 | U7: 61.8 | V7: 0 | W7: 81.5 | X7: 5.9 | Y7: 0 | Z7: 9.9 | AA7: 0 | AB7: 15.8 | AC7: 295 | AD7: 0 | AE7: 1 | AF7: 0 | AG7: 296 | AH7: 61 | AI7: 0 | AJ7: 94 | AK7: 0 | AL7: 155 | AM7: 0
A8: 2016 | B8: 189 | C8: PowerSouth Energy Cooperative | D8: AL | E8: =IFERROR(SUM(AC8,AH8)*10^3/S8,"") -> 35933.333 | F8: =IFERROR(SUM(AD8,AI8)*10^3/T8,"") | G8: =IFERROR(SUM(AE8,AJ8)*10^3/U8,"") | H8: =IFERROR(SUM(AF8,AK8)*10^3/V8,"") | I8: 17284 | J8: 0 | K8: 0 | L8: 0 | M8: 17284 | N8: 0 | O8: 0 | P8: 0 | Q8: 0 | R8: 0 | S8: 15 | T8: 0 | U8: 0 | V8: 0 | W8: 15 | X8: 15 | Y8: 0 | Z8: 0 | AA8: 0 | AB8: 15 | AC8: 0 | AD8: 0 | AE8: 0 | AF8: 0 | AG8: 0 | AH8: 539 | AI8: 0 | AJ8: 0 | AK8: 0 | AL8: 539 | AM8: 2259
A9: 2016 | B9: 195 | C9: Alabama Power Co | D9: AL | E9: =IFERROR(SUM(AC9,AH9)*10^3/S9,"") -> 5986.0465 | F9: =IFERROR(SUM(AD9,AI9)*10^3/T9,"") -> 219428.57 | G9: =IFERROR(SUM(AE9,AJ9)*10^3/U9,"") -> 16704.205 | H9: =IFERROR(SUM(AF9,AK9)*10^3/V9,"") | I9: 12232 | J9: 63 | K9: 168 | L9: 0 | M9: 12463 | N9: 316 | O9: 2621 | P9: 2230 | Q9: 0 | R9: 5167 | S9: 215 | T9: 7 | U9: 1403 | V9: 0 | W9: 1625 | X9: 6.6 | Y9: 6 | Z9: 21.9 | AA9: 0 | AB9: 34.5 | AC9: 0 | AD9: 0 | AE9: 0 | AF9: 0 | AG9: 0 | AH9: 1287 | AI9: 1536 | AJ9: 23436 | AK9: 0 | AL9: 26259 | AM9: .
A10: 2016 | B10: 213 | C10: Alaska Electric Light&Power Co | D10: AK | E10: =IFERROR(SUM(AC10,AH10)*10^3/S10,"") -> 19200 | F10: =IFERROR(SUM(AD10,AI10)*10^3/T10,"") -> 76.923077 | G10: =IFERROR(SUM(AE10,AJ10)*10^3/U10,"") -> 0 | H10: =IFERROR(SUM(AF10,AK10)*10^3/V10,"") | I10: 2358 | J10: 44 | K10: 1 | L10: 0 | M10: 2403 | N10: 0 | O10: 0 | P10: 0 | Q10: 0 | R10: 0 | S10: 5 | T10: 13 | U10: 9 | V10: 0 | W10: 27 | X10: 0 | Y10: 13 | Z10: 9 | AA10: 0 | AB10: 22 | AC10: 65 | AD10: 1 | AE10: 0 | AF10: 0 | AG10: 66 | AH10: 31 | AI10: 0 | AJ10: 0 | AK10: 0 | AL10: 31 | AM10: 0
A11: 2016 | B11: 295 | C11: City of Alexandria - (MN) | D11: MN | E11: =IFERROR(SUM(AC11,AH11)*10^3/S11,"") -> 4777.7778 | F11: =IFERROR(SUM(AD11,AI11)*10^3/T11,"") | G11: =IFERROR(SUM(AE11,AJ11)*10^3/U11,"") | H11: =IFERROR(SUM(AF11,AK11)*10^3/V11,"") | I11: 2816 | J11: 0 | K11: 0 | L11: 0 | M11: 2816 | N11: 0 | O11: 0 | P11: 0 | Q11: 0 | R11: 0 | S11: 9 | T11: 0 | U11: 0 | V11: 0 | W11: 9 | X11: 3.7 | Y11: 0 | Z11: 0 | AA11: 0 | AB11: 3.7 | AC11: 5 | AD11: 0 | AE11: 0 | AF11: 0 | AG11: 5 | AH11: 38 | AI11: 0 | AJ11: 0 | AK11: 0 | AL11: 38 | AM11: 12
A12: 2016 | B12: 329 | C12: Allamakee-Clayton El Coop, Inc | D12: IA | E12: =IFERROR(SUM(AC12,AH12)*10^3/S12,"") -> 87142.857 | F12: =IFERROR(SUM(AD12,AI12)*10^3/T12,"") -> 89444.444 | G12: =IFERROR(SUM(AE12,AJ12)*10^3/U12,"") | H12: =IFERROR(SUM(AF12,AK12)*10^3/V12,"") | I12: 2659 | J12: 163 | K12: 0 | L12: 0 | M12: 2822 | N12: 0 | O12: 0 | P12: 0 | Q12: 0 | R12: 0 | S12: 4.9 | T12: 1.8 | U12: 0 | V12: 0 | W12: 6.7 | X12: 2.6 | Y12: 1 | Z12: 0 | AA12: 0 | AB12: 3.6 | AC12: 314 | AD12: 118 | AE12: 0 | AF12: 0 | AG12: 432 | AH12: 113 | AI12: 43 | AJ12: 0 | AK12: 0 | AL12: 156 | AM12: .
A13: 2016 | B13: 407 | C13: Altamaha Electric Member Corp | D13: GA | E13: =IFERROR(SUM(AC13,AH13)*10^3/S13,"") | F13: =IFERROR(SUM(AD13,AI13)*10^3/T13,"") | G13: =IFERROR(SUM(AE13,AJ13)*10^3/U13,"") -> 2027.027 | H13: =IFERROR(SUM(AF13,AK13)*10^3/V13,"") | I13: 0 | J13: 0 | K13: 203 | L13: 0 | M13: 203 | N13: 0 | O13: 0 | P13: 0 | Q13: 0 | R13: 0 | S13: 0 | T13: 0 | U13: 14.8 | V13: 0 | W13: 14.8 | X13: 0 | Y13: 0 | Z13: 14.8 | AA13: 0 | AB13: 14.8 | AC13: 0 | AD13: 0 | AE13: 0 | AF13: 0 | AG13: 0 | AH13: 0 | AI13: 0 | AJ13: 30 | AK13: 0 | AL13: 30 | AM13: .
A14: 2016 | B14: 590 | C14: City of Anaheim - (CA) | D14: CA | E14: =IFERROR(SUM(AC14,AH14)*10^3/S14,"") | F14: =IFERROR(SUM(AD14,AI14)*10^3/T14,"") -> 0 | G14: =IFERROR(SUM(AE14,AJ14)*10^3/U14,"") -> 0 | H14: =IFERROR(SUM(AF14,AK14)*10^3/V14,"") | I14: 0 | J14: 3 | K14: 11 | L14: 0 | M14: 14 | N14: 0 | O14: 0 | P14: 0 | Q14: 0 | R14: 0 | S14: 0 | T14: 5 | U14: 8 | V14: 0 | W14: 13 | X14: 0 | Y14: 0 | Z14: 0 | AA14: 0 | AB14: 0 | AC14: 0 | AD14: 0 | AE14: 0 | AF14: 0 | AG14: 0 | AH14: 0 | AI14: 0 | AJ14: 0 | AK14: 0 | AL14: 0 | AM14: .
A15: 2016 | B15: 733 | C15: Appalachian Power Co | D15: VA | E15: =IFERROR(SUM(AC15,AH15)*10^3/S15,"") -> 0 | F15: =IFERROR(SUM(AD15,AI15)*10^3/T15,"") | G15: =IFERROR(SUM(AE15,AJ15)*10^3/U15,"") -> 0 | H15: =IFERROR(SUM(AF15,AK15)*10^3/V15,"") | I15: 3406 | J15: 0 | K15: 5 | L15: 0 | M15: 3411 | N15: 0 | O15: 0 | P15: 0 | Q15: 0 | R15: 0 | S15: 3.4 | T15: 0 | U15: 33.5 | V15: 0 | W15: 36.9 | X15: 3.4 | Y15: 0 | Z15: 0 | AA15: 0 | AB15: 3.4 | AC15: 0 | AD15: 0 | AE15: 0 | AF15: 0 | AG15: 0 | AH15: 0 | AI15: 0 | AJ15: 0 | AK15: 0 | AL15: 0 | AM15: .
A16: 2016 | B16: 733 | C16: Appalachian Power Co | D16: WV | E16: =IFERROR(SUM(AC16,AH16)*10^3/S16,"") -> 0 | F16: =IFERROR(SUM(AD16,AI16)*10^3/T16,"") | G16: =IFERROR(SUM(AE16,AJ16)*10^3/U16,"") -> 0 | H16: =IFERROR(SUM(AF16,AK16)*10^3/V16,"") | I16: 1420 | J16: 0 | K16: 5 | L16: 0 | M16: 1425 | N16: 1 | O16: 0 | P16: 0 | Q16: 0 | R16: 1 | S16: 1.4 | T16: 0 | U16: 93.7 | V16: 0 | W16: 95.1 | X16: 1.4 | Y16: 0 | Z16: 0 | AA16: 0 | AB16: 1.4 | AC16: 0 | AD16: 0 | AE16: 0 | AF16: 0 | AG16: 0 | AH16: 0 | AI16: 0 | AJ16: 0 | AK16: 0 | AL16: 0 | AM16: .
A17: 2016 | B17: 803 | C17: Arizona Public Service Co | D17: AZ | E17: =IFERROR(SUM(AC17,AH17)*10^3/S17,"") -> 10313.024 | F17: =IFERROR(SUM(AD17,AI17)*10^3/T17,"") -> 0 | G17: =IFERROR(SUM(AE17,AJ17)*10^3/U17,"") | H17: =IFERROR(SUM(AF17,AK17)*10^3/V17,"") | I17: 573415 | J17: 903 | K17: 0 | L17: 0 | M17: 574318 | N17: 791576 | O17: 121808 | P17: 0 | Q17: 0 | R17: 913384 | S17: 178.9 | T17: 27.8 | U17: 0 | V17: 0 | W17: 206.7 | X17: 178.9 | Y17: 27.8 | Z17: 0 | AA17: 0 | AB17: 206.7 | AC17: 0 | AD17: 0 | AE17: 0 | AF17: 0 | AG17: 0 | AH17: 1845 | AI17: 0 | AJ17: 0 | AK17: 0 | AL17: 1845 | AM17: .
A18: 2016 | B18: 807 | C18: Arkansas Electric Coop Corp | D18: AR | E18: =IFERROR(SUM(AC18,AH18)*10^3/S18,"") | F18: =IFERROR(SUM(AD18,AI18)*10^3/T18,"") -> 43804.14 | G18: =IFERROR(SUM(AE18,AJ18)*10^3/U18,"") | H18: =IFERROR(SUM(AF18,AK18)*10^3/V18,"") | I18: 0 | J18: 8 | K18: 0 | L18: 0 | M18: 8 | N18: 0 | O18: 0 | P18: 0 | Q18: 0 | R18: 0 | S18: 0 | T18: 628 | U18: 0 | V18: 0 | W18: 628 | X18: 0 | Y18: 80 | Z18: 0 | AA18: 0 | AB18: 80 | AC18: 0 | AD18: 27509 | AE18: 0 | AF18: 0 | AG18: 27509 | AH18: 0 | AI18: 0 | AJ18: 0 | AK18: 0 | AL18: 0 | AM18: .
A19: 2016 | B19: 814 | C19: Entergy Arkansas Inc | D19: AR | E19: =IFERROR(SUM(AC19,AH19)*10^3/S19,"") -> 133451.96 | F19: =IFERROR(SUM(AD19,AI19)*10^3/T19,"") | G19: =IFERROR(SUM(AE19,AJ19)*10^3/U19,"") -> 210529.41 | H19: =IFERROR(SUM(AF19,AK19)*10^3/V19,"") | I19: 23613 | J19: 0 | K19: 1547 | L19: 0 | M19: 25160 | N19: 52172 | O19: 0 | P19: 0 | Q19: 0 | R19: 52172 | S19: 28.1 | T19: 0 | U19: 17 | V19: 0 | W19: 45.1 | X19: 28.1 | Y19: 0 | Z19: 17 | AA19: 0 | AB19: 45.1 | AC19: 764 | AD19: 0 | AE19: 331 | AF19: 0 | AG19: 1095 | AH19: 2986 | AI19: 0 | AJ19: 3248 | AK19: 0 | AL19: 6234 | AM19: .
A20: 2016 | B20: 828 | C20: City of Arlington - (MN) | D20: MN | E20: =IFERROR(SUM(AC20,AH20)*10^3/S20,"") | F20: =IFERROR(SUM(AD20,AI20)*10^3/T20,"") | G20: =IFERROR(SUM(AE20,AJ20)*10^3/U20,"") | H20: =IFERROR(SUM(AF20,AK20)*10^3/V20,"") | I20: 444 | J20: 33 | K20: 0 | L20: 0 | M20: 477 | N20: 0 | O20: 0 | P20: 0 | Q20: 0 | R20: 0 | S20: 0 | T20: 0 | U20: 0 | V20: 0 | W20: 0 | X20: 0 | Y20: 0 | Z20: 0 | AA20: 0 | AB20: 0 | AC20: 11 | AD20: 1 | AE20: 0 | AF20: 0 | AG20: 12 | AH20: 0 | AI20: 0 | AJ20: 0 | AK20: 0 | AL20: 0 | AM20: .
A21: 2016 | B21: 963 | C21: Atlantic City Electric Co | D21: NJ | E21: =IFERROR(SUM(AC21,AH21)*10^3/S21,"") -> 39316.406 | F21: =IFERROR(SUM(AD21,AI21)*10^3/T21,"") | G21: =IFERROR(SUM(AE21,AJ21)*10^3/U21,"") | H21: =IFERROR(SUM(AF21,AK21)*10^3/V21,"") | I21: 46449 | J21: 0 | K21: 0 | L21: 0 | M21: 46449 | N21: 205 | O21: 0 | P21: 0 | Q21: 0 | R21: 205 | S21: 51.2 | T21: 0 | U21: 0 | V21: 0 | W21: 51.2 | X21: 51.2 | Y21: 0 | Z21: 0 | AA21: 0 | AB21: 51.2 | AC21: 145 | AD21: 0 | AE21: 0 | AF21: 0 | AG21: 145 | AH21: 1868 | AI21: 0 | AJ21: 0 | AK21: 0 | AL21: 1868 | AM21: .
A22: 2016 | B22: 965 | C22: Atlantic Municipal Utilities | D22: IA | E22: =IFERROR(SUM(AC22,AH22)*10^3/S22,"") -> 26000 | F22: =IFERROR(SUM(AD22,AI22)*10^3/T22,"") -> 10000 | G22: =IFERROR(SUM(AE22,AJ22)*10^3/U22,"") | H22: =IFERROR(SUM(AF22,AK22)*10^3/V22,"") | I22: 327 | J22: 33 | K22: 0 | L22: 0 | M22: 360 | N22: 25 | O22: 14 | P22: 0 | Q22: 0 | R22: 39 | S22: 0.5 | T22: 0.1 | U22: 0 | V22: 0 | W22: 0.6 | X22: 0.5 | Y22: 0.1 | Z22: 0 | AA22: 0 | AB22: 0.6 | AC22: 8 | AD22: 1 | AE22: 0 | AF22: 0 | AG22: 9 | AH22: 5 | AI22: 0 | AJ22: 0 | AK22: 0 | AL22: 5 | AM22: .
A23: 2016 | B23: 1009 | C23: City of Austin - (MN) | D23: MN | E23: =IFERROR(SUM(AC23,AH23)*10^3/S23,"") -> 0 | F23: =IFERROR(SUM(AD23,AI23)*10^3/T23,"") -> 42500 | G23: =IFERROR(SUM(AE23,AJ23)*10^3/U23,"") | H23: =IFERROR(SUM(AF23,AK23)*10^3/V23,"") | I23: 6542 | J23: 2 | K23: 0 | L23: 0 | M23: 6544 | N23: 304 | O23: 6 | P23: 0 | Q23: 0 | R23: 310 | S23: 3.5 | T23: 0.4 | U23: 0 | V23: 0 | W23: 3.9 | X23: 3.5 | Y23: 0.4 | Z23: 0 | AA23: 0 | AB23: 3.9 | AC23: 0 | AD23: 17 | AE23: 0 | AF23: 0 | AG23: 17 | AH23: 0 | AI23: 0 | AJ23: 0 | AK23: 0 | AL23: 0 | AM23: .
A24: 2016 | B24: 1015 | C24: Austin Energy | D24: TX | E24: =IFERROR(SUM(AC24,AH24)*10^3/S24,"") -> 39359.606 | F24: =IFERROR(SUM(AD24,AI24)*10^3/T24,"") -> 28257.426 | G24: =IFERROR(SUM(AE24,AJ24)*10^3/U24,"") -> 29141.104 | H24: =IFERROR(SUM(AF24,AK24)*10^3/V24,"") | I24: 128501 | J24: 8825 | K24: 2942 | L24: 0 | M24: 140268 | N24: 61 | O24: 205 | P24: 68 | Q24: 0 | R24: 334 | S24: 60.9 | T24: 50.5 | U24: 16.3 | V24: 0 | W24: 127.7 | X24: 35.3 | Y24: 35.4 | Z24: 11.2 | AA24: 0 | AB24: 81.9 | AC24: 1383 | AD24: 357 | AE24: 119 | AF24: 0 | AG24: 1859 | AH24: 1014 | AI24: 1070 | AJ24: 356 | AK24: 0 | AL24: 2440 | AM24: 1973
A25: 2016 | B25: 1167 | C25: Baltimore Gas & Electric Co | D25: MD | E25: =IFERROR(SUM(AC25,AH25)*10^3/S25,"") -> 90851.401 | F25: =IFERROR(SUM(AD25,AI25)*10^3/T25,"") | G25: =IFERROR(SUM(AE25,AJ25)*10^3/U25,"") | H25: =IFERROR(SUM(AF25,AK25)*10^3/V25,"") | I25: 332684 | J25: 0 | K25: 0 | L25: 0 | M25: 332684 | N25: 2302 | O25: 0 | P25: 0 | Q25: 0 | R25: 2302 | S25: 378.2 | T25: 0 | U25: 0 | V25: 0 | W25: 378.2 | X25: 0 | Y25: 0 | Z25: 0 | AA25: 0 | AB25: 0 | AC25: 23366 | AD25: 0 | AE25: 0 | AF25: 0 | AG25: 23366 | AH25: 10994 | AI25: 0 | AJ25: 0 | AK25: 0 | AL25: 10994 | AM25: .
A26: 2016 | B26: 1233 | C26: City of Barnesville - (MN) | D26: MN | E26: =IFERROR(SUM(AC26,AH26)*10^3/S26,"") -> 21000 | F26: =IFERROR(SUM(AD26,AI26)*10^3/T26,"") | G26: =IFERROR(SUM(AE26,AJ26)*10^3/U26,"") | H26: =IFERROR(SUM(AF26,AK26)*10^3/V26,"") | I26: 872 | J26: 60 | K26: 0 | L26: 0 | M26: 932 | N26: 9 | O26: 0 | P26: 0 | Q26: 0 | R26: 9 | S26: 1 | T26: 0 | U26: 0 | V26: 0 | W26: 1 | X26: 1 | Y26: 0 | Z26: 0 | AA26: 0 | AB26: 1 | AC26: 11 | AD26: 0 | AE26: 0 | AF26: 0 | AG26: 11 | AH26: 10 | AI26: 0 | AJ26: 0 | AK26: 0 | AL26: 10 | AM26: .
A27: 2016 | B27: 1251 | C27: Barron Electric Coop | D27: WI | E27: =IFERROR(SUM(AC27,AH27)*10^3/S27,"") -> 8571.4286 | F27: =IFERROR(SUM(AD27,AI27)*10^3/T27,"") -> 8518.5185 | G27: =IFERROR(SUM(AE27,AJ27)*10^3/U27,"") | H27: =IFERROR(SUM(AF27,AK27)*10^3/V27,"") | I27: 6067 | J27: 359 | K27: 0 | L27: 0 | M27: 6426 | N27: 0 | O27: 0 | P27: 0 | Q27: 0 | R27: 0 | S27: 3.5 | T27: 10.8 | U27: 0 | V27: 0 | W27: 14.3 | X27: 1.6 | Y27: 4.9 | Z27: 0 | AA27: 0 | AB27: 6.5 | AC27: 8 | AD27: 24 | AE27: 0 | AF27: 0 | AG27: 32 | AH27: 22 | AI27: 68 | AJ27: 0 | AK27: 0 | AL27: 90 | AM27: .
A28: 2016 | B28: 1367 | C28: Bayfield Electric Coop, Inc | D28: WI | E28: =IFERROR(SUM(AC28,AH28)*10^3/S28,"") -> 26500 | F28: =IFERROR(SUM(AD28,AI28)*10^3/T28,"") | G28: =IFERROR(SUM(AE28,AJ28)*10^3/U28,"") | H28: =IFERROR(SUM(AF28,AK28)*10^3/V28,"") | I28: 1201 | J28: 6 | K28: 0 | L28: 0 | M28: 1207 | N28: 398 | O28: 0 | P28: 0 | Q28: 0 | R28: 398 | S28: 2 | T28: 0 | U28: 0 | V28: 0 | W28: 2 | X28: 2 | Y28: 0 | Z28: 0 | AA28: 0 | AB28: 2 | AC28: 44 | AD28: 0 | AE28: 0 | AF28: 0 | AG28: 44 | AH28: 9 | AI28: 0 | AJ28: 0 | AK28: 0 | AL28: 9 | AM28: .
A29: 2016 | B29: 1529 | C29: Beltrami Electric Coop, Inc | D29: MN | E29: =IFERROR(SUM(AC29,AH29)*10^3/S29,"") -> 1383.5061 | F29: =IFERROR(SUM(AD29,AI29)*10^3/T29,"") -> 0 | G29: =IFERROR(SUM(AE29,AJ29)*10^3/U29,"") | H29: =IFERROR(SUM(AF29,AK29)*10^3/V29,"") | I29: 7760 | J29: 28 | K29: 0 | L29: 0 | M29: 7788 | N29: 5002 | O29: 0 | P29: 0 | Q29: 0 | R29: 5002 | S29: 221.9 | T29: 3.9 | U29: 0 | V29: 0 | W29: 225.8 | X29: 27.4 | Y29: 3.9 | Z29: 0 | AA29: 0 | AB29: 31.3 | AC29: 35 | AD29: 0 | AE29: 0 | AF29: 0 | AG29: 35 | AH29: 272 | AI29: 0 | AJ29: 0 | AK29: 0 | AL29: 272 | AM29: 0
A30: 2016 | B30: 1573 | C30: City of Benson - (MN) | D30: MN | E30: =IFERROR(SUM(AC30,AH30)*10^3/S30,"") -> 2941.1765 | F30: =IFERROR(SUM(AD30,AI30)*10^3/T30,"") -> 0 | G30: =IFERROR(SUM(AE30,AJ30)*10^3/U30,"") | H30: =IFERROR(SUM(AF30,AK30)*10^3/V30,"") | I30: 966 | J30: 35 | K30: 0 | L30: 0 | M30: 1001 | N30: 0 | O30: 0 | P30: 0 | Q30: 0 | R30: 0 | S30: 3.4 | T30: 0.4 | U30: 0 | V30: 0 | W30: 3.8 | X30: 2.6 | Y30: 0.4 | Z30: 0 | AA30: 0 | AB30: 3 | AC30: 2 | AD30: 0 | AE30: 0 | AF30: 0 | AG30: 2 | AH30: 8 | AI30: 0 | AJ30: 0 | AK30: 0 | AL30: 8 | AM30: .
A31: 2016 | B31: 1613 | C31: Berkeley Electric Coop Inc | D31: SC | E31: =IFERROR(SUM(AC31,AH31)*10^3/S31,"") -> 5098.7654 | F31: =IFERROR(SUM(AD31,AI31)*10^3/T31,"") | G31: =IFERROR(SUM(AE31,AJ31)*10^3/U31,"") | H31: =IFERROR(SUM(AF31,AK31)*10^3/V31,"") | I31: 18250 | J31: 0 | K31: 0 | L31: 0 | M31: 18250 | N31: 0 | O31: 0 | P31: 0 | Q31: 0 | R31: 0 | S31: 81 | T31: 0 | U31: 0 | V31: 0 | W31: 81 | X31: 16.2 | Y31: 0 | Z31: 0 | AA31: 0 | AB31: 16.2 | AC31: 154 | AD31: 0 | AE31: 0 | AF31: 0 | AG31: 154 | AH31: 259 | AI31: 0 | AJ31: 0 | AK31: 0 | AL31: 259 | AM31: .
A32: 2016 | B32: 1769 | C32: Black Hills Electric Coop, Inc | D32: SD | E32: =IFERROR(SUM(AC32,AH32)*10^3/S32,"") | F32: =IFERROR(SUM(AD32,AI32)*10^3/T32,"") | G32: =IFERROR(SUM(AE32,AJ32)*10^3/U32,"") | H32: =IFERROR(SUM(AF32,AK32)*10^3/V32,"") | I32: 183 | J32: 8 | K32: 0 | L32: 0 | M32: 191 | N32: 0 | O32: 0 | P32: 0 | Q32: 0 | R32: 0 | S32: 0 | T32: 0 | U32: 0 | V32: 0 | W32: 0 | X32: 0 | Y32: 0 | Z32: 0 | AA32: 0 | AB32: 0 | AC32: 0 | AD32: 0 | AE32: 0 | AF32: 0 | AG32: 0 | AH32: 0 | AI32: 0 | AJ32: 0 | AK32: 0 | AL32: 0 | AM32: .
A33: 2016 | B33: 1883 | C33: Blue Earth Light & Water | D33: MN | E33: =IFERROR(SUM(AC33,AH33)*10^3/S33,"") -> 9500 | F33: =IFERROR(SUM(AD33,AI33)*10^3/T33,"") | G33: =IFERROR(SUM(AE33,AJ33)*10^3/U33,"") | H33: =IFERROR(SUM(AF33,AK33)*10^3/V33,"") | I33: 508 | J33: 0 | K33: 0 | L33: 0 | M33: 508 | N33: 27 | O33: 0 | P33: 0 | Q33: 0 | R33: 27 | S33: 4 | T33: 0 | U33: 0 | V33: 0 | W33: 4 | X33: 1 | Y33: 0 | Z33: 0 | AA33: 0 | AB33: 1 | AC33: 38 | AD33: 0 | AE33: 0 | AF33: 0 | AG33: 38 | AH33: 0 | AI33: 0 | AJ33: 0 | AK33: 0 | AL33: 0 | AM33: .
A34: 2016 | B34: 2182 | C34: City of Breckenridge- (MN) | D34: MN | E34: =IFERROR(SUM(AC34,AH34)*10^3/S34,"") -> 8000 | F34: =IFERROR(SUM(AD34,AI34)*10^3/T34,"") -> 22000 | G34: =IFERROR(SUM(AE34,AJ34)*10^3/U34,"") | H34: =IFERROR(SUM(AF34,AK34)*10^3/V34,"") | I34: 652 | J34: 90 | K34: 0 | L34: 0 | M34: 742 | N34: 1 | O34: 1 | P34: 0 | Q34: 0 | R34: 2 | S34: 1 | T34: 1 | U34: 0 | V34: 0 | W34: 2 | X34: 1 | Y34: 1 | Z34: 0 | AA34: 0 | AB34: 2 | AC34: 8 | AD34: 22 | AE34: 0 | AF34: 0 | AG34: 30 | AH34: 0 | AI34: 0 | AJ34: 0 | AK34: 0 | AL34: 0 | AM34: .
A35: 2016 | B35: 2192 | C35: Bremen Electric Light & Power Co | D35: IN | E35: =IFERROR(SUM(AC35,AH35)*10^3/S35,"") | F35: =IFERROR(SUM(AD35,AI35)*10^3/T35,"") | G35: =IFERROR(SUM(AE35,AJ35)*10^3/U35,"") -> 10000 | H35: =IFERROR(SUM(AF35,AK35)*10^3/V35,"") | I35: 0 | J35: 0 | K35: 1 | L35: 0 | M35: 1 | N35: 0 | O35: 0 | P35: 0 | Q35: 0 | R35: 0 | S35: 0 | T35: 0 | U35: 4.2 | V35: 0 | W35: 4.2 | X35: 0 | Y35: 0 | Z35: 3.5 | AA35: 0 | AB35: 3.5 | AC35: 0 | AD35: 0 | AE35: 42 | AF35: 0 | AG35: 42 | AH35: 0 | AI35: 0 | AJ35: 0 | AK35: 0 | AL35: 0 | AM35: .
A36: 2016 | B36: 2599 | C36: Burt County Public Power Dist | D36: NE | E36: =IFERROR(SUM(AC36,AH36)*10^3/S36,"") | F36: =IFERROR(SUM(AD36,AI36)*10^3/T36,"") | G36: =IFERROR(SUM(AE36,AJ36)*10^3/U36,"") -> 266.66667 | H36: =IFERROR(SUM(AF36,AK36)*10^3/V36,"") | I36: 0 | J36: 0 | K36: 359 | L36: 0 | M36: 359 | N36: 0 | O36: 0 | P36: 215 | Q36: 0 | R36: 215 | S36: 0 | T36: 0 | U36: 15 | V36: 0 | W36: 15 | X36: 0 | Y36: 0 | Z36: 3 | AA36: 0 | AB36: 3 | AC36: 0 | AD36: 0 | AE36: 0 | AF36: 0 | AG36: 0 | AH36: 0 | AI36: 0 | AJ36: 4 | AK36: 0 | AL36: 4 | AM36: .
A37: 2016 | B37: 2641 | C37: Butler Rural El Coop Assn, Inc - (KS) | D37: KS | E37: =IFERROR(SUM(AC37,AH37)*10^3/S37,"") -> 0 | F37: =IFERROR(SUM(AD37,AI37)*10^3/T37,"") -> 0 | G37: =IFERROR(SUM(AE37,AJ37)*10^3/U37,"") -> 0 | H37: =IFERROR(SUM(AF37,AK37)*10^3/V37,"") | I37: 6585 | J37: 776 | K37: 4 | L37: 0 | M37: 7365 | N37: 0 | O37: 0 | P37: 0 | Q37: 0 | R37: 0 | S37: 2.6 | T37: 0.4 | U37: 1 | V37: 0 | W37: 4 | X37: 1.8 | Y37: 0.2 | Z37: 0.5 | AA37: 0 | AB37: 2.5 | AC37: 0 | AD37: 0 | AE37: 0 | AF37: 0 | AG37: 0 | AH37: 0 | AI37: 0 | AJ37: 0 | AK37: 0 | AL37: 0 | AM37: .
A38: 2016 | B38: 2643 | C38: Butler Public Power District - (NE) | D38: NE | E38: =IFERROR(SUM(AC38,AH38)*10^3/S38,"") | F38: =IFERROR(SUM(AD38,AI38)*10^3/T38,"") | G38: =IFERROR(SUM(AE38,AJ38)*10^3/U38,"") -> 224.7191 | H38: =IFERROR(SUM(AF38,AK38)*10^3/V38,"") | I38: 0 | J38: 0 | K38: 741 | L38: 0 | M38: 741 | N38: 0 | O38: 0 | P38: 993 | Q38: 0 | R38: 993 | S38: 0 | T38: 0 | U38: 17.8 | V38: 0 | W38: 17.8 | X38: 0 | Y38: 0 | Z38: 8.3 | AA38: 0 | AB38: 8.3 | AC38: 0 | AD38: 0 | AE38: 0 | AF38: 0 | AG38: 0 | AH38: 0 | AI38: 0 | AJ38: 4 | AK38: 0 | AL38: 4 | AM38: .
A39: 2016 | B39: 2655 | C39: Butte Electric Coop, Inc | D39: SD | E39: =IFERROR(SUM(AC39,AH39)*10^3/S39,"") -> 1375 | F39: =IFERROR(SUM(AD39,AI39)*10^3/T39,"") | G39: =IFERROR(SUM(AE39,AJ39)*10^3/U39,"") | H39: =IFERROR(SUM(AF39,AK39)*10^3/V39,"") | I39: 1438 | J39: 0 | K39: 0 | L39: 0 | M39: 1438 | N39: 948 | O39: 0 | P39: 0 | Q39: 0 | R39: 948 | S39: 8 | T39: 0 | U39: 0 | V39: 0 | W39: 8 | X39: 3 | Y39: 0 | Z39: 0 | AA39: 0 | AB39: 3 | AC39: 3 | AD39: 0 | AE39: 0 | AF39: 0 | AG39: 3 | AH39: 8 | AI39: 0 | AJ39: 0 | AK39: 0 | AL39: 8 | AM39: 1438
A40: 2016 | B40: 2678 | C40: C & L Electric Coop Corp | D40: AR | E40: =IFERROR(SUM(AC40,AH40)*10^3/S40,"") | F40: =IFERROR(SUM(AD40,AI40)*10^3/T40,"") -> 17000 | G40: =IFERROR(SUM(AE40,AJ40)*10^3/U40,"") | H40: =IFERROR(SUM(AF40,AK40)*10^3/V40,"") | I40: 0 | J40: 83 | K40: 0 | L40: 0 | M40: 83 | N40: 0 | O40: 0 | P40: 0 | Q40: 0 | R40: 0 | S40: 0 | T40: 2 | U40: 0 | V40: 0 | W40: 2 | X40: 0 | Y40: 1 | Z40: 0 | AA40: 0 | AB40: 1 | AC40: 0 | AD40: 32 | AE40: 0 | AF40: 0 | AG40: 32 | AH40: 0 | AI40: 2 | AJ40: 0 | AK40: 0 | AL40: 2 | AM40: .
...

Sheet Calculations
A1: Provider | B1: Average Cost ($/MW-yr) | C1: Share of DR
A2: residential | B2: =SUMPRODUCT('Demand Response_States'!E4:E430,'Demand Response_States'!S4:S430)/SUM('Demand Response_States'!S4:S430) -> 52676.668 | C2: =SUM('Demand Response_States'!S4:S430)/SUM('Demand Response_States'!$W4:$W430) -> 0.2927923
A3: commercial | B3: =SUMPRODUCT('Demand Response_States'!F4:F430,'Demand Response_States'!T4:T430)/SUM('Demand Response_States'!T4:T430) -> 46486.107 | C3: =SUM('Demand Response_States'!T4:T430)/SUM('Demand Response_States'!$W4:$W430) -> 0.30766811
A4: industrial | B4: =SUMPRODUCT('Demand Response_States'!G4:G430,'Demand Response_States'!U4:U430)/SUM('Demand Response_States'!U4:U430) -> 24022.777 | C4: =SUM('Demand Response_States'!U4:U430)/SUM('Demand Response_States'!$W4:$W430) -> 0.39914987
A6: In the EPS, the "industry" cash flow entity encompasses both industrial
A7: facilities and commercial buildings, so we combine these into a single
A8: entry:
A10: residential | B10: =B2 -> 52676.668 | C10: =C2 -> 0.2927923
A11: commercial & industrial | B11: =(B3*C3+B4*C4)/SUM(C3:C4) -> 33800.755 | C11: =SUM(C3:C4) -> 0.70681799

Sheet DRCo-ACpUDRC
B1: Cost ($/MW)
A2: government | B2: =Calculations!B11 -> 33800.755
A3: nonenergy industries | B3: =Calculations!B11 -> 33800.755
A4: labor and consumers | B4: =Calculations!B10 -> 52676.668
A5: foreign entities | B5: 0
A6: electricity suppliers | B6: =B$3 -> 33800.755
A7: coal suppliers | B7: =B$3 -> 33800.755
A8: natural gas and petroleum suppliers | B8: =B$3 -> 33800.755
A9: biomass and biofuel suppliers | B9: =B$3 -> 33800.755
A10: other energy suppliers | B10: =B$3 -> 33800.755

Sheet DRCo-SoDRbP
A1: % of DR (dimensionless) | B1: share
A2: government | B2: 0
A3: nonenergy industries | B3: =Calculations!C11 -> 0.70681799
A4: labor and consumers | B4: =Calculations!C10 -> 0.2927923
A5: foreign entities | B5: 0
A6: electricity suppliers | B6: 0
A7: coal suppliers | B7: 0
A8: natural gas and petroleum suppliers | B8: 0
A9: biomass and biofuel suppliers | B9: 0
A10: other energy suppliers | B10: 0
