Workbook

Sheet About
A1: SoCEUtiNTY Share of Components Energy Use that is New This Year
A3: Sources: | B3: Share of commercial floorspace that is new
B4: Zhejiang Statistical Year Book
B5: 2021
B6: Table 8-8
B10: Number of homes
B11: EIA
B12: 2017
B13: Annual Energy Outlook 2017
B14: https://www.eia.gov/outlooks/aeo/excel/aeotab_4.xlsx
B15: 4. Residential Sector Key Indicators and Consumption
B17: Share of homes that are new
B18: Zhejiang Statistical Year Book
B19: 2021
B24: Replacement rate of components in surviving buildings
B25: See bldgs/CL variable
A27: About
A28: This variable is used to estimate the share of BAU component energy use
A29: that is new (i.e. from newly installed components) each year. This includes
A30: both components to serve new buildings (demand growth) and components
A31: to replace retiring components.
A33: The "envelope" value in this variable does not matter, because envelope
A34: does not itself use energy. To avoid confusion, envelope is assigned
A35: a value of zero.
A37: We separately estimate the share of buildings that are new (whose components
A38: are all new) and the share of components in surviving buildings that are
A39: replaced each year. We consider the share of surviving buildings and
A40: new buildings to properly calculate overall component replacement rates.
... A43: to new regions.

Sheet Component Lifetimes
A1: Building Component | B1: Lifetime (yr)
A2: heating | B2: =[1]CL!$B$2 -> 17.333333
A3: cooling and ventilation | B3: =[1]CL!$B$3 -> 14
A4: envelope | B4: =[1]CL!$B$4 -> 51.818182
A5: lighting | B5: =[1]CL!$B$5 -> 9.1324201
A6: appliances | B6: =[1]CL!$B$6 -> 11.4
A7: other component | B7: =[1]CL!$B$7 -> 15.4

Sheet China Calculations
A1: Fraction of Commercial Floorspace that is New
A3: Unit:10^4 m2 | B3: 2010 | C3: 2011 | D3: 2012 | E3: 2013 | F3: 2014 | G3: 2015 | H3: 2016 | I3: 2017 | J3: 2018 | K3: 2019 | L3: 2020 | M3: 2021 | N3: 2022 | O3: 2023 | P3: 2024 | Q3: 2025 | R3: 2026 | S3: 2027 | T3: 2028 | U3: 2029 | V3: 2030 | W3: 2031 | X3: 2032 | Y3: 2033 | Z3: 2034 | AA3: 2035 | AB3: 2036 | AC3: 2037 | AD3: 2038 | AE3: 2039 | AF3: 2040 | AG3: 2041 | AH3: 2042 | AI3: 2043 | AJ3: 2044 | AK3: 2045 | AL3: 2046 | AM3: 2047 | AN3: 2048 | AO3: 2049 | AP3: 2050
A4: 住宅 | B4: 611.7 | C4: 471.9 | D4: 557.6 | E4: 348 | F4: 645 | G4: 616 | H4: 330.4 | I4: 394.7 | J4: 467.4 | K4: 380.3 | L4: 483.7
A5: 非住宅 | B5: 527.6 | C5: 519.5 | D5: 836.9 | E5: 483 | F5: 454 | G5: 448 | H5: =H7-H4 -> 898.2 | I5: =I7-I4 -> 978.2 | J5: =J7-J4 -> 942.1 | K5: =K7-K4 -> 763.2 | L5: =L7-L4 -> 604.5
A6: 总建筑面积
A7: 新建（竣工）建筑面积 | B7: =SUM(B4:B5) -> 1139.3 | C7: =SUM(C4:C5) -> 991.4 | D7: =SUM(D4:D5) -> 1394.5 | E7: =SUM(E4:E5) -> 831 | F7: =SUM(F4:F5) -> 1099 | G7: =SUM(G4:G5) -> 1064 | H7: 1228.6 | I7: 1372.9 | J7: 1409.5 | K7: 1143.5 | L7: 1088.2
A10: Commercial New Floorspace
A11: Hong Kong urbanization rate | G11: 1 | L11: 0.72
A12: Household size | B12: 2.9 | C12: 2.9 | D12: 2.9 | E12: 2.9 | F12: 2.9 | G12: 2.9 | H12: 2.8 | I12: 2.8 | J12: 2.8 | K12: 2.8 | L12: 2.7 | M12: 2.7 | N12: 2.7 | O12: 2.7 | P12: 2.7 | Q12: 2.7 | R12: 2.7 | S12: 2.7 | T12: 2.7 | U12: 2.7 | V12: 2.7 | W12: 2.6 | X12: 2.6 | Y12: 2.6 | Z12: 2.6 | AA12: 2.6 | AB12: 2.6 | AC12: 2.6 | AD12: 2.6 | AE12: 2.6 | AF12: 2.6 | AG12: 2.6 | AH12: 2.6 | AI12: 2.6 | AJ12: 2.6 | AK12: 2.6 | AL12: 2.6 | AM12: 2.6 | AN12: 2.6 | AO12: 2.6 | AP12: 2.6
A13: 城镇居民人均居住面积^2 | G13: 15 | H13: =($L13-$G13)/6+G13 -> 15.366667 | I13: =($L13-$G13)/6+H13 -> 15.733333 | J13: =($L13-$G13)/6+I13 -> 16.1 | K13: =($L13-$G13)/6+J13 -> 16.466667 | L13: 17.2 | M13: =($AP13-$L13)/30+L13 -> 17.416667 | N13: =($AP13-$L13)/30+M13 -> 17.633333 | O13: =($AP13-$L13)/30+N13 -> 17.85 | P13: =($AP13-$L13)/30+O13 -> 18.066667 | Q13: =($AP13-$L13)/30+P13 -> 18.283333 | R13: =($AP13-$L13)/30+Q13 -> 18.5 | S13: =($AP13-$L13)/30+R13 -> 18.716667 | T13: =($AP13-$L13)/30+S13 -> 18.933333 | ... AO13: =($AP13-$L13)/30+AN13 -> 23.483333 | AP13: 23.7
A14: 城镇居住人口 | H14: 3.9548092 | I14: 4.0643184 | J14: 4.0217777 | K14: 4.0522751 | L14: 4.0849012 | M14: 4.0994876 | N14: 4.1061934 | O14: 4.168299 | P14: 4.1929893 | Q14: 4.2154149 | R14: 4.2351377 | S14: 4.2535638 | T14: 4.2720488 | U14: 4.2903754 | V14: 4.3074555 | W14: 4.3240486 | X14: 4.3404806 | Y14: 4.3578953 | Z14: 4.3744954 | AA14: 4.3890248 | AB14: 4.4007157 | AC14: 4.4100546 | AD14: 4.4193872 | AE14: 4.4273467 | AF14: 4.4339855 | AG14: 4.4384802 | AH14: 4.4409369 | AI14: 4.4421744 | AJ14: 4.4419712 | AK14: 4.4402704 | AL14: 4.43685 | AM14: 4.4308836 | AN14: 4.423631 | AO14: 4.4144306 | AP14: 4.40242
A15: 城镇居住总面积 Mil. M2 | H15: =H14*H13 -> 60.772234 | I15: =I14*I13 -> 63.945277 | J15: =J14*J13 -> 64.750621 | K15: =K14*K13 -> 66.727463 | L15: =L14*L13 -> 70.260301 | M15: =M14*M13 -> 71.399409 | N15: =N14*N13 -> 72.405876 | O15: =O14*O13 -> 74.404138 | ... AP15: =AP14*AP13 -> 104.33735
A16: 新增城镇居住面积 | M16: =M15-L15 -> 1.1391081 | N16: =N15-M15 -> 1.006467 | O16: =O15-N15 -> 1.9982614 | P16: =P15-O15 -> 1.3492016 | Q16: =Q15-P15 -> 1.3184973 | R16: =R15-Q15 -> 1.2782107 | S16: =S15-R15 -> 1.2624887 | T16: =T15-S15 -> 1.2715887 | ... AP16: =AP15-AO15 -> 0.67180858
A17: 新增比例-commercial | M17: =M16/L15 -> 0.016212685 | N17: =N16/M15 -> 0.014096293 | O17: =O16/N15 -> 0.027598056 | P17: =P16/O15 -> 0.018133422 | Q17: =Q16/P15 -> 0.017405138 | R17: =R16/Q15 -> 0.016584666 | S17: =S16/R15 -> 0.016113439 | T17: =T16/S15 -> 0.015972217 | ... AP17: =AP16/AO15 -> 0.0064805387
A18: 农村居民人均居住面积 | G18: 11.216667 | H18: =($AP18-$G18)/35+G18 -> 11.324762 | I18: =($AP18-$G18)/35+H18 -> 11.432857 | J18: =($AP18-$G18)/35+I18 -> 11.540952 | K18: =($AP18-$G18)/35+J18 -> 11.649048 | L18: =($AP18-$G18)/35+K18 -> 11.757143 | M18: =($AP18-$G18)/35+L18 -> 11.865238 | N18: =($AP18-$G18)/35+M18 -> 11.973333 | O18: =($AP18-$G18)/35+N18 -> 12.081429 | ... AO18: =($AP18-$G18)/35+AN18 -> 14.891905 | AP18: 15
A19: 农村住人口 | H19: 3.3817908 | I19: 3.3273816 | J19: 3.4292223 | K19: 3.4503249 | L19: 3.4731988 | M19: 3.4807124 | N19: 3.5438066 | O19: 3.529301 | P19: 3.5453107 | Q19: 3.5593851 | R19: 3.5711623 | S19: 3.5818362 | T19: 3.5925512 | U19: 3.6031246 | V19: 3.6126445 | W19: 3.6217514 | X19: 3.6307194 | Y19: 3.6405047 | Z19: 3.6496046 | AA19: 3.6569752 | AB19: 3.6619843 | AC19: 3.6650454 | AD19: 3.6681128 | AE19: 3.6700533 | AF19: 3.6709145 | AG19: 3.6700198 | AH19: 3.6674631 | AI19: 3.6639256 | AJ19: 3.6592288 | AK19: 3.6533296 | AL19: 3.64605 | AM19: 3.6367164 | AN19: 3.626369 | AO19: 3.6144694 | AP19: 3.60198
A20: 农村居住总面积 Mil. M2 | H20: =H19*H18 -> 38.297976 | I20: =I19*I18 -> 38.041478 | J20: =J19*J18 -> 39.576491 | K20: =K19*K18 -> 40.192999 | L20: =L19*L18 -> 40.834894 | M20: =M19*M18 -> 41.299481 | N20: =N19*N18 -> 42.431178 | O20: =O19*O18 -> 42.638998 | ... AP20: =AP19*AP18 -> 54.0297
A21: 新增农村居住面积 | M21: =M20-L20 -> 0.46458708 | N21: =N20-M20 -> 1.131697 | O21: =O20-N20 -> 0.20781941 | P21: =P20-O20 -> 0.57665209 | Q21: =Q20-P20 -> 0.55631174 | R21: =R20-Q20 -> 0.53085783 | S21: =S20-R20 -> 0.51959656 | T21: =T20-S20 -> 0.5224228 | ... AP21: =AP20-AO20 -> 0.20336604
A22: 新增比例-urban residential | M22: =M21/L20 -> 0.011377208 | N22: =N21/M20 -> 0.027402208 | O22: =O21/N20 -> 0.0048977996 | P22: =P21/O20 -> 0.013524054 | Q22: =Q21/P20 -> 0.012872923 | R22: =R21/Q20 -> 0.012127805 | S22: =S21/R20 -> 0.011728296 | T22: =T21/S20 -> 0.011655391 | ... AP22: =AP21/AO20 -> 0.0037781885
A23: 商业和公共建筑人均面积 | L23: =[2]基础数据!$B$22 -> 13.620903
A24: 公共建筑总面积 Mil. M2 | L24: 47.9 | M24: 48.27 | N24: 48.64 | O24: 49.01 | P24: 49.38 | Q24: 49.75 | R24: 50.12 | S24: 50.49 | T24: 50.86 | U24: 51.23 | V24: 51.6 | W24: 51.97 | X24: 52.34 | Y24: 52.71 | Z24: 53.08 | AA24: 53.45 | AB24: 53.82 | AC24: 54.19 | AD24: 54.56 | AE24: 54.93 | AF24: 55.3 | AG24: 55.67 | AH24: 56.04 | AI24: 56.41 | AJ24: 56.78 | AK24: 57.15 | AL24: 57.52 | AM24: 57.89 | AN24: 58.26 | AO24: 58.63 | AP24: 59
A25: 新增公建面积 | M25: =M24-L24 -> 0.37 | N25: =N24-M24 -> 0.37 | O25: =O24-N24 -> 0.37 | P25: =P24-O24 -> 0.37 | Q25: =Q24-P24 -> 0.37 | R25: =R24-Q24 -> 0.37 | S25: =S24-R24 -> 0.37 | T25: =T24-S24 -> 0.37 | ... AP25: =AP24-AO24 -> 0.37
A26: 新增比例-rural residential | M26: =M25/M24 -> 0.0076652165 | N26: =N25/N24 -> 0.0076069079 | O26: =O25/O24 -> 0.0075494797 | P26: =P25/P24 -> 0.0074929121 | Q26: =Q25/Q24 -> 0.0074371859 | R26: =R25/R24 -> 0.0073822825 | S26: =S25/S24 -> 0.0073281838 | T26: =T25/T24 -> 0.0072748722 | ... AP26: =AP25/AP24 -> 0.0062711864
A28: Weighted average fraction of homes that are new
A29: UR-RE | B29: =AVERAGE(M17:AP17) -> 0.013276513 | D29: =L15 -> 70.260301
A30: RU-RE | B30: =AVERAGE(M22:AP22) -> 0.0093863635 | D30: =L20 -> 40.834894
A31: COM | B31: =AVERAGE(M26:AP26) -> 0.0069232338 | D31: =L24 -> 47.9
A32: total | B32: =SUMPRODUCT(B29:B31,D29:D31)/SUM(D29:D31) -> 0.010363369
A34: Share of Components That is New This Year
A36: The share of new components is the share of old components that are replaced in surviving
A37: buildings, plus the share of components in new buildings (which equals the share of new
A38: buildings, because all components in new buildings are new components).
A40: Share of Buildings that are Surviving
A41: UR-RE | B41: =1-B29 -> 0.98672349
A42: RU-RE | B42: =1-B30 -> 0.99061364
A43: COM | B43: =1-B31 -> 0.99307677
A45: Replacement rate of components in surviving buildings
A46: heating | B46: =1/'Component Lifetimes'!B2 -> 0.057692308
A47: cooling and ventilation | B47: =1/'Component Lifetimes'!B3 -> 0.071428571
A48: lighting | B48: =1/'Component Lifetimes'!B4 -> 0.019298246
...

Sheet SoCEUtiNTY
A1: Share of New Components Energy Use (dimensionless) | B1: urban residential | C1: rural residential | D1: commercial
A2: heating | B2: ='China Calculations'!B54 -> 0.070202868 | C2: ='China Calculations'!C54 -> 0.06653715 | D2: ='China Calculations'!D54 -> 0.064216124
A3: cooling and ventilation | B3: ='China Calculations'!B55 -> 0.083756763 | C3: ='China Calculations'!C55 -> 0.08014448 | D3: ='China Calculations'!D55 -> 0.077857289
A4: envelope | B4: 0 | C4: 0 | D4: 0
A5: lighting | B5: ='China Calculations'!B56 -> 0.032318546 | C5: ='China Calculations'!C56 -> 0.028503469 | D5: ='China Calculations'!D56 -> 0.026087873
A6: appliances | B6: ='China Calculations'!B57 -> 0.12132274 | C6: ='China Calculations'!C57 -> 0.11785856 | D6: ='China Calculations'!D57 -> 0.11566514
A7: other component | B7: ='China Calculations'!B58 -> 0.099831205 | C7: ='China Calculations'!C58 -> 0.096282297 | D7: ='China Calculations'!D58 -> 0.094035231
