Workbook
Name outputfrac_bio: #REF!
Name outputfrac_coal: #REF!
Name outputfrac_elec: #REF!
Name outputfrac_ngps: #REF!
Name outputfrac_nonenergy: #REF!
Name outputfrac_other: #REF!

Sheet About
A1: FoVObE Fraction of Vehicles Owned by Entity
A3: Source: | B3: Total Vehicles by Type
B4: Bureau of Transportation Statistics
B5: 2016
B6: National Transportation Statistics 2015
B7: http://www.rita.dot.gov/bts/sites/rita.dot.gov.bts/files/table_01_11_3.xlsx
B8: Table 1-11
B10: Federal Govt-Owned LDVs and HDVs
B11: General Services Administration
B12: 2011
B13: Fiscal Year 2011 Federal Fleet Report
B14: http://www.gsa.gov/graphics/ogp/2011FFR_Tables_FINAL.xlsx
B15: Table 2-1: Worldwide Inventory
B17: Fire Dept vehicles per 1000 people
B18: National Fire Protection Association
B19: 2013
B20: U.S. Fire Department Profile 2012
B21: http://www.nfpa.org/~/media/Files/Research/NFPA%20reports/Fire%20service%20statistics/osfdprofile.pdf
B22: Page 22, Table 13
B24: Police Department vehicles per 1000 people
B25: Bureau of Justice Statistics, U.S. Dept of Justice
B26: 2010
B27: Local Police Departments, 2007
B28: http://www.bjs.gov/content/pub/pdf/lpd07.pdf
B29: Page 38, Appendix Table 13
B31: Taxis and Limos
B32: Bureau of Labor Statistics
B33: 2013
B34: Occupational Outlook Handbook 2012
B35: http://www.bls.gov/ooh/transportation-and-material-moving/taxi-drivers-and-chauffeurs.htm
B36: Taxi Drivers and Chauffeurs
B38: U.S. Population, historical values, 2000-2009
B39: U.S. Census Bureau
B40: 2009
B41: Population Estimates: Vintage 2009: Annual Population Estimates
B42: http://www.census.gov/popest/data/state/totals/2009/tables/NST-EST2009-01.xls
B44: U.S. Population, historical values, 2010-2013
B45: U.S. Census Bureau
B46: 2013
B47: Population Estimates: National Totals: Vintage 2013
...

Sheet Results
A1: Subscripts | B1: Meaning in Model | C1: Fraction Owned by Govt | D1: Fraction Owned by Industry | E1: Fraction Owned by Consumers | F1: Explanation
A2: LDVs, passenger | B2: most LDVs | C2: =SUM('Federal Govt'!C4,'Federal Govt'!C6,'Federal Govt'!C11,'Police Departments'!A5)/SUM('NTS 1-11'!B8) -> 0.0059026388 | D2: ='Taxis and Limos'!A9+'Taxis and Limos'!A10/SUM('NTS 1-11'!B8) -> 1335.028 | E2: =1-SUM(C2:D2) -> -1334.0339 | F2: Government-owned passenger LDVs include all 4-wheeled police vehicles and all Federal LDVs. Industry-owned LDVs are estimated as one per taxi driver or chauffeur. Assumption that Cross-country vehicles were also considered as LDVs
A3: HDVs, passenger | B3: buses (school, transit, and intercity) | C3: 0 | D3: 1 | E3: 0 | F3: Hong Kong's transit system is operated by the franchised bus operating companies rather than the government
A4: aircraft, passenger | B4: commercial air travel for people (not general aviation) | C4: 0 | D4: 1 | E4: 0 | F4: We assume industry owns all commercial passenger aircraft.
A5: rail, passenger | B5: intercity, transit, and commuter rail | C5: 1 | D5: 0 | E5: 0 | F5: The MTR's sole shareholder is the HK Government
A6: ships, passenger | B6: recreational boats | C6: 0 | D6: 0 | E6: 1 | F6: We assume consumers own all recreational boats.
A7: motorbikes, passenger | B7: registered motorcycles | C7: ='Federal Govt'!C10/'NTS 1-11'!B7 -> 0.0067981733 | D7: 0 | E7: =1-C7 -> 0.99320183 | F7: Assumption that Police motorcycles are inclusive in the total Government number. We assume consumers own the rest.
A8: LDVs, freight | B8: commercial light trucks | C8: =SUM('Federal Govt'!C7,'Fire Departments'!A7)/SUM('NTS 1-11'!B12) -> 0.029272745 | D8: =1-C8 -> 0.97072725 | E8: 0 | F8: Data provided by EMSD at August 2023
A9: HDVs, freight | B9: all other HDVs | C9: =SUM('Federal Govt'!C5,'Federal Govt'!C8,'Fire Departments'!A7)/SUM('NTS 1-11'!B12) -> 0.012305636 | D9: =1-C9 -> 0.98769436 | E9: 0 | F9: Government-owned HDVs include those owned by the Federal government and all fire department vehicles. Also includes Medium Goods Vehicles. We assume industry owns the rest.
A10: aircraft, freight | B10: other commercial flights (not general aviation) | C10: 0 | D10: 1 | E10: 0 | F10: We assume industry owns all commercial freight aircraft.
A11: rail, freight | B11: all other rail | C11: 0 | D11: 1 | E11: 0 | F11: We assume all freight rail is industry-owned.
A12: ships, freight | B12: all other ships | C12: 0 | D12: 1 | E12: 0 | F12: We assume industry owns all freight ships.
A13: motorbikes, freight | B13: not used in model
A15: Orange = assumption
A16: Green = data
A18: NOTE

Sheet FoVObE-passengers
A1: Fraction Owned by Entity (dimensionless) | B1: government | C1: domestic industries | D1: labor and consumers | E1: foreign entities
A2: LDVs | B2: =Results!C2 -> 0.0059026388 | C2: =Results!D2 -> 1335.028 | D2: =Results!E2 -> -1334.0339 | E2: 0
A3: HDVs | B3: =Results!C3 -> 0 | C3: =Results!D3 -> 1 | D3: =Results!E3 -> 0 | E3: 0
A4: aircraft | B4: =Results!C4 -> 0 | C4: =Results!D4 -> 1 | D4: =Results!E4 -> 0 | E4: 0
A5: rail | B5: =Results!C5 -> 1 | C5: =Results!D5 -> 0 | D5: =Results!E5 -> 0 | E5: 0
A6: ships | B6: =Results!C6 -> 0 | C6: =Results!D6 -> 0 | D6: =Results!E6 -> 1 | E6: 0
A7: motorbikes | B7: =Results!C7 -> 0.0067981733 | C7: =Results!D7 -> 0 | D7: =Results!E7 -> 0.99320183 | E7: 0

Sheet FoVObE-freight
A1: Fraction Owned by Entity (dimensionless) | B1: government | C1: domestic industries | D1: labor and consumers | E1: foreign entities
A2: LDVs | B2: =Results!C8 -> 0.029272745 | C2: =Results!$D8 -> 0.97072725 | D2: =Results!E8 -> 0 | E2: 0
A3: HDVs | B3: =Results!C9 -> 0.012305636 | C3: =Results!$D9 -> 0.98769436 | D3: =Results!E9 -> 0 | E3: 0
A4: aircraft | B4: =Results!C10 -> 0 | C4: =Results!$D10 -> 1 | D4: =Results!E10 -> 0 | E4: 0
A5: rail | B5: =Results!C11 -> 0 | C5: =Results!$D11 -> 1 | D5: =Results!E11 -> 0 | E5: 0
A6: ships | B6: =Results!C12 -> 0 | C6: =Results!$D12 -> 1 | D6: =Results!E12 -> 0 | E6: 0
A7: motorbikes | B7: =Results!C13 -> 0 | C7: =Results!$D13 -> 0 | D7: =Results!E13 -> 0 | E7: 0

Sheet NTS 1-11
A1: Annual Traffic Census 2022
A2: Table 6-1
A3: Motor Vehicles Registered by Class 1947-2022
A6: Year (2022)
A7: Motorcycle | B7: 106205
A8: Private Motor Car | B8: 649540
A9: Taxi | B9: 19498
A10: Buses (Non-Franchised) | B10: 6198
A11: Buses (Franchised) | B11: 7720
A12: Goods Vehicles (incl. special purpose vehicles) | B12: 122708
A13: Public Light Bus | B13: 4349
A14: Private Light Bus | B14: 3473
A15: Government Vehicle | B15: 6899
A16: TOTAL | B16: =SUM(B7,B15) -> 113104

Sheet Federal Govt
A1: Federal Government-Owned Vehicles | C1: https://www.gld.gov.hk/en/our-services/land-transport/fleet-management/
B3: Ambulance | C3: 485
B4: Bus | C4: 421
B5: Heavy Goods Vehicles | C5: 5
B6: Light Bus | C6: 255
B7: Light Goods Vehicle | C7: 2340
B8: Medium Goods Vehicle | C8: 253
B9: Other Special Vehicle | C9: 122
B10: Motor Cycle | C10: 722
B11: Private Car | C11: 1909
B12: Recovery Vehicle | C12: 130
B13: Refuse Collection Vehicle | C13: 141
B14: Street Washer | C14: 45
... B16: Trailer | C16: 14
C17: 6899
B47: NOTE: taken from email conversation between EMSD Gary Cheung Aug 2023. Email is in the sharedrive

Sheet Fire Departments
A1: Fire Department Vehicles | D1: d
A3: HK Population in 2021
A4: =Population!B8 -> 7194600
A6: Fire Vehicles in 2023
A7: =837+415 -> 1252 | B7: Operational fire appliances/ supporting vehicles (including amublances)
A8: 480 | B8: ambulances (also located under the Fire Department)
B27: (screenshot taken from email conversation with garycheung@emsd.gov.hk [24/11/23]

Sheet Police Departments
A1: Police Department Vehicles | C1: https://www.aud.gov.hk/pdf_e/e71ch03.pdf
A3: Number of Motorized Land Vehicles operated by Local Police Departments, 2018
A4: General purpose vehicles (incl. saloon cars and small motorcycles) | B4: Other 4-wheeled vehicles (incl. specialised vehicles)
A5: 1249 | B5: 1145
A7: Year | B7: HK Population
A8: 2021 | B8: =Population!B8 -> 7194600
A11: We assume the majority of other 4-wheeled vehicles are SUVs and fall into the LDVs category.
A12: NOTE: Could not get an additional breakdown of police vehicles as this would be contravene with Clause 2.9© on the Code of Access and may harm the proper and efficient conduct of the operations of the HKPD

Sheet Taxis and Limos
A1: Taxi Cabs and Limousines
A3: Assumptions
A4: We assume approximately one LDV per driver.
A5: NOTE: TD defines hire car as the following (a) Hotel Hire Car Service (b) Tour Hire Car Service (C) Private Service [Limousine], (d) Private Service [Limousine-Cross Boundary] and (e) private service hire car
A6: https://www.info.gov.hk/gia/general/202205/18/P2022051800257.htm
A7: NOTE2: Source above only provides the statistics for 3. Assumption that "Private Hire Car Services" includes Limousine services too
A8: Number of Taxi Drivers and Chauffeurs
A9: =1115+100+120 -> 1335 | B9: Hire Cars (as of Dec 2021)
A10: 18163 | B10: Taxis (Urban, Island, New Territories)
A12: =SUM(A9:A10) -> 19498

Sheet Population
A1: Year | B1: HK population (updated 21/08/23) | C1: Type
A2: 2016 | B2: 7116829 | C2: Historical Data
A3: 2017 | B3: 7172800 | C3: Historical Data
A4: 2018 | B4: 7227800 | C4: Historical Data
A5: 2019 | B5: 7311400 | C5: Historical Data
A6: 2020 | B6: 7391600 | C6: Historical Data
A7: 2021 | B7: =+'[1]Key parameters rpt'!D4*1000000 -> 7334652 | C7: Historical Data
A8: 2022 | B8: 7194600 | C8: Future projection
A9: 2023 | B9: 7249300 | C9: Future projection
A10: 2024 | B10: 7290000 | C10: Future projection
A11: 2025 | B11: 7323700 | C11: Future projection
A12: 2026 | B12: 7361000 | C12: Future projection
A13: 2027 | B13: 7403300 | C13: Future projection
A14: 2028 | B14: 7450000 | C14: Future projection
A15: 2029 | B15: 7497600 | C15: Future projection
A16: 2030 | B16: 7544800 | C16: Future projection
A17: 2031 | B17: 7589900 | C17: Future projection
A18: 2032 | B18: 7634400 | C18: Future projection
A19: 2033 | B19: 7678700 | C19: Future projection
... A36: 2050 | B36: 7936900 | C36: Future projection
A37: 2051 | B37: ='[1]Key parameters rpt'!O4*1000000 -> 9066500 | C37: Future projection
