Workbook

Sheet About
A1: EIaE BAU Imported Electricity
A2: EIaE BAU Exported Electricity
A4: Source: | B4: Electricity production, imports, exports and consumption(Sheet: HK History Data)
B5: HK Census and Statistics Department(C&SD)
B6: 2023
B7: Hong Kong Energy Statistics Annual Report (2023 Edition)
B8: http://www.censtatd.gov.hk/en/wbr.html?ecode=B22000022022AN22&scode=90
B9: Table 1.1
B11: China Electricity Generation (Sheet:China Generation) | D11: China Electricity Generation (Sheet:China Generation)
B12: IEA Statistics | D12: Book: China Energy & Electricity Outlook 2017 (in Chinese)
B13: Retrieved 2019/03 | D13: 2017
B14: Statistics data browser-Electricity-China,People's Republic of | D14: Publisher: China Electric Power Press, Beijing, China
B15: https://www.iea.org//statistics/?country=CHINA&year=2016&category=Electricity&indicator=ElecGenByFuel&mode=chart&dataTable=ELECTRICITYANDHEAT | D15: Page 35
B17: China Electricity Installed Capacity (Sheet:China Capacity)
B18: Journal Article: China's Electricity Outlook toward 2050 (in Chinese)
B19: Energy of China. 2018. Volume:40, Issue:3.
B20: Publisher: China Electric Power Press, Beijing, China
B21: Page 7
B23: Unit Conversion (from TJ to GWh)
B24: Source: IEA, Unit Converter. http://www.iea.org/statistics/resources/unitconverter/
A26: Notes:
A27: 1.We need to know the mix of imported electricity types if we will be including
A28: pollutant emissions associated with imported electricity into the totals, which
A29: is managed by a control lever. If these emissions will not be included in the
A30: emissions totals, the breakdown is unimportant, and you may assign all
A31: imported electricity emissions to any one electricity source, if you prefer. ——This is note in the US model
A33: 2. Electricity exports are supplied by power plants in the modeled region and
A34: hence do not need their electricity source to be specified here.——Note in the US model
A36: 3.Since HK's current electricity import comes overwhelmingly from China's Daya Bay Nuclear Power Plant,
A37: which has a contract with HK's CLP company until 2034(see more detail about Guangdong Province's nuclear fact in Sheet "Guangdong Fact"),
A38: We assume that HK's imported electricity will still be dominated by nuclear power from Guangdong until 2035 (nuclear as 100%),
A39: and then other kinds of renewable energies (assign to wind power primarily; note that the assignment which won't make big difference in terms of pollutant emissions) will take a small but increasing part(30% in 2050, casually assumed by myself)
A41: 4. We assume that HK's electricity is only imported from and exported to mainland of China, considering its geographical location and conditions.
A42: Then: | B42: Produce+Import(from China)-Export(to China)=Consumption+System loss
A44: 5.The unit of electricity quantity in Sheets"ElaE-BIE" and "ELaE-BEE" is: MWh
A46: All canadian natural gas was assigned to the "natural gas nonpeaker" plant type
A47: because the breakdown between NG peaker and NG nonpeaker for imported
A48: electricity is not important.
A50: Note by Roman:
A51: We might want to change all imports to 100% nuclear until 2050 for the BAU case, and add scenario options to increase percentage of renewables from China.
...

Sheet HK History Data
A1: Electricity production, imports, exports and consumption | D1: (Unit: TJ)
A2: Year | B2: Electricity generated at local plants | C2: Imports of electricity from the mainland of China | D2: System Loss | E2: Exports of electricity to the mainland of China | F2: Local electricity consumption, as measured at meter points | G2: System loss percentage
A3: 2007 | B3: 140212 | C3: 37233 | D3: 15847 | E3: 14527 | F3: 147072 | G3: =D3/(B3+C3) -> 0.089306546 | H3: =SUM(B3,C3)-D3-E3 -> 147071
A4: 2008 | B4: 136765 | C4: 38883 | D4: 15514 | E4: 12789 | F4: 147345 | G4: =D4/(B4+C4) -> 0.088324376 | H4: =SUM(B4,C4)-D4-E4 -> 147345
A5: 2009 | B5: 139420 | C5: 39468 | D5: 16089 | E5: 13432 | F5: 149366 | G5: =D5/(B5+C5) -> 0.089938956 | H5: =SUM(B5,C5)-D5-E5 -> 149367
A6: 2010 | B6: 137850 | C6: 37838 | D6: 15590 | E6: 9392 | F6: 150705 | G6: =D6/(B6+C6) -> 0.088736852 | H6: =SUM(B6,C6)-D6-E6 -> 150706
A7: 2011 | B7: 140495 | C7: 38646 | D7: 17064 | E7: 10645 | F7: 151432 | G7: =D7/(B7+C7) -> 0.095254576 | H7: =SUM(B7,C7)-D7-E7 -> 151432
A8: 2012 | B8: 139506 | C8: 40160 | D8: 18139 | E8: 6617 | F8: 154911 | G8: =D8/(B8+C8) -> 0.10095956 | H8: =SUM(B8,C8)-D8-E8 -> 154910
A9: 2013 | B9: 140628 | C9: 35889 | D9: 17376 | E9: 5940 | F9: 153201 | G9: =D9/(B9+C9) -> 0.098438111 | H9: =SUM(B9,C9)-D9-E9 -> 153201
A10: 2014 | B10: 143291 | C10: 37038 | D10: 17948 | E10: 4414 | F10: 157967 | G10: =D10/(B10+C10) -> 0.099529194 | H10: =SUM(B10,C10)-D10-E10 -> 157967
A11: 2015 | B11: 136525 | C11: 42272 | D11: 16441 | E11: 4273 | F11: 158083 | G11: =D11/(B11+C11) -> 0.091953444 | H11: =SUM(B11,C11)-D11-E11 -> 158083
A12: 2016 | B12: 137356 | C12: 41835 | D12: 16352 | E12: 4338 | F12: 158500 | G12: =D12/(B12+C12) -> 0.091254583 | H12: =SUM(B12,C12)-D12-E12 -> 158501
A13: 2017 | B13: 132902 | C13: 45274 | D13: 15744 | E13: 4828 | F13: 157604 | G13: =D13/(B13+C13) -> 0.088362069 | H13: =SUM(B13,C13)-D13-E13 -> 157604
A14: 2018 | B14: 131254 | C14: 45357 | D14: 15492 | E14: 2002 | F14: 159116 | G14: =D14/(B14+C14) -> 0.087718206 | H14: =SUM(B14,C14)-D14-E14 -> 159117
... A18: 2022 | B18: 129928 | C18: 44452 | D18: 13225 | E18: 0 | F18: 161155 | G18: =D18/(B18+C18) -> 0.075840119 | H18: =SUM(B18,C18)-D18-E18 -> 161155
A22: Notes: | B22: 1. 1 terajoule = 10^12 joules.
B23: 2. "System loss" includes energy lossess in electricity generation, transmission and distribution.
B24: It also includes electricity consumed within the electricity companies, such as in their offices and staff residence.

Sheet HK I&E Projection
A1: 2007-2017:(Transposed from) History data | N1: 2022 onward, Production, Import, export & Consumption are obtained from Trending, System loss rate is fix at the average level of 2007-2017
B2: {=TRANSPOSE('HK History Data'!A2:F13)} -> Year | C2: 2007 | D2: 2008 | E2: 2009 | F2: 2010 | G2: 2011 | H2: 2012 | I2: 2013 | J2: 2014 | K2: 2015 | L2: 2016 | M2: 2017 | N2: 2018 | O2: 2019 | P2: 2020 | Q2: 2021 | R2: 2022 | S2: 2023 | T2: 2024 | U2: 2025 | V2: 2026 | W2: 2027 | X2: 2028 | Y2: 2029 | Z2: 2030 | AA2: 2031 | AB2: 2032 | AC2: 2033 | AD2: 2034 | AE2: 2035 | AF2: 2036 | AG2: 2037 | AH2: 2038 | AI2: 2039 | AJ2: 2040 | AK2: 2041 | AL2: 2042 | AM2: 2043 | AN2: 2044 | AO2: 2045 | AP2: 2046 | AQ2: 2047 | AR2: 2048 | AS2: 2049 | AT2: 2050
B3: Electricity generated at local plants | C3: 140212 | D3: 136765 | E3: 139420 | F3: 137850 | G3: 140495 | H3: 139506 | I3: 140628 | J3: 143291 | K3: 136525 | L3: 137356 | M3: 132902 | N3: 131254 | O3: 132462 | P3: 126307 | Q3: 133104 | R3: 129928 | S3: =TREND($C3:$M3,$C$2:$M$2,S$2) -> 135446.22 | T3: =TREND($C3:$M3,$C$2:$M$2,T$2) -> 135156.62 | U3: =TREND($C3:$M3,$C$2:$M$2,U$2) -> 134867.02 | V3: =TREND($C3:$M3,$C$2:$M$2,V$2) -> 134577.42 | W3: =TREND($C3:$M3,$C$2:$M$2,W$2) -> 134287.82 | X3: =TREND($C3:$M3,$C$2:$M$2,X$2) -> 133998.22 | Y3: =TREND($C3:$M3,$C$2:$M$2,Y$2) -> 133708.62 | Z3: =TREND($C3:$M3,$C$2:$M$2,Z$2) -> 133419.02 | ... AT3: =TREND($C3:$M3,$C$2:$M$2,AT$2) -> 127627.02
B4: Imports of electricity from the mainland of China | C4: 37233 | D4: 38883 | E4: 39468 | F4: 37838 | G4: 38646 | H4: 40160 | I4: 35889 | J4: 37038 | K4: 42272 | L4: 41835 | M4: 45274 | N4: 45357 | O4: 44571 | P4: 45716 | Q4: 45197 | R4: 44452 | S4: =TREND($C4:$M4,$C$2:$M$2,S$2) -> 45110.073 | T4: =TREND($C4:$M4,$C$2:$M$2,T$2) -> 45619.782 | U4: =TREND($C4:$M4,$C$2:$M$2,U$2) -> 46129.491 | V4: =TREND($C4:$M4,$C$2:$M$2,V$2) -> 46639.2 | W4: =TREND($C4:$M4,$C$2:$M$2,W$2) -> 47148.909 | X4: =TREND($C4:$M4,$C$2:$M$2,X$2) -> 47658.618 | Y4: =TREND($C4:$M4,$C$2:$M$2,Y$2) -> 48168.327 | Z4: =TREND($C4:$M4,$C$2:$M$2,Z$2) -> 48678.036 | ... AT4: =TREND($C4:$M4,$C$2:$M$2,AT$2) -> 58872.218
B5: System Loss | C5: 15847 | D5: 15514 | E5: 16089 | F5: 15590 | G5: 17064 | H5: 18139 | I5: 17376 | J5: 17948 | K5: 16441 | L5: 16352 | M5: 15744 | N5: 15492 | O5: 15742 | P5: 13272 | Q5: 13724 | R5: 13225 | S5: =(S3+S4)*AVERAGE('HK History Data'!$G$3:$G$13) -> 16776.277 | T5: =(T3+T4)*AVERAGE('HK History Data'!$G$3:$G$13) -> 16796.729 | U5: =(U3+U4)*AVERAGE('HK History Data'!$G$3:$G$13) -> 16817.18 | V5: =(V3+V4)*AVERAGE('HK History Data'!$G$3:$G$13) -> 16837.631 | W5: =(W3+W4)*AVERAGE('HK History Data'!$G$3:$G$13) -> 16858.082 | X5: =(X3+X4)*AVERAGE('HK History Data'!$G$3:$G$13) -> 16878.534 | Y5: =(Y3+Y4)*AVERAGE('HK History Data'!$G$3:$G$13) -> 16898.985 | Z5: =(Z3+Z4)*AVERAGE('HK History Data'!$G$3:$G$13) -> 16919.436 | ... AT5: =(AT3+AT4)*AVERAGE('HK History Data'!$G$3:$G$13) -> 17328.462
B6: Exports of electricity to the mainland of China | C6: 14527 | D6: 12789 | E6: 13432 | F6: 9392 | G6: 10645 | H6: 6617 | I6: 5940 | J6: 4414 | K6: 4273 | L6: 4338 | M6: 4828 | N6: 2002 | O6: 0 | P6: 0 | Q6: 0 | R6: 0 | S6: =TREND($O6:$R6,$O$2:$R$2,S$2) -> 0 | T6: =TREND($O6:$R6,$O$2:$R$2,T$2) -> 0 | U6: =TREND($O6:$R6,$O$2:$R$2,U$2) -> 0 | V6: =TREND($O6:$R6,$O$2:$R$2,V$2) -> 0 | W6: =TREND($O6:$R6,$O$2:$R$2,W$2) -> 0 | X6: =TREND($O6:$R6,$O$2:$R$2,X$2) -> 0 | Y6: =TREND($O6:$R6,$O$2:$R$2,Y$2) -> 0 | Z6: =TREND($O6:$R6,$O$2:$R$2,Z$2) -> 0 | ... AT6: =TREND($O6:$R6,$O$2:$R$2,AT$2) -> 0
B7: Local electricity consumption, as measured at meter points | C7: 147072 | D7: 147345 | E7: 149366 | F7: 150705 | G7: 151432 | H7: 154911 | I7: 153201 | J7: 157967 | K7: 158083 | L7: 158500 | M7: 157604 | N7: 159116 | O7: 161291 | P7: 158751 | Q7: 164578 | R7: 161155 | S7: =TREND($C7:$M7,$C$2:$M$2,S$2) -> 167262.04 | T7: =TREND($C7:$M7,$C$2:$M$2,T$2) -> 168532.25 | U7: =TREND($C7:$M7,$C$2:$M$2,U$2) -> 169802.47 | V7: =TREND($C7:$M7,$C$2:$M$2,V$2) -> 171072.69 | W7: =TREND($C7:$M7,$C$2:$M$2,W$2) -> 172342.91 | X7: =TREND($C7:$M7,$C$2:$M$2,X$2) -> 173613.13 | Y7: =TREND($C7:$M7,$C$2:$M$2,Y$2) -> 174883.35 | Z7: =TREND($C7:$M7,$C$2:$M$2,Z$2) -> 176153.56 | ... AT7: =TREND($C7:$M7,$C$2:$M$2,AT$2) -> 201557.93
B8: Import's ratio in consumption | C8: =C4/C7 -> 0.25316172 | D8: =D4/D7 -> 0.26389087 | E8: =E4/E7 -> 0.26423684 | F8: =F4/F7 -> 0.25107329 | G8: =G4/G7 -> 0.25520366 | H8: =H4/H7 -> 0.25924563 | I8: =I4/I7 -> 0.23426087 | J8: =J4/J7 -> 0.23446669 | ... AT8: =AT4/AT7 -> 0.29208585
N10: How to make projections for future Electricity Import&Export:
N12: 1. Observations
R13: Import | S13: Export
N14: 1) Average growth rate in 2007-2017 | R14: =(M4/C4)^(1/(M2-C2))-1 -> 0.019746172 | S14: =(M6/C6)^(1/(M2-C2))-1 -> -0.1043071
N15: 2) Facts: The HK's electricity imports have generally growing trend, while the exports decreasing.
N17: 2.WWF's advocation
N18: WWF proposes the imported RE from China to make up ~55% in HK's 2050 electricity mix
N19: While by extrapolating the 200-2017 trend of imported amount, we get 58872.2/127627，≈ | W19: =AT4/AT3 -> 0.46128335
O20: Since this percentage is in accord with and also a little bit smaller than WWF's projection, I primarily adopt this Trending method for Import Projection.
N46: 3. For export, I didn't find useful information, and therefore I just use the Trend function as well.
N47: Note: | O47: Export could be projected by :Produce+Import-Consumption-System Loss, but this method would results in large negative value.
P48: Perhaps the projections of Electricity Generation(by trending, it's decreasing) & Consumption need adjustments.
O49: Note that the current export amouts projected by trending will also decrease to below zero, therefore, I use 0 to replace the negative numbers in the final datasheet" ElaE-BEE".

Sheet Guangdong Fact
A1: Facts about HK's imported electricity
A2: 1 | B2: CLP, One of the two major electricity-supply companies in HK, "owns 25% shares of the (GNPS) power station (which belongs to CGNPC)"
B3: The station produces some 14 billion kWh of electricity per year, of which a portion is currently imported by CLP into its system in Hong Kong. In 2009, the supply contract was extended until 2034.
B4: From CLP website: https://www.clp.com.hk/en/about-clp/power-generation/infrastructure-and-fuel-mix/guangdong-daya-bay-nuclear-power-station
A6: 2 | B6: .About 1/4 HK's electricity consumption is supplied by GNPS(大亚湾核电基地供应香港电量约占香港用电量的1/4)
B7: From People's Daily (in Chinese):http://sz.people.com.cn/n/2014/0506/c202846-21149595.html
A9: 3 | B9: At the same time, HK's ratio of (imported electricity/total electricity consumption) is also about 1/4-The acute value was 25.3% in 2007，and is 28.7% in 2017.
B10: Calculations are made in sheet"HK I&E Projection"
A12: 4 | B12: From 2. and 3., it's easy to infer that HK's imported electricity is dominated by nuclear power from Guangdong.
A14: 5 | B14: Also, the LNPS Phase II, which also belongs to CGNPC, has put 2 units into commercial operation in 2010 and 2011 respectively.
B15: From CGNPC website: http://en.dnmc.com.cn/dnmc/index.shtml
B16: Guangdong also has other nuclear plants in build.
B17: From Research Institute of Energy in Xiamen University: http://realtime.xmuenergy.com/nuclearlistbycity.aspx?cityid=%E5%B9%BF%E4%B8%9C%E7%9C%81
B18: So, perhaps HK will cooperate with Guangdong further, after the current contract held by CLP expires.
A20: Abbr. | B20: CGNPC | C20: China Guangdong Nuclear Power Holding Corporation
B21: LNPS Phase II | C21: Ling Ao Nuclear Power Station Phase II
B22: GNPS | C22: Daya Bay Nuclear Power Station

Sheet Imported Mix
A1: Fuel Type | B1: 2015 | C1: 2016 | D1: 2017 | E1: 2018 | F1: 2019 | G1: 2020 | H1: 2021 | I1: 2022 | J1: 2023 | K1: 2024 | L1: 2025 | M1: 2026 | N1: 2027 | O1: 2028 | P1: 2029 | Q1: 2030 | R1: 2031 | S1: 2032 | T1: 2033 | U1: 2034 | V1: 2035 | W1: 2036 | X1: 2037 | Y1: 2038 | Z1: 2039 | AA1: 2040 | AB1: 2041 | AC1: 2042 | AD1: 2043 | AE1: 2044 | AF1: 2045 | AG1: 2046 | AH1: 2047 | AI1: 2048 | AJ1: 2049 | AK1: 2050
A2: hard coal
A3: natural gas nonpeaker
A4: nuclear | B4: 1 | C4: 1 | D4: 1 | E4: 1 | F4: 1 | G4: 1 | H4: 1 | I4: 1 | J4: 1 | K4: 1 | L4: 1 | M4: 1 | N4: 1 | O4: 1 | P4: 1 | Q4: 1 | R4: 1 | S4: 1 | T4: 1 | U4: 1 | V4: 0 | W4: =TREND($D$20:$D$21,$A$20:$A$21,W$1) -> 0 | X4: =TREND($D$20:$D$21,$A$20:$A$21,X$1) -> 0 | Y4: =TREND($D$20:$D$21,$A$20:$A$21,Y$1) -> 0 | Z4: =TREND($D$20:$D$21,$A$20:$A$21,Z$1) -> 0 | AA4: =TREND($D$20:$D$21,$A$20:$A$21,AA$1) -> 0 | AB4: =TREND($D$20:$D$21,$A$20:$A$21,AB$1) -> 0 | AC4: =TREND($D$20:$D$21,$A$20:$A$21,AC$1) -> 0 | AD4: =TREND($D$20:$D$21,$A$20:$A$21,AD$1) -> 0 | ... AJ4: =TREND($D$20:$D$21,$A$20:$A$21,AJ$1) -> 0 | AK4: 0
A5: hydro
A6: onshore wind | V6: 1 | W6: =TREND($F$20:$F$21,$A$20:$A$21,W$1) -> 1 | X6: =TREND($F$20:$F$21,$A$20:$A$21,X$1) -> 1 | Y6: =TREND($F$20:$F$21,$A$20:$A$21,Y$1) -> 1 | Z6: =TREND($F$20:$F$21,$A$20:$A$21,Z$1) -> 1 | AA6: =TREND($F$20:$F$21,$A$20:$A$21,AA$1) -> 1 | AB6: =TREND($F$20:$F$21,$A$20:$A$21,AB$1) -> 1 | AC6: =TREND($F$20:$F$21,$A$20:$A$21,AC$1) -> 1 | AD6: =TREND($F$20:$F$21,$A$20:$A$21,AD$1) -> 1 | ... AJ6: =TREND($F$20:$F$21,$A$20:$A$21,AJ$1) -> 1 | AK6: 1
A7: solar PV
A8: solar thermal
A9: biomass
A10: geothermal
A11: petroleum
A12: natural gas peaker
A13: lignite
A14: offshore wind
A16: Transposed for TREND function
A17: {=TRANSPOSE(A1:C14)} -> Fuel Type | B17: hard coal | C17: natural gas nonpeaker | D17: nuclear | E17: hydro | F17: onshore wind | G17: solar PV | H17: solar thermal | I17: biomass | J17: geothermal | K17: petroleum | L17: natural gas peaker | M17: lignite | N17: offshore wind
A18: 2015 | B18: 0 | C18: 0 | D18: 1 | E18: 0 | F18: 0 | G18: 0 | H18: 0 | I18: 0 | J18: 0 | K18: 0 | L18: 0 | M18: 0 | N18: 0
A19: 2016 | B19: 0 | C19: 0 | D19: 1 | E19: 0 | F19: 0 | G19: 0 | H19: 0 | I19: 0 | J19: 0 | K19: 0 | L19: 0 | M19: 0 | N19: 0
A20: {=TRANSPOSE(V1:V14)} -> 2035 | B20: 0 | C20: 0 | D20: 0 | E20: 0 | F20: 1 | G20: 0 | H20: 0 | I20: 0 | J20: 0 | K20: 0 | L20: 0 | M20: 0 | N20: 0 | O20: #N/A
A21: {=TRANSPOSE(AK1:AK14)} -> 2050 | B21: 0 | C21: 0 | D21: 0 | E21: 0 | F21: 1 | G21: 0 | H21: 0 | I21: 0 | J21: 0 | K21: 0 | L21: 0 | M21: 0 | N21: 0 | O21: #N/A

Sheet China Generation(not used)
A1: Fuel Type | B1: 2015 | C1: 2016 | D1: 2017 | E1: 2018 | F1: 2019 | G1: 2020 | H1: 2021 | I1: 2022 | J1: 2023 | K1: 2024 | L1: 2025 | M1: 2026 | N1: 2027 | O1: 2028 | P1: 2029 | Q1: 2030 | R1: 2031 | S1: 2032 | T1: 2033 | U1: 2034 | V1: 2035 | W1: 2036 | X1: 2037 | Y1: 2038 | Z1: 2039 | AA1: 2040 | AB1: 2041 | AC1: 2042 | AD1: 2043 | AE1: 2044 | AF1: 2045 | AG1: 2046 | AH1: 2047 | AI1: 2048 | AJ1: 2049 | AK1: 2050
A2: hard coal | B2: =B26/B$39 -> 0.70125155 | C2: =C26/C$39 -> 0.68218992 | D2: =TREND($B$18:$B$20,$A$18:$A$20,D$1) -> 0.66869845 | E2: =TREND($B$18:$B$20,$A$18:$A$20,E$1) -> 0.65330807 | F2: =TREND($B$18:$B$20,$A$18:$A$20,F$1) -> 0.63791768 | G2: =TREND($B$18:$B$20,$A$18:$A$20,G$1) -> 0.62252729 | H2: =TREND($B$18:$B$20,$A$18:$A$20,H$1) -> 0.6071369 | I2: =TREND($B$18:$B$20,$A$18:$A$20,I$1) -> 0.59174651 | J2: =TREND($B$18:$B$20,$A$18:$A$20,J$1) -> 0.57635612 | K2: =TREND($B$18:$B$20,$A$18:$A$20,K$1) -> 0.56096574 | ... P2: =TREND($B$18:$B$20,$A$18:$A$20,P$1) -> 0.48401379 | Q2: =Q26/Q$39 -> 0.46875 | R2: =TREND($B$20:$B$21,$A$20:$A$21,R$1) -> 0.45251589 | S2: =TREND($B$20:$B$21,$A$20:$A$21,S$1) -> 0.43628178 | T2: =TREND($B$20:$B$21,$A$20:$A$21,T$1) -> 0.42004767 | U2: =TREND($B$20:$B$21,$A$20:$A$21,U$1) -> 0.40381356 | V2: =TREND($B$20:$B$21,$A$20:$A$21,V$1) -> 0.38757945 | W2: =TREND($B$20:$B$21,$A$20:$A$21,W$1) -> 0.37134534 | X2: =TREND($B$20:$B$21,$A$20:$A$21,X$1) -> 0.35511123 | Y2: =TREND($B$20:$B$21,$A$20:$A$21,Y$1) -> 0.33887712 | ... AJ2: =TREND($B$20:$B$21,$A$20:$A$21,AJ$1) -> 0.16030191 | AK2: =R26/R$39 -> 0.1440678
A3: natural gas nonpeaker | B3: =B27/B$39 -> 0 | C3: =C27/C$39 -> 0 | D3: =TREND($C$18:$C$20,$A$18:$A$20,D$1) -> 0 | E3: =TREND($C$18:$C$20,$A$18:$A$20,E$1) -> 0 | F3: =TREND($C$18:$C$20,$A$18:$A$20,F$1) -> 0 | G3: =TREND($C$18:$C$20,$A$18:$A$20,G$1) -> 0 | H3: =TREND($C$18:$C$20,$A$18:$A$20,H$1) -> 0 | I3: =TREND($C$18:$C$20,$A$18:$A$20,I$1) -> 0 | J3: =TREND($C$18:$C$20,$A$18:$A$20,J$1) -> 0 | K3: =TREND($C$18:$C$20,$A$18:$A$20,K$1) -> 0 | ... P3: =TREND($C$18:$C$20,$A$18:$A$20,P$1) -> 0 | Q3: =Q27/Q$39 -> 0 | R3: =TREND($C$20:$C$21,$A$20:$A$21,R$1) -> 0 | S3: =TREND($C$20:$C$21,$A$20:$A$21,S$1) -> 0 | T3: =TREND($C$20:$C$21,$A$20:$A$21,T$1) -> 0 | U3: =TREND($C$20:$C$21,$A$20:$A$21,U$1) -> 0 | V3: =TREND($C$20:$C$21,$A$20:$A$21,V$1) -> 0 | W3: =TREND($C$20:$C$21,$A$20:$A$21,W$1) -> 0 | X3: =TREND($C$20:$C$21,$A$20:$A$21,X$1) -> 0 | Y3: =TREND($C$20:$C$21,$A$20:$A$21,Y$1) -> 0 | ... AJ3: =TREND($C$20:$C$21,$A$20:$A$21,AJ$1) -> 0 | AK3: =R27/R$39 -> 0
A4: nuclear | B4: =B28/B$39 -> 0.029147293 | C4: =C28/C$39 -> 0.034302118 | D4: =TREND($D$18:$D$20,$A$18:$A$20,D$1) -> 0.039216819 | E4: =TREND($D$18:$D$20,$A$18:$A$20,E$1) -> 0.044213381 | F4: =TREND($D$18:$D$20,$A$18:$A$20,F$1) -> 0.049209943 | G4: =TREND($D$18:$D$20,$A$18:$A$20,G$1) -> 0.054206505 | H4: =TREND($D$18:$D$20,$A$18:$A$20,H$1) -> 0.059203067 | I4: =TREND($D$18:$D$20,$A$18:$A$20,I$1) -> 0.064199629 | J4: =TREND($D$18:$D$20,$A$18:$A$20,J$1) -> 0.069196191 | K4: =TREND($D$18:$D$20,$A$18:$A$20,K$1) -> 0.074192753 | ... P4: =TREND($D$18:$D$20,$A$18:$A$20,P$1) -> 0.099175562 | Q4: =Q28/Q$39 -> 0.10416667 | R4: =TREND($D$20:$D$21,$A$20:$A$21,R$1) -> 0.10658545 | S4: =TREND($D$20:$D$21,$A$20:$A$21,S$1) -> 0.10900424 | T4: =TREND($D$20:$D$21,$A$20:$A$21,T$1) -> 0.11142302 | U4: =TREND($D$20:$D$21,$A$20:$A$21,U$1) -> 0.11384181 | V4: =TREND($D$20:$D$21,$A$20:$A$21,V$1) -> 0.11626059 | W4: =TREND($D$20:$D$21,$A$20:$A$21,W$1) -> 0.11867938 | X4: =TREND($D$20:$D$21,$A$20:$A$21,X$1) -> 0.12109816 | Y4: =TREND($D$20:$D$21,$A$20:$A$21,Y$1) -> 0.12351695 | ... AJ4: =TREND($D$20:$D$21,$A$20:$A$21,AJ$1) -> 0.15012359 | AK4: =R28/R$39 -> 0.15254237
A5: hydro | B5: =B29/B$39 -> 0.1928948 | C5: =C29/C$39 -> 0.19192569 | D5: =TREND($E$18:$E$20,$A$18:$A$20,D$1) -> 0.19082366 | E5: =TREND($E$18:$E$20,$A$18:$A$20,E$1) -> 0.18976695 | F5: =TREND($E$18:$E$20,$A$18:$A$20,F$1) -> 0.18871023 | G5: =TREND($E$18:$E$20,$A$18:$A$20,G$1) -> 0.18765352 | H5: =TREND($E$18:$E$20,$A$18:$A$20,H$1) -> 0.1865968 | I5: =TREND($E$18:$E$20,$A$18:$A$20,I$1) -> 0.18554008 | J5: =TREND($E$18:$E$20,$A$18:$A$20,J$1) -> 0.18448337 | K5: =TREND($E$18:$E$20,$A$18:$A$20,K$1) -> 0.18342665 | ... P5: =TREND($E$18:$E$20,$A$18:$A$20,P$1) -> 0.17814307 | Q5: =Q29/Q$39 -> 0.17708333 | R5: =TREND($E$20:$E$21,$A$20:$A$21,R$1) -> 0.17670374 | S5: =TREND($E$20:$E$21,$A$20:$A$21,S$1) -> 0.17632415 | T5: =TREND($E$20:$E$21,$A$20:$A$21,T$1) -> 0.17594456 | U5: =TREND($E$20:$E$21,$A$20:$A$21,U$1) -> 0.17556497 | V5: =TREND($E$20:$E$21,$A$20:$A$21,V$1) -> 0.17518538 | W5: =TREND($E$20:$E$21,$A$20:$A$21,W$1) -> 0.17480579 | X5: =TREND($E$20:$E$21,$A$20:$A$21,X$1) -> 0.1744262 | Y5: =TREND($E$20:$E$21,$A$20:$A$21,Y$1) -> 0.17404661 | ... AJ5: =TREND($E$20:$E$21,$A$20:$A$21,AJ$1) -> 0.16987112 | AK5: =R29/R$39 -> 0.16949153
A6: onshore wind | B6: =B30/B$39 -> 0.031703307 | C6: =C30/C$39 -> 0.038127206 | D6: =TREND($F$18:$F$20,$A$18:$A$20,D$1) -> 0.043145768 | E6: =TREND($F$18:$F$20,$A$18:$A$20,E$1) -> 0.048643422 | F6: =TREND($F$18:$F$20,$A$18:$A$20,F$1) -> 0.054141076 | G6: =TREND($F$18:$F$20,$A$18:$A$20,G$1) -> 0.05963873 | H6: =TREND($F$18:$F$20,$A$18:$A$20,H$1) -> 0.065136385 | I6: =TREND($F$18:$F$20,$A$18:$A$20,I$1) -> 0.070634039 | J6: =TREND($F$18:$F$20,$A$18:$A$20,J$1) -> 0.076131693 | K6: =TREND($F$18:$F$20,$A$18:$A$20,K$1) -> 0.081629347 | ... P6: =TREND($F$18:$F$20,$A$18:$A$20,P$1) -> 0.10911762 | Q6: =(Q30+Q38)/Q$39 -> 0.11458333 | R6: =TREND($F$20:$F$21,$A$20:$A$21,R$1) -> 0.11987112 | S6: =TREND($F$20:$F$21,$A$20:$A$21,S$1) -> 0.1251589 | T6: =TREND($F$20:$F$21,$A$20:$A$21,T$1) -> 0.13044668 | U6: =TREND($F$20:$F$21,$A$20:$A$21,U$1) -> 0.13573446 | V6: =TREND($F$20:$F$21,$A$20:$A$21,V$1) -> 0.14102225 | W6: =TREND($F$20:$F$21,$A$20:$A$21,W$1) -> 0.14631003 | X6: =TREND($F$20:$F$21,$A$20:$A$21,X$1) -> 0.15159781 | Y6: =TREND($F$20:$F$21,$A$20:$A$21,Y$1) -> 0.15688559 | ... AJ6: =TREND($F$20:$F$21,$A$20:$A$21,AJ$1) -> 0.2150512 | AK6: =(R30+R38)/R$39 -> 0.22033898
A7: solar PV | B7: =B31/B$39 -> 0.0076426121 | C7: =C31/C$39 -> 0.012103129 | D7: =TREND($G$18:$G$20,$A$18:$A$20,D$1) -> 0.013135014 | E7: =TREND($G$18:$G$20,$A$18:$A$20,E$1) -> 0.015335751 | F7: =TREND($G$18:$G$20,$A$18:$A$20,F$1) -> 0.017536487 | G7: =TREND($G$18:$G$20,$A$18:$A$20,G$1) -> 0.019737224 | H7: =TREND($G$18:$G$20,$A$18:$A$20,H$1) -> 0.02193796 | I7: =TREND($G$18:$G$20,$A$18:$A$20,I$1) -> 0.024138697 | J7: =TREND($G$18:$G$20,$A$18:$A$20,J$1) -> 0.026339434 | K7: =TREND($G$18:$G$20,$A$18:$A$20,K$1) -> 0.02854017 | ... P7: =TREND($G$18:$G$20,$A$18:$A$20,P$1) -> 0.039543854 | Q7: =Q31/Q$39 -> 0.041666667 | R7: =TREND($G$20:$G$21,$A$20:$A$21,R$1) -> 0.046362994 | S7: =TREND($G$20:$G$21,$A$20:$A$21,S$1) -> 0.051059322 | T7: =TREND($G$20:$G$21,$A$20:$A$21,T$1) -> 0.05575565 | U7: =TREND($G$20:$G$21,$A$20:$A$21,U$1) -> 0.060451977 | V7: =TREND($G$20:$G$21,$A$20:$A$21,V$1) -> 0.065148305 | W7: =TREND($G$20:$G$21,$A$20:$A$21,W$1) -> 0.069844633 | X7: =TREND($G$20:$G$21,$A$20:$A$21,X$1) -> 0.07454096 | Y7: =TREND($G$20:$G$21,$A$20:$A$21,Y$1) -> 0.079237288 | ... AJ7: =TREND($G$20:$G$21,$A$20:$A$21,AJ$1) -> 0.13089689 | AK7: =R31/R$39 -> 0.13559322
A8: solar thermal | B8: =B32/B$39 -> 4.6078899e-06 | C8: =C32/C$39 -> 4.6639571e-06 | D8: =TREND($H$18:$H$20,$A$18:$A$20,D$1) -> 0.0010902498 | E8: =TREND($H$18:$H$20,$A$18:$A$20,E$1) -> 0.0018057687 | F8: =TREND($H$18:$H$20,$A$18:$A$20,F$1) -> 0.0025212876 | G8: =TREND($H$18:$H$20,$A$18:$A$20,G$1) -> 0.0032368065 | H8: =TREND($H$18:$H$20,$A$18:$A$20,H$1) -> 0.0039523254 | I8: =TREND($H$18:$H$20,$A$18:$A$20,I$1) -> 0.0046678443 | J8: =TREND($H$18:$H$20,$A$18:$A$20,J$1) -> 0.0053833632 | K8: =TREND($H$18:$H$20,$A$18:$A$20,K$1) -> 0.0060988821 | ... P8: =TREND($H$18:$H$20,$A$18:$A$20,P$1) -> 0.0096764766 | Q8: =Q32/Q$39 -> 0.010416667 | R8: =TREND($H$20:$H$21,$A$20:$A$21,R$1) -> 0.013285664 | S8: =TREND($H$20:$H$21,$A$20:$A$21,S$1) -> 0.016154661 | T8: =TREND($H$20:$H$21,$A$20:$A$21,T$1) -> 0.019023658 | U8: =TREND($H$20:$H$21,$A$20:$A$21,U$1) -> 0.021892655 | V8: =TREND($H$20:$H$21,$A$20:$A$21,V$1) -> 0.024761653 | W8: =TREND($H$20:$H$21,$A$20:$A$21,W$1) -> 0.02763065 | X8: =TREND($H$20:$H$21,$A$20:$A$21,X$1) -> 0.030499647 | Y8: =TREND($H$20:$H$21,$A$20:$A$21,Y$1) -> 0.033368644 | ... AJ8: =TREND($H$20:$H$21,$A$20:$A$21,AJ$1) -> 0.064927613 | AK8: =R32/R$39 -> 0.06779661
A9: biomass | B9: =B33/B$39 -> 0.010877521 | C9: =C33/C$39 -> 0.012240957 | D9: =TREND($I$18:$I$20,$A$18:$A$20,D$1) -> 0.012510052 | E9: =TREND($I$18:$I$20,$A$18:$A$20,E$1) -> 0.013152218 | F9: =TREND($I$18:$I$20,$A$18:$A$20,F$1) -> 0.013794383 | G9: =TREND($I$18:$I$20,$A$18:$A$20,G$1) -> 0.014436549 | H9: =TREND($I$18:$I$20,$A$18:$A$20,H$1) -> 0.015078714 | I9: =TREND($I$18:$I$20,$A$18:$A$20,I$1) -> 0.01572088 | J9: =TREND($I$18:$I$20,$A$18:$A$20,J$1) -> 0.016363046 | K9: =TREND($I$18:$I$20,$A$18:$A$20,K$1) -> 0.017005211 | ... P9: =TREND($I$18:$I$20,$A$18:$A$20,P$1) -> 0.020216039 | Q9: =Q33/Q$39 -> 0.020833333 | R9: =TREND($I$20:$I$21,$A$20:$A$21,R$1) -> 0.023181497 | S9: =TREND($I$20:$I$21,$A$20:$A$21,S$1) -> 0.025529661 | T9: =TREND($I$20:$I$21,$A$20:$A$21,T$1) -> 0.027877825 | U9: =TREND($I$20:$I$21,$A$20:$A$21,U$1) -> 0.030225989 | V9: =TREND($I$20:$I$21,$A$20:$A$21,V$1) -> 0.032574153 | W9: =TREND($I$20:$I$21,$A$20:$A$21,W$1) -> 0.034922316 | X9: =TREND($I$20:$I$21,$A$20:$A$21,X$1) -> 0.03727048 | Y9: =TREND($I$20:$I$21,$A$20:$A$21,Y$1) -> 0.039618644 | ... AJ9: =TREND($I$20:$I$21,$A$20:$A$21,AJ$1) -> 0.065448446 | AK9: =R33/R$39 -> 0.06779661
A10: geothermal | B10: =B34/B$39 -> 2.1332824e-05 | C10: =C34/C$39 -> 2.0103263e-05 | D10: =TREND($J$18:$J$20,$A$18:$A$20,D$1) -> 1.8572437e-05 | E10: =TREND($J$18:$J$20,$A$18:$A$20,E$1) -> 1.7144314e-05 | F10: =TREND($J$18:$J$20,$A$18:$A$20,F$1) -> 1.5716192e-05 | G10: =TREND($J$18:$J$20,$A$18:$A$20,G$1) -> 1.428807e-05 | H10: =TREND($J$18:$J$20,$A$18:$A$20,H$1) -> 1.2859947e-05 | I10: =TREND($J$18:$J$20,$A$18:$A$20,I$1) -> 1.1431825e-05 | J10: =TREND($J$18:$J$20,$A$18:$A$20,J$1) -> 1.0003703e-05 | K10: =TREND($J$18:$J$20,$A$18:$A$20,K$1) -> 8.5755806e-06 | ... P10: =TREND($J$18:$J$20,$A$18:$A$20,P$1) -> 1.4349692e-06 | Q10: =Q34/Q$39 -> 0 | R10: =TREND($J$20:$J$21,$A$20:$A$21,R$1) -> 0 | S10: =TREND($J$20:$J$21,$A$20:$A$21,S$1) -> 0 | T10: =TREND($J$20:$J$21,$A$20:$A$21,T$1) -> 0 | U10: =TREND($J$20:$J$21,$A$20:$A$21,U$1) -> 0 | V10: =TREND($J$20:$J$21,$A$20:$A$21,V$1) -> 0 | W10: =TREND($J$20:$J$21,$A$20:$A$21,W$1) -> 0 | X10: =TREND($J$20:$J$21,$A$20:$A$21,X$1) -> 0 | Y10: =TREND($J$20:$J$21,$A$20:$A$21,Y$1) -> 0 | ... AJ10: =TREND($J$20:$J$21,$A$20:$A$21,AJ$1) -> 0 | AK10: =R34/R$39 -> 0
A11: petroleum | B11: =B35/B$39 -> 0.0016518432 | C11: =C35/C$39 -> 0.0016672842 | D11: =TREND($K$18:$K$20,$A$18:$A$20,D$1) -> 0.0014863457 | E11: =TREND($K$18:$K$20,$A$18:$A$20,E$1) -> 0.0013723547 | F11: =TREND($K$18:$K$20,$A$18:$A$20,F$1) -> 0.0012583638 | G11: =TREND($K$18:$K$20,$A$18:$A$20,G$1) -> 0.0011443728 | H11: =TREND($K$18:$K$20,$A$18:$A$20,H$1) -> 0.0010303818 | I11: =TREND($K$18:$K$20,$A$18:$A$20,I$1) -> 0.00091639087 | J11: =TREND($K$18:$K$20,$A$18:$A$20,J$1) -> 0.00080239991 | K11: =TREND($K$18:$K$20,$A$18:$A$20,K$1) -> 0.00068840895 | ... P11: =TREND($K$18:$K$20,$A$18:$A$20,P$1) -> 0.00011845414 | Q11: =Q35/Q$39 -> 0 | R11: =TREND($K$20:$K$21,$A$20:$A$21,R$1) -> 0 | S11: =TREND($K$20:$K$21,$A$20:$A$21,S$1) -> 0 | T11: =TREND($K$20:$K$21,$A$20:$A$21,T$1) -> 0 | U11: =TREND($K$20:$K$21,$A$20:$A$21,U$1) -> 0 | V11: =TREND($K$20:$K$21,$A$20:$A$21,V$1) -> 0 | W11: =TREND($K$20:$K$21,$A$20:$A$21,W$1) -> 0 | X11: =TREND($K$20:$K$21,$A$20:$A$21,X$1) -> 0 | Y11: =TREND($K$20:$K$21,$A$20:$A$21,Y$1) -> 0 | ... AJ11: =TREND($K$20:$K$21,$A$20:$A$21,AJ$1) -> 0 | AK11: =R35/R$39 -> 0
A12: natural gas peaker | B12: =B36/B$39 -> 0.024805125 | C12: =C36/C$39 -> 0.027418921 | D12: =TREND($L$18:$L$20,$A$18:$A$20,D$1) -> 0.029875061 | E12: =TREND($L$18:$L$20,$A$18:$A$20,E$1) -> 0.032384947 | F12: =TREND($L$18:$L$20,$A$18:$A$20,F$1) -> 0.034894833 | G12: =TREND($L$18:$L$20,$A$18:$A$20,G$1) -> 0.03740472 | H12: =TREND($L$18:$L$20,$A$18:$A$20,H$1) -> 0.039914606 | I12: =TREND($L$18:$L$20,$A$18:$A$20,I$1) -> 0.042424492 | J12: =TREND($L$18:$L$20,$A$18:$A$20,J$1) -> 0.044934379 | K12: =TREND($L$18:$L$20,$A$18:$A$20,K$1) -> 0.047444265 | ... P12: =TREND($L$18:$L$20,$A$18:$A$20,P$1) -> 0.059993697 | Q12: =Q36/Q$39 -> 0.0625 | R12: =TREND($L$20:$L$21,$A$20:$A$21,R$1) -> 0.061493644 | S12: =TREND($L$20:$L$21,$A$20:$A$21,S$1) -> 0.060487288 | T12: =TREND($L$20:$L$21,$A$20:$A$21,T$1) -> 0.059480932 | U12: =TREND($L$20:$L$21,$A$20:$A$21,U$1) -> 0.058474576 | V12: =TREND($L$20:$L$21,$A$20:$A$21,V$1) -> 0.05746822 | W12: =TREND($L$20:$L$21,$A$20:$A$21,W$1) -> 0.056461864 | X12: =TREND($L$20:$L$21,$A$20:$A$21,X$1) -> 0.055455508 | Y12: =TREND($L$20:$L$21,$A$20:$A$21,Y$1) -> 0.054449153 | ... AJ12: =TREND($L$20:$L$21,$A$20:$A$21,AJ$1) -> 0.043379237 | AK12: =R36/R$39 -> 0.042372881
A13: lignite | B13: =B37/B$39 -> 0 | C13: =C37/C$39 -> 0 | D13: =TREND($M$18:$M$20,$A$18:$A$20,D$1) -> 0 | E13: =TREND($M$18:$M$20,$A$18:$A$20,E$1) -> 0 | F13: =TREND($M$18:$M$20,$A$18:$A$20,F$1) -> 0 | G13: =TREND($M$18:$M$20,$A$18:$A$20,G$1) -> 0 | H13: =TREND($M$18:$M$20,$A$18:$A$20,H$1) -> 0 | I13: =TREND($M$18:$M$20,$A$18:$A$20,I$1) -> 0 | J13: =TREND($M$18:$M$20,$A$18:$A$20,J$1) -> 0 | K13: =TREND($M$18:$M$20,$A$18:$A$20,K$1) -> 0 | ... P13: =TREND($M$18:$M$20,$A$18:$A$20,P$1) -> 0 | Q13: =Q37/Q$39 -> 0 | R13: =TREND($M$20:$M$21,$A$20:$A$21,R$1) -> 0 | S13: =TREND($M$20:$M$21,$A$20:$A$21,S$1) -> 0 | T13: =TREND($M$20:$M$21,$A$20:$A$21,T$1) -> 0 | U13: =TREND($M$20:$M$21,$A$20:$A$21,U$1) -> 0 | V13: =TREND($M$20:$M$21,$A$20:$A$21,V$1) -> 0 | W13: =TREND($M$20:$M$21,$A$20:$A$21,W$1) -> 0 | X13: =TREND($M$20:$M$21,$A$20:$A$21,X$1) -> 0 | Y13: =TREND($M$20:$M$21,$A$20:$A$21,Y$1) -> 0 | ... AJ13: =TREND($M$20:$M$21,$A$20:$A$21,AJ$1) -> 0 | AK13: =R37/R$39 -> 0
A14: offshore wind | B14: =B38/B$39 -> 0 | C14: =C38/C$39 -> 0 | D14: =TREND($N$18:$N$20,$A$18:$A$20,D$1) -> 0 | E14: =TREND($N$18:$N$20,$A$18:$A$20,E$1) -> 0 | F14: =TREND($N$18:$N$20,$A$18:$A$20,F$1) -> 0 | G14: =TREND($N$18:$N$20,$A$18:$A$20,G$1) -> 0 | H14: =TREND($N$18:$N$20,$A$18:$A$20,H$1) -> 0 | I14: =TREND($N$18:$N$20,$A$18:$A$20,I$1) -> 0 | J14: =TREND($N$18:$N$20,$A$18:$A$20,J$1) -> 0 | K14: =TREND($N$18:$N$20,$A$18:$A$20,K$1) -> 0 | ... P14: =TREND($N$18:$N$20,$A$18:$A$20,P$1) -> 0 | Q14: 0 | R14: =TREND($N$20:$N$21,$A$20:$A$21,R$1) -> 0 | S14: =TREND($N$20:$N$21,$A$20:$A$21,S$1) -> 0 | T14: =TREND($N$20:$N$21,$A$20:$A$21,T$1) -> 0 | U14: =TREND($N$20:$N$21,$A$20:$A$21,U$1) -> 0 | V14: =TREND($N$20:$N$21,$A$20:$A$21,V$1) -> 0 | W14: =TREND($N$20:$N$21,$A$20:$A$21,W$1) -> 0 | X14: =TREND($N$20:$N$21,$A$20:$A$21,X$1) -> 0 | Y14: =TREND($N$20:$N$21,$A$20:$A$21,Y$1) -> 0 | ... AJ14: =TREND($N$20:$N$21,$A$20:$A$21,AJ$1) -> 0 | AK14: 0
A16: Transposed for TREND function
A17: {=TRANSPOSE(A1:C14)} -> Fuel Type | B17: hard coal | C17: natural gas nonpeaker | D17: nuclear | E17: hydro | F17: onshore wind | G17: solar PV | H17: solar thermal | I17: biomass | J17: geothermal | K17: petroleum | L17: natural gas peaker | M17: lignite | N17: offshore wind
A18: 2015 | B18: 0.70125155 | C18: 0 | D18: 0.029147293 | E18: 0.1928948 | F18: 0.031703307 | G18: 0.0076426121 | H18: 4.6078899e-06 | I18: 0.010877521 | J18: 2.1332824e-05 | K18: 0.0016518432 | L18: 0.024805125 | M18: 0 | N18: 0
A19: 2016 | B19: 0.68218992 | C19: 0 | D19: 0.034302118 | E19: 0.19192569 | F19: 0.038127206 | G19: 0.012103129 | H19: 4.6639571e-06 | I19: 0.012240957 | J19: 2.0103263e-05 | K19: 0.0016672842 | L19: 0.027418921 | M19: 0 | N19: 0
A20: {=TRANSPOSE(Q1:Q14)} -> 2030 | B20: 0.46875 | C20: 0 | D20: 0.10416667 | E20: 0.17708333 | F20: 0.11458333 | G20: 0.041666667 | H20: 0.010416667 | I20: 0.020833333 | J20: 0 | K20: 0 | L20: 0.0625 | M20: 0 | N20: 0 | O20: #N/A
A21: {=TRANSPOSE(AK1:AK14)} -> 2050 | B21: 0.1440678 | C21: 0 | D21: 0.15254237 | E21: 0.16949153 | F21: 0.22033898 | G21: 0.13559322 | H21: 0.06779661 | I21: 0.06779661 | J21: 0 | K21: 0 | L21: 0.042372881 | M21: 0 | N21: 0 | O21: #N/A
A23: Draft Area:
A24: 1.From IEA: China's Electricity generation by fuel type, original data (in quantity) | P24: 2.1 Electricity Mix Data, in quantity, from the book (scanning pages are shown below)
A25: Fuel Type | B25: 2015 | C25: 2016 | D25: unit:GWh | P25: Fuel Type | Q25: 2030 | R25: 2050 | S25: unit:*10^12kWh
A26: hard coal | B26: 4108994 | C26: 4241786 | P26: hard coal | Q26: 4.5 | R26: 1.7
A27: natural gas nonpeaker | B27: 0 | C27: 0 | P27: natural gas nonpeaker | Q27: 0 | R27: 0
A28: nuclear | B28: 170789 | C28: 213287 | P28: nuclear | Q28: 1 | R28: 1.8
A29: hydro | B29: 1130270 | C29: 1193374 | P29: hydro | Q29: 1.7 | R29: 2
A30: onshore wind | B30: 185766 | C30: 237071 | P30: onshore wind | Q30: 1 | R30: 2.4
A31: solar PV | B31: 44782 | C31: 75256 | P31: solar PV | Q31: 0.4 | R31: 1.6
A32: solar thermal | B32: 27 | C32: 29 | P32: solar thermal | Q32: 0.1 | R32: 0.8
A33: biomass | B33: =52700+11029+8 -> 63737 | C33: =64700+11413 -> 76113 | P33: biomass | Q33: 0.2 | R33: 0.8
A34: geothermal | B34: 125 | C34: 125 | P34: geothermal | Q34: 0 | R34: 0
A35: petroleum | B35: 9679 | C35: 10367 | P35: petroleum | Q35: 0 | R35: 0
A36: natural gas peaker | B36: 145346 | C36: 170488 | P36: natural gas peaker | Q36: 0.6 | R36: 0.5
A37: lignite | B37: 0 | C37: 0 | P37: lignite | Q37: 0 | R37: 0
A38: offshore wind | B38: 0 | C38: 0 | P38: offshore wind | Q38: 0.1 | R38: 0.2
A39: SUM | B39: =SUM(B26:B38) -> 5859515 | C39: =SUM(C26:C38) -> 6217896 | P39: SUM | Q39: =SUM(Q26:Q38) -> 9.6 | R39: =SUM(R26:R38) -> 11.8
A41: 2. Scanning version of the page with the needed future-prediction data in the book: China Energy & Electricity Outlook 2017 (in Chinese)

Sheet China Capacity(not used)
A1: Electricity Capacity (Quantity, *10^8kW) | B1: 常规转型情景Baseline Transition Scenario | I1: 电气化加速情景 Accelerated Electrification Scenario
A2: Year | B2: 2020 | C2: 2025 | D2: 2030 | E2: 2035 | F2: 2040 | G2: 2045 | H2: 2050 | I2: 2020 | J2: 2025 | K2: 2030 | L2: 2035 | M2: 2040 | N2: 2045 | O2: 2050
A3: 煤电Coal | B3: 10.3 | C3: 11.6 | D3: 11.7 | E3: 11.5 | F3: 10.1 | G3: 8.6 | H3: 7.3 | I3: 10.7 | J3: 12 | K3: 12.7 | L3: 12 | M3: 9.9 | N3: 8.4 | O3: 7
A4: 气电Gas | B4: 1.1 | C4: 1.3 | D4: 1.6 | E4: 1.6 | F4: 1.7 | G4: 1.8 | H4: 1.8 | I4: 1.1 | J4: 1.2 | K4: 1.8 | L4: 2.7 | M4: 3.6 | N4: 3.7 | O4: 3.7
A5: 核电Nuclear | B5: 0.6 | C5: 0.9 | D5: 1.2 | E5: 1.6 | F5: 1.9 | G5: 2.1 | H5: 2.2 | I5: 0.6 | J5: 0.9 | K5: 1.2 | L5: 1.6 | M5: 1.9 | N5: 2.1 | O5: 2.2
A6: 水电Hydropower | B6: 3.2 | C6: 4.1 | D6: 4.6 | E6: 4.9 | F6: 5.1 | G6: 5.3 | H6: 5.4 | I6: 3.3 | J6: 4.1 | K6: 4.6 | L6: 4.9 | M6: 5.1 | N6: 5.3 | O6: 5.4
A7: 陆上风电Onshore Wind | B7: 2.1 | C7: 2.6 | D7: 4.5 | E7: 6.6 | F7: 8.3 | G7: 9.1 | H7: 10.2 | I7: 2.9 | J7: 4.3 | K7: 6.8 | L7: 7.9 | M7: 9.4 | N7: 11 | O7: 12.1
A8: 光伏发电Solar PV | B8: 2.1 | C8: 2.7 | D8: 3.2 | E8: 4.8 | F8: 7.4 | G8: 11 | H8: 11.7 | I8: 2.4 | J8: 4.9 | K8: 6.9 | L8: 12.1 | M8: 15.8 | N8: 18.9 | O8: 20
A9: 光热发电Concentrating solar power | B9: 0 | C9: 0.2 | D9: 0.3 | E9: 0.5 | F9: 1 | G9: 1.5 | H9: 2 | I9: 0.1 | J9: 0.2 | K9: 0.4 | L9: 0.7 | M9: 1.1 | N9: 1.8 | O9: 2.7
A10: 海上风电Offshore Wind | B10: 0.1 | C10: 0.2 | D10: 0.2 | E10: 0.2 | F10: 0.3 | G10: 0.6 | H10: 0.7 | I10: 0.1 | J10: 0.3 | K10: 0.4 | L10: 0.7 | M10: 1 | N10: 1.3 | O10: 1.6
A11: 生物质及其他Biomass&Others | B11: 0.3 | C11: 0.3 | D11: 0.3 | E11: 0.4 | F11: 0.5 | G11: 0.7 | H11: 1.3 | I11: 0.3 | J11: 0.4 | K11: 0.5 | L11: 0.6 | M11: 0.7 | N11: 1.1 | O11: 1.5
A12: 抽水蓄能Pumped-storage power | B12: 0.4 | C12: 0.5 | D12: 1 | E12: 1.3 | F12: 1.6 | G12: 1.6 | H12: 1.6 | I12: 0.4 | J12: 0.7 | K12: 1 | L12: 1.3 | M12: 1.4 | N12: 1.5 | O12: 1.6
A13: 合计 | B13: =SUM(B3:B12) -> 20.2 | C13: =SUM(C3:C12) -> 24.4 | D13: =SUM(D3:D12) -> 28.6 | E13: =SUM(E3:E12) -> 33.4 | F13: =SUM(F3:F12) -> 37.9 | G13: =SUM(G3:G12) -> 42.3 | H13: =SUM(H3:H12) -> 44.2 | I13: =SUM(I3:I12) -> 21.9 | ... O13: =SUM(O3:O12) -> 57.8

Sheet Unit Conversion
A1: From IEA Unit Convertor:
B2: 1TJ= | C2: 2.388459e-05 | D2: Mtoe
C3: 0.27777778 | D3: GWh
C4: =C3*1000 -> 277.77778 | D4: MWh
C5: 947.81712 | D5: MBtu
C6: 3.4120842e-05 | D6: Mtce
C7: 238.8459 | D7: Gcal

Sheet EIaE-BIE
B1: 2016 | C1: 2017 | D1: 2018 | E1: 2019 | F1: 2020 | G1: 2021 | H1: 2022 | I1: 2023 | J1: 2024 | K1: 2025 | L1: 2026 | M1: 2027 | N1: 2028 | O1: 2029 | P1: 2030 | Q1: 2031 | R1: 2032 | S1: 2033 | T1: 2034 | U1: 2035 | V1: 2036 | W1: 2037 | X1: 2038 | Y1: 2039 | Z1: 2040 | AA1: 2041 | AB1: 2042 | AC1: 2043 | AD1: 2044 | AE1: 2045 | AF1: 2046 | AG1: 2047 | AH1: 2048 | AI1: 2049 | AJ1: 2050
A2: hard coal | B2: 0 | C2: ='HK I&E Projection'!M$4*'Imported Mix'!D2*'Unit Conversion'!$C$3*10^3 -> 0 | D2: ='HK I&E Projection'!N$4*'Imported Mix'!E2*'Unit Conversion'!$C$3*10^3 -> 0 | E2: ='HK I&E Projection'!O$4*'Imported Mix'!F2*'Unit Conversion'!$C$3*10^3 -> 0 | F2: ='HK I&E Projection'!P$4*'Imported Mix'!G2*'Unit Conversion'!$C$3*10^3 -> 0 | G2: ='HK I&E Projection'!Q$4*'Imported Mix'!H2*'Unit Conversion'!$C$3*10^3 -> 0 | H2: ='HK I&E Projection'!R$4*'Imported Mix'!I2*'Unit Conversion'!$C$3*10^3 -> 0 | I2: ='HK I&E Projection'!S$4*'Imported Mix'!J2*'Unit Conversion'!$C$3*10^3 -> 0 | J2: ='HK I&E Projection'!T$4*'Imported Mix'!K2*'Unit Conversion'!$C$3*10^3 -> 0 | ... AJ2: ='HK I&E Projection'!AT$4*'Imported Mix'!AK2*'Unit Conversion'!$C$3*10^3 -> 0
A3: natural gas nonpeaker | B3: 0 | C3: ='HK I&E Projection'!M$4*'Imported Mix'!D3*'Unit Conversion'!$C$3*10^3 -> 0 | D3: ='HK I&E Projection'!N$4*'Imported Mix'!E3*'Unit Conversion'!$C$3*10^3 -> 0 | E3: ='HK I&E Projection'!O$4*'Imported Mix'!F3*'Unit Conversion'!$C$3*10^3 -> 0 | F3: ='HK I&E Projection'!P$4*'Imported Mix'!G3*'Unit Conversion'!$C$3*10^3 -> 0 | G3: ='HK I&E Projection'!Q$4*'Imported Mix'!H3*'Unit Conversion'!$C$3*10^3 -> 0 | H3: ='HK I&E Projection'!R$4*'Imported Mix'!I3*'Unit Conversion'!$C$3*10^3 -> 0 | I3: ='HK I&E Projection'!S$4*'Imported Mix'!J3*'Unit Conversion'!$C$3*10^3 -> 0 | J3: ='HK I&E Projection'!T$4*'Imported Mix'!K3*'Unit Conversion'!$C$3*10^3 -> 0 | ... AJ3: ='HK I&E Projection'!AT$4*'Imported Mix'!AK3*'Unit Conversion'!$C$3*10^3 -> 0
A4: nuclear | B4: ='HK I&E Projection'!L$4*'Imported Mix'!C4*'Unit Conversion'!$C$3*10^3 -> 11620833 | C4: ='HK I&E Projection'!M$4*'Imported Mix'!D4*'Unit Conversion'!$C$3*10^3 -> 12576111 | D4: ='HK I&E Projection'!N$4*'Imported Mix'!E4*'Unit Conversion'!$C$3*10^3 -> 12599167 | E4: ='HK I&E Projection'!O$4*'Imported Mix'!F4*'Unit Conversion'!$C$3*10^3 -> 12380833 | F4: ='HK I&E Projection'!P$4*'Imported Mix'!G4*'Unit Conversion'!$C$3*10^3 -> 12698889 | G4: ='HK I&E Projection'!Q$4*'Imported Mix'!H4*'Unit Conversion'!$C$3*10^3 -> 12554722 | H4: ='HK I&E Projection'!R$4*'Imported Mix'!I4*'Unit Conversion'!$C$3*10^3 -> 12347778 | I4: ='HK I&E Projection'!S$4*'Imported Mix'!J4*'Unit Conversion'!$C$3*10^3 -> 12530576 | ... AJ4: ='HK I&E Projection'!AT$4*'Imported Mix'!AK4*'Unit Conversion'!$C$3*10^3 -> 0
A5: hydro | B5: 0 | C5: ='HK I&E Projection'!M$4*'Imported Mix'!D5*'Unit Conversion'!$C$3*10^3 -> 0 | D5: ='HK I&E Projection'!N$4*'Imported Mix'!E5*'Unit Conversion'!$C$3*10^3 -> 0 | E5: ='HK I&E Projection'!O$4*'Imported Mix'!F5*'Unit Conversion'!$C$3*10^3 -> 0 | F5: ='HK I&E Projection'!P$4*'Imported Mix'!G5*'Unit Conversion'!$C$3*10^3 -> 0 | G5: ='HK I&E Projection'!Q$4*'Imported Mix'!H5*'Unit Conversion'!$C$3*10^3 -> 0 | H5: ='HK I&E Projection'!R$4*'Imported Mix'!I5*'Unit Conversion'!$C$3*10^3 -> 0 | I5: ='HK I&E Projection'!S$4*'Imported Mix'!J5*'Unit Conversion'!$C$3*10^3 -> 0 | J5: ='HK I&E Projection'!T$4*'Imported Mix'!K5*'Unit Conversion'!$C$3*10^3 -> 0 | ... AJ5: ='HK I&E Projection'!AT$4*'Imported Mix'!AK5*'Unit Conversion'!$C$3*10^3 -> 0
A6: onshore wind | B6: 0 | C6: ='HK I&E Projection'!M$4*'Imported Mix'!D6*'Unit Conversion'!$C$3*10^3 -> 0 | D6: ='HK I&E Projection'!N$4*'Imported Mix'!E6*'Unit Conversion'!$C$3*10^3 -> 0 | E6: ='HK I&E Projection'!O$4*'Imported Mix'!F6*'Unit Conversion'!$C$3*10^3 -> 0 | F6: ='HK I&E Projection'!P$4*'Imported Mix'!G6*'Unit Conversion'!$C$3*10^3 -> 0 | G6: ='HK I&E Projection'!Q$4*'Imported Mix'!H6*'Unit Conversion'!$C$3*10^3 -> 0 | H6: ='HK I&E Projection'!R$4*'Imported Mix'!I6*'Unit Conversion'!$C$3*10^3 -> 0 | I6: ='HK I&E Projection'!S$4*'Imported Mix'!J6*'Unit Conversion'!$C$3*10^3 -> 0 | J6: ='HK I&E Projection'!T$4*'Imported Mix'!K6*'Unit Conversion'!$C$3*10^3 -> 0 | ... AJ6: ='HK I&E Projection'!AT$4*'Imported Mix'!AK6*'Unit Conversion'!$C$3*10^3 -> 16353394
A7: solar PV | B7: 0 | C7: ='HK I&E Projection'!M$4*'Imported Mix'!D7*'Unit Conversion'!$C$3*10^3 -> 0 | D7: ='HK I&E Projection'!N$4*'Imported Mix'!E7*'Unit Conversion'!$C$3*10^3 -> 0 | E7: ='HK I&E Projection'!O$4*'Imported Mix'!F7*'Unit Conversion'!$C$3*10^3 -> 0 | F7: ='HK I&E Projection'!P$4*'Imported Mix'!G7*'Unit Conversion'!$C$3*10^3 -> 0 | G7: ='HK I&E Projection'!Q$4*'Imported Mix'!H7*'Unit Conversion'!$C$3*10^3 -> 0 | H7: ='HK I&E Projection'!R$4*'Imported Mix'!I7*'Unit Conversion'!$C$3*10^3 -> 0 | I7: ='HK I&E Projection'!S$4*'Imported Mix'!J7*'Unit Conversion'!$C$3*10^3 -> 0 | J7: ='HK I&E Projection'!T$4*'Imported Mix'!K7*'Unit Conversion'!$C$3*10^3 -> 0 | ... AJ7: ='HK I&E Projection'!AT$4*'Imported Mix'!AK7*'Unit Conversion'!$C$3*10^3 -> 0
A8: solar thermal | B8: 0 | C8: ='HK I&E Projection'!M$4*'Imported Mix'!D8*'Unit Conversion'!$C$3*10^3 -> 0 | D8: ='HK I&E Projection'!N$4*'Imported Mix'!E8*'Unit Conversion'!$C$3*10^3 -> 0 | E8: ='HK I&E Projection'!O$4*'Imported Mix'!F8*'Unit Conversion'!$C$3*10^3 -> 0 | F8: ='HK I&E Projection'!P$4*'Imported Mix'!G8*'Unit Conversion'!$C$3*10^3 -> 0 | G8: ='HK I&E Projection'!Q$4*'Imported Mix'!H8*'Unit Conversion'!$C$3*10^3 -> 0 | H8: ='HK I&E Projection'!R$4*'Imported Mix'!I8*'Unit Conversion'!$C$3*10^3 -> 0 | I8: ='HK I&E Projection'!S$4*'Imported Mix'!J8*'Unit Conversion'!$C$3*10^3 -> 0 | J8: ='HK I&E Projection'!T$4*'Imported Mix'!K8*'Unit Conversion'!$C$3*10^3 -> 0 | ... AJ8: ='HK I&E Projection'!AT$4*'Imported Mix'!AK8*'Unit Conversion'!$C$3*10^3 -> 0
A9: biomass | B9: 0 | C9: ='HK I&E Projection'!M$4*'Imported Mix'!D9*'Unit Conversion'!$C$3*10^3 -> 0 | D9: ='HK I&E Projection'!N$4*'Imported Mix'!E9*'Unit Conversion'!$C$3*10^3 -> 0 | E9: ='HK I&E Projection'!O$4*'Imported Mix'!F9*'Unit Conversion'!$C$3*10^3 -> 0 | F9: ='HK I&E Projection'!P$4*'Imported Mix'!G9*'Unit Conversion'!$C$3*10^3 -> 0 | G9: ='HK I&E Projection'!Q$4*'Imported Mix'!H9*'Unit Conversion'!$C$3*10^3 -> 0 | H9: ='HK I&E Projection'!R$4*'Imported Mix'!I9*'Unit Conversion'!$C$3*10^3 -> 0 | I9: ='HK I&E Projection'!S$4*'Imported Mix'!J9*'Unit Conversion'!$C$3*10^3 -> 0 | J9: ='HK I&E Projection'!T$4*'Imported Mix'!K9*'Unit Conversion'!$C$3*10^3 -> 0 | ... AJ9: ='HK I&E Projection'!AT$4*'Imported Mix'!AK9*'Unit Conversion'!$C$3*10^3 -> 0
A10: geothermal | B10: 0 | C10: ='HK I&E Projection'!M$4*'Imported Mix'!D10*'Unit Conversion'!$C$3*10^3 -> 0 | D10: ='HK I&E Projection'!N$4*'Imported Mix'!E10*'Unit Conversion'!$C$3*10^3 -> 0 | E10: ='HK I&E Projection'!O$4*'Imported Mix'!F10*'Unit Conversion'!$C$3*10^3 -> 0 | F10: ='HK I&E Projection'!P$4*'Imported Mix'!G10*'Unit Conversion'!$C$3*10^3 -> 0 | G10: ='HK I&E Projection'!Q$4*'Imported Mix'!H10*'Unit Conversion'!$C$3*10^3 -> 0 | H10: ='HK I&E Projection'!R$4*'Imported Mix'!I10*'Unit Conversion'!$C$3*10^3 -> 0 | I10: ='HK I&E Projection'!S$4*'Imported Mix'!J10*'Unit Conversion'!$C$3*10^3 -> 0 | J10: ='HK I&E Projection'!T$4*'Imported Mix'!K10*'Unit Conversion'!$C$3*10^3 -> 0 | ... AJ10: ='HK I&E Projection'!AT$4*'Imported Mix'!AK10*'Unit Conversion'!$C$3*10^3 -> 0
A11: petroleum | B11: 0 | C11: ='HK I&E Projection'!M$4*'Imported Mix'!D11*'Unit Conversion'!$C$3*10^3 -> 0 | D11: ='HK I&E Projection'!N$4*'Imported Mix'!E11*'Unit Conversion'!$C$3*10^3 -> 0 | E11: ='HK I&E Projection'!O$4*'Imported Mix'!F11*'Unit Conversion'!$C$3*10^3 -> 0 | F11: ='HK I&E Projection'!P$4*'Imported Mix'!G11*'Unit Conversion'!$C$3*10^3 -> 0 | G11: ='HK I&E Projection'!Q$4*'Imported Mix'!H11*'Unit Conversion'!$C$3*10^3 -> 0 | H11: ='HK I&E Projection'!R$4*'Imported Mix'!I11*'Unit Conversion'!$C$3*10^3 -> 0 | I11: ='HK I&E Projection'!S$4*'Imported Mix'!J11*'Unit Conversion'!$C$3*10^3 -> 0 | J11: ='HK I&E Projection'!T$4*'Imported Mix'!K11*'Unit Conversion'!$C$3*10^3 -> 0 | ... AJ11: ='HK I&E Projection'!AT$4*'Imported Mix'!AK11*'Unit Conversion'!$C$3*10^3 -> 0
A12: natural gas peaker | B12: 0 | C12: ='HK I&E Projection'!M$4*'Imported Mix'!D12*'Unit Conversion'!$C$3*10^3 -> 0 | D12: ='HK I&E Projection'!N$4*'Imported Mix'!E12*'Unit Conversion'!$C$3*10^3 -> 0 | E12: ='HK I&E Projection'!O$4*'Imported Mix'!F12*'Unit Conversion'!$C$3*10^3 -> 0 | F12: ='HK I&E Projection'!P$4*'Imported Mix'!G12*'Unit Conversion'!$C$3*10^3 -> 0 | G12: ='HK I&E Projection'!Q$4*'Imported Mix'!H12*'Unit Conversion'!$C$3*10^3 -> 0 | H12: ='HK I&E Projection'!R$4*'Imported Mix'!I12*'Unit Conversion'!$C$3*10^3 -> 0 | I12: ='HK I&E Projection'!S$4*'Imported Mix'!J12*'Unit Conversion'!$C$3*10^3 -> 0 | J12: ='HK I&E Projection'!T$4*'Imported Mix'!K12*'Unit Conversion'!$C$3*10^3 -> 0 | ... AJ12: ='HK I&E Projection'!AT$4*'Imported Mix'!AK12*'Unit Conversion'!$C$3*10^3 -> 0
A13: lignite | B13: 0 | C13: ='HK I&E Projection'!M$4*'Imported Mix'!D13*'Unit Conversion'!$C$3*10^3 -> 0 | D13: ='HK I&E Projection'!N$4*'Imported Mix'!E13*'Unit Conversion'!$C$3*10^3 -> 0 | E13: ='HK I&E Projection'!O$4*'Imported Mix'!F13*'Unit Conversion'!$C$3*10^3 -> 0 | F13: ='HK I&E Projection'!P$4*'Imported Mix'!G13*'Unit Conversion'!$C$3*10^3 -> 0 | G13: ='HK I&E Projection'!Q$4*'Imported Mix'!H13*'Unit Conversion'!$C$3*10^3 -> 0 | H13: ='HK I&E Projection'!R$4*'Imported Mix'!I13*'Unit Conversion'!$C$3*10^3 -> 0 | I13: ='HK I&E Projection'!S$4*'Imported Mix'!J13*'Unit Conversion'!$C$3*10^3 -> 0 | J13: ='HK I&E Projection'!T$4*'Imported Mix'!K13*'Unit Conversion'!$C$3*10^3 -> 0 | ... AJ13: ='HK I&E Projection'!AT$4*'Imported Mix'!AK13*'Unit Conversion'!$C$3*10^3 -> 0
A14: offshore wind | B14: 0 | C14: ='HK I&E Projection'!M$4*'Imported Mix'!D14*'Unit Conversion'!$C$3*10^3 -> 0 | D14: ='HK I&E Projection'!N$4*'Imported Mix'!E14*'Unit Conversion'!$C$3*10^3 -> 0 | E14: ='HK I&E Projection'!O$4*'Imported Mix'!F14*'Unit Conversion'!$C$3*10^3 -> 0 | F14: ='HK I&E Projection'!P$4*'Imported Mix'!G14*'Unit Conversion'!$C$3*10^3 -> 0 | G14: ='HK I&E Projection'!Q$4*'Imported Mix'!H14*'Unit Conversion'!$C$3*10^3 -> 0 | H14: ='HK I&E Projection'!R$4*'Imported Mix'!I14*'Unit Conversion'!$C$3*10^3 -> 0 | I14: ='HK I&E Projection'!S$4*'Imported Mix'!J14*'Unit Conversion'!$C$3*10^3 -> 0 | J14: ='HK I&E Projection'!T$4*'Imported Mix'!K14*'Unit Conversion'!$C$3*10^3 -> 0 | ... AJ14: ='HK I&E Projection'!AT$4*'Imported Mix'!AK14*'Unit Conversion'!$C$3*10^3 -> 0

Sheet EIaE-BEE
B1: 2016 | C1: 2017 | D1: 2018 | E1: 2019 | F1: 2020 | G1: 2021 | H1: 2022 | I1: 2023 | J1: 2024 | K1: 2025 | L1: 2026 | M1: 2027 | N1: 2028 | O1: 2029 | P1: 2030 | Q1: 2031 | R1: 2032 | S1: 2033 | T1: 2034 | U1: 2035 | V1: 2036 | W1: 2037 | X1: 2038 | Y1: 2039 | Z1: 2040 | AA1: 2041 | AB1: 2042 | AC1: 2043 | AD1: 2044 | AE1: 2045 | AF1: 2046 | AG1: 2047 | AH1: 2048 | AI1: 2049 | AJ1: 2050
A2: Electricity Exports (MWh) | B2: =IF('HK I&E Projection'!L6>0,'HK I&E Projection'!L6*'Unit Conversion'!$C$3*10^3,0) -> 1205000 | C2: =IF('HK I&E Projection'!M6>0,'HK I&E Projection'!M6*'Unit Conversion'!$C$3*10^3,0) -> 1341111.1 | D2: =IF('HK I&E Projection'!N6>0,'HK I&E Projection'!N6*'Unit Conversion'!$C$3*10^3,0) -> 556111.11 | E2: =IF('HK I&E Projection'!O6>0,'HK I&E Projection'!O6*'Unit Conversion'!$C$3*10^3,0) -> 0 | F2: =IF('HK I&E Projection'!P6>0,'HK I&E Projection'!P6*'Unit Conversion'!$C$3*10^3,0) -> 0 | G2: =IF('HK I&E Projection'!Q6>0,'HK I&E Projection'!Q6*'Unit Conversion'!$C$3*10^3,0) -> 0 | H2: =IF('HK I&E Projection'!R6>0,'HK I&E Projection'!R6*'Unit Conversion'!$C$3*10^3,0) -> 0 | I2: =IF('HK I&E Projection'!S6>0,'HK I&E Projection'!S6*'Unit Conversion'!$C$3*10^3,0) -> 0 | ... AJ2: =IF('HK I&E Projection'!AT6>0,'HK I&E Projection'!AT6*'Unit Conversion'!$C$3*10^3,0) -> 0
