Workbook

Sheet About
A1: EoCPwEU Elasticity of Component Enerby Price wrt Energy Use
A3: Sources: | B3: Heating
B4: Residential Boilers | D4: Residential Furnaces | F4: Commercial Boilers | H4: Commercial Furnaces
B5: Technical Support Document: Energy Efficiency Program for Consumer Products: Residential Boilers | D5: Technical Support Document: Energy Efficiency Program for Consumer Products: Residential Furnaces | F5: Preliminary Technical Support Document: Energy Efficinecy Program for Consumer Products and Commercial and Industrial Equipment: Commercial Packaged Boilers | H5: Technical Support Document: Energy Efficiency Program for Consumer Products and Commercial and Industrial Equipment: Commercial Warm Air Furnaces
B6: 2015 | D6: 2015 | F6: 2014 | H6: 2015
B7: Table 8.2.5 | D7: Table 8.2.7 | F7: Table 8.2.3 | H7: Table 8.2.6
B8: https://www.regulations.gov/document?D=EERE-2012-BT-STD-0047-0070 | D8: https://www.regulations.gov/document?D=EERE-2014-BT-STD-0031-0027 | F8: https://www.regulations.gov/contentStreamer?documentId=EERE-2013-BT-STD-0030-0027&attachmentNumber=9&disposition=attachment&contentType=pdf | H8: https://www.regulations.gov/contentStreamer?documentId=EERE-2013-BT-STD-0021-0012&disposition=attachment&contentType=pdf
B10: Cooling
B11: Commercial Cooling (Packaged Air Conditioners and Heat Pumps) | D11: Commercial Cooling (Single Package Vertical Units) | F11: Residential Cooling
B12: Technical Support Document: Energy Efficiency Program for Consumer Products and Commercial and Industrial Equipment: Small, Large and Very Large Commercial Package Air Conditioning and Heating Equipment | D12: Technical Support Document: Energy Efficiency Program for Consumer Products and Commercial and Industrial Equipment: Single Package Vertical Units | F12: Technical Support Document: Energy Efficiency Program for Consumer Products: Residential Central Air Conditioners and Heat Pumps
B13: 2015 | D13: 2015 | F13: 2015
B14: Tables 5.6.5, 5.6.6, 5.6.7, and 8.2.8 | D14: Tables 5.8.1 and 8.2.4 | F14: Tables 5-13, 5-14, 5-15, 5-16, 5-17, 5-18, 5-19, 5-20, 5-21, 5-22, 5-23, 5-24, 5-25, 8.2.27, 8.2.28, 8.2.29, 8.2.30, 8.2.31, and 8.2.32
B15: http://www.regulations.gov/#%21documentDetail;D=EERE-2013-BT-STD-0007-0027 | D15: http://www.regulations.gov/#%21documentDetail;D=EERE-2013-BT-STD-0007-0027 | F15: http://www.regulations.gov/#%21documentDetail;D=EERE-2014-BT-STD-0048-0029
B18: Appliances
B19: Residential Water Heaters | D19: Residential Refrigerators and Freezers | F19: Residential Dishwashers | H19: Residential Clothes Washers
B20: Notice of Proposed Rulemaking Technical Support Document Energy Conservation Program for Consumer Products: Energy Conservation Standards for Residential Water Heaters, Direct Heating Equipment, and Pool Heaters | D20: Preliminary Technical Support Document: Energy Efficiency Standards for Consumer Products: Refrigerators, Refrigerator-Freezers, and Freezers | F20: Technical Support Document: Energy Efficiency Program for Consumer Products and Commercial and Industrial Equipment: Residential Dishwashers | H20: Technical Support Document: Energy Efficiency Program for Consumer Products and Commercial and Industrial Equipment: Residential Clothes Washers
B21: 2009 | D21: 2009 | F21: 2014 | H21: 2012
B22: Tables 8.2.13, 8.2.14, 8.12.15, and 8.12.16 | D22: Tables 8.2.6, 8.2.7, 8.2.8, and 8.2.9 | F22: Tables 8.2.6, and 8.2.7 | H22: Tables 8.2.7, 8.2.8, 8.2.9, 8.2.10, 8.4.1, 8.4.2, 8.4.3, and 8.4.4
B23: https://www.regulations.gov/contentStreamer?documentId=EERE-2006-STD-0129-0170&attachmentNumber=9&disposition=attachment&contentType=pdf | D23: https://www.regulations.gov/contentStreamer?documentId=EERE-2008-BT-STD-0012-0060&disposition=attachment&contentType=pdf | F23: https://www.regulations.gov/contentStreamer?documentId=EERE-2014-BT-STD-0021-0005&disposition=attachment&contentType=pdf | H23: https://www.regulations.gov/document?D=EERE-2008-BT-STD-0019-0047
B25: Residential Clothes Dryers | D25: Residential Ranges and Ovens | F25: Commercial Clothes Washers | H25: Commercial Refrigerators
B26: Technical Support Document: Energy Efficiency Program for Consumer Products and Commercial and Industrial Equipment: Residential Clothes Dryers and Room Air Conditioners | D26: Technical Support Document: Energy Efficiency Program for Consumer Products and Commercial and Industrial Equipment: Residential Conventional Ovens | F26: Technical Support Document: Energy Efficiency Program for Consumer Products and Commercial and Industrial Equipment: Commercial Clothes Washers | H26: Technical Support Document: Energy Efficiency Program for Consumer Products and Commercial and Industrial Equipment: Commercial Refrigeration Equipment
B27: 2011 | D27: 2015 | F27: 2014 | H27: 2014
B28: Tables 8.2.9, 8.2.10, 8.2.11, 8.2.12, 8.2.13, and 8.2.14 | D28: Tables 5.3.7, 5.3.8, 5.3.9, 5.3.10, 8.2.13, 8.2.14, 8.2.15, 8.2.16, 8.2.17, 8.2.18, 8.2.19, and 8.2.20 | F28: Tables 8.2.8 and 8.2.9 | H28: Tables 8.2.4 and 8.2.5
B29: https://www.regulations.gov/contentStreamer?documentId=EERE-2007-BT-STD-0010-0053&attachmentNumber=9&disposition=attachment&contentType=pdf | D29: https://www.regulations.gov/contentStreamer?documentId=EERE-2014-BT-STD-0005-0018&disposition=attachment&contentType=pdf | F29: https://www.regulations.gov/contentStreamer?documentId=EERE-2012-BT-STD-0020-0036&attachmentNumber=9&disposition=attachment&contentType=pdf | H29: https://www.regulations.gov/contentStreamer?documentId=EERE-2010-BT-STD-0003-0102&disposition=attachment&contentType=pdf
B31: Commercial Water Heaters
B32: Technical Support Document: Energy Efficiency Program for Consumer Products and Commercial and Industrial Equipment: Commercial Water Heating Equipment
B33: 2016
B34: Table 8.2.7
B35: https://www.regulations.gov/contentStreamer?documentId=EERE-2014-BT-STD-0042-0016&attachmentNumber=1&disposition=attachment&contentType=pdf
B37: Lighting
B38: All Lighting
B39: US Department of Energy
B40: 2014
B41: Energy Savings Forecast of Solid-State Lighting in General Illumination Applications
B42: Tables D.2, D.3, E.6, E.8, and E.9
B43: http://apps1.eere.energy.gov/buildings/publications/pdfs/ssl/energysavingsforecast14.pdf
B45: Other Equipment
B46: Residential Dehumidifiers | D46: Residential Pool Heaters | F46: Commercial Pumps | H46: Commercial Electric Motors
B47: Technical Support Document: Energy Efficiency Program for Consumer Products and Commercial and Industrial Equipment: Residential Dehumidifiers | D47: Technical Support Document: Energy Efficiency Program for Consumer Products and Commercial and Industrial Equipment: Pool Heaters, Direct Heating Equipment, and Water Heaters | F47: Technical Support Document: Energy Efficiency Program for Consumer Products and Commercial and Industrial Equipment: Pumps | H47: Technical Support Document: Energy Efficiency Program for Consumer Products and Commercial and Industrial Equipment: Electric Motors
B48: 2015 | D48: 2010 | F48: 2015 | H48: 2014
...

Sheet Heating
A1: Product Category | B1: Building Type | C1: Product | D1: Efficiency (AFUE) | E1: Price | F1: Elasticity | G1: % Improvement in Efficency from Base | H1: % Change in Price
A2: Heating | B2: Residential | C2: Non-Weatherized Gas Furnace | D2: 0.8 | E2: 1163.42 | F2: =IFERROR(H2/G2,"") | G2: {=(D2-MIN(IF($C$2:$C$98=C2,$D$2:$D$98)))/MIN(IF($C$2:$C$98=C2,$D$2:$D$98))} -> 0 | H2: {=(E2-MIN(IF($C$2:$C$98=C2,$E$2:$E$98)))/MIN(IF($C$2:$C$98=C2,$E$2:$E$98))} -> 0
A3: Heating | B3: Residential | C3: Non-Weatherized Gas Furnace | D3: 0.9 | E3: 1326.58 | F3: =IFERROR(H3/G3,"") -> 1.1219336 | G3: {=(D3-MIN(IF($C$2:$C$98=C3,$D$2:$D$98)))/MIN(IF($C$2:$C$98=C3,$D$2:$D$98))} -> 0.125 | H3: {=(E3-MIN(IF($C$2:$C$98=C3,$E$2:$E$98)))/MIN(IF($C$2:$C$98=C3,$E$2:$E$98))} -> 0.1402417
A4: Heating | B4: Residential | C4: Non-Weatherized Gas Furnace | D4: 0.92 | E4: 1342.61 | F4: =IFERROR(H4/G4,"") -> 1.0268003 | G4: {=(D4-MIN(IF($C$2:$C$98=C4,$D$2:$D$98)))/MIN(IF($C$2:$C$98=C4,$D$2:$D$98))} -> 0.15 | H4: {=(E4-MIN(IF($C$2:$C$98=C4,$E$2:$E$98)))/MIN(IF($C$2:$C$98=C4,$E$2:$E$98))} -> 0.15402004
A5: Heating | B5: Residential | C5: Non-Weatherized Gas Furnace | D5: 0.95 | E5: 1476.87 | F5: =IFERROR(H5/G5,"") -> 1.436913 | G5: {=(D5-MIN(IF($C$2:$C$98=C5,$D$2:$D$98)))/MIN(IF($C$2:$C$98=C5,$D$2:$D$98))} -> 0.1875 | H5: {=(E5-MIN(IF($C$2:$C$98=C5,$E$2:$E$98)))/MIN(IF($C$2:$C$98=C5,$E$2:$E$98))} -> 0.26942119
A6: Heating | B6: Residential | C6: Non-Weatherized Gas Furnace | D6: 0.98 | E6: 1669.18 | F6: =IFERROR(H6/G6,"") -> 1.9320815 | G6: {=(D6-MIN(IF($C$2:$C$98=C6,$D$2:$D$98)))/MIN(IF($C$2:$C$98=C6,$D$2:$D$98))} -> 0.225 | H6: {=(E6-MIN(IF($C$2:$C$98=C6,$E$2:$E$98)))/MIN(IF($C$2:$C$98=C6,$E$2:$E$98))} -> 0.43471833
A7: Heating | B7: Residential | C7: Mobile Home Gas Furnace | D7: 0.8 | E7: 816.32 | F7: =IFERROR(H7/G7,"") | G7: {=(D7-MIN(IF($C$2:$C$98=C7,$D$2:$D$98)))/MIN(IF($C$2:$C$98=C7,$D$2:$D$98))} -> 0 | H7: {=(E7-MIN(IF($C$2:$C$98=C7,$E$2:$E$98)))/MIN(IF($C$2:$C$98=C7,$E$2:$E$98))} -> 0
A8: Heating | B8: Residential | C8: Mobile Home Gas Furnace | D8: 0.92 | E8: 974.68 | F8: =IFERROR(H8/G8,"") -> 1.2932837 | G8: {=(D8-MIN(IF($C$2:$C$98=C8,$D$2:$D$98)))/MIN(IF($C$2:$C$98=C8,$D$2:$D$98))} -> 0.15 | H8: {=(E8-MIN(IF($C$2:$C$98=C8,$E$2:$E$98)))/MIN(IF($C$2:$C$98=C8,$E$2:$E$98))} -> 0.19399255
A9: Heating | B9: Residential | C9: Mobile Home Gas Furnace | D9: 0.95 | E9: 1117.93 | F9: =IFERROR(H9/G9,"") -> 1.9705344 | G9: {=(D9-MIN(IF($C$2:$C$98=C9,$D$2:$D$98)))/MIN(IF($C$2:$C$98=C9,$D$2:$D$98))} -> 0.1875 | H9: {=(E9-MIN(IF($C$2:$C$98=C9,$E$2:$E$98)))/MIN(IF($C$2:$C$98=C9,$E$2:$E$98))} -> 0.36947521
A10: Heating | B10: Residential | C10: Mobile Home Gas Furnace | D10: 0.97 | E10: 1232.96 | F10: =IFERROR(H10/G10,"") -> 2.4018263 | G10: {=(D10-MIN(IF($C$2:$C$98=C10,$D$2:$D$98)))/MIN(IF($C$2:$C$98=C10,$D$2:$D$98))} -> 0.2125 | H10: {=(E10-MIN(IF($C$2:$C$98=C10,$E$2:$E$98)))/MIN(IF($C$2:$C$98=C10,$E$2:$E$98))} -> 0.51038808
A11: Heating | B11: Residential | C11: Gas-Fired Hot Water Boiler | D11: 0.82 | E11: 2083 | F11: =IFERROR(H11/G11,"") | G11: {=(D11-MIN(IF($C$2:$C$98=C11,$D$2:$D$98)))/MIN(IF($C$2:$C$98=C11,$D$2:$D$98))} -> 0 | H11: {=(E11-MIN(IF($C$2:$C$98=C11,$E$2:$E$98)))/MIN(IF($C$2:$C$98=C11,$E$2:$E$98))} -> 0
A12: Heating | B12: Residential | C12: Gas-Fired Hot Water Boiler | D12: 0.83 | E12: 2099 | F12: =IFERROR(H12/G12,"") -> 0.62986078 | G12: {=(D12-MIN(IF($C$2:$C$98=C12,$D$2:$D$98)))/MIN(IF($C$2:$C$98=C12,$D$2:$D$98))} -> 0.012195122 | H12: {=(E12-MIN(IF($C$2:$C$98=C12,$E$2:$E$98)))/MIN(IF($C$2:$C$98=C12,$E$2:$E$98))} -> 0.007681229
A13: Heating | B13: Residential | C13: Gas-Fired Hot Water Boiler | D13: 0.84 | E13: 2114 | F13: =IFERROR(H13/G13,"") -> 0.61017763 | G13: {=(D13-MIN(IF($C$2:$C$98=C13,$D$2:$D$98)))/MIN(IF($C$2:$C$98=C13,$D$2:$D$98))} -> 0.024390244 | H13: {=(E13-MIN(IF($C$2:$C$98=C13,$E$2:$E$98)))/MIN(IF($C$2:$C$98=C13,$E$2:$E$98))} -> 0.014882381
... A98: Heating | B98: Commercial | C98: Oil-Fired Warm Air Furnace | D98: 0.92 | E98: 5867.8 | F98: =IFERROR(H98/G98,"") -> 1.8746209 | G98: {=(D98-MIN(IF($C$2:$C$98=C98,$D$2:$D$98)))/MIN(IF($C$2:$C$98=C98,$D$2:$D$98))} -> 0.13580247 | H98: {=(E98-MIN(IF($C$2:$C$98=C98,$E$2:$E$98)))/MIN(IF($C$2:$C$98=C98,$E$2:$E$98))} -> 0.25457815

Sheet Cooling
A1: Product Category | B1: Building Type | C1: Product | D1: SEER (BTU/Watt*hour) | E1: Efficiency (1 BTU out = X watt*hours in) | F1: Total Consumer Price | G1: Elasticity | H1: % Improvement in Efficency from Base | I1: % Change in Price
A2: Cooling | B2: Residential | C2: 2-ton blower coil split central | D2: 13.6 | E2: =1/D2 -> 0.073529412 | F2: 3042 | G2: =IFERROR(I2/H2,"") | H2: {=(E2-MAX(IF($C$2:$C$154=C2,$E$2:$E$154)))/MAX(IF($C$2:$C$154=C2,$E$2:$E$154))*-1} -> 0 | I2: {=(F2-MIN(IF($C$2:$C$154=C2,$F$2:$F$154)))/MIN(IF($C$2:$C$154=C2,$F$2:$F$154))} -> 0
A3: Cooling | B3: Residential | C3: 2-ton blower coil split central | D3: 14 | E3: =1/D3 -> 0.071428571 | F3: 3099 | G3: =IFERROR(I3/H3,"") -> 0.65581854 | H3: {=(E3-MAX(IF($C$2:$C$154=C3,$E$2:$E$154)))/MAX(IF($C$2:$C$154=C3,$E$2:$E$154))*-1} -> 0.028571429 | I3: {=(F3-MIN(IF($C$2:$C$154=C3,$F$2:$F$154)))/MIN(IF($C$2:$C$154=C3,$F$2:$F$154))} -> 0.018737673
A4: Cooling | B4: Residential | C4: 2-ton blower coil split central | D4: 14.5 | E4: =1/D4 -> 0.068965517 | F4: 3164 | G4: =IFERROR(I4/H4,"") -> 0.64613924 | H4: {=(E4-MAX(IF($C$2:$C$154=C4,$E$2:$E$154)))/MAX(IF($C$2:$C$154=C4,$E$2:$E$154))*-1} -> 0.062068966 | I4: {=(F4-MIN(IF($C$2:$C$154=C4,$F$2:$F$154)))/MIN(IF($C$2:$C$154=C4,$F$2:$F$154))} -> 0.040105194
A5: Cooling | B5: Residential | C5: 2-ton blower coil split central | D5: 15 | E5: =1/D5 -> 0.066666667 | F5: 3226 | G5: =IFERROR(I5/H5,"") -> 0.64806988 | H5: {=(E5-MAX(IF($C$2:$C$154=C5,$E$2:$E$154)))/MAX(IF($C$2:$C$154=C5,$E$2:$E$154))*-1} -> 0.093333333 | I5: {=(F5-MIN(IF($C$2:$C$154=C5,$F$2:$F$154)))/MIN(IF($C$2:$C$154=C5,$F$2:$F$154))} -> 0.060486522
A6: Cooling | B6: Residential | C6: 2-ton blower coil split central | D6: 15.5 | E6: =1/D6 -> 0.064516129 | F6: 3293 | G6: =IFERROR(I6/H6,"") -> 0.67312018 | H6: {=(E6-MAX(IF($C$2:$C$154=C6,$E$2:$E$154)))/MAX(IF($C$2:$C$154=C6,$E$2:$E$154))*-1} -> 0.12258065 | I6: {=(F6-MIN(IF($C$2:$C$154=C6,$F$2:$F$154)))/MIN(IF($C$2:$C$154=C6,$F$2:$F$154))} -> 0.082511506
A7: Cooling | B7: Residential | C7: 2-ton blower coil split central | D7: 16 | E7: =1/D7 -> 0.0625 | F7: 3364 | G7: =IFERROR(I7/H7,"") -> 0.70567609 | H7: {=(E7-MAX(IF($C$2:$C$154=C7,$E$2:$E$154)))/MAX(IF($C$2:$C$154=C7,$E$2:$E$154))*-1} -> 0.15 | I7: {=(F7-MIN(IF($C$2:$C$154=C7,$F$2:$F$154)))/MIN(IF($C$2:$C$154=C7,$F$2:$F$154))} -> 0.10585141
A8: Cooling | B8: Residential | C8: 2-ton blower coil split central | D8: 17 | E8: =1/D8 -> 0.058823529 | F8: 3498 | G8: =IFERROR(I8/H8,"") -> 0.7495069 | H8: {=(E8-MAX(IF($C$2:$C$154=C8,$E$2:$E$154)))/MAX(IF($C$2:$C$154=C8,$E$2:$E$154))*-1} -> 0.2 | I8: {=(F8-MIN(IF($C$2:$C$154=C8,$F$2:$F$154)))/MIN(IF($C$2:$C$154=C8,$F$2:$F$154))} -> 0.14990138
A9: Cooling | B9: Residential | C9: 2-ton blower coil split central | D9: 17.5 | E9: =1/D9 -> 0.057142857 | F9: 3606 | G9: =IFERROR(I9/H9,"") -> 0.83194255 | H9: {=(E9-MAX(IF($C$2:$C$154=C9,$E$2:$E$154)))/MAX(IF($C$2:$C$154=C9,$E$2:$E$154))*-1} -> 0.22285714 | I9: {=(F9-MIN(IF($C$2:$C$154=C9,$F$2:$F$154)))/MIN(IF($C$2:$C$154=C9,$F$2:$F$154))} -> 0.18540434
A10: Cooling | B10: Residential | C10: 2-ton blower coil split central | D10: 18 | E10: =1/D10 -> 0.055555556 | F10: 3742 | G10: =IFERROR(I10/H10,"") -> 0.94136633 | H10: {=(E10-MAX(IF($C$2:$C$154=C10,$E$2:$E$154)))/MAX(IF($C$2:$C$154=C10,$E$2:$E$154))*-1} -> 0.24444444 | I10: {=(F10-MIN(IF($C$2:$C$154=C10,$F$2:$F$154)))/MIN(IF($C$2:$C$154=C10,$F$2:$F$154))} -> 0.23011177
A11: Cooling | B11: Residential | C11: 2-ton blower coil split central | D11: 20 | E11: =1/D11 -> 0.05 | F11: 3759 | G11: =IFERROR(I11/H11,"") -> 0.73656312 | H11: {=(E11-MAX(IF($C$2:$C$154=C11,$E$2:$E$154)))/MAX(IF($C$2:$C$154=C11,$E$2:$E$154))*-1} -> 0.32 | I11: {=(F11-MIN(IF($C$2:$C$154=C11,$F$2:$F$154)))/MIN(IF($C$2:$C$154=C11,$F$2:$F$154))} -> 0.2357002
A12: Cooling | B12: Residential | C12: 2-ton blower coil split central | D12: 22 | E12: =1/D12 -> 0.045454545 | F12: 3777 | G12: =IFERROR(I12/H12,"") -> 0.63280736 | H12: {=(E12-MAX(IF($C$2:$C$154=C12,$E$2:$E$154)))/MAX(IF($C$2:$C$154=C12,$E$2:$E$154))*-1} -> 0.38181818 | I12: {=(F12-MIN(IF($C$2:$C$154=C12,$F$2:$F$154)))/MIN(IF($C$2:$C$154=C12,$F$2:$F$154))} -> 0.24161736
A13: Cooling | B13: Residential | C13: 2-ton blower coil split central | D13: 24 | E13: =1/D13 -> 0.041666667 | F13: 3827 | G13: =IFERROR(I13/H13,"") -> 0.59550903 | H13: {=(E13-MAX(IF($C$2:$C$154=C13,$E$2:$E$154)))/MAX(IF($C$2:$C$154=C13,$E$2:$E$154))*-1} -> 0.43333333 | I13: {=(F13-MIN(IF($C$2:$C$154=C13,$F$2:$F$154)))/MIN(IF($C$2:$C$154=C13,$F$2:$F$154))} -> 0.25805391
... A146: Cooling | B146: Commercial | C146: SPVAC (singleand three-phase) <65,000 Btu/h | D146: 11 | E146: =1/D146 -> 0.090909091 | F146: 2037 | G146: =IFERROR(I146/H146,"") -> 1.1976048 | H146: {=(E146-MAX(IF($C$2:$C$154=C146,$E$2:$E$154)))/MAX(IF($C$2:$C$154=C146,$E$2:$E$154))*-1} -> 0.090909091 | I146: {=(F146-MIN(IF($C$2:$C$154=C146,$F$2:$F$154)))/MIN(IF($C$2:$C$154=C146,$F$2:$F$154))} -> 0.10887316
A147: Cooling | B147: Commercial | C147: SPVAC (singleand three-phase) <65,000 Btu/h | D147: 11.75 | E147: =1/D147 -> 0.085106383 | F147: =1837+415 -> 2252 | G147: =IFERROR(I147/H147,"") -> 1.5168365 | H147: {=(E147-MAX(IF($C$2:$C$154=C147,$E$2:$E$154)))/MAX(IF($C$2:$C$154=C147,$E$2:$E$154))*-1} -> 0.14893617 | I147: {=(F147-MIN(IF($C$2:$C$154=C147,$F$2:$F$154)))/MIN(IF($C$2:$C$154=C147,$F$2:$F$154))} -> 0.22591181
A148: Cooling | B148: Commercial | C148: SPVAC (singleand three-phase) <65,000 Btu/h | D148: 12.3 | E148: =1/D148 -> 0.081300813 | F148: =1837+884 -> 2721 | G148: =IFERROR(I148/H148,"") -> 2.5734776 | H148: {=(E148-MAX(IF($C$2:$C$154=C148,$E$2:$E$154)))/MAX(IF($C$2:$C$154=C148,$E$2:$E$154))*-1} -> 0.18699187 | I148: {=(F148-MIN(IF($C$2:$C$154=C148,$F$2:$F$154)))/MIN(IF($C$2:$C$154=C148,$F$2:$F$154))} -> 0.48121938
A149: Cooling | B149: Commercial | C149: SPVHP (singleand three-phase) <65,000 Btu/h | D149: 10 | E149: =1/D149 -> 0.1 | F149: 2130 | G149: =IFERROR(I149/H149,"") | H149: {=(E149-MAX(IF($C$2:$C$154=C149,$E$2:$E$154)))/MAX(IF($C$2:$C$154=C149,$E$2:$E$154))*-1} -> 0 | I149: {=(F149-MIN(IF($C$2:$C$154=C149,$F$2:$F$154)))/MIN(IF($C$2:$C$154=C149,$F$2:$F$154))} -> 0
A150: Cooling | B150: Commercial | C150: SPVHP (singleand three-phase) <65,000 Btu/h | D150: 10.5 | E150: =1/D150 -> 0.095238095 | F150: =2130+117 -> 2247 | G150: =IFERROR(I150/H150,"") -> 1.1535211 | H150: {=(E150-MAX(IF($C$2:$C$154=C150,$E$2:$E$154)))/MAX(IF($C$2:$C$154=C150,$E$2:$E$154))*-1} -> 0.047619048 | I150: {=(F150-MIN(IF($C$2:$C$154=C150,$F$2:$F$154)))/MIN(IF($C$2:$C$154=C150,$F$2:$F$154))} -> 0.054929577
A151: Cooling | B151: Commercial | C151: SPVHP (singleand three-phase) <65,000 Btu/h | D151: 11 | E151: =1/D151 -> 0.090909091 | F151: =2130+233 -> 2363 | G151: =IFERROR(I151/H151,"") -> 1.2032864 | H151: {=(E151-MAX(IF($C$2:$C$154=C151,$E$2:$E$154)))/MAX(IF($C$2:$C$154=C151,$E$2:$E$154))*-1} -> 0.090909091 | I151: {=(F151-MIN(IF($C$2:$C$154=C151,$F$2:$F$154)))/MIN(IF($C$2:$C$154=C151,$F$2:$F$154))} -> 0.10938967
A152: Cooling | B152: Commercial | C152: SPVHP (singleand three-phase) <65,000 Btu/h | D152: 11.75 | E152: =1/D152 -> 0.085106383 | F152: =2130+481 -> 2611 | G152: =IFERROR(I152/H152,"") -> 1.5162307 | H152: {=(E152-MAX(IF($C$2:$C$154=C152,$E$2:$E$154)))/MAX(IF($C$2:$C$154=C152,$E$2:$E$154))*-1} -> 0.14893617 | I152: {=(F152-MIN(IF($C$2:$C$154=C152,$F$2:$F$154)))/MIN(IF($C$2:$C$154=C152,$F$2:$F$154))} -> 0.2258216
A153: Cooling | B153: Commercial | C153: SPVHP (singleand three-phase) <65,000 Btu/h | D153: 12.3 | E153: =1/D153 -> 0.081300813 | F153: =2130+1021 -> 3151 | G153: =IFERROR(I153/H153,"") -> 2.5634415 | H153: {=(E153-MAX(IF($C$2:$C$154=C153,$E$2:$E$154)))/MAX(IF($C$2:$C$154=C153,$E$2:$E$154))*-1} -> 0.18699187 | I153: {=(F153-MIN(IF($C$2:$C$154=C153,$F$2:$F$154)))/MIN(IF($C$2:$C$154=C153,$F$2:$F$154))} -> 0.47934272

Sheet Appliances
A1: Product Category | B1: Building Type | C1: Service | D1: Product | E1: Efficiency | F1: Price | G1: Elasticity | H1: % Improvement in Efficency from Base | I1: % Change in Price
A2: Appliances | B2: Residential | C2: Water Heating | D2: Gas-Fired Storage Water Heaters | E2: 0.59 | F2: 451 | G2: =IFERROR(I2/H2,"") | H2: {=(E2-MIN(IF($D$2:$D$283=D2,$E$2:$E$283)))/MIN(IF($D$2:$D$283=D2,$E$2:$E$283))} -> 0 | I2: {=(F2-MIN(IF($D$2:$D$283=D2,$F$2:$F$283)))/MIN(IF($D$2:$D$283=D2,$F$2:$F$283))} -> 0
A3: Appliances | B3: Residential | C3: Water Heating | D3: Gas-Fired Storage Water Heaters | E3: 0.62 | F3: 468 | G3: =IFERROR(I3/H3,"") -> 0.74131559 | H3: {=(E3-MIN(IF($D$2:$D$283=D3,$E$2:$E$283)))/MIN(IF($D$2:$D$283=D3,$E$2:$E$283))} -> 0.050847458 | I3: {=(F3-MIN(IF($D$2:$D$283=D3,$F$2:$F$283)))/MIN(IF($D$2:$D$283=D3,$F$2:$F$283))} -> 0.037694013
A4: Appliances | B4: Residential | C4: Water Heating | D4: Gas-Fired Storage Water Heaters | E4: 0.63 | F4: 506 | G4: =IFERROR(I4/H4,"") -> 1.7987805 | H4: {=(E4-MIN(IF($D$2:$D$283=D4,$E$2:$E$283)))/MIN(IF($D$2:$D$283=D4,$E$2:$E$283))} -> 0.06779661 | I4: {=(F4-MIN(IF($D$2:$D$283=D4,$F$2:$F$283)))/MIN(IF($D$2:$D$283=D4,$F$2:$F$283))} -> 0.12195122
A5: Appliances | B5: Residential | C5: Water Heating | D5: Gas-Fired Storage Water Heaters | E5: 0.64 | F5: 670 | G5: =IFERROR(I5/H5,"") -> 5.7299335 | H5: {=(E5-MIN(IF($D$2:$D$283=D5,$E$2:$E$283)))/MIN(IF($D$2:$D$283=D5,$E$2:$E$283))} -> 0.084745763 | I5: {=(F5-MIN(IF($D$2:$D$283=D5,$F$2:$F$283)))/MIN(IF($D$2:$D$283=D5,$F$2:$F$283))} -> 0.48558758
A6: Appliances | B6: Residential | C6: Water Heating | D6: Gas-Fired Storage Water Heaters | E6: 0.65 | F6: 686 | G6: =IFERROR(I6/H6,"") -> 5.123799 | H6: {=(E6-MIN(IF($D$2:$D$283=D6,$E$2:$E$283)))/MIN(IF($D$2:$D$283=D6,$E$2:$E$283))} -> 0.10169492 | I6: {=(F6-MIN(IF($D$2:$D$283=D6,$F$2:$F$283)))/MIN(IF($D$2:$D$283=D6,$F$2:$F$283))} -> 0.5210643
A7: Appliances | B7: Residential | C7: Water Heating | D7: Gas-Fired Storage Water Heaters | E7: 0.67 | F7: 730 | G7: =IFERROR(I7/H7,"") -> 4.5623614 | H7: {=(E7-MIN(IF($D$2:$D$283=D7,$E$2:$E$283)))/MIN(IF($D$2:$D$283=D7,$E$2:$E$283))} -> 0.13559322 | I7: {=(F7-MIN(IF($D$2:$D$283=D7,$F$2:$F$283)))/MIN(IF($D$2:$D$283=D7,$F$2:$F$283))} -> 0.61862528
A8: Appliances | B8: Residential | C8: Water Heating | D8: Gas-Fired Storage Water Heaters | E8: 0.8 | F8: 935 | G8: =IFERROR(I8/H8,"") -> 3.0150987 | H8: {=(E8-MIN(IF($D$2:$D$283=D8,$E$2:$E$283)))/MIN(IF($D$2:$D$283=D8,$E$2:$E$283))} -> 0.3559322 | I8: {=(F8-MIN(IF($D$2:$D$283=D8,$F$2:$F$283)))/MIN(IF($D$2:$D$283=D8,$F$2:$F$283))} -> 1.0731707
A9: Appliances | B9: Residential | C9: Water Heating | D9: Electric Storage Water Heaters | E9: 0.9 | F9: 296 | G9: =IFERROR(I9/H9,"") | H9: {=(E9-MIN(IF($D$2:$D$283=D9,$E$2:$E$283)))/MIN(IF($D$2:$D$283=D9,$E$2:$E$283))} -> 0 | I9: {=(F9-MIN(IF($D$2:$D$283=D9,$F$2:$F$283)))/MIN(IF($D$2:$D$283=D9,$F$2:$F$283))} -> 0
A10: Appliances | B10: Residential | C10: Water Heating | D10: Electric Storage Water Heaters | E10: 0.91 | F10: 305 | G10: =IFERROR(I10/H10,"") -> 2.7364865 | H10: {=(E10-MIN(IF($D$2:$D$283=D10,$E$2:$E$283)))/MIN(IF($D$2:$D$283=D10,$E$2:$E$283))} -> 0.011111111 | I10: {=(F10-MIN(IF($D$2:$D$283=D10,$F$2:$F$283)))/MIN(IF($D$2:$D$283=D10,$F$2:$F$283))} -> 0.030405405
A11: Appliances | B11: Residential | C11: Water Heating | D11: Electric Storage Water Heaters | E11: 0.92 | F11: 315 | G11: =IFERROR(I11/H11,"") -> 2.8885135 | H11: {=(E11-MIN(IF($D$2:$D$283=D11,$E$2:$E$283)))/MIN(IF($D$2:$D$283=D11,$E$2:$E$283))} -> 0.022222222 | I11: {=(F11-MIN(IF($D$2:$D$283=D11,$F$2:$F$283)))/MIN(IF($D$2:$D$283=D11,$F$2:$F$283))} -> 0.064189189
A12: Appliances | B12: Residential | C12: Water Heating | D12: Electric Storage Water Heaters | E12: 0.93 | F12: 319 | G12: =IFERROR(I12/H12,"") -> 2.3310811 | H12: {=(E12-MIN(IF($D$2:$D$283=D12,$E$2:$E$283)))/MIN(IF($D$2:$D$283=D12,$E$2:$E$283))} -> 0.033333333 | I12: {=(F12-MIN(IF($D$2:$D$283=D12,$F$2:$F$283)))/MIN(IF($D$2:$D$283=D12,$F$2:$F$283))} -> 0.077702703
A13: Appliances | B13: Residential | C13: Water Heating | D13: Electric Storage Water Heaters | E13: 0.94 | F13: 338 | G13: =IFERROR(I13/H13,"") -> 3.1925676 | H13: {=(E13-MIN(IF($D$2:$D$283=D13,$E$2:$E$283)))/MIN(IF($D$2:$D$283=D13,$E$2:$E$283))} -> 0.044444444 | I13: {=(F13-MIN(IF($D$2:$D$283=D13,$F$2:$F$283)))/MIN(IF($D$2:$D$283=D13,$F$2:$F$283))} -> 0.14189189
... A283: Appliances | B283: Commercial | C283: Water Heating | D283: commercial gas-fired instantaneous hot water supply boiler | E283: 0.96 | F283: 10754 | G283: =IFERROR(I283/H283,"") -> 2.2938144 | H283: {=(E283-MIN(IF($D$2:$D$283=D283,$E$2:$E$283)))/MIN(IF($D$2:$D$283=D283,$E$2:$E$283))} -> 0.2 | I283: {=(F283-MIN(IF($D$2:$D$283=D283,$F$2:$F$283)))/MIN(IF($D$2:$D$283=D283,$F$2:$F$283))} -> 0.45876289

Sheet Lighting
A1: Product Category | B1: Building Type | C1: Product | D1: Type | E1: Baseline | F1: Mean wattage | G1: lumens/watt | H1: mean lumens | I1: Price ($) | J1: Prcie ($/klm) | K1: $/1000 lumen | L1: Lifetime (hours) | M1: thousand watt/(lumen*hours) | N1: Elasticity | O1: % Improvement in Efficency from Base | P1: % Change in Price | Q1: Include/Exclude
A2: Lighting | B2: Residential | C2: Decorative Lighting | D2: CFL Decorative | E2: No | F2: 17 | G2: 53 | H2: =F2*G2 -> 901 | I2: 3.9 | K2: =IF(J2="",I2/H2*1000,J2) -> 4.3285239 | L2: 10000 | M2: =1/G2/L2*1000 -> 0.0018867925 | N2: =IFERROR(P2/O2,"") -> 0.62450414 | O2: {=(MAX(IF($C$2:$C$233=C2,IF($E$2:$E$233="Yes",IF($B$2:$B$78=B2,$M$2:$M$233)))-M2)/MAX(IF($C$2:$C$233=C2,IF($E$2:$E$233="Yes",IF($B$2:$B$78=B2,$M$2:$M$233)))))} -> 0.97924528 | P2: {=(K2-MIN(IF($C$2:$C$233=C2,IF($E$2:$E$233="Yes",IF($B$2:$B$78=B2,$K$2:$K$233)))))/MIN(IF($C$2:$C$233=C2,IF($E$2:$E$233="Yes",IF($B$2:$B$78=B2,$K$2:$K$233))))} -> 0.61154273 | Q2: Include
A3: Lighting | B3: Residential | C3: Decorative Lighting | D3: Halogen Decorative | E3: No | F3: 51 | G3: 14 | H3: =F3*G3 -> 714 | I3: 3.7 | K3: =IF(J3="",I3/H3*1000,J3) -> 5.1820728 | L3: 1200 | M3: =1/G3/L3*1000 -> 0.05952381 | N3: =IFERROR(P3/O3,"") -> 2.6918396 | O3: {=(MAX(IF($C$2:$C$233=C3,IF($E$2:$E$233="Yes",IF($B$2:$B$78=B3,$M$2:$M$233)))-M3)/MAX(IF($C$2:$C$233=C3,IF($E$2:$E$233="Yes",IF($B$2:$B$78=B3,$M$2:$M$233)))))} -> 0.3452381 | P3: {=(K3-MIN(IF($C$2:$C$233=C3,IF($E$2:$E$233="Yes",IF($B$2:$B$78=B3,$K$2:$K$233)))))/MIN(IF($C$2:$C$233=C3,IF($E$2:$E$233="Yes",IF($B$2:$B$78=B3,$K$2:$K$233))))} -> 0.92932558 | Q3: Include
A4: Lighting | B4: Residential | C4: Decorative Lighting | D4: Incadescent Decorative | E4: Yes | F4: 44 | G4: 11 | H4: =F4*G4 -> 484 | I4: 1.3 | K4: =IF(J4="",I4/H4*1000,J4) -> 2.6859504 | L4: 1000 | M4: =1/G4/L4*1000 -> 0.090909091 | N4: =IFERROR(P4/O4,"") | O4: {=(MAX(IF($C$2:$C$233=C4,IF($E$2:$E$233="Yes",IF($B$2:$B$78=B4,$M$2:$M$233)))-M4)/MAX(IF($C$2:$C$233=C4,IF($E$2:$E$233="Yes",IF($B$2:$B$78=B4,$M$2:$M$233)))))} -> 0 | P4: {=(K4-MIN(IF($C$2:$C$233=C4,IF($E$2:$E$233="Yes",IF($B$2:$B$78=B4,$K$2:$K$233)))))/MIN(IF($C$2:$C$233=C4,IF($E$2:$E$233="Yes",IF($B$2:$B$78=B4,$K$2:$K$233))))} -> 0 | Q4: Exclude
A5: Lighting | B5: Residential | C5: Decorative Lighting | D5: LED - 2015 | E5: No | G5: 73 | J5: 39 | K5: =IF(J5="",I5/H5*1000,J5) -> 39 | L5: 44000 | M5: =1/G5/L5*1000 -> 0.0003113325 | N5: =IFERROR(P5/O5,"") -> 13.56646 | O5: {=(MAX(IF($C$2:$C$233=C5,IF($E$2:$E$233="Yes",IF($B$2:$B$78=B5,$M$2:$M$233)))-M5)/MAX(IF($C$2:$C$233=C5,IF($E$2:$E$233="Yes",IF($B$2:$B$78=B5,$M$2:$M$233)))))} -> 0.99657534 | P5: {=(K5-MIN(IF($C$2:$C$233=C5,IF($E$2:$E$233="Yes",IF($B$2:$B$78=B5,$K$2:$K$233)))))/MIN(IF($C$2:$C$233=C5,IF($E$2:$E$233="Yes",IF($B$2:$B$78=B5,$K$2:$K$233))))} -> 13.52 | Q5: Exclude
A6: Lighting | B6: Residential | C6: Decorative Lighting | D6: LED - 2020 | E6: No | G6: 100 | J6: 12 | K6: =IF(J6="",I6/H6*1000,J6) -> 12 | L6: 49000 | M6: =1/G6/L6*1000 -> 0.00020408163 | N6: =IFERROR(P6/O6,"") -> 3.4754944 | O6: {=(MAX(IF($C$2:$C$233=C6,IF($E$2:$E$233="Yes",IF($B$2:$B$78=B6,$M$2:$M$233)))-M6)/MAX(IF($C$2:$C$233=C6,IF($E$2:$E$233="Yes",IF($B$2:$B$78=B6,$M$2:$M$233)))))} -> 0.9977551 | P6: {=(K6-MIN(IF($C$2:$C$233=C6,IF($E$2:$E$233="Yes",IF($B$2:$B$78=B6,$K$2:$K$233)))))/MIN(IF($C$2:$C$233=C6,IF($E$2:$E$233="Yes",IF($B$2:$B$78=B6,$K$2:$K$233))))} -> 3.4676923 | Q6: Include
A7: Lighting | B7: Residential | C7: Decorative Lighting | D7: LED - 2030 | E7: No | G7: 148 | J7: 2.2 | K7: =IF(J7="",I7/H7*1000,J7) -> 2.2 | L7: 50000 | M7: =1/G7/L7*1000 -> 0.00013513514 | N7: =IFERROR(P7/O7,"") -> -0.18119242 | O7: {=(MAX(IF($C$2:$C$233=C7,IF($E$2:$E$233="Yes",IF($B$2:$B$78=B7,$M$2:$M$233)))-M7)/MAX(IF($C$2:$C$233=C7,IF($E$2:$E$233="Yes",IF($B$2:$B$78=B7,$M$2:$M$233)))))} -> 0.99851351 | P7: {=(K7-MIN(IF($C$2:$C$233=C7,IF($E$2:$E$233="Yes",IF($B$2:$B$78=B7,$K$2:$K$233)))))/MIN(IF($C$2:$C$233=C7,IF($E$2:$E$233="Yes",IF($B$2:$B$78=B7,$K$2:$K$233))))} -> -0.18092308 | Q7: Include
A8: Lighting | B8: Residential | C8: Downlights/Track Lighting - Directional | D8: CFL Directional | E8: No | F8: 17 | G8: 44 | H8: =F8*G8 -> 748 | I8: 10.1 | K8: =IF(J8="",I8/H8*1000,J8) -> 13.502674 | L8: 10000 | M8: =1/G8/L8*1000 -> 0.0022727273 | N8: =IFERROR(P8/O8,"") -> 2.0800622 | O8: {=(MAX(IF($C$2:$C$233=C8,IF($E$2:$E$233="Yes",IF($B$2:$B$78=B8,$M$2:$M$233)))-M8)/MAX(IF($C$2:$C$233=C8,IF($E$2:$E$233="Yes",IF($B$2:$B$78=B8,$M$2:$M$233)))))} -> 0.94318182 | P8: {=(K8-MIN(IF($C$2:$C$233=C8,IF($E$2:$E$233="Yes",IF($B$2:$B$78=B8,$K$2:$K$233)))))/MIN(IF($C$2:$C$233=C8,IF($E$2:$E$233="Yes",IF($B$2:$B$78=B8,$K$2:$K$233))))} -> 1.9618768 | Q8: Include
A9: Lighting | B9: Residential | C9: Downlights/Track Lighting - Directional | D9: Halogen Directional | E9: No | F9: 68 | G9: 14 | H9: =F9*G9 -> 952 | I9: 4.6 | K9: =IF(J9="",I9/H9*1000,J9) -> 4.8319328 | L9: 3000 | M9: =1/G9/L9*1000 -> 0.023809524 | N9: =IFERROR(P9/O9,"") -> 0.14800759 | O9: {=(MAX(IF($C$2:$C$233=C9,IF($E$2:$E$233="Yes",IF($B$2:$B$78=B9,$M$2:$M$233)))-M9)/MAX(IF($C$2:$C$233=C9,IF($E$2:$E$233="Yes",IF($B$2:$B$78=B9,$M$2:$M$233)))))} -> 0.4047619 | P9: {=(K9-MIN(IF($C$2:$C$233=C9,IF($E$2:$E$233="Yes",IF($B$2:$B$78=B9,$K$2:$K$233)))))/MIN(IF($C$2:$C$233=C9,IF($E$2:$E$233="Yes",IF($B$2:$B$78=B9,$K$2:$K$233))))} -> 0.059907834 | Q9: Include
A10: Lighting | B10: Residential | C10: Downlights/Track Lighting - Directional | D10: Incandescent Directional | E10: Yes | F10: 68 | G10: 10 | H10: =F10*G10 -> 680 | I10: 3.1 | K10: =IF(J10="",I10/H10*1000,J10) -> 4.5588235 | L10: 2500 | M10: =1/G10/L10*1000 -> 0.04 | N10: =IFERROR(P10/O10,"") | O10: {=(MAX(IF($C$2:$C$233=C10,IF($E$2:$E$233="Yes",IF($B$2:$B$78=B10,$M$2:$M$233)))-M10)/MAX(IF($C$2:$C$233=C10,IF($E$2:$E$233="Yes",IF($B$2:$B$78=B10,$M$2:$M$233)))))} -> 0 | P10: {=(K10-MIN(IF($C$2:$C$233=C10,IF($E$2:$E$233="Yes",IF($B$2:$B$78=B10,$K$2:$K$233)))))/MIN(IF($C$2:$C$233=C10,IF($E$2:$E$233="Yes",IF($B$2:$B$78=B10,$K$2:$K$233))))} -> 0 | Q10: Exclude
A11: Lighting | B11: Residential | C11: Downlights/Track Lighting - Directional | D11: LED - 2015 | E11: No | G11: 72 | J11: 36 | K11: =IF(J11="",I11/H11*1000,J11) -> 36 | L11: 44000 | M11: =1/G11/L11*1000 -> 0.00031565657 | N11: =IFERROR(P11/O11,"") -> 6.9516324 | O11: {=(MAX(IF($C$2:$C$233=C11,IF($E$2:$E$233="Yes",IF($B$2:$B$78=B11,$M$2:$M$233)))-M11)/MAX(IF($C$2:$C$233=C11,IF($E$2:$E$233="Yes",IF($B$2:$B$78=B11,$M$2:$M$233)))))} -> 0.99210859 | P11: {=(K11-MIN(IF($C$2:$C$233=C11,IF($E$2:$E$233="Yes",IF($B$2:$B$78=B11,$K$2:$K$233)))))/MIN(IF($C$2:$C$233=C11,IF($E$2:$E$233="Yes",IF($B$2:$B$78=B11,$K$2:$K$233))))} -> 6.8967742 | Q11: Exclude
A12: Lighting | B12: Residential | C12: Downlights/Track Lighting - Directional | D12: LED - 2020 | E12: No | G12: 91 | J12: 15 | K12: =IF(J12="",I12/H12*1000,J12) -> 15 | L12: 49000 | M12: =1/G12/L12*1000 -> 0.00022426553 | N12: =IFERROR(P12/O12,"") -> 2.303236 | O12: {=(MAX(IF($C$2:$C$233=C12,IF($E$2:$E$233="Yes",IF($B$2:$B$78=B12,$M$2:$M$233)))-M12)/MAX(IF($C$2:$C$233=C12,IF($E$2:$E$233="Yes",IF($B$2:$B$78=B12,$M$2:$M$233)))))} -> 0.99439336 | P12: {=(K12-MIN(IF($C$2:$C$233=C12,IF($E$2:$E$233="Yes",IF($B$2:$B$78=B12,$K$2:$K$233)))))/MIN(IF($C$2:$C$233=C12,IF($E$2:$E$233="Yes",IF($B$2:$B$78=B12,$K$2:$K$233))))} -> 2.2903226 | Q12: Include
A13: Lighting | B13: Residential | C13: Downlights/Track Lighting - Directional | D13: LED - 2030 | E13: No | G13: 117 | J13: 2.7 | K13: =IF(J13="",I13/H13*1000,J13) -> 2.7 | L13: 50000 | M13: =1/G13/L13*1000 -> 0.00017094017 | N13: =IFERROR(P13/O13,"") -> -0.4094919 | O13: {=(MAX(IF($C$2:$C$233=C13,IF($E$2:$E$233="Yes",IF($B$2:$B$78=B13,$M$2:$M$233)))-M13)/MAX(IF($C$2:$C$233=C13,IF($E$2:$E$233="Yes",IF($B$2:$B$78=B13,$M$2:$M$233)))))} -> 0.9957265 | P13: {=(K13-MIN(IF($C$2:$C$233=C13,IF($E$2:$E$233="Yes",IF($B$2:$B$78=B13,$K$2:$K$233)))))/MIN(IF($C$2:$C$233=C13,IF($E$2:$E$233="Yes",IF($B$2:$B$78=B13,$K$2:$K$233))))} -> -0.40774194 | Q13: Include
A14: Lighting | B14: Residential | C14: Downlights/Track Lighting - Omni | D14: CFL Omni | E14: No | F14: 17 | G14: 54 | H14: =F14*G14 -> 918 | I14: 3 | K14: =IF(J14="",I14/H14*1000,J14) -> 3.2679739 | L14: 10000 | M14: =1/G14/L14*1000 -> 0.0018518519 | N14: =IFERROR(P14/O14,"") -> 1.482571 | O14: {=(MAX(IF($C$2:$C$233=C14,IF($E$2:$E$233="Yes",IF($B$2:$B$78=B14,$M$2:$M$233)))-M14)/MAX(IF($C$2:$C$233=C14,IF($E$2:$E$233="Yes",IF($B$2:$B$78=B14,$M$2:$M$233)))))} -> 0.96851852 | P14: {=(K14-MIN(IF($C$2:$C$233=C14,IF($E$2:$E$233="Yes",IF($B$2:$B$78=B14,$K$2:$K$233)))))/MIN(IF($C$2:$C$233=C14,IF($E$2:$E$233="Yes",IF($B$2:$B$78=B14,$K$2:$K$233))))} -> 1.4358974 | Q14: Include
A15: Lighting | B15: Residential | C15: Downlights/Track Lighting - Omni | D15: Halogen Omni | E15: No | F15: 51 | G15: 15 | H15: =F15*G15 -> 765 | I15: 1.9 | K15: =IF(J15="",I15/H15*1000,J15) -> 2.4836601 | L15: 1500 | M15: =1/G15/L15*1000 -> 0.044444444 | N15: =IFERROR(P15/O15,"") -> 3.4825175 | O15: {=(MAX(IF($C$2:$C$233=C15,IF($E$2:$E$233="Yes",IF($B$2:$B$78=B15,$M$2:$M$233)))-M15)/MAX(IF($C$2:$C$233=C15,IF($E$2:$E$233="Yes",IF($B$2:$B$78=B15,$M$2:$M$233)))))} -> 0.24444444 | P15: {=(K15-MIN(IF($C$2:$C$233=C15,IF($E$2:$E$233="Yes",IF($B$2:$B$78=B15,$K$2:$K$233)))))/MIN(IF($C$2:$C$233=C15,IF($E$2:$E$233="Yes",IF($B$2:$B$78=B15,$K$2:$K$233))))} -> 0.85128205 | Q15: Include
A16: Lighting | B16: Residential | C16: Downlights/Track Lighting - Omni | D16: Incadescent Omni | E16: Yes | F16: 57 | G16: 17 | H16: =F16*G16 -> 969 | I16: 1.3 | K16: =IF(J16="",I16/H16*1000,J16) -> 1.3415893 | L16: 1000 | M16: =1/G16/L16*1000 -> 0.058823529 | N16: =IFERROR(P16/O16,"") | O16: {=(MAX(IF($C$2:$C$233=C16,IF($E$2:$E$233="Yes",IF($B$2:$B$78=B16,$M$2:$M$233)))-M16)/MAX(IF($C$2:$C$233=C16,IF($E$2:$E$233="Yes",IF($B$2:$B$78=B16,$M$2:$M$233)))))} -> 0 | P16: {=(K16-MIN(IF($C$2:$C$233=C16,IF($E$2:$E$233="Yes",IF($B$2:$B$78=B16,$K$2:$K$233)))))/MIN(IF($C$2:$C$233=C16,IF($E$2:$E$233="Yes",IF($B$2:$B$78=B16,$K$2:$K$233))))} -> 0 | Q16: Exclude
A17: Lighting | B17: Residential | C17: General Service Lighting - Res | D17: CFL Omni | E17: No | F17: 17 | G17: 54 | H17: =F17*G17 -> 918 | I17: 3 | K17: =IF(J17="",I17/H17*1000,J17) -> 3.2679739 | L17: 10000 | M17: =1/G17/L17*1000 -> 0.0018518519 | N17: =IFERROR(P17/O17,"") -> 6.392871 | O17: {=(MAX(IF($C$2:$C$233=C17,IF($E$2:$E$233="Yes",IF($B$2:$B$78=B17,$M$2:$M$233)))-M17)/MAX(IF($C$2:$C$233=C17,IF($E$2:$E$233="Yes",IF($B$2:$B$78=B17,$M$2:$M$233)))))} -> 0.95592593 | P17: {=(K17-MIN(IF($C$2:$C$233=C17,IF($E$2:$E$233="Yes",IF($B$2:$B$78=B17,$K$2:$K$233)))))/MIN(IF($C$2:$C$233=C17,IF($E$2:$E$233="Yes",IF($B$2:$B$78=B17,$K$2:$K$233))))} -> 6.1111111 | Q17: Include
A18: Lighting | B18: Residential | C18: General Service Lighting - Res | D18: Halogen Omni | E18: No | F18: 51 | G18: 15 | H18: =F18*G18 -> 765 | I18: 1.9 | K18: =IF(J18="",I18/H18*1000,J18) -> 2.4836601 | L18: 1500 | M18: =1/G18/L18*1000 -> 0.044444444 | N18: =IFERROR(P18/O18,"") -> -76.230769 | O18: {=(MAX(IF($C$2:$C$233=C18,IF($E$2:$E$233="Yes",IF($B$2:$B$78=B18,$M$2:$M$233)))-M18)/MAX(IF($C$2:$C$233=C18,IF($E$2:$E$233="Yes",IF($B$2:$B$78=B18,$M$2:$M$233)))))} -> -0.057777778 | P18: {=(K18-MIN(IF($C$2:$C$233=C18,IF($E$2:$E$233="Yes",IF($B$2:$B$78=B18,$K$2:$K$233)))))/MIN(IF($C$2:$C$233=C18,IF($E$2:$E$233="Yes",IF($B$2:$B$78=B18,$K$2:$K$233))))} -> 4.4044444 | Q18: Exclude
A19: Lighting | B19: Residential | C19: General Service Lighting - Res | D19: Incandescent Omni | E19: Yes | F19: 64 | G19: 17 | H19: =F19*G19 -> 1088 | I19: 0.5 | K19: =IF(J19="",I19/H19*1000,J19) -> 0.45955882 | L19: 1400 | M19: =1/G19/L19*1000 -> 0.042016807 | N19: =IFERROR(P19/O19,"") | O19: {=(MAX(IF($C$2:$C$233=C19,IF($E$2:$E$233="Yes",IF($B$2:$B$78=B19,$M$2:$M$233)))-M19)/MAX(IF($C$2:$C$233=C19,IF($E$2:$E$233="Yes",IF($B$2:$B$78=B19,$M$2:$M$233)))))} -> 0 | P19: {=(K19-MIN(IF($C$2:$C$233=C19,IF($E$2:$E$233="Yes",IF($B$2:$B$78=B19,$K$2:$K$233)))))/MIN(IF($C$2:$C$233=C19,IF($E$2:$E$233="Yes",IF($B$2:$B$78=B19,$K$2:$K$233))))} -> 0 | Q19: Exclude
A20: Lighting | B20: Residential | C20: General Service Lighting - Res | D20: LED - 2015 | E20: No | G20: 81 | J20: 24 | K20: =IF(J20="",I20/H20*1000,J20) -> 24 | L20: 44000 | M20: =1/G20/L20*1000 -> 0.00028058361 | N20: =IFERROR(P20/O20,"") -> 51.568368 | O20: {=(MAX(IF($C$2:$C$233=C20,IF($E$2:$E$233="Yes",IF($B$2:$B$78=B20,$M$2:$M$233)))-M20)/MAX(IF($C$2:$C$233=C20,IF($E$2:$E$233="Yes",IF($B$2:$B$78=B20,$M$2:$M$233)))))} -> 0.99332211 | P20: {=(K20-MIN(IF($C$2:$C$233=C20,IF($E$2:$E$233="Yes",IF($B$2:$B$78=B20,$K$2:$K$233)))))/MIN(IF($C$2:$C$233=C20,IF($E$2:$E$233="Yes",IF($B$2:$B$78=B20,$K$2:$K$233))))} -> 51.224 | Q20: Exclude
A21: Lighting | B21: Residential | C21: General Service Lighting - Res | D21: LED - 2020 | E21: No | G21: 102 | J21: 8.7 | K21: =IF(J21="",I21/H21*1000,J21) -> 8.7 | L21: 49000 | M21: =1/G21/L21*1000 -> 0.00020008003 | N21: =IFERROR(P21/O21,"") -> 18.016995 | O21: {=(MAX(IF($C$2:$C$233=C21,IF($E$2:$E$233="Yes",IF($B$2:$B$78=B21,$M$2:$M$233)))-M21)/MAX(IF($C$2:$C$233=C21,IF($E$2:$E$233="Yes",IF($B$2:$B$78=B21,$M$2:$M$233)))))} -> 0.9952381 | P21: {=(K21-MIN(IF($C$2:$C$233=C21,IF($E$2:$E$233="Yes",IF($B$2:$B$78=B21,$K$2:$K$233)))))/MIN(IF($C$2:$C$233=C21,IF($E$2:$E$233="Yes",IF($B$2:$B$78=B21,$K$2:$K$233))))} -> 17.9312 | Q21: Include
A22: Lighting | B22: Residential | C22: General Service Lighting - Res | D22: LED - 2030 | E22: No | G22: 131 | J22: 1.3 | K22: =IF(J22="",I22/H22*1000,J22) -> 1.3 | L22: 50000 | M22: =1/G22/L22*1000 -> 0.00015267176 | N22: =IFERROR(P22/O22,"") -> 1.8354693 | O22: {=(MAX(IF($C$2:$C$233=C22,IF($E$2:$E$233="Yes",IF($B$2:$B$78=B22,$M$2:$M$233)))-M22)/MAX(IF($C$2:$C$233=C22,IF($E$2:$E$233="Yes",IF($B$2:$B$78=B22,$M$2:$M$233)))))} -> 0.99636641 | P22: {=(K22-MIN(IF($C$2:$C$233=C22,IF($E$2:$E$233="Yes",IF($B$2:$B$78=B22,$K$2:$K$233)))))/MIN(IF($C$2:$C$233=C22,IF($E$2:$E$233="Yes",IF($B$2:$B$78=B22,$K$2:$K$233))))} -> 1.8288 | Q22: Include
A23: Lighting | B23: Residential | C23: General Service Linear <4 ft | D23: LED - 2015 | E23: No | G23: 91 | J23: 89 | K23: =IF(J23="",I23/H23*1000,J23) -> 89 | L23: 44000 | M23: =1/G23/L23*1000 -> 0.00024975025 | N23: =IFERROR(P23/O23,"") -> 31.328237 | O23: {=(MAX(IF($C$2:$C$233=C23,IF($E$2:$E$233="Yes",IF($B$2:$B$78=B23,$M$2:$M$233)))-M23)/MAX(IF($C$2:$C$233=C23,IF($E$2:$E$233="Yes",IF($B$2:$B$78=B23,$M$2:$M$233)))))} -> 0.80519481 | P23: {=(K23-MIN(IF($C$2:$C$233=C23,IF($E$2:$E$233="Yes",IF($B$2:$B$78=B23,$K$2:$K$233)))))/MIN(IF($C$2:$C$233=C23,IF($E$2:$E$233="Yes",IF($B$2:$B$78=B23,$K$2:$K$233))))} -> 25.225333 | Q23: Exclude
A24: Lighting | B24: Residential | C24: General Service Linear <4 ft | D24: LED - 2020 | E24: No | G24: 109 | J24: 60 | K24: =IF(J24="",I24/H24*1000,J24) -> 60 | L24: 49000 | M24: =1/G24/L24*1000 -> 0.00018723086 | N24: =IFERROR(P24/O24,"") -> 19.532532 | O24: {=(MAX(IF($C$2:$C$233=C24,IF($E$2:$E$233="Yes",IF($B$2:$B$78=B24,$M$2:$M$233)))-M24)/MAX(IF($C$2:$C$233=C24,IF($E$2:$E$233="Yes",IF($B$2:$B$78=B24,$M$2:$M$233)))))} -> 0.85395993 | P24: {=(K24-MIN(IF($C$2:$C$233=C24,IF($E$2:$E$233="Yes",IF($B$2:$B$78=B24,$K$2:$K$233)))))/MIN(IF($C$2:$C$233=C24,IF($E$2:$E$233="Yes",IF($B$2:$B$78=B24,$K$2:$K$233))))} -> 16.68 | Q24: Include
A25: Lighting | B25: Residential | C25: General Service Linear <4 ft | D25: LED - 2030 | E25: No | G25: 132 | J25: 28 | K25: =IF(J25="",I25/H25*1000,J25) -> 28 | L25: 50000 | M25: =1/G25/L25*1000 -> 0.00015151515 | N25: =IFERROR(P25/O25,"") -> 8.2224055 | O25: {=(MAX(IF($C$2:$C$233=C25,IF($E$2:$E$233="Yes",IF($B$2:$B$78=B25,$M$2:$M$233)))-M25)/MAX(IF($C$2:$C$233=C25,IF($E$2:$E$233="Yes",IF($B$2:$B$78=B25,$M$2:$M$233)))))} -> 0.88181818 | P25: {=(K25-MIN(IF($C$2:$C$233=C25,IF($E$2:$E$233="Yes",IF($B$2:$B$78=B25,$K$2:$K$233)))))/MIN(IF($C$2:$C$233=C25,IF($E$2:$E$233="Yes",IF($B$2:$B$78=B25,$K$2:$K$233))))} -> 7.2506667 | Q25: Include
A26: Lighting | B26: Residential | C26: General Service Linear <4 ft | D26: T12 | E26: Yes | F26: 17 | G26: 52 | H26: =F26*G26 -> 884 | I26: 3 | K26: =IF(J26="",I26/H26*1000,J26) -> 3.3936652 | L26: 15000 | M26: =1/G26/L26*1000 -> 0.0012820513 | N26: =IFERROR(P26/O26,"") | O26: {=(MAX(IF($C$2:$C$233=C26,IF($E$2:$E$233="Yes",IF($B$2:$B$78=B26,$M$2:$M$233)))-M26)/MAX(IF($C$2:$C$233=C26,IF($E$2:$E$233="Yes",IF($B$2:$B$78=B26,$M$2:$M$233)))))} -> 0 | P26: {=(K26-MIN(IF($C$2:$C$233=C26,IF($E$2:$E$233="Yes",IF($B$2:$B$78=B26,$K$2:$K$233)))))/MIN(IF($C$2:$C$233=C26,IF($E$2:$E$233="Yes",IF($B$2:$B$78=B26,$K$2:$K$233))))} -> 0 | Q26: Exclude
A27: Lighting | B27: Residential | C27: General Service Linear <4 ft | D27: T5 | E27: No | F27: 13 | G27: 73 | H27: =F27*G27 -> 949 | I27: 4.2 | K27: =IF(J27="",I27/H27*1000,J27) -> 4.4257113 | L27: 30000 | M27: =1/G27/L27*1000 -> 0.000456621 | N27: =IFERROR(P27/O27,"") -> 0.47234043 | O27: {=(MAX(IF($C$2:$C$233=C27,IF($E$2:$E$233="Yes",IF($B$2:$B$78=B27,$M$2:$M$233)))-M27)/MAX(IF($C$2:$C$233=C27,IF($E$2:$E$233="Yes",IF($B$2:$B$78=B27,$M$2:$M$233)))))} -> 0.64383562 | P27: {=(K27-MIN(IF($C$2:$C$233=C27,IF($E$2:$E$233="Yes",IF($B$2:$B$78=B27,$K$2:$K$233)))))/MIN(IF($C$2:$C$233=C27,IF($E$2:$E$233="Yes",IF($B$2:$B$78=B27,$K$2:$K$233))))} -> 0.30410959 | Q27: Include
A28: Lighting | B28: Residential | C28: General Service Linear <4 ft | D28: T8 | E28: No | F28: 18 | G28: 65 | H28: =F28*G28 -> 1170 | I28: 5.4 | K28: =IF(J28="",I28/H28*1000,J28) -> 4.6153846 | L28: 20000 | M28: =1/G28/L28*1000 -> 0.00076923077 | N28: =IFERROR(P28/O28,"") -> 0.9 | O28: {=(MAX(IF($C$2:$C$233=C28,IF($E$2:$E$233="Yes",IF($B$2:$B$78=B28,$M$2:$M$233)))-M28)/MAX(IF($C$2:$C$233=C28,IF($E$2:$E$233="Yes",IF($B$2:$B$78=B28,$M$2:$M$233)))))} -> 0.4 | P28: {=(K28-MIN(IF($C$2:$C$233=C28,IF($E$2:$E$233="Yes",IF($B$2:$B$78=B28,$K$2:$K$233)))))/MIN(IF($C$2:$C$233=C28,IF($E$2:$E$233="Yes",IF($B$2:$B$78=B28,$K$2:$K$233))))} -> 0.36 | Q28: Include
A29: Lighting | B29: Residential | C29: General Service Linear >4 ft | D29: LED - 2015 | E29: No | G29: 91 | J29: 89 | K29: =IF(J29="",I29/H29*1000,J29) -> 89 | L29: 44000 | M29: =1/G29/L29*1000 -> 0.00024975025 | N29: =IFERROR(P29/O29,"") -> 63.665745 | O29: {=(MAX(IF($C$2:$C$233=C29,IF($E$2:$E$233="Yes",IF($B$2:$B$78=B29,$M$2:$M$233)))-M29)/MAX(IF($C$2:$C$233=C29,IF($E$2:$E$233="Yes",IF($B$2:$B$78=B29,$M$2:$M$233)))))} -> 0.77522478 | P29: {=(K29-MIN(IF($C$2:$C$233=C29,IF($E$2:$E$233="Yes",IF($B$2:$B$78=B29,$K$2:$K$233)))))/MIN(IF($C$2:$C$233=C29,IF($E$2:$E$233="Yes",IF($B$2:$B$78=B29,$K$2:$K$233))))} -> 49.355263 | Q29: Exclude
A30: Lighting | B30: Residential | C30: General Service Linear >4 ft | D30: LED - 2020 | E30: No | G30: 109 | J30: 60 | K30: =IF(J30="",I30/H30*1000,J30) -> 60 | L30: 49000 | M30: =1/G30/L30*1000 -> 0.00018723086 | N30: =IFERROR(P30/O30,"") -> 39.624385 | O30: {=(MAX(IF($C$2:$C$233=C30,IF($E$2:$E$233="Yes",IF($B$2:$B$78=B30,$M$2:$M$233)))-M30)/MAX(IF($C$2:$C$233=C30,IF($E$2:$E$233="Yes",IF($B$2:$B$78=B30,$M$2:$M$233)))))} -> 0.83149223 | P30: {=(K30-MIN(IF($C$2:$C$233=C30,IF($E$2:$E$233="Yes",IF($B$2:$B$78=B30,$K$2:$K$233)))))/MIN(IF($C$2:$C$233=C30,IF($E$2:$E$233="Yes",IF($B$2:$B$78=B30,$K$2:$K$233))))} -> 32.947368 | Q30: Include
A31: Lighting | B31: Residential | C31: General Service Linear >4 ft | D31: LED - 2030 | E31: No | G31: 132 | J31: 28 | K31: =IF(J31="",I31/H31*1000,J31) -> 28 | L31: 50000 | M31: =1/G31/L31*1000 -> 0.00015151515 | N31: =IFERROR(P31/O31,"") -> 17.185596 | O31: {=(MAX(IF($C$2:$C$233=C31,IF($E$2:$E$233="Yes",IF($B$2:$B$78=B31,$M$2:$M$233)))-M31)/MAX(IF($C$2:$C$233=C31,IF($E$2:$E$233="Yes",IF($B$2:$B$78=B31,$M$2:$M$233)))))} -> 0.86363636 | P31: {=(K31-MIN(IF($C$2:$C$233=C31,IF($E$2:$E$233="Yes",IF($B$2:$B$78=B31,$K$2:$K$233)))))/MIN(IF($C$2:$C$233=C31,IF($E$2:$E$233="Yes",IF($B$2:$B$78=B31,$K$2:$K$233))))} -> 14.842105 | Q31: Include
A32: Lighting | B32: Residential | C32: General Service Linear >4 ft | D32: T12 | E32: Yes | F32: 43 | G32: 75 | H32: =F32*G32 -> 3225 | I32: 5.7 | K32: =IF(J32="",I32/H32*1000,J32) -> 1.7674419 | L32: 12000 | M32: =1/G32/L32*1000 -> 0.0011111111 | N32: =IFERROR(P32/O32,"") | O32: {=(MAX(IF($C$2:$C$233=C32,IF($E$2:$E$233="Yes",IF($B$2:$B$78=B32,$M$2:$M$233)))-M32)/MAX(IF($C$2:$C$233=C32,IF($E$2:$E$233="Yes",IF($B$2:$B$78=B32,$M$2:$M$233)))))} -> 0 | P32: {=(K32-MIN(IF($C$2:$C$233=C32,IF($E$2:$E$233="Yes",IF($B$2:$B$78=B32,$K$2:$K$233)))))/MIN(IF($C$2:$C$233=C32,IF($E$2:$E$233="Yes",IF($B$2:$B$78=B32,$K$2:$K$233))))} -> 0 | Q32: Exclude
A33: Lighting | B33: Residential | C33: General Service Linear >4 ft | D33: T8 | E33: No | F33: 35 | G33: 88 | H33: =F33*G33 -> 3080 | I33: 7 | K33: =IF(J33="",I33/H33*1000,J33) -> 2.2727273 | L33: 18000 | M33: =1/G33/L33*1000 -> 0.00063131313 | N33: =IFERROR(P33/O33,"") -> 0.66204986 | O33: {=(MAX(IF($C$2:$C$233=C33,IF($E$2:$E$233="Yes",IF($B$2:$B$78=B33,$M$2:$M$233)))-M33)/MAX(IF($C$2:$C$233=C33,IF($E$2:$E$233="Yes",IF($B$2:$B$78=B33,$M$2:$M$233)))))} -> 0.43181818 | P33: {=(K33-MIN(IF($C$2:$C$233=C33,IF($E$2:$E$233="Yes",IF($B$2:$B$78=B33,$K$2:$K$233)))))/MIN(IF($C$2:$C$233=C33,IF($E$2:$E$233="Yes",IF($B$2:$B$78=B33,$K$2:$K$233))))} -> 0.28588517 | Q33: Include
A34: Lighting | B34: Residential | C34: General Service Linear 4 ft | D34: LED - 2015 | E34: No | G34: 91 | J34: 89 | K34: =IF(J34="",I34/H34*1000,J34) -> 89 | L34: 44000 | M34: =1/G34/L34*1000 -> 0.00024975025 | N34: =IFERROR(P34/O34,"") -> 94.200141 | O34: {=(MAX(IF($C$2:$C$233=C34,IF($E$2:$E$233="Yes",IF($B$2:$B$78=B34,$M$2:$M$233)))-M34)/MAX(IF($C$2:$C$233=C34,IF($E$2:$E$233="Yes",IF($B$2:$B$78=B34,$M$2:$M$233)))))} -> 0.749001 | P34: {=(K34-MIN(IF($C$2:$C$233=C34,IF($E$2:$E$233="Yes",IF($B$2:$B$78=B34,$K$2:$K$233)))))/MIN(IF($C$2:$C$233=C34,IF($E$2:$E$233="Yes",IF($B$2:$B$78=B34,$K$2:$K$233))))} -> 70.556 | Q34: Exclude
A35: Lighting | B35: Residential | C35: General Service Linear 4 ft | D35: LED - 2020 | E35: No | G35: 109 | J35: 60 | K35: =IF(J35="",I35/H35*1000,J35) -> 60 | L35: 49000 | M35: =1/G35/L35*1000 -> 0.00018723086 | N35: =IFERROR(P35/O35,"") -> 58.189308 | O35: {=(MAX(IF($C$2:$C$233=C35,IF($E$2:$E$233="Yes",IF($B$2:$B$78=B35,$M$2:$M$233)))-M35)/MAX(IF($C$2:$C$233=C35,IF($E$2:$E$233="Yes",IF($B$2:$B$78=B35,$M$2:$M$233)))))} -> 0.81183299 | P35: {=(K35-MIN(IF($C$2:$C$233=C35,IF($E$2:$E$233="Yes",IF($B$2:$B$78=B35,$K$2:$K$233)))))/MIN(IF($C$2:$C$233=C35,IF($E$2:$E$233="Yes",IF($B$2:$B$78=B35,$K$2:$K$233))))} -> 47.24 | Q35: Include
A36: Lighting | B36: Residential | C36: General Service Linear 4 ft | D36: LED - 2030 | E36: No | G36: 132 | J36: 28 | K36: =IF(J36="",I36/H36*1000,J36) -> 28 | L36: 50000 | M36: =1/G36/L36*1000 -> 0.00015151515 | N36: =IFERROR(P36/O36,"") -> 25.376086 | O36: {=(MAX(IF($C$2:$C$233=C36,IF($E$2:$E$233="Yes",IF($B$2:$B$78=B36,$M$2:$M$233)))-M36)/MAX(IF($C$2:$C$233=C36,IF($E$2:$E$233="Yes",IF($B$2:$B$78=B36,$M$2:$M$233)))))} -> 0.84772727 | P36: {=(K36-MIN(IF($C$2:$C$233=C36,IF($E$2:$E$233="Yes",IF($B$2:$B$78=B36,$K$2:$K$233)))))/MIN(IF($C$2:$C$233=C36,IF($E$2:$E$233="Yes",IF($B$2:$B$78=B36,$K$2:$K$233))))} -> 21.512 | Q36: Include
A37: Lighting | B37: Residential | C37: General Service Linear 4 ft | D37: T12 | E37: Yes | F37: 24 | G37: 67 | H37: =F37*G37 -> 1608 | I37: 2 | K37: =IF(J37="",I37/H37*1000,J37) -> 1.2437811 | L37: 15000 | M37: =1/G37/L37*1000 -> 0.00099502488 | N37: =IFERROR(P37/O37,"") | O37: {=(MAX(IF($C$2:$C$233=C37,IF($E$2:$E$233="Yes",IF($B$2:$B$78=B37,$M$2:$M$233)))-M37)/MAX(IF($C$2:$C$233=C37,IF($E$2:$E$233="Yes",IF($B$2:$B$78=B37,$M$2:$M$233)))))} -> 0 | P37: {=(K37-MIN(IF($C$2:$C$233=C37,IF($E$2:$E$233="Yes",IF($B$2:$B$78=B37,$K$2:$K$233)))))/MIN(IF($C$2:$C$233=C37,IF($E$2:$E$233="Yes",IF($B$2:$B$78=B37,$K$2:$K$233))))} -> 0 | Q37: Exclude
A38: Lighting | B38: Residential | C38: General Service Linear 4 ft | D38: T5 | E38: No | F38: 19 | G38: 85 | H38: =F38*G38 -> 1615 | I38: 4.2 | K38: =IF(J38="",I38/H38*1000,J38) -> 2.6006192 | L38: 30000 | M38: =1/G38/L38*1000 -> 0.00039215686 | N38: =IFERROR(P38/O38,"") -> 1.800511 | O38: {=(MAX(IF($C$2:$C$233=C38,IF($E$2:$E$233="Yes",IF($B$2:$B$78=B38,$M$2:$M$233)))-M38)/MAX(IF($C$2:$C$233=C38,IF($E$2:$E$233="Yes",IF($B$2:$B$78=B38,$M$2:$M$233)))))} -> 0.60588235 | P38: {=(K38-MIN(IF($C$2:$C$233=C38,IF($E$2:$E$233="Yes",IF($B$2:$B$78=B38,$K$2:$K$233)))))/MIN(IF($C$2:$C$233=C38,IF($E$2:$E$233="Yes",IF($B$2:$B$78=B38,$K$2:$K$233))))} -> 1.0908978 | Q38: Include
A39: Lighting | B39: Residential | C39: General Service Linear 4 ft | D39: T8 | E39: No | F39: 24 | G39: 76 | H39: =F39*G39 -> 1824 | I39: 2.8 | K39: =IF(J39="",I39/H39*1000,J39) -> 1.5350877 | L39: 21000 | M39: =1/G39/L39*1000 -> 0.00062656642 | N39: =IFERROR(P39/O39,"") -> 0.63248731 | O39: {=(MAX(IF($C$2:$C$233=C39,IF($E$2:$E$233="Yes",IF($B$2:$B$78=B39,$M$2:$M$233)))-M39)/MAX(IF($C$2:$C$233=C39,IF($E$2:$E$233="Yes",IF($B$2:$B$78=B39,$M$2:$M$233)))))} -> 0.37030075 | P39: {=(K39-MIN(IF($C$2:$C$233=C39,IF($E$2:$E$233="Yes",IF($B$2:$B$78=B39,$K$2:$K$233)))))/MIN(IF($C$2:$C$233=C39,IF($E$2:$E$233="Yes",IF($B$2:$B$78=B39,$K$2:$K$233))))} -> 0.23421053 | Q39: Include
A40: Lighting | B40: Commercial | C40: Downlights/Track Lighting - Directional | D40: CFL Directional | E40: No | F40: 59 | G40: 44 | H40: =F40*G40 -> 2596 | I40: 10.1 | K40: =IF(J40="",I40/H40*1000,J40) -> 3.8906009 | L40: 10000 | M40: =1/G40/L40*1000 -> 0.0022727273 | N40: =IFERROR(P40/O40,"") -> -0.92717727 | O40: {=(MAX(IF($C$2:$C$233=C40,IF($E$2:$E$233="Yes",IF($B$2:$B$78=B40,$M$2:$M$233)))-M40)/MAX(IF($C$2:$C$233=C40,IF($E$2:$E$233="Yes",IF($B$2:$B$78=B40,$M$2:$M$233)))))} -> 0.94318182 | P40: {=(K40-MIN(IF($C$2:$C$233=C40,IF($E$2:$E$233="Yes",IF($B$2:$B$78=B40,$K$2:$K$233)))))/MIN(IF($C$2:$C$233=C40,IF($E$2:$E$233="Yes",IF($B$2:$B$78=B40,$K$2:$K$233))))} -> -0.87449674 | Q40: Include
...

Sheet Other Equipment
A1: Product Category | B1: Building Type | C1: Service | D1: Product | E1: Efficiency | F1: Price | G1: Elasticity | H1: % Improvement in Efficency from Base | I1: % Change in Price
A2: Other Equipment | B2: Residential | C2: Dehumidiers | D2: Portable <30 pints/day | E2: 1 | F2: 212 | G2: =IFERROR(I2/H2,"") | H2: {=(E2-MIN(IF($D$2:$D$268=D2,$E$2:$E$268)))/MIN(IF($D$2:$D$268=D2,$E$2:$E$268))} -> 0 | I2: {=(F2-MIN(IF($D$2:$D$268=D2,$F$2:$F$268)))/MIN(IF($D$2:$D$268=D2,$F$2:$F$268))} -> 0
A3: Other Equipment | B3: Residential | C3: Dehumidiers | D3: Portable <30 pints/day | E3: 1.3 | F3: 212 | G3: =IFERROR(I3/H3,"") -> 0 | H3: {=(E3-MIN(IF($D$2:$D$268=D3,$E$2:$E$268)))/MIN(IF($D$2:$D$268=D3,$E$2:$E$268))} -> 0.3 | I3: {=(F3-MIN(IF($D$2:$D$268=D3,$F$2:$F$268)))/MIN(IF($D$2:$D$268=D3,$F$2:$F$268))} -> 0
A4: Other Equipment | B4: Residential | C4: Dehumidiers | D4: Portable <30 pints/day | E4: 1.3583333 | F4: 214 | G4: =IFERROR(I4/H4,"") -> 0.026327337 | H4: {=(E4-MIN(IF($D$2:$D$268=D4,$E$2:$E$268)))/MIN(IF($D$2:$D$268=D4,$E$2:$E$268))} -> 0.35833333 | I4: {=(F4-MIN(IF($D$2:$D$268=D4,$F$2:$F$268)))/MIN(IF($D$2:$D$268=D4,$F$2:$F$268))} -> 0.0094339623
A5: Other Equipment | B5: Residential | C5: Dehumidiers | D5: Portable <30 pints/day | E5: 1.4076923 | F5: 218 | G5: =IFERROR(I5/H5,"") -> 0.069419722 | H5: {=(E5-MIN(IF($D$2:$D$268=D5,$E$2:$E$268)))/MIN(IF($D$2:$D$268=D5,$E$2:$E$268))} -> 0.40769231 | I5: {=(F5-MIN(IF($D$2:$D$268=D5,$F$2:$F$268)))/MIN(IF($D$2:$D$268=D5,$F$2:$F$268))} -> 0.028301887
A6: Other Equipment | B6: Residential | C6: Dehumidiers | D6: Portable <30 pints/day | E6: 1.5095541 | F6: 241 | G6: =IFERROR(I6/H6,"") -> 0.26845519 | H6: {=(E6-MIN(IF($D$2:$D$268=D6,$E$2:$E$268)))/MIN(IF($D$2:$D$268=D6,$E$2:$E$268))} -> 0.50955414 | I6: {=(F6-MIN(IF($D$2:$D$268=D6,$F$2:$F$268)))/MIN(IF($D$2:$D$268=D6,$F$2:$F$268))} -> 0.13679245
A7: Other Equipment | B7: Residential | C7: Dehumidiers | D7: Portable 30-45 pints/day | E7: 1 | F7: 256 | G7: =IFERROR(I7/H7,"") | H7: {=(E7-MIN(IF($D$2:$D$268=D7,$E$2:$E$268)))/MIN(IF($D$2:$D$268=D7,$E$2:$E$268))} -> 0 | I7: {=(F7-MIN(IF($D$2:$D$268=D7,$F$2:$F$268)))/MIN(IF($D$2:$D$268=D7,$F$2:$F$268))} -> 0
A8: Other Equipment | B8: Residential | C8: Dehumidiers | D8: Portable 30-45 pints/day | E8: 1.2166667 | F8: 256 | G8: =IFERROR(I8/H8,"") -> 0 | H8: {=(E8-MIN(IF($D$2:$D$268=D8,$E$2:$E$268)))/MIN(IF($D$2:$D$268=D8,$E$2:$E$268))} -> 0.21666667 | I8: {=(F8-MIN(IF($D$2:$D$268=D8,$F$2:$F$268)))/MIN(IF($D$2:$D$268=D8,$F$2:$F$268))} -> 0
A9: Other Equipment | B9: Residential | C9: Dehumidiers | D9: Portable 30-45 pints/day | E9: 1.3285714 | F9: 259 | G9: =IFERROR(I9/H9,"") -> 0.035665761 | H9: {=(E9-MIN(IF($D$2:$D$268=D9,$E$2:$E$268)))/MIN(IF($D$2:$D$268=D9,$E$2:$E$268))} -> 0.32857143 | I9: {=(F9-MIN(IF($D$2:$D$268=D9,$F$2:$F$268)))/MIN(IF($D$2:$D$268=D9,$F$2:$F$268))} -> 0.01171875
A10: Other Equipment | B10: Residential | C10: Dehumidiers | D10: Portable 30-45 pints/day | E10: 1.4125 | F10: 268 | G10: =IFERROR(I10/H10,"") -> 0.11363636 | H10: {=(E10-MIN(IF($D$2:$D$268=D10,$E$2:$E$268)))/MIN(IF($D$2:$D$268=D10,$E$2:$E$268))} -> 0.4125 | I10: {=(F10-MIN(IF($D$2:$D$268=D10,$F$2:$F$268)))/MIN(IF($D$2:$D$268=D10,$F$2:$F$268))} -> 0.046875
A11: Other Equipment | B11: Residential | C11: Dehumidiers | D11: Portable 30-45 pints/day | E11: 1.4777778 | F11: 290 | G11: =IFERROR(I11/H11,"") -> 0.27797965 | H11: {=(E11-MIN(IF($D$2:$D$268=D11,$E$2:$E$268)))/MIN(IF($D$2:$D$268=D11,$E$2:$E$268))} -> 0.47777778 | I11: {=(F11-MIN(IF($D$2:$D$268=D11,$F$2:$F$268)))/MIN(IF($D$2:$D$268=D11,$F$2:$F$268))} -> 0.1328125
A12: Other Equipment | B12: Residential | C12: Dehumidiers | D12: Portable >45 pints/day | E12: 1 | F12: 915 | G12: =IFERROR(I12/H12,"") | H12: {=(E12-MIN(IF($D$2:$D$268=D12,$E$2:$E$268)))/MIN(IF($D$2:$D$268=D12,$E$2:$E$268))} -> 0 | I12: {=(F12-MIN(IF($D$2:$D$268=D12,$F$2:$F$268)))/MIN(IF($D$2:$D$268=D12,$F$2:$F$268))} -> 0
A13: Other Equipment | B13: Residential | C13: Dehumidiers | D13: Portable >45 pints/day | E13: 1.1375 | F13: 989 | G13: =IFERROR(I13/H13,"") -> 0.58817685 | H13: {=(E13-MIN(IF($D$2:$D$268=D13,$E$2:$E$268)))/MIN(IF($D$2:$D$268=D13,$E$2:$E$268))} -> 0.1375 | I13: {=(F13-MIN(IF($D$2:$D$268=D13,$F$2:$F$268)))/MIN(IF($D$2:$D$268=D13,$F$2:$F$268))} -> 0.080874317
... A73: Other Equipment | B73: Commercial | C73: Pumps | D73: VT-S 3600 | E73: 1.0513491 | F73: 838 | G73: =IFERROR(I73/H73,"") -> 3.6411345 | H73: {=(E73-MIN(IF($D$2:$D$268=D73,$E$2:$E$268)))/MIN(IF($D$2:$D$268=D73,$E$2:$E$268))} -> 0.051349061 | I73: {=(F73-MIN(IF($D$2:$D$268=D73,$F$2:$F$268)))/MIN(IF($D$2:$D$268=D73,$F$2:$F$268))} -> 0.18696884
A74: Other Equipment | B74: Commercial | C74: Electric Motors | D74: NEMA Design B, T-Frame, 5 hp, 4 Poles, Enclosed | E74: =82.5/(100) -> 0.825 | F74: 656 | G74: =IFERROR(I74/H74,"") | H74: {=(E74-MIN(IF($D$2:$D$268=D74,$E$2:$E$268)))/MIN(IF($D$2:$D$268=D74,$E$2:$E$268))} -> 0 | I74: {=(F74-MIN(IF($D$2:$D$268=D74,$F$2:$F$268)))/MIN(IF($D$2:$D$268=D74,$F$2:$F$268))} -> 0
A75: Other Equipment | B75: Commercial | C75: Electric Motors | D75: NEMA Design B, T-Frame, 5 hp, 4 Poles, Enclosed | E75: =87.5/(100) -> 0.875 | F75: 678 | G75: =IFERROR(I75/H75,"") -> 0.55335366 | H75: {=(E75-MIN(IF($D$2:$D$268=D75,$E$2:$E$268)))/MIN(IF($D$2:$D$268=D75,$E$2:$E$268))} -> 0.060606061 | I75: {=(F75-MIN(IF($D$2:$D$268=D75,$F$2:$F$268)))/MIN(IF($D$2:$D$268=D75,$F$2:$F$268))} -> 0.033536585
A76: Other Equipment | B76: Commercial | C76: Electric Motors | D76: NEMA Design B, T-Frame, 5 hp, 4 Poles, Enclosed | E76: =89.5/(100) -> 0.895 | F76: 731 | G76: =IFERROR(I76/H76,"") -> 1.3474521 | H76: {=(E76-MIN(IF($D$2:$D$268=D76,$E$2:$E$268)))/MIN(IF($D$2:$D$268=D76,$E$2:$E$268))} -> 0.084848485 | I76: {=(F76-MIN(IF($D$2:$D$268=D76,$F$2:$F$268)))/MIN(IF($D$2:$D$268=D76,$F$2:$F$268))} -> 0.11432927
A77: Other Equipment | B77: Commercial | C77: Electric Motors | D77: NEMA Design B, T-Frame, 5 hp, 4 Poles, Enclosed | E77: =90.2/(100) -> 0.902 | F77: 789 | G77: =IFERROR(I77/H77,"") -> 2.1722561 | H77: {=(E77-MIN(IF($D$2:$D$268=D77,$E$2:$E$268)))/MIN(IF($D$2:$D$268=D77,$E$2:$E$268))} -> 0.093333333 | I77: {=(F77-MIN(IF($D$2:$D$268=D77,$F$2:$F$268)))/MIN(IF($D$2:$D$268=D77,$F$2:$F$268))} -> 0.2027439
A78: Other Equipment | B78: Commercial | C78: Electric Motors | D78: NEMA Design B, T-Frame, 5 hp, 4 Poles, Enclosed | E78: =91/(100) -> 0.91 | F78: 1237 | G78: =IFERROR(I78/H78,"") -> 8.5962159 | H78: {=(E78-MIN(IF($D$2:$D$268=D78,$E$2:$E$268)))/MIN(IF($D$2:$D$268=D78,$E$2:$E$268))} -> 0.1030303 | I78: {=(F78-MIN(IF($D$2:$D$268=D78,$F$2:$F$268)))/MIN(IF($D$2:$D$268=D78,$F$2:$F$268))} -> 0.88567073
A79: Other Equipment | B79: Commercial | C79: Electric Motors | D79: NEMA Design B, T-Frame, 30 hp, 4 Poles, Enclosed | E79: =89.5/(100) -> 0.895 | F79: 1748 | G79: =IFERROR(I79/H79,"") | H79: {=(E79-MIN(IF($D$2:$D$268=D79,$E$2:$E$268)))/MIN(IF($D$2:$D$268=D79,$E$2:$E$268))} -> 0 | I79: {=(F79-MIN(IF($D$2:$D$268=D79,$F$2:$F$268)))/MIN(IF($D$2:$D$268=D79,$F$2:$F$268))} -> 0
A80: Other Equipment | B80: Commercial | C80: Electric Motors | D80: NEMA Design B, T-Frame, 30 hp, 4 Poles, Enclosed | E80: =92.4/(100) -> 0.924 | F80: 2181 | G80: =IFERROR(I80/H80,"") -> 7.6448947 | H80: {=(E80-MIN(IF($D$2:$D$268=D80,$E$2:$E$268)))/MIN(IF($D$2:$D$268=D80,$E$2:$E$268))} -> 0.032402235 | I80: {=(F80-MIN(IF($D$2:$D$268=D80,$F$2:$F$268)))/MIN(IF($D$2:$D$268=D80,$F$2:$F$268))} -> 0.24771167
A81: Other Equipment | B81: Commercial | C81: Electric Motors | D81: NEMA Design B, T-Frame, 30 hp, 4 Poles, Enclosed | E81: =93.6/(100) -> 0.936 | F81: 2300 | G81: =IFERROR(I81/H81,"") -> 6.8934531 | H81: {=(E81-MIN(IF($D$2:$D$268=D81,$E$2:$E$268)))/MIN(IF($D$2:$D$268=D81,$E$2:$E$268))} -> 0.045810056 | I81: {=(F81-MIN(IF($D$2:$D$268=D81,$F$2:$F$268)))/MIN(IF($D$2:$D$268=D81,$F$2:$F$268))} -> 0.31578947
A82: Other Equipment | B82: Commercial | C82: Electric Motors | D82: NEMA Design B, T-Frame, 30 hp, 4 Poles, Enclosed | E82: =94.1/(100) -> 0.941 | F82: 2559 | G82: =IFERROR(I82/H82,"") -> 9.0270247 | H82: {=(E82-MIN(IF($D$2:$D$268=D82,$E$2:$E$268)))/MIN(IF($D$2:$D$268=D82,$E$2:$E$268))} -> 0.051396648 | I82: {=(F82-MIN(IF($D$2:$D$268=D82,$F$2:$F$268)))/MIN(IF($D$2:$D$268=D82,$F$2:$F$268))} -> 0.46395881
A83: Other Equipment | B83: Commercial | C83: Electric Motors | D83: NEMA Design B, T-Frame, 30 hp, 4 Poles, Enclosed | E83: =94.5/(100) -> 0.945 | F83: 3891 | G83: =IFERROR(I83/H83,"") -> 21.944908 | H83: {=(E83-MIN(IF($D$2:$D$268=D83,$E$2:$E$268)))/MIN(IF($D$2:$D$268=D83,$E$2:$E$268))} -> 0.055865922 | I83: {=(F83-MIN(IF($D$2:$D$268=D83,$F$2:$F$268)))/MIN(IF($D$2:$D$268=D83,$F$2:$F$268))} -> 1.2259725
A84: Other Equipment | B84: Commercial | C84: Electric Motors | D84: NEMA Design B, T-Frame, 75 hp, 4 Poles, Enclosed | E84: =93/(100) -> 0.93 | F84: 3882 | G84: =IFERROR(I84/H84,"") | H84: {=(E84-MIN(IF($D$2:$D$268=D84,$E$2:$E$268)))/MIN(IF($D$2:$D$268=D84,$E$2:$E$268))} -> 0 | I84: {=(F84-MIN(IF($D$2:$D$268=D84,$F$2:$F$268)))/MIN(IF($D$2:$D$268=D84,$F$2:$F$268))} -> 0
A85: Other Equipment | B85: Commercial | C85: Electric Motors | D85: NEMA Design B, T-Frame, 75 hp, 4 Poles, Enclosed | E85: =94.1/(100) -> 0.941 | F85: 4182 | G85: =IFERROR(I85/H85,"") -> 6.5336518 | H85: {=(E85-MIN(IF($D$2:$D$268=D85,$E$2:$E$268)))/MIN(IF($D$2:$D$268=D85,$E$2:$E$268))} -> 0.011827957 | I85: {=(F85-MIN(IF($D$2:$D$268=D85,$F$2:$F$268)))/MIN(IF($D$2:$D$268=D85,$F$2:$F$268))} -> 0.077279753
A86: Other Equipment | B86: Commercial | C86: Electric Motors | D86: NEMA Design B, T-Frame, 75 hp, 4 Poles, Enclosed | E86: =95.4/(100) -> 0.954 | F86: 4692 | G86: =IFERROR(I86/H86,"") -> 8.0853941 | H86: {=(E86-MIN(IF($D$2:$D$268=D86,$E$2:$E$268)))/MIN(IF($D$2:$D$268=D86,$E$2:$E$268))} -> 0.025806452 | I86: {=(F86-MIN(IF($D$2:$D$268=D86,$F$2:$F$268)))/MIN(IF($D$2:$D$268=D86,$F$2:$F$268))} -> 0.20865533
A87: Other Equipment | B87: Commercial | C87: Electric Motors | D87: NEMA Design B, T-Frame, 75 hp, 4 Poles, Enclosed | E87: =95.8/(100) -> 0.958 | F87: 5473 | G87: =IFERROR(I87/H87,"") -> 13.612552 | H87: {=(E87-MIN(IF($D$2:$D$268=D87,$E$2:$E$268)))/MIN(IF($D$2:$D$268=D87,$E$2:$E$268))} -> 0.030107527 | I87: {=(F87-MIN(IF($D$2:$D$268=D87,$F$2:$F$268)))/MIN(IF($D$2:$D$268=D87,$F$2:$F$268))} -> 0.40984029
