Workbook

Sheet About
A1: DACD Direct Air Capture Potential
A2: DACD Direct Air Capture Energy Intensity
A3: DACD Direct Air Capture Amortized CapEx and OM
A5: Sources: | B5: Potential
B6: US Department of State
B7: 2021
B8: The Long-Term Strategy of the United States: Pathways to Net-Zero Greenhouse Gas Emissions by 2050
B9: https://www.whitehouse.gov/wp-content/uploads/2021/10/US-Long-Term-Strategy.pdf
B10: Figure 17
B12: Energy Intensity and CapEx Data
B13: Realmonte et al.
B14: 2019
B15: An inter-model assessment of the role of direct air capture in deep mitigation pathways
B16: https://www.nature.com/articles/s41467-019-10842-5
B17: Table 2
B18: https://static-content.springer.com/esm/art%3A10.1038%2Fs41467-019-10842-5/MediaObjects/41467_2019_10842_MOESM1_ESM.pdf
B19: Supplementary materials, Fig 3
A21: Notes
A22: We use the US Long-Term Strategy to project DAC potential and a
A23: separate source for energy intensity and CapEx calculations.
A25: Amortized CapEx and OM Cost Notes
A26: CapEx here should include the cost of equipment, maintenance, and labor.
A27: Energy costs are calculated separately in the model and should not be included here.

Sheet CDR potential
A1: pixels per 1.25 Gt | B1: 56
A2: pixels to upper range, 2030 | B2: 0
A3: pixels to upper range, 2040 | B3: 4
A4: pixels to upper range, 2050 | B4: 16
A6: 2040 potential (Gt) | B6: =B3/B1*1.25 -> 0.089285714
A7: 2050 potential (Gt) | B7: =B4/B1*1.25 -> 0.35714286
A9: *To be conservative, we choose to measure
A10: to the upper range of the CDR range. CDR
A11: in this report includes DAC as well as several
A12: other potential forms of geoengineering,
A13: meaning it is best to report the conservative
A14: potential.
B16: 2020 | C16: 2030 | D16: 2040 | E16: 2050
A17: potential | B17: 0 | C17: 0 | D17: =B6*10^9 -> 89285714 | E17: =B7*10^9 -> 3.5714286e+08

Sheet Data
A1: DAC Technologies Considered
A2: DAC1 = hydroxide sorbent-based technology, most mature technology, used for large-scale plants, requires high heat (>800C)
A3: DAC2 = amine-based technology, less mature, can be small modular units, can accept waste heat (temp 85-120C)
A5: According to the source paper, DAC1 heat is provided by natural gas, and DAC2 heat is provided by waste heat.
A6: However, the largest currently operating DAC facilities use solid sorbent systems and utilize non-fossil resources at low heat (80-120 C),
A7: see: https://www.wri.org/insights/direct-air-capture-resource-considerations-and-costs-carbon-removal, Status of the Leading DAC Companies.
A8: Therefore, we take the heat input specified for DAC1 plants and convert to the amount of electricity needed
A9: if supplied by a heat pump.
A11: Capital Cost per Ton CO2 Captured (amortized over lifetime of equipment)
A12: The paper indicates these costs include equipment, maintenance, and labor. Energy costs are not included.
A13: $/ton CO2 | B13: DAC1 | C13: DAC2
A14: High | B14: 300 | C14: 350
A15: Low | B15: 180 | C15: 200
A16: Floor | B16: 100 | C16: 50
A18: Electricity Required per Ton CO2 Captured
A19: GJ/ton CO2 | B19: DAC1 | C19: DAC2
A20: High | B20: 1.8 | C20: 1.1
A21: Low | B21: 1.3 | C21: 0.6
A22: Floor
A24: Heat Input Required per Ton CO2 Captured
A25: GJ/ton CO2 | B25: DAC1 | C25: DAC2
A26: High | B26: 8.1 | C26: 7.2
A27: Low | B27: 5.3 | C27: 4.4
A28: Floor
A30: Percent Reduction in Fuel Use with Heat Pump | B30: 0.67 | D30: Source: indst/PIFURfE
A32: Heat Input Required per Ton CO2 Captured, Converted to Electricity
A33: GJ/ton CO2 | B33: DAC1 | C33: DAC2
A34: High | B34: =B26*(1-$B$30) -> 2.673 | C34: =C26*(1-$B$30) -> 2.376
A35: Low | B35: =B27*(1-$B$30) -> 1.749 | C35: =C27*(1-$B$30) -> 1.452
A37: Technology Shares (Supplement Fig 3)
A38: Very little DAC of any sort is deployed before 2045-2050. DAC1 is dominant
A39: until after 2080. Therefore, for the EPS, which extends only to 2050, we
A40: assume the only relevant DAC technology is DAC1.
A62: Global DAC Potential
A63: We will use the 1.5-degree C pathway as our outer potential bound (100% lever setting),
A64: since it is the more aggressive of the two scenarios.
A65: We will measure deployment in specific years to the pixel, since the data are not
A66: provided in tabular form:
B68: 2045 | C68: 2050 | D68: 2060 | E68: 2070 | F68: 2080 | G68: 2090 | H68: 2100
A69: DAC1 (pixels, high zoom) | B69: 0 | C69: 5 | D69: 20 | E69: 122 | F69: 388 | G69: 384 | H69: 379
...

Sheet DACD-potential
A1: metric tons/yr | B1: 2017 | C1: 2018 | D1: 2019 | E1: 2020 | F1: 2021 | G1: 2022 | H1: 2023 | I1: 2024 | J1: 2025 | K1: 2026 | L1: 2027 | M1: 2028 | N1: 2029 | O1: 2030 | P1: 2031 | Q1: 2032 | R1: 2033 | S1: 2034 | T1: 2035 | U1: 2036 | V1: 2037 | W1: 2038 | X1: 2039 | Y1: 2040 | Z1: 2041 | AA1: 2042 | AB1: 2043 | AC1: 2044 | AD1: 2045 | AE1: 2046 | AF1: 2047 | AG1: 2048 | AH1: 2049 | AI1: 2050
A2: DAC Potential | B2: {=TREND('CDR potential'!$B$17:$C$17,'CDR potential'!$B$16:$C$16,'DACD-potential'!B1)} -> 0 | C2: {=TREND('CDR potential'!$B$17:$C$17,'CDR potential'!$B$16:$C$16,'DACD-potential'!C1)} -> 0 | D2: {=TREND('CDR potential'!$B$17:$C$17,'CDR potential'!$B$16:$C$16,'DACD-potential'!D1)} -> 0 | E2: {=TREND('CDR potential'!$B$17:$C$17,'CDR potential'!$B$16:$C$16,'DACD-potential'!E1)} -> 0 | F2: {=TREND('CDR potential'!$B$17:$C$17,'CDR potential'!$B$16:$C$16,'DACD-potential'!F1)} -> 0 | G2: {=TREND('CDR potential'!$B$17:$C$17,'CDR potential'!$B$16:$C$16,'DACD-potential'!G1)} -> 0 | H2: {=TREND('CDR potential'!$B$17:$C$17,'CDR potential'!$B$16:$C$16,'DACD-potential'!H1)} -> 0 | I2: {=TREND('CDR potential'!$B$17:$C$17,'CDR potential'!$B$16:$C$16,'DACD-potential'!I1)} -> 0 | ... N2: {=TREND('CDR potential'!$B$17:$C$17,'CDR potential'!$B$16:$C$16,'DACD-potential'!N1)} -> 0 | O2: {=TREND('CDR potential'!$C$17:$D$17,'CDR potential'!$C$16:$D$16,'DACD-potential'!O1)} -> 0 | P2: {=TREND('CDR potential'!$C$17:$D$17,'CDR potential'!$C$16:$D$16,'DACD-potential'!P1)} -> 8928571.4 | Q2: {=TREND('CDR potential'!$C$17:$D$17,'CDR potential'!$C$16:$D$16,'DACD-potential'!Q1)} -> 17857143 | R2: {=TREND('CDR potential'!$C$17:$D$17,'CDR potential'!$C$16:$D$16,'DACD-potential'!R1)} -> 26785714 | S2: {=TREND('CDR potential'!$C$17:$D$17,'CDR potential'!$C$16:$D$16,'DACD-potential'!S1)} -> 35714286 | T2: {=TREND('CDR potential'!$C$17:$D$17,'CDR potential'!$C$16:$D$16,'DACD-potential'!T1)} -> 44642857 | U2: {=TREND('CDR potential'!$C$17:$D$17,'CDR potential'!$C$16:$D$16,'DACD-potential'!U1)} -> 53571429 | V2: {=TREND('CDR potential'!$C$17:$D$17,'CDR potential'!$C$16:$D$16,'DACD-potential'!V1)} -> 62500000 | ... X2: {=TREND('CDR potential'!$C$17:$D$17,'CDR potential'!$C$16:$D$16,'DACD-potential'!X1)} -> 80357143 | Y2: {=TREND('CDR potential'!$D$17:$E$17,'CDR potential'!$D$16:$E$16,'DACD-potential'!Y1)} -> 89285714 | Z2: {=TREND('CDR potential'!$D$17:$E$17,'CDR potential'!$D$16:$E$16,'DACD-potential'!Z1)} -> 1.1607143e+08 | AA2: {=TREND('CDR potential'!$D$17:$E$17,'CDR potential'!$D$16:$E$16,'DACD-potential'!AA1)} -> 1.4285714e+08 | AB2: {=TREND('CDR potential'!$D$17:$E$17,'CDR potential'!$D$16:$E$16,'DACD-potential'!AB1)} -> 1.6964286e+08 | AC2: {=TREND('CDR potential'!$D$17:$E$17,'CDR potential'!$D$16:$E$16,'DACD-potential'!AC1)} -> 1.9642857e+08 | AD2: {=TREND('CDR potential'!$D$17:$E$17,'CDR potential'!$D$16:$E$16,'DACD-potential'!AD1)} -> 2.2321429e+08 | AE2: {=TREND('CDR potential'!$D$17:$E$17,'CDR potential'!$D$16:$E$16,'DACD-potential'!AE1)} -> 250000000 | AF2: {=TREND('CDR potential'!$D$17:$E$17,'CDR potential'!$D$16:$E$16,'DACD-potential'!AF1)} -> 2.7678571e+08 | ... AI2: {=TREND('CDR potential'!$D$17:$E$17,'CDR potential'!$D$16:$E$16,'DACD-potential'!AI1)} -> 3.5714286e+08

Sheet DACD-energyintensity
A1: BTU/metric ton CO2 | B1: 2017 | C1: 2018 | D1: 2019 | E1: 2020 | F1: 2021 | G1: 2022 | H1: 2023 | I1: 2024 | J1: 2025 | K1: 2026 | L1: 2027 | M1: 2028 | N1: 2029 | O1: 2030 | P1: 2031 | Q1: 2032 | R1: 2033 | S1: 2034 | T1: 2035 | U1: 2036 | V1: 2037 | W1: 2038 | X1: 2039 | Y1: 2040 | Z1: 2041 | AA1: 2042 | AB1: 2043 | AC1: 2044 | AD1: 2045 | AE1: 2046 | AF1: 2047 | AG1: 2048 | AH1: 2049 | AI1: 2050
A2: electricity | B2: =(Data!B20+Data!B34)*Data!B103 -> 4236315.7 | C2: =$B2 -> 4236315.7 | D2: =$B2 -> 4236315.7 | E2: =$B2 -> 4236315.7 | F2: =$B2 -> 4236315.7 | G2: =$B2 -> 4236315.7 | H2: =$B2 -> 4236315.7 | I2: =$B2 -> 4236315.7 | J2: =$B2 -> 4236315.7 | ... AI2: =$B2 -> 4236315.7
A3: coal | B3: 0 | C3: =$B3 -> 0 | D3: =$B3 -> 0 | E3: =$B3 -> 0 | F3: =$B3 -> 0 | G3: =$B3 -> 0 | H3: =$B3 -> 0 | I3: =$B3 -> 0 | J3: =$B3 -> 0 | ... AI3: =$B3 -> 0
A4: natural gas | B4: 0 | C4: =$B4 -> 0 | D4: =$B4 -> 0 | E4: =$B4 -> 0 | F4: =$B4 -> 0 | G4: =$B4 -> 0 | H4: =$B4 -> 0 | I4: =$B4 -> 0 | J4: =$B4 -> 0 | ... AI4: =$B4 -> 0
A5: biomass | B5: 0 | C5: =$B5 -> 0 | D5: =$B5 -> 0 | E5: =$B5 -> 0 | F5: =$B5 -> 0 | G5: =$B5 -> 0 | H5: =$B5 -> 0 | I5: =$B5 -> 0 | J5: =$B5 -> 0 | ... AI5: =$B5 -> 0
A6: petroleum diesel | B6: 0 | C6: =$B6 -> 0 | D6: =$B6 -> 0 | E6: =$B6 -> 0 | F6: =$B6 -> 0 | G6: =$B6 -> 0 | H6: =$B6 -> 0 | I6: =$B6 -> 0 | J6: =$B6 -> 0 | ... AI6: =$B6 -> 0
A7: heat | B7: 0 | C7: =$B7 -> 0 | D7: =$B7 -> 0 | E7: =$B7 -> 0 | F7: =$B7 -> 0 | G7: =$B7 -> 0 | H7: =$B7 -> 0 | I7: =$B7 -> 0 | J7: =$B7 -> 0 | ... AI7: =$B7 -> 0
A8: crude oil | B8: 0 | C8: =$B8 -> 0 | D8: =$B8 -> 0 | E8: =$B8 -> 0 | F8: =$B8 -> 0 | G8: =$B8 -> 0 | H8: =$B8 -> 0 | I8: =$B8 -> 0 | J8: =$B8 -> 0 | ... AI8: =$B8 -> 0
A9: heavy or residual fuel oil | B9: 0 | C9: =$B9 -> 0 | D9: =$B9 -> 0 | E9: =$B9 -> 0 | F9: =$B9 -> 0 | G9: =$B9 -> 0 | H9: =$B9 -> 0 | I9: =$B9 -> 0 | J9: =$B9 -> 0 | ... AI9: =$B9 -> 0
A10: LPG propane or butane | B10: 0 | C10: =$B10 -> 0 | D10: =$B10 -> 0 | E10: =$B10 -> 0 | F10: =$B10 -> 0 | G10: =$B10 -> 0 | H10: =$B10 -> 0 | I10: =$B10 -> 0 | J10: =$B10 -> 0 | ... AI10: =$B10 -> 0
A11: hydrogen | B11: 0 | C11: =$B11 -> 0 | D11: =$B11 -> 0 | E11: =$B11 -> 0 | F11: =$B11 -> 0 | G11: =$B11 -> 0 | H11: =$B11 -> 0 | I11: =$B11 -> 0 | J11: =$B11 -> 0 | ... AI11: =$B11 -> 0

Sheet DACD-capex
A1: $/metric ton CO2 | B1: 2017 | C1: 2018 | D1: 2019 | E1: 2020 | F1: 2021 | G1: 2022 | H1: 2023 | I1: 2024 | J1: 2025 | K1: 2026 | L1: 2027 | M1: 2028 | N1: 2029 | O1: 2030 | P1: 2031 | Q1: 2032 | R1: 2033 | S1: 2034 | T1: 2035 | U1: 2036 | V1: 2037 | W1: 2038 | X1: 2039 | Y1: 2040 | Z1: 2041 | AA1: 2042 | AB1: 2043 | AC1: 2044 | AD1: 2045 | AE1: 2046 | AF1: 2047 | AG1: 2048 | AH1: 2049 | AI1: 2050
A2: amortized CapEx | B2: =Data!B14 -> 300 | C2: =$B2 -> 300 | D2: =$B2 -> 300 | E2: =$B2 -> 300 | F2: =$B2 -> 300 | G2: =$B2 -> 300 | H2: =$B2 -> 300 | I2: =$B2 -> 300 | J2: =$B2 -> 300 | ... AI2: =$B2 -> 300
