Workbook
Name gal_per_barrel: [1]About!$A$63

Sheet About
A1: BIFUbC BAU Industrial Fuel Use before CCS
A3: Sources: | B3: All Subscripts Except Waste Management
B4: Energy Information Administration
B5: 2021, 2022
B6: Annual Energy Outlook 2021 and 2022
B7: https://www.eia.gov/outlooks/aeo/tables_side.php
B8: See below for listing of which tables are used for which data
B10: 2020 Values
B11: provided on request from EIA
B12: indusa tab
B14: Waste Management
B15: Energy Information Administration
B16: 2021
B17: Miscellaneous Electric Load Consumption Characterization 2021 Update
B18: https://www.eia.gov/analysis/studies/demand/miscelectric/pdf/miscelectric.pdf
B21: Reallocating Portions of "Balance of Manufacturing" to Specific Industry Categories
B22: U.S. Bureau of Economic Analysis
B23: 2012
B24: Input-Output Accounts Data
B25: https://www.bea.gov/industry/input-output-accounts-data
B26: "Use of Commodities by Industry" table, 405-industry breakdown
A28: Note:
A29: The words "before CCS" in this variable name indicate that this is the fuel use by industry, excluding
A30: any fuel used to power the energy-intensive process of carbon capture and sequestration. If any CCS
A31: is performed by Industry in the BAU case, this is handled in CCS sector input variables, not here.
A33: EIA Data Source and Adjustments
A34: The AEO 2022 model was rebased to EIA's 2018 Manufacturing Energy Consumption Survey, which means there are some significant
A35: differences between consumption between AEO 2021 and AEO 2022. Rather than take 2020 values directly from AEO 2021, we use a file
A36: provided by the EIA which extends the 2018 MECS data back to year 2018.
A38: The following table provides a key to the AEO data sources available for each EPS Industry Category:
B40: EPS Industry Category | C40: AEO Data Source
B41: agriculture and forestry 01T03 | C41: Table 34
B42: coal mining 05 | C42: EIA indusa data set (contains more breakout than the regular AEO)
B43: oil and gas extraction 06 | C43: EIA indusa data set (contains more breakout than the regular AEO)
B44: other mining and quarrying 07T08 | C44: EIA indusa data set (contains more breakout than the regular AEO)
B45: food beverage and tobacco 10T12 | C45: Table 25 (only includes food, beverages and tobacco are part of "balance of manufacturing" in Table 33)
B46: textiles apparel and leather 13T15 | C46: AEO includes this in "balance of manufacturing" in Table 33.
B47: wood products 16 | C47: Table 33 (excludes furniture, which is part of "balance of manufacturing" in Table 33)
B48: pulp paper and printing 17T18 | C48: Table 26 (only includes pulp and paper, printing services are part of "balance of manufacturing" in Table 33)
B49: refined petroleum and coke 19 | C49: Table 24
...

Sheet AEO T11 Petroleum 2022
B1: lowmacro.d011222a | C1: 2021 | D1: 2022 | E1: 2023 | F1: 2024 | G1: 2025 | H1: 2026 | I1: 2027 | J1: 2028 | K1: 2029 | L1: 2030 | M1: 2031 | N1: 2032 | O1: 2033 | P1: 2034 | Q1: 2035 | R1: 2036 | S1: 2037 | T1: 2038 | U1: 2039 | V1: 2040 | W1: 2041 | X1: 2042 | Y1: 2043 | Z1: 2044 | AA1: 2045 | AB1: 2046 | AC1: 2047 | AD1: 2048 | AE1: 2049 | AF1: 2050
A4: PSD000 | B4: 11. Petroleum and Other Liquids Supply and Disposition | AG4: Average
B5: (million barrels per day, unless otherwise noted) | AG5: Annual
AG6: Change
B7: Supply and Disposition | C7: 2021 | D7: 2022 | E7: 2023 | F7: 2024 | G7: 2025 | H7: 2026 | I7: 2027 | J7: 2028 | K7: 2029 | L7: 2030 | M7: 2031 | N7: 2032 | O7: 2033 | P7: 2034 | Q7: 2035 | R7: 2036 | S7: 2037 | T7: 2038 | U7: 2039 | V7: 2040 | W7: 2041 | X7: 2042 | Y7: 2043 | Z7: 2044 | AA7: 2045 | AB7: 2046 | AC7: 2047 | AD7: 2048 | AE7: 2049 | AF7: 2050 | AG7: 2021–2050
B9: Crude Oil
A10: PSD000:ba_DomesticCrude | B10: Domestic Crude Production 1/ | C10: 11.13137 | D10: 11.889478 | E10: 12.275469 | F10: 12.609236 | G10: 13.052148 | H10: 13.237693 | I10: 13.193173 | J10: 13.348814 | K10: 13.321289 | L10: 13.279312 | M10: 13.144327 | N10: 13.016207 | O10: 13.009095 | P10: 12.840246 | Q10: 12.759727 | R10: 12.67831 | S10: 12.545458 | T10: 12.455381 | U10: 12.459658 | V10: 12.500587 | W10: 12.419264 | X10: 12.381392 | Y10: 12.382156 | Z10: 12.307539 | AA10: 12.451011 | AB10: 12.532495 | AC10: 12.548349 | AD10: 12.492279 | AE10: 12.350566 | AF10: 12.663138 | AG10: 0.004456
A11: PSD000:ba_Alaska | B11: Alaska | C11: 0.440285 | D11: 0.413283 | E11: 0.394 | F11: 0.410075 | G11: 0.45657 | H11: 0.480052 | I11: 0.509854 | J11: 0.555656 | K11: 0.565951 | L11: 0.603593 | M11: 0.603082 | N11: 0.632631 | O11: 0.655834 | P11: 0.608421 | Q11: 0.562587 | R11: 0.523475 | S11: 0.489129 | T11: 0.457713 | U11: 0.427311 | V11: 0.399117 | W11: 0.372766 | X11: 0.387112 | Y11: 0.440329 | Z11: 0.49331 | AA11: 0.536112 | AB11: 0.537997 | AC11: 0.541833 | AD11: 0.604909 | AE11: 0.640281 | AF11: 0.704812 | AG11: 0.016357
A12: PSD000:ba_Lower48States | B12: Lower 48 States | C12: 10.691085 | D12: 11.476194 | E12: 11.881469 | F12: 12.199161 | G12: 12.595578 | H12: 12.757642 | I12: 12.683319 | J12: 12.793159 | K12: 12.755339 | L12: 12.675718 | M12: 12.541245 | N12: 12.383576 | O12: 12.353261 | P12: 12.231825 | Q12: 12.197142 | R12: 12.154836 | S12: 12.05633 | T12: 11.997668 | U12: 12.032348 | V12: 12.10147 | W12: 12.046497 | X12: 11.99428 | Y12: 11.941829 | Z12: 11.814229 | AA12: 11.914899 | AB12: 11.994498 | AC12: 12.006516 | AD12: 11.88737 | AE12: 11.710285 | AF12: 11.958327 | AG12: 0.00387
A13: PSD000:ba_NetImports | B13: Net Imports | C13: 3.23714 | D13: 4.19416 | E13: 4.152548 | F13: 3.877034 | G13: 3.537109 | H13: 3.305701 | I13: 3.298764 | J13: 3.111144 | K13: 3.134891 | L13: 3.133256 | M13: 3.141488 | N13: 3.378828 | O13: 3.304003 | P13: 3.387724 | Q13: 3.415774 | R13: 3.391183 | S13: 3.476847 | T13: 3.582338 | U13: 3.488359 | V13: 3.408924 | W13: 3.503948 | X13: 3.492462 | Y13: 3.525169 | Z13: 3.600249 | AA13: 3.368079 | AB13: 3.282752 | AC13: 3.169615 | AD13: 3.263203 | AE13: 3.406638 | AF13: 3.071324 | AG13: -0.001812
A14: PSD000:ba_GrossImports | B14: Gross Imports | C14: 6.263 | D14: 7.443 | E14: 7.518854 | F14: 7.215144 | G14: 6.878153 | H14: 6.604451 | I14: 6.609701 | J14: 6.468909 | K14: 6.427916 | L14: 6.403545 | M14: 6.487971 | N14: 6.648247 | O14: 6.573159 | P14: 6.718789 | Q14: 6.754125 | R14: 6.894927 | S14: 6.952014 | T14: 7.049026 | U14: 7.080949 | V14: 6.935089 | W14: 6.929074 | X14: 6.847743 | Y14: 6.697597 | Z14: 6.841123 | AA14: 6.528656 | AB14: 6.363351 | AC14: 6.282736 | AD14: 6.371989 | AE14: 6.519814 | AF14: 6.194175 | AG14: -0.000381
A15: PSD000:ba_Exports | B15: Exports | C15: 3.02586 | D15: 3.24884 | E15: 3.366306 | F15: 3.33811 | G15: 3.341043 | H15: 3.298751 | I15: 3.310937 | J15: 3.357765 | K15: 3.293025 | L15: 3.270289 | M15: 3.346483 | N15: 3.269419 | O15: 3.269156 | P15: 3.331066 | Q15: 3.338351 | R15: 3.503744 | S15: 3.475167 | T15: 3.466688 | U15: 3.59259 | V15: 3.526165 | W15: 3.425126 | X15: 3.355281 | Y15: 3.172428 | Z15: 3.240875 | AA15: 3.160577 | AB15: 3.080599 | AC15: 3.113122 | AD15: 3.108786 | AE15: 3.113176 | AF15: 3.122851 | AG15: 0.001089
A16: PSD000:ba_OtherCrudeSup | B16: Other Crude Supply 2/ | C16: 0.741 | D16: 0.203 | E16: 0.09795 | F16: 0.111 | G16: 0.05411 | H16: 0.10617 | I16: 0.10548 | J16: 0.07008 | K16: 0.06 | L16: 0.06 | M16: 0.06 | N16: 0 | O16: 0 | P16: 0 | Q16: 0 | R16: 0 | S16: 0 | T16: 0 | U16: 0 | V16: 0 | W16: 0 | X16: 0 | Y16: 0 | Z16: 0 | AA16: 0 | AB16: 0 | AC16: 0 | AD16: 0 | AE16: 0 | AF16: 0 | AG16: --
A17: PSD000:ba_TotalCrudeSup | B17: Total Crude Supply | C17: 15.109509 | D17: 16.286636 | E17: 16.525967 | F17: 16.597269 | G17: 16.643366 | H17: 16.649565 | I17: 16.597418 | J17: 16.530037 | K17: 16.51618 | L17: 16.472569 | M17: 16.345816 | N17: 16.395035 | O17: 16.313099 | P17: 16.22797 | Q17: 16.175501 | R17: 16.069494 | S17: 16.022305 | T17: 16.03772 | U17: 15.948017 | V17: 15.90951 | W17: 15.923212 | X17: 15.873854 | Y17: 15.907325 | Z17: 15.907787 | AA17: 15.81909 | AB17: 15.815247 | AC17: 15.717964 | AD17: 15.755483 | AE17: 15.757204 | AF17: 15.734463 | AG17: 0.001399
A19: PSD000:ca_NetProductImp | B19: Net Product Imports | C19: -3.404 | D19: -4.227 | E19: -4.772481 | F19: -5.014002 | G19: -5.141753 | H19: -5.107935 | I19: -5.031907 | J19: -5.008404 | K19: -5.134243 | L19: -5.219859 | M19: -5.125083 | N19: -5.179778 | O19: -5.092685 | P19: -5.112258 | Q19: -5.131105 | R19: -5.048989 | S19: -4.998381 | T19: -5.033622 | U19: -4.957439 | V19: -4.970531 | W19: -4.990724 | X19: -4.983805 | Y19: -5.049411 | Z19: -5.049631 | AA19: -5.000953 | AB19: -4.925579 | AC19: -4.780752 | AD19: -4.823569 | AE19: -4.789707 | AF19: -4.669329 | AG19: 0.010958
A20: PSD000:ca_GrossRefinedP | B20: Gross Refined Product Imports 3/ | C20: 1.045 | D20: 0.9 | E20: 0.540965 | F20: 0.536901 | G20: 0.573851 | H20: 0.625459 | I20: 0.64564 | J20: 0.644276 | K20: 0.628917 | L20: 0.637546 | M20: 0.635343 | N20: 0.65362 | O20: 0.653357 | P20: 0.653217 | Q20: 0.657973 | R20: 0.64936 | S20: 0.655096 | T20: 0.663124 | U20: 0.667046 | V20: 0.672157 | W20: 0.674622 | X20: 0.671073 | Y20: 0.676214 | Z20: 0.682098 | AA20: 0.690336 | AB20: 0.693412 | AC20: 0.707709 | AD20: 0.739248 | AE20: 0.7327 | AF20: 0.713065 | AG20: -0.013093
A21: PSD000:ca_UnfinishedOil | B21: Unfinished Oil Imports | C21: 0.601 | D21: 0.649 | E21: 0.632151 | F21: 0.646594 | G21: 0.64619 | H21: 0.599061 | I21: 0.597109 | J21: 0.595101 | K21: 0.584598 | L21: 0.582763 | M21: 0.589303 | N21: 0.579093 | O21: 0.577258 | P21: 0.575457 | Q21: 0.573956 | R21: 0.572121 | S21: 0.569918 | T21: 0.568292 | U21: 0.566248 | V21: 0.564759 | W21: 0.562567 | X21: 0.560732 | Y21: 0.558897 | Z21: 0.557062 | AA21: 0.555227 | AB21: 0.553392 | AC21: 0.551189 | AD21: 0.549354 | AE21: 0.54752 | AF21: 0.545685 | AG21: -0.003324
A22: PSD000:ca_BlendingCompo | B22: Blending Component Imports | C22: 0.53 | D22: 0.486 | E22: 0.602196 | F22: 0.628687 | G22: 0.639088 | H22: 0.613078 | I22: 0.563574 | J22: 0.524183 | K22: 0.49522 | L22: 0.474248 | M22: 0.438696 | N22: 0.430674 | O22: 0.411511 | P22: 0.396547 | Q22: 0.382388 | R22: 0.36969 | S22: 0.364156 | T22: 0.361914 | U22: 0.3574 | V22: 0.351959 | W22: 0.362047 | X22: 0.369328 | Y22: 0.36953 | Z22: 0.372241 | AA22: 0.377206 | AB22: 0.382094 | AC22: 0.385815 | AD22: 0.398275 | AE22: 0.402593 | AF22: 0.407672 | AG22: -0.009008
A23: PSD000:ca_Exports | B23: Exports | C23: 5.58 | D23: 6.262 | E23: 6.547793 | F23: 6.826184 | G23: 7.000882 | H23: 6.945532 | I23: 6.838229 | J23: 6.771964 | K23: 6.842978 | L23: 6.914416 | M23: 6.788424 | N23: 6.843165 | O23: 6.73481 | P23: 6.737479 | Q23: 6.745421 | R23: 6.640161 | S23: 6.587552 | T23: 6.626952 | U23: 6.548133 | V23: 6.559406 | W23: 6.589959 | X23: 6.584939 | Y23: 6.654051 | Z23: 6.661032 | AA23: 6.623722 | AB23: 6.554478 | AC23: 6.425466 | AD23: 6.510446 | AE23: 6.472519 | AF23: 6.335751 | AG23: 0.00439
A24: PSD000:ca_RefineryProce | B24: Refinery Processing Gain 4/ | C24: 0.96 | D24: 1.073 | E24: 1.000602 | F24: 0.964999 | G24: 0.975629 | H24: 0.988506 | I24: 0.966193 | J24: 0.980392 | K24: 0.989076 | L24: 1.004136 | M24: 0.997323 | N24: 1.004319 | O24: 1.008479 | P24: 1.033908 | Q24: 1.031711 | R24: 1.059599 | S24: 1.071261 | T24: 1.078428 | U24: 1.082535 | V24: 1.079149 | W24: 1.083481 | X24: 1.076755 | Y24: 1.067527 | Z24: 1.074581 | AA24: 1.065435 | AB24: 1.055148 | AC24: 1.050167 | AD24: 1.069102 | AE24: 1.078147 | AF24: 1.077413 | AG24: 0.003987
A25: PSD000:ProductStockDraw | B25: Product Stock Withdrawal | C25: 0.207 | D25: -0.116 | E25: 0 | F25: 0 | G25: 0 | H25: 0 | I25: 0 | J25: 0 | K25: 0 | L25: 0 | M25: 0 | N25: 0 | O25: 0 | P25: 0 | Q25: 0 | R25: 0 | S25: 0 | T25: 0 | U25: 0 | V25: 0 | W25: 0 | X25: 0 | Y25: 0 | Z25: 0 | AA25: 0 | AB25: 0 | AC25: 0 | AD25: 0 | AE25: 0 | AF25: 0 | AG25: --
A26: PSD000:ca_NaturalGasPla | B26: Natural Gas Plant Liquids | C26: 5.352244 | D26: 5.818853 | E26: 6.095093 | F26: 6.199161 | G26: 6.308229 | H26: 6.261226 | I26: 6.207613 | J26: 6.196386 | K26: 6.238307 | L26: 6.296646 | M26: 6.319704 | N26: 6.376586 | O26: 6.356655 | P26: 6.371484 | Q26: 6.396303 | R26: 6.344337 | S26: 6.319689 | T26: 6.321146 | U26: 6.362522 | V26: 6.400144 | W26: 6.414342 | X26: 6.498267 | Y26: 6.582048 | Z26: 6.570409 | AA26: 6.653749 | AB26: 6.681746 | AC26: 6.699253 | AD26: 6.707251 | AE26: 6.71034 | AF26: 6.747999 | AG26: 0.008023
A27: PSD000:from_Renewables | B27: Biofuels | C27: 1.070721 | D27: 1.155702 | E27: 1.136121 | F27: 1.134927 | G27: 1.134589 | H27: 1.133988 | I27: 1.132913 | J27: 1.131853 | K27: 1.130931 | L27: 1.130589 | M27: 1.130702 | N27: 1.130502 | O27: 1.130834 | P27: 1.130965 | Q27: 1.130826 | R27: 1.130789 | S27: 1.131159 | T27: 1.136443 | U27: 1.133184 | V27: 1.152908 | W27: 1.161384 | X27: 1.170208 | Y27: 1.178721 | Z27: 1.192037 | AA27: 1.202371 | AB27: 1.212905 | AC27: 1.225209 | AD27: 1.236486 | AE27: 1.251456 | AF27: 1.262136 | AG27: 0.005688
A28: PSD000:cb_TotalEthanol | B28: Ethanol (undenatured) | C28: 0.867395 | D28: 0.8941 | E28: 0.908598 | F28: 0.905286 | G28: 0.904918 | H28: 0.903162 | I28: 0.900128 | J28: 0.897371 | K28: 0.894905 | L28: 0.894096 | M28: 0.894649 | N28: 0.894581 | O28: 0.895917 | P28: 0.896592 | Q28: 0.896857 | R28: 0.896703 | S28: 0.897726 | T28: 0.899582 | U28: 0.902747 | V28: 0.907048 | W28: 0.910808 | X28: 0.915285 | Y28: 0.920009 | Z28: 0.925335 | AA28: 0.931836 | AB28: 0.939975 | AC28: 0.948851 | AD28: 0.95778 | AE28: 0.967349 | AF28: 0.978649 | AG28: 0.00417
A29: PSD000:ca_DomesticEthan | B29: Domestic Production | C29: 0.943897 | D29: 0.976075 | E29: 1.018353 | F29: 1.017787 | G29: 1.025995 | H29: 1.027261 | I29: 1.02733 | J29: 1.027758 | K29: 1.034911 | L29: 1.037597 | M29: 1.041743 | N29: 1.044947 | O29: 1.048755 | P29: 1.052864 | Q29: 1.059217 | R29: 1.063121 | S29: 1.068312 | T29: 1.074434 | U29: 1.090108 | V29: 1.090747 | W29: 1.100781 | X29: 1.108286 | Y29: 1.117845 | Z29: 1.137318 | AA29: 1.149122 | AB29: 1.162655 | AC29: 1.17697 | AD29: 1.191685 | AE29: 1.207161 | AF29: 1.226783 | AG29: 0.00908
A30: PSD000:ca_EthanolImport | B30: Net Imports | C30: -0.076502 | D30: -0.081975 | E30: -0.109756 | F30: -0.1125 | G30: -0.121077 | H30: -0.124098 | I30: -0.127202 | J30: -0.130387 | K30: -0.140006 | L30: -0.143501 | M30: -0.147094 | N30: -0.150366 | O30: -0.152838 | P30: -0.156272 | Q30: -0.16236 | R30: -0.166418 | S30: -0.170586 | T30: -0.174851 | U30: -0.187361 | V30: -0.1837 | W30: -0.189973 | X30: -0.193001 | Y30: -0.197836 | Z30: -0.211983 | AA30: -0.217286 | AB30: -0.22268 | AC30: -0.228118 | AD30: -0.233905 | AE30: -0.239811 | AF30: -0.248134 | AG30: 0.041409
A31: PSD000:ca_EthanolWithdr | B31: Stock Withdrawal | C31: 0 | D31: 0 | E31: 0 | F31: 0 | G31: 0 | H31: 0 | I31: 0 | J31: 0 | K31: 0 | L31: 0 | M31: 0 | N31: 0 | O31: 0 | P31: 0 | Q31: 0 | R31: 0 | S31: 0 | T31: 0 | U31: 0 | V31: 0 | W31: 0 | X31: 0 | Y31: 0 | Z31: 0 | AA31: 0 | AB31: 0 | AC31: 0 | AD31: 0 | AE31: 0 | AF31: 0 | AG31: --
A32: PSD000:cb_TotalBiodiesl | B32: Biodiesel | C32: 0.10957 | D32: 0.12343 | E32: 0.085491 | F32: 0.087156 | G32: 0.086575 | H32: 0.087775 | I32: 0.089271 | J32: 0.089958 | K32: 0.091673 | L32: 0.09195 | M32: 0.091554 | N32: 0.090458 | O32: 0.08909 | P32: 0.08837 | Q32: 0.087067 | R32: 0.087809 | S32: 0.088052 | T32: 0.090187 | U32: 0.090393 | V32: 0.102889 | W32: 0.105504 | X32: 0.108863 | Y32: 0.110526 | Z32: 0.116439 | AA32: 0.118634 | AB32: 0.119738 | AC32: 0.12037 | AD32: 0.121144 | AE32: 0.121403 | AF32: 0.122203 | AG32: --
A33: PSD000:cb_DomesticBiodi | B33: Domestic Production | C33: 0.112 | D33: 0.125859 | E33: 0.077513 | F33: 0.079138 | G33: 0.078517 | H33: 0.079676 | I33: 0.081133 | J33: 0.081779 | K33: 0.083453 | L33: 0.083689 | M33: 0.083251 | N33: 0.082114 | O33: 0.080704 | P33: 0.079942 | Q33: 0.078597 | R33: 0.079297 | S33: 0.079497 | T33: 0.081589 | U33: 0.081753 | V33: 0.094205 | W33: 0.096776 | X33: 0.100092 | Y33: 0.101712 | Z33: 0.10758 | AA33: 0.109731 | AB33: 0.110791 | AC33: 0.111378 | AD33: 0.112106 | AE33: 0.11232 | AF33: 0.113075 | AG33: 0.000329
A34: PSD000:cb_BiodieselImpo | B34: Net Imports | C34: -0.00243 | D34: -0.00243 | E34: 0.007978 | F34: 0.008018 | G34: 0.008058 | H34: 0.008098 | I34: 0.008139 | J34: 0.00818 | K34: 0.00822 | L34: 0.008262 | M34: 0.008303 | N34: 0.008344 | O34: 0.008386 | P34: 0.008428 | Q34: 0.00847 | R34: 0.008512 | S34: 0.008555 | T34: 0.008598 | U34: 0.008641 | V34: 0.008684 | W34: 0.008727 | X34: 0.008771 | Y34: 0.008815 | Z34: 0.008859 | AA34: 0.008903 | AB34: 0.008948 | AC34: 0.008993 | AD34: 0.009038 | AE34: 0.009083 | AF34: 0.009128 | AG34: --
A35: PSD000:cb_BiodieselWith | B35: Stock Withdrawal | C35: 0 | D35: 0 | E35: 0 | F35: 0 | G35: 0 | H35: 0 | I35: 0 | J35: 0 | K35: 0 | L35: 0 | M35: 0 | N35: 0 | O35: 0 | P35: 0 | Q35: 0 | R35: 0 | S35: 0 | T35: 0 | U35: 0 | V35: 0 | W35: 0 | X35: 0 | Y35: 0 | Z35: 0 | AA35: 0 | AB35: 0 | AC35: 0 | AD35: 0 | AE35: 0 | AF35: 0 | AG35: --
A36: PSD000:Other_BM-derived | B36: Other Biomass-derived Liquids 5/ | C36: 0.093755 | D36: 0.138173 | E36: 0.142032 | F36: 0.142485 | G36: 0.143096 | H36: 0.143051 | I36: 0.143513 | J36: 0.144524 | K36: 0.144353 | L36: 0.144542 | M36: 0.1445 | N36: 0.145463 | O36: 0.145827 | P36: 0.146004 | Q36: 0.146902 | R36: 0.146277 | S36: 0.145381 | T36: 0.146673 | U36: 0.140043 | V36: 0.142971 | W36: 0.145072 | X36: 0.146061 | Y36: 0.148185 | Z36: 0.150263 | AA36: 0.1519 | AB36: 0.153192 | AC36: 0.155988 | AD36: 0.157562 | AE36: 0.162704 | AF36: 0.161284 | AG36: 0.018882
A37: PSD000:Other_BM_Dome | B37: Domestic Production | C37: 0.069112 | D37: 0.100886 | E37: 0.107997 | F37: 0.108025 | G37: 0.108205 | H37: 0.107724 | I37: 0.107745 | J37: 0.108308 | K37: 0.107684 | L37: 0.107415 | M37: 0.106909 | N37: 0.107402 | O37: 0.10729 | P37: 0.106986 | Q37: 0.107396 | R37: 0.106277 | S37: 0.104881 | T37: 0.105667 | U37: 0.098524 | V37: 0.108887 | W37: 0.110561 | X37: 0.111119 | Y37: 0.112807 | Z37: 0.114442 | AA37: 0.115632 | AB37: 0.11647 | AC37: 0.118807 | AD37: 0.119916 | AE37: 0.124587 | AF37: 0.122691 | AG37: 0.019989
A38: PSD000:Other_BM_NetImp | B38: Net Imports | C38: 0.024644 | D38: 0.037287 | E38: 0.034035 | F38: 0.03446 | G38: 0.034891 | H38: 0.035327 | I38: 0.035769 | J38: 0.036216 | K38: 0.036668 | L38: 0.037127 | M38: 0.037591 | N38: 0.038061 | O38: 0.038536 | P38: 0.039018 | Q38: 0.039506 | R38: 0.04 | S38: 0.0405 | T38: 0.041006 | U38: 0.041519 | V38: 0.034084 | W38: 0.034511 | X38: 0.034942 | Y38: 0.035379 | Z38: 0.035821 | AA38: 0.036269 | AB38: 0.036722 | AC38: 0.037181 | AD38: 0.037646 | AE38: 0.038116 | AF38: 0.038593 | AG38: 0.015587
A39: PSD000:Other_BM_Stock | B39: Stock Withdrawal | C39: 0 | D39: 0 | E39: 0 | F39: 0 | G39: 0 | H39: 0 | I39: 0 | J39: 0 | K39: 0 | L39: 0 | M39: 0 | N39: 0 | O39: 0 | P39: 0 | Q39: 0 | R39: 0 | S39: 0 | T39: 0 | U39: 0 | V39: 0 | W39: 0 | X39: 0 | Y39: 0 | Z39: 0 | AA39: 0 | AB39: 0 | AC39: 0 | AD39: 0 | AE39: 0 | AF39: 0 | AG39: --
A40: PSD000:AllLiquidsfromGa | B40: Liquids from Gas | C40: 0 | D40: 0 | E40: 0 | F40: 0 | G40: 0 | H40: 0 | I40: 0 | J40: 0 | K40: 0 | L40: 0 | M40: 0 | N40: 0 | O40: 0 | P40: 0 | Q40: 0 | R40: 0 | S40: 0 | T40: 0 | U40: 0 | V40: 0 | W40: 0 | X40: 0 | Y40: 0 | Z40: 0 | AA40: 0 | AB40: 0 | AC40: 0 | AD40: 0 | AE40: 0 | AF40: 0 | AG40: --
A41: PSD000:ca_LiquidsfromCo | B41: Liquids from Coal | C41: 0 | D41: 0 | E41: 0 | F41: 0 | G41: 0 | H41: 0 | I41: 0 | J41: 0 | K41: 0 | L41: 0 | M41: 0 | N41: 0 | O41: 0 | P41: 0 | Q41: 0 | R41: 0 | S41: 0 | T41: 0 | U41: 0 | V41: 0 | W41: 0 | X41: 0 | Y41: 0 | Z41: 0 | AA41: 0 | AB41: 0 | AC41: 0 | AD41: 0 | AE41: 0 | AF41: 0 | AG41: --
A42: PSD000:ca_OtherOther | B42: Other 6/ | C42: 0.204 | D42: 0.204 | E42: 0.24125 | F42: 0.236141 | G42: 0.235012 | H42: 0.235472 | I42: 0.230299 | J42: 0.230071 | K42: 0.228028 | L42: 0.227871 | M42: 0.227135 | N42: 0.222182 | O42: 0.22186 | P42: 0.225621 | Q42: 0.224308 | R42: 0.228586 | S42: 0.230524 | T42: 0.231316 | U42: 0.230383 | V42: 0.226263 | W42: 0.22521 | X42: 0.222785 | Y42: 0.220057 | Z42: 0.222193 | AA42: 0.219587 | AB42: 0.216035 | AC42: 0.214285 | AD42: 0.217129 | AE42: 0.22031 | AF42: 0.218113 | AG42: 0.002309
A44: PSD000:da_TotalPrimaryS | B44: Total Primary Supply 7/ | C44: 19.499475 | D44: 20.195192 | E44: 20.226551 | F44: 20.118494 | G44: 20.155071 | H44: 20.160822 | I44: 20.10253 | J44: 20.060335 | K44: 19.968279 | L44: 19.911951 | M44: 19.895597 | N44: 19.948847 | O44: 19.938242 | P44: 19.877691 | Q44: 19.827545 | R44: 19.783815 | S44: 19.776556 | T44: 19.771431 | U44: 19.799202 | V44: 19.797443 | W44: 19.816906 | X44: 19.858063 | Y44: 19.906267 | Z44: 19.917377 | AA44: 19.959278 | AB44: 20.0555 | AC44: 20.126125 | AD44: 20.16188 | AE44: 20.227749 | AF44: 20.370794 | AG44: 0.001509
B47: Product Supplied
...

Sheet AEO T11 Petroleum 2021
B1: ref2021.d113020a | C1: 2020 | D1: 2021 | E1: 2022 | F1: 2023 | G1: 2024 | H1: 2025 | I1: 2026 | J1: 2027 | K1: 2028 | L1: 2029 | M1: 2030 | N1: 2031 | O1: 2032 | P1: 2033 | Q1: 2034 | R1: 2035 | S1: 2036 | T1: 2037 | U1: 2038 | V1: 2039 | W1: 2040 | X1: 2041 | Y1: 2042 | Z1: 2043 | AA1: 2044 | AB1: 2045 | AC1: 2046 | AD1: 2047 | AE1: 2048 | AF1: 2049 | AG1: 2050 | AJ1: Difference between 2020 and 2021
C3: Report | D3: Annual Energy Outlook 2021
C4: Scenario | D4: ref2021 | G4: Reference case
C5: Datekey | D5: d113020a
C6: Release Date | E6: January 2021
A10: PSD000 | B10: 11. Petroleum and Other Liquids Supply and Disposition | AH10: Compound
B11: (million barrels per day, unless otherwise noted) | AH11: Growth
AH12: 2020-2050
B13: Supply and Disposition | C13: 2020 | D13: 2021 | E13: 2022 | F13: 2023 | G13: 2024 | H13: 2025 | I13: 2026 | J13: 2027 | K13: 2028 | L13: 2029 | M13: 2030 | N13: 2031 | O13: 2032 | P13: 2033 | Q13: 2034 | R13: 2035 | S13: 2036 | T13: 2037 | U13: 2038 | V13: 2039 | W13: 2040 | X13: 2041 | Y13: 2042 | Z13: 2043 | AA13: 2044 | AB13: 2045 | AC13: 2046 | AD13: 2047 | AE13: 2048 | AF13: 2049 | AG13: 2050 | AH13: (percent)
B15: Crude Oil
A16: PSD000:ba_DomesticCrude | B16: Domestic Crude Production 1/ | C16: 11.470048 | D16: 11.166155 | E16: 11.626638 | F16: 12.329649 | G16: 12.74404 | H16: 13.231529 | I16: 13.497977 | J16: 13.594147 | K16: 13.710074 | L16: 13.718638 | M16: 13.76896 | N16: 13.795834 | O16: 13.768938 | P16: 13.861969 | Q16: 13.883383 | R16: 13.763157 | S16: 13.566243 | T16: 13.451651 | U16: 13.348973 | V16: 13.283369 | W16: 13.173889 | X16: 13.118857 | Y16: 13.146461 | Z16: 13.310509 | AA16: 13.351305 | AB16: 13.223972 | AC16: 13.249136 | AD16: 13.294786 | AE16: 13.227971 | AF16: 13.159329 | AG16: 12.87295 | AH16: 0.003854 | AJ16: =C16/D16 -> 1.0272155
A17: PSD000:ba_Alaska | B17: Alaska | C17: 0.457568 | D17: 0.485528 | E17: 0.472 | F17: 0.553932 | G17: 0.57012 | H17: 0.574502 | I17: 0.600343 | J17: 0.638631 | K17: 0.620714 | L17: 0.597336 | M17: 0.56874 | N17: 0.57986 | O17: 0.630835 | P17: 0.671899 | Q17: 0.690727 | R17: 0.670324 | S17: 0.641218 | T17: 0.610044 | U17: 0.581141 | V17: 0.554657 | W17: 0.555257 | X17: 0.597369 | Y17: 0.60897 | Z17: 0.740398 | AA17: 0.791331 | AB17: 0.759136 | AC17: 0.730634 | AD17: 0.705085 | AE17: 0.680323 | AF17: 0.658361 | AG17: 0.617198 | AH17: 0.010025 | AJ17: =C17/D17 -> 0.94241321
A18: PSD000:ba_Lower48States | B18: Lower 48 States | C18: 11.01248 | D18: 10.680627 | E18: 11.154638 | F18: 11.775717 | G18: 12.173921 | H18: 12.657028 | I18: 12.897635 | J18: 12.955516 | K18: 13.08936 | L18: 13.121303 | M18: 13.200219 | N18: 13.215974 | O18: 13.138103 | P18: 13.190071 | Q18: 13.192656 | R18: 13.092833 | S18: 12.925025 | T18: 12.841607 | U18: 12.767832 | V18: 12.728712 | W18: 12.618632 | X18: 12.521488 | Y18: 12.537491 | Z18: 12.570111 | AA18: 12.559974 | AB18: 12.464836 | AC18: 12.518502 | AD18: 12.589702 | AE18: 12.547648 | AF18: 12.500969 | AG18: 12.255751 | AH18: 0.003572 | AJ18: =C18/D18 -> 1.0310706
A19: PSD000:ba_NetImports | B19: Net Imports | C19: 2.83 | D19: 4.5 | E19: 4.97122 | F19: 4.794863 | G19: 4.470877 | H19: 4.198047 | I19: 4.015316 | J19: 3.97385 | K19: 3.856572 | L19: 3.847551 | M19: 3.808479 | N19: 3.760889 | O19: 3.784652 | P19: 3.641997 | Q19: 3.609391 | R19: 3.708626 | S19: 3.935255 | T19: 4.045917 | U19: 4.142609 | V19: 4.127064 | W19: 4.259272 | X19: 4.304543 | Y19: 4.313911 | Z19: 4.110817 | AA19: 4.074094 | AB19: 4.18912 | AC19: 4.129763 | AD19: 4.11883 | AE19: 4.203545 | AF19: 4.232956 | AG19: 4.496002 | AH19: 0.01555 | AJ19: =C19/D19 -> 0.62888889
A20: PSD000:ba_GrossImports | B20: Gross Imports | C20: 6.053 | D20: 7.55 | E20: 7.787116 | F20: 7.747426 | G20: 7.818967 | H20: 7.530605 | I20: 7.532843 | J20: 7.236153 | K20: 7.035046 | L20: 7.19906 | M20: 6.94103 | N20: 7.047481 | O20: 6.85515 | P20: 6.740557 | Q20: 6.838348 | R20: 6.962935 | S20: 7.224354 | T20: 7.286689 | U20: 7.339459 | V20: 7.553651 | W20: 7.465834 | X20: 7.463062 | Y20: 7.529857 | Z20: 7.372736 | AA20: 7.244863 | AB20: 7.257197 | AC20: 7.153084 | AD20: 7.193253 | AE20: 7.311895 | AF20: 7.347315 | AG20: 7.624471 | AH20: 0.007723 | AJ20: =C20/D20 -> 0.80172185
A21: PSD000:ba_Exports | B21: Exports | C21: 3.223 | D21: 3.05 | E21: 2.815896 | F21: 2.952563 | G21: 3.34809 | H21: 3.332558 | I21: 3.517526 | J21: 3.262303 | K21: 3.178474 | L21: 3.351509 | M21: 3.132551 | N21: 3.286592 | O21: 3.070499 | P21: 3.09856 | Q21: 3.228958 | R21: 3.25431 | S21: 3.289099 | T21: 3.240773 | U21: 3.19685 | V21: 3.426587 | W21: 3.206562 | X21: 3.158519 | Y21: 3.215945 | Z21: 3.261918 | AA21: 3.170769 | AB21: 3.068078 | AC21: 3.023321 | AD21: 3.074423 | AE21: 3.10835 | AF21: 3.114359 | AG21: 3.128469 | AH21: -0.000992 | AJ21: =C21/D21 -> 1.0567213
A22: PSD000:ba_OtherCrudeSup | B22: Other Crude Supply 2/ | C22: 0.042 | D22: 0.296 | E22: 0.03425 | F22: 0.0774 | G22: 0.09563 | H22: 0.07192 | I22: 0 | J22: 0 | K22: 0 | L22: 0 | M22: 0 | N22: 0 | O22: 0 | P22: 0 | Q22: 0 | R22: 0 | S22: 0 | T22: 0 | U22: 0 | V22: 0 | W22: 0 | X22: 0 | Y22: 0 | Z22: 0 | AA22: 0 | AB22: 0 | AC22: 0 | AD22: 0 | AE22: 0 | AF22: 0 | AG22: 0 | AH22: -- | AJ22: =C22/D22 -> 0.14189189
A23: PSD000:ba_TotalCrudeSup | B23: Total Crude Supply | C23: 14.342048 | D23: 15.962154 | E23: 16.632109 | F23: 17.201912 | G23: 17.310549 | H23: 17.501497 | I23: 17.513294 | J23: 17.567997 | K23: 17.566647 | L23: 17.566189 | M23: 17.577438 | N23: 17.556723 | O23: 17.553589 | P23: 17.503967 | Q23: 17.492773 | R23: 17.471783 | S23: 17.501499 | T23: 17.497566 | U23: 17.491583 | V23: 17.410433 | W23: 17.433161 | X23: 17.423401 | Y23: 17.460373 | Z23: 17.421326 | AA23: 17.4254 | AB23: 17.413092 | AC23: 17.378899 | AD23: 17.413616 | AE23: 17.431517 | AF23: 17.392284 | AG23: 17.368952 | AH23: 0.006403 | AJ23: =C23/D23 -> 0.8985033
AJ24: =C24/D24 -> #DIV/0!
A25: PSD000:ca_NetProductImp | B25: Net Product Imports | C25: -3.217 | D25: -3.635 | E25: -4.651141 | F25: -5.329247 | G25: -5.400157 | H25: -5.549729 | I25: -5.638276 | J25: -5.733 | K25: -5.730247 | L25: -5.797076 | M25: -5.845665 | N25: -5.837363 | O25: -5.795742 | P25: -5.718789 | Q25: -5.692716 | R25: -5.612529 | S25: -5.613312 | T25: -5.574323 | U25: -5.532296 | V25: -5.450375 | W25: -5.456642 | X25: -5.385563 | Y25: -5.377039 | Z25: -5.283255 | AA25: -5.243139 | AB25: -5.137103 | AC25: -5.021393 | AD25: -4.954345 | AE25: -4.876846 | AF25: -4.742838 | AG25: -4.633424 | AH25: 0.012236 | AJ25: =C25/D25 -> 0.88500688
A26: PSD000:ca_GrossRefinedP | B26: Gross Refined Product Imports 3/ | C26: 0.974 | D26: 0.852 | E26: 0.657141 | F26: 0.658067 | G26: 0.651951 | H26: 0.638855 | I26: 0.72687 | J26: 0.723677 | K26: 0.712943 | L26: 0.701428 | M26: 0.735705 | N26: 0.71881 | O26: 0.716891 | P26: 0.716738 | Q26: 0.720995 | R26: 0.728537 | S26: 0.720787 | T26: 0.72819 | U26: 0.733582 | V26: 0.741212 | W26: 0.747285 | X26: 0.761693 | Y26: 0.761609 | Z26: 0.763732 | AA26: 0.765033 | AB26: 0.773424 | AC26: 0.758651 | AD26: 0.769778 | AE26: 0.79673 | AF26: 0.797911 | AG26: 0.762324 | AH26: -0.008135 | AJ26: =C26/D26 -> 1.1431925
A27: PSD000:ca_UnfinishedOil | B27: Unfinished Oil Imports | C27: 0.563 | D27: 0.698 | E27: 0.664354 | F27: 0.657648 | G27: 0.646594 | H27: 0.64619 | I27: 0.599429 | J27: 0.597477 | K27: 0.595157 | L27: 0.584598 | M27: 0.583131 | N27: 0.581296 | O27: 0.579093 | P27: 0.577258 | Q27: 0.575791 | R27: 0.573956 | S27: 0.572121 | T27: 0.555167 | U27: 0.55344 | V27: 0.566616 | W27: 0.564781 | X27: 0.547568 | Y27: 0.545365 | Z27: 0.558529 | AA27: 0.556694 | AB27: 0.554859 | AC27: 0.553024 | AD27: 0.551189 | AE27: 0.549354 | AF27: 0.54752 | AG27: 0.545685 | AH27: -0.001041 | AJ27: =C27/D27 -> 0.80659026
A28: PSD000:ca_BlendingCompo | B28: Blending Component Imports | C28: 0.359 | D28: 0.442 | E28: 0.598704 | F28: 0.6216 | G28: 0.635292 | H28: 0.64028 | I28: 0.610671 | J28: 0.564376 | K28: 0.525891 | L28: 0.496328 | M28: 0.477206 | N28: 0.448678 | O28: 0.426883 | P28: 0.40751 | Q28: 0.396023 | R28: 0.380087 | S28: 0.381256 | T28: 0.375105 | U28: 0.370709 | V28: 0.365776 | W28: 0.36375 | X28: 0.359704 | Y28: 0.359535 | Z28: 0.362024 | AA28: 0.363643 | AB28: 0.361096 | AC28: 0.362296 | AD28: 0.368013 | AE28: 0.375189 | AF28: 0.381407 | AG28: 0.386442 | AH28: 0.002458 | AJ28: =C28/D28 -> 0.81221719
A29: PSD000:ca_Exports | B29: Exports | C29: 5.113 | D29: 5.627 | E29: 6.57134 | F29: 7.266561 | G29: 7.333994 | H29: 7.475054 | I29: 7.575245 | J29: 7.61853 | K29: 7.564239 | L29: 7.579431 | M29: 7.641706 | N29: 7.586148 | O29: 7.518609 | P29: 7.420295 | Q29: 7.385525 | R29: 7.295109 | S29: 7.287476 | T29: 7.232786 | U29: 7.190026 | V29: 7.123981 | W29: 7.132459 | X29: 7.054527 | Y29: 7.043549 | Z29: 6.96754 | AA29: 6.928508 | AB29: 6.826482 | AC29: 6.695365 | AD29: 6.643326 | AE29: 6.59812 | AF29: 6.469676 | AG29: 6.327875 | AH29: 0.007131 | AJ29: =C29/D29 -> 0.9086547
A30: PSD000:ca_RefineryProce | B30: Refinery Processing Gain 4/ | C30: 0.963 | D30: 1.093 | E30: 1.011712 | F30: 1.006525 | G30: 0.96884 | H30: 0.988423 | I30: 1.003248 | J30: 0.990855 | K30: 1.001114 | L30: 1.014459 | M30: 1.010121 | N30: 1.013339 | O30: 1.018253 | P30: 1.022922 | Q30: 1.044129 | R30: 1.04602 | S30: 1.072378 | T30: 1.078819 | U30: 1.084642 | V30: 1.097418 | W30: 1.093501 | X30: 1.095632 | Y30: 1.099306 | Z30: 1.083379 | AA30: 1.078065 | AB30: 1.075419 | AC30: 1.078596 | AD30: 1.081911 | AE30: 1.082935 | AF30: 1.081192 | AG30: 1.088299 | AH30: 0.004086 | AJ30: =C30/D30 -> 0.8810613
A31: PSD000:ProductStockDraw | B31: Product Stock Withdrawal | C31: -0.083 | D31: 0.052 | E31: 0 | F31: 0 | G31: 0 | H31: 0 | I31: 0 | J31: 0 | K31: 0 | L31: 0 | M31: 0 | N31: 0 | O31: 0 | P31: 0 | Q31: 0 | R31: 0 | S31: 0 | T31: 0 | U31: 0 | V31: 0 | W31: 0 | X31: 0 | Y31: 0 | Z31: 0 | AA31: 0 | AB31: 0 | AC31: 0 | AD31: 0 | AE31: 0 | AF31: 0 | AG31: 0 | AH31: -- | AJ31: =C31/D31 -> -1.5961538
A32: PSD000:ca_NaturalGasPla | B32: Natural Gas Plant Liquids | C32: 5.02603 | D32: 5.200461 | E32: 5.481331 | F32: 5.755203 | G32: 5.85873 | H32: 5.885843 | I32: 5.962521 | J32: 6.001111 | K32: 5.988202 | L32: 6.040942 | M32: 6.1231 | N32: 6.15308 | O32: 6.126073 | P32: 6.131374 | Q32: 6.158622 | R32: 6.153062 | S32: 6.125976 | T32: 6.123695 | U32: 6.121618 | V32: 6.141864 | W32: 6.149165 | X32: 6.135815 | Y32: 6.171154 | Z32: 6.223928 | AA32: 6.263006 | AB32: 6.266887 | AC32: 6.247303 | AD32: 6.218316 | AE32: 6.216486 | AF32: 6.237903 | AG32: 6.25917 | AH32: 0.007341 | AJ32: =C32/D32 -> 0.96645855
A33: PSD000:from_Renewables | B33: Biofuels | C33: 0.967844 | D33: 1.097252 | E33: 1.104007 | F33: 1.120142 | G33: 1.122895 | H33: 1.126976 | I33: 1.130516 | J33: 1.133907 | K33: 1.137306 | L33: 1.140499 | M33: 1.144013 | N33: 1.14387 | O33: 1.144006 | P33: 1.144678 | Q33: 1.145682 | R33: 1.146916 | S33: 1.147554 | T33: 1.148103 | U33: 1.148892 | V33: 1.150137 | W33: 1.151594 | X33: 1.152909 | Y33: 1.154606 | Z33: 1.15653 | AA33: 1.162142 | AB33: 1.168497 | AC33: 1.175066 | AD33: 1.182199 | AE33: 1.189561 | AF33: 1.200335 | AG33: 1.211093 | AH33: 0.007502 | AJ33: =C33/D33 -> 0.88206173
A34: PSD000:cb_TotalEthanol | B34: Ethanol | C34: 0.801417 | D34: 0.883641 | E34: 0.873613 | F34: 0.875332 | G34: 0.873404 | H34: 0.874846 | I34: 0.874832 | J34: 0.874454 | K34: 0.874113 | L34: 0.873241 | M34: 0.873034 | N34: 0.873036 | O34: 0.87352 | P34: 0.875343 | Q34: 0.878042 | R34: 0.881248 | S34: 0.883171 | T34: 0.88528 | U34: 0.8878 | V34: 0.891139 | W34: 0.894868 | X34: 0.898296 | Y34: 0.902709 | Z34: 0.907862 | AA34: 0.913282 | AB34: 0.918505 | AC34: 0.924127 | AD34: 0.929622 | AE34: 0.935832 | AF34: 0.942592 | AG34: 0.949442 | AH34: 0.005666 | AJ34: =C34/D34 -> 0.90694864
A35: PSD000:ca_DomesticEthan | B35: Domestic Production | C35: 0.87759 | D35: 0.967299 | E35: 0.980691 | F35: 0.985088 | G35: 0.98918 | H35: 0.995922 | I35: 0.99893 | J35: 1.001656 | K35: 1.0045 | L35: 1.006883 | M35: 1.010012 | N35: 1.020131 | O35: 1.024293 | P35: 1.029881 | Q35: 1.036442 | R35: 1.043608 | S35: 1.049588 | T35: 1.055866 | U35: 1.062651 | V35: 1.070354 | W35: 1.078568 | X35: 1.086592 | Y35: 1.09571 | Z35: 1.105691 | AA35: 1.116048 | AB35: 1.131383 | AC35: 1.137161 | AD35: 1.15791 | AE35: 1.169819 | AF35: 1.182431 | AG35: 1.195287 | AH35: 0.010352 | AJ35: =C35/D35 -> 0.90725825
A36: PSD000:ca_EthanolImport | B36: Net Imports | C36: -0.076173 | D36: -0.083658 | E36: -0.107078 | F36: -0.109756 | G36: -0.115777 | H36: -0.121077 | I36: -0.124098 | J36: -0.127202 | K36: -0.130387 | L36: -0.133642 | M36: -0.136978 | N36: -0.147094 | O36: -0.150773 | P36: -0.154538 | Q36: -0.1584 | R36: -0.16236 | S36: -0.166418 | T36: -0.170586 | U36: -0.174851 | V36: -0.179214 | W36: -0.1837 | X36: -0.188296 | Y36: -0.193001 | Z36: -0.197829 | AA36: -0.202767 | AB36: -0.212879 | AC36: -0.213033 | AD36: -0.228288 | AE36: -0.233987 | AF36: -0.239839 | AG36: -0.245844 | AH36: 0.039829 | AJ36: =C36/D36 -> 0.91052858
A37: PSD000:ca_EthanolWithdr | B37: Stock Withdrawal | C37: 0 | D37: 0 | E37: 0 | F37: 0 | G37: 0 | H37: 0 | I37: 0 | J37: 0 | K37: 0 | L37: 0 | M37: 0 | N37: 0 | O37: 0 | P37: 0 | Q37: 0 | R37: 0 | S37: 0 | T37: 0 | U37: 0 | V37: 0 | W37: 0 | X37: 0 | Y37: 0 | Z37: 0 | AA37: 0 | AB37: 0 | AC37: 0 | AD37: 0 | AE37: 0 | AF37: 0 | AG37: 0 | AH37: -- | AJ37: =C37/D37 -> #DIV/0!
A38: PSD000:cb_TotalBiodiesl | B38: Biodiesel | C38: 0.116095 | D38: 0.13709 | E38: 0.132302 | F38: 0.135473 | G38: 0.135684 | H38: 0.135886 | I38: 0.136087 | J38: 0.136455 | K38: 0.136648 | L38: 0.136864 | M38: 0.13762 | N38: 0.137471 | O38: 0.137665 | P38: 0.137726 | Q38: 0.137942 | R38: 0.138158 | S38: 0.137691 | T38: 0.135528 | U38: 0.134295 | V38: 0.134471 | W38: 0.134646 | X38: 0.134823 | Y38: 0.135 | Z38: 0.134761 | AA38: 0.134934 | AB38: 0.135108 | AC38: 0.135501 | AD38: 0.135683 | AE38: 0.135865 | AF38: 0.139333 | AG38: 0.141751 | AH38: -- | AJ38: =C38/D38 -> 0.84685243
A39: PSD000:cb_DomesticBiodi | B39: Domestic Production | C39: 0.113 | D39: 0.133995 | E39: 0.122511 | F39: 0.127495 | G39: 0.127666 | H39: 0.127828 | I39: 0.127989 | J39: 0.128316 | K39: 0.128469 | L39: 0.128643 | M39: 0.129358 | N39: 0.129168 | O39: 0.12932 | P39: 0.12934 | Q39: 0.129514 | R39: 0.129688 | S39: 0.129179 | T39: 0.126973 | U39: 0.125698 | V39: 0.12583 | W39: 0.125962 | X39: 0.126095 | Y39: 0.126229 | Z39: 0.125946 | AA39: 0.126075 | AB39: 0.126205 | AC39: 0.126553 | AD39: 0.12669 | AE39: 0.126828 | AF39: 0.13025 | AG39: 0.132623 | AH39: 0.005352 | AJ39: =C39/D39 -> 0.84331505
A40: PSD000:cb_BiodieselImpo | B40: Net Imports | C40: 0.003095 | D40: 0.003095 | E40: 0.009791 | F40: 0.007978 | G40: 0.008018 | H40: 0.008058 | I40: 0.008098 | J40: 0.008139 | K40: 0.00818 | L40: 0.00822 | M40: 0.008262 | N40: 0.008303 | O40: 0.008344 | P40: 0.008386 | Q40: 0.008428 | R40: 0.00847 | S40: 0.008512 | T40: 0.008555 | U40: 0.008598 | V40: 0.008641 | W40: 0.008684 | X40: 0.008727 | Y40: 0.008771 | Z40: 0.008815 | AA40: 0.008859 | AB40: 0.008903 | AC40: 0.008948 | AD40: 0.008993 | AE40: 0.009038 | AF40: 0.009083 | AG40: 0.009128 | AH40: 0.036709 | AJ40: =C40/D40 -> 1
A41: PSD000:cb_BiodieselWith | B41: Stock Withdrawal | C41: 0 | D41: 0 | E41: 0 | F41: 0 | G41: 0 | H41: 0 | I41: 0 | J41: 0 | K41: 0 | L41: 0 | M41: 0 | N41: 0 | O41: 0 | P41: 0 | Q41: 0 | R41: 0 | S41: 0 | T41: 0 | U41: 0 | V41: 0 | W41: 0 | X41: 0 | Y41: 0 | Z41: 0 | AA41: 0 | AB41: 0 | AC41: 0 | AD41: 0 | AE41: 0 | AF41: 0 | AG41: 0 | AH41: -- | AJ41: =C41/D41 -> #DIV/0!
A42: PSD000:Other_BM-derived | B42: Other Biomass-derived Liquids 5/ | C42: 0.050332 | D42: 0.076521 | E42: 0.098092 | F42: 0.109337 | G42: 0.113808 | H42: 0.116244 | I42: 0.119597 | J42: 0.122998 | K42: 0.126544 | L42: 0.130394 | M42: 0.13336 | N42: 0.133363 | O42: 0.132822 | P42: 0.131609 | Q42: 0.129698 | R42: 0.127509 | S42: 0.126692 | T42: 0.127295 | U42: 0.126796 | V42: 0.124528 | W42: 0.122079 | X42: 0.11979 | Y42: 0.116897 | Z42: 0.113907 | AA42: 0.113926 | AB42: 0.114884 | AC42: 0.115437 | AD42: 0.116895 | AE42: 0.117864 | AF42: 0.11841 | AG42: 0.1199 | AH42: 0.029357 | AJ42: =C42/D42 -> 0.65775408
A43: PSD000:Other_BM_Dome | B43: Domestic Production | C43: 0.032683 | D43: 0.050489 | E43: 0.073741 | F43: 0.084682 | G43: 0.088845 | H43: 0.090969 | I43: 0.094006 | J43: 0.097087 | K43: 0.10031 | L43: 0.103831 | M43: 0.106465 | N43: 0.106131 | O43: 0.10525 | P43: 0.103692 | Q43: 0.101433 | R43: 0.098891 | S43: 0.097716 | T43: 0.097957 | U43: 0.097091 | V43: 0.094451 | W43: 0.091627 | X43: 0.093372 | Y43: 0.091584 | Z43: 0.088278 | AA43: 0.087977 | AB43: 0.088611 | AC43: 0.088836 | AD43: 0.089961 | AE43: 0.090593 | AF43: 0.090798 | AG43: 0.091943 | AH43: 0.035078 | AJ43: =C43/D43 -> 0.64732912
A44: PSD000:Other_BM_NetImp | B44: Net Imports | C44: 0.017648 | D44: 0.026031 | E44: 0.024351 | F44: 0.024655 | G44: 0.024963 | H44: 0.025275 | I44: 0.025591 | J44: 0.025911 | K44: 0.026235 | L44: 0.026563 | M44: 0.026895 | N44: 0.027231 | O44: 0.027572 | P44: 0.027916 | Q44: 0.028265 | R44: 0.028618 | S44: 0.028976 | T44: 0.029338 | U44: 0.029705 | V44: 0.030076 | W44: 0.030452 | X44: 0.026418 | Y44: 0.025312 | Z44: 0.025629 | AA44: 0.025949 | AB44: 0.026273 | AC44: 0.026602 | AD44: 0.026934 | AE44: 0.027271 | AF44: 0.027612 | AG44: 0.027957 | AH44: 0.015452 | AJ44: =C44/D44 -> 0.67796089
A45: PSD000:Other_BM_Stock | B45: Stock Withdrawal | C45: 0 | D45: 0 | E45: 0 | F45: 0 | G45: 0 | H45: 0 | I45: 0 | J45: 0 | K45: 0 | L45: 0 | M45: 0 | N45: 0 | O45: 0 | P45: 0 | Q45: 0 | R45: 0 | S45: 0 | T45: 0 | U45: 0 | V45: 0 | W45: 0 | X45: 0 | Y45: 0 | Z45: 0 | AA45: 0 | AB45: 0 | AC45: 0 | AD45: 0 | AE45: 0 | AF45: 0 | AG45: 0 | AH45: -- | AJ45: =C45/D45 -> #DIV/0!
...

Sheet AEO T24 Refining 2022 Raw
A1: Table 24. Refining Industry Energy Consumption
A2: https://www.eia.gov/outlooks/aeo/data/browser/#/?id=35-AEO2022&cases=lowmacro&sourcekey=0
A3: Wed Jul 13 2022 09:47:36 GMT-0400 (Eastern Daylight Time)
A4: Source: U.S. Energy Information Administration
B5: full name | C5: api key | D5: units | E5: 2020 | F5: 2021 | G5: 2022 | H5: 2023 | I5: 2024 | J5: 2025 | K5: 2026 | L5: 2027 | M5: 2028 | N5: 2029 | O5: 2030 | P5: 2031 | Q5: 2032 | R5: 2033 | S5: 2034 | T5: 2035 | U5: 2036 | V5: 2037 | W5: 2038 | X5: 2039 | Y5: 2040 | Z5: 2041 | AA5: 2042 | AB5: 2043 | AC5: 2044 | AD5: 2045 | AE5: 2046 | AF5: 2047 | AG5: 2048 | AH5: 2049 | AI5: 2050 | AJ5: Growth (2021-2050)
A6: Value of Shipments (billion 2012 dollars) | B6: Refining Industry: Value of Shipments: Low economic growth | C6: 35-AEO2022.2.lowmacro-d011222a | D6: billion 2012 $ | F6: 746.87048 | G6: 840.716 | H6: 850.76227 | I6: 846.17731 | J6: 846.14966 | K6: 844.26404 | L6: 840.59943 | M6: 838.8761 | N6: 835.64575 | O6: 832.79443 | P6: 831.82013 | Q6: 833.64276 | R6: 833.2926 | S6: 831.01508 | T6: 828.73273 | U6: 827.11176 | V6: 826.83716 | W6: 826.18012 | X6: 827.33057 | Y6: 827.06683 | Z6: 827.62585 | AA6: 829.53912 | AB6: 831.72736 | AC6: 832.18103 | AD6: 834.06146 | AE6: 837.30823 | AF6: 839.42822 | AG6: 839.74255 | AH6: 842.51312 | AI6: 849.40979 | AJ6: 0.004
A7: Inputs to Distillation Units | C7: 35-AEO2022.3.
A8: (million barrels per day) | B8: Refining Industry: Inputs to Distillation Units: Low economic growth | C8: 35-AEO2022.4.lowmacro-d011222a | D8: MMb/d | F8: 15.710509 | G8: 16.935637 | H8: 17.158117 | I8: 17.243862 | J8: 17.289557 | K8: 17.248625 | L8: 17.194527 | M8: 17.125137 | N8: 17.100779 | O8: 17.055332 | P8: 16.935118 | Q8: 16.974129 | R8: 16.890358 | S8: 16.803427 | T8: 16.749456 | U8: 16.641615 | V8: 16.592222 | W8: 16.606012 | X8: 16.514265 | Y8: 16.474268 | Z8: 16.485779 | AA8: 16.434586 | AB8: 16.466223 | AC8: 16.464849 | AD8: 16.374317 | AE8: 16.368639 | AF8: 16.269154 | AG8: 16.304836 | AH8: 16.304724 | AI8: 16.280148 | AJ8: 0.001
A9: Total Energy Consumption (trillion Btu) | C9: 35-AEO2022.6.
A10: Residual Fuel Oil | B10: Refining Industry: Total Energy Use: Residual Fuel Oil: Low economic growth | C10: 35-AEO2022.7.lowmacro-d011222a | D10: trillion Btu | F10: 0.214 | G10: 0.214 | H10: 0 | I10: 0 | J10: 0 | K10: 0 | L10: 0 | M10: 0 | N10: 0 | O10: 0 | P10: 0 | Q10: 0 | R10: 0 | S10: 0 | T10: 0 | U10: 0 | V10: 0 | W10: 0 | X10: 0 | Y10: 0 | Z10: 0 | AA10: 0 | AB10: 0 | AC10: 0 | AD10: 0 | AE10: 0 | AF10: 0 | AG10: 0 | AH10: 0 | AI10: 0 | AJ10: - -
A11: Distillate Fuel Oil | B11: Refining Industry: Total Energy Use: Distillate Fuel Oil: Low economic growth | C11: 35-AEO2022.8.lowmacro-d011222a | D11: trillion Btu | F11: 1.625 | G11: 1.625 | H11: 0 | I11: 0 | J11: 0 | K11: 0 | L11: 0 | M11: 0 | N11: 0 | O11: 0 | P11: 0 | Q11: 0 | R11: 0 | S11: 0 | T11: 0 | U11: 0 | V11: 0 | W11: 0 | X11: 0 | Y11: 0 | Z11: 0 | AA11: 0 | AB11: 0 | AC11: 0 | AD11: 0 | AE11: 0 | AF11: 0 | AG11: 0 | AH11: 0 | AI11: 0 | AJ11: - -
A12: Liquefied Petroleum Gas Heat and Power | B12: Refining Industry: Total Energy Use: Liquefied Petroleum Gases: Low economic growth | C12: 35-AEO2022.9.lowmacro-d011222a | D12: trillion Btu | F12: 6.813 | G12: 6.813 | H12: 0 | I12: 0 | J12: 0 | K12: 0 | L12: 0 | M12: 0 | N12: 0 | O12: 0 | P12: 0 | Q12: 0 | R12: 0 | S12: 0 | T12: 0 | U12: 0 | V12: 0 | W12: 0 | X12: 0 | Y12: 0 | Z12: 0 | AA12: 0 | AB12: 0 | AC12: 0 | AD12: 0 | AE12: 0 | AF12: 0 | AG12: 0 | AH12: 0 | AI12: 0 | AJ12: - -
A13: Petroleum Coke | B13: Refining Industry: Total Energy Use: Petroleum Coke: Low economic growth | C13: 35-AEO2022.10.lowmacro-d011222a | D13: trillion Btu | F13: 457.229 | G13: 494.56598 | H13: 512.17004 | I13: 507.68442 | J13: 508.41577 | K13: 501.6297 | L13: 499.41949 | M13: 501.44247 | N13: 503.42487 | O13: 508.64514 | P13: 507.30545 | Q13: 510.25604 | R13: 510.57617 | S13: 511.58743 | T13: 510.87836 | U13: 510.53915 | V13: 508.83008 | W13: 508.80609 | X13: 509.01776 | Y13: 505.9101 | Z13: 506.77811 | AA13: 506.62024 | AB13: 508.24448 | AC13: 509.07855 | AD13: 510.58063 | AE13: 511.49094 | AF13: 511.26907 | AG13: 513.88257 | AH13: 517.29755 | AI13: 518.11548 | AJ13: 0.004
A14: Still Gas | B14: Refining Industry: Total Energy Use: Still Gas: Low economic growth | C14: 35-AEO2022.11.lowmacro-d011222a | D14: trillion Btu | F14: 1307.035 | G14: 1307.035 | H14: 1376.4792 | I14: 1370.5844 | J14: 1380.0272 | K14: 1384.7845 | L14: 1372.6489 | M14: 1386.3915 | N14: 1386.8704 | O14: 1389.0078 | P14: 1381.9146 | Q14: 1402.4971 | R14: 1398.6792 | S14: 1401.0201 | T14: 1406.3014 | U14: 1413.2411 | V14: 1434.525 | W14: 1435.3785 | X14: 1436.8918 | Y14: 1417.8949 | Z14: 1419.7549 | AA14: 1409.0181 | AB14: 1401.1478 | AC14: 1405.2753 | AD14: 1393.4462 | AE14: 1386.337 | AF14: 1375.0979 | AG14: 1388.4934 | AH14: 1397.1702 | AI14: 1386.0151 | AJ14: 0.002
A15: Other Petroleum | B15: Refining Industry: Total Energy Use: Other Petroleum: Low economic growth | C15: 35-AEO2022.12.lowmacro-d011222a | D15: trillion Btu | F15: 2.958 | G15: 2.958 | H15: 0 | I15: 0 | J15: 0.372267 | K15: 0.71969 | L15: 9.951056 | M15: 1.636055 | N15: 0 | O15: 0 | P15: 0 | Q15: 0.013138 | R15: 0 | S15: 0 | T15: 0.019257 | U15: 0.138091 | V15: 0.027799 | W15: 0.012505 | X15: 0.099726 | Y15: 0.032392 | Z15: 0.041556 | AA15: 0.077835 | AB15: 0.061223 | AC15: 0.011795 | AD15: 0.02569 | AE15: 0.039747 | AF15: 0.0126 | AG15: 0.039243 | AH15: 0.042319 | AI15: 0.037359 | AJ15: -0.14
A16: Petroleum and Other Liquids Subtotal | B16: Refining Industry: Total Energy Use: Petroleum Subtotal: Low economic growth | C16: 35-AEO2022.13.lowmacro-d011222a | D16: trillion Btu | F16: 1775.874 | G16: 1813.2111 | H16: 1888.6493 | I16: 1878.2688 | J16: 1888.8153 | K16: 1887.134 | L16: 1882.0194 | M16: 1889.4701 | N16: 1890.2952 | O16: 1897.653 | P16: 1889.22 | Q16: 1912.7664 | R16: 1909.2554 | S16: 1912.6075 | T16: 1917.199 | U16: 1923.9183 | V16: 1943.3829 | W16: 1944.197 | X16: 1946.0094 | Y16: 1923.8373 | Z16: 1926.5745 | AA16: 1915.7162 | AB16: 1909.4536 | AC16: 1914.3656 | AD16: 1904.0525 | AE16: 1897.8678 | AF16: 1886.3795 | AG16: 1902.4152 | AH16: 1914.5101 | AI16: 1904.168 | AJ16: 0.002
A17: Natural Gas | B17: Refining Industry: Total Energy Use: Natural Gas: Low economic growth | C17: 35-AEO2022.14.lowmacro-d011222a | D17: trillion Btu | F17: 1567.2632 | G17: 1576.2631 | H17: 1398.3788 | I17: 1360.6981 | J17: 1366.2755 | K17: 1393.6177 | L17: 1380.9757 | M17: 1389.9215 | N17: 1401.6855 | O17: 1410.05 | P17: 1412.5398 | Q17: 1371.0464 | R17: 1379.0742 | S17: 1406.8669 | T17: 1403.7351 | U17: 1439.798 | V17: 1443.9424 | W17: 1455.5973 | X17: 1459.7305 | Y17: 1459.2112 | Z17: 1457.2461 | AA17: 1460.7694 | AB17: 1463.6974 | AC17: 1482.3774 | AD17: 1484.8281 | AE17: 1477.1414 | AF17: 1490.5393 | AG17: 1521.3918 | AH17: 1539.7046 | AI17: 1557.6783 | AJ17: 0
A18: of which: Heat and Power | B18: Refining Industry: Total Energy Use: Natural Gas: Heat and Power: Low economic growth | C18: 35-AEO2022.15.lowmacro-d011222a | D18: trillion Btu | F18: 1376.2632 | G18: 1376.2631 | H18: 1195.0608 | I18: 1169.7944 | J18: 1176.6498 | K18: 1196.4496 | L18: 1187.5369 | M18: 1194.3967 | N18: 1205.7681 | O18: 1210.056 | P18: 1209.989 | Q18: 1180.3882 | R18: 1185.743 | S18: 1200.6757 | T18: 1197.2352 | U18: 1217.8516 | V18: 1215.5436 | W18: 1224.4225 | X18: 1226.9199 | Y18: 1235.1213 | Z18: 1234.569 | AA18: 1241.5365 | AB18: 1251.6686 | AC18: 1265.0332 | AD18: 1270.4662 | AE18: 1269.7192 | AF18: 1283.7209 | AG18: 1304.6792 | AH18: 1316.2902 | AI18: 1335.2708 | AJ18: -0.001
A19: of which: Feedstocks | B19: Refining Industry: Total Energy Use: Natural Gas: Feedstocks: Low economic growth | C19: 35-AEO2022.16.lowmacro-d011222a | D19: trillion Btu | F19: 191 | G19: 200 | H19: 203.31799 | I19: 190.90372 | J19: 189.62576 | K19: 197.16812 | L19: 193.4389 | M19: 195.5248 | N19: 195.91748 | O19: 199.99399 | P19: 202.55083 | Q19: 190.65814 | R19: 193.33115 | S19: 206.19127 | T19: 206.49988 | U19: 221.94636 | V19: 228.3988 | W19: 231.17477 | X19: 232.81056 | Y19: 224.0898 | Z19: 222.67714 | AA19: 219.23294 | AB19: 212.02879 | AC19: 217.34425 | AD19: 214.36197 | AE19: 207.42213 | AF19: 206.81836 | AG19: 216.71269 | AH19: 223.4144 | AI19: 222.40764 | AJ19: 0.005
A20: of which: Gas-to-Liquids Heat | B20: Refining Industry: Total Energy Use: Natural Gas: Gas-to-Liquids Heat: Low economic growth | C20: 35-AEO2022.17.lowmacro-d011222a | D20: trillion Btu | F20: 0 | G20: 0 | H20: 0 | I20: 0 | J20: 0 | K20: 0 | L20: 0 | M20: 0 | N20: 0 | O20: 0 | P20: 0 | Q20: 0 | R20: 0 | S20: 0 | T20: 0 | U20: 0 | V20: 0 | W20: 0 | X20: 0 | Y20: 0 | Z20: 0 | AA20: 0 | AB20: 0 | AC20: 0 | AD20: 0 | AE20: 0 | AF20: 0 | AG20: 0 | AH20: 0 | AI20: 0 | AJ20: - -
A21: Steam Coal | B21: Refining Industry: Total Energy Use: Steam Coal: Low economic growth | C21: 35-AEO2022.18.lowmacro-d011222a | D21: trillion Btu | F21: 24 | G21: 24 | H21: 0 | I21: 0 | J21: 0 | K21: 0 | L21: 0 | M21: 0 | N21: 0 | O21: 0 | P21: 0 | Q21: 0.044211 | R21: 0.587311 | S21: 0.587311 | T21: 4.129168 | U21: 6.791768 | V21: 10.297455 | W21: 13.768188 | X21: 24.259581 | Y21: 24.055048 | Z21: 30.481363 | AA21: 30.481363 | AB21: 30.481363 | AC21: 30.481363 | AD21: 30.472221 | AE21: 30.481363 | AF21: 30.481363 | AG21: 30.481363 | AH21: 30.481363 | AI21: 30.481363 | AJ21: 0.008
A22: Biofuels Heat and Coproducts | B22: Refining Industry: Total Energy Use: Biofuels Heat and Coproducts: Low economic growth | C22: 35-AEO2022.19.lowmacro-d011222a | D22: trillion Btu | F22: 941.45343 | G22: 933.54883 | H22: 902.31354 | I22: 902.28943 | J22: 910.22437 | K22: 911.72607 | L22: 911.99884 | M22: 912.42938 | N22: 919.52039 | O22: 922.16632 | P22: 925.97485 | Q22: 929.1579 | R22: 931.77387 | S22: 935.22247 | T22: 940.83124 | U22: 944.62891 | V22: 949.54382 | W22: 954.95795 | X22: 969.474 | Y22: 969.95734 | Z22: 978.94367 | AA22: 984.90363 | AB22: 992.83691 | AC22: 1009.6605 | AD22: 1019.3696 | AE22: 1030.2854 | AF22: 1042.0416 | AG22: 1054.1409 | AH22: 1066.8409 | AI22: 1083.0004 | AJ22: 0.005
A23: Purchased Electricity | B23: Refining Industry: Total Energy Use: Purchased Electricity: Low economic growth | C23: 35-AEO2022.20.lowmacro-d011222a | D23: trillion Btu | F23: 187.22299 | G23: 187.22299 | H23: 187.76643 | I23: 184.86105 | J23: 185.47809 | K23: 186.6109 | L23: 183.6449 | M23: 185.39218 | N23: 186.7728 | O23: 188.5428 | P23: 187.41983 | Q23: 191.95367 | R23: 191.76068 | S23: 194.25104 | T23: 193.53644 | U23: 196.57754 | V23: 197.63037 | W23: 198.64825 | X23: 199.39276 | Y23: 199.25093 | Z23: 200.21727 | AA23: 200.02982 | AB23: 200.91527 | AC23: 202.63843 | AD23: 202.20322 | AE23: 201.92714 | AF23: 202.16632 | AG23: 204.93985 | AH23: 207.32062 | AI23: 207.41142 | AJ23: 0.004
A24: Total | B24: Refining Industry: Total Energy Use: Total: Low economic growth | C24: 35-AEO2022.21.lowmacro-d011222a | D24: trillion Btu | F24: 4495.8135 | G24: 4534.2461 | H24: 4377.1079 | I24: 4326.1172 | J24: 4350.793 | K24: 4379.0889 | L24: 4358.6392 | M24: 4377.2129 | N24: 4398.2739 | O24: 4418.4121 | P24: 4415.1543 | Q24: 4404.9683 | R24: 4412.4517 | S24: 4449.5356 | T24: 4459.4307 | U24: 4511.7148 | V24: 4544.7969 | W24: 4567.1685 | X24: 4598.8662 | Y24: 4576.3115 | Z24: 4593.4629 | AA24: 4591.9004 | AB24: 4597.3848 | AC24: 4639.5234 | AD24: 4640.9258 | AE24: 4637.7031 | AF24: 4651.6084 | AG24: 4713.3691 | AH24: 4758.8579 | AI24: 4782.7393 | AJ24: 0.002
A25: Carbon Dioxide Emissions | C25: 35-AEO2022.24.
A26: (million metric tons carbon dioxide) | B26: Refining Industry: Carbon Dioxide Emissions: Low economic growth | C26: 35-AEO2022.25.lowmacro-d011222a | D26: MMmt CO2 | F26: 241.70407 | G26: 245.12738 | H26: 238.10994 | I26: 232.64516 | J26: 233.13074 | K26: 234.2005 | L26: 232.07024 | M26: 233.52861 | N26: 234.22252 | O26: 235.04095 | P26: 234.21455 | Q26: 233.83411 | R26: 234.32123 | S26: 235.57091 | T26: 235.3481 | U26: 237.81638 | V26: 239.53348 | W26: 240.60075 | X26: 242.01614 | Y26: 240.27261 | Z26: 241.00105 | AA26: 240.36909 | AB26: 240.12732 | AC26: 241.51883 | AD26: 240.81566 | AE26: 239.9462 | AF26: 239.82762 | AG26: 242.68574 | AH26: 244.67653 | AI26: 245.05357 | AJ26: 0
A27: Energy Related to Refining Activity Only | C27: 35-AEO2022.27.
A28: Energy Consumption | C28: 35-AEO2022.28.
A29: Residual Fuel Oil | B29: Refining Industry: Refinery Only Energy: Use: Residual Fuel Oil: Low economic growth | C29: 35-AEO2022.29.lowmacro-d011222a | D29: trillion Btu | F29: 0.214 | G29: 0.214 | H29: 0 | I29: 0 | J29: 0 | K29: 0 | L29: 0 | M29: 0 | N29: 0 | O29: 0 | P29: 0 | Q29: 0 | R29: 0 | S29: 0 | T29: 0 | U29: 0 | V29: 0 | W29: 0 | X29: 0 | Y29: 0 | Z29: 0 | AA29: 0 | AB29: 0 | AC29: 0 | AD29: 0 | AE29: 0 | AF29: 0 | AG29: 0 | AH29: 0 | AI29: 0 | AJ29: - -
A30: Distillate Fuel Oil | B30: Refining Industry: Refinery Only Energy: Use: Distillate Fuel Oil: Low economic growth | C30: 35-AEO2022.30.lowmacro-d011222a | D30: trillion Btu | F30: 1.625 | G30: 1.625 | H30: 0 | I30: 0 | J30: 0 | K30: 0 | L30: 0 | M30: 0 | N30: 0 | O30: 0 | P30: 0 | Q30: 0 | R30: 0 | S30: 0 | T30: 0 | U30: 0 | V30: 0 | W30: 0 | X30: 0 | Y30: 0 | Z30: 0 | AA30: 0 | AB30: 0 | AC30: 0 | AD30: 0 | AE30: 0 | AF30: 0 | AG30: 0 | AH30: 0 | AI30: 0 | AJ30: - -
A31: Liquefied Petroleum Gas Heat and Power | B31: Refining Industry: Refinery Only Energy: Use: Liquefied Petroleum Gases: Low economic growth | C31: 35-AEO2022.31.lowmacro-d011222a | D31: trillion Btu | F31: 6.813 | G31: 6.813 | H31: 0 | I31: 0 | J31: 0 | K31: 0 | L31: 0 | M31: 0 | N31: 0 | O31: 0 | P31: 0 | Q31: 0 | R31: 0 | S31: 0 | T31: 0 | U31: 0 | V31: 0 | W31: 0 | X31: 0 | Y31: 0 | Z31: 0 | AA31: 0 | AB31: 0 | AC31: 0 | AD31: 0 | AE31: 0 | AF31: 0 | AG31: 0 | AH31: 0 | AI31: 0 | AJ31: - -
A32: Petroleum Coke | B32: Refining Industry: Refinery Only Energy: Use: Petroleum Coke: Low economic growth | C32: 35-AEO2022.32.lowmacro-d011222a | D32: trillion Btu | F32: 454.61902 | G32: 491.70599 | H32: 512.17004 | I32: 507.68442 | J32: 508.41577 | K32: 501.6297 | L32: 499.41949 | M32: 501.44247 | N32: 503.42487 | O32: 508.64514 | P32: 507.30545 | Q32: 510.25604 | R32: 510.57617 | S32: 511.58743 | T32: 510.87836 | U32: 510.53915 | V32: 508.83008 | W32: 508.80609 | X32: 509.01776 | Y32: 505.9101 | Z32: 506.77811 | AA32: 506.62024 | AB32: 508.24448 | AC32: 509.07855 | AD32: 510.58063 | AE32: 511.49094 | AF32: 511.26907 | AG32: 513.88257 | AH32: 517.29755 | AI32: 518.11548 | AJ32: 0.005
A33: Still Gas | B33: Refining Industry: Refinery Only Energy: Use: Still Gas: Low economic growth | C33: 35-AEO2022.33.lowmacro-d011222a | D33: trillion Btu | F33: 1276.865 | G33: 1275.885 | H33: 1323.2778 | I33: 1318.073 | J33: 1326.8258 | K33: 1331.5831 | L33: 1319.4475 | M33: 1333.1901 | N33: 1333.6689 | O33: 1335.8064 | P33: 1328.7131 | Q33: 1351.6774 | R33: 1347.6113 | S33: 1349.8387 | T33: 1354.9116 | U33: 1361.7104 | V33: 1382.6962 | W33: 1383.4335 | X33: 1384.8945 | Y33: 1366.2391 | Z33: 1368.2394 | AA33: 1357.5138 | AB33: 1349.7498 | AC33: 1353.7228 | AD33: 1341.6931 | AE33: 1334.6233 | AF33: 1323.3475 | AG33: 1336.1302 | AH33: 1344.8271 | AI33: 1333.0242 | AJ33: 0.001
A34: Other Petroleum | B34: Refining Industry: Refinery Only Energy: Use: Other Petroleum: Low economic growth | C34: 35-AEO2022.34.lowmacro-d011222a | D34: trillion Btu | F34: 2.958 | G34: 2.958 | H34: 0 | I34: 0 | J34: 0.372267 | K34: 0.71969 | L34: 9.951056 | M34: 1.636055 | N34: 0 | O34: 0 | P34: 0 | Q34: 0.013138 | R34: 0 | S34: 0 | T34: 0.019257 | U34: 0.138091 | V34: 0.027799 | W34: 0.012505 | X34: 0.099726 | Y34: 0.032392 | Z34: 0.041556 | AA34: 0.077835 | AB34: 0.061223 | AC34: 0.011795 | AD34: 0.02569 | AE34: 0.039747 | AF34: 0.0126 | AG34: 0.039243 | AH34: 0.042319 | AI34: 0.037359 | AJ34: -0.14
A35: Petroleum and Other Liquids Subtotal | B35: Refining Industry: Refinery Only Energy: Use: Petroleum Subtotal: Low economic growth | C35: 35-AEO2022.35.lowmacro-d011222a | D35: trillion Btu | F35: 1743.094 | G35: 1779.201 | H35: 1835.4479 | I35: 1825.7574 | J35: 1835.6139 | K35: 1833.9326 | L35: 1828.818 | M35: 1836.2687 | N35: 1837.0938 | O35: 1844.4515 | P35: 1836.0186 | Q35: 1861.9465 | R35: 1858.1875 | S35: 1861.4261 | T35: 1865.8093 | U35: 1872.3877 | V35: 1891.5541 | W35: 1892.252 | X35: 1894.0121 | Y35: 1872.1815 | Z35: 1875.059 | AA35: 1864.2119 | AB35: 1858.0555 | AC35: 1862.8131 | AD35: 1852.2993 | AE35: 1846.1541 | AF35: 1834.6291 | AG35: 1850.052 | AH35: 1862.1671 | AI35: 1851.177 | AJ35: 0.002
A36: Natural Gas | B36: Refining Industry: Refinery Only Energy: Use: Natural Gas: Low economic growth | C36: 35-AEO2022.36.lowmacro-d011222a | D36: trillion Btu | F36: 858.72315 | G36: 857.25305 | H36: 551.43799 | I36: 529.18518 | J36: 529.53796 | K36: 548.72766 | L36: 539.75134 | M36: 546.42163 | N36: 554.59265 | O36: 557.69312 | P36: 555.9057 | Q36: 534.33868 | R36: 537.55603 | S36: 550.52112 | T36: 544.90601 | U36: 564.22528 | V36: 559.7583 | W36: 566.91125 | X36: 566.3078 | Y36: 575.64697 | Z36: 573.78314 | AA36: 578.16223 | AB36: 585.18103 | AC36: 590.72723 | AD36: 591.06335 | AE36: 585.5863 | AF36: 594.23023 | AG36: 607.37872 | AH36: 613.43616 | AI36: 622.67377 | AJ36: -0.011
A37: Steam Coal | B37: Refining Industry: Refinery Only Energy: Use: Steam Coal: Low economic growth | C37: 35-AEO2022.37.lowmacro-d011222a | D37: trillion Btu | F37: 0 | G37: 0 | H37: 0 | I37: 0 | J37: 0 | K37: 0 | L37: 0 | M37: 0 | N37: 0 | O37: 0 | P37: 0 | Q37: 0 | R37: 0 | S37: 0 | T37: 0 | U37: 0 | V37: 0 | W37: 0 | X37: 0 | Y37: 0 | Z37: 0 | AA37: 0 | AB37: 0 | AC37: 0 | AD37: 0 | AE37: 0 | AF37: 0 | AG37: 0 | AH37: 0 | AI37: 0 | AJ37: - -
A38: Purchased Electricity | B38: Refining Industry: Refinery Only Energy: Use: Purchased Electricity: Low economic growth | C38: 35-AEO2022.38.lowmacro-d011222a | D38: trillion Btu | F38: 150.22299 | G38: 150.22299 | H38: 146.39061 | I38: 143.5092 | J38: 143.77194 | K38: 144.84698 | L38: 141.87497 | M38: 143.60429 | N38: 144.68192 | O38: 146.33949 | P38: 145.05365 | Q38: 149.44209 | R38: 149.10196 | S38: 151.42042 | T38: 150.44222 | U38: 153.31632 | V38: 154.14926 | W38: 154.91486 | X38: 155.00134 | Y38: 154.84001 | Z38: 155.39178 | AA38: 154.89087 | AB38: 155.38863 | AC38: 156.29366 | AD38: 155.37083 | AE38: 154.5392 | AF38: 154.18634 | AG38: 156.35101 | AH38: 158.09168 | AI38: 157.37001 | AJ38: 0.002
A39: Total | B39: Refining Industry: Refinery Only Energy: Use: Total: Low economic growth | C39: 35-AEO2022.39.lowmacro-d011222a | D39: trillion Btu | F39: 2752.04 | G39: 2786.677 | H39: 2533.2764 | I39: 2498.4519 | J39: 2508.9238 | K39: 2527.5071 | L39: 2510.4443 | M39: 2526.2947 | N39: 2536.3684 | O39: 2548.4841 | P39: 2536.978 | Q39: 2545.7273 | R39: 2544.8457 | S39: 2563.3677 | T39: 2561.1575 | U39: 2589.9294 | V39: 2605.4617 | W39: 2614.0779 | X39: 2615.3213 | Y39: 2602.6687 | Z39: 2604.2339 | AA39: 2597.2649 | AB39: 2598.6252 | AC39: 2609.834 | AD39: 2598.7336 | AE39: 2586.2795 | AF39: 2583.0457 | AG39: 2613.7817 | AH39: 2633.6948 | AI39: 2631.2209 | AJ39: -0.002
A40: Carbon Dioxide Emissions | C40: 35-AEO2022.41.
...

Sheet AEO T24 Refining 2022
B1: ref2022.d011222a | C1: 2021 | D1: 2022 | E1: 2023 | F1: 2024 | G1: 2025 | H1: 2026 | I1: 2027 | J1: 2028 | K1: 2029 | L1: 2030 | M1: 2031 | N1: 2032 | O1: 2033 | P1: 2034 | Q1: 2035 | R1: 2036 | S1: 2037 | T1: 2038 | U1: 2039 | V1: 2040 | W1: 2041 | X1: 2042 | Y1: 2043 | Z1: 2044 | AA1: 2045 | AB1: 2046 | AC1: 2047 | AD1: 2048 | AE1: 2049 | AF1: 2050
A4: IRF000 | B4: 24. Refining Industry Energy Consumption | AG4: Average
AG5: Annual
B7: Shipments, Energy Consumption, and Emissions | C7: 2021 | D7: 2022 | E7: 2023 | F7: 2024 | G7: 2025 | H7: 2026 | I7: 2027 | J7: 2028 | K7: 2029 | L7: 2030 | M7: 2031 | N7: 2032 | O7: 2033 | P7: 2034 | Q7: 2035 | R7: 2036 | S7: 2037 | T7: 2038 | U7: 2039 | V7: 2040 | W7: 2041 | X7: 2042 | Y7: 2043 | Z7: 2044 | AA7: 2045 | AB7: 2046 | AC7: 2047 | AD7: 2048 | AE7: 2049 | AF7: 2050 | AG7: 2051
A9: IRF000:ba_ValueofShipme | B9: Value of Shipments (billion 2012 dollars) | C9: ='AEO T24 Refining 2022 Raw'!F6 -> 746.87048 | D9: ='AEO T24 Refining 2022 Raw'!G6 -> 840.716 | E9: ='AEO T24 Refining 2022 Raw'!H6 -> 850.76227 | F9: ='AEO T24 Refining 2022 Raw'!I6 -> 846.17731 | G9: ='AEO T24 Refining 2022 Raw'!J6 -> 846.14966 | H9: ='AEO T24 Refining 2022 Raw'!K6 -> 844.26404 | I9: ='AEO T24 Refining 2022 Raw'!L6 -> 840.59943 | J9: ='AEO T24 Refining 2022 Raw'!M6 -> 838.8761 | ... AG9: ='AEO T24 Refining 2022 Raw'!AJ6 -> 0.004
B10: Inputs to Distillation Units
A11: IRF000:ba_CrudeOilInput | B11: (million barrels per day) | C11: ='AEO T24 Refining 2022 Raw'!F8 -> 15.710509 | D11: ='AEO T24 Refining 2022 Raw'!G8 -> 16.935637 | E11: ='AEO T24 Refining 2022 Raw'!H8 -> 17.158117 | F11: ='AEO T24 Refining 2022 Raw'!I8 -> 17.243862 | G11: ='AEO T24 Refining 2022 Raw'!J8 -> 17.289557 | H11: ='AEO T24 Refining 2022 Raw'!K8 -> 17.248625 | I11: ='AEO T24 Refining 2022 Raw'!L8 -> 17.194527 | J11: ='AEO T24 Refining 2022 Raw'!M8 -> 17.125137 | ... AG11: ='AEO T24 Refining 2022 Raw'!AJ8 -> 0.001
B13: Total Energy Consumption (trillion Btu) 1/
A14: IRF000:ca_ResidualOil | B14: Residual Fuel Oil | C14: ='AEO T24 Refining 2022 Raw'!F10 -> 0.214 | D14: ='AEO T24 Refining 2022 Raw'!G10 -> 0.214 | E14: ='AEO T24 Refining 2022 Raw'!H10 -> 0 | F14: ='AEO T24 Refining 2022 Raw'!I10 -> 0 | G14: ='AEO T24 Refining 2022 Raw'!J10 -> 0 | H14: ='AEO T24 Refining 2022 Raw'!K10 -> 0 | I14: ='AEO T24 Refining 2022 Raw'!L10 -> 0 | J14: ='AEO T24 Refining 2022 Raw'!M10 -> 0 | ... AG14: ='AEO T24 Refining 2022 Raw'!AJ10 -> - -
