Workbook
Name dollars_2019_2012: About!$A$105
Name dollars_2020_2012: About!$A$104
Name dollars_2021_2012: About!$A$103
Name lignite_multiplier: 'Hard Coal and Lig Multipliers'!$N$15
Name nonlignite_multiplier: 'Hard Coal and Lig Multipliers'!$N$16

Sheet About
A1: BFPaT BAU Pretax Fuel Price by Sector
A2: BFPaT BAU Fuel Tax by Sector
A4: Sources: | B4: most fuels and growth rates | D4: Tax on Petroleum Gasoline, Petroleum Diesel, Jet Fuel
B5: Energy Information Administration | D5: Energy Information Administration
B6: 2021 | D6: 2021
B7: Annual Energy Outlook 2021 | D7: Annual Energy Outlook 2021
B8: https://www.eia.gov/outlooks/aeo/tables_side.php | D8: https://www.eia.gov/outlooks/aeo/tables_side.php
B9: Table 3 (and Table 2 for industrial coal consumption fractions by coal type) | D9: Table 59
B11: biomass | D11: Tax on Non-Liquid Fuels
B12: Energy Information Administraton | D12: The Sales Tax Clearinghouse
B13: 2020 | D13: n/a
B14: State Energy Data System (SEDS): 1960-2018 (complete) | D14: FAQ
B15: https://www.eia.gov/state/seds/archive/seper2018.pdf | D15: https://thestc.com/FAQ.stm
B16: Tables ET3, ET4, ET5, and ET7 | D16: Question "What is the average sales tax nationally?"
B18: biofuel diesel | D18: Gas future prices
B19: DOE Alternative Fuels Data Center | D19: CME Group
B20: 2018 | D20: 2020
B21: Clean Cities Alternative Fuel Price Report: January 2018 | D21: Henry Hub Natural Gas Futures - Quotes
B22: https://afdc.energy.gov/files/u/publication/alternative_fuel_price_report_jan_2018.pdf | D22: https://www.cmegroup.com/trading/energy/natural-gas/natural-gas_quotes_globex.html
B23: Page 4, Table 3
B25: heat | D25: Historical Henry Hub Prices, Retail Prices, and Consumption by Sector
B26: Euroheat & Power | D26: EIA
B27: n/a | D27: 2020
B28: DHC & Statistics: United States | D28: Natural Gas: Data
B29: http://www.euroheat.org/United-States-156.aspx | D29: https://www.eia.gov/naturalgas/data.php; https://www.eia.gov/dnav/ng/ng_pri_sum_dcu_nus_a.htm
B30: "Average District Heating price in 2011" (using "Steam" rather than "Water" because most U.S. district heating systems use steam) | D30: Prices; Natural gas spot and futures prices; and Delivered to Consumers links
B32: hydrogen start year costs | D32: Historical Natural Gas Consumption by Sector
B33: California Energy Commission and California Air Resources Board | D33: Bloomberg New Energy Finance
B34: 2015 | D34: 2020
B35: Assessment of Time and Cost Needed to Attain 100 Hydrogen Refueling Stations in California | D35: Hydrogen Economy Outlook: Key Messages
B36: https://ww2.energy.ca.gov/2015publications/CEC-600-2015-016/CEC-600-2015-016.pdf | D36: https://data.bloomberglp.com/professional/sites/24/BNEF-Hydrogen-Economy-Outlook-Key-Messages-30-Mar-2020.pdf
B37: Page 57, Table 12 | D37: Page 5
B39: lignite and non-lignite price multipliers
B40: Energy Information Administration
B41: 2019
B42: Form EIA-923 detailed data
B43: https://www.eia.gov/electricity/data/eia923/
B44: Year 2018, Tab 5
A45: Notes
A47: Pre-Tax Prices
...

Sheet AEO 2022 2
B1: ref2022.d011222a | C1: 2021 | D1: 2022 | E1: 2023 | F1: 2024 | G1: 2025 | H1: 2026 | I1: 2027 | J1: 2028 | K1: 2029 | L1: 2030 | M1: 2031 | N1: 2032 | O1: 2033 | P1: 2034 | Q1: 2035 | R1: 2036 | S1: 2037 | T1: 2038 | U1: 2039 | V1: 2040 | W1: 2041 | X1: 2042 | Y1: 2043 | Z1: 2044 | AA1: 2045 | AB1: 2046 | AC1: 2047 | AD1: 2048 | AE1: 2049 | AF1: 2050
C3: Report | D3: Annual Energy Outlook 2022
C4: Scenario | D4: ref2022 | G4: Reference
C5: Datekey | D5: d011222a
C6: Release Date | E6: March 2022
A10: QUA000 | B10: 2. Energy Consumption by Sector and Source | AG10: Average
B11: (quadrillion Btu, unless otherwise noted) | AG11: Annual
AG12: Change
B13: Sector and Source | C13: 2021 | D13: 2022 | E13: 2023 | F13: 2024 | G13: 2025 | H13: 2026 | I13: 2027 | J13: 2028 | K13: 2029 | L13: 2030 | M13: 2031 | N13: 2032 | O13: 2033 | P13: 2034 | Q13: 2035 | R13: 2036 | S13: 2037 | T13: 2038 | U13: 2039 | V13: 2040 | W13: 2041 | X13: 2042 | Y13: 2043 | Z13: 2044 | AA13: 2045 | AB13: 2046 | AC13: 2047 | AD13: 2048 | AE13: 2049 | AF13: 2050 | AG13: 2021–2050
B15: Residential
A16: QUA000:ca_LiquefiedPetr | B16: Propane | C16: 0.478688 | D16: 0.482703 | E16: 0.464288 | F16: 0.460531 | G16: 0.457639 | H16: 0.454679 | I16: 0.451559 | J16: 0.448273 | K16: 0.444886 | L16: 0.44168 | M16: 0.438529 | N16: 0.435397 | O16: 0.432479 | P16: 0.429935 | Q16: 0.427832 | R16: 0.426087 | S16: 0.424476 | T16: 0.422915 | U16: 0.421446 | V16: 0.42005 | W16: 0.418672 | X16: 0.417295 | Y16: 0.415866 | Z16: 0.414476 | AA16: 0.413321 | AB16: 0.412523 | AC16: 0.412023 | AD16: 0.411646 | AE16: 0.411273 | AF16: 0.410956 | AG16: -0.005247
A17: QUA000:ca_DistillateFue | B17: Distillate Fuel Oil 1/ | C17: 0.419546 | D17: 0.441378 | E17: 0.414719 | F17: 0.404789 | G17: 0.394743 | H17: 0.385008 | I17: 0.375941 | J17: 0.368066 | K17: 0.36113 | L17: 0.355018 | M17: 0.348935 | N17: 0.342917 | O17: 0.337075 | P17: 0.331558 | Q17: 0.326194 | R17: 0.320915 | S17: 0.315659 | T17: 0.31053 | U17: 0.305559 | V17: 0.300633 | W17: 0.295725 | X17: 0.290945 | Y17: 0.286024 | Z17: 0.281041 | AA17: 0.276311 | AB17: 0.271616 | AC17: 0.26707 | AD17: 0.262644 | AE17: 0.258195 | AF17: 0.253878 | AG17: -0.017172
A18: QUA000:ca_PetroleumSubt | B18: Petroleum and Other Liquids Subtotal | C18: 0.898234 | D18: 0.924081 | E18: 0.879007 | F18: 0.86532 | G18: 0.852382 | H18: 0.839687 | I18: 0.8275 | J18: 0.816339 | K18: 0.806015 | L18: 0.796699 | M18: 0.787464 | N18: 0.778314 | O18: 0.769554 | P18: 0.761493 | Q18: 0.754026 | R18: 0.747001 | S18: 0.740135 | T18: 0.733445 | U18: 0.727005 | V18: 0.720684 | W18: 0.714397 | X18: 0.70824 | Y18: 0.70189 | Z18: 0.695517 | AA18: 0.689632 | AB18: 0.684139 | AC18: 0.679093 | AD18: 0.674289 | AE18: 0.669469 | AF18: 0.664835 | AG18: -0.010322
A19: QUA000:ca_NaturalGas | B19: Natural Gas | C19: 5.007376 | D19: 5.070196 | E19: 4.99077 | F19: 5.003871 | G19: 5.018683 | H19: 5.024077 | I19: 5.023698 | J19: 5.014405 | K19: 4.998899 | L19: 4.983529 | M19: 4.969099 | N19: 4.951568 | O19: 4.934161 | P19: 4.920165 | Q19: 4.911035 | R19: 4.90425 | S19: 4.896574 | T19: 4.888241 | U19: 4.879435 | V19: 4.871953 | W19: 4.863002 | X19: 4.855389 | Y19: 4.849878 | Z19: 4.845332 | AA19: 4.840716 | AB19: 4.835385 | AC19: 4.829076 | AD19: 4.821843 | AE19: 4.813109 | AF19: 4.803506 | AG19: -0.001432
A20: QUA000:ca_RenewableEner | B20: Renewable Energy 2/ | C20: 0.463756 | D20: 0.48347 | E20: 0.450565 | F20: 0.445645 | G20: 0.442627 | H20: 0.439965 | I20: 0.436402 | J20: 0.431361 | K20: 0.425031 | L20: 0.417201 | M20: 0.409955 | N20: 0.403153 | O20: 0.395951 | P20: 0.388133 | Q20: 0.380095 | R20: 0.372198 | S20: 0.365149 | T20: 0.358661 | U20: 0.352049 | V20: 0.346263 | W20: 0.340993 | X20: 0.335841 | Y20: 0.331453 | Z20: 0.327786 | AA20: 0.323771 | AB20: 0.320077 | AC20: 0.315878 | AD20: 0.311247 | AE20: 0.306821 | AF20: 0.302059 | AG20: -0.014675
A21: QUA000:ca_Electricity | B21: Purchased Electricity | C21: 5.085111 | D21: 4.988574 | E21: 5.101863 | F21: 5.136075 | G21: 5.167903 | H21: 5.190618 | I21: 5.207037 | J21: 5.22809 | K21: 5.249576 | L21: 5.270422 | M21: 5.291863 | N21: 5.31704 | O21: 5.344032 | P21: 5.370875 | Q21: 5.406477 | R21: 5.448595 | S21: 5.494287 | T21: 5.540269 | U21: 5.586945 | V21: 5.627694 | W21: 5.668567 | X21: 5.710461 | Y21: 5.75561 | Z21: 5.803448 | AA21: 5.850867 | AB21: 5.903627 | AC21: 5.955761 | AD21: 6.009111 | AE21: 6.063807 | AF21: 6.124871 | AG21: 0.006436
A22: QUA000:ca_DeliveredEner | B22: Delivered Energy | C22: 11.454478 | D22: 11.466321 | E22: 11.422204 | F22: 11.450912 | G22: 11.481594 | H22: 11.494348 | I22: 11.494637 | J22: 11.490195 | K22: 11.47952 | L22: 11.467852 | M22: 11.458383 | N22: 11.450075 | O22: 11.4437 | P22: 11.440667 | Q22: 11.451631 | R22: 11.472043 | S22: 11.496145 | T22: 11.520617 | U22: 11.545433 | V22: 11.566592 | W22: 11.58696 | X22: 11.609931 | Y22: 11.63883 | Z22: 11.672083 | AA22: 11.704986 | AB22: 11.743228 | AC22: 11.779808 | AD22: 11.816492 | AE22: 11.853207 | AF22: 11.89527 | AG22: 0.001303
A23: QUA000:ca_ElectricityRe | B23: Electricity Related Losses | C23: 9.377542 | D23: 9.196331 | E23: 9.314765 | F23: 9.184469 | G23: 9.087095 | H23: 9.024928 | I23: 8.956861 | J23: 8.875485 | K23: 8.864312 | L23: 8.860741 | M23: 8.867586 | N23: 8.875726 | O23: 8.84233 | P23: 8.842175 | Q23: 8.850697 | R23: 8.882401 | S23: 8.918847 | T23: 8.951853 | U23: 9.000834 | V23: 9.040874 | W23: 9.082237 | X23: 9.119998 | Y23: 9.157075 | Z23: 9.203964 | AA23: 9.249299 | AB23: 9.290339 | AC23: 9.335984 | AD23: 9.39344 | AE23: 9.446524 | AF23: 9.518768 | AG23: 0.000516
A24: QUA000:ca_Total | B24: Total | C24: 20.83202 | D24: 20.662651 | E24: 20.736969 | F24: 20.635382 | G24: 20.568689 | H24: 20.519276 | I24: 20.451496 | J24: 20.365681 | K24: 20.343832 | L24: 20.328592 | M24: 20.32597 | N24: 20.325802 | O24: 20.28603 | P24: 20.282843 | Q24: 20.302326 | R24: 20.354445 | S24: 20.414993 | T24: 20.472469 | U24: 20.546267 | V24: 20.607466 | W24: 20.669197 | X24: 20.729929 | Y24: 20.795906 | Z24: 20.876047 | AA24: 20.954285 | AB24: 21.033567 | AC24: 21.115791 | AD24: 21.209932 | AE24: 21.29973 | AF24: 21.41404 | AG24: 0.000951
B26: Commercial
A27: QUA000:da_LiquefiedPetr | B27: Propane | C27: 0.17859 | D27: 0.18783 | E27: 0.186579 | F27: 0.184479 | G27: 0.18239 | H27: 0.180182 | I27: 0.18182 | J27: 0.18334 | K27: 0.18487 | L27: 0.18648 | M27: 0.188105 | N27: 0.189644 | O27: 0.191298 | P27: 0.193028 | Q27: 0.194755 | R27: 0.196456 | S27: 0.198034 | T27: 0.199594 | U27: 0.201224 | V27: 0.202767 | W27: 0.20432 | X27: 0.205891 | Y27: 0.207382 | Z27: 0.20892 | AA27: 0.210623 | AB27: 0.212427 | AC27: 0.214246 | AD27: 0.216022 | AE27: 0.217762 | AF27: 0.219574 | AG27: 0.007149
A28: QUA000:da_MotorGasoline | B28: Motor Gasoline 3/ | C28: 0.35056 | D28: 0.35151 | E28: 0.353471 | F28: 0.353966 | G28: 0.354745 | H28: 0.355503 | I28: 0.356187 | J28: 0.356588 | K28: 0.357041 | L28: 0.357326 | M28: 0.357812 | N28: 0.357763 | O28: 0.358197 | P28: 0.358654 | Q28: 0.359099 | R28: 0.359576 | S28: 0.360009 | T28: 0.360383 | U28: 0.360918 | V28: 0.361148 | W28: 0.36152 | X28: 0.361853 | Y28: 0.362139 | Z28: 0.362525 | AA28: 0.362952 | AB28: 0.363336 | AC28: 0.363789 | AD28: 0.36427 | AE28: 0.364716 | AF28: 0.365384 | AG28: 0.001429
A29: QUA000:da_Kerosene | B29: Kerosene | C29: 0.00185 | D29: 0.00174 | E29: 0.002293 | F29: 0.001994 | G29: 0.001895 | H29: 0.00178 | I29: 0.001731 | J29: 0.001694 | K29: 0.00167 | L29: 0.001676 | M29: 0.001625 | N29: 0.001531 | O29: 0.001523 | P29: 0.001517 | Q29: 0.001507 | R29: 0.001494 | S29: 0.001464 | T29: 0.001443 | U29: 0.001436 | V29: 0.001397 | W29: 0.001371 | X29: 0.00136 | Y29: 0.001324 | Z29: 0.001289 | AA29: 0.001286 | AB29: 0.001265 | AC29: 0.001267 | AD29: 0.001271 | AE29: 0.00126 | AF29: 0.001271 | AG29: -0.012861
A30: QUA000:da_DistillateFue | B30: Distillate Fuel Oil | C30: 0.31439 | D30: 0.32436 | E30: 0.322703 | F30: 0.320352 | G30: 0.31806 | H30: 0.315785 | I30: 0.316033 | J30: 0.315139 | K30: 0.313409 | L30: 0.311615 | M30: 0.309806 | N30: 0.307297 | O30: 0.305038 | P30: 0.303233 | Q30: 0.301571 | R30: 0.299843 | S30: 0.297911 | T30: 0.295842 | U30: 0.293922 | V30: 0.291693 | W30: 0.289451 | X30: 0.287349 | Y30: 0.285039 | Z30: 0.282571 | AA30: 0.280451 | AB30: 0.278366 | AC30: 0.276538 | AD30: 0.274924 | AE30: 0.273241 | AF30: 0.271715 | AG30: -0.005018
A31: QUA000:da_ResidualFuel | B31: Residual Fuel Oil | C31: 0.0019 | D31: 0.0019 | E31: 0.002376 | F31: 0.002199 | G31: 0.002339 | H31: 0.002517 | I31: 0.002365 | J31: 0.002365 | K31: 0.002377 | L31: 0.002376 | M31: 0.002383 | N31: 0.002373 | O31: 0.002384 | P31: 0.00239 | Q31: 0.00242 | R31: 0.00244 | S31: 0.002467 | T31: 0.002477 | U31: 0.002522 | V31: 0.002438 | W31: 0.00244 | X31: 0.002461 | Y31: 0.002443 | Z31: 0.002426 | AA31: 0.002446 | AB31: 0.002447 | AC31: 0.002469 | AD31: 0.002502 | AE31: 0.002518 | AF31: 0.002566 | AG31: 0.010417
A32: QUA000:da_PetroleumSubt | B32: Petroleum and Other Liquids Subtotal | C32: 0.84729 | D32: 0.86734 | E32: 0.867423 | F32: 0.86299 | G32: 0.859428 | H32: 0.855766 | I32: 0.858137 | J32: 0.859126 | K32: 0.859367 | L32: 0.859474 | M32: 0.859731 | N32: 0.858608 | O32: 0.85844 | P32: 0.858822 | Q32: 0.859353 | R32: 0.859809 | S32: 0.859885 | T32: 0.859738 | U32: 0.860021 | V32: 0.859443 | W32: 0.859103 | X32: 0.858913 | Y32: 0.858327 | Z32: 0.85773 | AA32: 0.857758 | AB32: 0.857841 | AC32: 0.858308 | AD32: 0.85899 | AE32: 0.859497 | AF32: 0.86051 | AG32: 0.000534
A33: QUA000:da_NaturalGas | B33: Natural Gas | C33: 3.481153 | D33: 3.618408 | E33: 3.562652 | F33: 3.568658 | G33: 3.578824 | H33: 3.577957 | I33: 3.593081 | J33: 3.596354 | K33: 3.591724 | L33: 3.587628 | M33: 3.588656 | N33: 3.586138 | O33: 3.582798 | P33: 3.583007 | Q33: 3.588976 | R33: 3.5977 | S33: 3.603375 | T33: 3.605938 | U33: 3.606794 | V33: 3.608207 | W33: 3.608019 | X33: 3.610833 | Y33: 3.616942 | Z33: 3.623439 | AA33: 3.630058 | AB33: 3.635484 | AC33: 3.639474 | AD33: 3.642248 | AE33: 3.642725 | AF33: 3.642333 | AG33: 0.001562
A34: QUA000:da_Coal | B34: Coal | C34: 0.01575 | D34: 0.01449 | E34: 0.015575 | F34: 0.015605 | G34: 0.015098 | H34: 0.014739 | I34: 0.014763 | J34: 0.01474 | K34: 0.014793 | L34: 0.014846 | M34: 0.015139 | N34: 0.014936 | O34: 0.015003 | P34: 0.015091 | Q34: 0.015483 | R34: 0.015631 | S34: 0.015763 | T34: 0.01586 | U34: 0.015857 | V34: 0.015841 | W34: 0.01585 | X34: 0.016514 | Y34: 0.016906 | Z34: 0.016929 | AA34: 0.016957 | AB34: 0.017001 | AC34: 0.017139 | AD34: 0.017267 | AE34: 0.017347 | AF34: 0.017454 | AG34: 0.003548
A35: QUA000:da_RenewableEner | B35: Renewable Energy 4/ | C35: 0.124386 | D35: 0.124386 | E35: 0.124386 | F35: 0.124386 | G35: 0.124386 | H35: 0.124386 | I35: 0.124386 | J35: 0.124386 | K35: 0.124386 | L35: 0.124386 | M35: 0.124386 | N35: 0.124386 | O35: 0.124386 | P35: 0.124386 | Q35: 0.124386 | R35: 0.124386 | S35: 0.124386 | T35: 0.124386 | U35: 0.124386 | V35: 0.124386 | W35: 0.124386 | X35: 0.124386 | Y35: 0.124386 | Z35: 0.124386 | AA35: 0.124386 | AB35: 0.124386 | AC35: 0.124386 | AD35: 0.124386 | AE35: 0.124386 | AF35: 0.124386 | AG35: 0
A36: QUA000:da_Electricity | B36: Purchased Electricity | C36: 4.499543 | D36: 4.539952 | E36: 4.572258 | F36: 4.560517 | G36: 4.554118 | H36: 4.53431 | I36: 4.538095 | J36: 4.54117 | K36: 4.545389 | L36: 4.54625 | M36: 4.552204 | N36: 4.561535 | O36: 4.571701 | P36: 4.585947 | Q36: 4.610533 | R36: 4.635308 | S36: 4.658102 | T36: 4.685641 | U36: 4.712861 | V36: 4.733045 | W36: 4.75976 | X36: 4.785551 | Y36: 4.817082 | Z36: 4.851602 | AA36: 4.885552 | AB36: 4.92259 | AC36: 4.962389 | AD36: 5.003931 | AE36: 5.045875 | AF36: 5.093176 | AG36: 0.004282
A37: QUA000:da_DeliveredEner | B37: Delivered Energy | C37: 8.968122 | D37: 9.164577 | E37: 9.142294 | F37: 9.132156 | G37: 9.131854 | H37: 9.107158 | I37: 9.128462 | J37: 9.135776 | K37: 9.135661 | L37: 9.132584 | M37: 9.140117 | N37: 9.145603 | O37: 9.152327 | P37: 9.167253 | Q37: 9.198732 | R37: 9.232837 | S37: 9.261511 | T37: 9.291564 | U37: 9.31992 | V37: 9.340922 | W37: 9.367119 | X37: 9.396197 | Y37: 9.433643 | Z37: 9.474088 | AA37: 9.514711 | AB37: 9.557301 | AC37: 9.601694 | AD37: 9.64682 | AE37: 9.689831 | AF37: 9.737859 | AG37: 0.002843
A38: QUA000:da_ElectricityRe | B38: Electricity Related Losses | C38: 8.297687 | D38: 8.369306 | E38: 8.347835 | F38: 8.15524 | G38: 8.007833 | H38: 7.883806 | I38: 7.806182 | J38: 7.709332 | K38: 7.675239 | L38: 7.643247 | M38: 7.628137 | N38: 7.614562 | O38: 7.564417 | P38: 7.549934 | Q38: 7.547693 | R38: 7.556566 | S38: 7.561472 | T38: 7.570962 | U38: 7.592642 | V38: 7.603622 | W38: 7.626137 | X38: 7.642853 | Y38: 7.663895 | Z38: 7.694386 | AA38: 7.723289 | AB38: 7.746513 | AC38: 7.778818 | AD38: 7.822142 | AE38: 7.860735 | AF38: 7.915395 | AG38: -0.001625
A39: QUA000:da_Total | B39: Total | C39: 17.265808 | D39: 17.533882 | E39: 17.490128 | F39: 17.287395 | G39: 17.139687 | H39: 16.990963 | I39: 16.934645 | J39: 16.845108 | K39: 16.8109 | L39: 16.775831 | M39: 16.768253 | N39: 16.760166 | O39: 16.716743 | P39: 16.717186 | Q39: 16.746426 | R39: 16.789402 | S39: 16.822983 | T39: 16.862526 | U39: 16.912561 | V39: 16.944546 | W39: 16.993256 | X39: 17.039051 | Y39: 17.097538 | Z39: 17.168474 | AA39: 17.238001 | AB39: 17.303814 | AC39: 17.380512 | AD39: 17.468962 | AE39: 17.550566 | AF39: 17.653254 | AG39: 0.000766
B41: Industrial 5/
A42: QUA000:ea_LiquefiedPetr | B42: Liquefied Petroleum Gases and Other 6/ | C42: 3.525503 | D42: 3.659933 | E42: 3.826037 | F42: 3.807156 | G42: 3.885298 | H42: 3.954717 | I42: 3.994848 | J42: 4.020617 | K42: 4.024005 | L42: 4.03884 | M42: 4.080049 | N42: 4.155496 | O42: 4.201034 | P42: 4.221895 | Q42: 4.242743 | R42: 4.270905 | S42: 4.30229 | T42: 4.326283 | U42: 4.35443 | V42: 4.366281 | W42: 4.383568 | X42: 4.407776 | Y42: 4.446388 | Z42: 4.447725 | AA42: 4.455647 | AB42: 4.511288 | AC42: 4.532683 | AD42: 4.502203 | AE42: 4.504282 | AF42: 4.568481 | AG42: 0.008977
A43: QUA000:ea_MotorGasoline | B43: Motor Gasoline 3/ | C43: 0.251457 | D43: 0.245233 | E43: 0.245962 | F43: 0.24949 | G43: 0.252653 | H43: 0.254981 | I43: 0.256543 | J43: 0.259321 | K43: 0.261791 | L43: 0.263735 | M43: 0.265413 | N43: 0.269782 | O43: 0.273194 | P43: 0.27352 | Q43: 0.273713 | R43: 0.274228 | S43: 0.276022 | T43: 0.278566 | U43: 0.281453 | V43: 0.283822 | W43: 0.285497 | X43: 0.287173 | Y43: 0.288766 | Z43: 0.290012 | AA43: 0.29119 | AB43: 0.292838 | AC43: 0.294271 | AD43: 0.29565 | AE43: 0.297591 | AF43: 0.300178 | AG43: 0.006126
A44: QUA000:ea_DistillateFue | B44: Distillate Fuel Oil | C44: 1.155744 | D44: 1.128442 | E44: 1.126598 | F44: 1.131399 | G44: 1.139035 | H44: 1.144452 | I44: 1.146798 | J44: 1.154044 | K44: 1.160566 | L44: 1.165561 | M44: 1.170175 | N44: 1.185123 | O44: 1.196447 | P44: 1.196179 | Q44: 1.195582 | R44: 1.196565 | S44: 1.202659 | T44: 1.211916 | U44: 1.22198 | V44: 1.229472 | W44: 1.235178 | X44: 1.241056 | Y44: 1.246023 | Z44: 1.249249 | AA44: 1.252306 | AB44: 1.25728 | AC44: 1.261749 | AD44: 1.266001 | AE44: 1.272091 | AF44: 1.281459 | AG44: 0.003567
A45: QUA000:ea_ResidualFuel | B45: Residual Fuel Oil | C45: 0.041609 | D45: 0.038239 | E45: 0.038356 | F45: 0.035517 | G45: 0.034044 | H45: 0.034206 | I45: 0.034337 | J45: 0.035531 | K45: 0.036764 | L45: 0.037789 | M45: 0.038746 | N45: 0.039363 | O45: 0.040495 | P45: 0.04097 | Q45: 0.041007 | R45: 0.041183 | S45: 0.041764 | T45: 0.042273 | U45: 0.043174 | V45: 0.042564 | W45: 0.04309 | X45: 0.043467 | Y45: 0.042769 | Z45: 0.042051 | AA45: 0.041564 | AB45: 0.041169 | AC45: 0.041241 | AD45: 0.041506 | AE45: 0.041357 | AF45: 0.041823 | AG45: 0.000177
A46: QUA000:ea_Petrochemical | B46: Petrochemical Feedstocks | C46: 0.583656 | D46: 0.563777 | E46: 0.6309 | F46: 0.55 | G46: 0.55 | H46: 0.55 | I46: 0.55 | J46: 0.55 | K46: 0.55 | L46: 0.55 | M46: 0.55 | N46: 0.55 | O46: 0.55 | P46: 0.55 | Q46: 0.55 | R46: 0.55 | S46: 0.55 | T46: 0.55 | U46: 0.55 | V46: 0.55 | W46: 0.55 | X46: 0.55 | Y46: 0.55 | Z46: 0.55 | AA46: 0.55 | AB46: 0.55 | AC46: 0.55 | AD46: 0.55 | AE46: 0.55 | AF46: 0.55 | AG46: -0.002046
A47: QUA000:ea_OtherPetroleu | B47: Other Petroleum 7/ | C47: 3.089952 | D47: 3.017606 | E47: 3.081593 | F47: 3.141184 | G47: 3.155158 | H47: 3.15898 | I47: 3.158485 | J47: 3.200037 | K47: 3.228584 | L47: 3.254435 | M47: 3.261669 | N47: 3.294676 | O47: 3.307526 | P47: 3.313891 | Q47: 3.314744 | R47: 3.3215 | S47: 3.347294 | T47: 3.353019 | U47: 3.365184 | V47: 3.332521 | W47: 3.34125 | X47: 3.334323 | Y47: 3.319442 | Z47: 3.314479 | AA47: 3.296336 | AB47: 3.288291 | AC47: 3.277879 | AD47: 3.292141 | AE47: 3.303919 | AF47: 3.302853 | AG47: 0.0023
...

Sheet AEO 2021 2
B1: ref2021.d113020a | C1: 2020 | D1: 2021 | E1: 2022 | F1: 2023 | G1: 2024 | H1: 2025 | I1: 2026 | J1: 2027 | K1: 2028 | L1: 2029 | M1: 2030 | N1: 2031 | O1: 2032 | P1: 2033 | Q1: 2034 | R1: 2035 | S1: 2036 | T1: 2037 | U1: 2038 | V1: 2039 | W1: 2040 | X1: 2041 | Y1: 2042 | Z1: 2043 | AA1: 2044 | AB1: 2045 | AC1: 2046 | AD1: 2047 | AE1: 2048 | AF1: 2049 | AG1: 2050
C3: Report | D3: Annual Energy Outlook 2021
C4: Scenario | D4: ref2021 | G4: Reference case
C5: Datekey | D5: d113020a
C6: Release Date | E6: January 2021
A10: QUA000 | B10: 2. Energy Consumption by Sector and Source | AH10: Compound
B11: (quadrillion Btu, unless otherwise noted) | AH11: Growth
AH12: 2020-2050
B13: Sector and Source | C13: 2020 | D13: 2021 | E13: 2022 | F13: 2023 | G13: 2024 | H13: 2025 | I13: 2026 | J13: 2027 | K13: 2028 | L13: 2029 | M13: 2030 | N13: 2031 | O13: 2032 | P13: 2033 | Q13: 2034 | R13: 2035 | S13: 2036 | T13: 2037 | U13: 2038 | V13: 2039 | W13: 2040 | X13: 2041 | Y13: 2042 | Z13: 2043 | AA13: 2044 | AB13: 2045 | AC13: 2046 | AD13: 2047 | AE13: 2048 | AF13: 2049 | AG13: 2050 | AH13: (percent)
B15: Residential
A16: QUA000:ca_LiquefiedPetr | B16: Propane | C16: 0.45518 | D16: 0.474045 | E16: 0.470818 | F16: 0.46705 | G16: 0.463122 | H16: 0.45916 | I16: 0.455288 | J16: 0.451774 | K16: 0.448461 | L16: 0.445483 | M16: 0.442539 | N16: 0.439852 | O16: 0.437278 | P16: 0.434946 | Q16: 0.432862 | R16: 0.431117 | S16: 0.429486 | T16: 0.42797 | U16: 0.426517 | V16: 0.425173 | W16: 0.423932 | X16: 0.422732 | Y16: 0.421615 | Z16: 0.420587 | AA16: 0.419687 | AB16: 0.419045 | AC16: 0.418424 | AD16: 0.417723 | AE16: 0.417084 | AF16: 0.41658 | AG16: 0.416192 | AH16: -0.00298
A17: QUA000:ca_DistillateFue | B17: Distillate Fuel Oil 1/ | C17: 0.429274 | D17: 0.454966 | E17: 0.452338 | F17: 0.438593 | G17: 0.425681 | H17: 0.414456 | I17: 0.404474 | J17: 0.396042 | K17: 0.388227 | L17: 0.381239 | M17: 0.374649 | N17: 0.36844 | O17: 0.362362 | P17: 0.356616 | Q17: 0.351066 | R17: 0.345831 | S17: 0.340664 | T17: 0.335491 | U17: 0.330365 | V17: 0.325589 | W17: 0.320742 | X17: 0.315938 | Y17: 0.311213 | Z17: 0.306462 | AA17: 0.301972 | AB17: 0.297575 | AC17: 0.29301 | AD17: 0.288385 | AE17: 0.283959 | AF17: 0.279589 | AG17: 0.275341 | AH17: -0.014694
A18: QUA000:ca_PetroleumSubt | B18: Petroleum and Other Liquids Subtotal | C18: 0.884454 | D18: 0.929011 | E18: 0.923157 | F18: 0.905643 | G18: 0.888803 | H18: 0.873616 | I18: 0.859762 | J18: 0.847816 | K18: 0.836689 | L18: 0.826722 | M18: 0.817188 | N18: 0.808292 | O18: 0.79964 | P18: 0.791562 | Q18: 0.783928 | R18: 0.776948 | S18: 0.77015 | T18: 0.763461 | U18: 0.756881 | V18: 0.750762 | W18: 0.744674 | X18: 0.738671 | Y18: 0.732828 | Z18: 0.727049 | AA18: 0.72166 | AB18: 0.71662 | AC18: 0.711434 | AD18: 0.706107 | AE18: 0.701044 | AF18: 0.696169 | AG18: 0.691533 | AH18: -0.008168
A19: QUA000:ca_NaturalGas | B19: Natural Gas | C19: 4.96935 | D19: 4.841384 | E19: 4.978416 | F19: 4.970707 | G19: 4.97238 | H19: 4.968029 | I19: 4.956164 | J19: 4.942776 | K19: 4.931273 | L19: 4.920139 | M19: 4.903756 | N19: 4.891912 | O19: 4.883052 | P19: 4.874524 | Q19: 4.866061 | R19: 4.860207 | S19: 4.8556 | T19: 4.851071 | U19: 4.846893 | V19: 4.843016 | W19: 4.840974 | X19: 4.838866 | Y19: 4.837218 | Z19: 4.83576 | AA19: 4.835349 | AB19: 4.834342 | AC19: 4.833664 | AD19: 4.832069 | AE19: 4.83002 | AF19: 4.82676 | AG19: 4.82341 | AH19: -0.000993
A20: QUA000:ca_RenewableEner | B20: Renewable Energy 2/ | C20: 0.457512 | D20: 0.454333 | E20: 0.443909 | F20: 0.448911 | G20: 0.454326 | H20: 0.456317 | I20: 0.45534 | J20: 0.451821 | K20: 0.448893 | L20: 0.444799 | M20: 0.440398 | N20: 0.435099 | O20: 0.429791 | P20: 0.423655 | Q20: 0.416962 | R20: 0.409784 | S20: 0.40251 | T20: 0.396165 | U20: 0.3906 | V20: 0.384448 | W20: 0.379422 | X20: 0.37479 | Y20: 0.370205 | Z20: 0.366157 | AA20: 0.361594 | AB20: 0.357145 | AC20: 0.353832 | AD20: 0.35059 | AE20: 0.346575 | AF20: 0.34247 | AG20: 0.338111 | AH20: -0.01003
A21: QUA000:ca_Electricity | B21: Purchased Electricity | C21: 5.052733 | D21: 5.085547 | E21: 5.091327 | F21: 5.10172 | G21: 5.115735 | H21: 5.131444 | I21: 5.153737 | J21: 5.175787 | K21: 5.20145 | L21: 5.229 | M21: 5.257937 | N21: 5.29014 | O21: 5.326302 | P21: 5.36082 | Q21: 5.40049 | R21: 5.442099 | S21: 5.487025 | T21: 5.534366 | U21: 5.582504 | V21: 5.630486 | W21: 5.674673 | X21: 5.718518 | Y21: 5.763376 | Z21: 5.812753 | AA21: 5.862584 | AB21: 5.912036 | AC21: 5.963373 | AD21: 6.013557 | AE21: 6.065495 | AF21: 6.119937 | AG21: 6.177919 | AH21: 0.006724
A22: QUA000:ca_DeliveredEner | B22: Delivered Energy | C22: 11.364052 | D22: 11.310277 | E22: 11.43681 | F22: 11.426983 | G22: 11.431243 | H22: 11.429406 | I22: 11.425002 | J22: 11.418199 | K22: 11.418305 | L22: 11.42066 | M22: 11.419279 | N22: 11.425442 | O22: 11.438783 | P22: 11.450561 | Q22: 11.46744 | R22: 11.489039 | S22: 11.515284 | T22: 11.545061 | U22: 11.576879 | V22: 11.608712 | W22: 11.639742 | X22: 11.670846 | Y22: 11.703629 | Z22: 11.741718 | AA22: 11.781187 | AB22: 11.820144 | AC22: 11.862303 | AD22: 11.902324 | AE22: 11.943133 | AF22: 11.985336 | AG22: 12.030972 | AH22: 0.001903
A23: QUA000:ca_ElectricityRe | B23: Electricity Related Losses | C23: 9.417956 | D23: 9.469259 | E23: 9.523586 | F23: 9.353558 | G23: 9.192634 | H23: 8.961144 | I23: 8.754603 | J23: 8.691695 | K23: 8.686027 | L23: 8.699572 | M23: 8.728955 | N23: 8.761385 | O23: 8.769801 | P23: 8.792642 | Q23: 8.811792 | R23: 8.85434 | S23: 8.896054 | T23: 8.943662 | U23: 8.971651 | V23: 9.00147 | W23: 9.030401 | X23: 9.071213 | Y23: 9.114241 | Z23: 9.156261 | AA23: 9.196094 | AB23: 9.234004 | AC23: 9.281438 | AD23: 9.33171 | AE23: 9.396441 | AF23: 9.454361 | AG23: 9.504673 | AH23: 0.000306
A24: QUA000:ca_Total | B24: Total | C24: 20.782009 | D24: 20.779537 | E24: 20.960396 | F24: 20.78054 | G24: 20.623877 | H24: 20.390551 | I24: 20.179605 | J24: 20.109894 | K24: 20.104332 | L24: 20.120232 | M24: 20.148235 | N24: 20.186827 | O24: 20.208584 | P24: 20.243202 | Q24: 20.279232 | R24: 20.34338 | S24: 20.411339 | T24: 20.488724 | U24: 20.548531 | V24: 20.610182 | W24: 20.670143 | X24: 20.742058 | Y24: 20.817871 | Z24: 20.89798 | AA24: 20.97728 | AB24: 21.054148 | AC24: 21.143742 | AD24: 21.234034 | AE24: 21.339573 | AF24: 21.439697 | AG24: 21.535645 | AH24: 0.001188
B26: Commercial
A27: QUA000:da_LiquefiedPetr | B27: Propane | C27: 0.16909 | D27: 0.17043 | E27: 0.171078 | F27: 0.172316 | G27: 0.173561 | H27: 0.174816 | I27: 0.176343 | J27: 0.177955 | K27: 0.179406 | L27: 0.18099 | M27: 0.182417 | N27: 0.184083 | O27: 0.185733 | P27: 0.187505 | Q27: 0.189335 | R27: 0.191154 | S27: 0.192913 | T27: 0.194645 | U27: 0.196334 | V27: 0.19808 | W27: 0.199782 | X27: 0.201515 | Y27: 0.203344 | Z27: 0.20515 | AA27: 0.207034 | AB27: 0.209041 | AC27: 0.210896 | AD27: 0.212778 | AE27: 0.214758 | AF27: 0.216768 | AG27: 0.218797 | AH27: 0.008627
A28: QUA000:da_MotorGasoline | B28: Motor Gasoline 3/ | C28: 0.32368 | D28: 0.35236 | E28: 0.356357 | F28: 0.360291 | G28: 0.364608 | H28: 0.368727 | I28: 0.369102 | J28: 0.369501 | K28: 0.369535 | L28: 0.369811 | M28: 0.369612 | N28: 0.370091 | O28: 0.370272 | P28: 0.370693 | Q28: 0.371042 | R28: 0.371446 | S28: 0.371816 | T28: 0.372163 | U28: 0.372466 | V28: 0.372967 | W28: 0.373217 | X28: 0.373596 | Y28: 0.37404 | Z28: 0.374493 | AA28: 0.37501 | AB28: 0.375614 | AC28: 0.375965 | AD28: 0.37649 | AE28: 0.376973 | AF28: 0.377576 | AG28: 0.378132 | AH28: 0.005196
A29: QUA000:da_Kerosene | B29: Kerosene | C29: 0.00133 | D29: 0.0015 | E29: 0.001517 | F29: 0.001596 | G29: 0.001578 | H29: 0.001647 | I29: 0.001544 | J29: 0.0015 | K29: 0.001387 | L29: 0.001341 | M29: 0.001233 | N29: 0.001191 | O29: 0.001136 | P29: 0.001107 | Q29: 0.001085 | R29: 0.001068 | S29: 0.001046 | T29: 0.001009 | U29: 0.000971 | V29: 0.000967 | W29: 0.000917 | X29: 0.000886 | Y29: 0.000865 | Z29: 0.000823 | AA29: 0.00082 | AB29: 0.000808 | AC29: 0.000776 | AD29: 0.000762 | AE29: 0.000766 | AF29: 0.000754 | AG29: 0.00075 | AH29: -0.018902
A30: QUA000:da_DistillateFue | B30: Distillate Fuel Oil | C30: 0.30937 | D30: 0.32117 | E30: 0.332396 | F30: 0.330707 | G30: 0.329671 | H30: 0.329941 | I30: 0.329299 | J30: 0.327888 | K30: 0.324954 | L30: 0.322151 | M30: 0.318692 | N30: 0.315975 | O30: 0.313346 | P30: 0.311243 | Q30: 0.309302 | R30: 0.307546 | S30: 0.305769 | T30: 0.303689 | U30: 0.30142 | V30: 0.299543 | W30: 0.297205 | X30: 0.294907 | Y30: 0.292766 | Z30: 0.290603 | AA30: 0.288871 | AB30: 0.287173 | AC30: 0.28523 | AD30: 0.283208 | AE30: 0.281544 | AF30: 0.279879 | AG30: 0.278342 | AH30: -0.003517
A31: QUA000:da_ResidualFuel | B31: Residual Fuel Oil | C31: 0.00229 | D31: 0.00229 | E31: 0.002156 | F31: 0.002281 | G31: 0.002835 | H31: 0.003581 | I31: 0.003333 | J31: 0.003306 | K31: 0.003205 | L31: 0.003171 | M31: 0.003097 | N31: 0.003083 | O31: 0.00305 | P31: 0.003053 | Q31: 0.003059 | R31: 0.003065 | S31: 0.003088 | T31: 0.003121 | U31: 0.003099 | V31: 0.003131 | W31: 0.002992 | X31: 0.002971 | Y31: 0.002982 | Z31: 0.003004 | AA31: 0.003021 | AB31: 0.003044 | AC31: 0.003045 | AD31: 0.003054 | AE31: 0.003072 | AF31: 0.003086 | AG31: 0.003102 | AH31: 0.010163
A32: QUA000:da_PetroleumSubt | B32: Petroleum and Other Liquids Subtotal | C32: 0.80576 | D32: 0.84775 | E32: 0.863505 | F32: 0.867191 | G32: 0.872253 | H32: 0.878713 | I32: 0.87962 | J32: 0.880149 | K32: 0.878488 | L32: 0.877464 | M32: 0.875051 | N32: 0.874424 | O32: 0.873537 | P32: 0.873601 | Q32: 0.873823 | R32: 0.874279 | S32: 0.874631 | T32: 0.874627 | U32: 0.874291 | V32: 0.874688 | W32: 0.874114 | X32: 0.873877 | Y32: 0.873997 | Z32: 0.874072 | AA32: 0.874756 | AB32: 0.875681 | AC32: 0.875912 | AD32: 0.876292 | AE32: 0.877114 | AF32: 0.878064 | AG32: 0.879122 | AH32: 0.002909
A33: QUA000:da_NaturalGas | B33: Natural Gas | C33: 3.313039 | D33: 3.422087 | E33: 3.39352 | F33: 3.503651 | G33: 3.569261 | H33: 3.628121 | I33: 3.634718 | J33: 3.636774 | K33: 3.637975 | L33: 3.636573 | M33: 3.628168 | N33: 3.629257 | O33: 3.634456 | P33: 3.639338 | Q33: 3.643619 | R33: 3.65011 | S33: 3.65797 | T33: 3.665039 | U33: 3.671028 | V33: 3.676408 | W33: 3.682669 | X33: 3.689942 | Y33: 3.697488 | Z33: 3.704461 | AA33: 3.711992 | AB33: 3.717591 | AC33: 3.722889 | AD33: 3.726569 | AE33: 3.728961 | AF33: 3.729583 | AG33: 3.729169 | AH33: 0.003952
A34: QUA000:da_Coal | B34: Coal | C34: 0.01723 | D34: 0.01564 | E34: 0.014035 | F34: 0.015413 | G34: 0.015117 | H34: 0.014992 | I34: 0.014925 | J34: 0.014909 | K34: 0.014822 | L34: 0.014695 | M34: 0.014566 | N34: 0.014422 | O34: 0.014271 | P34: 0.014132 | Q34: 0.014 | R34: 0.013848 | S34: 0.013664 | T34: 0.013565 | U34: 0.01348 | V34: 0.013432 | W34: 0.013331 | X34: 0.013255 | Y34: 0.013177 | Z34: 0.013076 | AA34: 0.012991 | AB34: 0.012942 | AC34: 0.012859 | AD34: 0.012784 | AE34: 0.012731 | AF34: 0.01263 | AG34: 0.012529 | AH34: -0.010563
A35: QUA000:da_RenewableEner | B35: Renewable Energy 4/ | C35: 0.131216 | D35: 0.131216 | E35: 0.131216 | F35: 0.131216 | G35: 0.131216 | H35: 0.131216 | I35: 0.131216 | J35: 0.131216 | K35: 0.131216 | L35: 0.131216 | M35: 0.131216 | N35: 0.131216 | O35: 0.131216 | P35: 0.131216 | Q35: 0.131216 | R35: 0.131216 | S35: 0.131216 | T35: 0.131216 | U35: 0.131216 | V35: 0.131216 | W35: 0.131216 | X35: 0.131216 | Y35: 0.131216 | Z35: 0.131216 | AA35: 0.131216 | AB35: 0.131216 | AC35: 0.131216 | AD35: 0.131216 | AE35: 0.131216 | AF35: 0.131216 | AG35: 0.131216 | AH35: 0
A36: QUA000:da_Electricity | B36: Purchased Electricity | C36: 4.33543 | D36: 4.395605 | E36: 4.490564 | F36: 4.557985 | G36: 4.63273 | H36: 4.705483 | I36: 4.714942 | J36: 4.72438 | K36: 4.737476 | L36: 4.750947 | M36: 4.759401 | N36: 4.772419 | O36: 4.796052 | P36: 4.814938 | Q36: 4.841106 | R36: 4.865653 | S36: 4.893783 | T36: 4.927176 | U36: 4.963278 | V36: 5.001215 | W36: 5.036965 | X36: 5.077383 | Y36: 5.118773 | Z36: 5.172633 | AA36: 5.224681 | AB36: 5.280979 | AC36: 5.340222 | AD36: 5.40219 | AE36: 5.469254 | AF36: 5.544512 | AG36: 5.624819 | AH36: 0.008717
A37: QUA000:da_DeliveredEner | B37: Delivered Energy | C37: 8.602675 | D37: 8.812298 | E37: 8.89284 | F37: 9.075455 | G37: 9.220575 | H37: 9.358524 | I37: 9.375421 | J37: 9.387427 | K37: 9.399977 | L37: 9.410897 | M37: 9.408401 | N37: 9.421737 | O37: 9.449532 | P37: 9.473225 | Q37: 9.503764 | R37: 9.535106 | S37: 9.571264 | T37: 9.611625 | U37: 9.653292 | V37: 9.696959 | W37: 9.738296 | X37: 9.785672 | Y37: 9.834651 | Z37: 9.895458 | AA37: 9.955635 | AB37: 10.018408 | AC37: 10.083097 | AD37: 10.149053 | AE37: 10.219275 | AF37: 10.296005 | AG37: 10.376855 | AH37: 0.00627
A38: QUA000:da_ElectricityRe | B38: Electricity Related Losses | C38: 8.080952 | D38: 8.184591 | E38: 8.399828 | F38: 8.356667 | G38: 8.324706 | H38: 8.21728 | I38: 8.009226 | J38: 7.933647 | K38: 7.911225 | L38: 7.904228 | M38: 7.901311 | N38: 7.903949 | O38: 7.89674 | P38: 7.897304 | Q38: 7.899065 | R38: 7.916457 | S38: 7.934237 | T38: 7.96243 | U38: 7.976492 | V38: 7.995452 | W38: 8.015583 | X38: 8.054189 | Y38: 8.094862 | Z38: 8.147943 | AA38: 8.195475 | AB38: 8.248356 | AC38: 8.311562 | AD38: 8.383004 | AE38: 8.472766 | AF38: 8.565417 | AG38: 8.653732 | AH38: 0.002285
A39: QUA000:da_Total | B39: Total | C39: 16.683628 | D39: 16.996889 | E39: 17.292667 | F39: 17.432121 | G39: 17.54528 | H39: 17.575806 | I39: 17.384647 | J39: 17.321075 | K39: 17.311203 | L39: 17.315125 | M39: 17.309711 | N39: 17.325686 | O39: 17.346272 | P39: 17.370529 | Q39: 17.402828 | R39: 17.451563 | S39: 17.505501 | T39: 17.574055 | U39: 17.629784 | V39: 17.69241 | W39: 17.75388 | X39: 17.839861 | Y39: 17.929512 | Z39: 18.0434 | AA39: 18.15111 | AB39: 18.266764 | AC39: 18.394659 | AD39: 18.532057 | AE39: 18.692041 | AF39: 18.861423 | AG39: 19.030586 | AH39: 0.004397
B41: Industrial 5/
A42: QUA000:ea_LiquefiedPetr | B42: Liquefied Petroleum Gases and Other 6/ | C42: 3.129955 | D42: 3.386781 | E42: 3.651851 | F42: 3.776361 | G42: 3.892941 | H42: 3.994641 | I42: 4.05975 | J42: 4.108074 | K42: 4.165377 | L42: 4.227348 | M42: 4.304934 | N42: 4.376987 | O42: 4.428152 | P42: 4.487323 | Q42: 4.555828 | R42: 4.623542 | S42: 4.666788 | T42: 4.718928 | U42: 4.768962 | V42: 4.79539 | W42: 4.804048 | X42: 4.828106 | Y42: 4.879942 | Z42: 4.921879 | AA42: 4.944526 | AB42: 4.980334 | AC42: 5.011189 | AD42: 5.043888 | AE42: 5.077971 | AF42: 5.142419 | AG42: 5.197212 | AH42: 0.017047
A43: QUA000:ea_MotorGasoline | B43: Motor Gasoline 3/ | C43: 0.238015 | D43: 0.259103 | E43: 0.266313 | F43: 0.273278 | G43: 0.279129 | H43: 0.285328 | I43: 0.290397 | J43: 0.294377 | K43: 0.297677 | L43: 0.301024 | M43: 0.304527 | N43: 0.3083 | O43: 0.311921 | P43: 0.315286 | Q43: 0.318999 | R43: 0.322577 | S43: 0.325664 | T43: 0.328823 | U43: 0.332402 | V43: 0.336007 | W43: 0.339763 | X43: 0.343731 | Y43: 0.347987 | Z43: 0.352715 | AA43: 0.357547 | AB43: 0.362092 | AC43: 0.36676 | AD43: 0.371305 | AE43: 0.376088 | AF43: 0.381094 | AG43: 0.386148 | AH43: 0.01626
A44: QUA000:ea_DistillateFue | B44: Distillate Fuel Oil | C44: 1.134867 | D44: 1.194101 | E44: 1.218216 | F44: 1.238876 | G44: 1.261172 | H44: 1.287802 | I44: 1.311676 | J44: 1.330589 | K44: 1.345493 | L44: 1.361019 | M44: 1.378233 | N44: 1.397494 | O44: 1.415234 | P44: 1.431922 | Q44: 1.450262 | R44: 1.469061 | S44: 1.484862 | T44: 1.500089 | U44: 1.517681 | V44: 1.535302 | W44: 1.552948 | X44: 1.573038 | Y44: 1.594831 | Z44: 1.6189 | AA44: 1.643961 | AB44: 1.668322 | AC44: 1.692229 | AD44: 1.715713 | AE44: 1.741043 | AF44: 1.768589 | AG44: 1.796802 | AH44: 0.015434
A45: QUA000:ea_ResidualFuel | B45: Residual Fuel Oil | C45: 0.03048 | D45: 0.034245 | E45: 0.034751 | F45: 0.034203 | G45: 0.033767 | H45: 0.034162 | I45: 0.03461 | J45: 0.035264 | K45: 0.035738 | L45: 0.036353 | M45: 0.036902 | N45: 0.037473 | O45: 0.037624 | P45: 0.038008 | Q45: 0.03837 | R45: 0.038572 | S45: 0.038748 | T45: 0.039002 | U45: 0.039153 | V45: 0.039356 | W45: 0.039151 | X45: 0.039204 | Y45: 0.039436 | Z45: 0.039724 | AA45: 0.03995 | AB45: 0.04008 | AC45: 0.040254 | AD45: 0.040476 | AE45: 0.040728 | AF45: 0.041022 | AG45: 0.041235 | AH45: 0.010125
A46: QUA000:ea_Petrochemical | B46: Petrochemical Feedstocks | C46: 0.580925 | D46: 0.607373 | E46: 0.641193 | F46: 0.642074 | G46: 0.644202 | H46: 0.64596 | I46: 0.647049 | J46: 0.647831 | K46: 0.648769 | L46: 0.649764 | M46: 0.650996 | N46: 0.652113 | O46: 0.652873 | P46: 0.653758 | Q46: 0.654771 | R46: 0.655756 | S46: 0.656368 | T46: 0.657105 | U46: 0.657801 | V46: 0.658146 | W46: 0.658242 | X46: 0.658551 | Y46: 0.659253 | Z46: 0.659804 | AA46: 0.660075 | AB46: 0.660527 | AC46: 0.660914 | AD46: 0.661325 | AE46: 0.661748 | AF46: 0.662582 | AG46: 0.663274 | AH46: 0.004429
A47: QUA000:ea_OtherPetroleu | B47: Other Petroleum 7/ | C47: 3.211545 | D47: 3.275826 | E47: 3.277059 | F47: 3.284837 | G47: 3.264796 | H47: 3.294298 | I47: 3.313754 | J47: 3.340309 | K47: 3.368908 | L47: 3.400828 | M47: 3.418661 | N47: 3.443216 | O47: 3.464936 | P47: 3.480493 | Q47: 3.514555 | R47: 3.53166 | S47: 3.563787 | T47: 3.596627 | U47: 3.609115 | V47: 3.623469 | W47: 3.624057 | X47: 3.63597 | Y47: 3.646353 | Z47: 3.645204 | AA47: 3.659037 | AB47: 3.687069 | AC47: 3.693583 | AD47: 3.721316 | AE47: 3.758235 | AF47: 3.781746 | AG47: 3.822744 | AH47: 0.005824
...

Sheet Gas Futures
A1: MONTH | B1: OPTIONS | C1: CHART | D1: LAST | E1: CHANGE | F1: PRIOR | G1: OPEN | H1: HIGH | I1: LOW | J1: VOLUME | K1: UPDATED | L1: Month.year
F2: SETTLE
A3: 44743 | B3: OPT | D3: 8.735 | E3: -0.160 (-1.80%) | F3: 8.895 | G3: 8.811 | H3: 8.895 | I3: 8.285 | J3: 102769 | K3: 15:10:18 CT | L3: =CONCATENATE(MONTH(A3),".",YEAR(A3)) -> 7.2022
A4: NGN2 | K4: 44708 | L4: =CONCATENATE(MONTH(A4),".",YEAR(A4)) -> #VALUE!
A5: 44774 | B5: OPT | D5: 8.715 | E5: -0.165 (-1.86%) | F5: 8.88 | G5: 8.797 | H5: 8.875 | I5: 8.275 | J5: 22123 | K5: 15:10:18 CT | L5: =CONCATENATE(MONTH(A5),".",YEAR(A5)) -> 8.2022
A6: NGQ2 | K6: 44708 | L6: =CONCATENATE(MONTH(A6),".",YEAR(A6)) -> #VALUE!
A7: 44805 | B7: OPT | D7: 8.673 | E7: -0.164 (-1.86%) | F7: 8.837 | G7: 8.733 | H7: 8.832 | I7: 8.243 | J7: 18084 | K7: 15:10:18 CT | L7: =CONCATENATE(MONTH(A7),".",YEAR(A7)) -> 9.2022
A8: NGU2 | K8: 44708 | L8: =CONCATENATE(MONTH(A8),".",YEAR(A8)) -> #VALUE!
A9: 44835 | B9: OPT | D9: 8.643 | E9: -0.159 (-1.81%) | F9: 8.802 | G9: 8.731 | H9: 8.801 | I9: 8.211 | J9: 17486 | K9: 15:05:43 CT | L9: =CONCATENATE(MONTH(A9),".",YEAR(A9)) -> 10.2022
A10: NGV2 | K10: 44708 | L10: =CONCATENATE(MONTH(A10),".",YEAR(A10)) -> #VALUE!
A11: 44866 | B11: OPT | D11: 8.688 | E11: -0.146 (-1.65%) | F11: 8.834 | G11: 8.791 | H11: 8.826 | I11: 8.263 | J11: 9758 | K11: 15:05:00 CT | L11: =CONCATENATE(MONTH(A11),".",YEAR(A11)) -> 11.2022
A12: NGX2 | K12: 44708 | L12: =CONCATENATE(MONTH(A12),".",YEAR(A12)) -> #VALUE!
A13: 44896 | B13: OPT | D13: 8.737 | E13: -0.168 (-1.89%) | F13: 8.905 | G13: 8.863 | H13: 8.888 | I13: 8.322 | J13: 9744 | K13: 15:06:17 CT | L13: =CONCATENATE(MONTH(A13),".",YEAR(A13)) -> 12.2022
A14: NGZ2 | K14: 44708 | L14: =CONCATENATE(MONTH(A14),".",YEAR(A14)) -> #VALUE!
A15: 44927 | B15: OPT | D15: 8.809 | E15: -0.174 (-1.94%) | F15: 8.983 | G15: 8.923 | H15: 8.968 | I15: 8.409 | J15: 13637 | K15: 15:07:08 CT | L15: =CONCATENATE(MONTH(A15),".",YEAR(A15)) -> 1.2023
A16: NGF3 | K16: 44708 | L16: =CONCATENATE(MONTH(A16),".",YEAR(A16)) -> #VALUE!
A17: 44958 | B17: OPT | D17: 8.457 | E17: -0.168 (-1.95%) | F17: 8.625 | G17: 8.594 | H17: 8.594 | I17: 8.078 | J17: 6250 | K17: 15:07:08 CT | L17: =CONCATENATE(MONTH(A17),".",YEAR(A17)) -> 2.2023
A18: NGG3 | K18: 44708 | L18: =CONCATENATE(MONTH(A18),".",YEAR(A18)) -> #VALUE!
A19: 44986 | B19: OPT | D19: 7.081 | E19: -0.088 (-1.23%) | F19: 7.169 | G19: 7.11 | H19: 7.159 | I19: 6.827 | J19: 7959 | K19: 15:04:58 CT | L19: =CONCATENATE(MONTH(A19),".",YEAR(A19)) -> 3.2023
A20: NGH3 | K20: 44708 | L20: =CONCATENATE(MONTH(A20),".",YEAR(A20)) -> #VALUE!
A21: 45017 | B21: OPT | D21: 5.157 | E21: -0.016 (-0.31%) | F21: 5.173 | G21: 5.15 | H21: 5.216 | I21: 5.016 | J21: 7588 | K21: 14:59:59 CT | L21: =CONCATENATE(MONTH(A21),".",YEAR(A21)) -> 4.2023
A22: NGJ3 | K22: 44708 | L22: =CONCATENATE(MONTH(A22),".",YEAR(A22)) -> #VALUE!
A23: 45047 | B23: OPT | D23: 4.955 | E23: -0.012 (-0.24%) | F23: 4.967 | G23: 4.93 | H23: 5.016 | I23: 4.829 | J23: 2909 | K23: 14:59:55 CT | L23: =CONCATENATE(MONTH(A23),".",YEAR(A23)) -> 5.2023
A24: NGK3 | K24: 44708 | L24: =CONCATENATE(MONTH(A24),".",YEAR(A24)) -> #VALUE!
A25: 45078 | B25: OPT | D25: 5.036 | E25: +0.015 (+0.30%) | F25: 5.021 | G25: 5.003 | H25: 5.067 | I25: 4.887 | J25: 1958 | K25: 14:57:29 CT | L25: =CONCATENATE(MONTH(A25),".",YEAR(A25)) -> 6.2023
A26: NGM3 | K26: 44708 | L26: =CONCATENATE(MONTH(A26),".",YEAR(A26)) -> #VALUE!
A27: 45108 | B27: OPT | D27: 5.05 | E27: -0.010 (-0.20%) | F27: 5.06 | G27: 5.063 | H27: 5.09 | I27: 4.931 | J27: 1206 | K27: 15:03:53 CT | L27: =CONCATENATE(MONTH(A27),".",YEAR(A27)) -> 7.2023
A28: NGN3 | K28: 44708 | L28: =CONCATENATE(MONTH(A28),".",YEAR(A28)) -> #VALUE!
A29: 45139 | B29: OPT | D29: 5.054 | E29: +0.012 (+0.24%) | F29: 5.042 | G29: 4.943 | H29: 5.058 | I29: 4.912 | J29: 1526 | K29: 15:06:17 CT | L29: =CONCATENATE(MONTH(A29),".",YEAR(A29)) -> 8.2023
A30: NGQ3 | K30: 44708 | L30: =CONCATENATE(MONTH(A30),".",YEAR(A30)) -> #VALUE!
A31: 45170 | B31: OPT | D31: 4.983 | E31: -0.025 (-0.50%) | F31: 5.008 | G31: 5.012 | H31: 5.031 | I31: 4.876 | J31: 899 | K31: 15:03:53 CT | L31: =CONCATENATE(MONTH(A31),".",YEAR(A31)) -> 9.2023
A32: NGU3 | K32: 44708 | L32: =CONCATENATE(MONTH(A32),".",YEAR(A32)) -> #VALUE!
A33: 45200 | B33: OPT | D33: 5.063 | E33: -0.006 (-0.12%) | F33: 5.069 | G33: 5.041 | H33: 5.098 | I33: 4.94 | J33: 1847 | K33: 14:52:52 CT | L33: =CONCATENATE(MONTH(A33),".",YEAR(A33)) -> 10.2023
A34: NGV3 | K34: 44708 | L34: =CONCATENATE(MONTH(A34),".",YEAR(A34)) -> #VALUE!
A35: 45231 | B35: OPT | D35: 5.21 | E35: -0.009 (-0.17%) | F35: 5.219 | G35: 5.091 | H35: 5.238 | I35: 5.091 | J35: 787 | K35: 14:52:52 CT | L35: =CONCATENATE(MONTH(A35),".",YEAR(A35)) -> 11.2023
A36: NGX3 | K36: 44708 | L36: =CONCATENATE(MONTH(A36),".",YEAR(A36)) -> #VALUE!
A37: 45261 | B37: OPT | D37: 5.493 | E37: +0.001 (+0.02%) | F37: 5.492 | G37: 5.465 | H37: 5.522 | I37: 5.36 | J37: 783 | K37: 13:59:44 CT | L37: =CONCATENATE(MONTH(A37),".",YEAR(A37)) -> 12.2023
A38: NGZ3 | K38: 44708 | L38: =CONCATENATE(MONTH(A38),".",YEAR(A38)) -> #VALUE!
A39: 45292 | B39: OPT | D39: 5.62 | E39: -0.008 (-0.14%) | F39: 5.628 | G39: 5.62 | H39: 5.635 | I39: 5.51 | J39: 550 | K39: 13:59:44 CT | L39: =CONCATENATE(MONTH(A39),".",YEAR(A39)) -> 1.2024
A40: NGF4 | K40: 44708 | L40: =CONCATENATE(MONTH(A40),".",YEAR(A40)) -> #VALUE!
...

Sheet Henry Hub Historicals
A1: Back to Contents | B1: Data 1: Spot Price
A2: Sourcekey | B2: RNGWHHD
A3: Date | B3: Henry Hub Natural Gas Spot Price (Dollars per Million Btu) | C3: Month.year
A4: 35445 | B4: 3.45 | C4: =CONCATENATE(MONTH(A4),".",YEAR(A4)) -> 1.1997
A5: 35476 | B5: 2.15 | C5: =CONCATENATE(MONTH(A5),".",YEAR(A5)) -> 2.1997
A6: 35504 | B6: 1.89 | C6: =CONCATENATE(MONTH(A6),".",YEAR(A6)) -> 3.1997
A7: 35535 | B7: 2.03 | C7: =CONCATENATE(MONTH(A7),".",YEAR(A7)) -> 4.1997
A8: 35565 | B8: 2.25 | C8: =CONCATENATE(MONTH(A8),".",YEAR(A8)) -> 5.1997
A9: 35596 | B9: 2.2 | C9: =CONCATENATE(MONTH(A9),".",YEAR(A9)) -> 6.1997
A10: 35626 | B10: 2.19 | C10: =CONCATENATE(MONTH(A10),".",YEAR(A10)) -> 7.1997
A11: 35657 | B11: 2.49 | C11: =CONCATENATE(MONTH(A11),".",YEAR(A11)) -> 8.1997
A12: 35688 | B12: 2.88 | C12: =CONCATENATE(MONTH(A12),".",YEAR(A12)) -> 9.1997
A13: 35718 | B13: 3.07 | C13: =CONCATENATE(MONTH(A13),".",YEAR(A13)) -> 10.1997
A14: 35749 | B14: 3.01 | C14: =CONCATENATE(MONTH(A14),".",YEAR(A14)) -> 11.1997
A15: 35779 | B15: 2.35 | C15: =CONCATENATE(MONTH(A15),".",YEAR(A15)) -> 12.1997
... A307: 44666 | B307: 6.6 | C307: =CONCATENATE(MONTH(A307),".",YEAR(A307)) -> 4.2022
A309: Back to Contents | B309: Data 1: Spot Price
A310: Sourcekey | B310: RNGWHHD
A311: Date | B311: Henry Hub Natural Gas Spot Price (Dollars per Million Btu)
A312: 35611 | B312: 2.49 | C312: 1997
A313: 35976 | B313: 2.09 | C313: 1998
A314: 36341 | B314: 2.27 | C314: 1999
A315: 36707 | B315: 4.31 | C315: 2000
A316: 37072 | B316: 3.96 | C316: 2001
A317: 37437 | B317: 3.38 | C317: 2002
A318: 37802 | B318: 5.47 | C318: 2003
A319: 38168 | B319: 5.89 | C319: 2004
A320: 38533 | B320: 8.69 | C320: 2005
A321: 38898 | B321: 6.73 | C321: 2006
A322: 39263 | B322: 6.97 | C322: 2007
A323: 39629 | B323: 8.86 | C323: 2008
... A336: 44377 | B336: 3.89 | C336: 2021

Sheet NG Sector Price Historicals
A1: Back to Contents | B1: Data 1: U.S. Natural Gas Prices
A2: Sourcekey | B2: N9190US3 | C2: N9100US3 | D2: N9102US3 | E2: N9103US3 | F2: N9130US3 | G2: N9132US3 | H2: N9133US3 | I2: NA1480_NUS_3 | J2: N3050US3 | K2: N3010US3 | L2: NA1504_NUS_4 | M2: N3020US3 | N2: N3020US4 | O2: N3035US3 | P2: N3035US4 | Q2: NA1570_NUS_3 | R2: N3045US3
A3: Date | B3: U.S. Natural Gas Wellhead Price (Dollars per Thousand Cubic Feet) | C3: Price of U.S. Natural Gas Imports (Dollars per Thousand Cubic Feet) | D3: U.S. Natural Gas Pipeline Imports Price (Dollars per Thousand Cubic Feet) | E3: Price of U.S. Natural Gas LNG Imports (Dollars per Thousand Cubic Feet) | F3: Price of U.S. Natural Gas Exports (Dollars per Thousand Cubic Feet) | G3: Price of U.S. Natural Gas Pipeline Exports (Dollars per Thousand Cubic Feet) | H3: Price of Liquefied U.S. Natural Gas Exports (Dollars per Thousand Cubic Feet) | I3: U.S. Natural Gas Pipeline and Distribution Use Price (Dollars per Thousand Cubic Feet) | J3: U.S. Natural Gas Citygate Price (Dollars per Thousand Cubic Feet) | K3: U.S. Price of Natural Gas Delivered to Residential Consumers (Dollars per Thousand Cubic Feet) | L3: U.S. Natural Gas % of Total Residential - Sales (%) | M3: U.S. Price of Natural Gas Sold to Commercial Consumers (Dollars per Thousand Cubic Feet) | N3: Percent of Commercial Natural Gas Deliveries in U.S. Total Represented by the Price (%) | O3: United States Natural Gas Industrial Price (Dollars per Thousand Cubic Feet) | P3: Percent of Industrial Natural Gas Deliveries in U.S. Total Represented by the Price (%) | Q3: U.S. Natural Gas Vehicle Fuel Price (Dollars per Thousand Cubic Feet) | R3: U.S. Natural Gas Electric Power Price (Dollars per Thousand Cubic Feet) | S3: Year
A4: 8217 | B4: 0.11 | S4: =YEAR(A4) -> 1922
A5: 8582 | B5: 0.1 | S5: =YEAR(A5) -> 1923
A6: 8948 | B6: 0.09 | S6: =YEAR(A6) -> 1924
A7: 9313 | B7: 0.09 | S7: =YEAR(A7) -> 1925
A8: 9678 | B8: 0.1 | S8: =YEAR(A8) -> 1926
A9: 10043 | B9: 0.09 | S9: =YEAR(A9) -> 1927
A10: 10409 | B10: 0.09 | S10: =YEAR(A10) -> 1928
A11: 10774 | B11: 0.08 | S11: =YEAR(A11) -> 1929
A12: 11139 | B12: 0.08 | S12: =YEAR(A12) -> 1930
A13: 11504 | B13: 0.07 | S13: =YEAR(A13) -> 1931
A14: 11870 | B14: 0.06 | S14: =YEAR(A14) -> 1932
A15: 12235 | B15: 0.06 | S15: =YEAR(A15) -> 1933
... A48: 24288 | B48: 0.16 | S48: =YEAR(A48) -> 1966
A49: 24653 | B49: 0.16 | I49: 0.2 | K49: 1.04 | M49: 0.74 | S49: =YEAR(A49) -> 1967
A50: 25019 | B50: 0.16 | I50: 0.2 | K50: 1.04 | M50: 0.73 | S50: =YEAR(A50) -> 1968
A51: 25384 | B51: 0.17 | I51: 0.21 | K51: 1.05 | M51: 0.74 | S51: =YEAR(A51) -> 1969
A52: 25749 | B52: 0.17 | I52: 0.21 | K52: 1.09 | M52: 0.77 | S52: =YEAR(A52) -> 1970
A53: 26114 | B53: 0.18 | I53: 0.22 | K53: 1.15 | M53: 0.82 | S53: =YEAR(A53) -> 1971
A54: 26480 | B54: 0.19 | I54: 0.23 | K54: 1.21 | M54: 0.88 | S54: =YEAR(A54) -> 1972
A55: 26845 | B55: 0.22 | I55: 0.25 | K55: 1.29 | M55: 0.94 | S55: =YEAR(A55) -> 1973
A56: 27210 | B56: 0.3 | I56: 0.3 | K56: 1.43 | M56: 1.07 | S56: =YEAR(A56) -> 1974
A57: 27575 | B57: 0.44 | I57: 0.4 | K57: 1.71 | M57: 1.35 | S57: =YEAR(A57) -> 1975
A58: 27941 | B58: 0.58 | I58: 0.51 | K58: 1.98 | M58: 1.64 | S58: =YEAR(A58) -> 1976
A59: 28306 | B59: 0.79 | I59: 0.77 | K59: 2.35 | M59: 2.04 | S59: =YEAR(A59) -> 1977
A60: 28671 | B60: 0.91 | I60: 0.9 | K60: 2.56 | M60: 2.23 | S60: =YEAR(A60) -> 1978
... A65: 30497 | B65: 2.59 | I65: 3.15 | K65: 6.06 | M65: 5.59 | S65: =YEAR(A65) -> 1983
A66: 30863 | B66: 2.66 | I66: 3.04 | J66: 3.95 | K66: 6.12 | M66: 5.55 | S66: =YEAR(A66) -> 1984
A67: 31228 | B67: 2.51 | C67: 3.21 | D67: 3.17 | E67: 4.6 | F67: 4.77 | G67: 3.92 | H67: 4.81 | I67: 2.92 | J67: 3.75 | K67: 6.12 | M67: 5.5 | S67: =YEAR(A67) -> 1985
A68: 31593 | B68: 1.94 | C68: 2.43 | D68: 2.42 | E68: 4.62 | F68: 2.81 | G68: 2.35 | H68: 2.91 | I68: 2.52 | J68: 3.22 | K68: 5.83 | M68: 5.08 | S68: =YEAR(A68) -> 1986
A69: 31958 | B69: 1.67 | C69: 1.95 | D69: 1.95 | F69: 3.07 | G69: 2.35 | H69: 3.15 | I69: 2.17 | J69: 2.87 | K69: 5.54 | M69: 4.77 | N69: 93.1 | S69: =YEAR(A69) -> 1987
A70: 32324 | B70: 1.69 | C70: 1.84 | D70: 1.83 | E70: 2.71 | F70: 2.74 | G70: 2.14 | H70: 2.98 | I70: 2.1 | J70: 2.92 | K70: 5.47 | M70: 4.63 | N70: 90.8 | S70: =YEAR(A70) -> 1988
A71: 32689 | B71: 1.69 | C71: 1.82 | D71: 1.81 | E71: 2.22 | F71: 2.51 | G71: 2.05 | H71: 3.01 | I71: 2.01 | J71: 3.01 | K71: 5.64 | L71: 99.9 | M71: 4.74 | N71: 89.1 | Q71: 4.17 | S71: =YEAR(A71) -> 1989
A72: 33054 | B72: 1.71 | C72: 1.94 | D72: 1.91 | E72: 2.47 | F72: 3.1 | G72: 2.31 | H72: 3.59 | I72: 1.95 | J72: 3.03 | K72: 5.8 | L72: 99.2 | M72: 4.83 | N72: 86.6 | Q72: 3.39 | S72: =YEAR(A72) -> 1990
A73: 33419 | B73: 1.64 | C73: 1.83 | D73: 1.81 | E73: 2.36 | F73: 2.59 | G73: 1.79 | H73: 3.71 | I73: 1.87 | J73: 2.9 | K73: 5.82 | L73: 99.2 | M73: 4.81 | N73: 85.1 | Q73: 3.96 | S73: =YEAR(A73) -> 1991
A74: 33785 | B74: 1.74 | C74: 1.85 | D74: 1.84 | E74: 2.54 | F74: 2.25 | G74: 1.88 | H74: 3.43 | I74: 2.07 | J74: 3.01 | K74: 5.89 | L74: 99.1 | M74: 4.88 | N74: 83.2 | Q74: 4.05 | S74: =YEAR(A74) -> 1992
A75: 34150 | B75: 2.04 | C75: 2.03 | D75: 2.02 | E75: 2.2 | F75: 2.59 | G75: 2.08 | H75: 3.34 | I75: 1.97 | J75: 3.21 | K75: 6.16 | L75: 99.1 | M75: 5.22 | N75: 83.9 | Q75: 4.27 | S75: =YEAR(A75) -> 1993
A76: 34515 | B76: 1.85 | C76: 1.87 | D76: 1.86 | E76: 2.28 | F76: 2.5 | G76: 2.08 | H76: 3.18 | I76: 1.7 | J76: 3.07 | K76: 6.41 | L76: 99.1 | M76: 5.44 | N76: 79.3 | Q76: 4.11 | S76: =YEAR(A76) -> 1994
...

Sheet Historical Monthly Gas Cons
A1: Back to Contents | B1: Data 1: Natural Gas Delivered to Consumers in the U.S. (MMcf)
A2: Sourcekey | B2: N3060US2
A3: Date | B3: Natural Gas Delivered to Consumers in the U.S. (MMcf)
A4: 36906 | B4: 2505011 | C4: =MONTH(A4) -> 1 | D4: =YEAR(A4) -> 2001
A5: 36937 | B5: 2156873 | C5: =MONTH(A5) -> 2 | D5: =YEAR(A5) -> 2001
A6: 36965 | B6: 2086568 | C6: =MONTH(A6) -> 3 | D6: =YEAR(A6) -> 2001
A7: 36996 | B7: 1663832 | C7: =MONTH(A7) -> 4 | D7: =YEAR(A7) -> 2001
A8: 37026 | B8: 1385163 | C8: =MONTH(A8) -> 5 | D8: =YEAR(A8) -> 2001
A9: 37057 | B9: 1313119 | C9: =MONTH(A9) -> 6 | D9: =YEAR(A9) -> 2001
A10: 37087 | B10: 1459919 | C10: =MONTH(A10) -> 7 | D10: =YEAR(A10) -> 2001
A11: 37118 | B11: 1528483 | C11: =MONTH(A11) -> 8 | D11: =YEAR(A11) -> 2001
A12: 37149 | B12: 1360871 | C12: =MONTH(A12) -> 9 | D12: =YEAR(A12) -> 2001
A13: 37179 | B13: 1507428 | C13: =MONTH(A13) -> 10 | D13: =YEAR(A13) -> 2001
A14: 37210 | B14: 1561970 | C14: =MONTH(A14) -> 11 | D14: =YEAR(A14) -> 2001
A15: 37240 | B15: 1965873 | C15: =MONTH(A15) -> 12 | D15: =YEAR(A15) -> 2001
... A257: 44607 | B257: 2797164 | C257: =MONTH(A257) -> 2 | D257: =YEAR(A257) -> 2022

Sheet NG Calcs
A1: Historical Monthly Consumption Average
A2: 1 | B2: {=SUMPRODUCT(IF('Historical Monthly Gas Cons'!$C$4:$C$257='NG Calcs'!A2,IF('Historical Monthly Gas Cons'!$D$4:$D$257>2015,'Historical Monthly Gas Cons'!$B$4:$B$257))/SUMPRODUCT(IF('Historical Monthly Gas Cons'!$D$4:$D$257>2015,'Historical Monthly Gas Cons'!$B$4:$B$257)))} -> 0.12704635
A3: 2 | B3: {=SUMPRODUCT(IF('Historical Monthly Gas Cons'!$C$4:$C$257='NG Calcs'!A3,IF('Historical Monthly Gas Cons'!$D$4:$D$257>2015,'Historical Monthly Gas Cons'!$B$4:$B$257))/SUMPRODUCT(IF('Historical Monthly Gas Cons'!$D$4:$D$257>2015,'Historical Monthly Gas Cons'!$B$4:$B$257)))} -> 0.10957724
A4: 3 | B4: {=SUMPRODUCT(IF('Historical Monthly Gas Cons'!$C$4:$C$257='NG Calcs'!A4,IF('Historical Monthly Gas Cons'!$D$4:$D$257>2015,'Historical Monthly Gas Cons'!$B$4:$B$257))/SUMPRODUCT(IF('Historical Monthly Gas Cons'!$D$4:$D$257>2015,'Historical Monthly Gas Cons'!$B$4:$B$257)))} -> 0.08724036
A5: 4 | B5: {=SUMPRODUCT(IF('Historical Monthly Gas Cons'!$C$4:$C$257='NG Calcs'!A5,IF('Historical Monthly Gas Cons'!$D$4:$D$257>2015,'Historical Monthly Gas Cons'!$B$4:$B$257))/SUMPRODUCT(IF('Historical Monthly Gas Cons'!$D$4:$D$257>2015,'Historical Monthly Gas Cons'!$B$4:$B$257)))} -> 0.070786697
A6: 5 | B6: {=SUMPRODUCT(IF('Historical Monthly Gas Cons'!$C$4:$C$257='NG Calcs'!A6,IF('Historical Monthly Gas Cons'!$D$4:$D$257>2015,'Historical Monthly Gas Cons'!$B$4:$B$257))/SUMPRODUCT(IF('Historical Monthly Gas Cons'!$D$4:$D$257>2015,'Historical Monthly Gas Cons'!$B$4:$B$257)))} -> 0.065746454
A7: 6 | B7: {=SUMPRODUCT(IF('Historical Monthly Gas Cons'!$C$4:$C$257='NG Calcs'!A7,IF('Historical Monthly Gas Cons'!$D$4:$D$257>2015,'Historical Monthly Gas Cons'!$B$4:$B$257))/SUMPRODUCT(IF('Historical Monthly Gas Cons'!$D$4:$D$257>2015,'Historical Monthly Gas Cons'!$B$4:$B$257)))} -> 0.067228772
A8: 7 | B8: {=SUMPRODUCT(IF('Historical Monthly Gas Cons'!$C$4:$C$257='NG Calcs'!A8,IF('Historical Monthly Gas Cons'!$D$4:$D$257>2015,'Historical Monthly Gas Cons'!$B$4:$B$257))/SUMPRODUCT(IF('Historical Monthly Gas Cons'!$D$4:$D$257>2015,'Historical Monthly Gas Cons'!$B$4:$B$257)))} -> 0.075765383
A9: 8 | B9: {=SUMPRODUCT(IF('Historical Monthly Gas Cons'!$C$4:$C$257='NG Calcs'!A9,IF('Historical Monthly Gas Cons'!$D$4:$D$257>2015,'Historical Monthly Gas Cons'!$B$4:$B$257))/SUMPRODUCT(IF('Historical Monthly Gas Cons'!$D$4:$D$257>2015,'Historical Monthly Gas Cons'!$B$4:$B$257)))} -> 0.075220401
A10: 9 | B10: {=SUMPRODUCT(IF('Historical Monthly Gas Cons'!$C$4:$C$257='NG Calcs'!A10,IF('Historical Monthly Gas Cons'!$D$4:$D$257>2015,'Historical Monthly Gas Cons'!$B$4:$B$257))/SUMPRODUCT(IF('Historical Monthly Gas Cons'!$D$4:$D$257>2015,'Historical Monthly Gas Cons'!$B$4:$B$257)))} -> 0.067544195
A11: 10 | B11: {=SUMPRODUCT(IF('Historical Monthly Gas Cons'!$C$4:$C$257='NG Calcs'!A11,IF('Historical Monthly Gas Cons'!$D$4:$D$257>2015,'Historical Monthly Gas Cons'!$B$4:$B$257))/SUMPRODUCT(IF('Historical Monthly Gas Cons'!$D$4:$D$257>2015,'Historical Monthly Gas Cons'!$B$4:$B$257)))} -> 0.070774681
A12: 11 | B12: {=SUMPRODUCT(IF('Historical Monthly Gas Cons'!$C$4:$C$257='NG Calcs'!A12,IF('Historical Monthly Gas Cons'!$D$4:$D$257>2015,'Historical Monthly Gas Cons'!$B$4:$B$257))/SUMPRODUCT(IF('Historical Monthly Gas Cons'!$D$4:$D$257>2015,'Historical Monthly Gas Cons'!$B$4:$B$257)))} -> 0.082458275
A13: 12 | B13: {=SUMPRODUCT(IF('Historical Monthly Gas Cons'!$C$4:$C$257='NG Calcs'!A13,IF('Historical Monthly Gas Cons'!$D$4:$D$257>2015,'Historical Monthly Gas Cons'!$B$4:$B$257))/SUMPRODUCT(IF('Historical Monthly Gas Cons'!$D$4:$D$257>2015,'Historical Monthly Gas Cons'!$B$4:$B$257)))} -> 0.1006112
A15: Future Prices | B15: 2021 | C15: 2022 | D15: 2023 | E15: 2024 | F15: 2025
A16: 1 | B16: =INDEX('Henry Hub Historicals'!$B$4:$B$307,MATCH(CONCATENATE('NG Calcs'!$A16,".",'NG Calcs'!B$15),'Henry Hub Historicals'!$C$4:$C$307,0),1) -> 2.71 | C16: =IFERROR(IF(AND($A16<7,C$15<2023),INDEX('Henry Hub Historicals'!$B$4:$B$307,MATCH(CONCATENATE('NG Calcs'!$A16,".",'NG Calcs'!C$15),'Henry Hub Historicals'!$C$4:$C$307,0),1),INDEX('Gas Futures'!$F:$F,MATCH(CONCATENATE('NG Calcs'!$A16,".",'NG Calcs'!C$15),'Gas Futures'!$L:$L,0),1)),"") -> 4.38 | D16: =IFERROR(IF(AND($A16<4,D$15<2022),INDEX('Henry Hub Historicals'!$B$4:$B$307,MATCH(CONCATENATE('NG Calcs'!$A16,".",'NG Calcs'!D$15),'Henry Hub Historicals'!$C$4:$C$307,0),1),INDEX('Gas Futures'!$F:$F,MATCH(CONCATENATE('NG Calcs'!$A16,".",'NG Calcs'!D$15),'Gas Futures'!$L:$L,0),1)),"") -> 8.983 | E16: =IFERROR(IF(AND($A16<4,E$15<2022),INDEX('Henry Hub Historicals'!$B$4:$B$307,MATCH(CONCATENATE('NG Calcs'!$A16,".",'NG Calcs'!E$15),'Henry Hub Historicals'!$C$4:$C$307,0),1),INDEX('Gas Futures'!$F:$F,MATCH(CONCATENATE('NG Calcs'!$A16,".",'NG Calcs'!E$15),'Gas Futures'!$L:$L,0),1)),"") -> 5.628 | F16: =IFERROR(IF(AND($A16<4,F$15<2022),INDEX('Henry Hub Historicals'!$B$4:$B$307,MATCH(CONCATENATE('NG Calcs'!$A16,".",'NG Calcs'!F$15),'Henry Hub Historicals'!$C$4:$C$307,0),1),INDEX('Gas Futures'!$F:$F,MATCH(CONCATENATE('NG Calcs'!$A16,".",'NG Calcs'!F$15),'Gas Futures'!$L:$L,0),1)),"") -> 4.977
A17: 2 | B17: =INDEX('Henry Hub Historicals'!$B$4:$B$307,MATCH(CONCATENATE('NG Calcs'!$A17,".",'NG Calcs'!B$15),'Henry Hub Historicals'!$C$4:$C$307,0),1) -> 5.35 | C17: =IFERROR(IF(AND($A17<7,C$15<2023),INDEX('Henry Hub Historicals'!$B$4:$B$307,MATCH(CONCATENATE('NG Calcs'!$A17,".",'NG Calcs'!C$15),'Henry Hub Historicals'!$C$4:$C$307,0),1),INDEX('Gas Futures'!$F:$F,MATCH(CONCATENATE('NG Calcs'!$A17,".",'NG Calcs'!C$15),'Gas Futures'!$L:$L,0),1)),"") -> 4.69 | D17: =IFERROR(IF(AND($A17<4,D$15<2022),INDEX('Henry Hub Historicals'!$B$4:$B$307,MATCH(CONCATENATE('NG Calcs'!$A17,".",'NG Calcs'!D$15),'Henry Hub Historicals'!$C$4:$C$307,0),1),INDEX('Gas Futures'!$F:$F,MATCH(CONCATENATE('NG Calcs'!$A17,".",'NG Calcs'!D$15),'Gas Futures'!$L:$L,0),1)),"") -> 8.625 | E17: =IFERROR(IF(AND($A17<4,E$15<2022),INDEX('Henry Hub Historicals'!$B$4:$B$307,MATCH(CONCATENATE('NG Calcs'!$A17,".",'NG Calcs'!E$15),'Henry Hub Historicals'!$C$4:$C$307,0),1),INDEX('Gas Futures'!$F:$F,MATCH(CONCATENATE('NG Calcs'!$A17,".",'NG Calcs'!E$15),'Gas Futures'!$L:$L,0),1)),"") -> 5.432 | F17: =IFERROR(IF(AND($A17<4,F$15<2022),INDEX('Henry Hub Historicals'!$B$4:$B$307,MATCH(CONCATENATE('NG Calcs'!$A17,".",'NG Calcs'!F$15),'Henry Hub Historicals'!$C$4:$C$307,0),1),INDEX('Gas Futures'!$F:$F,MATCH(CONCATENATE('NG Calcs'!$A17,".",'NG Calcs'!F$15),'Gas Futures'!$L:$L,0),1)),"") -> 4.844
A18: 3 | B18: =INDEX('Henry Hub Historicals'!$B$4:$B$307,MATCH(CONCATENATE('NG Calcs'!$A18,".",'NG Calcs'!B$15),'Henry Hub Historicals'!$C$4:$C$307,0),1) -> 2.62 | C18: =IFERROR(IF(AND($A18<7,C$15<2023),INDEX('Henry Hub Historicals'!$B$4:$B$307,MATCH(CONCATENATE('NG Calcs'!$A18,".",'NG Calcs'!C$15),'Henry Hub Historicals'!$C$4:$C$307,0),1),INDEX('Gas Futures'!$F:$F,MATCH(CONCATENATE('NG Calcs'!$A18,".",'NG Calcs'!C$15),'Gas Futures'!$L:$L,0),1)),"") -> 4.9 | D18: =IFERROR(IF(AND($A18<4,D$15<2022),INDEX('Henry Hub Historicals'!$B$4:$B$307,MATCH(CONCATENATE('NG Calcs'!$A18,".",'NG Calcs'!D$15),'Henry Hub Historicals'!$C$4:$C$307,0),1),INDEX('Gas Futures'!$F:$F,MATCH(CONCATENATE('NG Calcs'!$A18,".",'NG Calcs'!D$15),'Gas Futures'!$L:$L,0),1)),"") -> 7.169 | E18: =IFERROR(IF(AND($A18<4,E$15<2022),INDEX('Henry Hub Historicals'!$B$4:$B$307,MATCH(CONCATENATE('NG Calcs'!$A18,".",'NG Calcs'!E$15),'Henry Hub Historicals'!$C$4:$C$307,0),1),INDEX('Gas Futures'!$F:$F,MATCH(CONCATENATE('NG Calcs'!$A18,".",'NG Calcs'!E$15),'Gas Futures'!$L:$L,0),1)),"") -> 4.996 | F18: =IFERROR(IF(AND($A18<4,F$15<2022),INDEX('Henry Hub Historicals'!$B$4:$B$307,MATCH(CONCATENATE('NG Calcs'!$A18,".",'NG Calcs'!F$15),'Henry Hub Historicals'!$C$4:$C$307,0),1),INDEX('Gas Futures'!$F:$F,MATCH(CONCATENATE('NG Calcs'!$A18,".",'NG Calcs'!F$15),'Gas Futures'!$L:$L,0),1)),"") -> 4.522
A19: 4 | B19: =INDEX('Henry Hub Historicals'!$B$4:$B$307,MATCH(CONCATENATE('NG Calcs'!$A19,".",'NG Calcs'!B$15),'Henry Hub Historicals'!$C$4:$C$307,0),1) -> 2.66 | C19: =IFERROR(IF(AND($A19<7,C$15<2023),INDEX('Henry Hub Historicals'!$B$4:$B$307,MATCH(CONCATENATE('NG Calcs'!$A19,".",'NG Calcs'!C$15),'Henry Hub Historicals'!$C$4:$C$307,0),1),INDEX('Gas Futures'!$F:$F,MATCH(CONCATENATE('NG Calcs'!$A19,".",'NG Calcs'!C$15),'Gas Futures'!$L:$L,0),1)),"") -> 6.6 | D19: =IFERROR(IF(AND($A19<4,D$15<2022),INDEX('Henry Hub Historicals'!$B$4:$B$307,MATCH(CONCATENATE('NG Calcs'!$A19,".",'NG Calcs'!D$15),'Henry Hub Historicals'!$C$4:$C$307,0),1),INDEX('Gas Futures'!$F:$F,MATCH(CONCATENATE('NG Calcs'!$A19,".",'NG Calcs'!D$15),'Gas Futures'!$L:$L,0),1)),"") -> 5.173 | E19: =IFERROR(IF(AND($A19<4,E$15<2022),INDEX('Henry Hub Historicals'!$B$4:$B$307,MATCH(CONCATENATE('NG Calcs'!$A19,".",'NG Calcs'!E$15),'Henry Hub Historicals'!$C$4:$C$307,0),1),INDEX('Gas Futures'!$F:$F,MATCH(CONCATENATE('NG Calcs'!$A19,".",'NG Calcs'!E$15),'Gas Futures'!$L:$L,0),1)),"") -> 4.191 | F19: =IFERROR(IF(AND($A19<4,F$15<2022),INDEX('Henry Hub Historicals'!$B$4:$B$307,MATCH(CONCATENATE('NG Calcs'!$A19,".",'NG Calcs'!F$15),'Henry Hub Historicals'!$C$4:$C$307,0),1),INDEX('Gas Futures'!$F:$F,MATCH(CONCATENATE('NG Calcs'!$A19,".",'NG Calcs'!F$15),'Gas Futures'!$L:$L,0),1)),"") -> 3.932
