Workbook

Sheet About
A1: FoISaGPbE Fraction of Goods Purchased by Entity
A2: FoISaGPbE Nonenergy Inputs by Supplying Entity as Share of Gross Output
A4: Sources: | B4: All Data
B5: Organisation for Economic Co-operation and Development | C5: Organisation for Economic Co-operation and Development
B6: 2019 | C6: 2021 ed.
B7: Interactive Data Tables: OECD.Stat | C7: Interactive Data Tables: OECD Stat
B8: https://stats.oecd.org | C8: https://stats.oecd.org/Index.aspx?QueryId=109612
B9: Input Output Database: Input-Output Tables (IOTs) ISIC Rev. 4 | C9: Input Output Tables (IOTS) 2021ed.
B10: TTL : Total; VAL: Value Added, DOMIMP: Domestic output and imports | C10: DOMIMP (Domestic output and imports0
A13: Notes
A15: Explanation
A16: When industrial production declines in response to a policy package, the effect is not only
A17: to reduce industry revenue. Industry also buys less services from suppliers, and pays less
A18: income and other taxes to government. This variable helps us calculate the cash flows associated
A19: both with lost revenue (reduced purchases of industrial goods) and reduced spending by
A20: industry.
A22: Fraction of Goods Purchased by Entity is used to allocate money for reduced sales of industrial
A23: outputs. Values for all industries (except Waste Management) are calculated, but only the values
A24: for non-energy industries are actually used in Vensim (in EPS 1.5.0), since the cash flows associated
A25: with reduced sales of energy are already handled in the various demand sectors, with cash flows
A26: assigned to the relevant energy supply industry, as well as to the users of the energy, who buy less.
... A82: to imperceptible levels.

Sheet OECD Crosswalk
A1: OECD Name | B1: Fraction of Good Purchased Category | C1: Industry Category | E1: government | H1: Cement and other carbonate use
A2: TTL_01T03: Agriculture, forestry and fishing | B2: nonenergy industries | C2: agriculture | E2: nonenergy industries | H2: Natural gas and petroleum systems
A3: TTL_05T06: Mining and extraction of energy producing products | B3: natural gas and petroleum suppliers | C3: other industries | E3: labor and consumers | H3: Iron and steel
A4: TTL_07T08: Mining and quarrying of non-energy producing products | B4: nonenergy industries | C4: other industries | E4: foreign entities | H4: Chemicals
A5: TTL_09: Mining support service activities | B5: nonenergy industries | C5: other industries | E5: electricity suppliers | H5: Coal mining
A6: TTL_10T12: Food products, beverages and tobacco | B6: nonenergy industries | C6: other industries | E6: coal suppliers | H6: Waste management
A7: TTL_13T15: Textiles, wearing apparel, leather and related products | B7: nonenergy industries | C7: other industries | E7: natural gas and petroleum suppliers | H7: Agriculture
A8: TTL_16: Wood and of products of wood and cork (except furniture) | B8: nonenergy industries | C8: other industries | E8: biomass and biofuel suppliers | H8: Other industries
A9: TTL_17T18: Paper products and printing | B9: nonenergy industries | C9: other industries | E9: other energy suppliers
A10: TTL_19: Coke and refined petroleum products | B10: natural gas and petroleum suppliers | C10: natural gas and petroleum systems
A11: TTL_20T21: Chemicals and pharmaceutical products | B11: nonenergy industries | C11: chemicals
A12: TTL_22: Rubber and plastics products | B12: nonenergy industries | C12: other industries
A13: TTL_23: Other non-metallic mineral products | B13: nonenergy industries | C13: Cement and other carbonate use
A14: TTL_24: Manufacture of basic metals | B14: nonenergy industries | C14: iron and steel
A15: TTL_25: Fabricated metal products, except machinery and equipment | B15: nonenergy industries | C15: other industries
A16: TTL_26: Computer, electronic and optical products | B16: nonenergy industries | C16: other industries
A17: TTL_27: Electrical equipment | B17: nonenergy industries | C17: other industries
A18: TTL_28: Machinery and equipment n.e.c. | B18: nonenergy industries | C18: other industries
A19: TTL_29: Motor vehicles, trailers and semi-trailers | B19: nonenergy industries | C19: other industries
A20: TTL_30: Other transport equipment | B20: nonenergy industries | C20: other industries
A21: TTL_31T33: Other manufacturing; repair and installation of machinery and equipment | B21: nonenergy industries | C21: other industries
A22: TTL_35T39: Electricity, gas, water supply, sewerage, waste and remediation services | B22: energy suppliers | C22: energy suppliers
A23: TTL_41T43: Construction | B23: nonenergy industries
A24: TTL_45T47: Wholesale and retail trade; repair of motor vehicles | B24: nonenergy industries
A25: TTL_49T53: Transportation and storage | B25: nonenergy industries
A26: TTL_55T56: Accomodation and food services | B26: nonenergy industries
A27: TTL_58T60: Publishing, audiovisual and broadcasting activities | B27: nonenergy industries
A28: TTL_61: Telecommunications | B28: nonenergy industries
A29: TTL_62T63: IT and other information services | B29: nonenergy industries
A30: TTL_64T66: Financial and insurance activities | B30: nonenergy industries
A31: TTL_68: Real estate activities | B31: nonenergy industries
A32: TTL_69T82: Other business sector services | B32: nonenergy industries
A33: TTL_84: Public administration and defence; compulsory social security | B33: government
A34: TTL_85: Education | B34: nonenergy industries
... A42: OUTPUT: Output at basic prices | B42: output
A43: D01T03: Agriculture, forestry and fishing | B43: nonenergy industries | C43: agriculture
A44: D05T06: Mining and extraction of energy producing products | B44: natural gas and petroleum suppliers | C44: other industries
A45: D07T08: Mining and quarrying of non-energy producing products | B45: nonenergy industries | C45: other industries
A46: D09: Mining support service activities | B46: nonenergy industries | C46: other industries
A47: D10T12: Food products, beverages and tobacco | B47: nonenergy industries | C47: other industries
...

Sheet OECD Data IO Table - Total (HKD
A1: =DotStatQuery(#REF!) -> #NAME?
A2: To Sector | B2: =INDEX('OECD Crosswalk'!$B$2:$B$90,MATCH('OECD Data IO Table - Total (USD'!B8,'OECD Crosswalk'!$A$2:$A$90,0),1) -> #N/A | C2: =INDEX('OECD Crosswalk'!$B$2:$B$90,MATCH('OECD Data IO Table - Total (USD'!C8,'OECD Crosswalk'!$A$2:$A$90,0),1) -> #N/A | D2: =INDEX('OECD Crosswalk'!$B$2:$B$90,MATCH('OECD Data IO Table - Total (USD'!D8,'OECD Crosswalk'!$A$2:$A$90,0),1) -> #N/A | E2: =INDEX('OECD Crosswalk'!$B$2:$B$90,MATCH('OECD Data IO Table - Total (USD'!E8,'OECD Crosswalk'!$A$2:$A$90,0),1) -> nonenergy industries | F2: =INDEX('OECD Crosswalk'!$B$2:$B$90,MATCH('OECD Data IO Table - Total (USD'!F8,'OECD Crosswalk'!$A$2:$A$90,0),1) -> natural gas and petroleum suppliers | G2: =INDEX('OECD Crosswalk'!$B$2:$B$90,MATCH('OECD Data IO Table - Total (USD'!G8,'OECD Crosswalk'!$A$2:$A$90,0),1) -> nonenergy industries | H2: =INDEX('OECD Crosswalk'!$B$2:$B$90,MATCH('OECD Data IO Table - Total (USD'!H8,'OECD Crosswalk'!$A$2:$A$90,0),1) -> nonenergy industries | I2: =INDEX('OECD Crosswalk'!$B$2:$B$90,MATCH('OECD Data IO Table - Total (USD'!I8,'OECD Crosswalk'!$A$2:$A$90,0),1) -> nonenergy industries | ... AT2: =INDEX('OECD Crosswalk'!$B$2:$B$90,MATCH('OECD Data IO Table - Total (USD'!AT8,'OECD Crosswalk'!$A$2:$A$90,0),1) -> imports
A3: From Sector | B3: =INDEX('OECD Crosswalk'!$C$2:$C$90,MATCH('OECD Data IO Table - Total (USD'!B8,'OECD Crosswalk'!$A$2:$A$90,0),1) -> #N/A | C3: =INDEX('OECD Crosswalk'!$C$2:$C$90,MATCH('OECD Data IO Table - Total (USD'!C8,'OECD Crosswalk'!$A$2:$A$90,0),1) -> #N/A | D3: =INDEX('OECD Crosswalk'!$C$2:$C$90,MATCH('OECD Data IO Table - Total (USD'!D8,'OECD Crosswalk'!$A$2:$A$90,0),1) -> #N/A | E3: =INDEX('OECD Crosswalk'!$C$2:$C$90,MATCH('OECD Data IO Table - Total (USD'!E8,'OECD Crosswalk'!$A$2:$A$90,0),1) -> agriculture | F3: =INDEX('OECD Crosswalk'!$C$2:$C$90,MATCH('OECD Data IO Table - Total (USD'!F8,'OECD Crosswalk'!$A$2:$A$90,0),1) -> other industries | G3: =INDEX('OECD Crosswalk'!$C$2:$C$90,MATCH('OECD Data IO Table - Total (USD'!G8,'OECD Crosswalk'!$A$2:$A$90,0),1) -> other industries | H3: =INDEX('OECD Crosswalk'!$C$2:$C$90,MATCH('OECD Data IO Table - Total (USD'!H8,'OECD Crosswalk'!$A$2:$A$90,0),1) -> other industries | I3: =INDEX('OECD Crosswalk'!$C$2:$C$90,MATCH('OECD Data IO Table - Total (USD'!I8,'OECD Crosswalk'!$A$2:$A$90,0),1) -> other industries | ... AT3: =INDEX('OECD Crosswalk'!$C$2:$C$90,MATCH('OECD Data IO Table - Total (USD'!AT8,'OECD Crosswalk'!$A$2:$A$90,0),1) -> 0
A4: Variable | B4: TTL: Total
A5: Country | B5: HKG: Hong Kong, China
A6: Time | B6: 2021
A7: Unit | B7: HK Dollar, Millions
A8: To: (sector in column) | B8: D01T03: Agriculture, forestry and fishing | C8: D05T06: Mining and extraction of energy producing products | D8: D07T08: Mining and quarrying of non-energy producing products | E8: D09: Mining support service activities | F8: D10T12: Food products, beverages and tobacco | G8: D13T15: Textiles, wearing apparel, leather and related products | H8: D16: Wood and products of wood and cork | I8: D17T18: Paper products and printing | J8: D19: Coke and refined petroleum products | K8: D20T21: Chemicals and pharmaceutical products | L8: D22: Rubber and plastic products | M8: D23: Other non-metallic mineral products | N8: D24: Basic metals | O8: D25: Fabricated metal products | P8: D26: Computer, electronic and optical products | Q8: D27: Electrical equipment | R8: D28: Machinery and equipment, nec | S8: D29: Motor vehicles, trailers and semi-trailers | T8: D30: Other transport equipment | U8: D31T33: Other manufacturing; repair and installation of machinery and equipment | V8: D35T39: Electricity, gas, water supply, sewerage, waste and remediation services | W8: D41T43: Construction | X8: D45T47: Wholesale and retail trade; repair of motor vehicles | Y8: D49T53: Transportation and storage | Z8: D55T56: Accomodation and food services | AA8: D58T60: Publishing, audiovisual and broadcasting activities | AB8: D61: Telecommunications | AC8: D62T63: IT and other information services | AD8: D64T66: Financial and insurance activities | AE8: D68: Real estate activities | AF8: D69T82: Other business sector services | AG8: D84: Public admin. and defence; compulsory social security | AH8: D85: Education | AI8: D86T88: Human health and social work | AJ8: D90T96: Arts, entertainment, recreation and other service activities | AK8: D97T98: Private households with employed persons | AL8: HFCE: Final consumption expenditure of households | AM8: NPISH: Final consumption expenditure of non-profit institutions serving households | AN8: GGFC: Final consumption expenditure of general government | AO8: GFCF: Gross Fixed Capital Formation | AP8: INVNT: Changes in inventories | AQ8: CONS_ABR: Direct purchases abroad by residents (imports) | AR8: CONS_NONRES: Direct purchases by non-residents (exports) | AS8: EXPO: Exports (cross border) | AT8: IMPO: Imports (cross border) | AU8: Totals
A9: From: (sector in row)
A10: TTL_01T03: Agriculture, forestry and fishing | B10: =0.9+0.1+0.1 -> 1.1 | C10: 0 | D10: 0 | E10: 0.0012333592 | F10: =154.9+4.4 -> 159.3 | G10: =1.6+0.2 -> 1.8 | H10: =0.5+0.1 -> 0.6 | I10: =2.5+0.6 -> 3.1 | J10: 0 | K10: =0.3+0.2 -> 0.5 | L10: 0 | M10: 0.1 | N10: 0.4 | O10: 0 | P10: 0.1 | Q10: 0.1 | R10: 0.1 | S10: 0.1 | T10: 1.6348852e-05 | U10: 0 | V10: =43.7+16.7+5.3+2.2 -> 67.9 | W10: =7.9+1.3 -> 9.2 | X10: =44.4+3.5 -> 47.9 | Y10: =34.6+141.9+255+6.8+4+4.4+37.6+62.6+1.3+1.1 -> 549.3 | Z10: =453.1+91.4 -> 544.5 | AA10: =3.6+1 -> 4.6 | AB10: =8.3+1.8 -> 10.1 | AC10: 0.2 | AD10: =8.6+1.5 -> 10.1 | AE10: =2.9+0.4 -> 3.3 | AF10: =2+5.2+0.3+0.6 -> 8.1 | AG10: =7.1+0.7 -> 7.8 | AH10: =11.8+1.3 -> 13.1 | AI10: =19.4+1.6 -> 21 | AJ10: =13+2.4+19.7+3.5 -> 38.6 | AK10: 0 | AL10: =4367.1+711.7 -> 5078.8 | AM10: 0.1 | AN10: 0 | AO10: =3.2+0.3 -> 3.5 | AP10: =10.3+0.3 -> 10.6 | AQ10: =33.6+2.6 -> 36.2 | AR10: =1.1+2.5 -> 3.6 | AS10: =4.5+7.5 -> 12 | AT10: =-5242.7+-891.3 -> -6134 | AU10: =SUM(B10:AN10) -> 6581.9012
A11: TTL_05T06: Mining and extraction of energy producing products | B11: =15.7+1.5 -> 17.2 | C11: 0 | D11: 0 | E11: 169.3 | F11: 167.3 | G11: 136.5 | H11: 8.7 | I11: 91.6 | J11: 18.1 | K11: =0.6+0.1 -> 0.7 | L11: 0 | M11: 1.4 | N11: 43.7 | O11: 2.2 | P11: 4.1 | Q11: 11.9 | R11: 8.1 | S11: 2.6 | T11: 1.7 | U11: 9.7 | V11: =54.1+30.2 -> 84.3 | W11: 3.8 | X11: 22.3 | Y11: =129.4+1.9+39.4+1601.3+9.5 -> 1781.5 | Z11: 6 | AA11: 3.2 | AB11: 12.7 | AC11: 4.1 | AD11: 44.4 | AE11: 11.6 | AF11: =27.1+84.5 -> 111.6 | AG11: 7.7 | AH11: 30.2 | AI11: 16.2 | AJ11: =14.1+22.3 -> 36.4 | AK11: 0 | AL11: 37.1 | AM11: 0.6 | AN11: 0 | AO11: 3.7 | AP11: 31.4 | AQ11: 0.4 | AR11: 0 | AS11: 0 | AT11: -2952.4 | AU11: =SUM(B11:AN11) -> 2908.5
A12: TTL_07T08: Mining and quarrying of non-energy producing products | B12: =3.1+0.4 -> 3.5 | C12: 0 | D12: 0 | E12: 38.7 | F12: 20.2 | G12: 17.4 | H12: 1.3 | I12: 9.9 | J12: 0.5 | K12: =0.2+0.1 -> 0.3 | L12: 0 | M12: 0.9 | N12: 10.1 | O12: 0.6 | P12: 0.7 | Q12: 2.4 | R12: 1.6 | S12: 0.4 | T12: 0.3 | U12: 1.7 | V12: =4.2+4 -> 8.2 | W12: 2.1 | X12: 3.7 | Y12: =18.8+0.2+4.8+288.2+0.9 -> 312.9 | Z12: 0.8 | AA12: 800.1 | AB12: 1.6 | AC12: 0.5 | AD12: 4.7 | AE12: 1.8 | AF12: =5.7+10.8 -> 16.5 | AG12: 1.3 | AH12: 3.1 | AI12: 1.7 | AJ12: =1.9+3 -> 4.9 | AK12: 0 | AL12: 6.1 | AM12: 0 | AN12: 0 | AO12: 1 | AP12: 1.1 | AQ12: 0.4 | AR12: 0 | AS12: 0 | AT12: -481.4 | AU12: =SUM(B12:AN12) -> 1280.5
A13: TTL_09: Mining support service activities | B13: =61.5+20.9 -> 82.4 | C13: 0 | D13: 0 | E13: 6150 | F13: 152.1 | G13: 30.3 | H13: 37.1 | I13: 141.9 | J13: 2.4 | K13: =0.5 -> 0.5 | L13: 0 | M13: 1.1 | N13: 131.8 | O13: 6.1 | P13: 2 | Q13: 5.3 | R13: 22.1 | S13: 2 | T13: 1.1 | U13: 0.2 | V13: =52.3+30.2 -> 82.5 | W13: 10.6 | X13: 26.6 | Y13: =317.8+2.7+174+48.2+55.1 -> 597.8 | Z13: 3.5 | AA13: 3.2 | AB13: 0 | AC13: 1.6 | AD13: 190.1 | AE13: 50.8 | AF13: =120.1+41.2 -> 161.3 | AG13: 20.2 | AH13: 83.8 | AI13: 0.6 | AJ13: =6.4+18 -> 24.4 | AK13: 0 | AL13: 6.2 | AM13: 0 | AN13: 0 | AO13: 1.2 | AP13: 1.1 | AQ13: 0.1 | AR13: 0 | AS13: 73.2 | AT13: -14.6 | AU13: =SUM(B13:AN13) -> 8031.6
A14: TTL_10T12: Food products, beverages and tobacco | B14: =11.3+0.9 -> 12.2 | C14: 0 | D14: 0 | E14: 0.1 | F14: 539.2 | G14: 78.2 | H14: 53.8 | I14: 396.1 | J14: 2.8 | K14: =19.7+10.5 -> 30.2 | L14: 0 | M14: 3.2 | N14: 20.7 | O14: 1.7 | P14: 2.8 | Q14: 4.8 | R14: 3.2 | S14: 1.5 | T14: 0.6 | U14: 0.5 | V14: =255.9+134.1 -> 390 | W14: 848.3 | X14: 801 | Y14: =295.2+974+907.2+327.5+153.3 -> 2657.2 | Z14: 1390.5 | AA14: 800.1 | AB14: 197.8 | AC14: 9.7 | AD14: 595.1 | AE14: 216.6 | AF14: =66.2+113.4 -> 179.6 | AG14: 75.2 | AH14: 93.8 | AI14: 418.3 | AJ14: =106.5+249.3 -> 355.8 | AK14: 0 | AL14: 11837.5 | AM14: 0 | AN14: 0 | AO14: 244.1 | AP14: 3599.6 | AQ14: 148.6 | AR14: 219.5 | AS14: 380.6 | AT14: -17148.7 | AU14: =SUM(B14:AN14) -> 22018.1
A15: TTL_13T15: Textiles, wearing apparel, leather and related products | B15: =0.5+0.1 -> 0.6 | C15: 0 | D15: 0 | E15: 0.2 | F15: 22.7 | G15: 642.5 | H15: 2.8 | I15: 30.9 | J15: 0.1 | K15: =0.7+0.3 -> 1 | L15: 0 | M15: 0.6 | N15: 2.5 | O15: 0.3 | P15: 0.3 | Q15: 0.6 | R15: 0.4 | S15: 0.8 | T15: 0.2 | U15: 0.7 | V15: =13.3+21 -> 34.3 | W15: 15.2 | X15: 320.4 | Y15: =129+151.7+110.9+152.1+80.8 -> 624.5 | Z15: 11.8 | AA15: 3.2 | AB15: 86.1 | AC15: 3.9 | AD15: 312.3 | AE15: 117.6 | AF15: =28.7+60.6 -> 89.3 | AG15: 35.2 | AH15: 23.1 | AI15: 32.3 | AJ15: =20+106.4 -> 126.4 | AK15: 0 | AL15: 9666.4 | AM15: 0 | AN15: 0 | AO15: 62.4 | AP15: 1918.5 | AQ15: 94 | AR15: 19.7 | AS15: 389.1 | AT15: -11723.4 | AU15: =SUM(B15:AN15) -> 12209.2
A16: TTL_16: Wood and of products of wood and cork (except furniture) | B16: =2+0.1 -> 2.1 | C16: 0 | D16: 0 | E16: 0.1 | F16: 25.5 | G16: 0.2 | H16: 0 | I16: 0.2 | J16: 0 | K16: 0.1 | L16: 0 | M16: 0.1 | N16: 0.9 | O16: 0.1 | P16: 0.1 | Q16: 0.2 | R16: 0.1 | S16: 0.2 | T16: 0.1 | U16: 0.1 | V16: =1.8+1.9 -> 3.7 | W16: 113.8 | X16: 12.2 | Y16: =19.9+83.6+12.7+34.4+3.1 -> 153.7 | Z16: 1.4 | AA16: 800.1 | AB16: 4.7 | AC16: 0 | AD16: 10.6 | AE16: 3.1 | AF16: =0.9+1.2 -> 2.1 | AG16: 1.1 | AH16: 1.3 | AI16: 28.4 | AJ16: =2.3+3.6 -> 5.9 | AK16: 0 | AL16: 565.3 | AM16: 0 | AN16: 0 | AO16: 66.4 | AP16: 334.4 | AQ16: 6.2 | AR16: 0.2 | AS16: 26 | AT16: -626.1 | AU16: =SUM(B16:AN16) -> 1737.5
A17: TTL_17T18: Paper products and printing | B17: =9.6+1 -> 10.6 | C17: 0 | D17: 0 | E17: 0.1 | F17: 751.4 | G17: 175.7 | H17: 5.3 | I17: 796.5 | J17: 0.3 | K17: =3.2+2.7 -> 5.9 | L17: 0 | M17: 10 | N17: 6 | O17: 0.8 | P17: 4.5 | Q17: 10 | R17: 3.4 | S17: 1.3 | T17: 0.3 | U17: 3.3 | V17: =16.3+20.7 -> 37 | W17: 449.8 | X17: 427.7 | Y17: =117.7+176.3+82.9+171.8+54.5 -> 603.2 | Z17: 5.2 | AA17: 3.2 | AB17: 59.7 | AC17: 2.7 | AD17: 351.9 | AE17: 89.7 | AF17: =24.6+29.4 -> 54 | AG17: 16.4 | AH17: 39.5 | AI17: 334 | AJ17: =24+41.4 -> 65.4 | AK17: 0 | AL17: 1557.3 | AM17: 0 | AN17: 0 | AO17: 18.8 | AP17: 234 | AQ17: 17 | AR17: 74.7 | AS17: 124.2 | AT17: -1724.9 | AU17: =SUM(B17:AN17) -> 5882.1
A18: TTL_19: Coke and refined petroleum products | B18: =1+0.1 -> 1.1 | C18: 0 | D18: 0 | E18: 15.7 | F18: 11.7 | G18: 3.1 | H18: 2.1 | I18: 11.4 | J18: 74.9 | K18: =119.6+20.8 -> 140.4 | L18: 0 | M18: 52.8 | N18: 667.4 | O18: 48.7 | P18: 4.8 | Q18: 15.9 | R18: 9.3 | S18: 10.4 | T18: 3.5 | U18: 6.1 | V18: =84.7+55.8 -> 140.5 | W18: 4 | X18: 4405.8 | Y18: =293.6+671.7+606.3+737.5+45.6 -> 2354.7 | Z18: 15 | AA18: 800.1 | AB18: 40.7 | AC18: 3.9 | AD18: 535 | AE18: 134.4 | AF18: =23.7+97.7 -> 121.4 | AG18: 253.3 | AH18: 116.1 | AI18: 20.1 | AJ18: =29.2+62.4 -> 91.6 | AK18: 0 | AL18: 3345.6 | AM18: 0 | AN18: 0 | AO18: 12.6 | AP18: 1096.6 | AQ18: 63.2 | AR18: 69 | AS18: 33.1 | AT18: -13543.9 | AU18: =SUM(B18:AN18) -> 13461.5
A19: TTL_20T21: Chemicals and pharmaceutical products | B19: =2.1+0.1+0.1 -> 2.3 | C19: 0 | D19: 0 | E19: =11.5+0.1 -> 11.6 | F19: =32.9+2.4 -> 35.3 | G19: =3.1+22 -> 25.1 | H19: =11.5+0.4 -> 11.9 | I19: =93.6+2.1 -> 95.7 | J19: =27.4+0.7 -> 28.1 | K19: =289.4+68.9+7.7+55.8 -> 421.8 | L19: 0 | M19: =76.4+1.6 -> 78 | N19: =197.6+667.4 -> 865 | O19: =18.5+0.5 -> 19 | P19: =37+1.5 -> 38.5 | Q19: =106.2+2.1 -> 108.3 | R19: =28.2+0.9 -> 29.1 | S19: =20.4+0.5 -> 20.9 | T19: =6.1+0.2 -> 6.3 | U19: =12.1+0.2 -> 12.3 | V19: =12.5+158.3+0.6+4.8 -> 176.2 | W19: =7+0.8 -> 7.8 | X19: =764.3+51 -> 815.3 | Y19: =16.8+34.7+30.3+104+13+0.9+2.9+2.9+4.9+1.1 -> 211.5 | Z19: =23.4+2 -> 25.4 | AA19: =68.6+1.7 -> 70.3 | AB19: =21.5+2 -> 23.5 | AC19: =1.7+0.1 -> 1.8 | AD19: =125.9+9.8 -> 135.7 | AE19: =54+2.7 -> 56.7 | AF19: =19.7+46.6+2.8+1.7 -> 70.8 | AG19: =78+14.6 -> 92.6 | AH19: =202.3+21.7 -> 224 | AI19: =87.8+75.7 -> 163.5 | AJ19: =79.1+9.8+267.1+12.6 -> 368.6 | AK19: 0 | AL19: =3025.1+1373.4 -> 4398.5 | AM19: 0 | AN19: =0.2+0.2 -> 0.4 | AO19: =127.2+30.4 -> 157.6 | AP19: =899.5+349.2 -> 1248.7 | AQ19: =23.6+18.4 -> 42 | AR19: =6.1+44.5 -> 50.6 | AS19: =333.9+161.6 -> 495.5 | AT19: =-6496.9-1813.5 -> -8310.4 | AU19: =SUM(B19:AN19) -> 8651.8
A20: TTL_22: Rubber and plastics products | B20: 0.2 | C20: 0 | D20: 0 | E20: 1.4 | F20: 49.5 | G20: 5.7 | H20: 1.7 | I20: 21.7 | J20: 2.3 | K20: =19.8+12.8 -> 32.6 | L20: 0 | M20: 15.7 | N20: 41.9 | O20: 7.3 | P20: 28.6 | Q20: 83.7 | R20: 30.4 | S20: 82.5 | T20: 15.9 | U20: 10.9 | V20: =2.4+34 -> 36.4 | W20: 2.4 | X20: 2002.7 | Y20: =17.9+2.3+2.4+14.1+3.3 -> 40 | Z20: 7 | AA20: 14.4 | AB20: 5 | AC20: 0.2 | AD20: 14.1 | AE20: 29.8 | AF20: =1.6+3.5 -> 5.1 | AG20: 6.7 | AH20: 2.1 | AI20: 2.2 | AJ20: =15.1+38.2 -> 53.3 | AK20: 0 | AL20: 326 | AM20: 0 | AN20: 0.1 | AO20: 43.5 | AP20: 40.4 | AQ20: 0.5 | AR20: 0 | AS20: 0 | AT20: -3064 | AU20: =SUM(B20:AN20) -> 2979.5
A21: TTL_23: Other non-metallic mineral products | B21: 0.1 | C21: 0 | D21: 0 | E21: 4.4 | F21: 41.4 | G21: 1.6 | H21: 1.4 | I21: 5.3 | J21: 14 | K21: =11.9+8.7 -> 20.6 | L21: 0 | M21: 402.6 | N21: 451.1 | O21: 42.1 | P21: 36.3 | Q21: 98.8 | R21: 19.8 | S21: 61.1 | T21: 18.4 | U21: 6 | V21: =5.3+32 -> 37.3 | W21: 58.7 | X21: 183.1 | Y21: =2.6+2.7+5+26+13.2 -> 49.5 | Z21: 3.2 | AA21: 12.2 | AB21: 35.8 | AC21: 0.4 | AD21: 61.3 | AE21: 22 | AF21: =3.9+7.9 -> 11.8 | AG21: 115.8 | AH21: 81.2 | AI21: 4.6 | AJ21: =18.4+43.1 -> 61.5 | AK21: 0 | AL21: 672.5 | AM21: 0 | AN21: 0 | AO21: 49.4 | AP21: 165.7 | AQ21: 0.3 | AR21: 0 | AS21: 108.8 | AT21: -1681.9 | AU21: =SUM(B21:AN21) -> 2635.9
A22: TTL_24: Manufacture of basic metals | B22: 0.1 | C22: 0 | D22: 0 | E22: 5.3 | F22: 10.3 | G22: 0.9 | H22: 1.7 | I22: 8.7 | J22: 5 | K22: =14.7+3.7 -> 18.4 | L22: 0 | M22: 31.6 | N22: 5839.2 | O22: 476 | P22: 110.9 | Q22: 489.7 | R22: 157.6 | S22: 52.9 | T22: 10.1 | U22: 37.9 | V22: =6.5+87.6 -> 94.1 | W22: 8.3 | X22: 5508.3 | Y22: =5.3+13.1+10.3+50.1+2.9 -> 81.7 | Z22: 1.7 | AA22: 12.2 | AB22: 8.3 | AC22: 0.7 | AD22: 62 | AE22: 41 | AF22: =7.7+5.2 -> 12.9 | AG22: 13.7 | AH22: 14.6 | AI22: 2.3 | AJ22: =15.4+24.7 -> 40.1 | AK22: 0 | AL22: 158.6 | AM22: 0 | AN22: 0.1 | AO22: 263.3 | AP22: 295.4 | AQ22: 0.7 | AR22: 0 | AS22: 8466.3 | AT22: -10834.1 | AU22: =SUM(B22:AN22) -> 13316.9
A23: TTL_25: Fabricated metal products, except machinery and equipment | B23: 0.1 | C23: 0 | D23: 0 | E23: 3.9 | F23: 4.7 | G23: 0.9 | H23: 1.4 | I23: 3.2 | J23: 2.6 | K23: =4+1.7 -> 5.7 | L23: 0 | M23: 13 | N23: 275.8 | O23: 75.6 | P23: 24.8 | Q23: 81.6 | R23: 58.2 | S23: 32.3 | T23: 10.7 | U23: 10 | V23: =3.1+16.3 -> 19.4 | W23: 6.2 | X23: 2351.6 | Y23: =2.6+5+3.3+30+1.7 -> 42.6 | Z23: 1.6 | AA23: 6.1 | AB23: 6.9 | AC23: 0.6 | AD23: 32.2 | AE23: 31.1 | AF23: =4.4+10.3 -> 14.7 | AG23: 13.6 | AH23: 13.1 | AI23: 1.8 | AJ23: =9.7+14.1 -> 23.8 | AK23: 0 | AL23: 390.5 | AM23: 0 | AN23: 0 | AO23: 631.1 | AP23: 230.1 | AQ23: 0.5 | AR23: 0 | AS23: 335.3 | AT23: -3551.3 | AU23: =SUM(B23:AN23) -> 3560.3
A24: TTL_26: Computer, electronic and optical products | B24: 0.1 | C24: 0 | D24: 0 | E24: 2 | F24: 3.9 | G24: 1.3 | H24: 0.4 | I24: 3.9 | J24: 2.9 | K24: =4.7+2.9 -> 7.6 | L24: 0 | M24: 3.9 | N24: 20 | O24: 4.4 | P24: 384.8 | Q24: 160.8 | R24: 52.9 | S24: 26 | T24: 11.7 | U24: 9.6 | V24: =47.7+63 -> 110.7 | W24: 2.8 | X24: 11206.1 | Y24: =4.2+12.5+10.6+21.6+111.8 -> 160.7 | Z24: 3.3 | AA24: 134.7 | AB24: 1136.7 | AC24: 18.3 | AD24: 167.9 | AE24: 62.2 | AF24: =35.9+44.9 -> 80.8 | AG24: 72.9 | AH24: 101.3 | AI24: 7.3 | AJ24: =99.7+241.4 -> 341.1 | AK24: 0 | AL24: 9641.6 | AM24: 0 | AN24: 0.2 | AO24: 6253.5 | AP24: 29295.1 | AQ24: 28 | AR24: 0.1 | AS24: 1379.5 | AT24: -59402.6 | AU24: =SUM(B24:AN24) -> 23944.8
A25: TTL_27: Electrical equipment | B25: 0 | C25: 0 | D25: 0 | E25: 1.8 | F25: 3.2 | G25: 0.7 | H25: 0.5 | I25: 2.5 | J25: 2.5 | K25: =3.2+1.6 -> 4.8 | L25: 0 | M25: 5.3 | N25: 42.3 | O25: 5.7 | P25: 127.1 | Q25: 580.4 | R25: 102.4 | S25: 48.3 | T25: 14.3 | U25: 13.2 | V25: =75.6+61 -> 136.6 | W25: 6.7 | X25: 8164.4 | Y25: =5.2+11.2+6+17.1+62.9 -> 102.4 | Z25: 2.3 | AA25: 75 | AB25: 538.9 | AC25: 5 | AD25: 75.2 | AE25: 91 | AF25: =22.9+42.5 -> 65.4 | AG25: 37 | AH25: 46.3 | AI25: 3.2 | AJ25: =64.3+163.9 -> 228.2 | AK25: 0 | AL25: 4056.2 | AM25: 0 | AN25: 0.1 | AO25: 2029.2 | AP25: 1058.9 | AQ25: 11.8 | AR25: 2.4 | AS25: 342.1 | AT25: -15322.5 | AU25: =SUM(B25:AN25) -> 14588.9
A26: TTL_28: Machinery and equipment n.e.c. | B26: 0.3 | C26: 0 | D26: 0 | E26: 15.2 | F26: 14.4 | G26: 3.6 | H26: 2.6 | I26: 12.8 | J26: 5.9 | K26: =9.5+5.3 -> 14.8 | L26: 0 | M26: 29.5 | N26: 232.2 | O26: 39.9 | P26: 26.2 | Q26: 71.3 | R26: 237.1 | S26: 115.8 | T26: 39.9 | U26: 22.1 | V26: =12.3+20.7 -> 33 | W26: 3.2 | X26: 724.6 | Y26: =8.3+69.5+100.1+171.4+16.1 -> 365.4 | Z26: 3.7 | AA26: 10 | AB26: 34.5 | AC26: 0.4 | AD26: 251.5 | AE26: 61.5 | AF26: =2.8+8.4 -> 11.2 | AG26: 14 | AH26: 18.9 | AI26: 31.4 | AJ26: =13.1+20.5 -> 33.6 | AK26: 0 | AL26: 465.5 | AM26: 0 | AN26: 0.2 | AO26: 7163.9 | AP26: 1027.4 | AQ26: 0.8 | AR26: 0 | AS26: 912.5 | AT26: -10813.8 | AU26: =SUM(B26:AN26) -> 2946.2
A27: TTL_29: Motor vehicles, trailers and semi-trailers | B27: 0 | C27: 0 | D27: 0 | E27: 0.3 | F27: 0.6 | G27: 0.3 | H27: 0.1 | I27: 0.6 | J27: 0.2 | K27: =0.4+0.2 -> 0.6 | L27: 0 | M27: 1.5 | N27: 6.9 | O27: 1.1 | P27: 2.2 | Q27: 6.3 | R27: 9.4 | S27: 186.9 | T27: 7.3 | U27: 1.3 | V27: =0.9+26.3 -> 27.2 | W27: 0.3 | X27: 468 | Y27: =24.1+24+17.4+5.7+17.8 -> 89 | Z27: 1 | AA27: 13.7 | AB27: 19.5 | AC27: 0.4 | AD27: 36 | AE27: 5.3 | AF27: =2.6+11.3 -> 13.9 | AG27: 40.8 | AH27: 1.6 | AI27: 1 | AJ27: =23.9+32.8 -> 56.7 | AK27: 0 | AL27: 1598 | AM27: 0 | AN27: 0.1 | AO27: 2196.8 | AP27: 701.9 | AQ27: 13.1 | AR27: 4.1 | AS27: 45 | AT27: -4090.8 | AU27: =SUM(B27:AN27) -> 2598.1
A28: TTL_30: Other transport equipment | B28: 0 | C28: 0 | D28: 0 | E28: 0.1 | F28: 0.4 | G28: 0.1 | H28: 0.1 | I28: 0.5 | J28: 0.2 | K28: =0.3+0.2 -> 0.5 | L28: 0 | M28: 1.1 | N28: 5.5 | O28: 0.6 | P28: 1.1 | Q28: 2.2 | R28: 4.7 | S28: 199.1 | T28: 127.4 | U28: 4.6 | V28: =0.3+21.1 -> 21.4 | W28: 0.2 | X28: 475.7 | Y28: =17.1+53.5+83.6+5.8+13.3 -> 173.3 | Z28: 0.8 | AA28: 21.1 | AB28: 10.4 | AC28: 0.3 | AD28: 52.1 | AE28: 4 | AF28: =4.4+8 -> 12.4 | AG28: 91.9 | AH28: 1.1 | AI28: 0.7 | AJ28: =27.3+40.4 -> 67.7 | AK28: 0 | AL28: 916.2 | AM28: 0 | AN28: 0 | AO28: 4989.8 | AP28: 1071.4 | AQ28: 0.3 | AR28: 0 | AS28: 30.6 | AT28: -7770.4 | AU28: =SUM(B28:AN28) -> 2197.5
A29: TTL_31T33: Other manufacturing; repair and installation of machinery and equipment | B29: =0.3+0.1 -> 0.4 | C29: 0 | D29: 0 | E29: 1.2 | F29: 9.5 | G29: 2.4 | H29: 1.4 | I29: 12.9 | J29: 0.3 | K29: =0.8+0.7 -> 1.5 | L29: 0 | M29: 1.6 | N29: 31.2 | O29: 4.8 | P29: 2.7 | Q29: 4.2 | R29: 2.9 | S29: 5.5 | T29: 2.9 | U29: 3.1 | V29: =13.8+16.7 -> 30.5 | W29: 27.5 | X29: 362.7 | Y29: =33.7+59.1+91.5+52.2+10 -> 246.5 | Z29: 9.8 | AA29: 11.1 | AB29: 31.8 | AC29: 1.1 | AD29: 342.2 | AE29: 93.4 | AF29: =5.9+26 -> 31.9 | AG29: 42.3 | AH29: 37.9 | AI29: 17.6 | AJ29: =29.7+22.7 -> 52.4 | AK29: 0 | AL29: 1011.7 | AM29: 0 | AN29: 0.1 | AO29: 353.7 | AP29: 8436.5 | AQ29: 82.2 | AR29: 0 | AS29: 317.4 | AT29: -10821.1 | AU29: =SUM(B29:AN29) -> 2439
A30: TTL_35T39: Electricity, gas, water supply, sewerage, waste and remediation services | B30: =0.8+0.8+0.1 -> 1.7 | C30: 0 | D30: 0 | E30: =0.9+0.1 -> 1 | F30: =101.8+46.8 -> 148.6 | G30: =13.8+8.9 -> 22.7 | H30: =9.4+6.5 -> 15.9 | I30: =75.2+60.3 -> 135.5 | J30: =0.2+0.1 -> 0.3 | K30: =0.7+0.2+0.3+0.1 -> 1.3 | L30: 0 | M30: =0.7+0.3 -> 1 | N30: =7.2+7.3 -> 14.5 | O30: =0.4+0.4 -> 0.8 | P30: =0.2+0.2 -> 0.4 | Q30: =0.5+0.4 -> 0.9 | R30: =0.3+0.3 -> 0.6 | S30: =0.2+0.3 -> 0.5 | T30: =0.1+0.1 -> 0.2 | U30: =0.4+0.1 -> 0.5 | V30: =309.3+91.3+68.3+324.7 -> 793.6 | W30: =41+54.5 -> 95.5 | X30: =392.8+637.4 -> 1030.2 | Y30: =127.5+49.2+72.4+374.1+17.8+64.4+58.5+53.5+159.9+51.6 -> 1028.9 | Z30: =396.2+147.3 -> 543.5 | AA30: =68.5+27 -> 95.5 | AB30: =102.3+95.6 -> 197.9 | AC30: =3.9+5.8 -> 9.7 | AD30: =492.5+512.9 -> 1005.4 | AE30: =1271.9+1084 -> 2355.9 | AF30: =23.1+25.5+32.5+67.5 -> 148.6 | AG30: =154.8+97.2 -> 252 | AH30: =127.8+62.5 -> 190.3 | AI30: =202.9+80.2 -> 283.1 | AJ30: =115.3+120.8+55.8+107.4 -> 399.3 | AK30: 0 | AL30: =1356.2+1142.3 -> 2498.5 | AM30: =2.4+29.9 -> 32.3 | AN30: 0 | AO30: =2.2+108.1 -> 110.3 | AP30: =3.8+8.5 -> 12.3 | AQ30: =0.4+0.2 -> 0.6 | AR30: 0 | AS30: =39.5 -> 39.5 | AT30: =-915.6+-26.6 -> -942.2 | AU30: =SUM(B30:AN30) -> 11306.6
A31: TTL_41T43: Construction | B31: 0.8 | C31: 0 | D31: 0 | E31: 0.5 | F31: 7.4 | G31: 0.6 | H31: 0.4 | I31: 2.3 | J31: 0 | K31: =0.1+0.1 -> 0.2 | L31: 0 | M31: 0.4 | N31: 2.1 | O31: 0.2 | P31: 0.2 | Q31: 0.4 | R31: 0.2 | S31: 0.2 | T31: 0.1 | U31: 0.1 | V31: =5+5.5 -> 10.5 | W31: 6417 | X31: 31.4 | Y31: =22.1+14.8+63.3+24.6+3.4 -> 128.2 | Z31: 10.7 | AA31: 3.2 | AB31: 11.3 | AC31: 0.3 | AD31: 32.5 | AE31: 325.9 | AF31: =2.6+2.8 -> 5.4 | AG31: 352.5 | AH31: 22.6 | AI31: 23 | AJ31: =5.8+8.4 -> 14.2 | AK31: 0 | AL31: 13.2 | AM31: 0 | AN31: 0 | AO31: 20315.1 | AP31: 9.7 | AQ31: 1.6 | AR31: 0 | AS31: 0 | AT31: -55 | AU31: =SUM(B31:AN31) -> 7418
A32: TTL_45T47: Wholesale and retail trade; repair of motor vehicles | B32: =130.8+6.8 -> 137.6 | C32: 0 | D32: 0 | E32: 1505.9 | F32: 2412.7 | G32: 1050.7 | H32: 192.3 | I32: 1563.4 | J32: 172.2 | K32: =544.1+216.9 -> 761 | L32: 0 | M32: 461.7 | N32: 2750.3 | O32: 317 | P32: 521.1 | Q32: 757.5 | R32: 357.4 | S32: 470.6 | T32: 189.1 | U32: 529.4 | V32: =1129.9+873.3 -> 2003.2 | W32: 2384.2 | X32: 31331.2 | Y32: =1651.4+3322.3+3587.6+4514.6+589.3 -> 13665.2 | Z32: 3055.2 | AA32: 800.1 | AB32: 1862.5 | AC32: 71.6 | AD32: 4045.9 | AE32: 1503.6 | AF32: =376.4+934.6 -> 1311 | AG32: 985.7 | AH32: 1037.5 | AI32: 1582.7 | AJ32: =721.8+1395.5 -> 2117.3 | AK32: 0 | AL32: 60617 | AM32: 1.7 | AN32: 0.5 | AO32: 16654.3 | AP32: 5580.1 | AQ32: 108.4 | AR32: 467.9 | AS32: 37109.9 | AT32: -23738.3 | AU32: =SUM(B32:AN32) -> 142526
A33: TTL_49T53: Transportation and storage | B33: =4.8+0.4+1.1+0.1+1+0.1+2.6+0.2+0.3 -> 10.6 | C33: 0 | D33: 0 | E33: =28+6.5+5.1+15.3+0.1 -> 55 | F33: =120.7+89.2+59.6+57.8+33.8 -> 361.1 | G33: =60.7+27.5+20.2+28.1+9.1 -> 145.6 | H33: =7.7+9.6+5.4+3.8+4 -> 30.5 | I33: =11.6+2.3+2.1+6.5 -> 22.5 | J33: =11.6+2.3+2.1+6.5 -> 22.5 | K33: =33.8+12.3+6.6+2.3+6+2.1+18.7+6.6+0.1+0.1 -> 88.6 | L33: 0 | M33: =45.3+8.2+7.4+23.2+0.1 -> 84.2 | N33: =260.9+44.3+37.7+121.5+0.4 -> 464.8 | O33: =30.3+5.3+4.6+14.7+0.1 -> 55 | P33: =41.9+7.6+7+21.6+0.1 -> 78.2 | Q33: =69.7+11.4+10.3+32.4+0.2 -> 124 | R33: =31.7+5.4+4.8+14.9+0.2 -> 57 | S33: =33.3+5.9+5.3+16.4+0.1 -> 61 | T33: =14.4+2.6+2.4+7.3 -> 26.7 | U33: =7.6+1.6+1+3.8 -> 14 | V33: =50.8+52+14.2+24.8+11.6+13.7+26.4+25.6+8.2+18.6 -> 245.9 | W33: =82.1+84.9+61.7+43.9+17.7 -> 290.3 | X33: =1955.1+2124.8+1373.8+966.9+723.7 -> 7144.3 | Y33: =234.5+231.6+186.9+479.2+43.7+85.8+3781.7+1973.5+1578.4+647.4+56+2183+1169+551.6+397.6+44.5+93.7+96.4+244.7+20.4+32.2+417.1+55.5+73.2+736.5 -> 15414.1 | Z33: =188.3+59.4+44.5+90.6+22.1 -> 404.9 | AA33: =41.3+22.6+23.8+20.5+34.4 -> 142.6 | AB33: =135.5+599.9+351.4+69.2+459.7 -> 1615.7 | AC33: =4.5+9+7.1+1.9+7.6 -> 30.1 | AD33: =292.9+1034.6+547.4+102.6+992.6 -> 2970.1 | AE33: =84.7+73.1+46.8+38.1+205.7 -> 448.4 | AF33: =25+57.2+49.8+151.2+36.3+83.7+10.4+24.7+40.6+67 -> 545.9 | AG33: =63.3+40.3+28.1+32.7+60.3 -> 224.7 | AH33: =63.3+35.8+25+32.3+30.2 -> 186.6 | AI33: =70.8+44.9+31.4+34.2+34.3 -> 215.6 | AJ33: =40.9+95.6+30+120.9+20.5+65.2+20+45.1+30.9+76.8 -> 545.9 | AK33: 0 | AL33: =3927.6+1996.7+1249+1753+279.6 -> 9205.9 | AM33: =0.3+0.1+0.1+0.2+7.1 -> 7.8 | AN33: 0.1 | AO33: =1191.2+231+202.6+598.2+308.9 -> 2531.9 | AP33: =-1034+276.2+332.1+654.1+87.6 -> 316 | AQ33: =374.1+68.8+181+6.8+5.4 -> 636.1 | AR33: =4706.2+1724.6+1965.7+14.2+67.5 -> 8478.2 | AS33: =2393.5+2708.3+11912.4+13749.2+1316.9 -> 32080.3 | AT33: =-4656.3+-1227.2+-1495+-1421.5+-1087 -> -9887 | AU33: =SUM(B33:AN33) -> 41340.2
A34: TTL_55T56: Accomodation and food services | B34: 0.2 | C34: 0 | D34: 0 | E34: 0.1 | F34: 9.7 | G34: 2.7 | H34: 1.3 | I34: 5.5 | J34: 0 | K34: 0.1 | L34: 0 | M34: 0.1 | N34: 0.2 | O34: 0 | P34: 0 | Q34: 0.1 | R34: 0.1 | S34: 0 | T34: 0 | U34: 0.1 | V34: =4.9+7.3 -> 12.2 | W34: 11.7 | X34: 129.3 | Y34: =16.5+44.3+11.1+33.1+10.7 -> 115.7 | Z34: 72.5 | AA34: 16.9 | AB34: 32.9 | AC34: 2.5 | AD34: 214.8 | AE34: 96.2 | AF34: =10.3+16.5 -> 26.8 | AG34: 14 | AH34: 33.1 | AI34: 19.9 | AJ34: 00=8.4+24.4 | AK34: 0 | AL34: 4944.9 | AM34: 0 | AN34: 0 | AO34: 25.5 | AP34: 4.6 | AQ34: 1302.9 | AR34: 14832.2 | AS34: 0 | AT34: -1329.3 | AU34: =SUM(B34:AN34) -> 5763.6
A35: TTL_58T60: Publishing, audiovisual and broadcasting activities | B35: =2.1+0.2 -> 2.3 | C35: 0 | D35: 0 | E35: 0.1 | F35: 56.1 | G35: 15.6 | H35: 1.4 | I35: 21.5 | J35: 0.2 | K35: =0.6+0.3 -> 0.9 | L35: 0 | M35: 0.8 | N35: 2.2 | O35: 0.2 | P35: 1 | Q35: 1.6 | R35: 0.7 | S35: 0.4 | T35: 0.1 | U35: 0.3 | V35: =12.2+7.8 -> 20 | W35: 78 | X35: 430.3 | Y35: =44.5+66.3+69.3+70.6+19.6 -> 270.3 | Z35: 28.3 | AA35: 431.7 | AB35: 136.5 | AC35: 4.6 | AD35: 460.8 | AE35: 258.3 | AF35: =62.1+21.2 -> 83.3 | AG35: 22.2 | AH35: 37.5 | AI35: 111 | AJ35: =74.7+36.6 -> 111.3 | AK35: 0 | AL35: 1190.7 | AM35: 4.1 | AN35: 0.1 | AO35: 194.9 | AP35: 12.9 | AQ35: 21.7 | AR35: 114.3 | AS35: 3613.2 | AT35: -1908.6 | AU35: =SUM(B35:AN35) -> 3784.4
A36: TTL_61: Telecommunications | B36: =0.7+0.1 -> 0.8 | C36: 0 | D36: 0 | E36: 0.1 | F36: 68.7 | G36: 20.4 | H36: 9.9 | I36: 40.1 | J36: 0 | K36: =0.2+0.2 -> 0.4 | L36: 0 | M36: 0.2 | N36: 1.4 | O36: 0.2 | P36: 0.4 | Q36: 0.5 | R36: 0.4 | S36: 0.2 | T36: 0.1 | U36: 0.1 | V36: =16.5+38.6 -> 55.1 | W36: 62.8 | X36: 1284.1 | Y36: =84.6+1281+185.3+159.5+60.6 -> 1771 | Z36: 95.1 | AA36: 134.6 | AB36: 1340.8 | AC36: 31.5 | AD36: 2217.2 | AE36: 567.7 | AF36: =104.5+145.6 -> 250.1 | AG36: 119.1 | AH36: 76.9 | AI36: 111 | AJ36: =87.3+149.7 -> 237 | AK36: 0 | AL36: 1842.2 | AM36: 7.9 | AN36: 0 | AO36: 306.2 | AP36: 161.7 | AQ36: 84.7 | AR36: 1251 | AS36: 4880.9 | AT36: -352.5 | AU36: =SUM(B36:AN36) -> 10348
A37: TTL_62T63: IT and other information services | B37: 0.4 | C37: 0 | D37: 0 | E37: 0.1 | F37: 35.2 | G37: 12.2 | H37: 4.7 | I37: 26.1 | J37: 0 | K37: =0.3+0.2 -> 0.5 | L37: 0 | M37: 0.2 | N37: 2.6 | O37: 0.2 | P37: 0.5 | Q37: 0.7 | R37: 0.3 | S37: 0.4 | T37: 0.2 | U37: 0.1 | V37: =8.3+10.2 -> 18.5 | W37: 24 | X37: 567.6 | Y37: =43.7+37.6+70+84.4+37.7 -> 273.4 | Z37: 34.8 | AA37: 42.4 | AB37: 217.3 | AC37: 25.1 | AD37: 966.5 | AE37: 233.6 | AF37: =24.4+17.6 -> 42 | AG37: 79.8 | AH37: 42 | AI37: 35.1 | AJ37: =23.9+34.1 -> 58 | AK37: 0 | AL37: 98.2 | AM37: 0 | AN37: 0.1 | AO37: 408.3 | AP37: 70.1 | AQ37: 1.9 | AR37: 15.6 | AS37: 2128.6 | AT37: -921.1 | AU37: =SUM(B37:AN37) -> 2842.8
A38: TTL_64T66: Financial and insurance activities | B38: =1.1+0.1 -> 1.2 | C38: 0 | D38: 0 | E38: 0.1 | F38: 421.4 | G38: 108.9 | H38: 45.3 | I38: 350.3 | J38: 0.4 | K38: =1.1+0.6 -> 1.7 | L38: 0 | M38: 1.3 | N38: 12 | O38: 1.2 | P38: 1 | Q38: 2 | R38: 1.2 | S38: 0.8 | T38: 0.3 | U38: 0.6 | V38: =286.1+238.2 -> 524.3 | W38: 253.9 | X38: 6839.4 | Y38: =629.2+920.9+301+1126+208.2 -> 3185.3 | Z38: 434.6 | AA38: 258.3 | AB38: 654.5 | AC38: 66.3 | AD38: 25577.6 | AE38: 12634.4 | AF38: =355.7+731.7 -> 1087.4 | AG38: 176.8 | AH38: 466.3 | AI38: 330.2 | AJ38: =328.9+836.1 -> 1165 | AK38: 0 | AL38: 22484.8 | AM38: 0 | AN38: 371.8 | AO38: 497.7 | AP38: 4729.6 | AQ38: 70.5 | AR38: 1071.6 | AS38: 41690.4 | AT38: -2972.6 | AU38: =SUM(B38:AN38) -> 77460.6
A39: TTL_68: Real estate activities | B39: =1.2+0.1 -> 1.3 | C39: 0 | D39: 0 | E39: 0.1 | F39: 90.6 | G39: 44 | H39: 13.3 | I39: 76 | J39: 0.1 | K39: =0.2+0.1 -> 0.3 | L39: 0 | M39: 0.6 | N39: 4.2 | O39: 0.6 | P39: 0.7 | Q39: 1.2 | R39: 0.8 | S39: 0.6 | T39: 0.2 | U39: 0.4 | V39: =95.1+305.7 -> 400.8 | W39: 185.2 | X39: 6898.8 | Y39: =278.5+170+219.5+2384+104.5 -> 3156.5 | Z39: 1391.8 | AA39: 403 | AB39: 392.3 | AC39: 58.3 | AD39: 4381.8 | AE39: 4338.3 | AF39: =281.5+509.8 -> 791.3 | AG39: 77.7 | AH39: 303.2 | AI39: 524.7 | AJ39: =616.5+1577.2 -> 2193.7 | AK39: 0 | AL39: 45769.3 | AM39: 0 | AN39: 0.1 | AO39: 6134.7 | AP39: 4.7 | AQ39: 229.3 | AR39: 3510.3 | AS39: 41.9 | AT39: -395.1 | AU39: =SUM(B39:AN39) -> 71501.8
A40: TTL_69T82: Other business sector services | B40: =3.1+0.3+1.1+0.1 -> 4.6 | C40: 0 | D40: 0 | E40: =4.6+1.4 -> 6 | F40: =207.4+63.2 -> 270.6 | G40: =58.1+17.2 -> 75.3 | H40: =36.2+13.2 -> 49.4 | I40: =183.2+59.5 -> 242.7 | J40: =0.2+0.1 -> 0.3 | K40: =1+1.2+0.3+0.2 -> 2.7 | L40: 0 | M40: =0.6+0.2 -> 0.8 | N40: =4.4+1.9 -> 6.3 | O40: =0.5+0.2 -> 0.7 | P40: =1.4+0.3 -> 1.7 | Q40: =2.7+0.6 -> 3.3 | R40: =1.7+0.4 -> 2.1 | S40: =1.8+0.4 -> 2.2 | T40: =0.6+0.1 -> 0.7 | U40: =1.1+0.8 -> 1.9 | V40: =45.7+82.8+14.6+37.6 -> 180.7 | W40: =238.6+62 -> 300.6 | X40: =3920.9+1506.9 -> 5427.8 | Y40: =220.2+208.5+279.9+399.6+112.8+167.2+212+252.5+245.6+113.4 -> 2211.7 | Z40: =210.5+86.1 -> 296.6 | AA40: =169.2+122.1 -> 291.3 | AB40: =599.6+346.7 -> 946.3 | AC40: =46.3+16.6 -> 62.9 | AD40: =3109.4+1132.7 -> 4242.1 | AE40: =1710+694.3 -> 2404.3 | AF40: =488.7+96.2 -> 584.9 | AG40: =409.8+124.8 -> 534.6 | AH40: =209.1+95.6 -> 304.7 | AI40: =301.4+152.1 -> 453.5 | AJ40: =167.1+235+87.6+88 -> 577.7 | AK40: 0 | AL40: =525.5+187.8 -> 713.3 | AM40: =7.8 -> 7.8 | AN40: =348.2+0.1 -> 348.3 | AO40: =2565+91 -> 2656 | AP40: =97.9+59.5 -> 157.4 | AQ40: =32.9+73 -> 105.9 | AR40: =541.9+1088.8 -> 1630.7 | AS40: =2254.3+1482.5 -> 3736.8 | AT40: =-967+-91.6 -> -1058.6 | AU40: =SUM(B40:AN40) -> 20560.4
...

Sheet OECD Data IO Table - Total (USD
D1: =DotStatQuery(#REF!) -> #NAME?
D2: To Sector | E2: =INDEX('OECD Crosswalk'!$B$2:$B$90,MATCH('OECD Data IO Table - Total (USD'!E8,'OECD Crosswalk'!$A$2:$A$90,0),1) -> nonenergy industries | F2: =INDEX('OECD Crosswalk'!$B$2:$B$90,MATCH('OECD Data IO Table - Total (USD'!F8,'OECD Crosswalk'!$A$2:$A$90,0),1) -> natural gas and petroleum suppliers | G2: =INDEX('OECD Crosswalk'!$B$2:$B$90,MATCH('OECD Data IO Table - Total (USD'!G8,'OECD Crosswalk'!$A$2:$A$90,0),1) -> nonenergy industries | H2: =INDEX('OECD Crosswalk'!$B$2:$B$90,MATCH('OECD Data IO Table - Total (USD'!H8,'OECD Crosswalk'!$A$2:$A$90,0),1) -> nonenergy industries | I2: =INDEX('OECD Crosswalk'!$B$2:$B$90,MATCH('OECD Data IO Table - Total (USD'!I8,'OECD Crosswalk'!$A$2:$A$90,0),1) -> nonenergy industries | J2: =INDEX('OECD Crosswalk'!$B$2:$B$90,MATCH('OECD Data IO Table - Total (USD'!J8,'OECD Crosswalk'!$A$2:$A$90,0),1) -> nonenergy industries | K2: =INDEX('OECD Crosswalk'!$B$2:$B$90,MATCH('OECD Data IO Table - Total (USD'!K8,'OECD Crosswalk'!$A$2:$A$90,0),1) -> nonenergy industries | L2: =INDEX('OECD Crosswalk'!$B$2:$B$90,MATCH('OECD Data IO Table - Total (USD'!L8,'OECD Crosswalk'!$A$2:$A$90,0),1) -> nonenergy industries | ... AW2: =INDEX('OECD Crosswalk'!$B$2:$B$90,MATCH('OECD Data IO Table - Total (USD'!AW8,'OECD Crosswalk'!$A$2:$A$90,0),1) -> imports
D3: From Sector | E3: =INDEX('OECD Crosswalk'!$C$2:$C$90,MATCH('OECD Data IO Table - Total (USD'!E8,'OECD Crosswalk'!$A$2:$A$90,0),1) -> agriculture | F3: =INDEX('OECD Crosswalk'!$C$2:$C$90,MATCH('OECD Data IO Table - Total (USD'!F8,'OECD Crosswalk'!$A$2:$A$90,0),1) -> other industries | G3: =INDEX('OECD Crosswalk'!$C$2:$C$90,MATCH('OECD Data IO Table - Total (USD'!G8,'OECD Crosswalk'!$A$2:$A$90,0),1) -> other industries | H3: =INDEX('OECD Crosswalk'!$C$2:$C$90,MATCH('OECD Data IO Table - Total (USD'!H8,'OECD Crosswalk'!$A$2:$A$90,0),1) -> other industries | I3: =INDEX('OECD Crosswalk'!$C$2:$C$90,MATCH('OECD Data IO Table - Total (USD'!I8,'OECD Crosswalk'!$A$2:$A$90,0),1) -> other industries | J3: =INDEX('OECD Crosswalk'!$C$2:$C$90,MATCH('OECD Data IO Table - Total (USD'!J8,'OECD Crosswalk'!$A$2:$A$90,0),1) -> other industries | K3: =INDEX('OECD Crosswalk'!$C$2:$C$90,MATCH('OECD Data IO Table - Total (USD'!K8,'OECD Crosswalk'!$A$2:$A$90,0),1) -> other industries | L3: =INDEX('OECD Crosswalk'!$C$2:$C$90,MATCH('OECD Data IO Table - Total (USD'!L8,'OECD Crosswalk'!$A$2:$A$90,0),1) -> other industries | ... AW3: =INDEX('OECD Crosswalk'!$C$2:$C$90,MATCH('OECD Data IO Table - Total (USD'!AW8,'OECD Crosswalk'!$A$2:$A$90,0),1) -> 0
D4: Variable | E4: TTL: Total
D5: Country | E5: HKG: Hong Kong, China
D6: Time | E6: 2021
D7: Unit | E7: US Dollar, Millions
D8: To: (sector in column) | E8: D01T03: Agriculture, forestry and fishing | F8: D05T06: Mining and extraction of energy producing products | G8: D07T08: Mining and quarrying of non-energy producing products | H8: D09: Mining support service activities | I8: D10T12: Food products, beverages and tobacco | J8: D13T15: Textiles, wearing apparel, leather and related products | K8: D16: Wood and products of wood and cork | L8: D17T18: Paper products and printing | M8: D19: Coke and refined petroleum products | N8: D20T21: Chemicals and pharmaceutical products | O8: D22: Rubber and plastic products | P8: D23: Other non-metallic mineral products | Q8: D24: Basic metals | R8: D25: Fabricated metal products | S8: D26: Computer, electronic and optical products | T8: D27: Electrical equipment | U8: D28: Machinery and equipment, nec | V8: D29: Motor vehicles, trailers and semi-trailers | W8: D30: Other transport equipment | X8: D31T33: Other manufacturing; repair and installation of machinery and equipment | Y8: D35T39: Electricity, gas, water supply, sewerage, waste and remediation services | Z8: D41T43: Construction | AA8: D45T47: Wholesale and retail trade; repair of motor vehicles | AB8: D49T53: Transportation and storage | AC8: D55T56: Accomodation and food services | AD8: D58T60: Publishing, audiovisual and broadcasting activities | AE8: D61: Telecommunications | AF8: D62T63: IT and other information services | AG8: D64T66: Financial and insurance activities | AH8: D68: Real estate activities | AI8: D69T82: Other business sector services | AJ8: D84: Public admin. and defence; compulsory social security | AK8: D85: Education | AL8: D86T88: Human health and social work | AM8: D90T96: Arts, entertainment, recreation and other service activities | AN8: D97T98: Private households with employed persons | AO8: HFCE: Final consumption expenditure of households | AP8: NPISH: Final consumption expenditure of non-profit institutions serving households | AQ8: GGFC: Final consumption expenditure of general government | AR8: GFCF: Gross Fixed Capital Formation | AS8: INVNT: Changes in inventories | AT8: CONS_ABR: Direct purchases abroad by residents (imports) | AU8: CONS_NONRES: Direct purchases by non-residents (exports) | AV8: EXPO: Exports (cross border) | AW8: IMPO: Imports (cross border) | AX8: Totals
A9: From Sector | B9: To Sector | D9: From: (sector in row)
A10: =INDEX('OECD Crosswalk'!$C$2:$C$90,MATCH('OECD Data IO Table - Total (USD'!D10,'OECD Crosswalk'!$A$2:$A$90,0),1) -> agriculture | B10: =INDEX('OECD Crosswalk'!$B$2:$B$90,MATCH('OECD Data IO Table - Total (USD'!D10,'OECD Crosswalk'!$A$2:$A$90,0),1) -> nonenergy industries | D10: TTL_01T03: Agriculture, forestry and fishing | E10: =0.9+0.1+0.1 -> 1.1 | F10: 0 | G10: 0 | H10: 0.0012333592 | I10: =154.9+4.4 -> 159.3 | J10: =1.6+0.2 -> 1.8 | K10: =0.5+0.1 -> 0.6 | L10: =2.5+0.6 -> 3.1 | M10: 0 | N10: =0.3+0.2 -> 0.5 | O10: 0 | P10: 0.1 | Q10: 0.4 | R10: 0 | S10: 0.1 | T10: 0.1 | U10: 0.1 | V10: 0.1 | W10: 1.6348852e-05 | X10: 0 | Y10: =43.7+16.7+5.3+2.2 -> 67.9 | Z10: =7.9+1.3 -> 9.2 | AA10: =44.4+3.5 -> 47.9 | AB10: =34.6+141.9+255+6.8+4+4.4+37.6+62.6+1.3+1.1 -> 549.3 | AC10: =453.1+91.4 -> 544.5 | AD10: =3.6+1 -> 4.6 | AE10: =8.3+1.8 -> 10.1 | AF10: 0.2 | AG10: =8.6+1.5 -> 10.1 | AH10: =2.9+0.4 -> 3.3 | AI10: =2+5.2+0.3+0.6 -> 8.1 | AJ10: =7.1+0.7 -> 7.8 | AK10: =11.8+1.3 -> 13.1 | AL10: =19.4+1.6 -> 21 | AM10: =13+2.4+19.7+3.5 -> 38.6 | AN10: 0 | AO10: =4367.1+711.7 -> 5078.8 | AP10: 0.1 | AQ10: 0 | AR10: =3.2+0.3 -> 3.5 | AS10: =10.3+0.3 -> 10.6 | AT10: =33.6+2.6 -> 36.2 | AU10: =1.1+2.5 -> 3.6 | AV10: =4.5+7.5 -> 12 | AW10: =-5242.7+-891.3 -> -6134 | AX10: =SUM(E10:AQ10) -> 6581.9012
A11: =INDEX('OECD Crosswalk'!$C$2:$C$90,MATCH('OECD Data IO Table - Total (USD'!D11,'OECD Crosswalk'!$A$2:$A$90,0),1) -> other industries | B11: =INDEX('OECD Crosswalk'!$B$2:$B$90,MATCH('OECD Data IO Table - Total (USD'!D11,'OECD Crosswalk'!$A$2:$A$90,0),1) -> natural gas and petroleum suppliers | D11: TTL_05T06: Mining and extraction of energy producing products | E11: =15.7+1.5 -> 17.2 | F11: 0 | G11: 0 | H11: 169.3 | I11: 167.3 | J11: 136.5 | K11: 8.7 | L11: 91.6 | M11: 18.1 | N11: =0.6+0.1 -> 0.7 | O11: 0 | P11: 1.4 | Q11: 43.7 | R11: 2.2 | S11: 4.1 | T11: 11.9 | U11: 8.1 | V11: 2.6 | W11: 1.7 | X11: 9.7 | Y11: =54.1+30.2 -> 84.3 | Z11: 3.8 | AA11: 22.3 | AB11: =129.4+1.9+39.4+1601.3+9.5 -> 1781.5 | AC11: 6 | AD11: 3.2 | AE11: 12.7 | AF11: 4.1 | AG11: 44.4 | AH11: 11.6 | AI11: =27.1+84.5 -> 111.6 | AJ11: 7.7 | AK11: 30.2 | AL11: 16.2 | AM11: =14.1+22.3 -> 36.4 | AN11: 0 | AO11: 37.1 | AP11: 0.6 | AQ11: 0 | AR11: 3.7 | AS11: 31.4 | AT11: 0.4 | AU11: 0 | AV11: 0 | AW11: -2952.4 | AX11: =SUM(E11:AQ11) -> 2908.5
A12: =INDEX('OECD Crosswalk'!$C$2:$C$90,MATCH('OECD Data IO Table - Total (USD'!D12,'OECD Crosswalk'!$A$2:$A$90,0),1) -> other industries | B12: =INDEX('OECD Crosswalk'!$B$2:$B$90,MATCH('OECD Data IO Table - Total (USD'!D12,'OECD Crosswalk'!$A$2:$A$90,0),1) -> nonenergy industries | D12: TTL_07T08: Mining and quarrying of non-energy producing products | E12: =3.1+0.4 -> 3.5 | F12: 0 | G12: 0 | H12: 38.7 | I12: 20.2 | J12: 17.4 | K12: 1.3 | L12: 9.9 | M12: 0.5 | N12: =0.2+0.1 -> 0.3 | O12: 0 | P12: 0.9 | Q12: 10.1 | R12: 0.6 | S12: 0.7 | T12: 2.4 | U12: 1.6 | V12: 0.4 | W12: 0.3 | X12: 1.7 | Y12: =4.2+4 -> 8.2 | Z12: 2.1 | AA12: 3.7 | AB12: =18.8+0.2+4.8+288.2+0.9 -> 312.9 | AC12: 0.8 | AD12: 800.1 | AE12: 1.6 | AF12: 0.5 | AG12: 4.7 | AH12: 1.8 | AI12: =5.7+10.8 -> 16.5 | AJ12: 1.3 | AK12: 3.1 | AL12: 1.7 | AM12: =1.9+3 -> 4.9 | AN12: 0 | AO12: 6.1 | AP12: 0 | AQ12: 0 | AR12: 1 | AS12: 1.1 | AT12: 0.4 | AU12: 0 | AV12: 0 | AW12: -481.4 | AX12: =SUM(E12:AQ12) -> 1280.5
A13: =INDEX('OECD Crosswalk'!$C$2:$C$90,MATCH('OECD Data IO Table - Total (USD'!D13,'OECD Crosswalk'!$A$2:$A$90,0),1) -> other industries | B13: =INDEX('OECD Crosswalk'!$B$2:$B$90,MATCH('OECD Data IO Table - Total (USD'!D13,'OECD Crosswalk'!$A$2:$A$90,0),1) -> nonenergy industries | D13: TTL_09: Mining support service activities | E13: =61.5+20.9 -> 82.4 | F13: 0 | G13: 0 | H13: 6150 | I13: 152.1 | J13: 30.3 | K13: 37.1 | L13: 141.9 | M13: 2.4 | N13: =0.5 -> 0.5 | O13: 0 | P13: 1.1 | Q13: 131.8 | R13: 6.1 | S13: 2 | T13: 5.3 | U13: 22.1 | V13: 2 | W13: 1.1 | X13: 0.2 | Y13: =52.3+30.2 -> 82.5 | Z13: 10.6 | AA13: 26.6 | AB13: =317.8+2.7+174+48.2+55.1 -> 597.8 | AC13: 3.5 | AD13: 3.2 | AE13: 0 | AF13: 1.6 | AG13: 190.1 | AH13: 50.8 | AI13: =120.1+41.2 -> 161.3 | AJ13: 20.2 | AK13: 83.8 | AL13: 0.6 | AM13: =6.4+18 -> 24.4 | AN13: 0 | AO13: 6.2 | AP13: 0 | AQ13: 0 | AR13: 1.2 | AS13: 1.1 | AT13: 0.1 | AU13: 0 | AV13: 73.2 | AW13: -14.6 | AX13: =SUM(E13:AQ13) -> 8031.6
A14: =INDEX('OECD Crosswalk'!$C$2:$C$90,MATCH('OECD Data IO Table - Total (USD'!D14,'OECD Crosswalk'!$A$2:$A$90,0),1) -> other industries | B14: =INDEX('OECD Crosswalk'!$B$2:$B$90,MATCH('OECD Data IO Table - Total (USD'!D14,'OECD Crosswalk'!$A$2:$A$90,0),1) -> nonenergy industries | D14: TTL_10T12: Food products, beverages and tobacco | E14: =11.3+0.9 -> 12.2 | F14: 0 | G14: 0 | H14: 0.1 | I14: 539.2 | J14: 78.2 | K14: 53.8 | L14: 396.1 | M14: 2.8 | N14: =19.7+10.5 -> 30.2 | O14: 0 | P14: 3.2 | Q14: 20.7 | R14: 1.7 | S14: 2.8 | T14: 4.8 | U14: 3.2 | V14: 1.5 | W14: 0.6 | X14: 0.5 | Y14: =255.9+134.1 -> 390 | Z14: 848.3 | AA14: 801 | AB14: =295.2+974+907.2+327.5+153.3 -> 2657.2 | AC14: 1390.5 | AD14: 800.1 | AE14: 197.8 | AF14: 9.7 | AG14: 595.1 | AH14: 216.6 | AI14: =66.2+113.4 -> 179.6 | AJ14: 75.2 | AK14: 93.8 | AL14: 418.3 | AM14: =106.5+249.3 -> 355.8 | AN14: 0 | AO14: 11837.5 | AP14: 0 | AQ14: 0 | AR14: 244.1 | AS14: 3599.6 | AT14: 148.6 | AU14: 219.5 | AV14: 380.6 | AW14: -17148.7 | AX14: =SUM(E14:AQ14) -> 22018.1
A15: =INDEX('OECD Crosswalk'!$C$2:$C$90,MATCH('OECD Data IO Table - Total (USD'!D15,'OECD Crosswalk'!$A$2:$A$90,0),1) -> other industries | B15: =INDEX('OECD Crosswalk'!$B$2:$B$90,MATCH('OECD Data IO Table - Total (USD'!D15,'OECD Crosswalk'!$A$2:$A$90,0),1) -> nonenergy industries | D15: TTL_13T15: Textiles, wearing apparel, leather and related products | E15: =0.5+0.1 -> 0.6 | F15: 0 | G15: 0 | H15: 0.2 | I15: 22.7 | J15: 642.5 | K15: 2.8 | L15: 30.9 | M15: 0.1 | N15: =0.7+0.3 -> 1 | O15: 0 | P15: 0.6 | Q15: 2.5 | R15: 0.3 | S15: 0.3 | T15: 0.6 | U15: 0.4 | V15: 0.8 | W15: 0.2 | X15: 0.7 | Y15: =13.3+21 -> 34.3 | Z15: 15.2 | AA15: 320.4 | AB15: =129+151.7+110.9+152.1+80.8 -> 624.5 | AC15: 11.8 | AD15: 3.2 | AE15: 86.1 | AF15: 3.9 | AG15: 312.3 | AH15: 117.6 | AI15: =28.7+60.6 -> 89.3 | AJ15: 35.2 | AK15: 23.1 | AL15: 32.3 | AM15: =20+106.4 -> 126.4 | AN15: 0 | AO15: 9666.4 | AP15: 0 | AQ15: 0 | AR15: 62.4 | AS15: 1918.5 | AT15: 94 | AU15: 19.7 | AV15: 389.1 | AW15: -11723.4 | AX15: =SUM(E15:AQ15) -> 12209.2
A16: =INDEX('OECD Crosswalk'!$C$2:$C$90,MATCH('OECD Data IO Table - Total (USD'!D16,'OECD Crosswalk'!$A$2:$A$90,0),1) -> other industries | B16: =INDEX('OECD Crosswalk'!$B$2:$B$90,MATCH('OECD Data IO Table - Total (USD'!D16,'OECD Crosswalk'!$A$2:$A$90,0),1) -> nonenergy industries | D16: TTL_16: Wood and of products of wood and cork (except furniture) | E16: =2+0.1 -> 2.1 | F16: 0 | G16: 0 | H16: 0.1 | I16: 25.5 | J16: 0.2 | K16: 0 | L16: 0.2 | M16: 0 | N16: 0.1 | O16: 0 | P16: 0.1 | Q16: 0.9 | R16: 0.1 | S16: 0.1 | T16: 0.2 | U16: 0.1 | V16: 0.2 | W16: 0.1 | X16: 0.1 | Y16: =1.8+1.9 -> 3.7 | Z16: 113.8 | AA16: 12.2 | AB16: =19.9+83.6+12.7+34.4+3.1 -> 153.7 | AC16: 1.4 | AD16: 800.1 | AE16: 4.7 | AF16: 0 | AG16: 10.6 | AH16: 3.1 | AI16: =0.9+1.2 -> 2.1 | AJ16: 1.1 | AK16: 1.3 | AL16: 28.4 | AM16: =2.3+3.6 -> 5.9 | AN16: 0 | AO16: 565.3 | AP16: 0 | AQ16: 0 | AR16: 66.4 | AS16: 334.4 | AT16: 6.2 | AU16: 0.2 | AV16: 26 | AW16: -626.1 | AX16: =SUM(E16:AQ16) -> 1737.5
A17: =INDEX('OECD Crosswalk'!$C$2:$C$90,MATCH('OECD Data IO Table - Total (USD'!D17,'OECD Crosswalk'!$A$2:$A$90,0),1) -> other industries | B17: =INDEX('OECD Crosswalk'!$B$2:$B$90,MATCH('OECD Data IO Table - Total (USD'!D17,'OECD Crosswalk'!$A$2:$A$90,0),1) -> nonenergy industries | D17: TTL_17T18: Paper products and printing | E17: =9.6+1 -> 10.6 | F17: 0 | G17: 0 | H17: 0.1 | I17: 751.4 | J17: 175.7 | K17: 5.3 | L17: 796.5 | M17: 0.3 | N17: =3.2+2.7 -> 5.9 | O17: 0 | P17: 10 | Q17: 6 | R17: 0.8 | S17: 4.5 | T17: 10 | U17: 3.4 | V17: 1.3 | W17: 0.3 | X17: 3.3 | Y17: =16.3+20.7 -> 37 | Z17: 449.8 | AA17: 427.7 | AB17: =117.7+176.3+82.9+171.8+54.5 -> 603.2 | AC17: 5.2 | AD17: 3.2 | AE17: 59.7 | AF17: 2.7 | AG17: 351.9 | AH17: 89.7 | AI17: =24.6+29.4 -> 54 | AJ17: 16.4 | AK17: 39.5 | AL17: 334 | AM17: =24+41.4 -> 65.4 | AN17: 0 | AO17: 1557.3 | AP17: 0 | AQ17: 0 | AR17: 18.8 | AS17: 234 | AT17: 17 | AU17: 74.7 | AV17: 124.2 | AW17: -1724.9 | AX17: =SUM(E17:AQ17) -> 5882.1
A18: =INDEX('OECD Crosswalk'!$C$2:$C$90,MATCH('OECD Data IO Table - Total (USD'!D18,'OECD Crosswalk'!$A$2:$A$90,0),1) -> natural gas and petroleum systems | B18: =INDEX('OECD Crosswalk'!$B$2:$B$90,MATCH('OECD Data IO Table - Total (USD'!D18,'OECD Crosswalk'!$A$2:$A$90,0),1) -> natural gas and petroleum suppliers | D18: TTL_19: Coke and refined petroleum products | E18: =1+0.1 -> 1.1 | F18: 0 | G18: 0 | H18: 15.7 | I18: 11.7 | J18: 3.1 | K18: 2.1 | L18: 11.4 | M18: 74.9 | N18: =119.6+20.8 -> 140.4 | O18: 0 | P18: 52.8 | Q18: 667.4 | R18: 48.7 | S18: 4.8 | T18: 15.9 | U18: 9.3 | V18: 10.4 | W18: 3.5 | X18: 6.1 | Y18: =84.7+55.8 -> 140.5 | Z18: 4 | AA18: 4405.8 | AB18: =293.6+671.7+606.3+737.5+45.6 -> 2354.7 | AC18: 15 | AD18: 800.1 | AE18: 40.7 | AF18: 3.9 | AG18: 535 | AH18: 134.4 | AI18: =23.7+97.7 -> 121.4 | AJ18: 253.3 | AK18: 116.1 | AL18: 20.1 | AM18: =29.2+62.4 -> 91.6 | AN18: 0 | AO18: 3345.6 | AP18: 0 | AQ18: 0 | AR18: 12.6 | AS18: 1096.6 | AT18: 63.2 | AU18: 69 | AV18: 33.1 | AW18: -13543.9 | AX18: =SUM(E18:AQ18) -> 13461.5
A19: =INDEX('OECD Crosswalk'!$C$2:$C$90,MATCH('OECD Data IO Table - Total (USD'!D19,'OECD Crosswalk'!$A$2:$A$90,0),1) -> chemicals | B19: =INDEX('OECD Crosswalk'!$B$2:$B$90,MATCH('OECD Data IO Table - Total (USD'!D19,'OECD Crosswalk'!$A$2:$A$90,0),1) -> nonenergy industries | D19: TTL_20T21: Chemicals and pharmaceutical products | E19: =2.1+0.1+0.1 -> 2.3 | F19: 0 | G19: 0 | H19: =11.5+0.1 -> 11.6 | I19: =32.9+2.4 -> 35.3 | J19: =3.1+22 -> 25.1 | K19: =11.5+0.4 -> 11.9 | L19: =93.6+2.1 -> 95.7 | M19: =27.4+0.7 -> 28.1 | N19: =289.4+68.9+7.7+55.8 -> 421.8 | O19: 0 | P19: =76.4+1.6 -> 78 | Q19: =197.6+667.4 -> 865 | R19: =18.5+0.5 -> 19 | S19: =37+1.5 -> 38.5 | T19: =106.2+2.1 -> 108.3 | U19: =28.2+0.9 -> 29.1 | V19: =20.4+0.5 -> 20.9 | W19: =6.1+0.2 -> 6.3 | X19: =12.1+0.2 -> 12.3 | Y19: =12.5+158.3+0.6+4.8 -> 176.2 | Z19: =7+0.8 -> 7.8 | AA19: =764.3+51 -> 815.3 | AB19: =16.8+34.7+30.3+104+13+0.9+2.9+2.9+4.9+1.1 -> 211.5 | AC19: =23.4+2 -> 25.4 | AD19: =68.6+1.7 -> 70.3 | AE19: =21.5+2 -> 23.5 | AF19: =1.7+0.1 -> 1.8 | AG19: =125.9+9.8 -> 135.7 | AH19: =54+2.7 -> 56.7 | AI19: =19.7+46.6+2.8+1.7 -> 70.8 | AJ19: =78+14.6 -> 92.6 | AK19: =202.3+21.7 -> 224 | AL19: =87.8+75.7 -> 163.5 | AM19: =79.1+9.8+267.1+12.6 -> 368.6 | AN19: 0 | AO19: =3025.1+1373.4 -> 4398.5 | AP19: 0 | AQ19: =0.2+0.2 -> 0.4 | AR19: =127.2+30.4 -> 157.6 | AS19: =899.5+349.2 -> 1248.7 | AT19: =23.6+18.4 -> 42 | AU19: =6.1+44.5 -> 50.6 | AV19: =333.9+161.6 -> 495.5 | AW19: =-6496.9-1813.5 -> -8310.4 | AX19: =SUM(E19:AQ19) -> 8651.8
A20: =INDEX('OECD Crosswalk'!$C$2:$C$90,MATCH('OECD Data IO Table - Total (USD'!D20,'OECD Crosswalk'!$A$2:$A$90,0),1) -> other industries | B20: =INDEX('OECD Crosswalk'!$B$2:$B$90,MATCH('OECD Data IO Table - Total (USD'!D20,'OECD Crosswalk'!$A$2:$A$90,0),1) -> nonenergy industries | D20: TTL_22: Rubber and plastics products | E20: 0.2 | F20: 0 | G20: 0 | H20: 1.4 | I20: 49.5 | J20: 5.7 | K20: 1.7 | L20: 21.7 | M20: 2.3 | N20: =19.8+12.8 -> 32.6 | O20: 0 | P20: 15.7 | Q20: 41.9 | R20: 7.3 | S20: 28.6 | T20: 83.7 | U20: 30.4 | V20: 82.5 | W20: 15.9 | X20: 10.9 | Y20: =2.4+34 -> 36.4 | Z20: 2.4 | AA20: 2002.7 | AB20: =17.9+2.3+2.4+14.1+3.3 -> 40 | AC20: 7 | AD20: 14.4 | AE20: 5 | AF20: 0.2 | AG20: 14.1 | AH20: 29.8 | AI20: =1.6+3.5 -> 5.1 | AJ20: 6.7 | AK20: 2.1 | AL20: 2.2 | AM20: =15.1+38.2 -> 53.3 | AN20: 0 | AO20: 326 | AP20: 0 | AQ20: 0.1 | AR20: 43.5 | AS20: 40.4 | AT20: 0.5 | AU20: 0 | AV20: 0 | AW20: -3064 | AX20: =SUM(E20:AQ20) -> 2979.5
A21: =INDEX('OECD Crosswalk'!$C$2:$C$90,MATCH('OECD Data IO Table - Total (USD'!D21,'OECD Crosswalk'!$A$2:$A$90,0),1) -> Cement and other carbonate use | B21: =INDEX('OECD Crosswalk'!$B$2:$B$90,MATCH('OECD Data IO Table - Total (USD'!D21,'OECD Crosswalk'!$A$2:$A$90,0),1) -> nonenergy industries | D21: TTL_23: Other non-metallic mineral products | E21: 0.1 | F21: 0 | G21: 0 | H21: 4.4 | I21: 41.4 | J21: 1.6 | K21: 1.4 | L21: 5.3 | M21: 14 | N21: =11.9+8.7 -> 20.6 | O21: 0 | P21: 402.6 | Q21: 451.1 | R21: 42.1 | S21: 36.3 | T21: 98.8 | U21: 19.8 | V21: 61.1 | W21: 18.4 | X21: 6 | Y21: =5.3+32 -> 37.3 | Z21: 58.7 | AA21: 183.1 | AB21: =2.6+2.7+5+26+13.2 -> 49.5 | AC21: 3.2 | AD21: 12.2 | AE21: 35.8 | AF21: 0.4 | AG21: 61.3 | AH21: 22 | AI21: =3.9+7.9 -> 11.8 | AJ21: 115.8 | AK21: 81.2 | AL21: 4.6 | AM21: =18.4+43.1 -> 61.5 | AN21: 0 | AO21: 672.5 | AP21: 0 | AQ21: 0 | AR21: 49.4 | AS21: 165.7 | AT21: 0.3 | AU21: 0 | AV21: 108.8 | AW21: -1681.9 | AX21: =SUM(E21:AQ21) -> 2635.9
A22: =INDEX('OECD Crosswalk'!$C$2:$C$90,MATCH('OECD Data IO Table - Total (USD'!D22,'OECD Crosswalk'!$A$2:$A$90,0),1) -> iron and steel | B22: =INDEX('OECD Crosswalk'!$B$2:$B$90,MATCH('OECD Data IO Table - Total (USD'!D22,'OECD Crosswalk'!$A$2:$A$90,0),1) -> nonenergy industries | D22: TTL_24: Manufacture of basic metals | E22: 0.1 | F22: 0 | G22: 0 | H22: 5.3 | I22: 10.3 | J22: 0.9 | K22: 1.7 | L22: 8.7 | M22: 5 | N22: =14.7+3.7 -> 18.4 | O22: 0 | P22: 31.6 | Q22: 5839.2 | R22: 476 | S22: 110.9 | T22: 489.7 | U22: 157.6 | V22: 52.9 | W22: 10.1 | X22: 37.9 | Y22: =6.5+87.6 -> 94.1 | Z22: 8.3 | AA22: 5508.3 | AB22: =5.3+13.1+10.3+50.1+2.9 -> 81.7 | AC22: 1.7 | AD22: 12.2 | AE22: 8.3 | AF22: 0.7 | AG22: 62 | AH22: 41 | AI22: =7.7+5.2 -> 12.9 | AJ22: 13.7 | AK22: 14.6 | AL22: 2.3 | AM22: =15.4+24.7 -> 40.1 | AN22: 0 | AO22: 158.6 | AP22: 0 | AQ22: 0.1 | AR22: 263.3 | AS22: 295.4 | AT22: 0.7 | AU22: 0 | AV22: 8466.3 | AW22: -10834.1 | AX22: =SUM(E22:AQ22) -> 13316.9
A23: =INDEX('OECD Crosswalk'!$C$2:$C$90,MATCH('OECD Data IO Table - Total (USD'!D23,'OECD Crosswalk'!$A$2:$A$90,0),1) -> other industries | B23: =INDEX('OECD Crosswalk'!$B$2:$B$90,MATCH('OECD Data IO Table - Total (USD'!D23,'OECD Crosswalk'!$A$2:$A$90,0),1) -> nonenergy industries | D23: TTL_25: Fabricated metal products, except machinery and equipment | E23: 0.1 | F23: 0 | G23: 0 | H23: 3.9 | I23: 4.7 | J23: 0.9 | K23: 1.4 | L23: 3.2 | M23: 2.6 | N23: =4+1.7 -> 5.7 | O23: 0 | P23: 13 | Q23: 275.8 | R23: 75.6 | S23: 24.8 | T23: 81.6 | U23: 58.2 | V23: 32.3 | W23: 10.7 | X23: 10 | Y23: =3.1+16.3 -> 19.4 | Z23: 6.2 | AA23: 2351.6 | AB23: =2.6+5+3.3+30+1.7 -> 42.6 | AC23: 1.6 | AD23: 6.1 | AE23: 6.9 | AF23: 0.6 | AG23: 32.2 | AH23: 31.1 | AI23: =4.4+10.3 -> 14.7 | AJ23: 13.6 | AK23: 13.1 | AL23: 1.8 | AM23: =9.7+14.1 -> 23.8 | AN23: 0 | AO23: 390.5 | AP23: 0 | AQ23: 0 | AR23: 631.1 | AS23: 230.1 | AT23: 0.5 | AU23: 0 | AV23: 335.3 | AW23: -3551.3 | AX23: =SUM(E23:AQ23) -> 3560.3
A24: =INDEX('OECD Crosswalk'!$C$2:$C$90,MATCH('OECD Data IO Table - Total (USD'!D24,'OECD Crosswalk'!$A$2:$A$90,0),1) -> other industries | B24: =INDEX('OECD Crosswalk'!$B$2:$B$90,MATCH('OECD Data IO Table - Total (USD'!D24,'OECD Crosswalk'!$A$2:$A$90,0),1) -> nonenergy industries | D24: TTL_26: Computer, electronic and optical products | E24: 0.1 | F24: 0 | G24: 0 | H24: 2 | I24: 3.9 | J24: 1.3 | K24: 0.4 | L24: 3.9 | M24: 2.9 | N24: =4.7+2.9 -> 7.6 | O24: 0 | P24: 3.9 | Q24: 20 | R24: 4.4 | S24: 384.8 | T24: 160.8 | U24: 52.9 | V24: 26 | W24: 11.7 | X24: 9.6 | Y24: =47.7+63 -> 110.7 | Z24: 2.8 | AA24: 11206.1 | AB24: =4.2+12.5+10.6+21.6+111.8 -> 160.7 | AC24: 3.3 | AD24: 134.7 | AE24: 1136.7 | AF24: 18.3 | AG24: 167.9 | AH24: 62.2 | AI24: =35.9+44.9 -> 80.8 | AJ24: 72.9 | AK24: 101.3 | AL24: 7.3 | AM24: =99.7+241.4 -> 341.1 | AN24: 0 | AO24: 9641.6 | AP24: 0 | AQ24: 0.2 | AR24: 6253.5 | AS24: 29295.1 | AT24: 28 | AU24: 0.1 | AV24: 1379.5 | AW24: -59402.6 | AX24: =SUM(E24:AQ24) -> 23944.8
A25: =INDEX('OECD Crosswalk'!$C$2:$C$90,MATCH('OECD Data IO Table - Total (USD'!D25,'OECD Crosswalk'!$A$2:$A$90,0),1) -> other industries | B25: =INDEX('OECD Crosswalk'!$B$2:$B$90,MATCH('OECD Data IO Table - Total (USD'!D25,'OECD Crosswalk'!$A$2:$A$90,0),1) -> nonenergy industries | D25: TTL_27: Electrical equipment | E25: 0 | F25: 0 | G25: 0 | H25: 1.8 | I25: 3.2 | J25: 0.7 | K25: 0.5 | L25: 2.5 | M25: 2.5 | N25: =3.2+1.6 -> 4.8 | O25: 0 | P25: 5.3 | Q25: 42.3 | R25: 5.7 | S25: 127.1 | T25: 580.4 | U25: 102.4 | V25: 48.3 | W25: 14.3 | X25: 13.2 | Y25: =75.6+61 -> 136.6 | Z25: 6.7 | AA25: 8164.4 | AB25: =5.2+11.2+6+17.1+62.9 -> 102.4 | AC25: 2.3 | AD25: 75 | AE25: 538.9 | AF25: 5 | AG25: 75.2 | AH25: 91 | AI25: =22.9+42.5 -> 65.4 | AJ25: 37 | AK25: 46.3 | AL25: 3.2 | AM25: =64.3+163.9 -> 228.2 | AN25: 0 | AO25: 4056.2 | AP25: 0 | AQ25: 0.1 | AR25: 2029.2 | AS25: 1058.9 | AT25: 11.8 | AU25: 2.4 | AV25: 342.1 | AW25: -15322.5 | AX25: =SUM(E25:AQ25) -> 14588.9
A26: =INDEX('OECD Crosswalk'!$C$2:$C$90,MATCH('OECD Data IO Table - Total (USD'!D26,'OECD Crosswalk'!$A$2:$A$90,0),1) -> other industries | B26: =INDEX('OECD Crosswalk'!$B$2:$B$90,MATCH('OECD Data IO Table - Total (USD'!D26,'OECD Crosswalk'!$A$2:$A$90,0),1) -> nonenergy industries | D26: TTL_28: Machinery and equipment n.e.c. | E26: 0.3 | F26: 0 | G26: 0 | H26: 15.2 | I26: 14.4 | J26: 3.6 | K26: 2.6 | L26: 12.8 | M26: 5.9 | N26: =9.5+5.3 -> 14.8 | O26: 0 | P26: 29.5 | Q26: 232.2 | R26: 39.9 | S26: 26.2 | T26: 71.3 | U26: 237.1 | V26: 115.8 | W26: 39.9 | X26: 22.1 | Y26: =12.3+20.7 -> 33 | Z26: 3.2 | AA26: 724.6 | AB26: =8.3+69.5+100.1+171.4+16.1 -> 365.4 | AC26: 3.7 | AD26: 10 | AE26: 34.5 | AF26: 0.4 | AG26: 251.5 | AH26: 61.5 | AI26: =2.8+8.4 -> 11.2 | AJ26: 14 | AK26: 18.9 | AL26: 31.4 | AM26: =13.1+20.5 -> 33.6 | AN26: 0 | AO26: 465.5 | AP26: 0 | AQ26: 0.2 | AR26: 7163.9 | AS26: 1027.4 | AT26: 0.8 | AU26: 0 | AV26: 912.5 | AW26: -10813.8 | AX26: =SUM(E26:AQ26) -> 2946.2
