Workbook
Name Average_emission_factor: '[1]Electricity emissions'!$H$38
Name footnote500011: FloorAreaPer!$A$170

Sheet About
A1: Sources:
B2: EMSD Energy End-use Data | C2: (Sheets:Energy8Sec, Residential8Fuel, Commercial8Fuel, Residential8EndUse, Commertial8EndUse)
B3: Hong Kong Energy End-use Data
B4: 2013-2018
B5: https://www.emsd.gov.hk/en/energy_efficiency/energy_end_use_data_and_consumption_indicators/hong_kong_energy_end_use_data/data/index.html
B6: Sheets:"Energy8Sec","Residential8Fuel","Commercial8Fuel","Residential8EndUse" and "Commercial8EndUse" are all from this data source.
B8: HK 2030 Report | F8: HK 2030: Baseline Review
B9: HK Development Bureau, HK Planning Department | F9: HK Development Bureau, HK Planning Department
B10: 2017 | F10: 2017
B11: Final Report | F11: Baseline Review: Population, Housing, Economy and Spatial Development Pattern
B12: https://www.pland.gov.hk/pland_en/p_study/comp_s/hk2030/eng/finalreport/ | F12: https://www.hk2030plus.hk/document/Baseline%20Review%20-%20Population_Housing_Economy%20and%20Spatial%20Development%20Pattern_Eng.pdf
B14: Household History Data(Sheet: Household_Histo) | F14: Household Prediction Data(Sheet: Household_Pred)
B15: Census and Statistics Department, HK | F15: Census and Statistics Department, HK
B16: 2019 | F16: 2019
B17: Table 005 : Statistics on Domestic Households | F17: Table E485 : Hong Kong Domestic Household Projections
B18: https://www.censtatd.gov.hk/hkstat/sub/sp150.jsp?tableID=005&ID=0&productType=8 | F18: https://www.censtatd.gov.hk/hkstat/sub/sp190.jsp?productCode=D5320185
B20: Floor Area Per capita (Sheet: FloorAreaPer)
B21: Population By-census
B22: 2017
B23: Table E129c: Median Per Capita Floor Area of Accommodation by Area of Residence, Household Size, Year and Type of Housing
B24: https://www.bycensus2016.gov.hk/en/bc-mt.html?search=E129c
B26: Building 2016 Data
B27: From Xiaoqian Jiang
B28: 2017
B29: From Excel "Copy of HK 2016 end use energy consumption rough 20190226 (added the building waste) revised2 lawrence.xlsx", Sheet"Building"
A32: Edition Log (WU Yazhen)
A33: 20190301_v1
A34: This part of data collection has not been finished.
A35: Next step: | B35: 1.Found Household Unit Composition to separate urban/rural residential
B36: 2.Use historical and predicted data of :Population, GDP, total residential area, total commercial arer, average number of people per household, average residential area per household
C37: to make linear or non-linear regression to predict future total energy consumption of residential/commercial sector of each fuel type.
C38: Then assuming the end-use composition stay unchanged throught the years, and the already-annouced building energy saving goal achieved.
C39: To predict future BAU End-use Data
A40: 20190304_v2
A41: Finished: | B41: 1.Found household history and prediction data.
B42: 2.Found Commercial AreaUse relative prediction ( average living area per household, household number; average living area per person, population) to predict residential area.
B43: 3.Done regression for estimating future residential energy consumption and
A44: 20190305_v3
A45: Finished: | B45: 1.Finished 1st version of Future Energy (End-use) Share Prediction.
B46: 2.Finished all calculation and got the final results, with TJ been converted to BTU.
...

Sheet Note
A1: Method
A2: Step1: Predict Future Total Energy Consumption by Segments using socioeconomic and energy intensity data
B3: predict per capita/per area energy consumption and then multiply it with population/area projections. Not directly predict total energy consumption by regression.
A4: Step2: Predict Future Energy Type Share by using trend function.
A5: Step3: Predict Future End-use share of different(electricity/non-electricity) type in residential energy use
A8: Assumptions & Classicification
A9: 1. "Coal and oil"(in statistics: energy consumption by fuel) is made up of 50% coal, 50% oil. And "Town gas &Oil gas" equals to natural gas
A10: 2. The end-use "Hot water" are categorized as "Appliance", not as part of the "Heating".
A11: 3. No energy consumption in "Heating"(In EPS model note, the "Heating" means distributed heating, which HK does not have), and thus
A12: 4. The end-use "Appliance" includes "Hot water &Refrigeration", "Office equipment" and "Cooking", while the category "Others" includes "Others" in the Residential/Commercial sector segment statistic.
A13: 5. The share of end-uses in all different non-electricity energy types are the same.
A15: Future considerations
A16: 1.The fact that older peole' energy demand is different and the HK population structure is changing
A17: 2. Classification of end-use categories. E.g. perhaps "Cooking" should be grouped into "Appliance" category, not "Others"?
A18: 3. Refer to BEC (HK Energy-saving Report)?
... A51: 10. Sheet "Future Energy Share", data in row 64-65 is currently not yet supported by valid material; they are assumed by me.

Sheet InternalLink
A2: About
A3: InternalLink
A4: Household_Histo
A5: Household_Pred
A6: Energy8Sec
A7: Residential8Fuel
A8: Commercial8Fuel
A9: Residential8EndUse
A10: Commercial8EndUse
A11: Commercial
A12: Residential
A13: Future Pred
... A18: Note

Sheet Household_Histo
A1: Table005: Statistics on Domestic Households
A3: Period | C3: Number of domestic households ('000) | D3: Average domestic household size | E3: Owner-occupiers as a proportion of total number of domestic households (%) | F3: Owner-occupiers in public sector housing as a proportion of total number of domestic households in public sector housing (%) | G3: Owner-occupiers in private sector housing as a proportion of total number of domestic households in private sector housing (%)
A4: 1982 | C4: 1311.6 | D4: 3.9 | E4: 28.7 | F4: N.A. | G4: N.A.
A5: 1983 | C5: 1334.3 | D5: 3.9 | E5: 30.7 | F5: N.A. | G5: N.A.
A6: 1984 | C6: 1378.7 | D6: 3.7 | E6: 31.2 | F6: N.A. | G6: N.A.
A7: 1985 | C7: 1417.7 | D7: 3.7 | E7: 32.8 | F7: 6.6 | G7: 51.8
A8: 1986 | C8: 1473.1 | D8: 3.6 | E8: 34.9 | F8: 9.1 | G8: 53.9
A9: 1987 | C9: 1496.1 | D9: 3.6 | E9: 37.9 | F9: 10.1 | G9: 59.1
A10: 1988 | C10: 1532.6 | D10: 3.6 | E10: 39.4 | F10: 11.9 | G10: 60.8
A11: 1989 | C11: 1549 | D11: 3.6 | E11: 41.6 | F11: 12.9 | G11: 64.5
A12: 1990 | C12: 1559 | D12: 3.5 | E12: 42.6 | F12: 14.2 | G12: 66.3
A13: 1991 | C13: 1601.9 | D13: 3.5 | E13: 43.1 | F13: 15.8 | G13: 66.5
A14: 1992 | C14: 1633.5 | D14: 3.4 | E14: 43.5 | F14: 16.3 | G14: 68
A15: 1993 | C15: 1677.7 | D15: 3.5 | E15: 44.6 | F15: 18.2 | G15: 68.6
A16: 1994 | C16: 1729.1 | D16: 3.4 | E16: 45.1 | F16: 20.5 | G16: 67.8
A17: 1995 | C17: 1783 | D17: 3.4 | E17: 45.2 | F17: 21.6 | G17: 67.3
A18: 1996 | C18: 1864.5 | D18: 3.4 | E18: 45.9 | F18: 21.9 | G18: 67.1
... A39: 2017 | C39: 2534.7 | D39: 2.8 | E39: 49.2 | F39: 31.8 | G39: 63.8
A40: 10/1981 - 12/1981 | C40: 1297.7 | D40: 3.8 | E40: 28.7 | F40: N.A. | G40: N.A.
A41: 1/1982 - 3/1982 | C41: 1297.4 | D41: 3.9 | E41: 28.3 | F41: N.A. | G41: N.A.
A42: 4/1982 - 6/1982 | C42: 1317.5 | D42: 3.9 | E42: 28.5 | F42: N.A. | G42: N.A.
A43: 7/1982 - 9/1982 | C43: 1312.3 | D43: 3.9 | E43: 29 | F43: N.A. | G43: N.A.
A44: 10/1982 - 12/1982 | C44: 1319.3 | D44: 3.9 | E44: 29 | F44: N.A. | G44: N.A.
A45: 1/1983 - 3/1983 | C45: 1320.1 | D45: 3.9 | E45: 31.1 | F45: N.A. | G45: N.A.
A46: 4/1983 - 6/1983 | C46: 1330.5 | D46: 3.9 | E46: 30.9 | F46: N.A. | G46: N.A.
A47: 7/1983 - 9/1983 | C47: 1336.9 | D47: 3.8 | E47: 30.3 | F47: N.A. | G47: N.A.
A48: 10/1983 - 12/1983 | C48: 1349.9 | D48: 3.8 | E48: 30.3 | F48: N.A. | G48: N.A.
A49: 1/1984 - 3/1984 | C49: 1345.4 | D49: 3.8 | E49: 30.9 | F49: N.A. | G49: N.A.
A50: 4/1984 - 6/1984 | C50: 1378.1 | D50: 3.8 | E50: 30.9 | F50: N.A. | G50: N.A.
A51: 7/1984 - 9/1984 | C51: 1386.3 | D51: 3.7 | E51: 31.8 | F51: N.A. | G51: N.A.
A52: 10/1984 - 12/1984 | C52: 1405 | D52: 3.7 | E52: 31.3 | F52: N.A. | G52: N.A.
A53: 1/1985 - 3/1985 | C53: 1402.9 | D53: 3.7 | E53: 31.4 | F53: 5.9 | G53: 50.2
A54: 4/1985 - 6/1985 | C54: 1416.7 | D54: 3.7 | E54: 32.8 | F54: 6.3 | G54: 51.6
A55: 7/1985 - 9/1985 | C55: 1416.5 | D55: 3.7 | E55: 33.9 | F55: 6.9 | G55: 53.6
A56: 10/1985 - 12/1985 | C56: 1434.7 | D56: 3.7 | E56: 33.2 | F56: 7.3 | G56: 51.8
A57: 1/1986 - 3/1986 | C57: 1453 | D57: 3.7 | E57: 32.9 | F57: 7.9 | G57: 50.6
A58: 4/1986 - 6/1986 | C58: 1469.7 | D58: 3.6 | E58: 34 | F58: 9 | G58: 52
A59: 7/1986 - 9/1986 | C59: 1481.4 | D59: 3.6 | E59: 36 | F59: 9.5 | G59: 56.4
A60: 10/1986 - 12/1986 | C60: 1488.2 | D60: 3.6 | E60: 36.5 | F60: 9.9 | G60: 56.9
A61: 1/1987 - 3/1987 | C61: 1478.3 | D61: 3.6 | E61: 37.1 | F61: 9.9 | G61: 57.7
...

Sheet Household_Pred
A1: 表 1 | B1: 家庭住戶數目及平均住戶人數
A2: Table 1 | B2: Number of domestic households and average household size
A4: 年份 | B4: 家庭住戶數目 | C4: 前五年內平均每年增幅 | D4: 平均住戶人數
A5: Year | B5: Number of domestic households | C5: Average annual growth over the past 5 years | D5: Average household size
A7: 1981 | B7: 1244700 | C7: - | D7: 3.9
A8: 1986 | B8: 1452600 | C8: 41600 | D8: 3.7
A9: 1991 | B9: 1582200 | C9: 25900 | D9: 3.4
A10: 1996 | B10: 1855600 | C10: 54700 | D10: 3.3
A11: 2001 | B11: 2053400 | C11: 39600 | D11: 3.1
A12: 2006 | B12: 2226500 | C12: 34600 | D12: 3
A13: 2011 | B13: 2368800 | C13: 28500 | D13: 2.9
A14: 2016 | B14: 2509700 | C14: 28200 | D14: 2.8
A15: 2021 | B15: 2657000 | C15: 29400 | D15: 2.8
A16: 2026 | B16: 2768900 | C16: 22400 | D16: 2.7
A17: 2031 | B17: 2854500 | C17: 17100 | D17: 2.7
A18: 2036 | B18: 2920200 | C18: 13100 | D18: 2.7
A19: 2041 | B19: 2961400 | C19: 8200 | D19: 2.7
... A21: 2051 | B21: 2949500 | C21: -4500 | D21: 2.7
A23: 註釋： | B23: 虛線以下的數字是推算數字。
B24: 推算結果反映若過往有關生育、死亡、人口遷移及戶主率的人口趨勢仍延續，未來的整體趨勢情況。要注意的是由於未來可能會發生現階段不能預見及預測的情況，因此，有關未來趨勢的假設亦受制於這些不確定因素的發展。
A26: Notes : | B26: Figures below the broken lines are based on projections.
B27: The projection results aim at illustrating what would happen if the past demographic trends on fertility, mortality, movement and headship rates continue into the future. It should however be noted that the assumptions of future trends are subject to uncertainties arising from unforeseeable and unpredictable future events.

Sheet History Type Share
A1: Residential Energy Use by Fuel
A2: Source: | B2: EMSD End-use Data report 2023
A3: 住宅 Residential
A4: 年份 Year | B4: 煤氣及石油氣* Town Gas & Liquefied Petroleum Gas* | D4: 油及煤產品 Oil & Coal Products | F4: 電力 Electricity | H4: 總計 Total
A5: 2006 | B5: 18476 | C5: 0.34 | D5: 79 | E5: 0 | F5: 35428 | G5: 0.66 | H5: 53982
A6: 2007 | B6: 18238 | C6: 0.33 | D6: 57 | E6: 0 | F6: 36422 | G6: 0.67 | H6: 54717
A7: 2008 | B7: 18708 | C7: 0.33 | D7: 41 | E7: 0 | F7: 37100 | G7: 0.66 | H7: 55849
A8: 2009 | B8: 18736 | C8: 0.32 | D8: 23 | E8: 0 | F8: 38972 | G8: 0.68 | H8: 57731
A9: 2010 | B9: 19038 | C9: 0.33 | D9: 13 | E9: 0 | F9: 39344 | G9: 0.67 | H9: 58396
A10: 2011 | B10: 18977 | C10: 0.32 | D10: 8 | E10: 0 | F10: 39872 | G10: 0.68 | H10: 58857
A11: 2012 | B11: 18841 | C11: 0.31 | D11: 8 | E11: 0 | F11: 41189 | G11: 0.69 | H11: 60037
A12: 2013 | B12: 18635 | C12: 0.32 | D12: 7 | E12: 0 | F12: 39941 | G12: 0.68 | H12: 58582
A13: 2014 | B13: 18681 | C13: 0.3 | D13: 7 | E13: 0 | F13: 43415 | G13: 0.7 | H13: 62103
A14: 2015 | B14: 18063 | C14: 0.3 | D14: 8 | E14: 0 | F14: 42368 | G14: 0.7 | H14: 60439
A15: 2016 | B15: 18574 | C15: 0.3 | D15: 10 | E15: 0 | F15: 43120 | G15: 0.7 | H15: 61704
A16: 2017 | B16: 18335 | C16: 0.3 | D16: 14 | E16: 0 | F16: 42127 | G16: 0.7 | H16: 60476
... A20: 2021 | B20: 19242 | C20: 0.29 | D20: 15 | E20: 0 | F20: 47464 | G20: 0.7 | H20: 66721
A23: Commercial Energy Use by Fuel
A24: Source: | B24: EMSD End-use Data report 2022#
A25: 商业 Commercial
A26: 年份 Year | B26: 煤氣及石油氣* Town Gas & Liquefied Petroleum Gas* | D26: 油及煤產品 Oil & Coal Products | F26: 電力 Electricity | H26: 總計 Total
A27: 2006 | B27: 13631 | C27: 0.12 | D27: 4936 | E27: 0.04 | F27: 93317 | G27: 0.83 | H27: 111884
A28: 2007 | B28: 13888 | C28: 0.12 | D28: 4975 | E28: 0.04 | F28: 95051 | G28: 0.83 | H28: 113914
A29: 2008 | B29: 13471 | C29: 0.12 | D29: 4739 | E29: 0.04 | F29: 95543 | G29: 0.84 | H29: 113753
A30: 2009 | B30: 12815 | C30: 0.11 | D30: 4753 | E30: 0.04 | F30: 96728 | G30: 0.85 | H30: 114297
A31: 2010 | B31: 13971 | C31: 0.12 | D31: 4526 | E31: 0.04 | F31: 97894 | G31: 0.84 | H31: 116391
A32: 2011 | B32: 14129 | C32: 0.12 | D32: 1979 | E32: 0.02 | F32: 99905 | G32: 0.86 | H32: 116013
A33: 2012 | B33: 14280 | C33: 0.12 | D33: 1696 | E33: 0.01 | F33: 102353 | G33: 0.86 | H33: 118330
A34: 2013 | B34: 14512 | C34: 0.12 | D34: 1477 | E34: 0.01 | F34: 102221 | G34: 0.86 | H34: 118209
A35: 2014 | B35: 14713 | C35: 0.12 | D35: 1431 | E35: 0.01 | F35: 103471 | G35: 0.87 | H35: 119615
A36: 2015 | B36: 14535 | C36: 0.12 | D36: 1235 | E36: 0.01 | F36: 104647 | G36: 0.87 | H36: 120417
A37: 2016 | B37: 14601 | C37: 0.12 | D37: 1019 | E37: 0.01 | F37: 104839 | G37: 0.87 | H37: 120458
A38: 2017 | B38: 14908 | C38: 0.12 | D38: 830 | E38: 0.01 | F38: 104669 | G38: 0.87 | H38: 120408
... A42: 2021 | B42: 12353 | C42: 0.1 | D42: 490 | E42: 0 | F42: 107240 | G42: 0.89 | H42: 120083

Sheet Commercial8Fuel
A1: Commercial Energy Use by Fuel
A2: Source: | B2: EMSD End-use Data report 2023
A3: 商业 Commercial
A4: 年份 Year | B4: 煤氣及石油氣* Town Gas & Liquefied Petroleum Gas* | D4: 油及煤產品 Oil & Coal Products | F4: 電力 Electricity | H4: 總計 Total
A5: 2006 | B5: 13631 | C5: 0.12 | D5: 4936 | E5: 0.04 | F5: 93317 | G5: 0.86 | H5: 111884
A6: 2007 | B6: 13888 | C6: 0.12 | D6: 4975 | E6: 0.04 | F6: 95051 | G6: 0.86 | H6: 113914
A7: 2008 | B7: 13471 | C7: 0.12 | D7: 4739 | E7: 0.04 | F7: 95543 | G7: 0.86 | H7: 113753
A8: 2009 | B8: 12815 | C8: 0.11 | D8: 4753 | E8: 0.04 | F8: 96728 | G8: 0.87 | H8: 114297
A9: 2010 | B9: 13971 | C9: 0.12 | D9: 4526 | E9: 0.04 | F9: 97894 | G9: 0.87 | H9: 116391
A10: 2011 | B10: 14129 | C10: 0.12 | D10: 1979 | E10: 0.02 | F10: 99905 | G10: 0.87 | H10: 116013
A11: 2012 | B11: 14280 | C11: 0.12 | D11: 1696 | E11: 0.01 | F11: 102353 | G11: 0.87 | H11: 118330
A12: 2013 | B12: 14512 | C12: 0.12 | D12: 1477 | E12: 0.01 | F12: 102221 | G12: 0.87 | H12: 118209
A13: 2014 | B13: 14713 | C13: 0.12 | D13: 1431 | E13: 0.01 | F13: 103471 | G13: 0.87 | H13: 119615
A14: 2015 | B14: 14535 | C14: 0.12 | D14: 1235 | E14: 0.01 | F14: 104647 | G14: 0.87 | H14: 120417
A15: 2016 | B15: 14601 | C15: 0.12 | D15: 1019 | E15: 0.01 | F15: 104839 | G15: 0.87 | H15: 120458
A16: 2017 | B16: 14908 | C16: 0.12 | D16: 830 | E16: 0.01 | F16: 104669 | G16: 0.87 | H16: 120408
... A20: 2021 | B20: 12353 | C20: 0.1 | D20: 490 | E20: 0 | F20: 107240 | G20: 0.89 | H20: 120083

Sheet Residential8EndUse
A1: Residential Sector Energy Consumption by End-use
A2: Source: | B2: EMSD End-use Data report | D2: Chapter : By Sectors&Segments
B4: Data from END-use data report 2023 | G4: Data from END-use data report 2013-2018
B5: Energy | G5: Energy
D6: 2016 | E6: 2021 | H6: Air Conditioning | I6: Hot Water | J6: Lighting | K6: Refrigeration | L6: Office Equipment | M6: Cooking | N6: Others | O6: Sum
B7: 空气调节 | C7: Air Conditioning | D7: 0.25 | E7: 0.28 | G7: 2005 | H7: 0.23 | I7: 0.21 | J7: 0.08 | K7: 0.11 | L7: 0.08 | M7: 0.26 | N7: 0.03 | O7: =SUM(H7:N7) -> 1
B8: 热水 | C8: Hot Water | D8: 0.18 | E8: 0.23 | G8: 2006 | H8: 0.22 | I8: 0.2 | J8: 0.08 | K8: 0.11 | L8: 0.09 | M8: 0.26 | N8: 0.04 | O8: =SUM(H8:N8) -> 1
B9: 照明 | C9: Lighting | D9: 0.06 | E9: 0.04 | G9: 2007 | H9: The Categories are different in End-use Datas which reporting the end-use data
B10: 冷冻 | C10: Refrigeration | D10: 0.09 | E10: 0.05 | G10: 2008 | H10: between 2007 and 2010
B11: 办公设备 | C11: Office Equipment | D11: 0.11 | E11: 0.06 | G11: 2009
B12: 煮食 | C12: Cooking | D12: 0.24 | E12: 0.26 | G12: 2010
B13: 其他 | C13: Others | D13: 0.07 | E13: 0.08 | G13: 2011 | H13: 0.23 | I13: 0.19 | J13: 0.07 | K13: 0.1 | L13: 0.1 | M13: 0.25 | N13: 0.06 | O13: =SUM(H13:N13) -> 1
B14: Sum | D14: =SUM(D7:D13) -> 1 | E14: =SUM(E7:E13) -> 1 | G14: 2012 | H14: 0.23 | I14: 0.19 | J14: 0.07 | K14: 0.09 | L14: 0.1 | M14: 0.26 | N14: 0.06 | O14: =SUM(H14:N14) -> 1
G15: 2013 | H15: 0.21 | I15: 0.19 | J15: 0.07 | K15: 0.09 | L15: 0.11 | M15: 0.26 | N15: 0.07 | O15: =SUM(H15:N15) -> 1
G16: 2014 | H16: 0.25 | I16: 0.18 | J16: 0.06 | K16: 0.09 | L16: 0.1 | M16: 0.25 | N16: 0.07 | O16: =SUM(H16:N16) -> 1
G17: 2015 | H17: 0.25 | I17: 0.18 | J17: 0.06 | K17: 0.1 | L17: 0.1 | M17: 0.24 | N17: 0.07 | O17: =SUM(H17:N17) -> 1
G18: 2016 | H18: 0.27 | I18: 0.24 | J18: 0.04 | K18: 0.05 | L18: 0.06 | M18: 0.26 | N18: 0.08 | O18: =SUM(H18:N18) -> 1
G19: 2017 | H19: 0.26 | I19: 0.24 | J19: 0.04 | K19: 0.05 | L19: 0.06 | M19: 0.27 | N19: 0.08 | O19: =SUM(H19:N19) -> 1
G20: 2018 | H20: 0.26 | I20: 0.24 | J20: 0.04 | K20: 0.05 | L20: 0.06 | M20: 0.27 | N20: 0.08 | O20: =SUM(H20:N20) -> 1
G21: 2019 | H21: 0.26 | I21: 0.23 | J21: 0.04 | K21: 0.05 | L21: 0.06 | M21: 0.27 | N21: 0.09 | O21: =SUM(H21:N21) -> 1
G22: 2020 | H22: 0.27 | I22: 0.23 | J22: 0.04 | K22: 0.05 | L22: 0.06 | M22: 0.26 | N22: 0.08 | O22: =SUM(H22:N22) -> 0.99
G23: 2021 | H23: 0.28 | I23: 0.23 | J23: 0.04 | K23: 0.05 | L23: 0.06 | M23: 0.26 | N23: 0.08 | O23: =SUM(H23:N23) -> 1
G25: Electricity
B26: Electricity | H26: Air Conditioning | I26: Hot Water | J26: Lighting | K26: Refrigeration | L26: Office Equipment | M26: Cooking | N26: Others | O26: Sum
D27: 2016 | E27: 2021 | G27: 2005 | H27: 0.35 | I27: 0.1 | J27: 0.12 | K27: 0.16 | L27: 0.13 | M27: 0.09 | N27: 0.05 | O27: =SUM(H27:N27) -> 1
B28: 空气调节 | C28: Air Conditioning | D28: 0.35 | E28: 0.39 | G28: 2006 | H28: 0.34 | I28: 0.11 | J28: 0.12 | K28: 0.16 | L28: 0.13 | M28: 0.09 | N28: 0.05 | O28: =SUM(H28:N28) -> 1
B29: 热水 | C29: Hot Water | D29: 0.08 | E29: 0.11 | G29: 2007 | H29: No data about electricity demand decomposition between 2007-2011
B30: 照明 | C30: Lighting | D30: 0.09 | E30: 0.05 | G30: 2008
B31: 冷冻 | C31: Refrigeration | D31: 0.14 | E31: 0.08 | G31: 2009
B32: 办公设备 | C32: Office Equipment | D32: 0.15 | E32: 0.08 | G32: 2010
B33: 煮食 | C33: Cooking | D33: 0.09 | E33: 0.17 | G33: 2011
B34: 其他 | C34: Others | D34: 0.1 | E34: 0.11 | G34: 2012 | H34: 0.34 | I34: 0.08 | J34: 0.1 | K34: 0.14 | L34: 0.15 | M34: 0.09 | N34: 0.1 | O34: =SUM(H34:N34) -> 1
B35: Sum | D35: =SUM(D28:D34) -> 1 | E35: =SUM(E28:E34) -> 0.99 | G35: 2013 | H35: 0.31 | I35: 0.09 | J35: 0.1 | K35: 0.14 | L35: 0.16 | M35: 0.1 | N35: 0.1 | O35: =SUM(H35:N35) -> 1
G36: 2014 | H36: 0.36 | I36: 0.08 | J36: 0.09 | K36: 0.13 | L36: 0.15 | M36: 0.09 | N36: 0.1 | O36: =SUM(H36:N36) -> 1
G37: 2015 | H37: 0.36 | I37: 0.08 | J37: 0.09 | K37: 0.14 | L37: 0.15 | M37: 0.09 | N37: 0.09 | O37: =SUM(H37:N37) -> 1
G38: 2016 | H38: 0.35 | I38: 0.08 | J38: 0.09 | K38: 0.14 | L38: 0.15 | M38: 0.09 | N38: 0.1 | O38: =SUM(H38:N38) -> 1
G39: 2017 | H39: 0.38 | I39: 0.12 | J39: 0.05 | K39: 0.08 | L39: 0.08 | M39: 0.18 | N39: 0.12 | O39: =SUM(H39:N39) -> 1.01
G40: 2018 | H40: 0.38 | I40: 0.12 | J40: 0.05 | K40: 0.08 | L40: 0.08 | M40: 0.18 | N40: 0.12 | O40: =SUM(H40:N40) -> 1.01
G41: 2019 | H41: 0.38 | I41: 0.11 | J41: 0.05 | K41: 0.08 | L41: 0.08 | M41: 0.18 | N41: 0.12 | O41: =SUM(H41:N41) -> 1
G42: 2020 | H42: 0.39 | I42: 0.11 | J42: 0.05 | K42: 0.08 | L42: 0.08 | M42: 0.18 | N42: 0.12 | O42: =SUM(H42:N42) -> 1.01
...

Sheet Energy8Sec
A1: All Energy/Electricity Consumption by Sector
A2: Source: | B2: EMSD End-use Data report 2018
A3: P23
A5: 终端能源使用All Energy Consumption By Sectors | F5: Unit:Terajoule | H5: Sectors Energy Consumption Percentage
A6: Year | B6: 住宅 Residential | C6: 商业 Commercial | D6: 工业 Industrial | E6: 运输 Transport | F6: 总计 Total | H6: Year | I6: 住宅 Residential | J6: 商业 Commercial | K6: 工业 Industrial | L6: 运输 Transport | M6: 总计 Total
A7: 2006 | B7: 53982 | C7: 111884 | D7: 18934 | E7: 96404 | F7: =SUM(B7:E7) -> 281204 | H7: 2006 | I7: =B7/$F7 -> 0.1919674 | J7: =C7/$F7 -> 0.39787485 | K7: =D7/$F7 -> 0.067331901 | L7: =E7/$F7 -> 0.34282585 | M7: =F7/$F7 -> 1
A8: 2007 | B8: 54717 | C8: 113914 | D8: 17645 | E8: 96165 | F8: =SUM(B8:E8) -> 282441 | H8: 2007 | I8: =B8/$F8 -> 0.19372896 | J8: =C8/$F8 -> 0.40331963 | K8: =D8/$F8 -> 0.062473224 | L8: =E8/$F8 -> 0.34047819 | M8: =F8/$F8 -> 1
A9: 2008 | B9: 55849 | C9: 113753 | D9: 17332 | E9: 94504 | F9: =SUM(B9:E9) -> 281438 | H9: 2008 | I9: =B9/$F9 -> 0.19844158 | J9: =C9/$F9 -> 0.40418494 | K9: =D9/$F9 -> 0.061583724 | L9: =E9/$F9 -> 0.33578977 | M9: =F9/$F9 -> 1
A10: 2009 | B10: 57731 | C10: 114297 | D10: 16129 | E10: 90643 | F10: =SUM(B10:E10) -> 278800 | H10: 2009 | I10: =B10/$F10 -> 0.20706958 | J10: =C10/$F10 -> 0.40996055 | K10: =D10/$F10 -> 0.057851506 | L10: =E10/$F10 -> 0.32511836 | M10: =F10/$F10 -> 1
A11: 2010 | B11: 58396 | C11: 116391 | D11: 16053 | E11: 90889 | F11: =SUM(B11:E11) -> 281729 | H11: 2010 | I11: =B11/$F11 -> 0.20727721 | J11: =C11/$F11 -> 0.41313106 | K11: =D11/$F11 -> 0.05698029 | L11: =E11/$F11 -> 0.32261145 | M11: =F11/$F11 -> 1
A12: 2011 | B12: 58826 | C12: 118558 | D12: 14732 | E12: 90774 | F12: =SUM(B12:E12) -> 282890 | H12: 2011 | I12: =B12/$F12 -> 0.20794655 | J12: =C12/$F12 -> 0.41909576 | K12: =D12/$F12 -> 0.052076779 | L12: =E12/$F12 -> 0.32088091 | M12: =F12/$F12 -> 1
A13: 2012 | B13: 59932 | C13: 120970 | D13: 14723 | E13: 90423 | F13: =SUM(B13:E13) -> 286048 | H13: 2012 | I13: =B13/$F13 -> 0.20951728 | J13: =C13/$F13 -> 0.42290105 | K13: =D13/$F13 -> 0.051470383 | L13: =E13/$F13 -> 0.31611128 | M13: =F13/$F13 -> 1
A14: 2013 | B14: 58394 | C14: 121215 | D14: 14583 | E14: 90198 | F14: =SUM(B14:E14) -> 284390 | H14: 2013 | I14: =B14/$F14 -> 0.20533071 | J14: =C14/$F14 -> 0.42622807 | K14: =D14/$F14 -> 0.051278174 | L14: =E14/$F14 -> 0.31716305 | M14: =F14/$F14 -> 1
A15: 2014 | B15: 61910 | C15: 122711 | D15: 14718 | E15: 89999 | F15: =SUM(B15:E15) -> 289338 | H15: 2014 | I15: =B15/$F15 -> 0.2139712 | J15: =C15/$F15 -> 0.42410952 | K15: =D15/$F15 -> 0.050867843 | L15: =E15/$F15 -> 0.31105143 | M15: =F15/$F15 -> 1
A16: 2015 | B16: 60214 | C16: 123674 | D16: 14853 | E16: 89245 | F16: =SUM(B16:E16) -> 287986 | H16: 2015 | I16: =B16/$F16 -> 0.20908655 | J16: =C16/$F16 -> 0.42944449 | K16: =D16/$F16 -> 0.051575424 | L16: =E16/$F16 -> 0.30989354 | M16: =F16/$F16 -> 1
A17: 2016 | B17: 61439 | C17: 123969 | D17: 13992 | E17: 89819 | F17: =SUM(B17:E17) -> 289219 | H17: 2016 | I17: =B17/$F17 -> 0.21243072 | J17: =C17/$F17 -> 0.42863367 | K17: =D17/$F17 -> 0.048378564 | L17: =E17/$F17 -> 0.31055705 | M17: =F17/$F17 -> 1
A18: 2017 | B18: 60476 | C18: 120408 | D18: 12722 | E18: 86557 | F18: 280162 | H18: 2017 | I18: =B18/$F18 -> 0.21586082 | J18: =C18/$F18 -> 0.42977991 | K18: =D18/$F18 -> 0.045409442 | L18: =E18/$F18 -> 0.30895339 | M18: =F18/$F18 -> 1
A19: 2018 | B19: 61556 | C19: 122220 | D19: 12829 | E19: 85054 | F19: 281659 | H19: 2018 | I19: =B19/$F19 -> 0.21854796 | J19: =C19/$F19 -> 0.43392897 | K19: =D19/$F19 -> 0.045547985 | L19: =E19/$F19 -> 0.30197508 | M19: =F19/$F19 -> 1
A20: 2019 | B20: 61021 | C20: 123001 | D20: 12274 | E20: 85877 | F20: 282174 | H20: 2019 | I20: =B20/$F20 -> 0.21625309 | J20: =C20/$F20 -> 0.4359048 | K20: =D20/$F20 -> 0.043497984 | L20: =E20/$F20 -> 0.30434058 | M20: =F20/$F20 -> 1
A21: 2020 | B21: 66413 | C21: 114512 | D21: 12161 | E21: 78514 | F21: 271600 | H21: 2020 | I21: =B21/$F21 -> 0.24452504 | J21: =C21/$F21 -> 0.42162003 | K21: =D21/$F21 -> 0.044775405 | L21: =E21/$F21 -> 0.28907953 | M21: =F21/$F21 -> 1
A22: 2021 | B22: 66721 | C22: 120083 | D22: 11945 | E22: 81158 | F22: 279907 | H22: 2021 | I22: =B22/$F22 -> 0.23836846 | J22: =C22/$F22 -> 0.42901035 | K22: =D22/$F22 -> 0.042674888 | L22: =E22/$F22 -> 0.2899463 | M22: =F22/$F22 -> 1
A25: 电力使用 Electricity Consuption By Sectors | H25: Sectors Electricity Consumption Percentage
A26: Year | B26: 住宅 Residential | C26: 商业 Commercial | D26: 工业 Industrial | E26: 运输 Transport | F26: 总计 Total | H26: Year | I26: 住宅 Residential | J26: 商业 Commercial | K26: 工业 Industrial | L26: 运输 Transport | M26: 总计 Total | O26: Check
A27: 2006 | B27: 35428 | C27: 93317 | D27: 14015 | E27: 2444 | F27: =SUM(B27:E27) -> 145204 | H27: 2006 | I27: =B27/$F27 -> 0.24398777 | J27: =C27/$F27 -> 0.64266136 | K27: =D27/$F27 -> 0.09651938 | L27: =E27/$F27 -> 0.016831492 | M27: =F27/$F27 -> 1 | O27: =B7*'History Type Share'!G5 -> 35628.12
A28: 2007 | B28: 36422 | C28: 95051 | D28: 13104 | E28: 2495 | F28: =SUM(B28:E28) -> 147072 | H28: 2007 | I28: =B28/$F28 -> 0.24764741 | J28: =C28/$F28 -> 0.64628889 | K28: =D28/$F28 -> 0.089099217 | L28: =E28/$F28 -> 0.01696448 | M28: =F28/$F28 -> 1 | O28: =B8*'History Type Share'!G6 -> 36660.39
A29: 2008 | B29: 37100 | C29: 95543 | D29: 12182 | E29: 2520 | F29: =SUM(B29:E29) -> 147345 | H29: 2008 | I29: =B29/$F29 -> 0.25179002 | J29: =C29/$F29 -> 0.64843055 | K29: =D29/$F29 -> 0.082676711 | L29: =E29/$F29 -> 0.017102718 | M29: =F29/$F29 -> 1 | O29: =B9*'History Type Share'!G7 -> 36860.34
A30: 2009 | B30: 38972 | C30: 96728 | D30: 11143 | E30: 2523 | F30: =SUM(B30:E30) -> 149366 | H30: 2009 | I30: =B30/$F30 -> 0.26091614 | J30: =C30/$F30 -> 0.64759048 | K30: =D30/$F30 -> 0.074601984 | L30: =E30/$F30 -> 0.016891394 | M30: =F30/$F30 -> 1 | O30: =B10*'History Type Share'!G8 -> 39257.08
A31: 2010 | B31: 39344 | C31: 97894 | D31: 11082 | E31: 2540 | F31: =SUM(B31:E31) -> 150860 | H31: 2010 | I31: =B31/$F31 -> 0.26079809 | J31: =C31/$F31 -> 0.64890627 | K31: =D31/$F31 -> 0.073458836 | L31: =E31/$F31 -> 0.016836802 | M31: =F31/$F31 -> 1 | O31: =B11*'History Type Share'!G9 -> 39125.32
A32: 2011 | B32: 39872 | C32: 99594 | D32: 9530 | E32: 2609 | F32: =SUM(B32:E32) -> 151605 | H32: 2011 | I32: =B32/$F32 -> 0.26299924 | J32: =C32/$F32 -> 0.65693084 | K32: =D32/$F32 -> 0.062860724 | L32: =E32/$F32 -> 0.017209195 | M32: =F32/$F32 -> 1 | O32: =B12*'History Type Share'!G10 -> 40001.68
A33: 2012 | B33: 41189 | C33: 101813 | D33: 9356 | E33: 2722 | F33: =SUM(B33:E33) -> 155080 | H33: 2012 | I33: =B33/$F33 -> 0.2655984 | J33: =C33/$F33 -> 0.65651922 | K33: =D33/$F33 -> 0.060330152 | L33: =E33/$F33 -> 0.017552231 | M33: =F33/$F33 -> 1 | O33: =B13*'History Type Share'!G11 -> 41353.08
A34: 2013 | B34: 39941 | C34: 101480 | D34: 9144 | E34: 2796 | F34: =SUM(B34:E34) -> 153361 | H34: 2013 | I34: =B34/$F34 -> 0.26043779 | J34: =C34/$F34 -> 0.66170669 | K34: =D34/$F34 -> 0.059624024 | L34: =E34/$F34 -> 0.018231493 | M34: =F34/$F34 -> 1 | O34: =B14*'History Type Share'!G12 -> 39707.92
A35: 2014 | B35: 43415 | C35: 102627 | D35: 9230 | E35: 2875 | F35: =SUM(B35:E35) -> 158147 | H35: 2014 | I35: =B35/$F35 -> 0.27452307 | J35: =C35/$F35 -> 0.64893422 | K35: =D35/$F35 -> 0.058363421 | L35: =E35/$F35 -> 0.018179289 | M35: =F35/$F35 -> 1 | O35: =B15*'History Type Share'!G13 -> 43337
A36: 2015 | B36: 42368 | C36: 103693 | D36: 9242 | E36: 2972 | F36: =SUM(B36:E36) -> 158275 | H36: 2015 | I36: =B36/$F36 -> 0.26768599 | J36: =C36/$F36 -> 0.65514453 | K36: =D36/$F36 -> 0.058392039 | L36: =E36/$F36 -> 0.018777444 | M36: =F36/$F36 -> 1 | O36: =B16*'History Type Share'!G14 -> 42149.8
A37: 2016 | B37: 43120 | C37: 103881 | D37: 8709 | E37: 2951 | F37: =SUM(B37:E37) -> 158661 | H37: 2016 | I37: =B37/$F37 -> 0.27177441 | J37: =C37/$F37 -> 0.65473557 | K37: =D37/$F37 -> 0.054890616 | L37: =E37/$F37 -> 0.018599404 | M37: =F37/$F37 -> 1 | O37: =B17*'History Type Share'!G15 -> 43007.3
A38: 2017 | B38: 42127 | C38: 104669 | D38: 7963 | E38: 3218 | F38: =SUM(B38:E38) -> 157977 | H38: 2017 | I38: =B38/$F38 -> 0.2666654 | J38: =C38/$F38 -> 0.66255847 | K38: =D38/$F38 -> 0.050406072 | L38: =E38/$F38 -> 0.020370054 | M38: =F38/$F38 -> 1 | O38: =B18*'History Type Share'!G16 -> 42333.2
... A42: 2021 | B42: 47464 | C42: 107240 | D42: 7222 | E42: 3002 | F42: =SUM(B42:E42) -> 164928 | H42: 2021 | I42: =B42/$F42 -> 0.28778619 | J42: =C42/$F42 -> 0.65022313 | K42: =D42/$F42 -> 0.043788805 | L42: =E42/$F42 -> 0.018201882 | M42: =F42/$F42 -> 1 | O42: =B22*'History Type Share'!G20 -> 46704.7

Sheet Private,Public8EndUse
A1: Private/Public Residential Energy Consumption by End-use
A2: Source: | B2: EMSD End-use Data report | D2: Chapter : By Sectors&Segments
A3: Energy
A4: 所有住宅All Residential | K4: 私人住宅Private Housing Segment | U4: 公共住宅 Public Housing | AE4: 重新加总Private+Public
A5: (缺少原始数据 No raw data) | I5: 總計 Total | K5: 年份 Year | L5: 煮食 Cooking | M5: 空氣調節 Air Conditioning | N5: 熱水 Hot Water | O5: 照明 Lighting | P5: 冷凍 Refrigeration | Q5: 辦公室設備 Office Equipment | R5: 其他 1 Others 1 | S5: 總計 Total | U5: 年份 Year | V5: 煮食 Cooking | W5: 空氣調節 Air Conditioning | X5: 熱水 Hot Water | Y5: 照明 Lighting | Z5: 冷凍 Refrigeration | AA5: 辦公室設備 Office Equipment | AB5: 其他 1 Others 1 | AC5: 總計 Total | AE5: 年份 Year | AF5: 煮食 Cooking | AG5: 空氣調節 Air Conditioning | AH5: 熱水 Hot Water | AI5: 照明 Lighting | AJ5: 冷凍 Refrigeration | AK5: 辦公室設備 Office Equipment | AL5: 其他 1 Others 1 | AM5: 總計 Total
I6: 53982 | K6: 2006 | L6: 6828 | M6: 6122 | N6: 5074 | O6: 2148 | P6: 2830 | Q6: 2311 | R6: 898 | S6: 26211 | U6: 2006 | V6: =B120+L120 -> 6900 | W6: =C120+M120 -> 5006 | X6: =D120+N120 -> 5485 | Y6: =E120+O120 -> 1760 | Z6: =F120+P120 -> 2656 | AA6: =G120+Q120 -> 2211 | AB6: =H120+R120 -> 948 | AC6: =I120+S120 -> 24967 | AE6: 2006 | AF6: =L6+V6 -> 13728 | AG6: =M6+W6 -> 11128 | AH6: =N6+X6 -> 10559 | AI6: =O6+Y6 -> 3908 | AJ6: =P6+Z6 -> 5486 | AK6: =Q6+AA6 -> 4522 | AL6: =R6+AB6 -> 1846 | AM6: =S6+AC6 -> 51178
I7: 54717 | K7: 2007 | L7: 6974 | M7: 6176 | N7: 5104 | O7: 2100 | P7: 2962 | Q7: 2469 | R7: 948 | S7: 26733 | U7: 2007 | V7: =B121+L121 -> 7023 | W7: =C121+M121 -> 4963 | X7: =D121+N121 -> 5436 | Y7: =E121+O121 -> 1709 | Z7: =F121+P121 -> 2741 | AA7: =G121+Q121 -> 2323 | AB7: =H121+R121 -> 990 | AC7: =I121+S121 -> 25185 | AE7: 2007 | AF7: =L7+V7 -> 13997 | AG7: =M7+W7 -> 11139 | AH7: =N7+X7 -> 10540 | AI7: =O7+Y7 -> 3809 | AJ7: =P7+Z7 -> 5703 | AK7: =Q7+AA7 -> 4792 | AL7: =R7+AB7 -> 1938 | AM7: =S7+AC7 -> 51918
I8: 55849 | K8: 2008 | L8: 7334 | M8: 6240 | N8: 5323 | O8: 2055 | P8: 3101 | Q8: 2646 | R8: 1002 | S8: 27701 | U8: 2008 | V8: =B122+L122 -> 7334 | W8: =C122+M122 -> 4836 | X8: =D122+N122 -> 5559 | Y8: =E122+O122 -> 1625 | Z8: =F122+P122 -> 2765 | AA8: =G122+Q122 -> 2398 | AB8: =H122+R122 -> 1017 | AC8: =I122+S122 -> 25533 | AE8: 2008 | AF8: =L8+V8 -> 14668 | AG8: =M8+W8 -> 11076 | AH8: =N8+X8 -> 10882 | AI8: =O8+Y8 -> 3680 | AJ8: =P8+Z8 -> 5866 | AK8: =Q8+AA8 -> 5044 | AL8: =R8+AB8 -> 2019 | AM8: =S8+AC8 -> 53234
I9: 57731 | K9: 2009 | L9: 7232 | M9: 6740 | N9: 5344 | O9: 2167 | P9: 3134 | Q9: 2764 | R9: 1164 | S9: 28544 | U9: 2009 | V9: =B123+L123 -> 7307 | W9: =C123+M123 -> 5103 | X9: =D123+N123 -> 5543 | Y9: =E123+O123 -> 1639 | Z9: =F123+P123 -> 2818 | AA9: =G123+Q123 -> 2519 | AB9: =H123+R123 -> 1139 | AC9: =I123+S123 -> 26068 | AE9: 2009 | AF9: =L9+V9 -> 14539 | AG9: =M9+W9 -> 11843 | AH9: =N9+X9 -> 10887 | AI9: =O9+Y9 -> 3806 | AJ9: =P9+Z9 -> 5952 | AK9: =Q9+AA9 -> 5283 | AL9: =R9+AB9 -> 2303 | AM9: =S9+AC9 -> 54612
I10: 58396 | K10: 2010 | L10: 7172 | M10: 6949 | N10: 5279 | O10: 2178 | P10: 3003 | Q10: 2815 | R10: 1333 | S10: 28730 | U10: 2010 | V10: 4661 | W10: 2870 | X10: 3557 | Y10: 947 | Z10: 1818 | AA10: 1558 | AB10: 742 | AC10: 16152 | AE10: 2010 | AF10: =L10+V10 -> 11833 | AG10: =M10+W10 -> 9819 | AH10: =N10+X10 -> 8836 | AI10: =O10+Y10 -> 3125 | AJ10: =P10+Z10 -> 4821 | AK10: =Q10+AA10 -> 4373 | AL10: =R10+AB10 -> 2075 | AM10: =S10+AC10 -> 44882
I11: 58826 | K11: 2011 | L11: 7028 | M11: 7201 | N11: 5259 | O11: 2204 | P11: 2891 | Q11: 2945 | R11: 1606 | S11: 29134 | U11: 2011 | V11: 4740 | W11: 2931 | X11: 3565 | Y11: 942 | Z11: 1763 | AA11: 1642 | AB11: 841 | AC11: 16425 | AE11: 2011 | AF11: =L11+V11 -> 11768 | AG11: =M11+W11 -> 10132 | AH11: =N11+X11 -> 8824 | AI11: =O11+Y11 -> 3146 | AJ11: =P11+Z11 -> 4654 | AK11: =Q11+AA11 -> 4587 | AL11: =R11+AB11 -> 2447 | AM11: =S11+AC11 -> 45559
I12: 59932 | K12: 2012 | L12: 6788 | M12: 7364 | N12: 5113 | O12: 2208 | P12: 2743 | Q12: 3099 | R12: 2008 | S12: 29324 | U12: 2012 | V12: 4804 | W12: 3029 | X12: 3549 | Y12: 970 | Z12: 1725 | AA12: 1794 | AB12: 995 | AC12: 16866 | AE12: 2012 | AF12: =L12+V12 -> 11592 | AG12: =M12+W12 -> 10393 | AH12: =N12+X12 -> 8662 | AI12: =O12+Y12 -> 3178 | AJ12: =P12+Z12 -> 4468 | AK12: =Q12+AA12 -> 4893 | AL12: =R12+AB12 -> 3003 | AM12: =S12+AC12 -> 46190
I13: 58394 | K13: 2013 | L13: 7301 | M13: 6914 | N13: 5450 | O13: 1874 | P13: 2404 | Q13: 2505 | R13: 2042 | S13: 28489 | U13: 2013 | V13: 5085 | W13: 2883 | X13: 3661 | Y13: 823 | Z13: 1544 | AA13: 1573 | AB13: 1035 | AC13: 16604 | AE13: 2013 | AF13: =L13+V13 -> 12386 | AG13: =M13+W13 -> 9797 | AH13: =N13+X13 -> 9111 | AI13: =O13+Y13 -> 2697 | AJ13: =P13+Z13 -> 3948 | AK13: =Q13+AA13 -> 4078 | AL13: =R13+AB13 -> 3077 | AM13: =S13+AC13 -> 45093
I14: 61910 | K14: 2014 | L14: 7499 | M14: 8322 | N14: 6055 | O14: 1752 | P14: 2292 | Q14: 2357 | R14: 2271 | S14: 30548 | U14: 2014 | V14: 5083 | W14: 3496 | X14: 3866 | Y14: 775 | Z14: 1495 | AA14: 1489 | AB14: 1168 | AC14: 17371 | AE14: 2014 | AF14: =L14+V14 -> 12582 | AG14: =M14+W14 -> 11818 | AH14: =N14+X14 -> 9921 | AI14: =O14+Y14 -> 2527 | AJ14: =P14+Z14 -> 3787 | AK14: =Q14+AA14 -> 3846 | AL14: =R14+AB14 -> 3439 | AM14: =S14+AC14 -> 47919
I15: 60214 | K15: 2015 | L15: 7243 | M15: 8046 | N15: 6136 | O15: 1500 | P15: 1972 | Q15: 2047 | R15: 2296 | S15: 29241 | U15: 2015 | V15: 4912 | W15: 3580 | X15: 3866 | Y15: 691 | Z15: 1349 | AA15: 1338 | AB15: 1235 | AC15: 16970 | AE15: 2015 | AF15: =L15+V15 -> 12155 | AG15: =M15+W15 -> 11626 | AH15: =N15+X15 -> 10002 | AI15: =O15+Y15 -> 2191 | AJ15: =P15+Z15 -> 3321 | AK15: =Q15+AA15 -> 3385 | AL15: =R15+AB15 -> 3531 | AM15: =S15+AC15 -> 46211
I16: 61439 | K16: 2016 | L16: 7706 | M16: 8323 | N16: 6933 | O16: 1379 | P16: 1789 | Q16: 1893 | R16: 2465 | S16: 30489 | U16: 2016 | V16: 4942 | W16: 3758 | X16: 4079 | Y16: 633 | Z16: 1226 | AA16: 1231 | AB16: 1320 | AC16: 17190 | AE16: 2016 | AF16: =L16+V16 -> 12648 | AG16: =M16+W16 -> 12081 | AH16: =N16+X16 -> 11012 | AI16: =O16+Y16 -> 2012 | AJ16: =P16+Z16 -> 3015 | AK16: =Q16+AA16 -> 3124 | AL16: =R16+AB16 -> 3785 | AM16: =S16+AC16 -> 47679
I17: 59992 | K17: 2017 | L17: 7888 | M17: 8203 | N17: 7242 | O17: 1220 | P17: 1523 | Q17: 1652 | R17: 1036 | S17: 30231 | U17: 2017 | V17: 4786 | W17: 3829 | X17: 4048 | Y17: 571 | Z17: 1055 | AA17: 1082 | AB17: 550 | AC17: 16713 | AE17: 2017 | AF17: =L17+V17 -> 12674 | AG17: =M17+W17 -> 12032 | AH17: =N17+X17 -> 11290 | AI17: =O17+Y17 -> 1791 | AJ17: =P17+Z17 -> 2578 | AK17: =Q17+AA17 -> 2734 | AL17: =R17+AB17 -> 1586 | AM17: =S17+AC17 -> 46944
I18: 60793 | K18: 2018 | L18: 8216 | M18: 8009 | N18: 7215 | O18: 1203 | P18: 1502 | Q18: 1629 | R18: 1022 | S18: 30241 | U18: 2018 | V18: 4960 | W18: 3783 | X18: 4139 | Y18: 570 | Z18: 1054 | AA18: 1080 | AB18: 549 | AC18: 16925 | AE18: 2018 | AF18: =L18+V18 -> 13176 | AG18: =M18+W18 -> 11792 | AH18: =N18+X18 -> 11354 | AI18: =O18+Y18 -> 1773 | AJ18: =P18+Z18 -> 2556 | AK18: =Q18+AA18 -> 2709 | AL18: =R18+AB18 -> 1571 | AM18: =S18+AC18 -> 47166
I19: 61025 | K19: 2019 | L19: 7850 | M19: 8206 | N19: 7035 | O19: 1239 | P19: 1567 | Q19: 1678 | R19: 1052 | S19: 30115 | U19: 2019 | V19: 4792 | W19: 3839 | X19: 3980 | Y19: 587 | Z19: 1098 | AA19: 1111 | AB19: 565 | AC19: 16785 | AE19: 2019 | AF19: =L19+V19 -> 12642 | AG19: =M19+W19 -> 12045 | AH19: =N19+X19 -> 11015 | AI19: =O19+Y19 -> 1826 | AJ19: =P19+Z19 -> 2665 | AK19: =Q19+AA19 -> 2789 | AL19: =R19+AB19 -> 1617 | AM19: =S19+AC19 -> 46900
I20: 66416 | K20: 2020 | L20: 8417 | M20: 9257 | N20: 7711 | O20: 1320 | P20: 1667 | Q20: 1788 | R20: 1122 | S20: 32856 | U20: 2020 | V20: 5131 | W20: 4280 | X20: 4318 | Y20: 617 | Z20: 1153 | AA20: 1169 | AB20: 595 | AC20: 18119 | AE20: 2020 | AF20: =L20+V20 -> 13548 | AG20: =M20+W20 -> 13537 | AH20: =N20+X20 -> 12029 | AI20: =O20+Y20 -> 1937 | AJ20: =P20+Z20 -> 2820 | AK20: =Q20+AA20 -> 2957 | AL20: =R20+AB20 -> 1717 | AM20: =S20+AC20 -> 50975
I21: 66721 | K21: 2021 | L21: 8198 | M21: 9309 | N21: 7349 | O21: 1301 | P21: 1651 | Q21: 1762 | R21: 1105 | S21: 32236 | U21: 2021 | V21: 5121 | W21: 4466 | X21: 4249 | Y21: 630 | Z21: 1183 | AA21: 1193 | AB21: 607 | AC21: 18298 | AE21: 2021 | AF21: =L21+V21 -> 13319 | AG21: =M21+W21 -> 13775 | AH21: =N21+X21 -> 11598 | AI21: =O21+Y21 -> 1931 | AJ21: =P21+Z21 -> 2834 | AK21: =Q21+AA21 -> 2955 | AL21: =R21+AB21 -> 1712 | AM21: =S21+AC21 -> 50534
A23: 转换为百分比Change to percentage
A24: Year | B24: Air Conditioning | C24: Hot Water | D24: Lighting | E24: Refrigeration | F24: Office Equipment | G24: Cooking | H24: Others | I24: Sum | K24: 私人住宅Private Housing Segment | U24: 公共住宅 Public Housing | AE24: 重新加总Private+Public
A25: 2005 | B25: 0.23 | C25: 0.21 | D25: 0.08 | E25: 0.11 | F25: 0.08 | G25: 0.26 | H25: 0.03 | I25: =SUM(B25:H25) -> 1 | K25: 年份 Year | L25: 煮食 Cooking | M25: 空氣調節 Air Conditioning | N25: 熱水 Hot Water | O25: 照明 Lighting | P25: 冷凍 Refrigeration | Q25: 辦公室設備 Office Equipment | R25: 其他 1 Others 1 | S25: 總計 Total | U25: 年份 Year | V25: 煮食 Cooking | W25: 空氣調節 Air Conditioning | X25: 熱水 Hot Water | Y25: 照明 Lighting | Z25: 冷凍 Refrigeration | AA25: 辦公室設備 Office Equipment | AB25: 其他 1 Others 1 | AC25: 總計 Total | AE25: 年份 Year | AF25: 煮食 Cooking | AG25: 空氣調節 Air Conditioning | AH25: 熱水 Hot Water | AI25: 照明 Lighting | AJ25: 冷凍 Refrigeration | AK25: 辦公室設備 Office Equipment | AL25: 其他 1 Others 1 | AM25: 總計 Total
A26: 2006 | B26: 0.22 | C26: 0.2 | D26: 0.08 | E26: 0.11 | F26: 0.09 | G26: 0.26 | H26: 0.04 | I26: =SUM(B26:H26) -> 1 | K26: 2006 | L26: =L6/$S6 -> 0.26050132 | M26: =M6/$S6 -> 0.23356606 | N26: =N6/$S6 -> 0.19358285 | O26: =O6/$S6 -> 0.081950326 | P26: =P6/$S6 -> 0.10796994 | Q26: =Q6/$S6 -> 0.088169089 | R26: =R6/$S6 -> 0.034260425 | S26: =S6/$S6 -> 1 | U26: 2006 | V26: =V6/$AC6 -> 0.2763648 | W26: =W6/$AC6 -> 0.20050467 | X26: =X6/$AC6 -> 0.21968999 | Y26: =Y6/$AC6 -> 0.070493051 | Z26: =Z6/$AC6 -> 0.10638042 | AA26: =AA6/$AC6 -> 0.088556895 | AB26: =AB6/$AC6 -> 0.037970121 | AC26: =AC6/$AC6 -> 1 | AE26: 2006 | AF26: =(L26*$S6+V26*$AC6)/$I6 -> 0.25430699 | AG26: =(M26*$S6+W26*$AC6)/$I6 -> 0.20614279 | AH26: =(N26*$S6+X26*$AC6)/$I6 -> 0.19560224 | AI26: =(O26*$S6+Y26*$AC6)/$I6 -> 0.072394502 | AJ26: =(P26*$S6+Z26*$AC6)/$I6 -> 0.10162647 | AK26: =(Q26*$S6+AA26*$AC6)/$I6 -> 0.083768664 | AL26: =(R26*$S6+AB26*$AC6)/$I6 -> 0.034196584 | AM26: =(S26*$S6+AC26*$AC6)/$I6 -> 0.94805676
A27: 2007 | B27: The Categories are different in End-use Datas which reporting the end-use data | K27: 2007 | L27: =L7/$S7 -> 0.26087607 | M27: =M7/$S7 -> 0.23102532 | N27: =N7/$S7 -> 0.19092507 | O27: =O7/$S7 -> 0.078554595 | P27: =P7/$S7 -> 0.11079939 | Q27: =Q7/$S7 -> 0.09235776 | R27: =R7/$S7 -> 0.035461789 | S27: =S7/$S7 -> 1 | U27: 2007 | V27: =V7/$AC7 -> 0.27885646 | W27: =W7/$AC7 -> 0.19706174 | X27: =X7/$AC7 -> 0.21584276 | Y27: =Y7/$AC7 -> 0.067857852 | Z27: =Z7/$AC7 -> 0.10883462 | AA27: =AA7/$AC7 -> 0.092237443 | AB27: =AB7/$AC7 -> 0.039309113 | AC27: =AC7/$AC7 -> 1 | AE27: 2007 | AF27: =(L27*$S7+V27*$AC7)/$I7 -> 0.25580715 | AG27: =(M27*$S7+W27*$AC7)/$I7 -> 0.20357476 | AH27: =(N27*$S7+X27*$AC7)/$I7 -> 0.19262752 | AI27: =(O27*$S7+Y27*$AC7)/$I7 -> 0.069612735 | AJ27: =(P27*$S7+Z27*$AC7)/$I7 -> 0.10422721 | AK27: =(Q27*$S7+AA27*$AC7)/$I7 -> 0.087577901 | AL27: =(R27*$S7+AB27*$AC7)/$I7 -> 0.035418608 | AM27: =(S27*$S7+AC27*$AC7)/$I7 -> 0.94884588
A28: 2008 | B28: between 2007 and 2010 | K28: 2008 | L28: =L8/$S8 -> 0.26475578 | M28: =M8/$S8 -> 0.22526263 | N28: =N8/$S8 -> 0.19215913 | O28: =O8/$S8 -> 0.074185047 | P28: =P8/$S8 -> 0.11194542 | Q28: =Q8/$S8 -> 0.095520017 | R28: =R8/$S8 -> 0.036171979 | S28: =S8/$S8 -> 1 | U28: 2008 | V28: =V8/$AC8 -> 0.28723613 | W28: =W8/$AC8 -> 0.18940195 | X28: =X8/$AC8 -> 0.21771825 | Y28: =Y8/$AC8 -> 0.063643129 | Z28: =Z8/$AC8 -> 0.10829123 | AA28: =AA8/$AC8 -> 0.093917675 | AB28: =AB8/$AC8 -> 0.039830807 | AC28: =AC8/$AC8 -> 1 | AE28: 2008 | AF28: =(L28*$S8+V28*$AC8)/$I8 -> 0.26263675 | AG28: =(M28*$S8+W28*$AC8)/$I8 -> 0.19832047 | AH28: =(N28*$S8+X28*$AC8)/$I8 -> 0.19484682 | AI28: =(O28*$S8+Y28*$AC8)/$I8 -> 0.065891959 | AJ28: =(P28*$S8+Z28*$AC8)/$I8 -> 0.10503321 | AK28: =(Q28*$S8+AA28*$AC8)/$I8 -> 0.090314956 | AL28: =(R28*$S8+AB28*$AC8)/$I8 -> 0.03615105 | AM28: =(S28*$S8+AC28*$AC8)/$I8 -> 0.95317732
A29: 2009 | K29: 2009 | L29: =L9/$S9 -> 0.25336323 | M29: =M9/$S9 -> 0.23612668 | N29: =N9/$S9 -> 0.18721973 | O29: =O9/$S9 -> 0.075917881 | P29: =P9/$S9 -> 0.1097954 | Q29: =Q9/$S9 -> 0.09683296 | R29: =R9/$S9 -> 0.040779148 | S29: =S9/$S9 -> 1 | U29: 2009 | V29: =V9/$AC9 -> 0.28030536 | W29: =W9/$AC9 -> 0.19575725 | X29: =X9/$AC9 -> 0.21263618 | Y29: =Y9/$AC9 -> 0.062874022 | Z29: =Z9/$AC9 -> 0.10810189 | AA29: =AA9/$AC9 -> 0.096631886 | AB29: =AB9/$AC9 -> 0.043693417 | AC29: =AC9/$AC9 -> 1 | AE29: 2009 | AF29: =(L29*$S9+V29*$AC9)/$I9 -> 0.25184043 | AG29: =(M29*$S9+W29*$AC9)/$I9 -> 0.20514109 | AH29: =(N29*$S9+X29*$AC9)/$I9 -> 0.18858152 | AI29: =(O29*$S9+Y29*$AC9)/$I9 -> 0.065926452 | AJ29: =(P29*$S9+Z29*$AC9)/$I9 -> 0.10309886 | AK29: =(Q29*$S9+AA29*$AC9)/$I9 -> 0.091510627 | AL29: =(R29*$S9+AB29*$AC9)/$I9 -> 0.039891912 | AM29: =(S29*$S9+AC29*$AC9)/$I9 -> 0.94597357
A30: 2010 | K30: 2010 | L30: =L10/$S10 -> 0.24963453 | M30: =M10/$S10 -> 0.24187261 | N30: =N10/$S10 -> 0.18374521 | O30: =O10/$S10 -> 0.075809259 | P30: =P10/$S10 -> 0.10452489 | Q30: =Q10/$S10 -> 0.097981204 | R30: =R10/$S10 -> 0.046397494 | S30: =S10/$S10 -> 1 | U30: 2010 | V30: =V10/$AC10 -> 0.28857107 | W30: =W10/$AC10 -> 0.17768697 | X30: =X10/$AC10 -> 0.22022041 | Y30: =Y10/$AC10 -> 0.05863051 | Z30: =Z10/$AC10 -> 0.11255572 | AA30: =AA10/$AC10 -> 0.096458643 | AB30: =AB10/$AC10 -> 0.045938583 | AC30: =AC10/$AC10 -> 1 | AE30: 2010 | AF30: =(L30*$S10+V30*$AC10)/$I10 -> 0.20263374 | AG30: =(M30*$S10+W30*$AC10)/$I10 -> 0.16814508 | AH30: =(N30*$S10+X30*$AC10)/$I10 -> 0.15131173 | AI30: =(O30*$S10+Y30*$AC10)/$I10 -> 0.053513939 | AJ30: =(P30*$S10+Z30*$AC10)/$I10 -> 0.082557024 | AK30: =(Q30*$S10+AA30*$AC10)/$I10 -> 0.074885266 | AL30: =(R30*$S10+AB30*$AC10)/$I10 -> 0.035533256 | AM30: =(S30*$S10+AC30*$AC10)/$I10 -> 0.76858004
A31: 2011 | B31: 0.23 | C31: 0.19 | D31: 0.07 | E31: 0.1 | F31: 0.1 | G31: 0.25 | H31: 0.06 | I31: =SUM(B31:H31) -> 1 | K31: 2011 | L31: =L11/$S11 -> 0.24123018 | M31: =M11/$S11 -> 0.24716826 | N31: =N11/$S11 -> 0.18051074 | O31: =O11/$S11 -> 0.075650443 | P31: =P11/$S11 -> 0.099231139 | Q31: =Q11/$S11 -> 0.10108464 | R31: =R11/$S11 -> 0.055124597 | S31: =S11/$S11 -> 1 | U31: 2011 | V31: =V11/$AC11 -> 0.28858447 | W31: =W11/$AC11 -> 0.17844749 | X31: =X11/$AC11 -> 0.21704718 | Y31: =Y11/$AC11 -> 0.057351598 | Z31: =Z11/$AC11 -> 0.10733638 | AA31: =AA11/$AC11 -> 0.099969559 | AB31: =AB11/$AC11 -> 0.051202435 | AC31: =AC11/$AC11 -> 1 | AE31: 2011 | AF31: =(L31*$S11+V31*$AC11)/$I11 -> 0.2000476 | AG31: =(M31*$S11+W31*$AC11)/$I11 -> 0.17223677 | AH31: =(N31*$S11+X31*$AC11)/$I11 -> 0.1500017 | AI31: =(O31*$S11+Y31*$AC11)/$I11 -> 0.053479754 | AJ31: =(P31*$S11+Z31*$AC11)/$I11 -> 0.079114677 | AK31: =(Q31*$S11+AA31*$AC11)/$I11 -> 0.077975725 | AL31: =(R31*$S11+AB31*$AC11)/$I11 -> 0.041597253 | AM31: =(S31*$S11+AC31*$AC11)/$I11 -> 0.77447047
A32: 2012 | B32: 0.23 | C32: 0.19 | D32: 0.07 | E32: 0.09 | F32: 0.1 | G32: 0.26 | H32: 0.06 | I32: =SUM(B32:H32) -> 1 | K32: 2012 | L32: =L12/$S12 -> 0.23148274 | M32: =M12/$S12 -> 0.25112536 | N32: =N12/$S12 -> 0.1743623 | O32: =O12/$S12 -> 0.075296685 | P32: =P12/$S12 -> 0.093541127 | Q32: =Q12/$S12 -> 0.10568135 | R32: =R12/$S12 -> 0.068476333 | S32: =S12/$S12 -> 1 | U32: 2012 | V32: =V12/$AC12 -> 0.28483339 | W32: =W12/$AC12 -> 0.17959208 | X32: =X12/$AC12 -> 0.21042334 | Y32: =Y12/$AC12 -> 0.057512155 | Z32: =Z12/$AC12 -> 0.10227677 | AA32: =AA12/$AC12 -> 0.10636784 | AB32: =AB12/$AC12 -> 0.058994427 | AC32: =AC12/$AC12 -> 1 | AE32: 2012 | AF32: =(L32*$S12+V32*$AC12)/$I12 -> 0.19341921 | AG32: =(M32*$S12+W32*$AC12)/$I12 -> 0.1734132 | AH32: =(N32*$S12+X32*$AC12)/$I12 -> 0.14453047 | AI32: =(O32*$S12+Y32*$AC12)/$I12 -> 0.053026764 | AJ32: =(P32*$S12+Z32*$AC12)/$I12 -> 0.074551158 | AK32: =(Q32*$S12+AA32*$AC12)/$I12 -> 0.081642528 | AL32: =(R32*$S12+AB32*$AC12)/$I12 -> 0.050106788 | AM32: =(S32*$S12+AC32*$AC12)/$I12 -> 0.7707068
A33: 2013 | B33: 0.21 | C33: 0.19 | D33: 0.07 | E33: 0.09 | F33: 0.11 | G33: 0.26 | H33: 0.07 | I33: =SUM(B33:H33) -> 1 | K33: 2013 | L33: =L13/$S13 -> 0.25627435 | M33: =M13/$S13 -> 0.24269016 | N33: =N13/$S13 -> 0.19130191 | O33: =O13/$S13 -> 0.065779775 | P33: =P13/$S13 -> 0.084383446 | Q33: =Q13/$S13 -> 0.087928674 | R33: =R13/$S13 -> 0.071676788 | S33: =S13/$S13 -> 1 | U33: 2013 | V33: =V13/$AC13 -> 0.30625151 | W33: =W17/$AC17 -> 0.22910309 | X33: =X13/$AC13 -> 0.22048904 | Y33: =Y13/$AC13 -> 0.04956637 | Z33: =Z13/$AC13 -> 0.092989641 | AA33: =AA13/$AC13 -> 0.094736208 | AB33: =AB13/$AC13 -> 0.062334377 | AC33: =AC13/$AC13 -> 1 | AE33: 2013 | AF33: =(L33*$S13+V33*$AC13)/$I13 -> 0.21211083 | AG33: =(M33*$S13+W33*$AC13)/$I13 -> 0.18354673 | AH33: =(N33*$S13+X33*$AC13)/$I13 -> 0.1560263 | AI33: =(O33*$S13+Y33*$AC13)/$I13 -> 0.046186252 | AJ33: =(P33*$S13+Z33*$AC13)/$I13 -> 0.067609686 | AK33: =(Q33*$S13+AA33*$AC13)/$I13 -> 0.069835942 | AL33: =(R33*$S13+AB33*$AC13)/$I13 -> 0.05269377 | AM33: =(S33*$S13+AC33*$AC13)/$I13 -> 0.77221975
A34: 2014 | B34: 0.25 | C34: 0.18 | D34: 0.06 | E34: 0.09 | F34: 0.1 | G34: 0.25 | H34: 0.07 | I34: =SUM(B34:H34) -> 1 | K34: 2014 | L34: =L14/$S14 -> 0.24548252 | M34: =M14/$S14 -> 0.27242373 | N34: =N14/$S14 -> 0.19821265 | O34: =O14/$S14 -> 0.057352363 | P34: =P14/$S14 -> 0.075029462 | Q34: =Q14/$S14 -> 0.077157261 | R34: =R14/$S14 -> 0.074342019 | S34: =S14/$S14 -> 1 | U34: 2014 | V34: =V14/$AC14 -> 0.29261413 | W34: =W13/$AC13 -> 0.17363286 | X34: =X14/$AC14 -> 0.22255483 | Y34: =Y14/$AC14 -> 0.044614588 | Z34: =Z14/$AC14 -> 0.086062979 | AA34: =AA14/$AC14 -> 0.085717575 | AB34: =AB14/$AC14 -> 0.067238501 | AC34: =AC14/$AC14 -> 1 | AE34: 2014 | AF34: =(L34*$S14+V34*$AC14)/$I14 -> 0.2032305 | AG34: =(M34*$S14+W34*$AC14)/$I14 -> 0.18313966 | AH34: =(N34*$S14+X34*$AC14)/$I14 -> 0.16024875 | AI34: =(O34*$S14+Y34*$AC14)/$I14 -> 0.040817315 | AJ34: =(P34*$S14+Z34*$AC14)/$I14 -> 0.06116944 | AK34: =(Q34*$S14+AA34*$AC14)/$I14 -> 0.062122436 | AL34: =(R34*$S14+AB34*$AC14)/$I14 -> 0.055548377 | AM34: =(S34*$S14+AC34*$AC14)/$I14 -> 0.77401066
A35: 2015 | K35: 2015 | L35: =L15/$S15 -> 0.24770015 | M35: =M15/$S15 -> 0.27516159 | N35: =N15/$S15 -> 0.20984234 | O35: =O15/$S15 -> 0.051297835 | P35: =P15/$S15 -> 0.067439554 | Q35: =Q15/$S15 -> 0.070004446 | R35: =R15/$S15 -> 0.078519886 | S35: =S15/$S15 -> 1 | U35: 2015 | V35: =V15/$AC15 -> 0.28945197 | W35: =W14/$AC14 -> 0.20125497 | X35: =X15/$AC15 -> 0.22781379 | Y35: =Y15/$AC15 -> 0.040718916 | Z35: =Z15/$AC15 -> 0.079493223 | AA35: =AA15/$AC15 -> 0.078845021 | AB35: =AB15/$AC15 -> 0.072775486 | AC35: =AC15/$AC15 -> 1 | AE35: 2015 | AF35: =(L35*$S15+V35*$AC15)/$I15 -> 0.20186335 | AG35: =(M35*$S15+W35*$AC15)/$I15 -> 0.19034272 | AH35: =(N35*$S15+X35*$AC15)/$I15 -> 0.16610755 | AI35: =(O35*$S15+Y35*$AC15)/$I15 -> 0.036386887 | AJ35: =(P35*$S15+Z35*$AC15)/$I15 -> 0.055153287 | AK35: =(Q35*$S15+AA35*$AC15)/$I15 -> 0.056216162 | AL35: =(R35*$S15+AB35*$AC15)/$I15 -> 0.058640848 | AM35: =(S35*$S15+AC35*$AC15)/$I15 -> 0.76744611
A36: 2016 | K36: 2016 | L36: =L16/$S16 -> 0.25274689 | M36: =M16/$S16 -> 0.2729837 | N36: =N16/$S16 -> 0.22739349 | O36: =O16/$S16 -> 0.045229427 | P36: =P16/$S16 -> 0.0586769 | Q36: =Q16/$S16 -> 0.062087966 | R36: =R16/$S16 -> 0.080848831 | S36: =S16/$S16 -> 1 | U36: 2016 | V36: =V16/$AC16 -> 0.28749273 | W36: =W15/$AC15 -> 0.21096052 | X36: =X16/$AC16 -> 0.23728912 | Y36: =Y16/$AC16 -> 0.036823735 | Z36: =Z16/$AC16 -> 0.071320535 | AA36: =AA16/$AC16 -> 0.071611402 | AB36: =AB16/$AC16 -> 0.076788831 | AC36: =AC16/$AC16 -> 1 | AE36: 2016 | AF36: =(L36*$S16+V36*$AC16)/$I16 -> 0.20586273 | AG36: =(M36*$S16+W36*$AC16)/$I16 -> 0.19449228 | AH36: =(N36*$S16+X36*$AC16)/$I16 -> 0.17923469 | AI36: =(O36*$S16+Y36*$AC16)/$I16 -> 0.032747929 | AJ36: =(P36*$S16+Z36*$AC16)/$I16 -> 0.049073064 | AK36: =(Q36*$S16+AA36*$AC16)/$I16 -> 0.050847182 | AL36: =(R36*$S16+AB36*$AC16)/$I16 -> 0.06160582 | AM36: =(S36*$S16+AC36*$AC16)/$I16 -> 0.77603802
A37: 2017 | K37: 2017 | L37: =L17/$S17 -> 0.26092422 | M37: =M17/$S17 -> 0.27134398 | N37: =N17/$S17 -> 0.23955542 | O37: =O17/$S17 -> 0.040355926 | P37: =P17/$S17 -> 0.05037875 | Q37: =Q17/$S17 -> 0.054645893 | R37: =R17/$S17 -> 0.034269459 | S37: =S17/$S17 -> 1 | U37: 2017 | V37: =V17/$AC17 -> 0.28636391 | W37: =W16/$AC16 -> 0.21861547 | X37: =X17/$AC17 -> 0.24220667 | Y37: =Y17/$AC17 -> 0.034165021 | Z37: =Z17/$AC17 -> 0.063124514 | AA37: =AA17/$AC17 -> 0.064740023 | AB37: =AB17/$AC17 -> 0.032908514 | AC37: =AC17/$AC17 -> 1 | AE37: 2017 | AF37: =(L37*$S17+V37*$AC17)/$I17 -> 0.2112615 | AG37: =(M37*$S17+W37*$AC17)/$I17 -> 0.19763836 | AH37: =(N37*$S17+X37*$AC17)/$I17 -> 0.18819176 | AI37: =(O37*$S17+Y37*$AC17)/$I17 -> 0.029853981 | AJ37: =(P37*$S17+Z37*$AC17)/$I17 -> 0.042972396 | AK37: =(Q37*$S17+AA37*$AC17)/$I17 -> 0.045572743 | AL37: =(R37*$S17+AB37*$AC17)/$I17 -> 0.026436858 | AM37: =(S37*$S17+AC37*$AC17)/$I17 -> 0.78250433
A38: 2018 | K38: 2018 | L38: =L18/$S18 -> 0.27168414 | M38: =M18/$S18 -> 0.26483913 | N38: =N18/$S18 -> 0.23858338 | O38: =O18/$S18 -> 0.039780431 | P38: =P18/$S18 -> 0.04966767 | Q38: =Q18/$S18 -> 0.053867266 | R38: =R18/$S18 -> 0.033795179 | S38: =S18/$S18 -> 1 | U38: 2018 | V38: =V18/$AC18 -> 0.29305761 | W38: =W17/$AC17 -> 0.22910309 | X38: =X18/$AC18 -> 0.24454948 | Y38: =Y18/$AC18 -> 0.033677991 | Z38: =Z18/$AC18 -> 0.062274742 | AA38: =AA18/$AC18 -> 0.063810931 | AB38: =AB18/$AC18 -> 0.032437223 | AC38: =AC18/$AC18 -> 1 | AE38: 2018 | AF38: =(L38*$S18+V38*$AC18)/$I18 -> 0.21673548 | AG38: =(M38*$S18+W38*$AC18)/$I18 -> 0.1955253 | AH38: =(N38*$S18+X38*$AC18)/$I18 -> 0.18676492 | AI38: =(O38*$S18+Y38*$AC18)/$I18 -> 0.029164542 | AJ38: =(P38*$S18+Z38*$AC18)/$I18 -> 0.042044314 | AK38: =(Q38*$S18+AA38*$AC18)/$I18 -> 0.044561051 | AL38: =(R38*$S18+AB38*$AC18)/$I18 -> 0.025841791 | AM38: =(S38*$S18+AC38*$AC18)/$I18 -> 0.7758459
A39: 2019 | K39: 2019 | L39: =L19/$S19 -> 0.26066744 | M39: =M19/$S19 -> 0.27248879 | N39: =N19/$S19 -> 0.23360452 | O39: =O19/$S19 -> 0.041142288 | P39: =P19/$S19 -> 0.05203387 | Q39: =Q19/$S19 -> 0.055719741 | R39: =R19/$S19 -> 0.034932758 | S39: =S19/$S19 -> 1 | U39: 2019 | V39: =V19/$AC19 -> 0.285493 | W39: =W18/$AC18 -> 0.22351551 | X39: =X19/$AC19 -> 0.23711647 | Y39: =Y19/$AC19 -> 0.034971701 | Z39: =Z19/$AC19 -> 0.06541555 | AA39: =AA19/$AC19 -> 0.066190051 | AB39: =AB19/$AC19 -> 0.033661007 | AC39: =AC19/$AC19 -> 1 | AE39: 2019 | AF39: =(L39*$S19+V39*$AC19)/$I19 -> 0.207161 | AG39: =(M39*$S19+W39*$AC19)/$I19 -> 0.19594769 | AH39: =(N39*$S19+X39*$AC19)/$I19 -> 0.1804998 | AI39: =(O39*$S19+Y39*$AC19)/$I19 -> 0.029922163 | AJ39: =(P39*$S19+Z39*$AC19)/$I19 -> 0.043670627 | AK39: =(Q39*$S19+AA39*$AC19)/$I19 -> 0.045702581 | AL39: =(R39*$S19+AB39*$AC19)/$I19 -> 0.026497337 | AM39: =(S39*$S19+AC39*$AC19)/$I19 -> 0.76853748
A40: 2020 | K40: 2020 | L40: =L20/$S20 -> 0.25617848 | M40: =M20/$S20 -> 0.28174458 | N40: =N20/$S20 -> 0.23469077 | O40: =O20/$S20 -> 0.04017531 | P40: =P20/$S20 -> 0.050736547 | Q40: =Q20/$S20 -> 0.054419284 | R40: =R20/$S20 -> 0.034149014 | S40: =S20/$S20 -> 1 | U40: 2020 | V40: =V20/$AC20 -> 0.2831834 | W40: =W19/$AC19 -> 0.22871612 | X40: =X20/$AC20 -> 0.23831337 | Y40: =Y20/$AC20 -> 0.034052652 | Z40: =Z20/$AC20 -> 0.063634858 | AA40: =AA20/$AC20 -> 0.064517909 | AB40: =AB20/$AC20 -> 0.032838457 | AC40: =AC20/$AC20 -> 1 | AE40: 2020 | AF40: =(L40*$S20+V40*$AC20)/$I20 -> 0.20398699 | AG40: =(M40*$S20+W40*$AC20)/$I20 -> 0.20177528 | AH40: =(N40*$S20+X40*$AC20)/$I20 -> 0.181116 | AI40: =(O40*$S20+Y40*$AC20)/$I20 -> 0.029164659 | AJ40: =(P40*$S20+Z40*$AC20)/$I20 -> 0.042459648 | AK40: =(Q40*$S20+AA40*$AC20)/$I20 -> 0.044522404 | AL40: =(R40*$S20+AB40*$AC20)/$I20 -> 0.025852204 | AM40: =(S40*$S20+AC40*$AC20)/$I20 -> 0.76751084
A41: 2021 | K41: 2021 | L41: =L21/$S21 -> 0.25431195 | M41: =M21/$S21 -> 0.28877652 | N41: =N21/$S21 -> 0.22797493 | O41: =O21/$S21 -> 0.040358605 | P41: =P21/$S21 -> 0.051216032 | Q41: =Q21/$S21 -> 0.054659387 | R41: =R21/$S21 -> 0.034278446 | S41: =S21/$S21 -> 1 | U41: 2021 | V41: =V21/$AC21 -> 0.27986665 | W41: =W20/$AC20 -> 0.23621613 | X41: =X21/$AC21 -> 0.23221117 | Y41: =Y21/$AC21 -> 0.034429992 | Z41: =Z21/$AC21 -> 0.064651875 | AA41: =AA21/$AC21 -> 0.065198382 | AB41: =AB21/$AC21 -> 0.033173024 | AC41: =AC21/$AC21 -> 1 | AE41: 2021 | AF41: =(L41*$S21+V41*$AC21)/$I21 -> 0.19962231 | AG41: =(M41*$S21+W41*$AC21)/$I21 -> 0.20430273 | AH41: =(N41*$S21+X41*$AC21)/$I21 -> 0.17382833 | AI41: =(O41*$S21+Y41*$AC21)/$I21 -> 0.028941413 | AJ41: =(P41*$S21+Z41*$AC21)/$I21 -> 0.042475383 | AK41: =(Q41*$S21+AA41*$AC21)/$I21 -> 0.044288905 | AL41: =(R41*$S21+AB41*$AC21)/$I21 -> 0.025659088 | AM41: =(S41*$S21+AC41*$AC21)/$I21 -> 0.75739272
...

Sheet Commercial8EndUse
A1: Commercial Sector Energy Consumption by End-use
A2: Source: | B2: EMSD End Use 2023 | G2: NOTE --> from 2017 - 2021, referred to the corresponding ESMD End use report since there was no singular graph that showed total energy/ electiricty consumption by commercial end use with multiple years :. Had to refer to many previous iterations
B4: Energy | G4: Energy
D5: 2021 | E5: 2016 | H5: Air Conditioning | I5: Hot Water & Refrigeration | J5: Lighting | K5: Office Equipment | L5: Cooking | M5: Others | N5: Sum | O5: NOTE --> Others include vertical transport
G6: 2005 | H6: 0.28 | I6: 0.07 | J6: 0.16 | K6: 0.05 | L6: 0.15 | M6: 0.29 | N6: =SUM(H6:M6) -> 1
B7: 空气调节 | C7: Air Conditioning | D7: 0.25 | E7: 0.24 | G7: 2006 | H7: 0.27 | I7: 0.08 | J7: 0.15 | K7: 0.05 | L7: 0.15 | M7: 0.3 | N7: =SUM(H7:M7) -> 1
B8: 热水及冷冻 | C8: Hot Water & Refrigeration | D8: 0.09 | E8: 0.12 | G8: 2007 | H8: 0.27 | I8: 0.06 | J8: 0.15 | K8: 0.04 | L8: 0.11 | M8: 0.37 | N8: =SUM(H8:M8) -> 1
B9: 照明 | C9: Lighting | D9: 0.11 | E9: 0.12 | G9: 2008 | H9: 0.24 | I9: 0.1 | J9: 0.1 | K9: 0.05 | L9: 0.13 | M9: 0.38 | N9: =SUM(H9:M9) -> 1
B10: 办公设备 | C10: Office Equipment | D10: 0.05 | E10: 0.05 | G10: 2009 | H10: 0.24 | I10: 0.1 | J10: 0.1 | K10: 0.05 | L10: 0.13 | M10: 0.38 | N10: =SUM(H10:M10) -> 1
B11: 煮食 | C11: Cooking | D11: 0.11 | E11: 0.14 | G11: 2010 | H11: 0.25 | I11: 0.1 | J11: 0.12 | K11: 0.05 | L11: 0.13 | M11: 0.35 | N11: =SUM(H11:M11) -> 1 | Q11: Taken from EMSD Total Energy Consumption by End-Use
B12: 其他 | C12: Others | D12: 0.32 | E12: 0.33 | G12: 2011 | H12: 0.26 | I12: 0.12 | J12: 0.13 | K12: 0.05 | L12: 0.13 | M12: 0.31 | N12: =SUM(H12:M12) -> 1 | Q12: 116013
B13: Sum | E13: =SUM(E7:E12) -> 1 | G13: 2012 | H13: 0.25 | I13: 0.12 | J13: 0.13 | K13: 0.05 | L13: 0.14 | M13: 0.31 | N13: =SUM(H13:M13) -> 1 | Q13: 118330
G14: 2013 | H14: 0.26 | I14: 0.12 | J14: 0.13 | K14: 0.05 | L14: 0.14 | M14: 0.3 | N14: =SUM(H14:M14) -> 1 | Q14: 118209
G15: 2014 | H15: 0.26 | I15: 0.12 | J15: 0.13 | K15: 0.05 | L15: 0.14 | M15: 0.3 | N15: =SUM(H15:M15) -> 1 | Q15: 119615
G16: 2015 | H16: 0.25 | I16: 0.12 | J16: 0.12 | K16: 0.05 | L16: 0.14 | M16: 0.32 | N16: =SUM(H16:M16) -> 1 | Q16: 120417
G17: 2016 | H17: 0.24 | I17: 0.12 | J17: 0.12 | K17: 0.05 | L17: 0.14 | M17: 0.33 | N17: =SUM(H17:M17) -> 1 | Q17: 120458
G18: 2017 | H18: 0.25 | I18: 0.12 | J18: 0.12 | K18: 0.05 | L18: 0.13 | M18: 0.33 | N18: =SUM(H18:M18) -> 1 | Q18: 120408
G19: 2018 | H19: 0.26 | I19: 0.12 | J19: 0.12 | K19: 0.05 | L19: 0.14 | M19: 0.32 | N19: =SUM(H19:M19) -> 1.01 | Q19: 122220
G20: 2019 | H20: 0.22 | I20: 0.1 | J20: 0.1 | K20: 0.05 | L20: 0.13 | M20: 0.39 | N20: =SUM(H20:M20) -> 0.99 | Q20: 123001
G21: 2020 | H21: 0.25 | I21: 0.09 | J21: 0.11 | K21: 0.06 | L21: 0.1 | M21: 0.39 | N21: =SUM(H21:M21) -> 1 | Q21: 114512
G22: 2021 | H22: 0.25 | I22: 0.09 | J22: 0.11 | K22: 0.05 | L22: 0.11 | M22: 0.39 | N22: =SUM(H22:M22) -> 1 | Q22: 120083
B25: Electricity | G25: Electricity
D26: 2021 | E26: 2016 | H26: Air Conditioning | I26: Hot Water & Refrigeration | J26: Lighting | K26: Office Equipment | L26: Cooking | M26: Others | N26: Sum
B27: 空气调节 | C27: Air Conditioning | D27: 0.28 | E27: 0.29 | G27: 2005 | H27: 0.34 | I27: 0.03 | J27: 0.19 | K27: 0.07 | L27: 0.05 | M27: 0.32 | N27: =SUM(H27:M27) -> 1
B28: 热水及冷冻 | C28: Hot Water & Refrigeration | D28: 0.06 | E28: 0.08 | G28: 2006 | H28: 0.33 | I28: 0.05 | J28: 0.17 | K28: 0.06 | L28: 0.06 | M28: 0.33 | N28: =SUM(H28:M28) -> 1
B29: 照明 | C29: Lighting | D29: 0.12 | E29: 0.15 | G29: 2007 | H29: No data about electricity demand decomposition between 2007-2011
B30: 办公设备 | C30: Office Equipment | D30: 0.06 | E30: 0.06 | G30: 2008
B31: 煮食 | C31: Cooking | D31: 0.06 | E31: 0.07 | G31: 2009
B32: 其他 | C32: Others | D32: 0.34 | E32: 0.35 | G32: 2010
B33: Sum | E33: =SUM(E27:E32) -> 1 | G33: 2011
G34: 2012 | H34: 0.3 | I34: 0.08 | J34: 0.15 | K34: 0.06 | L34: 0.08 | M34: 0.33 | N34: =SUM(H34:M34) -> 1
G35: 2013 | H35: 0.3 | I35: 0.08 | J35: 0.16 | K35: 0.06 | L35: 0.08 | M35: 0.32 | N35: =SUM(H35:M35) -> 1
G36: 2014 | H36: 0.31 | I36: 0.08 | J36: 0.15 | K36: 0.06 | L36: 0.08 | M36: 0.32 | N36: =SUM(H36:M36) -> 1
G37: 2015 | H37: 0.29 | I37: 0.08 | J37: 0.15 | K37: 0.06 | L37: 0.07 | M37: 0.35 | N37: =SUM(H37:M37) -> 1
G38: 2016 | H38: 0.29 | I38: 0.08 | J38: 0.15 | K38: 0.06 | L38: 0.07 | M38: 0.35 | N38: =SUM(H38:M38) -> 1
G39: 2017 | H39: 0.3 | I39: 0.09 | J39: 0.14 | K39: 0.06 | L39: 0.07 | M39: 0.34 | N39: =SUM(H39:M39) -> 1
G40: 2018 | H40: 0.31 | I40: 0.09 | J40: 0.14 | K40: 0.06 | L40: 0.07 | M40: 0.34 | N40: =SUM(H40:M40) -> 1.01
G41: 2019 | H41: 0.25 | I41: 0.07 | J41: 0.12 | K41: 0.06 | L41: 0.07 | M41: 0.43 | N41: =SUM(H41:M41) -> 1
G42: 2020 | H42: 0.28 | I42: 0.06 | J42: 0.12 | K42: 0.06 | L42: 0.05 | M42: 0.42 | N42: =SUM(H42:M42) -> 0.99
G43: 2021 | H43: 0.28 | I43: 0.06 | J43: 0.12 | K43: 0.06 | L43: 0.06 | M43: 0.42 | N43: =SUM(H43:M43) -> 1
...

Sheet FloorAreaPer
A1: Median Per Capita Floor Area of Accommodation by Area of Residence, Household Size, Year and Type of Housing | J1: source:Population By-census, 2016
D2: Median Per Capita Floor Area of Accommodation(1)
D3: Square Metres
A4: Year | D4: 2016
A5: Type of Housing | D5: Public rental housing | E5: Subsidised home ownership housing | F5: Private permanent housing | G5: Others | H5: Overall
A6: Area of Residence | C6: Household Size
A7: Central and Western | C7: 1 | D7: 25 | E7: - | F7: 35 | G7: 19 | H7: 34
C8: 2 | D8: 13.5 | E8: - | F8: 20 | G8: 21.5 | H8: 19.5
C9: 3 | D9: 11.3 | E9: - | F9: 14.3 | G9: 12 | H9: 14.3
C10: 4 | D10: 8.8 | E10: - | F10: 12.3 | G10: 13.5 | H10: 11.8
C11: 5 | D11: 7.2 | E11: - | F11: 14 | G11: 14.8 | H11: 13.2
C12: 6 and over | D12: 5.7 | E12: - | F12: 17.3 | G12: 23.3 | H12: 16.7
C13: Sub-Total | D13: 11.5 | E13: - | F13: 20.5 | G13: 18.6 | H13: 20
A14: Wan Chai | C14: 1 | D14: 28 | E14: - | F14: 38 | G14: 15 | H14: 37
C15: 2 | D15: 14 | E15: - | F15: 22.5 | G15: 8.5 | H15: 21.5
C16: 3 | D16: 10.7 | E16: - | F16: 17 | G16: 11.3 | H16: 16.7
C17: 4 | D17: 8.5 | E17: - | F17: 15 | G17: 11.5 | H17: 14.5
C18: 5 | D18: 6.8 | E18: - | F18: 18 | G18: 11.2 | H18: 17.6
C19: 6 and over | D19: 6.5 | E19: - | F19: 16.1 | G19: 9.3 | H19: 15.7
C20: Sub-Total | D20: 12.5 | E20: - | F20: 23.3 | G20: 11.3 | H20: 22.4
A21: Eastern | C21: 1 | D21: 22 | E21: 45 | F21: 37 | G21: 21 | H21: 35
C22: 2 | D22: 15.5 | E22: 25 | F22: 22.5 | G22: 9.5 | H22: 21
C23: 3 | D23: 11.3 | E23: 16.7 | F23: 16.3 | G23: 18.7 | H23: 15
C24: 4 | D24: 8.8 | E24: 13 | F24: 13.5 | G24: 9.5 | H24: 12.3
C25: 5 | D25: 8 | E25: 10.8 | F25: 12.2 | G25: 3 | H25: 11
C26: 6 and over | D26: 7.2 | E26: 8.7 | F26: 10.7 | G26: 5.4 | H26: 9.2
C27: Sub-Total | D27: 11.5 | E27: 17.3 | F27: 17.7 | G27: 11.5 | H27: 16
A28: Southern | C28: 1 | D28: 24 | E28: 38 | F28: 46 | G28: 25 | H28: 35
C29: 2 | D29: 15 | E29: 19.5 | F29: 25.5 | G29: 16.5 | H29: 19
C30: 3 | D30: 11 | E30: 13 | F30: 18.3 | G30: 11.3 | H30: 13
C31: 4 | D31: 8.8 | E31: 11 | F31: 14.3 | G31: 13.8 | H31: 10.8
C32: 5 | D32: 7.2 | E32: 9.2 | F32: 13.8 | G32: 3.6 | H32: 11
C33: 6 and over | D33: 6 | E33: 7.7 | F33: 20.8 | G33: 12.1 | H33: 14
C34: Sub-Total | D34: 11.5 | E34: 14.7 | F34: 20.5 | G34: 16.8 | H34: 16
A35: Yau Tsim Mong | C35: 1 | D35: 19 | E35: 45 | F35: 33 | G35: 46 | H35: 34
C36: 2 | D36: 11.5 | E36: 24.8 | F36: 18.5 | G36: 23 | H36: 19
