Workbook
Name Average_emission_factor: '[1]Electricity emissions'!$H$38
Name footnote500011: FloorAreaPer!$A$170

Sheet About
A1: Sources:
B2: EMSD Energy End-use Data | C2: (Sheets:Energy8Sec, Residential8Fuel, Commercial8Fuel, Residential8EndUse, Commertial8EndUse)
B3: Hong Kong Energy End-use Data
B4: 2013-2018
B5: https://www.emsd.gov.hk/en/energy_efficiency/energy_end_use_data_and_consumption_indicators/hong_kong_energy_end_use_data/data/index.html
B6: Sheets:"Energy8Sec","Residential8Fuel","Commercial8Fuel","Residential8EndUse" and "Commercial8EndUse" are all from this data source.
B8: HK 2030 Report | F8: HK 2030: Baseline Review
B9: HK Development Bureau, HK Planning Department | F9: HK Development Bureau, HK Planning Department
B10: 2017 | F10: 2017
B11: Final Report | F11: Baseline Review: Population, Housing, Economy and Spatial Development Pattern
B12: https://www.pland.gov.hk/pland_en/p_study/comp_s/hk2030/eng/finalreport/ | F12: https://www.hk2030plus.hk/document/Baseline%20Review%20-%20Population_Housing_Economy%20and%20Spatial%20Development%20Pattern_Eng.pdf
B14: Household History Data(Sheet: Household_Histo) | F14: Household Prediction Data(Sheet: Household_Pred)
B15: Census and Statistics Department, HK | F15: Census and Statistics Department, HK
B16: 2019 | F16: 2019
B17: Table 005 : Statistics on Domestic Households | F17: Table E485 : Hong Kong Domestic Household Projections
B18: https://www.censtatd.gov.hk/hkstat/sub/sp150.jsp?tableID=005&ID=0&productType=8 | F18: https://www.censtatd.gov.hk/hkstat/sub/sp190.jsp?productCode=D5320185
B20: Floor Area Per capita (Sheet: FloorAreaPer)
B21: Population By-census
B22: 2017
B23: Table E129c: Median Per Capita Floor Area of Accommodation by Area of Residence, Household Size, Year and Type of Housing
B24: https://www.bycensus2016.gov.hk/en/bc-mt.html?search=E129c
B26: Building 2016 Data
B27: From Xiaoqian Jiang
B28: 2017
B29: From Excel "Copy of HK 2016 end use energy consumption rough 20190226 (added the building waste) revised2 lawrence.xlsx", Sheet"Building"
A32: Edition Log (WU Yazhen)
A33: 20190301_v1
A34: This part of data collection has not been finished.
A35: Next step: | B35: 1.Found Household Unit Composition to separate urban/rural residential
B36: 2.Use historical and predicted data of :Population, GDP, total residential area, total commercial arer, average number of people per household, average residential area per household
C37: to make linear or non-linear regression to predict future total energy consumption of residential/commercial sector of each fuel type.
C38: Then assuming the end-use composition stay unchanged throught the years, and the already-annouced building energy saving goal achieved.
C39: To predict future BAU End-use Data
A40: 20190304_v2
A41: Finished: | B41: 1.Found household history and prediction data.
B42: 2.Found Commercial AreaUse relative prediction ( average living area per household, household number; average living area per person, population) to predict residential area.
B43: 3.Done regression for estimating future residential energy consumption and
A44: 20190305_v3
A45: Finished: | B45: 1.Finished 1st version of Future Energy (End-use) Share Prediction.
B46: 2.Finished all calculation and got the final results, with TJ been converted to BTU.
...

Sheet Note
A1: Method
A2: Step1: Predict Future Total Energy Consumption by Segments using socioeconomic and energy intensity data
B3: predict per capita/per area energy consumption and then multiply it with population/area projections. Not directly predict total energy consumption by regression.
A4: Step2: Predict Future Energy Type Share by using trend function.
A5: Step3: Predict Future End-use share of different(electricity/non-electricity) type in residential energy use
A8: Assumptions & Classicification
A9: 1. "Coal and oil"(in statistics: energy consumption by fuel) is made up of 50% coal, 50% oil. And "Town gas &Oil gas" equals to natural gas
A10: 2. The end-use "Hot water" are categorized as "Appliance", not as part of the "Heating".
A11: 3. No energy consumption in "Heating"(In EPS model note, the "Heating" means distributed heating, which HK does not have), and thus
A12: 4. The end-use "Appliance" includes "Hot water &Refrigeration", "Office equipment" and "Cooking", while the category "Others" includes "Others" in the Residential/Commercial sector segment statistic.
A13: 5. The share of end-uses in all different non-electricity energy types are the same.
A15: Future considerations
A16: 1.The fact that older peole' energy demand is different and the HK population structure is changing
A17: 2. Classification of end-use categories. E.g. perhaps "Cooking" should be grouped into "Appliance" category, not "Others"?
A18: 3. Refer to BEC (HK Energy-saving Report)?
... A51: 10. Sheet "Future Energy Share", data in row 64-65 is currently not yet supported by valid material; they are assumed by me.

Sheet InternalLink
A2: About
A3: InternalLink
A4: Household_Histo
A5: Household_Pred
A6: Energy8Sec
A7: Residential8Fuel
A8: Commercial8Fuel
A9: Residential8EndUse
A10: Commercial8EndUse
A11: Commercial
A12: Residential
A13: Future Pred
... A18: Note

Sheet Household_Histo
A1: Table005: Statistics on Domestic Households
A3: Period | C3: Number of domestic households ('000) | D3: Average domestic household size | E3: Owner-occupiers as a proportion of total number of domestic households (%) | F3: Owner-occupiers in public sector housing as a proportion of total number of domestic households in public sector housing (%) | G3: Owner-occupiers in private sector housing as a proportion of total number of domestic households in private sector housing (%)
A4: 1982 | C4: 1311.6 | D4: 3.9 | E4: 28.7 | F4: N.A. | G4: N.A.
A5: 1983 | C5: 1334.3 | D5: 3.9 | E5: 30.7 | F5: N.A. | G5: N.A.
A6: 1984 | C6: 1378.7 | D6: 3.7 | E6: 31.2 | F6: N.A. | G6: N.A.
A7: 1985 | C7: 1417.7 | D7: 3.7 | E7: 32.8 | F7: 6.6 | G7: 51.8
A8: 1986 | C8: 1473.1 | D8: 3.6 | E8: 34.9 | F8: 9.1 | G8: 53.9
A9: 1987 | C9: 1496.1 | D9: 3.6 | E9: 37.9 | F9: 10.1 | G9: 59.1
A10: 1988 | C10: 1532.6 | D10: 3.6 | E10: 39.4 | F10: 11.9 | G10: 60.8
A11: 1989 | C11: 1549 | D11: 3.6 | E11: 41.6 | F11: 12.9 | G11: 64.5
A12: 1990 | C12: 1559 | D12: 3.5 | E12: 42.6 | F12: 14.2 | G12: 66.3
A13: 1991 | C13: 1601.9 | D13: 3.5 | E13: 43.1 | F13: 15.8 | G13: 66.5
A14: 1992 | C14: 1633.5 | D14: 3.4 | E14: 43.5 | F14: 16.3 | G14: 68
A15: 1993 | C15: 1677.7 | D15: 3.5 | E15: 44.6 | F15: 18.2 | G15: 68.6
A16: 1994 | C16: 1729.1 | D16: 3.4 | E16: 45.1 | F16: 20.5 | G16: 67.8
A17: 1995 | C17: 1783 | D17: 3.4 | E17: 45.2 | F17: 21.6 | G17: 67.3
A18: 1996 | C18: 1864.5 | D18: 3.4 | E18: 45.9 | F18: 21.9 | G18: 67.1
... A39: 2017 | C39: 2534.7 | D39: 2.8 | E39: 49.2 | F39: 31.8 | G39: 63.8
A40: 10/1981 - 12/1981 | C40: 1297.7 | D40: 3.8 | E40: 28.7 | F40: N.A. | G40: N.A.
A41: 1/1982 - 3/1982 | C41: 1297.4 | D41: 3.9 | E41: 28.3 | F41: N.A. | G41: N.A.
A42: 4/1982 - 6/1982 | C42: 1317.5 | D42: 3.9 | E42: 28.5 | F42: N.A. | G42: N.A.
A43: 7/1982 - 9/1982 | C43: 1312.3 | D43: 3.9 | E43: 29 | F43: N.A. | G43: N.A.
A44: 10/1982 - 12/1982 | C44: 1319.3 | D44: 3.9 | E44: 29 | F44: N.A. | G44: N.A.
A45: 1/1983 - 3/1983 | C45: 1320.1 | D45: 3.9 | E45: 31.1 | F45: N.A. | G45: N.A.
A46: 4/1983 - 6/1983 | C46: 1330.5 | D46: 3.9 | E46: 30.9 | F46: N.A. | G46: N.A.
A47: 7/1983 - 9/1983 | C47: 1336.9 | D47: 3.8 | E47: 30.3 | F47: N.A. | G47: N.A.
A48: 10/1983 - 12/1983 | C48: 1349.9 | D48: 3.8 | E48: 30.3 | F48: N.A. | G48: N.A.
A49: 1/1984 - 3/1984 | C49: 1345.4 | D49: 3.8 | E49: 30.9 | F49: N.A. | G49: N.A.
A50: 4/1984 - 6/1984 | C50: 1378.1 | D50: 3.8 | E50: 30.9 | F50: N.A. | G50: N.A.
A51: 7/1984 - 9/1984 | C51: 1386.3 | D51: 3.7 | E51: 31.8 | F51: N.A. | G51: N.A.
A52: 10/1984 - 12/1984 | C52: 1405 | D52: 3.7 | E52: 31.3 | F52: N.A. | G52: N.A.
A53: 1/1985 - 3/1985 | C53: 1402.9 | D53: 3.7 | E53: 31.4 | F53: 5.9 | G53: 50.2
A54: 4/1985 - 6/1985 | C54: 1416.7 | D54: 3.7 | E54: 32.8 | F54: 6.3 | G54: 51.6
A55: 7/1985 - 9/1985 | C55: 1416.5 | D55: 3.7 | E55: 33.9 | F55: 6.9 | G55: 53.6
A56: 10/1985 - 12/1985 | C56: 1434.7 | D56: 3.7 | E56: 33.2 | F56: 7.3 | G56: 51.8
A57: 1/1986 - 3/1986 | C57: 1453 | D57: 3.7 | E57: 32.9 | F57: 7.9 | G57: 50.6
A58: 4/1986 - 6/1986 | C58: 1469.7 | D58: 3.6 | E58: 34 | F58: 9 | G58: 52
A59: 7/1986 - 9/1986 | C59: 1481.4 | D59: 3.6 | E59: 36 | F59: 9.5 | G59: 56.4
A60: 10/1986 - 12/1986 | C60: 1488.2 | D60: 3.6 | E60: 36.5 | F60: 9.9 | G60: 56.9
A61: 1/1987 - 3/1987 | C61: 1478.3 | D61: 3.6 | E61: 37.1 | F61: 9.9 | G61: 57.7
...

Sheet Household_Pred
A1: 表 1 | B1: 家庭住戶數目及平均住戶人數
A2: Table 1 | B2: Number of domestic households and average household size
A4: 年份 | B4: 家庭住戶數目 | C4: 前五年內平均每年增幅 | D4: 平均住戶人數
A5: Year | B5: Number of domestic households | C5: Average annual growth over the past 5 years | D5: Average household size
A7: 1981 | B7: 1244700 | C7: - | D7: 3.9
A8: 1986 | B8: 1452600 | C8: 41600 | D8: 3.7
A9: 1991 | B9: 1582200 | C9: 25900 | D9: 3.4
A10: 1996 | B10: 1855600 | C10: 54700 | D10: 3.3
A11: 2001 | B11: 2053400 | C11: 39600 | D11: 3.1
A12: 2006 | B12: 2226500 | C12: 34600 | D12: 3
A13: 2011 | B13: 2368800 | C13: 28500 | D13: 2.9
A14: 2016 | B14: 2509700 | C14: 28200 | D14: 2.8
A15: 2021 | B15: 2657000 | C15: 29400 | D15: 2.8
A16: 2026 | B16: 2768900 | C16: 22400 | D16: 2.7
A17: 2031 | B17: 2854500 | C17: 17100 | D17: 2.7
A18: 2036 | B18: 2920200 | C18: 13100 | D18: 2.7
A19: 2041 | B19: 2961400 | C19: 8200 | D19: 2.7
... A21: 2051 | B21: 2949500 | C21: -4500 | D21: 2.7
A23: 註釋： | B23: 虛線以下的數字是推算數字。
B24: 推算結果反映若過往有關生育、死亡、人口遷移及戶主率的人口趨勢仍延續，未來的整體趨勢情況。要注意的是由於未來可能會發生現階段不能預見及預測的情況，因此，有關未來趨勢的假設亦受制於這些不確定因素的發展。
A26: Notes : | B26: Figures below the broken lines are based on projections.
B27: The projection results aim at illustrating what would happen if the past demographic trends on fertility, mortality, movement and headship rates continue into the future. It should however be noted that the assumptions of future trends are subject to uncertainties arising from unforeseeable and unpredictable future events.

Sheet History Type Share
A1: Residential Energy Use by Fuel
A2: Source: | B2: EMSD End-use Data report 2023
A3: 住宅 Residential
A4: 年份 Year | B4: 煤氣及石油氣* Town Gas & Liquefied Petroleum Gas* | D4: 油及煤產品 Oil & Coal Products | F4: 電力 Electricity | H4: 總計 Total
A5: 2006 | B5: 18476 | C5: 0.34 | D5: 79 | E5: 0 | F5: 35428 | G5: 0.66 | H5: 53982
A6: 2007 | B6: 18238 | C6: 0.33 | D6: 57 | E6: 0 | F6: 36422 | G6: 0.67 | H6: 54717
A7: 2008 | B7: 18708 | C7: 0.33 | D7: 41 | E7: 0 | F7: 37100 | G7: 0.66 | H7: 55849
A8: 2009 | B8: 18736 | C8: 0.32 | D8: 23 | E8: 0 | F8: 38972 | G8: 0.68 | H8: 57731
A9: 2010 | B9: 19038 | C9: 0.33 | D9: 13 | E9: 0 | F9: 39344 | G9: 0.67 | H9: 58396
A10: 2011 | B10: 18977 | C10: 0.32 | D10: 8 | E10: 0 | F10: 39872 | G10: 0.68 | H10: 58857
A11: 2012 | B11: 18841 | C11: 0.31 | D11: 8 | E11: 0 | F11: 41189 | G11: 0.69 | H11: 60037
A12: 2013 | B12: 18635 | C12: 0.32 | D12: 7 | E12: 0 | F12: 39941 | G12: 0.68 | H12: 58582
A13: 2014 | B13: 18681 | C13: 0.3 | D13: 7 | E13: 0 | F13: 43415 | G13: 0.7 | H13: 62103
A14: 2015 | B14: 18063 | C14: 0.3 | D14: 8 | E14: 0 | F14: 42368 | G14: 0.7 | H14: 60439
A15: 2016 | B15: 18574 | C15: 0.3 | D15: 10 | E15: 0 | F15: 43120 | G15: 0.7 | H15: 61704
A16: 2017 | B16: 18335 | C16: 0.3 | D16: 14 | E16: 0 | F16: 42127 | G16: 0.7 | H16: 60476
... A20: 2021 | B20: 19242 | C20: 0.29 | D20: 15 | E20: 0 | F20: 47464 | G20: 0.7 | H20: 66721
A23: Commercial Energy Use by Fuel
A24: Source: | B24: EMSD End-use Data report 2022#
A25: 商业 Commercial
A26: 年份 Year | B26: 煤氣及石油氣* Town Gas & Liquefied Petroleum Gas* | D26: 油及煤產品 Oil & Coal Products | F26: 電力 Electricity | H26: 總計 Total
A27: 2006 | B27: 13631 | C27: 0.12 | D27: 4936 | E27: 0.04 | F27: 93317 | G27: 0.83 | H27: 111884
A28: 2007 | B28: 13888 | C28: 0.12 | D28: 4975 | E28: 0.04 | F28: 95051 | G28: 0.83 | H28: 113914
A29: 2008 | B29: 13471 | C29: 0.12 | D29: 4739 | E29: 0.04 | F29: 95543 | G29: 0.84 | H29: 113753
A30: 2009 | B30: 12815 | C30: 0.11 | D30: 4753 | E30: 0.04 | F30: 96728 | G30: 0.85 | H30: 114297
A31: 2010 | B31: 13971 | C31: 0.12 | D31: 4526 | E31: 0.04 | F31: 97894 | G31: 0.84 | H31: 116391
A32: 2011 | B32: 14129 | C32: 0.12 | D32: 1979 | E32: 0.02 | F32: 99905 | G32: 0.86 | H32: 116013
A33: 2012 | B33: 14280 | C33: 0.12 | D33: 1696 | E33: 0.01 | F33: 102353 | G33: 0.86 | H33: 118330
A34: 2013 | B34: 14512 | C34: 0.12 | D34: 1477 | E34: 0.01 | F34: 102221 | G34: 0.86 | H34: 118209
A35: 2014 | B35: 14713 | C35: 0.12 | D35: 1431 | E35: 0.01 | F35: 103471 | G35: 0.87 | H35: 119615
A36: 2015 | B36: 14535 | C36: 0.12 | D36: 1235 | E36: 0.01 | F36: 104647 | G36: 0.87 | H36: 120417
A37: 2016 | B37: 14601 | C37: 0.12 | D37: 1019 | E37: 0.01 | F37: 104839 | G37: 0.87 | H37: 120458
A38: 2017 | B38: 14908 | C38: 0.12 | D38: 830 | E38: 0.01 | F38: 104669 | G38: 0.87 | H38: 120408
... A42: 2021 | B42: 12353 | C42: 0.1 | D42: 490 | E42: 0 | F42: 107240 | G42: 0.89 | H42: 120083

Sheet Commercial8Fuel
A1: Commercial Energy Use by Fuel
A2: Source: | B2: EMSD End-use Data report 2023
A3: 商业 Commercial
A4: 年份 Year | B4: 煤氣及石油氣* Town Gas & Liquefied Petroleum Gas* | D4: 油及煤產品 Oil & Coal Products | F4: 電力 Electricity | H4: 總計 Total
A5: 2006 | B5: 13631 | C5: 0.12 | D5: 4936 | E5: 0.04 | F5: 93317 | G5: 0.86 | H5: 111884
A6: 2007 | B6: 13888 | C6: 0.12 | D6: 4975 | E6: 0.04 | F6: 95051 | G6: 0.86 | H6: 113914
A7: 2008 | B7: 13471 | C7: 0.12 | D7: 4739 | E7: 0.04 | F7: 95543 | G7: 0.86 | H7: 113753
A8: 2009 | B8: 12815 | C8: 0.11 | D8: 4753 | E8: 0.04 | F8: 96728 | G8: 0.87 | H8: 114297
A9: 2010 | B9: 13971 | C9: 0.12 | D9: 4526 | E9: 0.04 | F9: 97894 | G9: 0.87 | H9: 116391
A10: 2011 | B10: 14129 | C10: 0.12 | D10: 1979 | E10: 0.02 | F10: 99905 | G10: 0.87 | H10: 116013
A11: 2012 | B11: 14280 | C11: 0.12 | D11: 1696 | E11: 0.01 | F11: 102353 | G11: 0.87 | H11: 118330
A12: 2013 | B12: 14512 | C12: 0.12 | D12: 1477 | E12: 0.01 | F12: 102221 | G12: 0.87 | H12: 118209
A13: 2014 | B13: 14713 | C13: 0.12 | D13: 1431 | E13: 0.01 | F13: 103471 | G13: 0.87 | H13: 119615
A14: 2015 | B14: 14535 | C14: 0.12 | D14: 1235 | E14: 0.01 | F14: 104647 | G14: 0.87 | H14: 120417
A15: 2016 | B15: 14601 | C15: 0.12 | D15: 1019 | E15: 0.01 | F15: 104839 | G15: 0.87 | H15: 120458
A16: 2017 | B16: 14908 | C16: 0.12 | D16: 830 | E16: 0.01 | F16: 104669 | G16: 0.87 | H16: 120408
... A20: 2021 | B20: 12353 | C20: 0.1 | D20: 490 | E20: 0 | F20: 107240 | G20: 0.89 | H20: 120083

Sheet Energy8Sec
A1: All Energy/Electricity Consumption by Sector
A2: Source: | B2: EMSD End-use Data report 2018
A3: P23
A5: 终端能源使用All Energy Consumption By Sectors | F5: Unit:Terajoule | H5: Sectors Energy Consumption Percentage
A6: Year | B6: 住宅 Residential | C6: 商业 Commercial | D6: 工业 Industrial | E6: 运输 Transport | F6: 总计 Total | H6: Year | I6: 住宅 Residential | J6: 商业 Commercial | K6: 工业 Industrial | L6: 运输 Transport | M6: 总计 Total
A7: 2006 | B7: 53982 | C7: 111884 | D7: 18934 | E7: 96404 | F7: =SUM(B7:E7) -> 281204 | H7: 2006 | I7: =B7/$F7 -> 0.1919674 | J7: =C7/$F7 -> 0.39787485 | K7: =D7/$F7 -> 0.067331901 | L7: =E7/$F7 -> 0.34282585 | M7: =F7/$F7 -> 1
A8: 2007 | B8: 54717 | C8: 113914 | D8: 17645 | E8: 96165 | F8: =SUM(B8:E8) -> 282441 | H8: 2007 | I8: =B8/$F8 -> 0.19372896 | J8: =C8/$F8 -> 0.40331963 | K8: =D8/$F8 -> 0.062473224 | L8: =E8/$F8 -> 0.34047819 | M8: =F8/$F8 -> 1
A9: 2008 | B9: 55849 | C9: 113753 | D9: 17332 | E9: 94504 | F9: =SUM(B9:E9) -> 281438 | H9: 2008 | I9: =B9/$F9 -> 0.19844158 | J9: =C9/$F9 -> 0.40418494 | K9: =D9/$F9 -> 0.061583724 | L9: =E9/$F9 -> 0.33578977 | M9: =F9/$F9 -> 1
A10: 2009 | B10: 57731 | C10: 114297 | D10: 16129 | E10: 90643 | F10: =SUM(B10:E10) -> 278800 | H10: 2009 | I10: =B10/$F10 -> 0.20706958 | J10: =C10/$F10 -> 0.40996055 | K10: =D10/$F10 -> 0.057851506 | L10: =E10/$F10 -> 0.32511836 | M10: =F10/$F10 -> 1
A11: 2010 | B11: 58396 | C11: 116391 | D11: 16053 | E11: 90889 | F11: =SUM(B11:E11) -> 281729 | H11: 2010 | I11: =B11/$F11 -> 0.20727721 | J11: =C11/$F11 -> 0.41313106 | K11: =D11/$F11 -> 0.05698029 | L11: =E11/$F11 -> 0.32261145 | M11: =F11/$F11 -> 1
A12: 2011 | B12: 58826 | C12: 118558 | D12: 14732 | E12: 90774 | F12: =SUM(B12:E12) -> 282890 | H12: 2011 | I12: =B12/$F12 -> 0.20794655 | J12: =C12/$F12 -> 0.41909576 | K12: =D12/$F12 -> 0.052076779 | L12: =E12/$F12 -> 0.32088091 | M12: =F12/$F12 -> 1
A13: 2012 | B13: 59932 | C13: 120970 | D13: 14723 | E13: 90423 | F13: =SUM(B13:E13) -> 286048 | H13: 2012 | I13: =B13/$F13 -> 0.20951728 | J13: =C13/$F13 -> 0.42290105 | K13: =D13/$F13 -> 0.051470383 | L13: =E13/$F13 -> 0.31611128 | M13: =F13/$F13 -> 1
A14: 2013 | B14: 58394 | C14: 121215 | D14: 14583 | E14: 90198 | F14: =SUM(B14:E14) -> 284390 | H14: 2013 | I14: =B14/$F14 -> 0.20533071 | J14: =C14/$F14 -> 0.42622807 | K14: =D14/$F14 -> 0.051278174 | L14: =E14/$F14 -> 0.31716305 | M14: =F14/$F14 -> 1
A15: 2014 | B15: 61910 | C15: 122711 | D15: 14718 | E15: 89999 | F15: =SUM(B15:E15) -> 289338 | H15: 2014 | I15: =B15/$F15 -> 0.2139712 | J15: =C15/$F15 -> 0.42410952 | K15: =D15/$F15 -> 0.050867843 | L15: =E15/$F15 -> 0.31105143 | M15: =F15/$F15 -> 1
A16: 2015 | B16: 60214 | C16: 123674 | D16: 14853 | E16: 89245 | F16: =SUM(B16:E16) -> 287986 | H16: 2015 | I16: =B16/$F16 -> 0.20908655 | J16: =C16/$F16 -> 0.42944449 | K16: =D16/$F16 -> 0.051575424 | L16: =E16/$F16 -> 0.30989354 | M16: =F16/$F16 -> 1
A17: 2016 | B17: 61439 | C17: 123969 | D17: 13992 | E17: 89819 | F17: =SUM(B17:E17) -> 289219 | H17: 2016 | I17: =B17/$F17 -> 0.21243072 | J17: =C17/$F17 -> 0.42863367 | K17: =D17/$F17 -> 0.048378564 | L17: =E17/$F17 -> 0.31055705 | M17: =F17/$F17 -> 1
A18: 2017 | B18: 60476 | C18: 120408 | D18: 12722 | E18: 86557 | F18: 280162 | H18: 2017 | I18: =B18/$F18 -> 0.21586082 | J18: =C18/$F18 -> 0.42977991 | K18: =D18/$F18 -> 0.045409442 | L18: =E18/$F18 -> 0.30895339 | M18: =F18/$F18 -> 1
A19: 2018 | B19: 61556 | C19: 122220 | D19: 12829 | E19: 85054 | F19: 281659 | H19: 2018 | I19: =B19/$F19 -> 0.21854796 | J19: =C19/$F19 -> 0.43392897 | K19: =D19/$F19 -> 0.045547985 | L19: =E19/$F19 -> 0.30197508 | M19: =F19/$F19 -> 1
A20: 2019 | B20: 61021 | C20: 123001 | D20: 12274 | E20: 85877 | F20: 282174 | H20: 2019 | I20: =B20/$F20 -> 0.21625309 | J20: =C20/$F20 -> 0.4359048 | K20: =D20/$F20 -> 0.043497984 | L20: =E20/$F20 -> 0.30434058 | M20: =F20/$F20 -> 1
A21: 2020 | B21: 66413 | C21: 114512 | D21: 12161 | E21: 78514 | F21: 271600 | H21: 2020 | I21: =B21/$F21 -> 0.24452504 | J21: =C21/$F21 -> 0.42162003 | K21: =D21/$F21 -> 0.044775405 | L21: =E21/$F21 -> 0.28907953 | M21: =F21/$F21 -> 1
A22: 2021 | B22: 66721 | C22: 120083 | D22: 11945 | E22: 81158 | F22: 279907 | H22: 2021 | I22: =B22/$F22 -> 0.23836846 | J22: =C22/$F22 -> 0.42901035 | K22: =D22/$F22 -> 0.042674888 | L22: =E22/$F22 -> 0.2899463 | M22: =F22/$F22 -> 1
A25: 电力使用 Electricity Consuption By Sectors | H25: Sectors Electricity Consumption Percentage
A26: Year | B26: 住宅 Residential | C26: 商业 Commercial | D26: 工业 Industrial | E26: 运输 Transport | F26: 总计 Total | H26: Year | I26: 住宅 Residential | J26: 商业 Commercial | K26: 工业 Industrial | L26: 运输 Transport | M26: 总计 Total | O26: Check
A27: 2006 | B27: 35428 | C27: 93317 | D27: 14015 | E27: 2444 | F27: =SUM(B27:E27) -> 145204 | H27: 2006 | I27: =B27/$F27 -> 0.24398777 | J27: =C27/$F27 -> 0.64266136 | K27: =D27/$F27 -> 0.09651938 | L27: =E27/$F27 -> 0.016831492 | M27: =F27/$F27 -> 1 | O27: =B7*'History Type Share'!G5 -> 35628.12
A28: 2007 | B28: 36422 | C28: 95051 | D28: 13104 | E28: 2495 | F28: =SUM(B28:E28) -> 147072 | H28: 2007 | I28: =B28/$F28 -> 0.24764741 | J28: =C28/$F28 -> 0.64628889 | K28: =D28/$F28 -> 0.089099217 | L28: =E28/$F28 -> 0.01696448 | M28: =F28/$F28 -> 1 | O28: =B8*'History Type Share'!G6 -> 36660.39
A29: 2008 | B29: 37100 | C29: 95543 | D29: 12182 | E29: 2520 | F29: =SUM(B29:E29) -> 147345 | H29: 2008 | I29: =B29/$F29 -> 0.25179002 | J29: =C29/$F29 -> 0.64843055 | K29: =D29/$F29 -> 0.082676711 | L29: =E29/$F29 -> 0.017102718 | M29: =F29/$F29 -> 1 | O29: =B9*'History Type Share'!G7 -> 36860.34
A30: 2009 | B30: 38972 | C30: 96728 | D30: 11143 | E30: 2523 | F30: =SUM(B30:E30) -> 149366 | H30: 2009 | I30: =B30/$F30 -> 0.26091614 | J30: =C30/$F30 -> 0.64759048 | K30: =D30/$F30 -> 0.074601984 | L30: =E30/$F30 -> 0.016891394 | M30: =F30/$F30 -> 1 | O30: =B10*'History Type Share'!G8 -> 39257.08
A31: 2010 | B31: 39344 | C31: 97894 | D31: 11082 | E31: 2540 | F31: =SUM(B31:E31) -> 150860 | H31: 2010 | I31: =B31/$F31 -> 0.26079809 | J31: =C31/$F31 -> 0.64890627 | K31: =D31/$F31 -> 0.073458836 | L31: =E31/$F31 -> 0.016836802 | M31: =F31/$F31 -> 1 | O31: =B11*'History Type Share'!G9 -> 39125.32
A32: 2011 | B32: 39872 | C32: 99594 | D32: 9530 | E32: 2609 | F32: =SUM(B32:E32) -> 151605 | H32: 2011 | I32: =B32/$F32 -> 0.26299924 | J32: =C32/$F32 -> 0.65693084 | K32: =D32/$F32 -> 0.062860724 | L32: =E32/$F32 -> 0.017209195 | M32: =F32/$F32 -> 1 | O32: =B12*'History Type Share'!G10 -> 40001.68
A33: 2012 | B33: 41189 | C33: 101813 | D33: 9356 | E33: 2722 | F33: =SUM(B33:E33) -> 155080 | H33: 2012 | I33: =B33/$F33 -> 0.2655984 | J33: =C33/$F33 -> 0.65651922 | K33: =D33/$F33 -> 0.060330152 | L33: =E33/$F33 -> 0.017552231 | M33: =F33/$F33 -> 1 | O33: =B13*'History Type Share'!G11 -> 41353.08
A34: 2013 | B34: 39941 | C34: 101480 | D34: 9144 | E34: 2796 | F34: =SUM(B34:E34) -> 153361 | H34: 2013 | I34: =B34/$F34 -> 0.26043779 | J34: =C34/$F34 -> 0.66170669 | K34: =D34/$F34 -> 0.059624024 | L34: =E34/$F34 -> 0.018231493 | M34: =F34/$F34 -> 1 | O34: =B14*'History Type Share'!G12 -> 39707.92
A35: 2014 | B35: 43415 | C35: 102627 | D35: 9230 | E35: 2875 | F35: =SUM(B35:E35) -> 158147 | H35: 2014 | I35: =B35/$F35 -> 0.27452307 | J35: =C35/$F35 -> 0.64893422 | K35: =D35/$F35 -> 0.058363421 | L35: =E35/$F35 -> 0.018179289 | M35: =F35/$F35 -> 1 | O35: =B15*'History Type Share'!G13 -> 43337
A36: 2015 | B36: 42368 | C36: 103693 | D36: 9242 | E36: 2972 | F36: =SUM(B36:E36) -> 158275 | H36: 2015 | I36: =B36/$F36 -> 0.26768599 | J36: =C36/$F36 -> 0.65514453 | K36: =D36/$F36 -> 0.058392039 | L36: =E36/$F36 -> 0.018777444 | M36: =F36/$F36 -> 1 | O36: =B16*'History Type Share'!G14 -> 42149.8
A37: 2016 | B37: 43120 | C37: 103881 | D37: 8709 | E37: 2951 | F37: =SUM(B37:E37) -> 158661 | H37: 2016 | I37: =B37/$F37 -> 0.27177441 | J37: =C37/$F37 -> 0.65473557 | K37: =D37/$F37 -> 0.054890616 | L37: =E37/$F37 -> 0.018599404 | M37: =F37/$F37 -> 1 | O37: =B17*'History Type Share'!G15 -> 43007.3
A38: 2017 | B38: 42127 | C38: 104669 | D38: 7963 | E38: 3218 | F38: =SUM(B38:E38) -> 157977 | H38: 2017 | I38: =B38/$F38 -> 0.2666654 | J38: =C38/$F38 -> 0.66255847 | K38: =D38/$F38 -> 0.050406072 | L38: =E38/$F38 -> 0.020370054 | M38: =F38/$F38 -> 1 | O38: =B18*'History Type Share'!G16 -> 42333.2
... A42: 2021 | B42: 47464 | C42: 107240 | D42: 7222 | E42: 3002 | F42: =SUM(B42:E42) -> 164928 | H42: 2021 | I42: =B42/$F42 -> 0.28778619 | J42: =C42/$F42 -> 0.65022313 | K42: =D42/$F42 -> 0.043788805 | L42: =E42/$F42 -> 0.018201882 | M42: =F42/$F42 -> 1 | O42: =B22*'History Type Share'!G20 -> 46704.7
A44: Year | B44: Residential (Unit : Terajoule) | C44: Commercial (Unit : Terajoule) | D44: Industrial (Unit : Terajoule) | E44: Transport (Unit : Terajoule) | F44: 总计 Total | H44: Year | I44: Residential Percentage (%) | J44: Commercial Percentage (%) | K44: Industrial Percentage (%) | L44: Transport Percentage (%) | M44: 总计 Total
A45: 2011 | B45: 8 | C45: 1979 | D45: 3978 | E45: 72383 | F45: =SUM(B45:E45) -> 78348 | H45: 2011 | I45: 0 | J45: 0.03 | K45: 0.05 | L45: 0.92 | M45: =SUM(I45:L45) -> 1
A46: 2012 | B46: 8 | C46: 1696 | D46: 3728 | E46: 71927 | F46: =SUM(B46:E46) -> 77359 | H46: 2012 | I46: 0 | J46: 0.02 | K46: 0.05 | L46: 0.93 | M46: =SUM(I46:L46) -> 1
A47: 2013 | B47: 7 | C47: 1477 | D47: 3571 | E47: 71449 | F47: =SUM(B47:E47) -> 76504 | H47: 2013 | I47: 0 | J47: 0.02 | K47: 0.05 | L47: 0.93 | M47: =SUM(I47:L47) -> 1
...

Sheet Private,Public8EndUse
A1: Private/Public Residential Energy Consumption by End-use | K1: Air Conditioning | L1: Hot Water | M1: Lighting | N1: Refrigeration | O1: Office Equipment | P1: Cooking | Q1: Others | R1: Sum
A2: Source: | C2: Chapter : By Sectors&Segments | G2: EMSD End-use Data report
A3: Energy
A4: 所有住宅All Residential | K4: 私人住宅Private Housing Segment | V4: 公共住宅 Public Housing | AG4: 房委会资助出售单位组别 Housing Authority Subsidized Sale Flats Segment | AR4: Total Energy Consumption in Other Housing Segment by End-use | BC4: 重新加总Private+Public | BM4: Private = Urban defination in the EPS | BW4: Public = Rural defination in the EPS
A5: 年份 Year | B5: 空氣調節 Air Conditioning | C5: 熱水 Hot Water | D5: 照明 Lighting | E5: 冷凍 Refrigeration | F5: 辦公室設備 Office Equipment | G5: 煮食 Cooking | H5: 其他 1 Others 1 | I5: 總計 Total | K5: 年份 Year | L5: Cooking (Unit : Terajoule) | M5: Air Conditioning (Unit : Terajoule) | N5: Hot Water (Unit : Terajoule) | O5: Lighting (Unit : Terajoule) | P5: Refrigeration (Unit : Terajoule) | Q5: Office Equipment (Unit : Terajoule) | R5: Laundry (Unit : Terajoule) | S5: Others (Unit : Terajoule) | T5: 總計 Total | V5: 年份 Year | W5: Cooking (Unit : Terajoule) | X5: Air Conditioning (Unit : Terajoule) | Y5: Hot Water (Unit : Terajoule) | Z5: Lighting (Unit : Terajoule) | AA5: Refrigeration (Unit : Terajoule) | AB5: Office Equipment (Unit : Terajoule) | AC5: Laundry (Unit : Terajoule) | AD5: Others (Unit : Terajoule) | AE5: 總計 Total | AG5: 年份 Year | AH5: Cooking (Unit : Terajoule) | AI5: Air Conditioning (Unit : Terajoule) | AJ5: Hot Water (Unit : Terajoule) | AK5: Lighting (Unit : Terajoule) | AL5: Refrigeration (Unit : Terajoule) | AM5: Office Equipment (Unit : Terajoule) | AN5: Laundry (Unit : Terajoule) | AO5: Others (Unit : Terajoule) | AP5: 總計 Total | AR5: Year | AS5: Cooking (Unit : Terajoule) | AT5: Air Conditioning (Unit : Terajoule) | AU5: Hot Water (Unit : Terajoule) | AV5: Lighting (Unit : Terajoule) | AW5: Refrigeration (Unit : Terajoule) | AX5: Office Equipment (Unit : Terajoule) | AY5: Laundry (Unit : Terajoule) | AZ5: Others (Unit : Terajoule) | BA5: 總計 Total | BC5: 年份 Year | BD5: 煮食 Cooking | BE5: 空氣調節 Air Conditioning | BF5: 熱水 Hot Water | BG5: 照明 Lighting | BH5: 冷凍 Refrigeration | BI5: 辦公室設備 Office Equipment | BJ5: 其他 1 Others 1 | BK5: 總計 Total | BM5: 年份 Year | BN5: 煮食 Cooking | BO5: 空氣調節 Air Conditioning | BP5: 熱水 Hot Water | BQ5: 照明 Lighting | BR5: 冷凍 Refrigeration | BS5: 辦公室設備 Office Equipment | BT5: 其他 1 Others 1 | BU5: 總計 Total | BW5: 年份 Year | BX5: 煮食 Cooking | BY5: 空氣調節 Air Conditioning | BZ5: 熱水 Hot Water | CA5: 照明 Lighting | CB5: 冷凍 Refrigeration | CC5: 辦公室設備 Office Equipment | CD5: 其他 1 Others 1 | CE5: 總計 Total
A6: 2006 | B6: =BE6 -> 13285 | C6: =BF6 -> 12535 | D6: =BG6 -> 4633 | E6: =BH6 -> 6372 | F6: =BI6 -> 5366 | G6: =BD6 -> 16232 | H6: =BJ6 -> 2231 | I6: =BK6 -> 60654 | K6: 2006 | L6: 6828 | M6: 6122 | N6: 5074 | O6: 2148 | P6: 2830 | Q6: 2311 | R6: 0 | S6: 898 | T6: 26211 | V6: 2006 | W6: =G139+AH6 -> 6900 | X6: =B139+AI6 -> 5006 | Y6: =C139+AJ6 -> 5485 | Z6: =D139+AK6 -> 1760 | AA6: =E139+AL6 -> 2656 | AB6: =F139+AM6 -> 2211 | AD6: =H139+AO6 -> 948 | AE6: =I139+AP6 -> 24967 | AG6: 2006 | AH6: 2504 | AI6: 2157 | AJ6: 1976 | AK6: 725 | AL6: 886 | AM6: 844 | AN6: 0 | AO6: 385 | AP6: 9478 | AR6: 2006 | BA6: 0 | BC6: 2006 | BD6: =L6+W6+AH6+AS6 -> 16232 | BE6: =M6+X6+AI6+AT6 -> 13285 | BF6: =N6+Y6+AJ6+AU6 -> 12535 | BG6: =O6+Z6+AK6+AV6 -> 4633 | BH6: =P6+AA6+AL6+AW6 -> 6372 | BI6: =Q6+AB6+AM6+AX6 -> 5366 | BJ6: =R6+AC6+AN6+AY6+S6+AD6+AO6+AZ6 -> 2231 | BK6: =SUM(BD6:BJ6) -> 60654 | BM6: 2006 | BN6: =L6+AH6+AS6 -> 9332 | BO6: =M6+AI6+AT6 -> 8279 | BP6: =N6+AJ6+AU6 -> 7050 | BQ6: =O6+AK6+AV6 -> 2873 | BR6: =P6+AL6+AW6 -> 3716 | BS6: =Q6+AM6+AX6 -> 3155 | BT6: =R6+AY6+AN6+S6+AZ6+AO6 -> 1283 | BU6: =SUM(BN6:BT6) -> 35688 | BW6: 2006 | BX6: =W6 -> 6900 | BY6: =X6 -> 5006 | BZ6: =Y6 -> 5485 | CA6: =Z6 -> 1760 | CB6: =AA6 -> 2656 | CC6: =AB6 -> 2211 | CD6: =AC6+AD6 -> 948 | CE6: =SUM(BX6:CD6) -> 24966
A7: 2007 | B7: =BE7 -> 13329 | C7: =BF7 -> 12467 | D7: =BG7 -> 4509 | E7: =BH7 -> 6618 | F7: =BI7 -> 5701 | G7: =BD7 -> 16618 | H7: =BJ7 -> 2339 | I7: =BK7 -> 61581 | K7: 2007 | L7: 6974 | M7: 6176 | N7: 5104 | O7: 2100 | P7: 2962 | Q7: 2469 | R7: 0 | S7: 948 | T7: 26733 | V7: 2007 | W7: =G140+AH7 -> 7023 | X7: =B140+AI7 -> 4963 | Y7: =C140+AJ7 -> 5436 | Z7: =D140+AK7 -> 1709 | AA7: =E140+AL7 -> 2741 | AB7: =F140+AM7 -> 2323 | AD7: =H140+AO7 -> 990 | AE7: =I140+AP7 -> 25185 | AG7: 2007 | AH7: 2621 | AI7: 2190 | AJ7: 1927 | AK7: 700 | AL7: 915 | AM7: 909 | AN7: 0 | AO7: 401 | AP7: 9664 | AR7: 2007 | BA7: 0 | BC7: 2007 | BD7: =L7+W7+AH7+AS7 -> 16618 | BE7: =M7+X7+AI7+AT7 -> 13329 | BF7: =N7+Y7+AJ7+AU7 -> 12467 | BG7: =O7+Z7+AK7+AV7 -> 4509 | BH7: =P7+AA7+AL7+AW7 -> 6618 | BI7: =Q7+AB7+AM7+AX7 -> 5701 | BJ7: =R7+AC7+AN7+AY7+S7+AD7+AO7+AZ7 -> 2339 | BK7: =SUM(BD7:BJ7) -> 61581 | BM7: 2007 | BN7: =L7+AH7+AS7 -> 9595 | BO7: =M7+AI7+AT7 -> 8366 | BP7: =N7+AJ7+AU7 -> 7031 | BQ7: =O7+AK7+AV7 -> 2800 | BR7: =P7+AL7+AW7 -> 3877 | BS7: =Q7+AM7+AX7 -> 3378 | BT7: =R7+AY7+AN7+S7+AZ7+AO7 -> 1349 | BU7: =SUM(BN7:BT7) -> 36396 | BW7: 2007 | BX7: =W7 -> 7023 | BY7: =X7 -> 4963 | BZ7: =Y7 -> 5436 | CA7: =Z7 -> 1709 | CB7: =AA7 -> 2741 | CC7: =AB7 -> 2323 | CD7: =AC7+AD7 -> 990 | CE7: =SUM(BX7:CD7) -> 25185
A8: 2008 | B8: =BE8 -> 13292 | C8: =BF8 -> 12874 | D8: =BG8 -> 4353 | E8: =BH8 -> 6806 | F8: =BI8 -> 6021 | G8: =BD8 -> 17535 | H8: =BJ8 -> 2437 | I8: =BK8 -> 63318 | K8: 2008 | L8: 7334 | M8: 6240 | N8: 5323 | O8: 2055 | P8: 3101 | Q8: 2646 | R8: 0 | S8: 1002 | T8: 27701 | V8: 2008 | W8: =G141+AH8 -> 7334 | X8: =B141+AI8 -> 4836 | Y8: =C141+AJ8 -> 5559 | Z8: =D141+AK8 -> 1625 | AA8: =E141+AL8 -> 2765 | AB8: =F141+AM8 -> 2398 | AD8: =H141+AO8 -> 1017 | AE8: =I141+AP8 -> 25533 | AG8: 2008 | AH8: 2867 | AI8: 2216 | AJ8: 1992 | AK8: 673 | AL8: 940 | AM8: 977 | AN8: 0 | AO8: 418 | AP8: 10082 | AR8: 2008 | BA8: 0 | BC8: 2008 | BD8: =L8+W8+AH8+AS8 -> 17535 | BE8: =M8+X8+AI8+AT8 -> 13292 | BF8: =N8+Y8+AJ8+AU8 -> 12874 | BG8: =O8+Z8+AK8+AV8 -> 4353 | BH8: =P8+AA8+AL8+AW8 -> 6806 | BI8: =Q8+AB8+AM8+AX8 -> 6021 | BJ8: =R8+AC8+AN8+AY8+S8+AD8+AO8+AZ8 -> 2437 | BK8: =SUM(BD8:BJ8) -> 63318 | BM8: 2008 | BN8: =L8+AH8+AS8 -> 10201 | BO8: =M8+AI8+AT8 -> 8456 | BP8: =N8+AJ8+AU8 -> 7315 | BQ8: =O8+AK8+AV8 -> 2728 | BR8: =P8+AL8+AW8 -> 4041 | BS8: =Q8+AM8+AX8 -> 3623 | BT8: =R8+AY8+AN8+S8+AZ8+AO8 -> 1420 | BU8: =SUM(BN8:BT8) -> 37784 | BW8: 2008 | BX8: =W8 -> 7334 | BY8: =X8 -> 4836 | BZ8: =Y8 -> 5559 | CA8: =Z8 -> 1625 | CB8: =AA8 -> 2765 | CC8: =AB8 -> 2398 | CD8: =AC8+AD8 -> 1017 | CE8: =SUM(BX8:CD8) -> 25534
A9: 2009 | B9: =BE9 -> 14145 | C9: =BF9 -> 12864 | D9: =BG9 -> 4482 | E9: =BH9 -> 6907 | F9: =BI9 -> 6297 | G9: =BD9 -> 17300 | H9: =BJ9 -> 2771 | I9: =BK9 -> 64766 | K9: 2009 | L9: 7232 | M9: 6740 | N9: 5344 | O9: 2167 | P9: 3134 | Q9: 2764 | R9: 0 | S9: 1164 | T9: 28544 | V9: 2009 | W9: =G142+AH9 -> 7307 | X9: =B142+AI9 -> 5103 | Y9: =C142+AJ9 -> 5543 | Z9: =D142+AK9 -> 1639 | AA9: =E142+AL9 -> 2818 | AB9: =F142+AM9 -> 2519 | AD9: =H142+AO9 -> 1139 | AE9: =I142+AP9 -> 26068 | AG9: 2009 | AH9: 2761 | AI9: 2302 | AJ9: 1977 | AK9: 676 | AL9: 955 | AM9: 1014 | AN9: 0 | AO9: 468 | AP9: 10153 | AR9: 2009 | BA9: 0 | BC9: 2009 | BD9: =L9+W9+AH9+AS9 -> 17300 | BE9: =M9+X9+AI9+AT9 -> 14145 | BF9: =N9+Y9+AJ9+AU9 -> 12864 | BG9: =O9+Z9+AK9+AV9 -> 4482 | BH9: =P9+AA9+AL9+AW9 -> 6907 | BI9: =Q9+AB9+AM9+AX9 -> 6297 | BJ9: =R9+AC9+AN9+AY9+S9+AD9+AO9+AZ9 -> 2771 | BK9: =SUM(BD9:BJ9) -> 64766 | BM9: 2009 | BN9: =L9+AH9+AS9 -> 9993 | BO9: =M9+AI9+AT9 -> 9042 | BP9: =N9+AJ9+AU9 -> 7321 | BQ9: =O9+AK9+AV9 -> 2843 | BR9: =P9+AL9+AW9 -> 4089 | BS9: =Q9+AM9+AX9 -> 3778 | BT9: =R9+AY9+AN9+S9+AZ9+AO9 -> 1632 | BU9: =SUM(BN9:BT9) -> 38698 | BW9: 2009 | BX9: =W9 -> 7307 | BY9: =X9 -> 5103 | BZ9: =Y9 -> 5543 | CA9: =Z9 -> 1639 | CB9: =AA9 -> 2818 | CC9: =AB9 -> 2519 | CD9: =AC9+AD9 -> 1139 | CE9: =SUM(BX9:CD9) -> 26068
A10: 2010 | B10: =BE10 -> 12104 | C10: =BF10 -> 10831 | D10: =BG10 -> 3770 | E10: =BH10 -> 5747 | F10: =BI10 -> 5402 | G10: =BD10 -> 14518 | H10: =BJ10 -> 2594 | I10: =BK10 -> 54966 | K10: 2010 | L10: 7172 | M10: 6949 | N10: 5279 | O10: 2178 | P10: 3003 | Q10: 2815 | R10: 0 | S10: 1333 | T10: 28730 | V10: 2010 | W10: 4661 | X10: 2870 | Y10: 3557 | Z10: 947 | AA10: 1818 | AB10: 1558 | AD10: 742 | AE10: 16152 | AG10: 2010 | AH10: 2685 | AI10: 2285 | AJ10: 1995 | AK10: 645 | AL10: 926 | AM10: 1029 | AN10: 0 | AO10: 519 | AP10: 10084 | AR10: 2010 | BA10: 0 | BC10: 2010 | BD10: =L10+W10+AH10+AS10 -> 14518 | BE10: =M10+X10+AI10+AT10 -> 12104 | BF10: =N10+Y10+AJ10+AU10 -> 10831 | BG10: =O10+Z10+AK10+AV10 -> 3770 | BH10: =P10+AA10+AL10+AW10 -> 5747 | BI10: =Q10+AB10+AM10+AX10 -> 5402 | BJ10: =R10+AC10+AN10+AY10+S10+AD10+AO10+AZ10 -> 2594 | BK10: =SUM(BD10:BJ10) -> 54966 | BM10: 2010 | BN10: =L10+AH10+AS10 -> 9857 | BO10: =M10+AI10+AT10 -> 9234 | BP10: =N10+AJ10+AU10 -> 7274 | BQ10: =O10+AK10+AV10 -> 2823 | BR10: =P10+AL10+AW10 -> 3929 | BS10: =Q10+AM10+AX10 -> 3844 | BT10: =R10+AY10+AN10+S10+AZ10+AO10 -> 1852 | BU10: =SUM(BN10:BT10) -> 38813 | BW10: 2010 | BX10: =W10 -> 4661 | BY10: =X10 -> 2870 | BZ10: =Y10 -> 3557 | CA10: =Z10 -> 947 | CB10: =AA10 -> 1818 | CC10: =AB10 -> 1558 | CD10: =AC10+AD10 -> 742 | CE10: =SUM(BX10:CD10) -> 16153
A11: 2011 | B11: =BE11 -> 13423 | C11: =BF11 -> 11329 | D11: =BG11 -> 4042 | E11: =BH11 -> 5858 | F11: =BI11 -> 5908 | G11: =BD11 -> 15071 | H11: =BJ11 -> 3224 | I11: =BK11 -> 58855 | K11: 2011 | L11: 7028 | M11: 7201 | N11: 5259 | O11: 2204 | P11: 2891 | Q11: 2945 | R11: 0 | S11: 1606 | T11: =SUM(L11:S11) -> 29134 | V11: 2011 | W11: 4740 | X11: 2931 | Y11: 3565 | Z11: 942 | AA11: 1763 | AB11: 1642 | AD11: 841 | AE11: =SUM(W11:AD11) -> 16424 | AG11: 2011 | AH11: 2517 | AI11: 2163 | AJ11: 1950 | AK11: 585 | AL11: 857 | AM11: 1025 | AN11: 0 | AO11: 567 | AP11: =SUM(AH11:AO11) -> 9664 | AR11: 2011 | AS11: 786 | AT11: 1128 | AU11: 555 | AV11: 311 | AW11: 347 | AX11: 296 | AY11: 0 | AZ11: 210 | BA11: =SUM(AS11:AZ11) -> 3633 | BC11: 2011 | BD11: =L11+W11+AH11+AS11 -> 15071 | BE11: =M11+X11+AI11+AT11 -> 13423 | BF11: =N11+Y11+AJ11+AU11 -> 11329 | BG11: =O11+Z11+AK11+AV11 -> 4042 | BH11: =P11+AA11+AL11+AW11 -> 5858 | BI11: =Q11+AB11+AM11+AX11 -> 5908 | BJ11: =R11+AC11+AN11+AY11+S11+AD11+AO11+AZ11 -> 3224 | BK11: =SUM(BD11:BJ11) -> 58855 | BM11: 2011 | BN11: =L11+AH11+AS11 -> 10331 | BO11: =M11+AI11+AT11 -> 10492 | BP11: =N11+AJ11+AU11 -> 7764 | BQ11: =O11+AK11+AV11 -> 3100 | BR11: =P11+AL11+AW11 -> 4095 | BS11: =Q11+AM11+AX11 -> 4266 | BT11: =R11+AY11+AN11+S11+AZ11+AO11 -> 2383 | BU11: =SUM(BN11:BT11) -> 42431 | BW11: 2011 | BX11: =W11 -> 4740 | BY11: =X11 -> 2931 | BZ11: =Y11 -> 3565 | CA11: =Z11 -> 942 | CB11: =AA11 -> 1763 | CC11: =AB11 -> 1642 | CD11: =AC11+AD11 -> 841 | CE11: =SUM(BX11:CD11) -> 16424
A12: 2012 | B12: =BE12 -> 13846 | C12: =BF12 -> 11214 | D12: =BG12 -> 4086 | E12: =BH12 -> 5665 | F12: =BI12 -> 6357 | G12: =BD12 -> 14920 | H12: =BJ12 -> 3947 | I12: =BK12 -> 60035 | K12: 2012 | L12: 6788 | M12: 7364 | N12: 5113 | O12: 2208 | P12: 2743 | Q12: 3099 | R12: 0 | S12: 2008 | T12: =SUM(L12:S12) -> 29323 | V12: 2012 | W12: 4804 | X12: 3029 | Y12: 3549 | Z12: 970 | AA12: 1725 | AB12: 1794 | AD12: 995 | AE12: =SUM(W12:AD12) -> 16866 | AG12: 2012 | AH12: 2464 | AI12: 2162 | AJ12: 1982 | AK12: 561 | AL12: 838 | AM12: 1127 | AN12: 0 | AO12: 678 | AP12: =SUM(AH12:AO12) -> 9812 | AR12: 2012 | AS12: 864 | AT12: 1291 | AU12: 570 | AV12: 347 | AW12: 359 | AX12: 337 | AY12: 0 | AZ12: 266 | BA12: =SUM(AS12:AZ12) -> 4034 | BC12: 2012 | BD12: =L12+W12+AH12+AS12 -> 14920 | BE12: =M12+X12+AI12+AT12 -> 13846 | BF12: =N12+Y12+AJ12+AU12 -> 11214 | BG12: =O12+Z12+AK12+AV12 -> 4086 | BH12: =P12+AA12+AL12+AW12 -> 5665 | BI12: =Q12+AB12+AM12+AX12 -> 6357 | BJ12: =R12+AC12+AN12+AY12+S12+AD12+AO12+AZ12 -> 3947 | BK12: =SUM(BD12:BJ12) -> 60035 | BM12: 2012 | BN12: =L12+AH12+AS12 -> 10116 | BO12: =M12+AI12+AT12 -> 10817 | BP12: =N12+AJ12+AU12 -> 7665 | BQ12: =O12+AK12+AV12 -> 3116 | BR12: =P12+AL12+AW12 -> 3940 | BS12: =Q12+AM12+AX12 -> 4563 | BT12: =R12+AY12+AN12+S12+AZ12+AO12 -> 2952 | BU12: =SUM(BN12:BT12) -> 43169 | BW12: 2012 | BX12: =W12 -> 4804 | BY12: =X12 -> 3029 | BZ12: =Y12 -> 3549 | CA12: =Z12 -> 970 | CB12: =AA12 -> 1725 | CC12: =AB12 -> 1794 | CD12: =AC12+AD12 -> 995 | CE12: =SUM(BX12:CD12) -> 16866
A13: 2013 | B13: =BE13 -> 13078 | C13: =BF13 -> 11791 | D13: =BG13 -> 3469 | E13: =BH13 -> 5000 | F13: =BI13 -> 5319 | G13: =BD13 -> 15898 | H13: =BJ13 -> 4030 | I13: =BK13 -> 58585 | K13: 2013 | L13: 7301 | M13: 6914 | N13: 5450 | O13: 1874 | P13: 2404 | Q13: 2505 | R13: 0 | S13: 2042 | T13: =SUM(L13:S13) -> 28490 | V13: 2013 | W13: 5085 | X13: 2883 | Y13: 3661 | Z13: 823 | AA13: 1544 | AB13: 1573 | AD13: 1035 | AE13: =SUM(W13:AD13) -> 16604 | AG13: 2013 | AH13: 2515 | AI13: 2075 | AJ13: 2049 | AK13: 480 | AL13: 741 | AM13: 945 | AN13: 0 | AO13: 664 | AP13: =SUM(AH13:AO13) -> 9469 | AR13: 2013 | AS13: 997 | AT13: 1206 | AU13: 631 | AV13: 292 | AW13: 311 | AX13: 296 | AY13: 0 | AZ13: 289 | BA13: =SUM(AS13:AZ13) -> 4022 | BC13: 2013 | BD13: =L13+W13+AH13+AS13 -> 15898 | BE13: =M13+X13+AI13+AT13 -> 13078 | BF13: =N13+Y13+AJ13+AU13 -> 11791 | BG13: =O13+Z13+AK13+AV13 -> 3469 | BH13: =P13+AA13+AL13+AW13 -> 5000 | BI13: =Q13+AB13+AM13+AX13 -> 5319 | BJ13: =R13+AC13+AN13+AY13+S13+AD13+AO13+AZ13 -> 4030 | BK13: =SUM(BD13:BJ13) -> 58585 | BM13: 2013 | BN13: =L13+AH13+AS13 -> 10813 | BO13: =M13+AI13+AT13 -> 10195 | BP13: =N13+AJ13+AU13 -> 8130 | BQ13: =O13+AK13+AV13 -> 2646 | BR13: =P13+AL13+AW13 -> 3456 | BS13: =Q13+AM13+AX13 -> 3746 | BT13: =R13+AY13+AN13+S13+AZ13+AO13 -> 2995 | BU13: =SUM(BN13:BT13) -> 41981 | BW13: 2013 | BX13: =W13 -> 5085 | BY13: =X13 -> 2883 | BZ13: =Y13 -> 3661 | CA13: =Z13 -> 823 | CB13: =AA13 -> 1544 | CC13: =AB13 -> 1573 | CD13: =AC13+AD13 -> 1035 | CE13: =SUM(BX13:CD13) -> 16604
A14: 2014 | B14: =BE14 -> 15738 | C14: =BF14 -> 12772 | D14: =BG14 -> 3239 | E14: =BH14 -> 4778 | F14: =BI14 -> 4986 | G14: =BD14 -> 16114 | H14: =BJ14 -> 4479 | I14: =BK14 -> 62106 | K14: 2014 | L14: 7499 | M14: 8322 | N14: 6055 | O14: 1752 | P14: 2292 | Q14: 2357 | R14: 0 | S14: 2271 | T14: =SUM(L14:S14) -> 30548 | V14: 2014 | W14: 5083 | X14: 3496 | Y14: 3866 | Z14: 775 | AA14: 1495 | AB14: 1489 | AD14: 1168 | AE14: =SUM(W14:AD14) -> 17372 | AG14: 2014 | AH14: 2491 | AI14: 2565 | AJ14: 2167 | AK14: 454 | AL14: 715 | AM14: 873 | AN14: 0 | AO14: 718 | AP14: =SUM(AH14:AO14) -> 9983 | AR14: 2014 | AS14: 1041 | AT14: 1355 | AU14: 684 | AV14: 258 | AW14: 276 | AX14: 267 | AY14: 0 | AZ14: 322 | BA14: =SUM(AS14:AZ14) -> 4203 | BC14: 2014 | BD14: =L14+W14+AH14+AS14 -> 16114 | BE14: =M14+X14+AI14+AT14 -> 15738 | BF14: =N14+Y14+AJ14+AU14 -> 12772 | BG14: =O14+Z14+AK14+AV14 -> 3239 | BH14: =P14+AA14+AL14+AW14 -> 4778 | BI14: =Q14+AB14+AM14+AX14 -> 4986 | BJ14: =R14+AC14+AN14+AY14+S14+AD14+AO14+AZ14 -> 4479 | BK14: =SUM(BD14:BJ14) -> 62106 | BM14: 2014 | BN14: =L14+AH14+AS14 -> 11031 | BO14: =M14+AI14+AT14 -> 12242 | BP14: =N14+AJ14+AU14 -> 8906 | BQ14: =O14+AK14+AV14 -> 2464 | BR14: =P14+AL14+AW14 -> 3283 | BS14: =Q14+AM14+AX14 -> 3497 | BT14: =R14+AY14+AN14+S14+AZ14+AO14 -> 3311 | BU14: =SUM(BN14:BT14) -> 44734 | BW14: 2014 | BX14: =W14 -> 5083 | BY14: =X14 -> 3496 | BZ14: =Y14 -> 3866 | CA14: =Z14 -> 775 | CB14: =AA14 -> 1495 | CC14: =AB14 -> 1489 | CD14: =AC14+AD14 -> 1168 | CE14: =SUM(BX14:CD14) -> 17372
A15: 2015 | B15: =BE15 -> 15662 | C15: =BF15 -> 12957 | D15: =BG15 -> 2840 | E15: =BH15 -> 4213 | F15: =BI15 -> 4404 | G15: =BD15 -> 15727 | H15: =BJ15 -> 4636 | I15: =BK15 -> 60439 | K15: 2015 | L15: 7243 | M15: 8046 | N15: 6136 | O15: 1500 | P15: 1972 | Q15: 2047 | R15: 0 | S15: 2296 | T15: =SUM(L15:S15) -> 29240 | V15: 2015 | W15: 4912 | X15: 3580 | Y15: 3866 | Z15: 691 | AA15: 1349 | AB15: 1338 | AD15: 1235 | AE15: =SUM(W15:AD15) -> 16971 | AG15: 2015 | AH15: 2350 | AI15: 2605 | AJ15: 2177 | AK15: 400 | AL15: 632 | AM15: 758 | AN15: 0 | AO15: 718 | AP15: =SUM(AH15:AO15) -> 9640 | AR15: 2015 | AS15: 1222 | AT15: 1431 | AU15: 778 | AV15: 249 | AW15: 260 | AX15: 261 | AY15: 0 | AZ15: 387 | BA15: =SUM(AS15:AZ15) -> 4588 | BC15: 2015 | BD15: =L15+W15+AH15+AS15 -> 15727 | BE15: =M15+X15+AI15+AT15 -> 15662 | BF15: =N15+Y15+AJ15+AU15 -> 12957 | BG15: =O15+Z15+AK15+AV15 -> 2840 | BH15: =P15+AA15+AL15+AW15 -> 4213 | BI15: =Q15+AB15+AM15+AX15 -> 4404 | BJ15: =R15+AC15+AN15+AY15+S15+AD15+AO15+AZ15 -> 4636 | BK15: =SUM(BD15:BJ15) -> 60439 | BM15: 2015 | BN15: =L15+AH15+AS15 -> 10815 | BO15: =M15+AI15+AT15 -> 12082 | BP15: =N15+AJ15+AU15 -> 9091 | BQ15: =O15+AK15+AV15 -> 2149 | BR15: =P15+AL15+AW15 -> 2864 | BS15: =Q15+AM15+AX15 -> 3066 | BT15: =R15+AY15+AN15+S15+AZ15+AO15 -> 3401 | BU15: =SUM(BN15:BT15) -> 43468 | BW15: 2015 | BX15: =W15 -> 4912 | BY15: =X15 -> 3580 | BZ15: =Y15 -> 3866 | CA15: =Z15 -> 691 | CB15: =AA15 -> 1349 | CC15: =AB15 -> 1338 | CD15: =AC15+AD15 -> 1235 | CE15: =SUM(BX15:CD15) -> 16971
A16: 2016 | B16: =BE16 -> 16082 | C16: =BF16 -> 14095 | D16: =BG16 -> 2581 | E16: =BH16 -> 3783 | F16: =BI16 -> 4017 | G16: =BD16 -> 16236 | H16: =BJ16 -> 4908 | I16: =BK16 -> 61702 | K16: 2016 | L16: 7706 | M16: 8323 | N16: 6933 | O16: 1379 | P16: 1789 | Q16: 1893 | R16: 0 | S16: 2465 | T16: =SUM(L16:S16) -> 30488 | V16: 2016 | W16: 4942 | X16: 3758 | Y16: 4079 | Z16: 633 | AA16: 1226 | AB16: 1231 | AD16: 1320 | AE16: =SUM(W16:AD16) -> 17189 | AG16: 2016 | AH16: 2298 | AI16: 2676 | AJ16: 2278 | AK16: 359 | AL16: 560 | AM16: 674 | AN16: 0 | AO16: 726 | AP16: =SUM(AH16:AO16) -> 9571 | AR16: 2016 | AS16: 1290 | AT16: 1325 | AU16: 805 | AV16: 210 | AW16: 208 | AX16: 219 | AY16: 0 | AZ16: 397 | BA16: =SUM(AS16:AZ16) -> 4454 | BC16: 2016 | BD16: =L16+W16+AH16+AS16 -> 16236 | BE16: =M16+X16+AI16+AT16 -> 16082 | BF16: =N16+Y16+AJ16+AU16 -> 14095 | BG16: =O16+Z16+AK16+AV16 -> 2581 | BH16: =P16+AA16+AL16+AW16 -> 3783 | BI16: =Q16+AB16+AM16+AX16 -> 4017 | BJ16: =R16+AC16+AN16+AY16+S16+AD16+AO16+AZ16 -> 4908 | BK16: =SUM(BD16:BJ16) -> 61702 | BM16: 2016 | BN16: =L16+AH16+AS16 -> 11294 | BO16: =M16+AI16+AT16 -> 12324 | BP16: =N16+AJ16+AU16 -> 10016 | BQ16: =O16+AK16+AV16 -> 1948 | BR16: =P16+AL16+AW16 -> 2557 | BS16: =Q16+AM16+AX16 -> 2786 | BT16: =R16+AY16+AN16+S16+AZ16+AO16 -> 3588 | BU16: =SUM(BN16:BT16) -> 44513 | BW16: 2016 | BX16: =W16 -> 4942 | BY16: =X16 -> 3758 | BZ16: =Y16 -> 4079 | CA16: =Z16 -> 633 | CB16: =AA16 -> 1226 | CC16: =AB16 -> 1231 | CD16: =AC16+AD16 -> 1320 | CE16: =SUM(BX16:CD16) -> 17189
A17: 2017 | B17: =BE17 -> 15926 | C17: =BF17 -> 14376 | D17: =BG17 -> 2286 | E17: =BH17 -> 3214 | F17: =BI17 -> 3495 | G17: =BD17 -> 16227 | H17: =BJ17 -> 4949 | I17: =BK17 -> 60473 | K17: 2017 | L17: 7887 | M17: 8202 | N17: 7241 | O17: 1220 | P17: 1522 | Q17: 1652 | R17: 1465 | S17: 1036 | T17: =SUM(L17:S17) -> 30225 | V17: 2017 | W17: 4777 | X17: 3821 | Y17: 4041 | Z17: 570 | AA17: 1053 | AB17: 1080 | AC17: 790 | AD17: 549 | AE17: =SUM(W17:AD17) -> 16681 | AG17: 2017 | AH17: 2190 | AI17: 2703 | AJ17: 2306 | AK17: 318 | AL17: 477 | AM17: 582 | AN17: 475 | AO17: 234 | AP17: =SUM(AH17:AO17) -> 9285 | AR17: 2017 | AS17: 1373 | AT17: 1200 | AU17: 788 | AV17: 178 | AW17: 162 | AX17: 181 | AY17: 144 | AZ17: 256 | BA17: =SUM(AS17:AZ17) -> 4282 | BC17: 2017 | BD17: =L17+W17+AH17+AS17 -> 16227 | BE17: =M17+X17+AI17+AT17 -> 15926 | BF17: =N17+Y17+AJ17+AU17 -> 14376 | BG17: =O17+Z17+AK17+AV17 -> 2286 | BH17: =P17+AA17+AL17+AW17 -> 3214 | BI17: =Q17+AB17+AM17+AX17 -> 3495 | BJ17: =R17+AC17+AN17+AY17+S17+AD17+AO17+AZ17 -> 4949 | BK17: =SUM(BD17:BJ17) -> 60473 | BM17: 2017 | BN17: =L17+AH17+AS17 -> 11450 | BO17: =M17+AI17+AT17 -> 12105 | BP17: =N17+AJ17+AU17 -> 10335 | BQ17: =O17+AK17+AV17 -> 1716 | BR17: =P17+AL17+AW17 -> 2161 | BS17: =Q17+AM17+AX17 -> 2415 | BT17: =R17+AY17+AN17+S17+AZ17+AO17 -> 3610 | BU17: =SUM(BN17:BT17) -> 43792 | BW17: 2017 | BX17: =W17 -> 4777 | BY17: =X17 -> 3821 | BZ17: =Y17 -> 4041 | CA17: =Z17 -> 570 | CB17: =AA17 -> 1053 | CC17: =AB17 -> 1080 | CD17: =AC17+AD17 -> 1339 | CE17: =SUM(BX17:CD17) -> 16681
A18: 2018 | B18: =BE18 -> 15765 | C18: =BF18 -> 14692 | D18: =BG18 -> 2286 | E18: =BH18 -> 3211 | F18: =BI18 -> 3489 | G18: =BD18 -> 17159 | H18: =BJ18 -> 4955 | I18: =BK18 -> 61557 | K18: 2018 | L18: 8210 | M18: 8000 | N18: 7212 | O18: 1202 | P18: 1502 | Q18: 1628 | R18: 1445 | S18: 1021 | T18: =SUM(L18:S18) -> 30220 | V18: 2018 | W18: 4941 | X18: 3767 | Y18: 4124 | Z18: 568 | AA18: 1050 | AB18: 1076 | AC18: 787 | AD18: 547 | AE18: =SUM(W18:AD18) -> 16860 | AG18: 2018 | AH18: 2269 | AI18: 2678 | AJ18: 2431 | AK18: 318 | AL18: 478 | AM18: 583 | AN18: 475 | AO18: 234 | AP18: =SUM(AH18:AO18) -> 9466 | AR18: 2018 | AS18: 1739 | AT18: 1320 | AU18: 925 | AV18: 198 | AW18: 181 | AX18: 202 | AY18: 161 | AZ18: 285 | BA18: =SUM(AS18:AZ18) -> 5011 | BC18: 2018 | BD18: =L18+W18+AH18+AS18 -> 17159 | BE18: =M18+X18+AI18+AT18 -> 15765 | BF18: =N18+Y18+AJ18+AU18 -> 14692 | BG18: =O18+Z18+AK18+AV18 -> 2286 | BH18: =P18+AA18+AL18+AW18 -> 3211 | BI18: =Q18+AB18+AM18+AX18 -> 3489 | BJ18: =R18+AC18+AN18+AY18+S18+AD18+AO18+AZ18 -> 4955 | BK18: =SUM(BD18:BJ18) -> 61557 | BM18: 2018 | BN18: =L18+AH18+AS18 -> 12218 | BO18: =M18+AI18+AT18 -> 11998 | BP18: =N18+AJ18+AU18 -> 10568 | BQ18: =O18+AK18+AV18 -> 1718 | BR18: =P18+AL18+AW18 -> 2161 | BS18: =Q18+AM18+AX18 -> 2413 | BT18: =R18+AY18+AN18+S18+AZ18+AO18 -> 3621 | BU18: =SUM(BN18:BT18) -> 44697 | BW18: 2018 | BX18: =W18 -> 4941 | BY18: =X18 -> 3767 | BZ18: =Y18 -> 4124 | CA18: =Z18 -> 568 | CB18: =AA18 -> 1050 | CC18: =AB18 -> 1076 | CD18: =AC18+AD18 -> 1334 | CE18: =SUM(BX18:CD18) -> 16860
A19: 2019 | B19: =BE19 -> 16113 | C19: =BF19 -> 14147 | D19: =BG19 -> 2354 | E19: =BH19 -> 3349 | F19: =BI19 -> 3594 | G19: =BD19 -> 16365 | H19: =BJ19 -> 5099 | I19: =BK19 -> 61021 | K19: 2019 | L19: 7851 | M19: 8203 | N19: 7037 | O19: 1239 | P19: 1567 | Q19: 1678 | R19: 1487 | S19: 1053 | T19: =SUM(L19:S19) -> 30115 | V19: 2019 | W19: 4768 | X19: 3819 | Y19: 3961 | Z19: 584 | AA19: 1093 | AB19: 1106 | AC19: 808 | AD19: 563 | AE19: =SUM(W19:AD19) -> 16702 | AG19: 2019 | AH19: 2225 | AI19: 2778 | AJ19: 2301 | AK19: 331 | AL19: 504 | AM19: 606 | AN19: 494 | AO19: 244 | AP19: =SUM(AH19:AO19) -> 9483 | AR19: 2019 | AS19: 1521 | AT19: 1313 | AU19: 848 | AV19: 200 | AW19: 185 | AX19: 204 | AY19: 162 | AZ19: 288 | BA19: =SUM(AS19:AZ19) -> 4721 | BC19: 2019 | BD19: =L19+W19+AH19+AS19 -> 16365 | BE19: =M19+X19+AI19+AT19 -> 16113 | BF19: =N19+Y19+AJ19+AU19 -> 14147 | BG19: =O19+Z19+AK19+AV19 -> 2354 | BH19: =P19+AA19+AL19+AW19 -> 3349 | BI19: =Q19+AB19+AM19+AX19 -> 3594 | BJ19: =R19+AC19+AN19+AY19+S19+AD19+AO19+AZ19 -> 5099 | BK19: =SUM(BD19:BJ19) -> 61021 | BM19: 2019 | BN19: =L19+AH19+AS19 -> 11597 | BO19: =M19+AI19+AT19 -> 12294 | BP19: =N19+AJ19+AU19 -> 10186 | BQ19: =O19+AK19+AV19 -> 1770 | BR19: =P19+AL19+AW19 -> 2256 | BS19: =Q19+AM19+AX19 -> 2488 | BT19: =R19+AY19+AN19+S19+AZ19+AO19 -> 3728 | BU19: =SUM(BN19:BT19) -> 44319 | BW19: 2019 | BX19: =W19 -> 4768 | BY19: =X19 -> 3819 | BZ19: =Y19 -> 3961 | CA19: =Z19 -> 584 | CB19: =AA19 -> 1093 | CC19: =AB19 -> 1106 | CD19: =AC19+AD19 -> 1371 | CE19: =SUM(BX19:CD19) -> 16702
A20: 2020 | B20: =BE20 -> 18137 | C20: =BF20 -> 15449 | D20: =BG20 -> 2501 | E20: =BH20 -> 3550 | F20: =BI20 -> 3819 | G20: =BD20 -> 17535 | H20: =BJ20 -> 5421 | I20: =BK20 -> 66412 | K20: 2020 | L20: 8417 | M20: 9247 | N20: 7710 | O20: 1320 | P20: 1666 | Q20: 1788 | R20: 1586 | S20: 1121 | T20: =SUM(L20:S20) -> 32855 | V20: 2020 | W20: 5131 | X20: 4280 | Y20: 4318 | Z20: 617 | AA20: 1153 | AB20: 1169 | AC20: 855 | AD20: 595 | AE20: =SUM(W20:AD20) -> 18118 | AG20: 2020 | AH20: 2413 | AI20: 3131 | AJ20: 2524 | AK20: 352 | AL20: 535 | AM20: 646 | AN20: 526 | AO20: 260 | AP20: =SUM(AH20:AO20) -> 10387 | AR20: 2020 | AS20: 1574 | AT20: 1479 | AU20: 897 | AV20: 212 | AW20: 196 | AX20: 216 | AY20: 172 | AZ20: 306 | BA20: =SUM(AS20:AZ20) -> 5052 | BC20: 2020 | BD20: =L20+W20+AH20+AS20 -> 17535 | BE20: =M20+X20+AI20+AT20 -> 18137 | BF20: =N20+Y20+AJ20+AU20 -> 15449 | BG20: =O20+Z20+AK20+AV20 -> 2501 | BH20: =P20+AA20+AL20+AW20 -> 3550 | BI20: =Q20+AB20+AM20+AX20 -> 3819 | BJ20: =R20+AC20+AN20+AY20+S20+AD20+AO20+AZ20 -> 5421 | BK20: =SUM(BD20:BJ20) -> 66412 | BM20: 2020 | BN20: =L20+AH20+AS20 -> 12404 | BO20: =M20+AI20+AT20 -> 13857 | BP20: =N20+AJ20+AU20 -> 11131 | BQ20: =O20+AK20+AV20 -> 1884 | BR20: =P20+AL20+AW20 -> 2397 | BS20: =Q20+AM20+AX20 -> 2650 | BT20: =R20+AY20+AN20+S20+AZ20+AO20 -> 3971 | BU20: =SUM(BN20:BT20) -> 48294 | BW20: 2020 | BX20: =W20 -> 5131 | BY20: =X20 -> 4280 | BZ20: =Y20 -> 4318 | CA20: =Z20 -> 617 | CB20: =AA20 -> 1153 | CC20: =AB20 -> 1169 | CD20: =AC20+AD20 -> 1450 | CE20: =SUM(BX20:CD20) -> 18118
A21: 2021 | B21: =BE21 -> 18697 | C21: =BF21 -> 15074 | D21: =BG21 -> 2526 | E21: =BH21 -> 3603 | F21: =BI21 -> 3855 | G21: =BD21 -> 17493 | H21: =BJ21 -> 5475 | I21: =BK21 -> 66723 | K21: 2021 | L21: 8198 | M21: 9309 | N21: 7349 | O21: 1301 | P21: 1651 | Q21: 1762 | R21: 1561 | S21: 1105 | T21: =SUM(L21:S21) -> 32236 | V21: 2021 | W21: 5121 | X21: 4446 | Y21: 4249 | Z21: 630 | AA21: 1183 | AB21: 1193 | AC21: 871 | AD21: 607 | AE21: =SUM(W21:AD21) -> 18300 | AG21: 2021 | AH21: 2426 | AI21: 3288 | AJ21: 2501 | AK21: 362 | AL21: 553 | AM21: 663 | AN21: 540 | AO21: 267 | AP21: =SUM(AH21:AO21) -> 10600 | AR21: 2021 | AS21: 1748 | AT21: 1654 | AU21: 975 | AV21: 233 | AW21: 216 | AX21: 237 | AY21: 189 | AZ21: 335 | BA21: =SUM(AS21:AZ21) -> 5587 | BC21: 2021 | BD21: =L21+W21+AH21+AS21 -> 17493 | BE21: =M21+X21+AI21+AT21 -> 18697 | BF21: =N21+Y21+AJ21+AU21 -> 15074 | BG21: =O21+Z21+AK21+AV21 -> 2526 | BH21: =P21+AA21+AL21+AW21 -> 3603 | BI21: =Q21+AB21+AM21+AX21 -> 3855 | BJ21: =R21+AC21+AN21+AY21+S21+AD21+AO21+AZ21 -> 5475 | BK21: =SUM(BD21:BJ21) -> 66723 | BM21: 2021 | BN21: =L21+AH21+AS21 -> 12372 | BO21: =M21+AI21+AT21 -> 14251 | BP21: =N21+AJ21+AU21 -> 10825 | BQ21: =O21+AK21+AV21 -> 1896 | BR21: =P21+AL21+AW21 -> 2420 | BS21: =Q21+AM21+AX21 -> 2662 | BT21: =R21+AY21+AN21+S21+AZ21+AO21 -> 3997 | BU21: =SUM(BN21:BT21) -> 48423 | BW21: 2021 | BX21: =W21 -> 5121 | BY21: =X21 -> 4446 | BZ21: =Y21 -> 4249 | CA21: =Z21 -> 630 | CB21: =AA21 -> 1183 | CC21: =AB21 -> 1193 | CD21: =AC21+AD21 -> 1478 | CE21: =SUM(BX21:CD21) -> 18300
A23: 转换为百分比Change to percentage
A24: Year | B24: Hot Water | C24: Lighting | D24: Refrigeration | E24: Office Equipment | F24: Cooking | G24: Air Conditioning | H24: Others | I24: Sum | K24: 私人住宅Private Housing Segment | V24: 公共住宅 Public Housing | AG24: 房委会资助出售单位组别 Housing Authority Subsidized Sale Flats Segment | AR24: Total Energy Consumption in Other Housing Segment by End-use | BC24: 重新加总Private+Public | BM24: Private = Urban defination in the EPS | BW24: Public = Rural defination in the EPS
A25: 年份 Year | B25: =BE25 -> 空氣調節 Air Conditioning | C25: =BF25 -> 熱水 Hot Water | D25: =BG25 -> 照明 Lighting | E25: =BH25 -> 冷凍 Refrigeration | F25: =BI25 -> 辦公室設備 Office Equipment | G25: =BD25 -> 煮食 Cooking | H25: =BJ25 -> 其他 1 Others 1 | I25: =BK25 -> 總計 Total | K25: 年份 Year | L25: 煮食 Cooking | M25: 空氣調節 Air Conditioning | N25: 熱水 Hot Water | O25: 照明 Lighting | P25: 冷凍 Refrigeration | Q25: 辦公室設備 Office Equipment | R25: Laundry (Unit : Terajoule) | S25: 其他 1 Others 1 | T25: 總計 Total | V25: 年份 Year | W25: 煮食 Cooking | X25: 空氣調節 Air Conditioning | Y25: 熱水 Hot Water | Z25: 照明 Lighting | AA25: 冷凍 Refrigeration | AB25: 辦公室設備 Office Equipment | AC25: Laundry (Unit : Terajoule) | AD25: 其他 1 Others 1 | AE25: 總計 Total | AG25: 年份 Year | AH25: 煮食 Cooking | AI25: 空氣調節 Air Conditioning | AJ25: 熱水 Hot Water | AK25: 照明 Lighting | AL25: 冷凍 Refrigeration | AM25: 辦公室設備 Office Equipment | AN25: Laundry (Unit : Terajoule) | AO25: 其他 1 Others 1 | AP25: 總計 Total | AR25: 年份 Year | AS25: 煮食 Cooking | AT25: 空氣調節 Air Conditioning | AU25: 熱水 Hot Water | AV25: 照明 Lighting | AW25: 冷凍 Refrigeration | AX25: 辦公室設備 Office Equipment | AY25: Laundry (Unit : Terajoule) | AZ25: 其他 1 Others 1 | BA25: 總計 Total | BC25: 年份 Year | BD25: 煮食 Cooking | BE25: 空氣調節 Air Conditioning | BF25: 熱水 Hot Water | BG25: 照明 Lighting | BH25: 冷凍 Refrigeration | BI25: 辦公室設備 Office Equipment | BJ25: 其他 1 Others 1 | BK25: 總計 Total | BM25: 年份 Year | BN25: 煮食 Cooking | BO25: 空氣調節 Air Conditioning | BP25: 熱水 Hot Water | BQ25: 照明 Lighting | BR25: 冷凍 Refrigeration | BS25: 辦公室設備 Office Equipment | BT25: 其他 1 Others 1 | BU25: 總計 Total | BW25: 年份 Year | BX25: 煮食 Cooking | BY25: 空氣調節 Air Conditioning | BZ25: 熱水 Hot Water | CA25: 照明 Lighting | CB25: 冷凍 Refrigeration | CC25: 辦公室設備 Office Equipment | CD25: 其他 1 Others 1 | CE25: 總計 Total
A26: 2006 | B26: =BE26 -> 0.21902925 | C26: =BF26 -> 0.20666403 | D26: =BG26 -> 0.07638408 | E26: =BH26 -> 0.1050549 | F26: =BI26 -> 0.088469021 | G26: =BD26 -> 0.26761632 | H26: =BJ26 -> 0.036782405 | I26: =BK26 -> 1 | K26: 2006 | L26: =L6/$T6 -> 0.26050132 | M26: =M6/$T6 -> 0.23356606 | N26: =N6/$T6 -> 0.19358285 | O26: =O6/$T6 -> 0.081950326 | P26: =P6/$T6 -> 0.10796994 | Q26: =Q6/$T6 -> 0.088169089 | R26: =R6/$T6 -> 0 | S26: =S6/$T6 -> 0.034260425 | T26: =T6/$T6 -> 1 | V26: 2006 | W26: =W6/$AE6 -> 0.2763648 | X26: =X6/$AE6 -> 0.20050467 | Y26: =Y6/$AE6 -> 0.21968999 | Z26: =Z6/$AE6 -> 0.070493051 | AA26: =AA6/$AE6 -> 0.10638042 | AB26: =AB6/$AE6 -> 0.088556895 | AC26: =AC6/$AE6 -> 0 | AD26: =AD6/$AE6 -> 0.037970121 | AE26: =AE6/$AE6 -> 1 | AG26: 2006 | AH26: =AH6/$AP6 -> 0.26419076 | AI26: =AI6/$AP6 -> 0.22757966 | AJ26: =AJ6/$AP6 -> 0.2084828 | AK26: =AK6/$AP6 -> 0.076492931 | AL26: =AL6/$AP6 -> 0.093479637 | AM26: =AM6/$AP6 -> 0.089048322 | AN26: =AN6/$AP6 -> 0 | AO26: =AO6/$AP6 -> 0.040620384 | AP26: =AP6/$AE6 -> 0.3796211 | AR26: 2006 | AS26: =IFERROR(AS6/$BA6,0) -> 0 | AT26: =IFERROR(AT6/$BA6,0) -> 0 | AU26: =IFERROR(AU6/$BA6,0) -> 0 | AV26: =IFERROR(AV6/$BA6,0) -> 0 | AW26: =IFERROR(AW6/$BA6,0) -> 0 | AX26: =IFERROR(AX6/$BA6,0) -> 0 | AY26: =IFERROR(AY6/$BA6,0) -> 0 | AZ26: =AZ6/$AP6 -> 0 | BA26: =BA6/$AE6 -> 0 | BC26: 2006 | BD26: =(L26*$T6+W26*$AE6+AH26*$AP6+AS26*$BA6)/$I6 -> 0.26761632 | BE26: =(M26*$T6+X26*$AE6+AI26*$AP6+AT26*$BA6)/$I6 -> 0.21902925 | BF26: =(N26*$T6+Y26*$AE6+AJ26*$AP6+AU26*$BA6)/$I6 -> 0.20666403 | BG26: =(O26*$T6+Z26*$AE6+AK26*$AP6+AV26*$BA6)/$I6 -> 0.07638408 | BH26: =(P26*$T6+AA26*$AE6+AL26*$AP6+AW26*$BA6)/$I6 -> 0.1050549 | BI26: =(Q26*$T6+AB26*$AE6+AM26*$AP6+AX26*$BA6)/$I6 -> 0.088469021 | BJ26: =((R26+S26)*$T6+(AC26+AD26)*$AE6+(AN26+AO26)*$AP6+(AZ26+AY26)*$BA6)/$I6 -> 0.036782405 | BK26: =SUM(BD26:BJ26) -> 1 | BM26: 2006 | BN26: =BN6/$BU6 -> 0.26148846 | BO26: =BO6/$BU6 -> 0.23198274 | BP26: =BP6/$BU6 -> 0.19754539 | BQ26: =BQ6/$BU6 -> 0.08050325 | BR26: =BR6/$BU6 -> 0.10412464 | BS26: =BS6/$BU6 -> 0.088405066 | BT26: =BT6/$BU6 -> 0.03595046 | BU26: =SUM(BN26:BT26) -> 1 | BW26: 2006 | BX26: =IFERROR(BX6/$CE6,0) -> 0.27637587 | BY26: =IFERROR(BY6/$CE6,0) -> 0.2005127 | BZ26: =IFERROR(BZ6/$CE6,0) -> 0.21969879 | CA26: =IFERROR(CA6/$CE6,0) -> 0.070495874 | CB26: =IFERROR(CB6/$CE6,0) -> 0.10638468 | CC26: =IFERROR(CC6/$CE6,0) -> 0.088560442 | CD26: =IFERROR(CD6/$CE6,0) -> 0.037971641 | CE26: =SUM(BX26:CD26) -> 1
A27: 2007 | B27: =BE27 -> 0.21644663 | C27: =BF27 -> 0.20244881 | D27: =BG27 -> 0.073220636 | E27: =BH27 -> 0.10746821 | F27: =BI27 -> 0.092577256 | G27: =BD27 -> 0.26985596 | H27: =BJ27 -> 0.037982495 | I27: =BK27 -> 1 | K27: 2007 | L27: =L7/$T7 -> 0.26087607 | M27: =M7/$T7 -> 0.23102532 | N27: =N7/$T7 -> 0.19092507 | O27: =O7/$T7 -> 0.078554595 | P27: =P7/$T7 -> 0.11079939 | Q27: =Q7/$T7 -> 0.09235776 | R27: =R7/$T7 -> 0 | S27: =S7/$T7 -> 0.035461789 | T27: =T7/$T7 -> 1 | V27: 2007 | W27: =W7/$AE7 -> 0.27885646 | X27: =X7/$AE7 -> 0.19706174 | Y27: =Y7/$AE7 -> 0.21584276 | Z27: =Z7/$AE7 -> 0.067857852 | AA27: =AA7/$AE7 -> 0.10883462 | AB27: =AB7/$AE7 -> 0.092237443 | AC27: =AC7/$AE7 -> 0 | AD27: =AD7/$AE7 -> 0.039309113 | AE27: =AE7/$AE7 -> 1 | AG27: 2007 | AH27: =AH7/$AP7 -> 0.27121275 | AI27: =AI7/$AP7 -> 0.22661424 | AJ27: =AJ7/$AP7 -> 0.19939983 | AK27: =AK7/$AP7 -> 0.072433775 | AL27: =AL7/$AP7 -> 0.094681291 | AM27: =AM7/$AP7 -> 0.09406043 | AN27: =AN7/$AP7 -> 0 | AO27: =AO7/$AP7 -> 0.041494205 | AP27: =AP7/$AE7 -> 0.38372047 | AR27: 2007 | AS27: =IFERROR(AS7/$BA7,0) -> 0 | AT27: =IFERROR(AT7/$BA7,0) -> 0 | AU27: =IFERROR(AU7/$BA7,0) -> 0 | AV27: =IFERROR(AV7/$BA7,0) -> 0 | AW27: =IFERROR(AW7/$BA7,0) -> 0 | AX27: =IFERROR(AX7/$BA7,0) -> 0 | AY27: =IFERROR(AY7/$BA7,0) -> 0 | AZ27: =AZ7/$AP7 -> 0 | BA27: =BA7/$AE7 -> 0 | BC27: 2007 | BD27: =(L27*$T7+W27*$AE7+AH27*$AP7+AS27*$BA7)/$I7 -> 0.26985596 | BE27: =(M27*$T7+X27*$AE7+AI27*$AP7+AT27*$BA7)/$I7 -> 0.21644663 | BF27: =(N27*$T7+Y27*$AE7+AJ27*$AP7+AU27*$BA7)/$I7 -> 0.20244881 | BG27: =(O27*$T7+Z27*$AE7+AK27*$AP7+AV27*$BA7)/$I7 -> 0.073220636 | BH27: =(P27*$T7+AA27*$AE7+AL27*$AP7+AW27*$BA7)/$I7 -> 0.10746821 | BI27: =(Q27*$T7+AB27*$AE7+AM27*$AP7+AX27*$BA7)/$I7 -> 0.092577256 | BJ27: =((R27+S27)*$T7+(AC27+AD27)*$AE7+(AN27+AO27)*$AP7+(AZ27+AY27)*$BA7)/$I7 -> 0.037982495 | BK27: =SUM(BD27:BJ27) -> 1 | BM27: 2007 | BN27: =BN7/$BU7 -> 0.26362787 | BO27: =BO7/$BU7 -> 0.22986042 | BP27: =BP7/$BU7 -> 0.19318057 | BQ27: =BQ7/$BU7 -> 0.076931531 | BR27: =BR7/$BU7 -> 0.10652269 | BS27: =BS7/$BU7 -> 0.092812397 | BT27: =BT7/$BU7 -> 0.037064513 | BU27: =SUM(BN27:BT27) -> 1 | BW27: 2007 | BX27: =IFERROR(BX7/$CE7,0) -> 0.27885646 | BY27: =IFERROR(BY7/$CE7,0) -> 0.19706174 | BZ27: =IFERROR(BZ7/$CE7,0) -> 0.21584276 | CA27: =IFERROR(CA7/$CE7,0) -> 0.067857852 | CB27: =IFERROR(CB7/$CE7,0) -> 0.10883462 | CC27: =IFERROR(CC7/$CE7,0) -> 0.092237443 | CD27: =IFERROR(CD7/$CE7,0) -> 0.039309113 | CE27: =SUM(BX27:CD27) -> 1
A28: 2008 | B28: =BE28 -> 0.20992451 | C28: =BF28 -> 0.20332291 | D28: =BG28 -> 0.068748223 | E28: =BH28 -> 0.10748918 | F28: =BI28 -> 0.095091443 | G28: =BD28 -> 0.27693547 | H28: =BJ28 -> 0.038488266 | I28: =BK28 -> 1 | K28: 2008 | L28: =L8/$T8 -> 0.26475578 | M28: =M8/$T8 -> 0.22526263 | N28: =N8/$T8 -> 0.19215913 | O28: =O8/$T8 -> 0.074185047 | P28: =P8/$T8 -> 0.11194542 | Q28: =Q8/$T8 -> 0.095520017 | R28: =R8/$T8 -> 0 | S28: =S8/$T8 -> 0.036171979 | T28: =T8/$T8 -> 1 | V28: 2008 | W28: =W8/$AE8 -> 0.28723613 | X28: =X8/$AE8 -> 0.18940195 | Y28: =Y8/$AE8 -> 0.21771825 | Z28: =Z8/$AE8 -> 0.063643129 | AA28: =AA8/$AE8 -> 0.10829123 | AB28: =AB8/$AE8 -> 0.093917675 | AC28: =AC8/$AE8 -> 0 | AD28: =AD8/$AE8 -> 0.039830807 | AE28: =AE8/$AE8 -> 1 | AG28: 2008 | AH28: =AH8/$AP8 -> 0.28436818 | AI28: =AI8/$AP8 -> 0.21979766 | AJ28: =AJ8/$AP8 -> 0.19757985 | AK28: =AK8/$AP8 -> 0.066752628 | AL28: =AL8/$AP8 -> 0.093235469 | AM28: =AM8/$AP8 -> 0.096905376 | AN28: =AN8/$AP8 -> 0 | AO28: =AO8/$AP8 -> 0.041460028 | AP28: =AP8/$AE8 -> 0.39486155 | AR28: 2008 | AS28: =IFERROR(AS8/$BA8,0) -> 0 | AT28: =IFERROR(AT8/$BA8,0) -> 0 | AU28: =IFERROR(AU8/$BA8,0) -> 0 | AV28: =IFERROR(AV8/$BA8,0) -> 0 | AW28: =IFERROR(AW8/$BA8,0) -> 0 | AX28: =IFERROR(AX8/$BA8,0) -> 0 | AY28: =IFERROR(AY8/$BA8,0) -> 0 | AZ28: =AZ8/$AP8 -> 0 | BA28: =BA8/$AE8 -> 0 | BC28: 2008 | BD28: =(L28*$T8+W28*$AE8+AH28*$AP8+AS28*$BA8)/$I8 -> 0.27693547 | BE28: =(M28*$T8+X28*$AE8+AI28*$AP8+AT28*$BA8)/$I8 -> 0.20992451 | BF28: =(N28*$T8+Y28*$AE8+AJ28*$AP8+AU28*$BA8)/$I8 -> 0.20332291 | BG28: =(O28*$T8+Z28*$AE8+AK28*$AP8+AV28*$BA8)/$I8 -> 0.068748223 | BH28: =(P28*$T8+AA28*$AE8+AL28*$AP8+AW28*$BA8)/$I8 -> 0.10748918 | BI28: =(Q28*$T8+AB28*$AE8+AM28*$AP8+AX28*$BA8)/$I8 -> 0.095091443 | BJ28: =((R28+S28)*$T8+(AC28+AD28)*$AE8+(AN28+AO28)*$AP8+(AZ28+AY28)*$BA8)/$I8 -> 0.038488266 | BK28: =SUM(BD28:BJ28) -> 1 | BM28: 2008 | BN28: =BN8/$BU8 -> 0.269982 | BO28: =BO8/$BU8 -> 0.22379843 | BP28: =BP8/$BU8 -> 0.19360047 | BQ28: =BQ8/$BU8 -> 0.072199873 | BR28: =BR8/$BU8 -> 0.10695003 | BS28: =BS8/$BU8 -> 0.095887148 | BT28: =BT8/$BU8 -> 0.037582045 | BU28: =SUM(BN28:BT28) -> 1 | BW28: 2008 | BX28: =IFERROR(BX8/$CE8,0) -> 0.28722488 | BY28: =IFERROR(BY8/$CE8,0) -> 0.18939453 | BZ28: =IFERROR(BZ8/$CE8,0) -> 0.21770972 | CA28: =IFERROR(CA8/$CE8,0) -> 0.063640636 | CB28: =IFERROR(CB8/$CE8,0) -> 0.10828699 | CC28: =IFERROR(CC8/$CE8,0) -> 0.093913997 | CD28: =IFERROR(CD8/$CE8,0) -> 0.039829247 | CE28: =SUM(BX28:CD28) -> 1
