Workbook

Sheet About
A1: FoHObDT Fraction of Health Outcomes by Demographic Trait
A3: Source: | B3: Health Outcome Distribution by County by Pollutant by Emitting Sector
B4: U.S. Environmental Protection Agency
B5: 2021
B6: COBRA
B7: https://www.epa.gov/cobra
B8: Use web edition at https://cobra.app.cloud.gov/
B10: Demographics of Population by County
B11: U.S. Census Bureau
B12: 2020
B13: County Population by Characteristics: 2010-2019
B14: https://www.census.gov/data/tables/time-series/demo/popest/2010s-counties-detail.html
B15: "United States" file "Annual County Resident Population Estimates by Age, Sex, Race, and Hispanic Origin: April 1, 2010 to July 1, 2019 (CC-EST2019-ALLDATA)"
B16: Filtered to remove age bracket rows, past year rows, and unused race/ethnicity columns
B18: Future Year Projections
B19: U.S. Census Bureau
B20: 2017
B21: Projections for the United States: 2017-2060
B22: https://www.census.gov/data/tables/2017/demo/popproj/2017-summary-tables.html
B23: Main Series, Table 4
A25: Notes
A27: In HOIpTP, the EPS calculates the number of avoided premature deaths per ton of pollutant abated. That doesn’t give us a demographic breakout of the avoided deaths.
A28: This variable's purpose is to allocate avoided deaths among people broken out by sex, race, and Hispanic or Latino status.
A30: Since the EPS is a fast-running model, we need a set of static multipliers derived from a more detailed model. (This is analogous to the way the EPA produced static multipliers derived from runs of their
A31: BenMAP tool in the following document:
A32: https://www.epa.gov/sites/production/files/2018-02/documents/sourceapportionmentbpttsd_2018.pdf
A33: We use the EPA’s COBRA model for this, because it can provide county-level impact information, and we can get county-level demographic information from the U.S. Census.
A35: A series of COBRA model runs were performed in order to get health impacts disaggregated down to the U.S. county level. The EPS groups emissions from sectors when calculating health impacts, so we
A36: need separate COBRA runs for each EPS sector. EPS health impacts are based on direct PM2.5, NOx, and SOx/SO2, so three runs (one for each pollutant) were performed for each EPS sector (except
A37: LULUCF, for which the EPA only had data for one pollutant used for health impacts in the EPS), for a total of 13 runs. Pollutants were reduced by 50% relative to baseline in each test. (The exact
A38: reduction percentage doesn't matter, as we're only using this to apportion impacts among counties, not to calculate the absolute magnitude of impacts. 50% reduction should avoid any potential
A39: odd behavior near 0% and 100%, giving a representative apportionment.)
... A42: COBRA sectors to form a single EPS sector):
A44: EPS Sector | B44: COBRA Sectors
A45: transport | B45: highway vehicles, off-highway
A46: electricity | B46: fuel combustion: electric utility
A47: buildings | B47: fuel combustion: other
A48: industry | B48: chemical & allied product manufacturing, fuel combustion: industrial, metals processing, other industrial process, petroleum & related industries
A49: LULUCF | B49: natural resources
A51: We only are disaggregating mortality (not other health outcomes) in the EPS by demographic traits, so only mortality results were recorded from the COBRA runs, to save on file size and
...

Sheet EPA Data
D1: Avoided All-Cause Mortality from 50% Reduction in Listed Pollutant from Listed Sector
A2: FIPS | B2: STATE | C2: COUNTY | D2: Electricity PM2.5 | E2: Electricity NOx | F2: Electricity SO2 | G2: Transport PM2.5 | H2: Transport NOx | I2: Transport SO2 | J2: Industry PM2.5 | K2: Industry NOx | L2: Industry SO2 | M2: Buildings PM2.5 | N2: Buildings NOx | O2: Buildings SO2 | P2: LULUCF
A3: 01001 | B3: Alabama | C3: Autauga | D3: 0.42223362 | E3: 0.10984253 | F3: 0.37934946 | G3: 0.25921369 | H3: 0.49183914 | I3: 0.025798067 | J3: 1.1604378 | K3: 0.31433105 | L3: 0.89310628 | M3: 0.30422545 | N3: 0.042070889 | O3: 0.016383812 | P3: 0.12963945
A4: 01003 | B4: Alabama | C4: Baldwin | D4: 0.68589473 | E4: 0.45448532 | F4: 1.9206996 | G4: 1.6023033 | H4: 2.6244283 | I4: 0.15914061 | J4: 5.0122162 | K4: 1.3594963 | L4: 3.0407817 | M4: 1.2692582 | N4: 0.18014942 | O4: 0.07065105 | P4: 0.63094453
A5: 01005 | B5: Alabama | C5: Barbour | D5: 0.066944824 | E5: 0.044303638 | F5: 0.1791837 | G5: 0.10555461 | H5: 0.22159911 | I5: 0.012177019 | J5: 0.49557419 | K5: 0.1262687 | L5: 0.31795104 | M5: 0.12089905 | N5: 0.018880073 | O5: 0.007568842 | P5: 0.063582185
A6: 01007 | B6: Alabama | C6: Bibb | D6: 0.063941474 | E6: 0.0463281 | F6: 0.18813345 | G6: 0.13394439 | H6: 0.24529835 | I6: 0.012437108 | J6: 0.49106936 | K6: 0.16147518 | L6: 0.42023984 | M6: 0.1396829 | N6: 0.021287678 | O6: 0.007801131 | P6: 0.057581864
A7: 01009 | B7: Alabama | C7: Blount | D7: 0.16416625 | E7: 0.1178101 | F7: 0.49571566 | G7: 0.39446476 | H7: 0.66735809 | I7: 0.031908272 | J7: 1.1615838 | K7: 0.33063725 | L7: 0.8009227 | M7: 0.52812672 | N7: 0.060143741 | O7: 0.022063402 | P7: 0.15742092
A8: 01011 | B8: Alabama | C8: Bullock | D8: 0.025105068 | E8: 0.015705266 | F8: 0.063479516 | G8: 0.03959552 | H8: 0.079231801 | I8: 0.004181578 | J8: 0.14945827 | K8: 0.044772635 | L8: 0.11817999 | M8: 0.044674703 | N8: 0.006859365 | O8: 0.002697322 | P8: 0.02244529
A9: 01013 | B9: Alabama | C9: Butler | D9: 0.056687442 | E9: 0.039380056 | F9: 0.16063078 | G9: 0.10128878 | H9: 0.20614897 | I9: 0.012037931 | J9: 0.37959944 | K9: 0.11036092 | L9: 0.29015455 | M9: 0.10246543 | N9: 0.016194052 | O9: 0.006554831 | P9: 0.056883954
A10: 01015 | B10: Alabama | C10: Calhoun | D10: 0.37028006 | E10: 0.25123191 | F10: 1.0301837 | G10: 0.94305071 | H10: 1.4638305 | I10: 0.070954667 | J10: 2.6234766 | K10: 0.71217419 | L10: 1.6675377 | M10: 1.2837392 | N10: 0.14773415 | O10: 0.047884811 | P10: 0.32255934
A11: 01017 | B11: Alabama | C11: Chambers | D11: 0.18139797 | E11: 0.074054665 | F11: 0.29148534 | G11: 0.2398771 | H11: 0.42638325 | I11: 0.026602961 | J11: 0.82127836 | K11: 0.20003887 | L11: 0.43966882 | M11: 0.2707659 | N11: 0.041440342 | O11: 0.01326363 | P11: 0.098060216
A12: 01019 | B12: Alabama | C12: Cherokee | D12: 0.11621263 | E12: 0.073352656 | F12: 0.30791261 | G12: 0.21857893 | H12: 0.39451449 | I12: 0.019948977 | J12: 0.61432315 | K12: 0.18344393 | L12: 0.39125701 | M12: 0.31251543 | N12: 0.040970736 | O12: 0.01468471 | P12: 0.094244924
A13: 01021 | B13: Alabama | C13: Chilton | D13: 0.14623669 | E13: 0.082415001 | F13: 0.33459699 | G13: 0.25748199 | H13: 0.45505093 | I13: 0.022775997 | J13: 0.93118013 | K13: 0.26708726 | L13: 0.69872784 | M13: 0.28521125 | N13: 0.03791772 | O13: 0.014370842 | P13: 0.10927278
A14: 01023 | B14: Alabama | C14: Choctaw | D14: 0.029341123 | E14: 0.024497114 | F14: 0.10704592 | G14: 0.047070908 | H14: 0.11137044 | I14: 0.006395084 | J14: 0.2757682 | K14: 0.09014522 | L14: 0.17991383 | M14: 0.056505014 | N14: 0.009522521 | O14: 0.00396334 | P14: 0.034418548
... A3110: 56045 | B3110: Wyoming | C3110: Weston | D3110: 0.009752365 | E3110: 0.011231607 | F3110: 0.026587753 | G3110: 0.014317059 | H3110: 0.04331759 | I3110: 0.001145671 | J3110: 0.039684944 | K3110: 0.042280595 | L3110: 0.020911522 | M3110: 0.013912399 | N3110: 0.003354686 | O3110: 0.000645936 | P3110: 0.0269374

Sheet Census Data
A1: FIPS | B1: STATE | C1: COUNTY | D1: STNAME | E1: CTYNAME | F1: TOT_POP | G1: TOT_MALE | H1: TOT_FEMALE | I1: WA_MALE | J1: WA_FEMALE | K1: BA_MALE | L1: BA_FEMALE | M1: IA_MALE | N1: IA_FEMALE | O1: AA_MALE | P1: AA_FEMALE | Q1: NA_MALE | R1: NA_FEMALE | S1: TOM_MALE | T1: TOM_FEMALE | U1: NH_MALE | V1: NH_FEMALE | W1: H_MALE | X1: H_FEMALE
A2: =TEXT(B2*1000+C2,"00000") -> 01001 | B2: 1 | C2: 1 | D2: Alabama | E2: Autauga | F2: 55869 | G2: 27092 | H2: 28777 | I2: 20878 | J2: 21729 | K2: 5237 | L2: 6000 | M2: 121 | N2: 145 | O2: 286 | P2: 370 | Q2: 32 | R2: 26 | S2: 538 | T2: 507 | U2: 26208 | V2: 27990 | W2: 884 | X2: 787
A3: =TEXT(B3*1000+C3,"00000") -> 01003 | B3: 1 | C3: 3 | D3: Alabama | E3: Baldwin | F3: 223234 | G3: 108247 | H3: 114987 | I3: 94810 | J3: 100388 | K3: 9486 | L3: 10107 | M3: 903 | N3: 839 | O3: 932 | P3: 1448 | Q3: 74 | R3: 80 | S3: 2042 | T3: 2125 | U3: 102702 | V3: 109998 | W3: 5545 | X3: 4989
A4: =TEXT(B4*1000+C4,"00000") -> 01005 | B4: 1 | C4: 5 | D4: Alabama | E4: Barbour | F4: 24686 | G4: 13064 | H4: 11622 | I4: 6389 | J4: 5745 | K4: 6311 | L4: 5595 | M4: 103 | N4: 67 | O4: 55 | P4: 61 | Q4: 34 | R4: 18 | S4: 172 | T4: 136 | U4: 12435 | V4: 11134 | W4: 629 | X4: 488
A5: =TEXT(B5*1000+C5,"00000") -> 01007 | B5: 1 | C5: 7 | D5: Alabama | E5: Bibb | F5: 22394 | G5: 11929 | H5: 10465 | I5: 8766 | J5: 8425 | K5: 2941 | L5: 1822 | M5: 53 | N5: 50 | O5: 23 | P5: 25 | Q5: 22 | R5: 4 | S5: 124 | T5: 139 | U5: 11586 | V5: 10185 | W5: 343 | X5: 280
A6: =TEXT(B6*1000+C6,"00000") -> 01009 | B6: 1 | C6: 9 | D6: Alabama | E6: Blount | F6: 57826 | G6: 28472 | H6: 29354 | I6: 27258 | J6: 28154 | K6: 516 | L6: 462 | M6: 192 | N6: 178 | O6: 85 | P6: 100 | Q6: 42 | R6: 25 | S6: 379 | T6: 435 | U6: 25522 | V6: 26722 | W6: 2950 | X6: 2632
A7: =TEXT(B7*1000+C7,"00000") -> 01011 | B7: 1 | C7: 11 | D7: Alabama | E7: Bullock | F7: 10101 | G7: 5508 | H7: 4593 | I7: 1629 | J7: 1060 | K7: 3713 | L7: 3384 | M7: 40 | N7: 44 | O7: 9 | P7: 12 | Q7: 41 | R7: 36 | S7: 76 | T7: 57 | U7: 5059 | V7: 4178 | W7: 449 | X7: 415
A8: =TEXT(B8*1000+C8,"00000") -> 01013 | B8: 1 | C8: 13 | D8: Alabama | E8: Butler | F8: 19448 | G8: 9024 | H8: 10424 | I8: 4829 | J8: 5298 | K8: 3885 | L8: 4862 | M8: 39 | N8: 38 | O8: 168 | P8: 111 | Q8: 4 | R8: 4 | S8: 99 | T8: 111 | U8: 8871 | V8: 10288 | W8: 153 | X8: 136
A9: =TEXT(B9*1000+C9,"00000") -> 01015 | B9: 1 | C9: 15 | D9: Alabama | E9: Calhoun | F9: 113605 | G9: 54481 | H9: 59124 | I9: 41342 | J9: 43980 | K9: 11220 | L9: 12993 | M9: 310 | N9: 295 | O9: 401 | P9: 623 | Q9: 65 | R9: 62 | S9: 1143 | T9: 1171 | U9: 52123 | V9: 56868 | W9: 2358 | X9: 2256
A10: =TEXT(B10*1000+C10,"00000") -> 01017 | B10: 1 | C10: 17 | D10: Alabama | E10: Chambers | F10: 33254 | G10: 15895 | H10: 17359 | I10: 9157 | J10: 9813 | K10: 6221 | L10: 7144 | M10: 59 | N10: 50 | O10: 240 | P10: 134 | Q10: 10 | R10: 5 | S10: 208 | T10: 213 | U10: 15423 | V10: 16960 | W10: 472 | X10: 399
A11: =TEXT(B11*1000+C11,"00000") -> 01019 | B11: 1 | C11: 19 | D11: Alabama | E11: Cherokee | F11: 26196 | G11: 12926 | H11: 13270 | I11: 12033 | J11: 12376 | K11: 558 | L11: 515 | M11: 94 | N11: 87 | O11: 37 | P11: 66 | Q11: 5 | R11: 3 | S11: 199 | T11: 223 | U11: 12697 | V11: 13050 | W11: 229 | X11: 220
A12: =TEXT(B12*1000+C12,"00000") -> 01021 | B12: 1 | C12: 21 | D12: Alabama | E12: Chilton | F12: 44428 | G12: 21800 | H12: 22628 | I12: 18965 | J12: 19712 | K12: 2247 | L12: 2349 | M12: 132 | N12: 118 | O12: 87 | P12: 130 | Q12: 48 | R12: 29 | S12: 321 | T12: 290 | U12: 19810 | V12: 20982 | W12: 1990 | X12: 1646
A13: =TEXT(B13*1000+C13,"00000") -> 01023 | B13: 1 | C13: 23 | D13: Alabama | E13: Choctaw | F13: 12589 | G13: 5938 | H13: 6651 | I13: 3499 | J13: 3692 | K13: 2370 | L13: 2885 | M13: 16 | N13: 10 | O13: 7 | P13: 18 | Q13: 0 | R13: 0 | S13: 46 | T13: 46 | U13: 5883 | V13: 6578 | W13: 55 | X13: 73
... A3143: =TEXT(B3143*1000+C3143,"00000") -> 56045 | B3143: 56 | C3143: 45 | D3143: Wyoming | E3143: Weston | F3143: 6927 | G3143: 3624 | H3143: 3303 | I3143: 3392 | J3143: 3062 | K3143: 32 | L3143: 16 | M3143: 78 | N3143: 53 | O3143: 34 | P3143: 83 | Q3143: 2 | R3143: 0 | S3143: 86 | T3143: 89 | U3143: 3469 | V3143: 3173 | W3143: 155 | X3143: 130

Sheet First Year Calculations
A1: FIPS | B1: STATE | C1: COUNTY | D1: male | E1: female | F1: white | G1: black | H1: asian | I1: other race | J1: hispanic | K1: nonhispanic | L1: % Electricity PM2.5 | M1: % Electricity NOx | N1: % Electricity SO2 | O1: % Transport PM2.5 | P1: % Transport NOx | Q1: % Transport SO2 | R1: % Industry PM2.5 | S1: % Industry NOx | T1: % Industry SO2 | U1: % Buildings PM2.5 | V1: % Buildings NOx | W1: % Buildings SO2 | X1: % LULUCF
A2: 01001 | B2: Alabama | C2: Autauga | D2: =SUMIFS('Census Data'!G:G,'Census Data'!$A:$A,$A2)/SUMIFS('Census Data'!$F:$F,'Census Data'!$A:$A,$A2) -> 0.48492008 | E2: =SUMIFS('Census Data'!H:H,'Census Data'!$A:$A,$A2)/SUMIFS('Census Data'!$F:$F,'Census Data'!$A:$A,$A2) -> 0.51507992 | F2: =SUM(SUMIFS('Census Data'!I:I,'Census Data'!$A:$A,$A2),SUMIFS('Census Data'!J:J,'Census Data'!$A:$A,$A2))/SUMIFS('Census Data'!$F:$F,'Census Data'!$A:$A,$A2) -> 0.76262328 | G2: =SUM(SUMIFS('Census Data'!K:K,'Census Data'!$A:$A,$A2),SUMIFS('Census Data'!L:L,'Census Data'!$A:$A,$A2))/SUMIFS('Census Data'!$F:$F,'Census Data'!$A:$A,$A2) -> 0.20113122 | H2: =SUM(SUMIFS('Census Data'!O:O,'Census Data'!$A:$A,$A2),SUMIFS('Census Data'!P:P,'Census Data'!$A:$A,$A2))/SUMIFS('Census Data'!$F:$F,'Census Data'!$A:$A,$A2) -> 0.011741753 | I2: =100%-SUM(F2:H2) -> 0.02450375 | J2: =SUM(SUMIFS('Census Data'!W:W,'Census Data'!$A:$A,$A2),SUMIFS('Census Data'!X:X,'Census Data'!$A:$A,$A2))/SUMIFS('Census Data'!$F:$F,'Census Data'!$A:$A,$A2) -> 0.029909252 | K2: =100%-J2 -> 0.97009075 | L2: ='EPA Data'!D3/SUM('EPA Data'!D:D) -> 0.00029441307 | M2: ='EPA Data'!E3/SUM('EPA Data'!E:E) -> 0.00017781152 | N2: ='EPA Data'!F3/SUM('EPA Data'!F:F) -> 0.00018249641 | O2: ='EPA Data'!G3/SUM('EPA Data'!G:G) -> 6.3660489e-05 | P2: ='EPA Data'!H3/SUM('EPA Data'!H:H) -> 0.00010862356 | Q2: ='EPA Data'!I3/SUM('EPA Data'!I:I) -> 6.7581597e-05 | R2: ='EPA Data'!J3/SUM('EPA Data'!J:J) -> 0.00011553481 | S2: ='EPA Data'!K3/SUM('EPA Data'!K:K) -> 0.00018275232 | T2: ='EPA Data'!L3/SUM('EPA Data'!L:L) -> 0.0003966398 | U2: ='EPA Data'!M3/SUM('EPA Data'!M:M) -> 5.1434601e-05 | V2: ='EPA Data'!N3/SUM('EPA Data'!N:N) -> 5.3141437e-05 | W2: ='EPA Data'!O3/SUM('EPA Data'!O:O) -> 6.3464995e-05 | X2: ='EPA Data'!P3/SUM('EPA Data'!P:P) -> 0.00017397857
A3: 01003 | B3: Alabama | C3: Baldwin | D3: =SUMIFS('Census Data'!G:G,'Census Data'!$A:$A,$A3)/SUMIFS('Census Data'!$F:$F,'Census Data'!$A:$A,$A3) -> 0.48490373 | E3: =SUMIFS('Census Data'!H:H,'Census Data'!$A:$A,$A3)/SUMIFS('Census Data'!$F:$F,'Census Data'!$A:$A,$A3) -> 0.51509627 | F3: =SUM(SUMIFS('Census Data'!I:I,'Census Data'!$A:$A,$A3),SUMIFS('Census Data'!J:J,'Census Data'!$A:$A,$A3))/SUMIFS('Census Data'!$F:$F,'Census Data'!$A:$A,$A3) -> 0.87440981 | G3: =SUM(SUMIFS('Census Data'!K:K,'Census Data'!$A:$A,$A3),SUMIFS('Census Data'!L:L,'Census Data'!$A:$A,$A3))/SUMIFS('Census Data'!$F:$F,'Census Data'!$A:$A,$A3) -> 0.087768888 | H3: =SUM(SUMIFS('Census Data'!O:O,'Census Data'!$A:$A,$A3),SUMIFS('Census Data'!P:P,'Census Data'!$A:$A,$A3))/SUMIFS('Census Data'!$F:$F,'Census Data'!$A:$A,$A3) -> 0.010661458 | I3: =100%-SUM(F3:H3) -> 0.027159841 | J3: =SUM(SUMIFS('Census Data'!W:W,'Census Data'!$A:$A,$A3),SUMIFS('Census Data'!X:X,'Census Data'!$A:$A,$A3))/SUMIFS('Census Data'!$F:$F,'Census Data'!$A:$A,$A3) -> 0.047188152 | K3: =100%-J3 -> 0.95281185 | L3: ='EPA Data'!D4/SUM('EPA Data'!D:D) -> 0.00047825744 | M3: ='EPA Data'!E4/SUM('EPA Data'!E:E) -> 0.00073571436 | N3: ='EPA Data'!F4/SUM('EPA Data'!F:F) -> 0.00092400493 | O3: ='EPA Data'!G4/SUM('EPA Data'!G:G) -> 0.0003935109 | P3: ='EPA Data'!H4/SUM('EPA Data'!H:H) -> 0.00057960971 | Q3: ='EPA Data'!I4/SUM('EPA Data'!I:I) -> 0.0004168908 | R3: ='EPA Data'!J4/SUM('EPA Data'!J:J) -> 0.00049902325 | S3: ='EPA Data'!K4/SUM('EPA Data'!K:K) -> 0.00079041221 | T3: ='EPA Data'!L4/SUM('EPA Data'!L:L) -> 0.0013504496 | U3: ='EPA Data'!M4/SUM('EPA Data'!M:M) -> 0.00021459016 | V3: ='EPA Data'!N4/SUM('EPA Data'!N:N) -> 0.00022755399 | W3: ='EPA Data'!O4/SUM('EPA Data'!O:O) -> 0.00027367676 | X3: ='EPA Data'!P4/SUM('EPA Data'!P:P) -> 0.00084673934
A4: 01005 | B4: Alabama | C4: Barbour | D4: =SUMIFS('Census Data'!G:G,'Census Data'!$A:$A,$A4)/SUMIFS('Census Data'!$F:$F,'Census Data'!$A:$A,$A4) -> 0.52920684 | E4: =SUMIFS('Census Data'!H:H,'Census Data'!$A:$A,$A4)/SUMIFS('Census Data'!$F:$F,'Census Data'!$A:$A,$A4) -> 0.47079316 | F4: =SUM(SUMIFS('Census Data'!I:I,'Census Data'!$A:$A,$A4),SUMIFS('Census Data'!J:J,'Census Data'!$A:$A,$A4))/SUMIFS('Census Data'!$F:$F,'Census Data'!$A:$A,$A4) -> 0.49153366 | G4: =SUM(SUMIFS('Census Data'!K:K,'Census Data'!$A:$A,$A4),SUMIFS('Census Data'!L:L,'Census Data'!$A:$A,$A4))/SUMIFS('Census Data'!$F:$F,'Census Data'!$A:$A,$A4) -> 0.48229766 | H4: =SUM(SUMIFS('Census Data'!O:O,'Census Data'!$A:$A,$A4),SUMIFS('Census Data'!P:P,'Census Data'!$A:$A,$A4))/SUMIFS('Census Data'!$F:$F,'Census Data'!$A:$A,$A4) -> 0.0046990197 | I4: =100%-SUM(F4:H4) -> 0.021469659 | J4: =SUM(SUMIFS('Census Data'!W:W,'Census Data'!$A:$A,$A4),SUMIFS('Census Data'!X:X,'Census Data'!$A:$A,$A4))/SUMIFS('Census Data'!$F:$F,'Census Data'!$A:$A,$A4) -> 0.045248319 | K4: =100%-J4 -> 0.95475168 | L4: ='EPA Data'!D5/SUM('EPA Data'!D:D) -> 4.6678971e-05 | M4: ='EPA Data'!E5/SUM('EPA Data'!E:E) -> 7.1718098e-05 | N4: ='EPA Data'!F5/SUM('EPA Data'!F:F) -> 8.6201205e-05 | O4: ='EPA Data'!G5/SUM('EPA Data'!G:G) -> 2.5923237e-05 | P4: ='EPA Data'!H5/SUM('EPA Data'!H:H) -> 4.8940562e-05 | Q4: ='EPA Data'!I5/SUM('EPA Data'!I:I) -> 3.1899382e-05 | R4: ='EPA Data'!J5/SUM('EPA Data'!J:J) -> 4.934006e-05 | S4: ='EPA Data'!K5/SUM('EPA Data'!K:K) -> 7.3412719e-05 | T4: ='EPA Data'!L5/SUM('EPA Data'!L:L) -> 0.00014120608 | U4: ='EPA Data'!M5/SUM('EPA Data'!M:M) -> 2.0440086e-05 | V4: ='EPA Data'!N5/SUM('EPA Data'!N:N) -> 2.3848182e-05 | W4: ='EPA Data'!O5/SUM('EPA Data'!O:O) -> 2.9318971e-05 | X4: ='EPA Data'!P5/SUM('EPA Data'!P:P) -> 8.5328479e-05
A5: 01007 | B5: Alabama | C5: Bibb | D5: =SUMIFS('Census Data'!G:G,'Census Data'!$A:$A,$A5)/SUMIFS('Census Data'!$F:$F,'Census Data'!$A:$A,$A5) -> 0.53268733 | E5: =SUMIFS('Census Data'!H:H,'Census Data'!$A:$A,$A5)/SUMIFS('Census Data'!$F:$F,'Census Data'!$A:$A,$A5) -> 0.46731267 | F5: =SUM(SUMIFS('Census Data'!I:I,'Census Data'!$A:$A,$A5),SUMIFS('Census Data'!J:J,'Census Data'!$A:$A,$A5))/SUMIFS('Census Data'!$F:$F,'Census Data'!$A:$A,$A5) -> 0.76766098 | G5: =SUM(SUMIFS('Census Data'!K:K,'Census Data'!$A:$A,$A5),SUMIFS('Census Data'!L:L,'Census Data'!$A:$A,$A5))/SUMIFS('Census Data'!$F:$F,'Census Data'!$A:$A,$A5) -> 0.2126909 | H5: =SUM(SUMIFS('Census Data'!O:O,'Census Data'!$A:$A,$A5),SUMIFS('Census Data'!P:P,'Census Data'!$A:$A,$A5))/SUMIFS('Census Data'!$F:$F,'Census Data'!$A:$A,$A5) -> 0.0021434313 | I5: =100%-SUM(F5:H5) -> 0.017504689 | J5: =SUM(SUMIFS('Census Data'!W:W,'Census Data'!$A:$A,$A5),SUMIFS('Census Data'!X:X,'Census Data'!$A:$A,$A5))/SUMIFS('Census Data'!$F:$F,'Census Data'!$A:$A,$A5) -> 0.027819952 | K5: =100%-J5 -> 0.97218005 | L5: ='EPA Data'!D6/SUM('EPA Data'!D:D) -> 4.4584809e-05 | M5: ='EPA Data'!E6/SUM('EPA Data'!E:E) -> 7.4995267e-05 | N5: ='EPA Data'!F6/SUM('EPA Data'!F:F) -> 9.050673e-05 | O5: ='EPA Data'!G6/SUM('EPA Data'!G:G) -> 3.2895505e-05 | P5: ='EPA Data'!H6/SUM('EPA Data'!H:H) -> 5.4174583e-05 | Q5: ='EPA Data'!I6/SUM('EPA Data'!I:I) -> 3.2580721e-05 | R5: ='EPA Data'!J6/SUM('EPA Data'!J:J) -> 4.8891552e-05 | S5: ='EPA Data'!K6/SUM('EPA Data'!K:K) -> 9.3881795e-05 | T5: ='EPA Data'!L6/SUM('EPA Data'!L:L) -> 0.00018663383 | U5: ='EPA Data'!M6/SUM('EPA Data'!M:M) -> 2.3615823e-05 | V5: ='EPA Data'!N6/SUM('EPA Data'!N:N) -> 2.6889325e-05 | W5: ='EPA Data'!O6/SUM('EPA Data'!O:O) -> 3.0218775e-05 | X5: ='EPA Data'!P6/SUM('EPA Data'!P:P) -> 7.7275936e-05
A6: 01009 | B6: Alabama | C6: Blount | D6: =SUMIFS('Census Data'!G:G,'Census Data'!$A:$A,$A6)/SUMIFS('Census Data'!$F:$F,'Census Data'!$A:$A,$A6) -> 0.49237367 | E6: =SUMIFS('Census Data'!H:H,'Census Data'!$A:$A,$A6)/SUMIFS('Census Data'!$F:$F,'Census Data'!$A:$A,$A6) -> 0.50762633 | F6: =SUM(SUMIFS('Census Data'!I:I,'Census Data'!$A:$A,$A6),SUMIFS('Census Data'!J:J,'Census Data'!$A:$A,$A6))/SUMIFS('Census Data'!$F:$F,'Census Data'!$A:$A,$A6) -> 0.95825407 | G6: =SUM(SUMIFS('Census Data'!K:K,'Census Data'!$A:$A,$A6),SUMIFS('Census Data'!L:L,'Census Data'!$A:$A,$A6))/SUMIFS('Census Data'!$F:$F,'Census Data'!$A:$A,$A6) -> 0.016912807 | H6: =SUM(SUMIFS('Census Data'!O:O,'Census Data'!$A:$A,$A6),SUMIFS('Census Data'!P:P,'Census Data'!$A:$A,$A6))/SUMIFS('Census Data'!$F:$F,'Census Data'!$A:$A,$A6) -> 0.0031992529 | I6: =100%-SUM(F6:H6) -> 0.021633867 | J6: =SUM(SUMIFS('Census Data'!W:W,'Census Data'!$A:$A,$A6),SUMIFS('Census Data'!X:X,'Census Data'!$A:$A,$A6))/SUMIFS('Census Data'!$F:$F,'Census Data'!$A:$A,$A6) -> 0.096530972 | K6: =100%-J6 -> 0.90346903 | L6: ='EPA Data'!D7/SUM('EPA Data'!D:D) -> 0.00011446907 | M6: ='EPA Data'!E7/SUM('EPA Data'!E:E) -> 0.00019070932 | N6: ='EPA Data'!F7/SUM('EPA Data'!F:F) -> 0.00023847754 | O6: ='EPA Data'!G7/SUM('EPA Data'!G:G) -> 9.6876901e-05 | P6: ='EPA Data'!H7/SUM('EPA Data'!H:H) -> 0.00014738724 | Q6: ='EPA Data'!I7/SUM('EPA Data'!I:I) -> 8.3588123e-05 | R6: ='EPA Data'!J7/SUM('EPA Data'!J:J) -> 0.00011564891 | S6: ='EPA Data'!K7/SUM('EPA Data'!K:K) -> 0.00019223275 | T6: ='EPA Data'!L7/SUM('EPA Data'!L:L) -> 0.0003556999 | U6: ='EPA Data'!M7/SUM('EPA Data'!M:M) -> 8.9289001e-05 | V6: ='EPA Data'!N7/SUM('EPA Data'!N:N) -> 7.5969985e-05 | W6: ='EPA Data'!O7/SUM('EPA Data'!O:O) -> 8.5465683e-05 | X6: ='EPA Data'!P7/SUM('EPA Data'!P:P) -> 0.00021126181
A7: 01011 | B7: Alabama | C7: Bullock | D7: =SUMIFS('Census Data'!G:G,'Census Data'!$A:$A,$A7)/SUMIFS('Census Data'!$F:$F,'Census Data'!$A:$A,$A7) -> 0.54529255 | E7: =SUMIFS('Census Data'!H:H,'Census Data'!$A:$A,$A7)/SUMIFS('Census Data'!$F:$F,'Census Data'!$A:$A,$A7) -> 0.45470745 | F7: =SUM(SUMIFS('Census Data'!I:I,'Census Data'!$A:$A,$A7),SUMIFS('Census Data'!J:J,'Census Data'!$A:$A,$A7))/SUMIFS('Census Data'!$F:$F,'Census Data'!$A:$A,$A7) -> 0.26621127 | G7: =SUM(SUMIFS('Census Data'!K:K,'Census Data'!$A:$A,$A7),SUMIFS('Census Data'!L:L,'Census Data'!$A:$A,$A7))/SUMIFS('Census Data'!$F:$F,'Census Data'!$A:$A,$A7) -> 0.7026037 | H7: =SUM(SUMIFS('Census Data'!O:O,'Census Data'!$A:$A,$A7),SUMIFS('Census Data'!P:P,'Census Data'!$A:$A,$A7))/SUMIFS('Census Data'!$F:$F,'Census Data'!$A:$A,$A7) -> 0.0020790021 | I7: =100%-SUM(F7:H7) -> 0.029106029 | J7: =SUM(SUMIFS('Census Data'!W:W,'Census Data'!$A:$A,$A7),SUMIFS('Census Data'!X:X,'Census Data'!$A:$A,$A7))/SUMIFS('Census Data'!$F:$F,'Census Data'!$A:$A,$A7) -> 0.085536086 | K7: =100%-J7 -> 0.91446391 | L7: ='EPA Data'!D8/SUM('EPA Data'!D:D) -> 1.7505143e-05 | M7: ='EPA Data'!E8/SUM('EPA Data'!E:E) -> 2.5423461e-05 | N7: ='EPA Data'!F8/SUM('EPA Data'!F:F) -> 3.0538553e-05 | O7: ='EPA Data'!G8/SUM('EPA Data'!G:G) -> 9.724294e-06 | P7: ='EPA Data'!H8/SUM('EPA Data'!H:H) -> 1.7498486e-05 | Q7: ='EPA Data'!I8/SUM('EPA Data'!I:I) -> 1.0954221e-05 | R7: ='EPA Data'!J8/SUM('EPA Data'!J:J) -> 1.4880274e-05 | S7: ='EPA Data'!K8/SUM('EPA Data'!K:K) -> 2.6030845e-05 | T7: ='EPA Data'!L8/SUM('EPA Data'!L:L) -> 5.2485228e-05 | U7: ='EPA Data'!M8/SUM('EPA Data'!M:M) -> 7.553035e-06 | V7: ='EPA Data'!N8/SUM('EPA Data'!N:N) -> 8.6643406e-06 | W7: ='EPA Data'!O8/SUM('EPA Data'!O:O) -> 1.0448455e-05 | X7: ='EPA Data'!P8/SUM('EPA Data'!P:P) -> 3.0121998e-05
A8: 01013 | B8: Alabama | C8: Butler | D8: =SUMIFS('Census Data'!G:G,'Census Data'!$A:$A,$A8)/SUMIFS('Census Data'!$F:$F,'Census Data'!$A:$A,$A8) -> 0.46400658 | E8: =SUMIFS('Census Data'!H:H,'Census Data'!$A:$A,$A8)/SUMIFS('Census Data'!$F:$F,'Census Data'!$A:$A,$A8) -> 0.53599342 | F8: =SUM(SUMIFS('Census Data'!I:I,'Census Data'!$A:$A,$A8),SUMIFS('Census Data'!J:J,'Census Data'!$A:$A,$A8))/SUMIFS('Census Data'!$F:$F,'Census Data'!$A:$A,$A8) -> 0.52072193 | G8: =SUM(SUMIFS('Census Data'!K:K,'Census Data'!$A:$A,$A8),SUMIFS('Census Data'!L:L,'Census Data'!$A:$A,$A8))/SUMIFS('Census Data'!$F:$F,'Census Data'!$A:$A,$A8) -> 0.44976347 | H8: =SUM(SUMIFS('Census Data'!O:O,'Census Data'!$A:$A,$A8),SUMIFS('Census Data'!P:P,'Census Data'!$A:$A,$A8))/SUMIFS('Census Data'!$F:$F,'Census Data'!$A:$A,$A8) -> 0.014345948 | I8: =100%-SUM(F8:H8) -> 0.015168655 | J8: =SUM(SUMIFS('Census Data'!W:W,'Census Data'!$A:$A,$A8),SUMIFS('Census Data'!X:X,'Census Data'!$A:$A,$A8))/SUMIFS('Census Data'!$F:$F,'Census Data'!$A:$A,$A8) -> 0.01486014 | K8: =100%-J8 -> 0.98513986 | L8: ='EPA Data'!D9/SUM('EPA Data'!D:D) -> 3.9526752e-05 | M8: ='EPA Data'!E9/SUM('EPA Data'!E:E) -> 6.3747873e-05 | N8: ='EPA Data'!F9/SUM('EPA Data'!F:F) -> 7.7275818e-05 | O8: ='EPA Data'!G9/SUM('EPA Data'!G:G) -> 2.487559e-05 | P8: ='EPA Data'!H9/SUM('EPA Data'!H:H) -> 4.5528372e-05 | Q8: ='EPA Data'!I9/SUM('EPA Data'!I:I) -> 3.1535022e-05 | R8: ='EPA Data'!J9/SUM('EPA Data'!J:J) -> 3.7793452e-05 | S8: ='EPA Data'!K9/SUM('EPA Data'!K:K) -> 6.4163923e-05 | T8: ='EPA Data'!L9/SUM('EPA Data'!L:L) -> 0.00012886131 | U8: ='EPA Data'!M9/SUM('EPA Data'!M:M) -> 1.7323562e-05 | V8: ='EPA Data'!N9/SUM('EPA Data'!N:N) -> 2.045536e-05 | W8: ='EPA Data'!O9/SUM('EPA Data'!O:O) -> 2.5391058e-05 | X8: ='EPA Data'!P9/SUM('EPA Data'!P:P) -> 7.6339328e-05
A9: 01015 | B9: Alabama | C9: Calhoun | D9: =SUMIFS('Census Data'!G:G,'Census Data'!$A:$A,$A9)/SUMIFS('Census Data'!$F:$F,'Census Data'!$A:$A,$A9) -> 0.47956516 | E9: =SUMIFS('Census Data'!H:H,'Census Data'!$A:$A,$A9)/SUMIFS('Census Data'!$F:$F,'Census Data'!$A:$A,$A9) -> 0.52043484 | F9: =SUM(SUMIFS('Census Data'!I:I,'Census Data'!$A:$A,$A9),SUMIFS('Census Data'!J:J,'Census Data'!$A:$A,$A9))/SUMIFS('Census Data'!$F:$F,'Census Data'!$A:$A,$A9) -> 0.75104089 | G9: =SUM(SUMIFS('Census Data'!K:K,'Census Data'!$A:$A,$A9),SUMIFS('Census Data'!L:L,'Census Data'!$A:$A,$A9))/SUMIFS('Census Data'!$F:$F,'Census Data'!$A:$A,$A9) -> 0.21313322 | H9: =SUM(SUMIFS('Census Data'!O:O,'Census Data'!$A:$A,$A9),SUMIFS('Census Data'!P:P,'Census Data'!$A:$A,$A9))/SUMIFS('Census Data'!$F:$F,'Census Data'!$A:$A,$A9) -> 0.0090136878 | I9: =100%-SUM(F9:H9) -> 0.0268122 | J9: =SUM(SUMIFS('Census Data'!W:W,'Census Data'!$A:$A,$A9),SUMIFS('Census Data'!X:X,'Census Data'!$A:$A,$A9))/SUMIFS('Census Data'!$F:$F,'Census Data'!$A:$A,$A9) -> 0.04061441 | K9: =100%-J9 -> 0.95938559 | L9: ='EPA Data'!D10/SUM('EPA Data'!D:D) -> 0.00025818713 | M9: ='EPA Data'!E10/SUM('EPA Data'!E:E) -> 0.00040669063 | N9: ='EPA Data'!F10/SUM('EPA Data'!F:F) -> 0.00049559796 | O9: ='EPA Data'!G10/SUM('EPA Data'!G:G) -> 0.00023160455 | P9: ='EPA Data'!H10/SUM('EPA Data'!H:H) -> 0.00032328961 | Q9: ='EPA Data'!I10/SUM('EPA Data'!I:I) -> 0.00018587554 | R9: ='EPA Data'!J10/SUM('EPA Data'!J:J) -> 0.000261197 | S9: ='EPA Data'!K10/SUM('EPA Data'!K:K) -> 0.00041405863 | T9: ='EPA Data'!L10/SUM('EPA Data'!L:L) -> 0.0007405746 | U9: ='EPA Data'!M10/SUM('EPA Data'!M:M) -> 0.00021703842 | V9: ='EPA Data'!N10/SUM('EPA Data'!N:N) -> 0.00018660896 | W9: ='EPA Data'!O10/SUM('EPA Data'!O:O) -> 0.00018548853 | X9: ='EPA Data'!P10/SUM('EPA Data'!P:P) -> 0.00043288066
A10: 01017 | B10: Alabama | C10: Chambers | D10: =SUMIFS('Census Data'!G:G,'Census Data'!$A:$A,$A10)/SUMIFS('Census Data'!$F:$F,'Census Data'!$A:$A,$A10) -> 0.47798761 | E10: =SUMIFS('Census Data'!H:H,'Census Data'!$A:$A,$A10)/SUMIFS('Census Data'!$F:$F,'Census Data'!$A:$A,$A10) -> 0.52201239 | F10: =SUM(SUMIFS('Census Data'!I:I,'Census Data'!$A:$A,$A10),SUMIFS('Census Data'!J:J,'Census Data'!$A:$A,$A10))/SUMIFS('Census Data'!$F:$F,'Census Data'!$A:$A,$A10) -> 0.57045769 | G10: =SUM(SUMIFS('Census Data'!K:K,'Census Data'!$A:$A,$A10),SUMIFS('Census Data'!L:L,'Census Data'!$A:$A,$A10))/SUMIFS('Census Data'!$F:$F,'Census Data'!$A:$A,$A10) -> 0.40190654 | H10: =SUM(SUMIFS('Census Data'!O:O,'Census Data'!$A:$A,$A10),SUMIFS('Census Data'!P:P,'Census Data'!$A:$A,$A10))/SUMIFS('Census Data'!$F:$F,'Census Data'!$A:$A,$A10) -> 0.011246767 | I10: =100%-SUM(F10:H10) -> 0.016389006 | J10: =SUM(SUMIFS('Census Data'!W:W,'Census Data'!$A:$A,$A10),SUMIFS('Census Data'!X:X,'Census Data'!$A:$A,$A10))/SUMIFS('Census Data'!$F:$F,'Census Data'!$A:$A,$A10) -> 0.026192338 | K10: =100%-J10 -> 0.97380766 | L10: ='EPA Data'!D11/SUM('EPA Data'!D:D) -> 0.00012648432 | M10: ='EPA Data'!E11/SUM('EPA Data'!E:E) -> 0.00011987863 | N10: ='EPA Data'!F11/SUM('EPA Data'!F:F) -> 0.00014022697 | O10: ='EPA Data'!G11/SUM('EPA Data'!G:G) -> 5.89116e-05 | P10: ='EPA Data'!H11/SUM('EPA Data'!H:H) -> 9.4167508e-05 | Q10: ='EPA Data'!I11/SUM('EPA Data'!I:I) -> 6.9690128e-05 | R10: ='EPA Data'!J11/SUM('EPA Data'!J:J) -> 8.1767622e-05 | S10: ='EPA Data'!K11/SUM('EPA Data'!K:K) -> 0.00011630275 | T10: ='EPA Data'!L11/SUM('EPA Data'!L:L) -> 0.00019526249 | U10: ='EPA Data'!M11/SUM('EPA Data'!M:M) -> 4.5777682e-05 | V10: ='EPA Data'!N11/SUM('EPA Data'!N:N) -> 5.2344967e-05 | W10: ='EPA Data'!O11/SUM('EPA Data'!O:O) -> 5.1378532e-05 | X10: ='EPA Data'!P11/SUM('EPA Data'!P:P) -> 0.00013159864
A11: 01019 | B11: Alabama | C11: Cherokee | D11: =SUMIFS('Census Data'!G:G,'Census Data'!$A:$A,$A11)/SUMIFS('Census Data'!$F:$F,'Census Data'!$A:$A,$A11) -> 0.49343411 | E11: =SUMIFS('Census Data'!H:H,'Census Data'!$A:$A,$A11)/SUMIFS('Census Data'!$F:$F,'Census Data'!$A:$A,$A11) -> 0.50656589 | F11: =SUM(SUMIFS('Census Data'!I:I,'Census Data'!$A:$A,$A11),SUMIFS('Census Data'!J:J,'Census Data'!$A:$A,$A11))/SUMIFS('Census Data'!$F:$F,'Census Data'!$A:$A,$A11) -> 0.93178348 | G11: =SUM(SUMIFS('Census Data'!K:K,'Census Data'!$A:$A,$A11),SUMIFS('Census Data'!L:L,'Census Data'!$A:$A,$A11))/SUMIFS('Census Data'!$F:$F,'Census Data'!$A:$A,$A11) -> 0.040960452 | H11: =SUM(SUMIFS('Census Data'!O:O,'Census Data'!$A:$A,$A11),SUMIFS('Census Data'!P:P,'Census Data'!$A:$A,$A11))/SUMIFS('Census Data'!$F:$F,'Census Data'!$A:$A,$A11) -> 0.003931898 | I11: =100%-SUM(F11:H11) -> 0.023324172 | J11: =SUM(SUMIFS('Census Data'!W:W,'Census Data'!$A:$A,$A11),SUMIFS('Census Data'!X:X,'Census Data'!$A:$A,$A11))/SUMIFS('Census Data'!$F:$F,'Census Data'!$A:$A,$A11) -> 0.017140021 | K11: =100%-J11 -> 0.98285998 | L11: ='EPA Data'!D12/SUM('EPA Data'!D:D) -> 8.1032197e-05 | M11: ='EPA Data'!E12/SUM('EPA Data'!E:E) -> 0.00011874223 | N11: ='EPA Data'!F12/SUM('EPA Data'!F:F) -> 0.00014812976 | O11: ='EPA Data'!G12/SUM('EPA Data'!G:G) -> 5.3680966e-05 | P11: ='EPA Data'!H12/SUM('EPA Data'!H:H) -> 8.7129236e-05 | Q11: ='EPA Data'!I12/SUM('EPA Data'!I:I) -> 5.2259099e-05 | R11: ='EPA Data'!J12/SUM('EPA Data'!J:J) -> 6.1162872e-05 | S11: ='EPA Data'!K12/SUM('EPA Data'!K:K) -> 0.00010665444 | T11: ='EPA Data'!L12/SUM('EPA Data'!L:L) -> 0.00017376219 | U11: ='EPA Data'!M12/SUM('EPA Data'!M:M) -> 5.2836165e-05 | V11: ='EPA Data'!N12/SUM('EPA Data'!N:N) -> 5.1751789e-05 | W11: ='EPA Data'!O12/SUM('EPA Data'!O:O) -> 5.6883285e-05 | X11: ='EPA Data'!P12/SUM('EPA Data'!P:P) -> 0.00012647845
A12: 01021 | B12: Alabama | C12: Chilton | D12: =SUMIFS('Census Data'!G:G,'Census Data'!$A:$A,$A12)/SUMIFS('Census Data'!$F:$F,'Census Data'!$A:$A,$A12) -> 0.49068155 | E12: =SUMIFS('Census Data'!H:H,'Census Data'!$A:$A,$A12)/SUMIFS('Census Data'!$F:$F,'Census Data'!$A:$A,$A12) -> 0.50931845 | F12: =SUM(SUMIFS('Census Data'!I:I,'Census Data'!$A:$A,$A12),SUMIFS('Census Data'!J:J,'Census Data'!$A:$A,$A12))/SUMIFS('Census Data'!$F:$F,'Census Data'!$A:$A,$A12) -> 0.87055461 | G12: =SUM(SUMIFS('Census Data'!K:K,'Census Data'!$A:$A,$A12),SUMIFS('Census Data'!L:L,'Census Data'!$A:$A,$A12))/SUMIFS('Census Data'!$F:$F,'Census Data'!$A:$A,$A12) -> 0.10344828 | H12: =SUM(SUMIFS('Census Data'!O:O,'Census Data'!$A:$A,$A12),SUMIFS('Census Data'!P:P,'Census Data'!$A:$A,$A12))/SUMIFS('Census Data'!$F:$F,'Census Data'!$A:$A,$A12) -> 0.0048843072 | I12: =100%-SUM(F12:H12) -> 0.021112812 | J12: =SUM(SUMIFS('Census Data'!W:W,'Census Data'!$A:$A,$A12),SUMIFS('Census Data'!X:X,'Census Data'!$A:$A,$A12))/SUMIFS('Census Data'!$F:$F,'Census Data'!$A:$A,$A12) -> 0.081840281 | K12: =100%-J12 -> 0.91815972 | L12: ='EPA Data'!D13/SUM('EPA Data'!D:D) -> 0.00010196723 | M12: ='EPA Data'!E13/SUM('EPA Data'!E:E) -> 0.00013341223 | N12: ='EPA Data'!F13/SUM('EPA Data'!F:F) -> 0.00016096701 | O12: ='EPA Data'!G13/SUM('EPA Data'!G:G) -> 6.3235198e-05 | P12: ='EPA Data'!H13/SUM('EPA Data'!H:H) -> 0.00010049882 | Q12: ='EPA Data'!I13/SUM('EPA Data'!I:I) -> 5.9664868e-05 | R12: ='EPA Data'!J13/SUM('EPA Data'!J:J) -> 9.2709596e-05 | S12: ='EPA Data'!K13/SUM('EPA Data'!K:K) -> 0.00015528474 | T12: ='EPA Data'!L13/SUM('EPA Data'!L:L) -> 0.00031031387 | U12: ='EPA Data'!M13/SUM('EPA Data'!M:M) -> 4.8219919e-05 | V12: ='EPA Data'!N13/SUM('EPA Data'!N:N) -> 4.7895401e-05 | W12: ='EPA Data'!O13/SUM('EPA Data'!O:O) -> 5.5667473e-05 | X12: ='EPA Data'!P13/SUM('EPA Data'!P:P) -> 0.00014664611
A13: 01023 | B13: Alabama | C13: Choctaw | D13: =SUMIFS('Census Data'!G:G,'Census Data'!$A:$A,$A13)/SUMIFS('Census Data'!$F:$F,'Census Data'!$A:$A,$A13) -> 0.47168163 | E13: =SUMIFS('Census Data'!H:H,'Census Data'!$A:$A,$A13)/SUMIFS('Census Data'!$F:$F,'Census Data'!$A:$A,$A13) -> 0.52831837 | F13: =SUM(SUMIFS('Census Data'!I:I,'Census Data'!$A:$A,$A13),SUMIFS('Census Data'!J:J,'Census Data'!$A:$A,$A13))/SUMIFS('Census Data'!$F:$F,'Census Data'!$A:$A,$A13) -> 0.57121296 | G13: =SUM(SUMIFS('Census Data'!K:K,'Census Data'!$A:$A,$A13),SUMIFS('Census Data'!L:L,'Census Data'!$A:$A,$A13))/SUMIFS('Census Data'!$F:$F,'Census Data'!$A:$A,$A13) -> 0.41742791 | H13: =SUM(SUMIFS('Census Data'!O:O,'Census Data'!$A:$A,$A13),SUMIFS('Census Data'!P:P,'Census Data'!$A:$A,$A13))/SUMIFS('Census Data'!$F:$F,'Census Data'!$A:$A,$A13) -> 0.0019858607 | I13: =100%-SUM(F13:H13) -> 0.0093732624 | J13: =SUM(SUMIFS('Census Data'!W:W,'Census Data'!$A:$A,$A13),SUMIFS('Census Data'!X:X,'Census Data'!$A:$A,$A13))/SUMIFS('Census Data'!$F:$F,'Census Data'!$A:$A,$A13) -> 0.010167607 | K13: =100%-J13 -> 0.98983239 | L13: ='EPA Data'!D14/SUM('EPA Data'!D:D) -> 2.045884e-05 | M13: ='EPA Data'!E14/SUM('EPA Data'!E:E) -> 3.9655579e-05 | N13: ='EPA Data'!F14/SUM('EPA Data'!F:F) -> 5.1497362e-05 | O13: ='EPA Data'!G14/SUM('EPA Data'!G:G) -> 1.156018e-05 | P13: ='EPA Data'!H14/SUM('EPA Data'!H:H) -> 2.4596362e-05 | Q13: ='EPA Data'!I14/SUM('EPA Data'!I:I) -> 1.6752805e-05 | R13: ='EPA Data'!J14/SUM('EPA Data'!J:J) -> 2.7455868e-05 | S13: ='EPA Data'!K14/SUM('EPA Data'!K:K) -> 5.2410501e-05 | T13: ='EPA Data'!L14/SUM('EPA Data'!L:L) -> 7.9902009e-05 | U13: ='EPA Data'!M14/SUM('EPA Data'!M:M) -> 9.5531547e-06 | V13: ='EPA Data'!N14/SUM('EPA Data'!N:N) -> 1.202828e-05 | W13: ='EPA Data'!O14/SUM('EPA Data'!O:O) -> 1.5352554e-05 | X13: ='EPA Data'!P14/SUM('EPA Data'!P:P) -> 4.6190334e-05
... A3109: 56045 | B3109: Wyoming | C3109: Weston | D3109: =SUMIFS('Census Data'!G:G,'Census Data'!$A:$A,$A3109)/SUMIFS('Census Data'!$F:$F,'Census Data'!$A:$A,$A3109) -> 0.5231702 | E3109: =SUMIFS('Census Data'!H:H,'Census Data'!$A:$A,$A3109)/SUMIFS('Census Data'!$F:$F,'Census Data'!$A:$A,$A3109) -> 0.4768298 | F3109: =SUM(SUMIFS('Census Data'!I:I,'Census Data'!$A:$A,$A3109),SUMIFS('Census Data'!J:J,'Census Data'!$A:$A,$A3109))/SUMIFS('Census Data'!$F:$F,'Census Data'!$A:$A,$A3109) -> 0.93171647 | G3109: =SUM(SUMIFS('Census Data'!K:K,'Census Data'!$A:$A,$A3109),SUMIFS('Census Data'!L:L,'Census Data'!$A:$A,$A3109))/SUMIFS('Census Data'!$F:$F,'Census Data'!$A:$A,$A3109) -> 0.0069294067 | H3109: =SUM(SUMIFS('Census Data'!O:O,'Census Data'!$A:$A,$A3109),SUMIFS('Census Data'!P:P,'Census Data'!$A:$A,$A3109))/SUMIFS('Census Data'!$F:$F,'Census Data'!$A:$A,$A3109) -> 0.016890429 | I3109: =100%-SUM(F3109:H3109) -> 0.044463693 | J3109: =SUM(SUMIFS('Census Data'!W:W,'Census Data'!$A:$A,$A3109),SUMIFS('Census Data'!X:X,'Census Data'!$A:$A,$A3109))/SUMIFS('Census Data'!$F:$F,'Census Data'!$A:$A,$A3109) -> 0.041143352 | K3109: =100%-J3109 -> 0.95885665 | L3109: ='EPA Data'!D3110/SUM('EPA Data'!D:D) -> 6.800083e-06 | M3109: ='EPA Data'!E3110/SUM('EPA Data'!E:E) -> 1.8181565e-05 | N3109: ='EPA Data'!F3110/SUM('EPA Data'!F:F) -> 1.2790764e-05 | O3109: ='EPA Data'!G3110/SUM('EPA Data'!G:G) -> 3.5161375e-06 | P3109: ='EPA Data'!H3110/SUM('EPA Data'!H:H) -> 9.5667678e-06 | Q3109: ='EPA Data'!I3110/SUM('EPA Data'!I:I) -> 3.0012433e-06 | R3109: ='EPA Data'!J3110/SUM('EPA Data'!J:J) -> 3.9510885e-06 | S3109: ='EPA Data'!K3110/SUM('EPA Data'!K:K) -> 2.4581971e-05 | T3109: ='EPA Data'!L3110/SUM('EPA Data'!L:L) -> 9.2870715e-06 | U3109: ='EPA Data'!M3110/SUM('EPA Data'!M:M) -> 2.3521328e-06 | V3109: ='EPA Data'!N3110/SUM('EPA Data'!N:N) -> 4.2374392e-06 | W3109: ='EPA Data'!O3110/SUM('EPA Data'!O:O) -> 2.5021237e-06 | X3109: ='EPA Data'!P3110/SUM('EPA Data'!P:P) -> 3.6150494e-05

Sheet Census Projection
A1: table with row headers in column A and column headers in rows 4 through 5
A2: Projected Race and Hispanic Origin
A3: Projections for the United States: 2017-2060
A4: Main series. Table 4
A5: (2016 base population. Resident population as of July 1. Numbers in thousands)
B6: 2016 | C6: 2020 | D6: 2025 | E6: 2030 | F6: 2035 | G6: 2040 | H6: 2045 | I6: 2050 | J6: 2055 | K6: 2060
A7: Total | B7: 323128 | C7: 332639 | D7: 344234 | E7: 355101 | F7: 364862 | G7: 373528 | H7: 381390 | I7: 388922 | J7: 396557 | K7: 404483
A8: .One race | B8: 314648 | C8: 323069 | D8: 333181 | E8: 342432 | F8: 350454 | G8: 357252 | H8: 363105 | I8: 368473 | J8: 373781 | K8: 379228
A9: .White | B9: 248503 | C9: 253280 | D9: 258778 | E9: 263453 | F9: 267057 | G9: 269578 | H9: 271249 | I9: 272486 | J9: 273679 | K9: 275014
A10: ..Non-Hispanic White | B10: 197970 | C10: 198571 | D10: 198751 | E10: 197992 | F10: 196105 | G10: 193210 | H10: 189671 | I10: 185954 | J10: 182411 | K10: 179162
A11: .Black or African American | B11: 43001 | C11: 44734 | D11: 46906 | E11: 49009 | F11: 51002 | G11: 52919 | H11: 54814 | I11: 56725 | J11: 58680 | K11: 60690
A12: .American Indian and Alaska Native | B12: 4055 | C12: 4232 | D12: 4452 | E12: 4663 | F12: 4859 | G12: 5038 | H12: 5199 | I12: 5341 | J12: 5468 | K12: 5583
A13: .Asian | B13: 18319 | C13: 20009 | D13: 22181 | E13: 24394 | F13: 26579 | G13: 28718 | H13: 30806 | I13: 32850 | J13: 34854 | K13: 36815
A14: .Native Hawaiian and Other Pacific Islander | B14: 771 | C14: 813 | D14: 865 | E14: 913 | F14: 958 | G14: 999 | H14: 1038 | I14: 1071 | J14: 1100 | K14: 1125
A15: .Two or More Races | B15: 8480 | C15: 9570 | D15: 11053 | E15: 12669 | F15: 14408 | G15: 16276 | H15: 18285 | I15: 20450 | J15: 22776 | K15: 25255
A16: .Hispanic or Latino | B16: 57470 | C16: 62313 | D16: 68484 | E16: 74807 | F16: 81230 | G16: 87616 | H16: 93826 | I16: 99798 | J16: 105570 | K16: 111216
A17: Male | B17: 159079 | C17: 163904 | D17: 169738 | E17: 175174 | F17: 180070 | G17: 184481 | H17: 188575 | I17: 192577 | J17: 196661 | K17: 200871
A18: .One race | B18: 154890 | C18: 159159 | D18: 164236 | E18: 168847 | F18: 172855 | G18: 176311 | H18: 179377 | I18: 182269 | J18: 185161 | K18: 188100
... A36: .Hispanic or Latino | B36: 28455 | C36: 30843 | D36: 33884 | E36: 36999 | F36: 40164 | G36: 43315 | H36: 46381 | I36: 49333 | J36: 52187 | K36: 54978
A37: Note: 2016 is the base population estimate for the projections. Hispanic origin is considered an ethnicity, not a race. Hispanics may be of any race. Responses of "Some Other Race" from the 2010 Census are modified. For more information, see http://www.census.gov/popest/data/historical/files/MRSF-01-US1.pdf.
A39: Suggested Citation:
A40: Projected Race and Hispanic Origin: Main Projections Series for the United States, 2017-2060. U.S. Census Bureau, Population Division: Washington, DC.
A42: Source: U.S. Census Bureau, Population Division
A43: Original Release Date: March 2018
A44: Revised Release Date: September 2018
A46: Erratum Note: The 2017 National Population Projections were revised after their original release date to correct an error in infant mortality rates. The files were removed from the website on August 1, 2018 and an erratum note posted. The error incorrectly calculated infant mortality rates, which erroneously caused an increase in the number of deaths projected in the total population. Correcting the error in infant mortality results in a decrease in the number of deaths and a slight increase in the total projected population in the revised series. The error did not affect the other two components of population change in the projections series (fertility and migration). Major demographic trends, such as an aging population and an increase in racial and ethnic diversity, remain unchanged.

Sheet Projections
A1: Share of Population
B2: 2020 | C2: 2025 | D2: 2030 | E2: 2035 | F2: 2040 | G2: 2045 | H2: 2050
A3: male | B3: ='Census Projection'!C17/'Census Projection'!C7 -> 0.49273837 | C3: ='Census Projection'!D17/'Census Projection'!D7 -> 0.493089 | D3: ='Census Projection'!E17/'Census Projection'!E7 -> 0.49330754 | E3: ='Census Projection'!F17/'Census Projection'!F7 -> 0.49352906 | F3: ='Census Projection'!G17/'Census Projection'!G7 -> 0.49388801 | G3: ='Census Projection'!H17/'Census Projection'!H7 -> 0.49444139 | H3: ='Census Projection'!I17/'Census Projection'!I7 -> 0.49515584
A4: female | B4: =1-B3 -> 0.50726163 | C4: =1-C3 -> 0.506911 | D4: =1-D3 -> 0.50669246 | E4: =1-E3 -> 0.50647094 | F4: =1-F3 -> 0.50611199 | G4: =1-G3 -> 0.50555861 | H4: =1-H3 -> 0.50484416
A5: white | B5: ='Census Projection'!C9/'Census Projection'!C7 -> 0.76142605 | C5: ='Census Projection'!D9/'Census Projection'!D7 -> 0.75175026 | D5: ='Census Projection'!E9/'Census Projection'!E7 -> 0.74191005 | E5: ='Census Projection'!F9/'Census Projection'!F7 -> 0.73193975 | F5: ='Census Projection'!G9/'Census Projection'!G7 -> 0.72170761 | G5: ='Census Projection'!H9/'Census Projection'!H7 -> 0.71121162 | H5: ='Census Projection'!I9/'Census Projection'!I7 -> 0.70061863
A6: black | B6: ='Census Projection'!C11/'Census Projection'!C7 -> 0.13448213 | C6: ='Census Projection'!D11/'Census Projection'!D7 -> 0.13626196 | D6: ='Census Projection'!E11/'Census Projection'!E7 -> 0.13801426 | E6: ='Census Projection'!F11/'Census Projection'!F7 -> 0.13978436 | F6: ='Census Projection'!G11/'Census Projection'!G7 -> 0.14167345 | G6: ='Census Projection'!H11/'Census Projection'!H7 -> 0.14372165 | H6: ='Census Projection'!I11/'Census Projection'!I7 -> 0.14585187
A7: asian | B7: ='Census Projection'!C13/'Census Projection'!C7 -> 0.060152297 | C7: ='Census Projection'!D13/'Census Projection'!D7 -> 0.06443582 | D7: ='Census Projection'!E13/'Census Projection'!E7 -> 0.068695948 | E7: ='Census Projection'!F13/'Census Projection'!F7 -> 0.07284672 | F7: ='Census Projection'!G13/'Census Projection'!G7 -> 0.076883125 | G7: ='Census Projection'!H13/'Census Projection'!H7 -> 0.080772962 | H7: ='Census Projection'!I13/'Census Projection'!I7 -> 0.084464237
A8: other race | B8: =1-SUM(B5:B7) -> 0.043939526 | C8: =1-SUM(C5:C7) -> 0.047551956 | D8: =1-SUM(D5:D7) -> 0.051379748 | E8: =1-SUM(E5:E7) -> 0.055429176 | F8: =1-SUM(F5:F7) -> 0.059735816 | G8: =1-SUM(G5:G7) -> 0.064293768 | H8: =1-SUM(H5:H7) -> 0.069065262
A9: hispanic | B9: ='Census Projection'!C16/'Census Projection'!C7 -> 0.18732921 | C9: ='Census Projection'!D16/'Census Projection'!D7 -> 0.19894607 | D9: ='Census Projection'!E16/'Census Projection'!E7 -> 0.21066401 | E9: ='Census Projection'!F16/'Census Projection'!F7 -> 0.22263212 | F9: ='Census Projection'!G16/'Census Projection'!G7 -> 0.23456341 | G9: ='Census Projection'!H16/'Census Projection'!H7 -> 0.24601065 | H9: ='Census Projection'!I16/'Census Projection'!I7 -> 0.25660158
A10: nonhispanic | B10: =1-B9 -> 0.81267079 | C10: =1-C9 -> 0.80105393 | D10: =1-D9 -> 0.78933599 | E10: =1-E9 -> 0.77736788 | F10: =1-F9 -> 0.76543659 | G10: =1-G9 -> 0.75398935 | H10: =1-H9 -> 0.74339842
A12: Annualized
B13: 2020 | C13: 2021 | D13: 2022 | E13: 2023 | F13: 2024 | G13: 2025 | H13: 2026 | I13: 2027 | J13: 2028 | K13: 2029 | L13: 2030 | M13: 2031 | N13: 2032 | O13: 2033 | P13: 2034 | Q13: 2035 | R13: 2036 | S13: 2037 | T13: 2038 | U13: 2039 | V13: 2040 | W13: 2041 | X13: 2042 | Y13: 2043 | Z13: 2044 | AA13: 2045 | AB13: 2046 | AC13: 2047 | AD13: 2048 | AE13: 2049 | AF13: 2050
A14: male | B14: {=TREND($B3:$C3,$B$2:$C$2,B$13)} -> 0.49273837 | C14: {=TREND($B3:$C3,$B$2:$C$2,C$13)} -> 0.4928085 | D14: {=TREND($B3:$C3,$B$2:$C$2,D$13)} -> 0.49287863 | E14: {=TREND($B3:$C3,$B$2:$C$2,E$13)} -> 0.49294875 | F14: {=TREND($B3:$C3,$B$2:$C$2,F$13)} -> 0.49301888 | G14: {=TREND($B3:$C3,$B$2:$C$2,G$13)} -> 0.493089 | H14: {=TREND($C3:$D3,$C$2:$D$2,H$13)} -> 0.49313271 | I14: {=TREND($C3:$D3,$C$2:$D$2,I$13)} -> 0.49317642 | J14: {=TREND($C3:$D3,$C$2:$D$2,J$13)} -> 0.49322012 | K14: {=TREND($C3:$D3,$C$2:$D$2,K$13)} -> 0.49326383 | L14: {=TREND($C3:$D3,$C$2:$D$2,L$13)} -> 0.49330754 | M14: {=TREND($D3:$E3,$D$2:$E$2,M$13)} -> 0.49335184 | N14: {=TREND($D3:$E3,$D$2:$E$2,N$13)} -> 0.49339615 | O14: {=TREND($D3:$E3,$D$2:$E$2,O$13)} -> 0.49344045 | P14: {=TREND($D3:$E3,$D$2:$E$2,P$13)} -> 0.49348476 | Q14: {=TREND($D3:$E3,$D$2:$E$2,Q$13)} -> 0.49352906 | R14: {=TREND($E3:$F3,$E$2:$F$2,R$13)} -> 0.49360085 | S14: {=TREND($E3:$F3,$E$2:$F$2,S$13)} -> 0.49367264 | T14: {=TREND($E3:$F3,$E$2:$F$2,T$13)} -> 0.49374443 | U14: {=TREND($E3:$F3,$E$2:$F$2,U$13)} -> 0.49381622 | V14: {=TREND($E3:$F3,$E$2:$F$2,V$13)} -> 0.49388801 | W14: {=TREND($F3:$G3,$F$2:$G$2,W$13)} -> 0.49399868 | X14: {=TREND($F3:$G3,$F$2:$G$2,X$13)} -> 0.49410936 | Y14: {=TREND($F3:$G3,$F$2:$G$2,Y$13)} -> 0.49422003 | Z14: {=TREND($F3:$G3,$F$2:$G$2,Z$13)} -> 0.49433071 | AA14: {=TREND($F3:$G3,$F$2:$G$2,AA$13)} -> 0.49444139 | AB14: {=TREND($G3:$H3,$G$2:$H$2,AB$13)} -> 0.49458428 | AC14: {=TREND($G3:$H3,$G$2:$H$2,AC$13)} -> 0.49472717 | AD14: {=TREND($G3:$H3,$G$2:$H$2,AD$13)} -> 0.49487006 | AE14: {=TREND($G3:$H3,$G$2:$H$2,AE$13)} -> 0.49501295 | AF14: {=TREND($G3:$H3,$G$2:$H$2,AF$13)} -> 0.49515584
A15: female | B15: {=TREND($B4:$C4,$B$2:$C$2,B$13)} -> 0.50726163 | C15: {=TREND($B4:$C4,$B$2:$C$2,C$13)} -> 0.5071915 | D15: {=TREND($B4:$C4,$B$2:$C$2,D$13)} -> 0.50712137 | E15: {=TREND($B4:$C4,$B$2:$C$2,E$13)} -> 0.50705125 | F15: {=TREND($B4:$C4,$B$2:$C$2,F$13)} -> 0.50698112 | G15: {=TREND($B4:$C4,$B$2:$C$2,G$13)} -> 0.506911 | H15: {=TREND($C4:$D4,$C$2:$D$2,H$13)} -> 0.50686729 | I15: {=TREND($C4:$D4,$C$2:$D$2,I$13)} -> 0.50682358 | J15: {=TREND($C4:$D4,$C$2:$D$2,J$13)} -> 0.50677988 | K15: {=TREND($C4:$D4,$C$2:$D$2,K$13)} -> 0.50673617 | L15: {=TREND($C4:$D4,$C$2:$D$2,L$13)} -> 0.50669246 | M15: {=TREND($D4:$E4,$D$2:$E$2,M$13)} -> 0.50664816 | N15: {=TREND($D4:$E4,$D$2:$E$2,N$13)} -> 0.50660385 | O15: {=TREND($D4:$E4,$D$2:$E$2,O$13)} -> 0.50655955 | P15: {=TREND($D4:$E4,$D$2:$E$2,P$13)} -> 0.50651524 | Q15: {=TREND($D4:$E4,$D$2:$E$2,Q$13)} -> 0.50647094 | R15: {=TREND($E4:$F4,$E$2:$F$2,R$13)} -> 0.50639915 | S15: {=TREND($E4:$F4,$E$2:$F$2,S$13)} -> 0.50632736 | T15: {=TREND($E4:$F4,$E$2:$F$2,T$13)} -> 0.50625557 | U15: {=TREND($E4:$F4,$E$2:$F$2,U$13)} -> 0.50618378 | V15: {=TREND($E4:$F4,$E$2:$F$2,V$13)} -> 0.50611199 | W15: {=TREND($F4:$G4,$F$2:$G$2,W$13)} -> 0.50600132 | X15: {=TREND($F4:$G4,$F$2:$G$2,X$13)} -> 0.50589064 | Y15: {=TREND($F4:$G4,$F$2:$G$2,Y$13)} -> 0.50577997 | Z15: {=TREND($F4:$G4,$F$2:$G$2,Z$13)} -> 0.50566929 | AA15: {=TREND($F4:$G4,$F$2:$G$2,AA$13)} -> 0.50555861 | AB15: {=TREND($G4:$H4,$G$2:$H$2,AB$13)} -> 0.50541572 | AC15: {=TREND($G4:$H4,$G$2:$H$2,AC$13)} -> 0.50527283 | AD15: {=TREND($G4:$H4,$G$2:$H$2,AD$13)} -> 0.50512994 | AE15: {=TREND($G4:$H4,$G$2:$H$2,AE$13)} -> 0.50498705 | AF15: {=TREND($G4:$H4,$G$2:$H$2,AF$13)} -> 0.50484416
A16: white | B16: {=TREND($B5:$C5,$B$2:$C$2,B$13)} -> 0.76142605 | C16: {=TREND($B5:$C5,$B$2:$C$2,C$13)} -> 0.75949089 | D16: {=TREND($B5:$C5,$B$2:$C$2,D$13)} -> 0.75755574 | E16: {=TREND($B5:$C5,$B$2:$C$2,E$13)} -> 0.75562058 | F16: {=TREND($B5:$C5,$B$2:$C$2,F$13)} -> 0.75368542 | G16: {=TREND($B5:$C5,$B$2:$C$2,G$13)} -> 0.75175026 | H16: {=TREND($C5:$D5,$C$2:$D$2,H$13)} -> 0.74978222 | I16: {=TREND($C5:$D5,$C$2:$D$2,I$13)} -> 0.74781418 | J16: {=TREND($C5:$D5,$C$2:$D$2,J$13)} -> 0.74584613 | K16: {=TREND($C5:$D5,$C$2:$D$2,K$13)} -> 0.74387809 | L16: {=TREND($C5:$D5,$C$2:$D$2,L$13)} -> 0.74191005 | M16: {=TREND($D5:$E5,$D$2:$E$2,M$13)} -> 0.73991599 | N16: {=TREND($D5:$E5,$D$2:$E$2,N$13)} -> 0.73792193 | O16: {=TREND($D5:$E5,$D$2:$E$2,O$13)} -> 0.73592787 | P16: {=TREND($D5:$E5,$D$2:$E$2,P$13)} -> 0.73393381 | Q16: {=TREND($D5:$E5,$D$2:$E$2,Q$13)} -> 0.73193975 | R16: {=TREND($E5:$F5,$E$2:$F$2,R$13)} -> 0.72989332 | S16: {=TREND($E5:$F5,$E$2:$F$2,S$13)} -> 0.72784689 | T16: {=TREND($E5:$F5,$E$2:$F$2,T$13)} -> 0.72580046 | U16: {=TREND($E5:$F5,$E$2:$F$2,U$13)} -> 0.72375404 | V16: {=TREND($E5:$F5,$E$2:$F$2,V$13)} -> 0.72170761 | W16: {=TREND($F5:$G5,$F$2:$G$2,W$13)} -> 0.71960841 | X16: {=TREND($F5:$G5,$F$2:$G$2,X$13)} -> 0.71750921 | Y16: {=TREND($F5:$G5,$F$2:$G$2,Y$13)} -> 0.71541002 | Z16: {=TREND($F5:$G5,$F$2:$G$2,Z$13)} -> 0.71331082 | AA16: {=TREND($F5:$G5,$F$2:$G$2,AA$13)} -> 0.71121162 | AB16: {=TREND($G5:$H5,$G$2:$H$2,AB$13)} -> 0.70909302 | AC16: {=TREND($G5:$H5,$G$2:$H$2,AC$13)} -> 0.70697443 | AD16: {=TREND($G5:$H5,$G$2:$H$2,AD$13)} -> 0.70485583 | AE16: {=TREND($G5:$H5,$G$2:$H$2,AE$13)} -> 0.70273723 | AF16: {=TREND($G5:$H5,$G$2:$H$2,AF$13)} -> 0.70061863
A17: black | B17: {=TREND($B6:$C6,$B$2:$C$2,B$13)} -> 0.13448213 | C17: {=TREND($B6:$C6,$B$2:$C$2,C$13)} -> 0.13483809 | D17: {=TREND($B6:$C6,$B$2:$C$2,D$13)} -> 0.13519406 | E17: {=TREND($B6:$C6,$B$2:$C$2,E$13)} -> 0.13555003 | F17: {=TREND($B6:$C6,$B$2:$C$2,F$13)} -> 0.13590599 | G17: {=TREND($B6:$C6,$B$2:$C$2,G$13)} -> 0.13626196 | H17: {=TREND($C6:$D6,$C$2:$D$2,H$13)} -> 0.13661242 | I17: {=TREND($C6:$D6,$C$2:$D$2,I$13)} -> 0.13696288 | J17: {=TREND($C6:$D6,$C$2:$D$2,J$13)} -> 0.13731334 | K17: {=TREND($C6:$D6,$C$2:$D$2,K$13)} -> 0.1376638 | L17: {=TREND($C6:$D6,$C$2:$D$2,L$13)} -> 0.13801426 | M17: {=TREND($D6:$E6,$D$2:$E$2,M$13)} -> 0.13836828 | N17: {=TREND($D6:$E6,$D$2:$E$2,N$13)} -> 0.1387223 | O17: {=TREND($D6:$E6,$D$2:$E$2,O$13)} -> 0.13907632 | P17: {=TREND($D6:$E6,$D$2:$E$2,P$13)} -> 0.13943034 | Q17: {=TREND($D6:$E6,$D$2:$E$2,Q$13)} -> 0.13978436 | R17: {=TREND($E6:$F6,$E$2:$F$2,R$13)} -> 0.14016218 | S17: {=TREND($E6:$F6,$E$2:$F$2,S$13)} -> 0.14053999 | T17: {=TREND($E6:$F6,$E$2:$F$2,T$13)} -> 0.14091781 | U17: {=TREND($E6:$F6,$E$2:$F$2,U$13)} -> 0.14129563 | V17: {=TREND($E6:$F6,$E$2:$F$2,V$13)} -> 0.14167345 | W17: {=TREND($F6:$G6,$F$2:$G$2,W$13)} -> 0.14208309 | X17: {=TREND($F6:$G6,$F$2:$G$2,X$13)} -> 0.14249273 | Y17: {=TREND($F6:$G6,$F$2:$G$2,Y$13)} -> 0.14290237 | Z17: {=TREND($F6:$G6,$F$2:$G$2,Z$13)} -> 0.14331201 | AA17: {=TREND($F6:$G6,$F$2:$G$2,AA$13)} -> 0.14372165 | AB17: {=TREND($G6:$H6,$G$2:$H$2,AB$13)} -> 0.14414769 | AC17: {=TREND($G6:$H6,$G$2:$H$2,AC$13)} -> 0.14457374 | AD17: {=TREND($G6:$H6,$G$2:$H$2,AD$13)} -> 0.14499978 | AE17: {=TREND($G6:$H6,$G$2:$H$2,AE$13)} -> 0.14542582 | AF17: {=TREND($G6:$H6,$G$2:$H$2,AF$13)} -> 0.14585187
A18: asian | B18: {=TREND($B7:$C7,$B$2:$C$2,B$13)} -> 0.060152297 | C18: {=TREND($B7:$C7,$B$2:$C$2,C$13)} -> 0.061009002 | D18: {=TREND($B7:$C7,$B$2:$C$2,D$13)} -> 0.061865706 | E18: {=TREND($B7:$C7,$B$2:$C$2,E$13)} -> 0.062722411 | F18: {=TREND($B7:$C7,$B$2:$C$2,F$13)} -> 0.063579115 | G18: {=TREND($B7:$C7,$B$2:$C$2,G$13)} -> 0.06443582 | H18: {=TREND($C7:$D7,$C$2:$D$2,H$13)} -> 0.065287846 | I18: {=TREND($C7:$D7,$C$2:$D$2,I$13)} -> 0.066139871 | J18: {=TREND($C7:$D7,$C$2:$D$2,J$13)} -> 0.066991897 | K18: {=TREND($C7:$D7,$C$2:$D$2,K$13)} -> 0.067843923 | L18: {=TREND($C7:$D7,$C$2:$D$2,L$13)} -> 0.068695948 | M18: {=TREND($D7:$E7,$D$2:$E$2,M$13)} -> 0.069526103 | N18: {=TREND($D7:$E7,$D$2:$E$2,N$13)} -> 0.070356257 | O18: {=TREND($D7:$E7,$D$2:$E$2,O$13)} -> 0.071186411 | P18: {=TREND($D7:$E7,$D$2:$E$2,P$13)} -> 0.072016566 | Q18: {=TREND($D7:$E7,$D$2:$E$2,Q$13)} -> 0.07284672 | R18: {=TREND($E7:$F7,$E$2:$F$2,R$13)} -> 0.073654001 | S18: {=TREND($E7:$F7,$E$2:$F$2,S$13)} -> 0.074461282 | T18: {=TREND($E7:$F7,$E$2:$F$2,T$13)} -> 0.075268563 | U18: {=TREND($E7:$F7,$E$2:$F$2,U$13)} -> 0.076075844 | V18: {=TREND($E7:$F7,$E$2:$F$2,V$13)} -> 0.076883125 | W18: {=TREND($F7:$G7,$F$2:$G$2,W$13)} -> 0.077661093 | X18: {=TREND($F7:$G7,$F$2:$G$2,X$13)} -> 0.07843906 | Y18: {=TREND($F7:$G7,$F$2:$G$2,Y$13)} -> 0.079217027 | Z18: {=TREND($F7:$G7,$F$2:$G$2,Z$13)} -> 0.079994995 | AA18: {=TREND($F7:$G7,$F$2:$G$2,AA$13)} -> 0.080772962 | AB18: {=TREND($G7:$H7,$G$2:$H$2,AB$13)} -> 0.081511217 | AC18: {=TREND($G7:$H7,$G$2:$H$2,AC$13)} -> 0.082249472 | AD18: {=TREND($G7:$H7,$G$2:$H$2,AD$13)} -> 0.082987727 | AE18: {=TREND($G7:$H7,$G$2:$H$2,AE$13)} -> 0.083725982 | AF18: {=TREND($G7:$H7,$G$2:$H$2,AF$13)} -> 0.084464237
A19: other race | B19: {=TREND($B8:$C8,$B$2:$C$2,B$13)} -> 0.043939526 | C19: {=TREND($B8:$C8,$B$2:$C$2,C$13)} -> 0.044662012 | D19: {=TREND($B8:$C8,$B$2:$C$2,D$13)} -> 0.045384498 | E19: {=TREND($B8:$C8,$B$2:$C$2,E$13)} -> 0.046106984 | F19: {=TREND($B8:$C8,$B$2:$C$2,F$13)} -> 0.04682947 | G19: {=TREND($B8:$C8,$B$2:$C$2,G$13)} -> 0.047551956 | H19: {=TREND($C8:$D8,$C$2:$D$2,H$13)} -> 0.048317514 | I19: {=TREND($C8:$D8,$C$2:$D$2,I$13)} -> 0.049083073 | J19: {=TREND($C8:$D8,$C$2:$D$2,J$13)} -> 0.049848631 | K19: {=TREND($C8:$D8,$C$2:$D$2,K$13)} -> 0.05061419 | L19: {=TREND($C8:$D8,$C$2:$D$2,L$13)} -> 0.051379748 | M19: {=TREND($D8:$E8,$D$2:$E$2,M$13)} -> 0.052189634 | N19: {=TREND($D8:$E8,$D$2:$E$2,N$13)} -> 0.052999519 | O19: {=TREND($D8:$E8,$D$2:$E$2,O$13)} -> 0.053809405 | P19: {=TREND($D8:$E8,$D$2:$E$2,P$13)} -> 0.05461929 | Q19: {=TREND($D8:$E8,$D$2:$E$2,Q$13)} -> 0.055429176 | R19: {=TREND($E8:$F8,$E$2:$F$2,R$13)} -> 0.056290504 | S19: {=TREND($E8:$F8,$E$2:$F$2,S$13)} -> 0.057151832 | T19: {=TREND($E8:$F8,$E$2:$F$2,T$13)} -> 0.05801316 | U19: {=TREND($E8:$F8,$E$2:$F$2,U$13)} -> 0.058874488 | V19: {=TREND($E8:$F8,$E$2:$F$2,V$13)} -> 0.059735816 | W19: {=TREND($F8:$G8,$F$2:$G$2,W$13)} -> 0.060647407 | X19: {=TREND($F8:$G8,$F$2:$G$2,X$13)} -> 0.061558997 | Y19: {=TREND($F8:$G8,$F$2:$G$2,Y$13)} -> 0.062470587 | Z19: {=TREND($F8:$G8,$F$2:$G$2,Z$13)} -> 0.063382177 | AA19: {=TREND($F8:$G8,$F$2:$G$2,AA$13)} -> 0.064293768 | AB19: {=TREND($G8:$H8,$G$2:$H$2,AB$13)} -> 0.065248067 | AC19: {=TREND($G8:$H8,$G$2:$H$2,AC$13)} -> 0.066202365 | AD19: {=TREND($G8:$H8,$G$2:$H$2,AD$13)} -> 0.067156664 | AE19: {=TREND($G8:$H8,$G$2:$H$2,AE$13)} -> 0.068110963 | AF19: {=TREND($G8:$H8,$G$2:$H$2,AF$13)} -> 0.069065262
A20: hispanic | B20: {=TREND($B9:$C9,$B$2:$C$2,B$13)} -> 0.18732921 | C20: {=TREND($B9:$C9,$B$2:$C$2,C$13)} -> 0.18965258 | D20: {=TREND($B9:$C9,$B$2:$C$2,D$13)} -> 0.19197595 | E20: {=TREND($B9:$C9,$B$2:$C$2,E$13)} -> 0.19429932 | F20: {=TREND($B9:$C9,$B$2:$C$2,F$13)} -> 0.19662269 | G20: {=TREND($B9:$C9,$B$2:$C$2,G$13)} -> 0.19894607 | H20: {=TREND($C9:$D9,$C$2:$D$2,H$13)} -> 0.20128965 | I20: {=TREND($C9:$D9,$C$2:$D$2,I$13)} -> 0.20363324 | J20: {=TREND($C9:$D9,$C$2:$D$2,J$13)} -> 0.20597683 | K20: {=TREND($C9:$D9,$C$2:$D$2,K$13)} -> 0.20832042 | L20: {=TREND($C9:$D9,$C$2:$D$2,L$13)} -> 0.21066401 | M20: {=TREND($D9:$E9,$D$2:$E$2,M$13)} -> 0.21305763 | N20: {=TREND($D9:$E9,$D$2:$E$2,N$13)} -> 0.21545125 | O20: {=TREND($D9:$E9,$D$2:$E$2,O$13)} -> 0.21784487 | P20: {=TREND($D9:$E9,$D$2:$E$2,P$13)} -> 0.2202385 | Q20: {=TREND($D9:$E9,$D$2:$E$2,Q$13)} -> 0.22263212 | R20: {=TREND($E9:$F9,$E$2:$F$2,R$13)} -> 0.22501838 | S20: {=TREND($E9:$F9,$E$2:$F$2,S$13)} -> 0.22740463 | T20: {=TREND($E9:$F9,$E$2:$F$2,T$13)} -> 0.22979089 | U20: {=TREND($E9:$F9,$E$2:$F$2,U$13)} -> 0.23217715 | V20: {=TREND($E9:$F9,$E$2:$F$2,V$13)} -> 0.23456341 | W20: {=TREND($F9:$G9,$F$2:$G$2,W$13)} -> 0.23685285 | X20: {=TREND($F9:$G9,$F$2:$G$2,X$13)} -> 0.2391423 | Y20: {=TREND($F9:$G9,$F$2:$G$2,Y$13)} -> 0.24143175 | Z20: {=TREND($F9:$G9,$F$2:$G$2,Z$13)} -> 0.2437212 | AA20: {=TREND($F9:$G9,$F$2:$G$2,AA$13)} -> 0.24601065 | AB20: {=TREND($G9:$H9,$G$2:$H$2,AB$13)} -> 0.24812883 | AC20: {=TREND($G9:$H9,$G$2:$H$2,AC$13)} -> 0.25024702 | AD20: {=TREND($G9:$H9,$G$2:$H$2,AD$13)} -> 0.25236521 | AE20: {=TREND($G9:$H9,$G$2:$H$2,AE$13)} -> 0.25448339 | AF20: {=TREND($G9:$H9,$G$2:$H$2,AF$13)} -> 0.25660158
A21: nonhispanic | B21: {=TREND($B10:$C10,$B$2:$C$2,B$13)} -> 0.81267079 | C21: {=TREND($B10:$C10,$B$2:$C$2,C$13)} -> 0.81034742 | D21: {=TREND($B10:$C10,$B$2:$C$2,D$13)} -> 0.80802405 | E21: {=TREND($B10:$C10,$B$2:$C$2,E$13)} -> 0.80570068 | F21: {=TREND($B10:$C10,$B$2:$C$2,F$13)} -> 0.80337731 | G21: {=TREND($B10:$C10,$B$2:$C$2,G$13)} -> 0.80105393 | H21: {=TREND($C10:$D10,$C$2:$D$2,H$13)} -> 0.79871035 | I21: {=TREND($C10:$D10,$C$2:$D$2,I$13)} -> 0.79636676 | J21: {=TREND($C10:$D10,$C$2:$D$2,J$13)} -> 0.79402317 | K21: {=TREND($C10:$D10,$C$2:$D$2,K$13)} -> 0.79167958 | L21: {=TREND($C10:$D10,$C$2:$D$2,L$13)} -> 0.78933599 | M21: {=TREND($D10:$E10,$D$2:$E$2,M$13)} -> 0.78694237 | N21: {=TREND($D10:$E10,$D$2:$E$2,N$13)} -> 0.78454875 | O21: {=TREND($D10:$E10,$D$2:$E$2,O$13)} -> 0.78215513 | P21: {=TREND($D10:$E10,$D$2:$E$2,P$13)} -> 0.7797615 | Q21: {=TREND($D10:$E10,$D$2:$E$2,Q$13)} -> 0.77736788 | R21: {=TREND($E10:$F10,$E$2:$F$2,R$13)} -> 0.77498162 | S21: {=TREND($E10:$F10,$E$2:$F$2,S$13)} -> 0.77259537 | T21: {=TREND($E10:$F10,$E$2:$F$2,T$13)} -> 0.77020911 | U21: {=TREND($E10:$F10,$E$2:$F$2,U$13)} -> 0.76782285 | V21: {=TREND($E10:$F10,$E$2:$F$2,V$13)} -> 0.76543659 | W21: {=TREND($F10:$G10,$F$2:$G$2,W$13)} -> 0.76314715 | X21: {=TREND($F10:$G10,$F$2:$G$2,X$13)} -> 0.7608577 | Y21: {=TREND($F10:$G10,$F$2:$G$2,Y$13)} -> 0.75856825 | Z21: {=TREND($F10:$G10,$F$2:$G$2,Z$13)} -> 0.7562788 | AA21: {=TREND($F10:$G10,$F$2:$G$2,AA$13)} -> 0.75398935 | AB21: {=TREND($G10:$H10,$G$2:$H$2,AB$13)} -> 0.75187117 | AC21: {=TREND($G10:$H10,$G$2:$H$2,AC$13)} -> 0.74975298 | AD21: {=TREND($G10:$H10,$G$2:$H$2,AD$13)} -> 0.74763479 | AE21: {=TREND($G10:$H10,$G$2:$H$2,AE$13)} -> 0.74551661 | AF21: {=TREND($G10:$H10,$G$2:$H$2,AF$13)} -> 0.74339842
A23: If Positive: Fraction of People Without this Trait in 2020 that Have this Trait in the Specified Year
A24: If Negative: Fraction of People With this Trait in 2020 that Do Not Have this Trait in the Specified Year
B25: 2020 | C25: 2021 | D25: 2022 | E25: 2023 | F25: 2024 | G25: 2025 | H25: 2026 | I25: 2027 | J25: 2028 | K25: 2029 | L25: 2030 | M25: 2031 | N25: 2032 | O25: 2033 | P25: 2034 | Q25: 2035 | R25: 2036 | S25: 2037 | T25: 2038 | U25: 2039 | V25: 2040 | W25: 2041 | X25: 2042 | Y25: 2043 | Z25: 2044 | AA25: 2045 | AB25: 2046 | AC25: 2047 | AD25: 2048 | AE25: 2049 | AF25: 2050
A26: male | B26: =IF(B14>=$B14,(B14-$B14)/(1-$B14),(B14-$B14)/$B14) -> 0 | C26: =IF(C14>=$B14,(C14-$B14)/(1-$B14),(C14-$B14)/$B14) -> 0.000138244 | D26: =IF(D14>=$B14,(D14-$B14)/(1-$B14),(D14-$B14)/$B14) -> 0.000276488 | E26: =IF(E14>=$B14,(E14-$B14)/(1-$B14),(E14-$B14)/$B14) -> 0.000414732 | F26: =IF(F14>=$B14,(F14-$B14)/(1-$B14),(F14-$B14)/$B14) -> 0.00055297599 | G26: =IF(G14>=$B14,(G14-$B14)/(1-$B14),(G14-$B14)/$B14) -> 0.00069121999 | H26: =IF(H14>=$B14,(H14-$B14)/(1-$B14),(H14-$B14)/$B14) -> 0.00077738241 | I26: =IF(I14>=$B14,(I14-$B14)/(1-$B14),(I14-$B14)/$B14) -> 0.00086354483 | ... AF26: =IF(AF14>=$B14,(AF14-$B14)/(1-$B14),(AF14-$B14)/$B14) -> 0.0047657202
A27: female | B27: =IF(B15>=$B15,(B15-$B15)/(1-$B15),(B15-$B15)/$B15) -> 0 | C27: =IF(C15>=$B15,(C15-$B15)/(1-$B15),(C15-$B15)/$B15) -> -0.000138244 | D27: =IF(D15>=$B15,(D15-$B15)/(1-$B15),(D15-$B15)/$B15) -> -0.000276488 | E27: =IF(E15>=$B15,(E15-$B15)/(1-$B15),(E15-$B15)/$B15) -> -0.000414732 | F27: =IF(F15>=$B15,(F15-$B15)/(1-$B15),(F15-$B15)/$B15) -> -0.00055297599 | G27: =IF(G15>=$B15,(G15-$B15)/(1-$B15),(G15-$B15)/$B15) -> -0.00069121999 | H27: =IF(H15>=$B15,(H15-$B15)/(1-$B15),(H15-$B15)/$B15) -> -0.00077738241 | I27: =IF(I15>=$B15,(I15-$B15)/(1-$B15),(I15-$B15)/$B15) -> -0.00086354483 | ... AF27: =IF(AF15>=$B15,(AF15-$B15)/(1-$B15),(AF15-$B15)/$B15) -> -0.0047657202
A28: white | B28: =IF(B16>=$B16,(B16-$B16)/(1-$B16),(B16-$B16)/$B16) -> 0 | C28: =IF(C16>=$B16,(C16-$B16)/(1-$B16),(C16-$B16)/$B16) -> -0.0025414911 | D28: =IF(D16>=$B16,(D16-$B16)/(1-$B16),(D16-$B16)/$B16) -> -0.0050829822 | E28: =IF(E16>=$B16,(E16-$B16)/(1-$B16),(E16-$B16)/$B16) -> -0.0076244732 | F28: =IF(F16>=$B16,(F16-$B16)/(1-$B16),(F16-$B16)/$B16) -> -0.010165964 | G28: =IF(G16>=$B16,(G16-$B16)/(1-$B16),(G16-$B16)/$B16) -> -0.012707455 | H28: =IF(H16>=$B16,(H16-$B16)/(1-$B16),(H16-$B16)/$B16) -> -0.015292136 | I28: =IF(I16>=$B16,(I16-$B16)/(1-$B16),(I16-$B16)/$B16) -> -0.017876816 | ... AF28: =IF(AF16>=$B16,(AF16-$B16)/(1-$B16),(AF16-$B16)/$B16) -> -0.079859912
