Workbook

Sheet About
A1: DSCF Distributed Solar Capacity Factor
A3: Source: | B3: NREL
B4: 2021, 2022
B5: Annual Technology Baseline 2021, Annual Technology Baseline 2022
B6: https://atb.nrel.gov/
B7: "Solar - PV Dist. Res" tab
A9: Notes
A10: We use the ATB "Moderate" case
J14: Source (Hong Kong)
J15: 2014
J16: Solar Energy – New Development and Future Trend by Prof. Yang Hongxing
J17: http://www.energyinst.org.hk/Activity/ICE2014/2.2%20Prof%20Hongxing%20YANG.pdf
J18: Slide 33
A22: Note by Wing 300823
A23: Added J19:J23 and put 12.9% on sheet DSCF.

Sheet Solar - PV Dist. Res 2021
D1: X | G1: Future Projections
L2: Basis Year
L3: 2019 | M3: 2020 | N3: 2021 | O3: 2022 | P3: 2023 | Q3: 2024 | R3: 2025 | S3: 2026 | T3: 2027 | U3: 2028 | V3: 2029 | W3: 2030 | X3: 2031 | Y3: 2032 | Z3: 2033 | AA3: 2034 | AB3: 2035 | AC3: 2036 | AD3: 2037 | AE3: 2038 | AF3: 2039 | AG3: 2040 | AH3: 2041 | AI3: 2042 | AJ3: 2043 | AK3: 2044 | AL3: 2045 | AM3: 2046 | AN3: 2047 | AO3: 2048 | AP3: 2049 | AQ3: 2050
H4: Techno-Economic Cost and Performance Parameters | J4: Net Capacity Factor (%) | K4: Residential PV - Class 10 - Advanced | L4: 0.11966056 | M4: 0.12013139 | N4: 0.12060223 | O4: 0.12107307 | P4: 0.1215439 | Q4: 0.12201474 | R4: 0.12248557 | S4: 0.12295641 | T4: 0.12342725 | U4: 0.12389808 | V4: 0.12436892 | W4: 0.12483975 | X4: 0.12483975 | Y4: 0.12483975 | Z4: 0.12483975 | AA4: 0.12483975 | AB4: 0.12483975 | AC4: 0.12483975 | AD4: 0.12483975 | AE4: 0.12483975 | AF4: 0.12483975 | AG4: 0.12483975 | AH4: 0.12483975 | AI4: 0.12483975 | AJ4: 0.12483975 | AK4: 0.12483975 | AL4: 0.12483975 | AM4: 0.12483975 | AN4: 0.12483975 | AO4: 0.12483975 | AP4: 0.12483975 | AQ4: 0.12483975
K5: Residential PV - Class 10 - Moderate | L5: 0.11966056 | M5: 0.11984569 | N5: 0.12003083 | O5: 0.12021596 | P5: 0.1204011 | Q5: 0.12058623 | R5: 0.12077137 | S5: 0.12095651 | T5: 0.12114164 | U5: 0.12132678 | V5: 0.12151191 | W5: 0.12169705 | X5: 0.12185418 | Y5: 0.12201132 | Z5: 0.12216845 | AA5: 0.12232559 | AB5: 0.12248272 | AC5: 0.12263986 | AD5: 0.12279699 | AE5: 0.12295413 | AF5: 0.12311126 | AG5: 0.1232684 | AH5: 0.12342554 | AI5: 0.12358267 | AJ5: 0.12373981 | AK5: 0.12389694 | AL5: 0.12405408 | AM5: 0.12421121 | AN5: 0.12436835 | AO5: 0.12452548 | AP5: 0.12468262 | AQ5: 0.12483975
K6: Residential PV - Class 10 - Conservative | L6: 0.11966056 | M6: 0.11966056 | N6: 0.11966056 | O6: 0.11966056 | P6: 0.11966056 | Q6: 0.11966056 | R6: 0.11966056 | S6: 0.11966056 | T6: 0.11966056 | U6: 0.11966056 | V6: 0.11966056 | W6: 0.11966056 | X6: 0.11976238 | Y6: 0.11986421 | Z6: 0.11996603 | AA6: 0.12006786 | AB6: 0.12016968 | AC6: 0.1202715 | AD6: 0.12037333 | AE6: 0.12047515 | AF6: 0.12057698 | AG6: 0.1206788 | AH6: 0.12078063 | AI6: 0.12088245 | AJ6: 0.12098428 | AK6: 0.1210861 | AL6: 0.12118792 | AM6: 0.12128975 | AN6: 0.12139157 | AO6: 0.1214934 | AP6: 0.12159522 | AQ6: 0.12169705
K7: Residential PV - Class 9 - Advanced | L7: 0.13106905 | M7: 0.13158478 | N7: 0.13210051 | O7: 0.13261623 | P7: 0.13313196 | Q7: 0.13364768 | R7: 0.13416341 | S7: 0.13467913 | T7: 0.13519486 | U7: 0.13571059 | V7: 0.13622631 | W7: 0.13674204 | X7: 0.13674204 | Y7: 0.13674204 | Z7: 0.13674204 | AA7: 0.13674204 | AB7: 0.13674204 | AC7: 0.13674204 | AD7: 0.13674204 | AE7: 0.13674204 | AF7: 0.13674204 | AG7: 0.13674204 | AH7: 0.13674204 | AI7: 0.13674204 | AJ7: 0.13674204 | AK7: 0.13674204 | AL7: 0.13674204 | AM7: 0.13674204 | AN7: 0.13674204 | AO7: 0.13674204 | AP7: 0.13674204 | AQ7: 0.13674204
K8: Residential PV - Class 9 - Moderate | L8: 0.13106905 | M8: 0.13127184 | N8: 0.13147463 | O8: 0.13167741 | P8: 0.1318802 | Q8: 0.13208299 | R8: 0.13228577 | S8: 0.13248856 | T8: 0.13269134 | U8: 0.13289413 | V8: 0.13309692 | W8: 0.1332997 | X8: 0.13347182 | Y8: 0.13364394 | Z8: 0.13381605 | AA8: 0.13398817 | AB8: 0.13416029 | AC8: 0.1343324 | AD8: 0.13450452 | AE8: 0.13467664 | AF8: 0.13484875 | AG8: 0.13502087 | AH8: 0.13519299 | AI8: 0.1353651 | AJ8: 0.13553722 | AK8: 0.13570934 | AL8: 0.13588145 | AM8: 0.13605357 | AN8: 0.13622569 | AO8: 0.1363978 | AP8: 0.13656992 | AQ8: 0.13674204
K9: Residential PV - Class 9 - Conservative | L9: 0.13106905 | M9: 0.13106905 | N9: 0.13106905 | O9: 0.13106905 | P9: 0.13106905 | Q9: 0.13106905 | R9: 0.13106905 | S9: 0.13106905 | T9: 0.13106905 | U9: 0.13106905 | V9: 0.13106905 | W9: 0.13106905 | X9: 0.13118059 | Y9: 0.13129212 | Z9: 0.13140365 | AA9: 0.13151518 | AB9: 0.13162672 | AC9: 0.13173825 | AD9: 0.13184978 | AE9: 0.13196131 | AF9: 0.13207285 | AG9: 0.13218438 | AH9: 0.13229591 | AI9: 0.13240744 | AJ9: 0.13251898 | AK9: 0.13263051 | AL9: 0.13274204 | AM9: 0.13285357 | AN9: 0.13296511 | AO9: 0.13307664 | AP9: 0.13318817 | AQ9: 0.1332997
K10: Residential PV - Class 8 - Advanced | L10: 0.1365026 | M10: 0.13703971 | N10: 0.13757681 | O10: 0.13811392 | P10: 0.13865103 | Q10: 0.13918813 | R10: 0.13972524 | S10: 0.14026234 | T10: 0.14079945 | U10: 0.14133655 | V10: 0.14187366 | W10: 0.14241076 | X10: 0.14241076 | Y10: 0.14241076 | Z10: 0.14241076 | AA10: 0.14241076 | AB10: 0.14241076 | AC10: 0.14241076 | AD10: 0.14241076 | AE10: 0.14241076 | AF10: 0.14241076 | AG10: 0.14241076 | AH10: 0.14241076 | AI10: 0.14241076 | AJ10: 0.14241076 | AK10: 0.14241076 | AL10: 0.14241076 | AM10: 0.14241076 | AN10: 0.14241076 | AO10: 0.14241076 | AP10: 0.14241076 | AQ10: 0.14241076
K11: Residential PV - Class 8 - Moderate | L11: 0.1365026 | M11: 0.1367138 | N11: 0.13692499 | O11: 0.13713618 | P11: 0.13734738 | Q11: 0.13755857 | R11: 0.13776976 | S11: 0.13798095 | T11: 0.13819215 | U11: 0.13840334 | V11: 0.13861453 | W11: 0.13882573 | X11: 0.13900498 | Y11: 0.13918423 | Z11: 0.13936348 | AA11: 0.13954273 | AB11: 0.13972198 | AC11: 0.13990124 | AD11: 0.14008049 | AE11: 0.14025974 | AF11: 0.14043899 | AG11: 0.14061824 | AH11: 0.1407975 | AI11: 0.14097675 | AJ11: 0.141156 | AK11: 0.14133525 | AL11: 0.1415145 | AM11: 0.14169376 | AN11: 0.14187301 | AO11: 0.14205226 | AP11: 0.14223151 | AQ11: 0.14241076
K12: Residential PV - Class 8 - Conservative | L12: 0.1365026 | M12: 0.1365026 | N12: 0.1365026 | O12: 0.1365026 | P12: 0.1365026 | Q12: 0.1365026 | R12: 0.1365026 | S12: 0.1365026 | T12: 0.1365026 | U12: 0.1365026 | V12: 0.1365026 | W12: 0.1365026 | X12: 0.13661876 | Y12: 0.13673492 | Z12: 0.13685107 | AA12: 0.13696723 | AB12: 0.13708338 | AC12: 0.13719954 | AD12: 0.1373157 | AE12: 0.13743185 | AF12: 0.13754801 | AG12: 0.13766416 | AH12: 0.13778032 | AI12: 0.13789648 | AJ12: 0.13801263 | AK12: 0.13812879 | AL12: 0.13824494 | AM12: 0.1383611 | AN12: 0.13847726 | AO12: 0.13859341 | AP12: 0.13870957 | AQ12: 0.13882573
K13: Residential PV - Class 7 - Advanced | L13: 0.14329455 | M13: 0.14385838 | N13: 0.14442221 | O13: 0.14498604 | P13: 0.14554987 | Q13: 0.1461137 | R13: 0.14667753 | S13: 0.14724136 | T13: 0.14780519 | U13: 0.14836902 | V13: 0.14893285 | W13: 0.14949668 | X13: 0.14949668 | Y13: 0.14949668 | Z13: 0.14949668 | AA13: 0.14949668 | AB13: 0.14949668 | AC13: 0.14949668 | AD13: 0.14949668 | AE13: 0.14949668 | AF13: 0.14949668 | AG13: 0.14949668 | AH13: 0.14949668 | AI13: 0.14949668 | AJ13: 0.14949668 | AK13: 0.14949668 | AL13: 0.14949668 | AM13: 0.14949668 | AN13: 0.14949668 | AO13: 0.14949668 | AP13: 0.14949668 | AQ13: 0.14949668
K14: Residential PV - Class 7 - Moderate | L14: 0.14329455 | M14: 0.14351625 | N14: 0.14373795 | O14: 0.14395965 | P14: 0.14418135 | Q14: 0.14440305 | R14: 0.14462475 | S14: 0.14484645 | T14: 0.14506816 | U14: 0.14528986 | V14: 0.14551156 | W14: 0.14573326 | X14: 0.14592143 | Y14: 0.1461096 | Z14: 0.14629777 | AA14: 0.14648594 | AB14: 0.14667411 | AC14: 0.14686229 | AD14: 0.14705046 | AE14: 0.14723863 | AF14: 0.1474268 | AG14: 0.14761497 | AH14: 0.14780314 | AI14: 0.14799131 | AJ14: 0.14817948 | AK14: 0.14836765 | AL14: 0.14855582 | AM14: 0.14874399 | AN14: 0.14893217 | AO14: 0.14912034 | AP14: 0.14930851 | AQ14: 0.14949668
K15: Residential PV - Class 7 - Conservative | L15: 0.14329455 | M15: 0.14329455 | N15: 0.14329455 | O15: 0.14329455 | P15: 0.14329455 | Q15: 0.14329455 | R15: 0.14329455 | S15: 0.14329455 | T15: 0.14329455 | U15: 0.14329455 | V15: 0.14329455 | W15: 0.14329455 | X15: 0.14341648 | Y15: 0.14353842 | Z15: 0.14366035 | AA15: 0.14378229 | AB15: 0.14390422 | AC15: 0.14402616 | AD15: 0.1441481 | AE15: 0.14427003 | AF15: 0.14439197 | AG15: 0.1445139 | AH15: 0.14463584 | AI15: 0.14475777 | AJ15: 0.14487971 | AK15: 0.14500165 | AL15: 0.14512358 | AM15: 0.14524552 | AN15: 0.14536745 | AO15: 0.14548939 | AP15: 0.14561132 | AQ15: 0.14573326
K16: Residential PV - Class 6 - Advanced | L16: 0.14990328 | M16: 0.15049312 | N16: 0.15108295 | O16: 0.15167279 | P16: 0.15226262 | Q16: 0.15285245 | R16: 0.15344229 | S16: 0.15403212 | T16: 0.15462196 | U16: 0.15521179 | V16: 0.15580162 | W16: 0.15639146 | X16: 0.15639146 | Y16: 0.15639146 | Z16: 0.15639146 | AA16: 0.15639146 | AB16: 0.15639146 | AC16: 0.15639146 | AD16: 0.15639146 | AE16: 0.15639146 | AF16: 0.15639146 | AG16: 0.15639146 | AH16: 0.15639146 | AI16: 0.15639146 | AJ16: 0.15639146 | AK16: 0.15639146 | AL16: 0.15639146 | AM16: 0.15639146 | AN16: 0.15639146 | AO16: 0.15639146 | AP16: 0.15639146 | AQ16: 0.15639146
... K33: Residential PV - Class 1 - Conservative | L33: 0.18463784 | M33: 0.18463784 | N33: 0.18463784 | O33: 0.18463784 | P33: 0.18463784 | Q33: 0.18463784 | R33: 0.18463784 | S33: 0.18463784 | T33: 0.18463784 | U33: 0.18463784 | V33: 0.18463784 | W33: 0.18463784 | X33: 0.18479496 | Y33: 0.18495208 | Z33: 0.18510919 | AA33: 0.18526631 | AB33: 0.18542343 | AC33: 0.18558054 | AD33: 0.18573766 | AE33: 0.18589478 | AF33: 0.18605189 | AG33: 0.18620901 | AH33: 0.18636613 | AI33: 0.18652324 | AJ33: 0.18668036 | AK33: 0.18683748 | AL33: 0.18699459 | AM33: 0.18715171 | AN33: 0.18730882 | AO33: 0.18746594 | AP33: 0.18762306 | AQ33: 0.18778017

Sheet Solar - PV Dist. Res 2022
A1: Solar Distributed Residential PV | M1: https://atb.nrel.gov/electricity/2022/residential_pv
U2: Inputs
U3: Calculated
U4: Input from other tab
B7: X | G7: Assumptions
H9: Technology | J9: Base Year: | M9: 2020
J10: All values are given in 2020 U.S. dollars, using the Consumer Price Index (BLS, 2021) for dollar year conversions where source dollar years don't match 2020.
J11: Residential Solar Photovoltaic
J14: Representative Dist. Res system is fixed-tilt roof mounted with capacity of 7.15 kW
J15: Overnight Capital Cost, Capacity Factor, Fixed O&M, and Variable O&M costs
J16: represent $/kW DC; however LCOE reflects $/MWh AC.
J17: Capacity factors chosen here to reflect range across the continental U.S. using NREL PVWATTS.
O20: Available | P20: Available
O21: Capacity | P21: Generation
O22: (GW) | P22: (GWh)
O23: 731 | P23: 926000
M26: ATB values reflect annual average capacity factor over life of plant including estimated degradation, starting at 0.7% per year, reducing to 0.2%, 0.5%, and 0.5% annual degradation by 2050 for the advanced, moderate, and conservative scenarios, respectively.
H33: Finance | J33: Financial Assumptions:
J34: Capital Recovery Period (Years) | O34: =S35 -> 30 | Q34: Financial Case | S34: ='[2]Financial and CRP Inputs'!$B$5 -> Market
J35: Depreciation Period | O35: 5 | Q35: Capital Recovery Period | S35: =IF('[2]Financial and CRP Inputs'!$E$5="Custom",'[2]Financial and CRP Inputs'!$J$10,IF('[2]Financial and CRP Inputs'!$E$5="TechLife",'[2]Financial and CRP Inputs'!$I$10,'[2]Financial and CRP Inputs'!$E$5)) -> 30
J36: Equity Premium During Construction | O36: 0.02
J37: Construction Duration yrs | O37: 0
J38: Year | K38: Capital | L38: Percent of Leverage During Construction | M38: Percent of Equity During Construction
J39: Index | K39: Fraction
J42: 0 | K42: 1 | L42: 0.8 | M42: =1-L42 -> 0.2
J43: 1 | K43: 0 | L43: 0.8 | M43: =1-L43 -> 0.2
J44: 2 | K44: 0 | L44: 0.8 | M44: =1-L44 -> 0.2
M46: Base Year
M47: 2020 | N47: 2021 | O47: 2022 | P47: 2023 | Q47: 2024 | R47: 2025 | S47: 2026 | T47: 2027 | U47: 2028 | V47: 2029 | W47: 2030 | X47: 2031 | Y47: 2032 | Z47: 2033 | AA47: 2034 | AB47: 2035 | AC47: 2036 | AD47: 2037 | AE47: 2038 | AF47: 2039 | AG47: 2040 | AH47: 2041 | AI47: 2042 | AJ47: 2043 | AK47: 2044 | AL47: 2045 | AM47: 2046 | AN47: 2047 | AO47: 2048 | AP47: 2049 | AQ47: 2050
J48: Assumptions | K48: Inflation Rate | L48: * | M48: =IF($S$34="Market",'[2]WACC Calc'!F368,'[2]WACC Calc'!F550) -> 0.025 | N48: =IF($S$34="Market",'[2]WACC Calc'!G368,'[2]WACC Calc'!G550) -> 0.025 | O48: =IF($S$34="Market",'[2]WACC Calc'!H368,'[2]WACC Calc'!H550) -> 0.025 | P48: =IF($S$34="Market",'[2]WACC Calc'!I368,'[2]WACC Calc'!I550) -> 0.025 | Q48: =IF($S$34="Market",'[2]WACC Calc'!J368,'[2]WACC Calc'!J550) -> 0.025 | R48: =IF($S$34="Market",'[2]WACC Calc'!K368,'[2]WACC Calc'!K550) -> 0.025 | S48: =IF($S$34="Market",'[2]WACC Calc'!L368,'[2]WACC Calc'!L550) -> 0.025 | T48: =IF($S$34="Market",'[2]WACC Calc'!M368,'[2]WACC Calc'!M550) -> 0.025 | ... AQ48: =IF($S$34="Market",'[2]WACC Calc'!AJ368,'[2]WACC Calc'!AJ550) -> 0.025
K49: Interest Rate Nominal | L49: Advanced | M49: =IF($S$34="Market",'[2]WACC Calc'!F369,'[2]WACC Calc'!F551) -> 0.04 | N49: =IF($S$34="Market",'[2]WACC Calc'!G369,'[2]WACC Calc'!G551) -> 0.04 | O49: =IF($S$34="Market",'[2]WACC Calc'!H369,'[2]WACC Calc'!H551) -> 0.04 | P49: =IF($S$34="Market",'[2]WACC Calc'!I369,'[2]WACC Calc'!I551) -> 0.04 | Q49: =IF($S$34="Market",'[2]WACC Calc'!J369,'[2]WACC Calc'!J551) -> 0.04 | R49: =IF($S$34="Market",'[2]WACC Calc'!K369,'[2]WACC Calc'!K551) -> 0.04 | S49: =IF($S$34="Market",'[2]WACC Calc'!L369,'[2]WACC Calc'!L551) -> 0.042 | T49: =IF($S$34="Market",'[2]WACC Calc'!M369,'[2]WACC Calc'!M551) -> 0.044 | ... AQ49: =IF($S$34="Market",'[2]WACC Calc'!AJ369,'[2]WACC Calc'!AJ551) -> 0.05
K50: Interest Rate Nominal | L50: Moderate | M50: =IF($S$34="Market",'[2]WACC Calc'!F370,'[2]WACC Calc'!F552) -> 0.04 | N50: =IF($S$34="Market",'[2]WACC Calc'!G370,'[2]WACC Calc'!G552) -> 0.04 | O50: =IF($S$34="Market",'[2]WACC Calc'!H370,'[2]WACC Calc'!H552) -> 0.04 | P50: =IF($S$34="Market",'[2]WACC Calc'!I370,'[2]WACC Calc'!I552) -> 0.04 | Q50: =IF($S$34="Market",'[2]WACC Calc'!J370,'[2]WACC Calc'!J552) -> 0.04 | R50: =IF($S$34="Market",'[2]WACC Calc'!K370,'[2]WACC Calc'!K552) -> 0.04 | S50: =IF($S$34="Market",'[2]WACC Calc'!L370,'[2]WACC Calc'!L552) -> 0.042 | T50: =IF($S$34="Market",'[2]WACC Calc'!M370,'[2]WACC Calc'!M552) -> 0.044 | ... AQ50: =IF($S$34="Market",'[2]WACC Calc'!AJ370,'[2]WACC Calc'!AJ552) -> 0.05
K51: Interest Rate Nominal | L51: Conservative | M51: =IF($S$34="Market",'[2]WACC Calc'!F371,'[2]WACC Calc'!F553) -> 0.04 | N51: =IF($S$34="Market",'[2]WACC Calc'!G371,'[2]WACC Calc'!G553) -> 0.04 | O51: =IF($S$34="Market",'[2]WACC Calc'!H371,'[2]WACC Calc'!H553) -> 0.04 | P51: =IF($S$34="Market",'[2]WACC Calc'!I371,'[2]WACC Calc'!I553) -> 0.04 | Q51: =IF($S$34="Market",'[2]WACC Calc'!J371,'[2]WACC Calc'!J553) -> 0.04 | R51: =IF($S$34="Market",'[2]WACC Calc'!K371,'[2]WACC Calc'!K553) -> 0.04 | S51: =IF($S$34="Market",'[2]WACC Calc'!L371,'[2]WACC Calc'!L553) -> 0.042 | T51: =IF($S$34="Market",'[2]WACC Calc'!M371,'[2]WACC Calc'!M553) -> 0.044 | ... AQ51: =IF($S$34="Market",'[2]WACC Calc'!AJ371,'[2]WACC Calc'!AJ553) -> 0.05
K52: Calculated Interest Rate Real | L52: Advanced | M52: =(1+M49)/(1+M$48) - 1 -> 0.014634146 | N52: =(1+N49)/(1+N$48) - 1 -> 0.014634146 | O52: =(1+O49)/(1+O$48) - 1 -> 0.014634146 | P52: =(1+P49)/(1+P$48) - 1 -> 0.014634146 | Q52: =(1+Q49)/(1+Q$48) - 1 -> 0.014634146 | R52: =(1+R49)/(1+R$48) - 1 -> 0.014634146 | S52: =(1+S49)/(1+S$48) - 1 -> 0.016585366 | T52: =(1+T49)/(1+T$48) - 1 -> 0.018536585 | ... AQ52: =(1+AQ49)/(1+AQ$48) - 1 -> 0.024390244
K53: Calculated Interest Rate Real | L53: Moderate | M53: =(1+M50)/(1+M$48) - 1 -> 0.014634146 | N53: =(1+N50)/(1+N$48) - 1 -> 0.014634146 | O53: =(1+O50)/(1+O$48) - 1 -> 0.014634146 | P53: =(1+P50)/(1+P$48) - 1 -> 0.014634146 | Q53: =(1+Q50)/(1+Q$48) - 1 -> 0.014634146 | R53: =(1+R50)/(1+R$48) - 1 -> 0.014634146 | S53: =(1+S50)/(1+S$48) - 1 -> 0.016585366 | T53: =(1+T50)/(1+T$48) - 1 -> 0.018536585 | ... AQ53: =(1+AQ50)/(1+AQ$48) - 1 -> 0.024390244
K54: Calculated Interest Rate Real | L54: Conservative | M54: =(1+M51)/(1+M$48) - 1 -> 0.014634146 | N54: =(1+N51)/(1+N$48) - 1 -> 0.014634146 | O54: =(1+O51)/(1+O$48) - 1 -> 0.014634146 | P54: =(1+P51)/(1+P$48) - 1 -> 0.014634146 | Q54: =(1+Q51)/(1+Q$48) - 1 -> 0.014634146 | R54: =(1+R51)/(1+R$48) - 1 -> 0.014634146 | S54: =(1+S51)/(1+S$48) - 1 -> 0.016585366 | T54: =(1+T51)/(1+T$48) - 1 -> 0.018536585 | ... AQ54: =(1+AQ51)/(1+AQ$48) - 1 -> 0.024390244
K55: Interest During Construction - Nominal | L55: * | M55: =IF($S$34="Market",'[2]WACC Calc'!F375,'[2]WACC Calc'!F557) -> 0.035 | N55: =IF($S$34="Market",'[2]WACC Calc'!G375,'[2]WACC Calc'!G557) -> 0.035 | O55: =IF($S$34="Market",'[2]WACC Calc'!H375,'[2]WACC Calc'!H557) -> 0.035 | P55: =IF($S$34="Market",'[2]WACC Calc'!I375,'[2]WACC Calc'!I557) -> 0.035 | Q55: =IF($S$34="Market",'[2]WACC Calc'!J375,'[2]WACC Calc'!J557) -> 0.035 | R55: =IF($S$34="Market",'[2]WACC Calc'!K375,'[2]WACC Calc'!K557) -> 0.035 | S55: =IF($S$34="Market",'[2]WACC Calc'!L375,'[2]WACC Calc'!L557) -> 0.037 | T55: =IF($S$34="Market",'[2]WACC Calc'!M375,'[2]WACC Calc'!M557) -> 0.039 | ... AQ55: =IF($S$34="Market",'[2]WACC Calc'!AJ375,'[2]WACC Calc'!AJ557) -> 0.045
K56: Rate of Return on Equity Nominal | L56: Advanced | M56: =IF($S$34="Market",'[2]WACC Calc'!F376,'[2]WACC Calc'!F558) -> 0.088 | N56: =IF($S$34="Market",'[2]WACC Calc'!G376,'[2]WACC Calc'!G558) -> 0.088 | O56: =IF($S$34="Market",'[2]WACC Calc'!H376,'[2]WACC Calc'!H558) -> 0.088 | P56: =IF($S$34="Market",'[2]WACC Calc'!I376,'[2]WACC Calc'!I558) -> 0.088 | Q56: =IF($S$34="Market",'[2]WACC Calc'!J376,'[2]WACC Calc'!J558) -> 0.088 | R56: =IF($S$34="Market",'[2]WACC Calc'!K376,'[2]WACC Calc'!K558) -> 0.088 | S56: =IF($S$34="Market",'[2]WACC Calc'!L376,'[2]WACC Calc'!L558) -> 0.088 | T56: =IF($S$34="Market",'[2]WACC Calc'!M376,'[2]WACC Calc'!M558) -> 0.088 | ... AQ56: =IF($S$34="Market",'[2]WACC Calc'!AJ376,'[2]WACC Calc'!AJ558) -> 0.088
K57: Rate of Return on Equity Nominal | L57: Moderate | M57: =IF($S$34="Market",'[2]WACC Calc'!F377,'[2]WACC Calc'!F559) -> 0.088 | N57: =IF($S$34="Market",'[2]WACC Calc'!G377,'[2]WACC Calc'!G559) -> 0.088 | O57: =IF($S$34="Market",'[2]WACC Calc'!H377,'[2]WACC Calc'!H559) -> 0.088 | P57: =IF($S$34="Market",'[2]WACC Calc'!I377,'[2]WACC Calc'!I559) -> 0.088 | Q57: =IF($S$34="Market",'[2]WACC Calc'!J377,'[2]WACC Calc'!J559) -> 0.088 | R57: =IF($S$34="Market",'[2]WACC Calc'!K377,'[2]WACC Calc'!K559) -> 0.088 | S57: =IF($S$34="Market",'[2]WACC Calc'!L377,'[2]WACC Calc'!L559) -> 0.088 | T57: =IF($S$34="Market",'[2]WACC Calc'!M377,'[2]WACC Calc'!M559) -> 0.088 | ... AQ57: =IF($S$34="Market",'[2]WACC Calc'!AJ377,'[2]WACC Calc'!AJ559) -> 0.088
K58: Rate of Return on Equity Nominal | L58: Conservative | M58: =IF($S$34="Market",'[2]WACC Calc'!F378,'[2]WACC Calc'!F560) -> 0.088 | N58: =IF($S$34="Market",'[2]WACC Calc'!G378,'[2]WACC Calc'!G560) -> 0.088 | O58: =IF($S$34="Market",'[2]WACC Calc'!H378,'[2]WACC Calc'!H560) -> 0.088 | P58: =IF($S$34="Market",'[2]WACC Calc'!I378,'[2]WACC Calc'!I560) -> 0.088 | Q58: =IF($S$34="Market",'[2]WACC Calc'!J378,'[2]WACC Calc'!J560) -> 0.088 | R58: =IF($S$34="Market",'[2]WACC Calc'!K378,'[2]WACC Calc'!K560) -> 0.088 | S58: =IF($S$34="Market",'[2]WACC Calc'!L378,'[2]WACC Calc'!L560) -> 0.088 | T58: =IF($S$34="Market",'[2]WACC Calc'!M378,'[2]WACC Calc'!M560) -> 0.088 | ... AQ58: =IF($S$34="Market",'[2]WACC Calc'!AJ378,'[2]WACC Calc'!AJ560) -> 0.088
...

Sheet DSCF
B1: 2019 | C1: 2020 | D1: 2021 | E1: 2022 | F1: 2023 | G1: 2024 | H1: 2025 | I1: 2026 | J1: 2027 | K1: 2028 | L1: 2029 | M1: 2030 | N1: 2031 | O1: 2032 | P1: 2033 | Q1: 2034 | R1: 2035 | S1: 2036 | T1: 2037 | U1: 2038 | V1: 2039 | W1: 2040 | X1: 2041 | Y1: 2042 | Z1: 2043 | AA1: 2044 | AB1: 2045 | AC1: 2046 | AD1: 2047 | AE1: 2048 | AF1: 2049 | AG1: 2050
A2: Capacity Factor (dimensionless) | B2: =AVERAGE('Solar - PV Dist. Res 2021'!L5,'Solar - PV Dist. Res 2021'!L8,'Solar - PV Dist. Res 2021'!L11,'Solar - PV Dist. Res 2021'!L14,'Solar - PV Dist. Res 2021'!L17,'Solar - PV Dist. Res 2021'!L20,'Solar - PV Dist. Res 2021'!L23,'Solar - PV Dist. Res 2021'!L26,'Solar - PV Dist. Res 2021'!L29,'Solar - PV Dist. Res 2021'!L32) -> 0.15284766 | C2: =AVERAGE('Solar - PV Dist. Res 2022'!M86,'Solar - PV Dist. Res 2022'!M89,'Solar - PV Dist. Res 2022'!M92,'Solar - PV Dist. Res 2022'!M95,'Solar - PV Dist. Res 2022'!M98,'Solar - PV Dist. Res 2022'!M101,'Solar - PV Dist. Res 2022'!M104,'Solar - PV Dist. Res 2022'!M107,'Solar - PV Dist. Res 2022'!M110,'Solar - PV Dist. Res 2022'!M113) -> 0.15308415 | D2: =AVERAGE('Solar - PV Dist. Res 2022'!N86,'Solar - PV Dist. Res 2022'!N89,'Solar - PV Dist. Res 2022'!N92,'Solar - PV Dist. Res 2022'!N95,'Solar - PV Dist. Res 2022'!N98,'Solar - PV Dist. Res 2022'!N101,'Solar - PV Dist. Res 2022'!N104,'Solar - PV Dist. Res 2022'!N107,'Solar - PV Dist. Res 2022'!N110,'Solar - PV Dist. Res 2022'!N113) -> 0.15332063 | E2: =AVERAGE('Solar - PV Dist. Res 2022'!O86,'Solar - PV Dist. Res 2022'!O89,'Solar - PV Dist. Res 2022'!O92,'Solar - PV Dist. Res 2022'!O95,'Solar - PV Dist. Res 2022'!O98,'Solar - PV Dist. Res 2022'!O101,'Solar - PV Dist. Res 2022'!O104,'Solar - PV Dist. Res 2022'!O107,'Solar - PV Dist. Res 2022'!O110,'Solar - PV Dist. Res 2022'!O113) -> 0.15355711 | F2: =AVERAGE('Solar - PV Dist. Res 2022'!P86,'Solar - PV Dist. Res 2022'!P89,'Solar - PV Dist. Res 2022'!P92,'Solar - PV Dist. Res 2022'!P95,'Solar - PV Dist. Res 2022'!P98,'Solar - PV Dist. Res 2022'!P101,'Solar - PV Dist. Res 2022'!P104,'Solar - PV Dist. Res 2022'!P107,'Solar - PV Dist. Res 2022'!P110,'Solar - PV Dist. Res 2022'!P113) -> 0.15379359 | G2: =AVERAGE('Solar - PV Dist. Res 2022'!Q86,'Solar - PV Dist. Res 2022'!Q89,'Solar - PV Dist. Res 2022'!Q92,'Solar - PV Dist. Res 2022'!Q95,'Solar - PV Dist. Res 2022'!Q98,'Solar - PV Dist. Res 2022'!Q101,'Solar - PV Dist. Res 2022'!Q104,'Solar - PV Dist. Res 2022'!Q107,'Solar - PV Dist. Res 2022'!Q110,'Solar - PV Dist. Res 2022'!Q113) -> 0.15403007 | H2: =AVERAGE('Solar - PV Dist. Res 2022'!R86,'Solar - PV Dist. Res 2022'!R89,'Solar - PV Dist. Res 2022'!R92,'Solar - PV Dist. Res 2022'!R95,'Solar - PV Dist. Res 2022'!R98,'Solar - PV Dist. Res 2022'!R101,'Solar - PV Dist. Res 2022'!R104,'Solar - PV Dist. Res 2022'!R107,'Solar - PV Dist. Res 2022'!R110,'Solar - PV Dist. Res 2022'!R113) -> 0.15426655 | I2: =AVERAGE('Solar - PV Dist. Res 2022'!S86,'Solar - PV Dist. Res 2022'!S89,'Solar - PV Dist. Res 2022'!S92,'Solar - PV Dist. Res 2022'!S95,'Solar - PV Dist. Res 2022'!S98,'Solar - PV Dist. Res 2022'!S101,'Solar - PV Dist. Res 2022'!S104,'Solar - PV Dist. Res 2022'!S107,'Solar - PV Dist. Res 2022'!S110,'Solar - PV Dist. Res 2022'!S113) -> 0.15450303 | J2: =AVERAGE('Solar - PV Dist. Res 2022'!T86,'Solar - PV Dist. Res 2022'!T89,'Solar - PV Dist. Res 2022'!T92,'Solar - PV Dist. Res 2022'!T95,'Solar - PV Dist. Res 2022'!T98,'Solar - PV Dist. Res 2022'!T101,'Solar - PV Dist. Res 2022'!T104,'Solar - PV Dist. Res 2022'!T107,'Solar - PV Dist. Res 2022'!T110,'Solar - PV Dist. Res 2022'!T113) -> 0.15473952 | ... AG2: =AVERAGE('Solar - PV Dist. Res 2022'!AQ86,'Solar - PV Dist. Res 2022'!AQ89,'Solar - PV Dist. Res 2022'!AQ92,'Solar - PV Dist. Res 2022'!AQ95,'Solar - PV Dist. Res 2022'!AQ98,'Solar - PV Dist. Res 2022'!AQ101,'Solar - PV Dist. Res 2022'!AQ104,'Solar - PV Dist. Res 2022'!AQ107,'Solar - PV Dist. Res 2022'!AQ110,'Solar - PV Dist. Res 2022'!AQ113) -> 0.15946328
A3: Capacity Factor (dimensionless) | B3: 0.129 | C3: 0.129 | D3: 0.129 | E3: 0.129 | F3: 0.129 | G3: 0.129 | H3: 0.129 | I3: 0.129 | J3: 0.129 | K3: 0.129 | L3: 0.129 | M3: 0.129 | N3: 0.129 | O3: 0.129 | P3: 0.129 | Q3: 0.129 | R3: 0.129 | S3: 0.129 | T3: 0.129 | U3: 0.129 | V3: 0.129 | W3: 0.129 | X3: 0.129 | Y3: 0.129 | Z3: 0.129 | AA3: 0.129 | AB3: 0.129 | AC3: 0.129 | AD3: 0.129 | AE3: 0.129 | AF3: 0.129 | AG3: 0.129
