Workbook

Sheet About
A1: BCR BAU Capacity Retirements
A3: Sources: | B3: Electricity Mix, Capacity and Plans
B4: CLP website and HK Electricity website
B5: Retrieved 2019/03/23
B6: CLP:https://www.clpgroup.com/en/about/our-business/assets-and-services.html
B7: HKE:https://www.powerassets.com/en/our-business/hong-kong
A9: Notes
A10: 1.To estimate the capacity retirements (except nuclear) in the future,
A11: we subtract the capacity lifetime from the required year and
A12: use the (newly) installed capacity for that year as the retirements for the required year.
A13: The capacity lifetime data(with light green background) is from EPA China model,
A14: which is from the "BAU Generation Capacity Lifetime" xls in that model.
A15: If scheduled retirement time given, then use the scheduled time first; if not, the above capacity data is adopted.
A17: 2.Given that HK's electricity is overwhelming dominated by two companys-CLP and HK Electricity(HKE),
A18: who supply almost all HK's electricity demand, their public resources and data are reviewed to get information
A19: about the current capacity of the two company and the generator's age.
A21: Pumped Storage information not included here.
A23: Question
... A25: 2. Should the twoo newly built CLP Power’s New Gas-Fired Generation Units be included?

Sheet CLP Assets
A1: Performance Statistics of CLP’s Asset
A2: CLP in Hong Kong 亚太业务-香港
A3: Summary of HK Power Genaration Stations
B4: Power Stations | C4: Capacity(MW) | D4: Fuel | E4: In-production Year 投产年份 | F4: 备注 | G4: Source: | H4: https://www.clpgroup.com/content/dam/clp-group/channels/sustainability/document/sustainability-report/2022/SR2022_APS.pdf.coredownload.pdf
B5: Castle Peak Power Station青山发电厂 | C5: 4108 | D5: Coal | E5: 1982-1990 | F5: (=4*350MW+4*677MW). CLP owns 2875.6 MW. Accounts for more than 40% of CLP's generating capacity. A joint venture jointly owned by CLP power (70%) and China southern power international (Hong Kong) limited (30%).
B6: 4 Oldest (1400MW) | G6: 4 oldest coal generators will gradually retire in the mid-2020s. | P6: should be phased out between 2022-2025
B7: Another 4 (2708MV) | G7: Another 4 are assumed to retire by 2030.
B8: Black Point Power Station 龙鼓滩发电厂 | C8: 3250 | D8: Gas | E8: 1996-2006, by stages | F8: 8x 312.5MW). CLP owns 1750 MW. One of the largest gas-fired combined cycle power plants in the world. A joint venture between CLP power (70 per cent) and China southern power international (Hong Kong) limited (30 per cent), with CLP power operating the plant.
B9: Penny's Bay Power Station 竹篙湾发电厂 | C9: 300 | D9: Oil | E9: 1992 | F9: CLP owns 210 MW. Important backup power generation facilities, can quickly respond to emergencies and peak power demand.It can be put into operation quickly.Linking to the 132KV transmission network, power generation is supplied to the New Territories via submarine cables
B10: NT West Biomass Project 新界西堆填区沼气发电项目 | C10: 10 | D10: Biomass | E10: 2019 | F10: (=5*2MW). In construction. The largest landfill gas power generation project in Hong Kong. | O10: （中电资料册）
B11: Daya Bay Nuclear Power Station in Guangdong 广东大亚湾核电站 | C11: =2*984 -> 1968 | D11: Nuclear | E11: 1994 | F11: (=2*984MW). 70% of the generated electricity is sold to CLP to transmit to HK. Supply 25% of HK's elec demand. The contract is renewed until 2034 in 2009. From the end of 2014 to 2018, the propotion of electricity export from the port in total power generation increased to 80%.
B12: Purchased by CLP (80%) | C12: 1577
B13: Guangzhou Pumped Storage Power Station 广州蓄能水电厂 | C13: 2400 | D13: Hydro | E13: 1994 and 2000 (finished by 2 stages, 1200MW respectively) | F13: To support the grid system to cope with peak generating capacity as a backup energy source in case of emergency.CLP's rights expire in 2034.
B14: Total Capacity | C14: =SUM(C5:C10) -> 7668
B15: Total Capacity (including those under construction) 香港总装机容量（含在建） | C15: 8268MW | G15: Source | H15: https://www.clpgroup.com/content/dam/clp-group/channels/media/document/embedded_pdfs_en/20211028_D1_Factsheet_en.pdf
H16: https://www.clpgroup.com/en/about/our-business/assets-and-services/hong-kong/black-point-power-station.html
A17: Scheme of Control (SoC) Business in Hong Kong 香港管制计划业务部分 | H17: New Turbines increased BlackPoint Power Station gross capacity from 2250 to 3250
B18: Indicator | C18: Unit | D18: 2022 | E18: 2018
B19: Electricity Sales 电力销售 | C19: GWh | D19: 34824 | E19: 34218
B20: Generation capacity and capacity purchase 发电容量+购入的发电容量 | C20: MW | D20: =3250+4108+300+10+1577 -> 9245 | E20: =2575+4108+300+1377.6 -> 8360.6 | H20: https://www.clpgroup.com/content/dam/clp-group/channels/investor/document/3-3-financial-reports/2022/e_2022Annual%20Report.pdf
A21: CLP owns 区内投资
B22: HK Elec transmission, distribution and customer service | C22: 1 | D22: CLP Power HK Limited | I22: Investor information - business data 投资者信息-业务资料
B23: HK Elec generation | C23: 0.7 | D23: Castle Peak Power Company Limited | F23: 另外30%是南方電網國際（香港）有限公司 | I23: https://www.clpgroup.com/tc/investors-information/quick-facts/operating-information
B24: HK Gas pipeline | C24: 0.4 | D24: PetroChina Company Limited | F24: 另外60%是中國石油天然氣股份有限公司
A25: Business Model 商业模式
B26: Power generation, transmission and retail 發電、輸供電及零售業務
B27: Purchase electricity to supplement local needs 購買電力以補充本地所需的供應
B28: The cost of imported fuel and related fuel borne by the customer 進口燃料、相關燃料成本由客戶承擔
A30: Power Stations
B31: 龙鼓滩 Black Point Power Station | D31: 2022资产表现数据 2022 Asset Performance Statistics | G31: 2017资产表现数据 2017 Asset Performance Statistics | K31: Infomation
B32: 营运Operation | C32: Unit | D32: 2022 | E32: 2021 | F32: 2020 | G32: 2018 | H32: 2017 | I32: 2016 | K32: Gas-fired power station 燃氣電廠    | U32: Energy Source:
B33: 输出电量 Electricity sent out | C33: GWh百万度 | D33: =3363+13544 -> 16907 | E33: =3550+13876 -> 17426 | F33: =714+15175 -> 15889 | G33: 9304 | H33: 9550 | I33: 9175 | K33: 2,525MW (3 x 337.5MW & 5 x 312.5MW) 2,525兆瓦 (3 x 337.5兆瓦 和 5 x 312.5兆瓦)
B34: 天然气消耗 Gas consumed | C34: TJ | D34: =22782+105670 -> 128452 | E34: =24122+108481 -> 132603 | F34: =4922+118081 -> 123003 | G34: 72963 | H34: 75747 | I34: 73014 | K34: Plant commissioned between 1996 and 2006 電廠於1996年至2006年間分阶段投產
B35: 燃油消耗 Oil consumed | C35: TJ | D35: =2+95 -> 97 | E35: =239+98 -> 337 | F35: 68 | G35: 163 | H35: 76 | I35: 227 | K35: Shareholding of 70% with operational control by CLP 中電擁有70%權益及營運控制權(1750MW)
B36: 发电效能 Thermal effiiciency | C36: % | D36: =53.1+46.1 -> 99.2 | E36: =52.5+46 -> 98.5 | F36: =52.2+46.2 -> 98.4 | G36: 45.8 | H36: 45.3 | I36: 45.1
B37: 气体排放Air Emissions | C37: Unit | D37: 2022 | E37: 2021 | F37: 2020 | G37: 2018 | H37: 2017 | I37: 2016
B38: CO2 (Scope1)(1) | C38: kT | D38: =1167+5318 -> 6485 | E38: =1271+5566 -> 6837 | F38: =247+6151 -> 6398 | G38: 3776 | H38: 3923 | I38: 3761
B39: CO2 (Scope1) | C39: kT | D39: =1161+5285 -> 6446 | E39: =1263+5537 -> 6800 | F39: =247+6126 -> 6373 | G39: 3759 | H39: 3906 | I39: 3745 | K39: Note:
B40: SO2 | C40: kT | D40: =0.011+0.027 -> 0.038 | E40: =0.016+0.005 -> 0.021 | F40: =0.001+0.077 -> 0.078 | G40: 0.08 | H40: 0.08 | I40: 0.05 | K40: (1) Scope 2 emissions are included in Scope 1 as electricity consumed was generated within CLP Power Hong Kong's own Organisational
B41: NOx | C41: kT | D41: =0.05+1.93 -> 1.98 | E41: =0.17+1.78 -> 1.95 | F41: =0.12+1.96 -> 2.08 | G41: 1.4 | H41: 1.4 | I41: 1.6 | K41: boundary.
...

Sheet HKE Asset
A1: Asset Information of HKE-HKE's Power Stations | G1: https://www.hkelectric.com/documents/en/CorporateSocialResponsibility/CorporateSocialResponsibility_CDD/Documents/SR2022E.pdf
A3: 1. Operating | B3: Station | C3: Generator | D3: Capacity (MW) | E3: In-produce Year | F3: Lifetime | G3: Note
B4: Lamma Power Station(南丫发电厂)
B5: Coal&Oil | D5: 2305
C6: 5 oil fired open-cycle gas turbine units | D6: 555 | G6: aim to cease coal-fired power operations by 2035
C7: 5 coal fired units | D7: 1750 | G7: Fuel oil is used for starting and flame stabilisation of coal-fired units and so the specific breakdown for fuel oil was not provided
B8: Gas | D8: =SUM(D9:D10) -> 1095
C9: 3 gas-fired combined cycle units | D9: 1095 | E9: 2006 | G9: L10, L11 were commissioned in 2020 and 2022 respectively. L12 operation date to be revised to Early 2024, rather than 2023
B11: RE | D11: =1.1+0.8+0.1 -> 2
C12: Solar PV | D12: 1.1 | E12: 2006 | G12: Generate 1.1 Mil. kWh each year(by prediction) with 915kT CO2 reduced.
C13: Other small-scale RE installation | D13: 0.1 | E13: 2013
C14: Wind Power | D14: 0.8 | E14: 2006.2 | G14: Generatting 1Mil. kWh each year.
B15: Sum | C15: Sum-2017 | D15: 3487
C16: Sum-2022 | D16: 3402
C17: delta(2017-2022) | D17: =D15-D16 -> 85
B18: Gas Ratio
C19: From 2022 Annual report | D19: 0.53
A21: 2. In Construction | B21: Station | C21: Generator | D21: Capacity (MW) | E21: In-produce Year | F21: Lifetime | G21: Note
C22: Solar PV on rooftops | D22: 1.2 | E22: 2023 | G22: aim to double existing the existing capacity of installed PVs (from 1.1 to 2.4)
A25: 3. Approved | B25: Station | C25: Generator | D25: Capacity (MW) | E25: In-produce Year | F25: Lifetime | G25: Note
A28: 4. Plans | B28: Station | C28: Generator | D28: Capacity (MW)
C29: Offshore wind farm | D29: 150 | G29: Will generate roughly 400 million units of zero-carbon electricity per year
G30: NOTE: 150MW is the expected total installed capacity rather than additional 150 MW
B33: HKE thinks it's better to develop gas generation.

Sheet Natural gas&Petroleum&Coal
A1: Year | B1: New Capacity (MW) | I1: Capacity Lifetime(yr) | L1: Note:
B2: Natural Gas | C2: Natural Gas Peaker | D2: Petroleum | E2: Coal-HKE | F2: Coal-CLP | H2: Retire year | I2: Natural Gas | J2: 40 | L2: 1. The eight gas units of longgutan power plant were put into operation successively from 1996 to 2006, so they were allocated into the 10 years relatively evenly.
A3: 1978 | H3: =A3+40 -> 2018 | I3: Petroleum | J3: 40
A4: 1979 | H4: =A4+40 -> 2019 | I4: Hard Coal | J4: 40
A5: 1980 | F5: ='CLP Assets'!C6 -> 0 | H5: =A5+40 -> 2020
A6: 1981 | H6: =A6+40 -> 2021 | I6: Coal, CLP | J6: 40 | L6: 2. CLP's 4 oldest coal genarators,which were built in 1980, are planned to gradually retired around mid-2020s. So their lifetime are about 45 yrs. Therefore we adopt the lifetime of 45 year for coal units in CLP(which means retiring in 2025). As stated in sheet"CLP Assets", we assume another 4 to retire by 2030, therefore we put this capacity in the "new capacity in 1985" row(5 years later retire->equals to 5 yrs more->equals to 5 years later built)
A7: 1982 | H7: =A7+40 -> 2022 | I7: Coal, HKE | J7: 36 | L7: 3. One of the HKE's first coal-fired units, which was built in 1984, has retired before 2017, and the others built in 1990s are planned to retire all before 2030. Therefore, we estimate the lifetime of coal units in HKE is around 33 yrs.
A8: 1983 | H8: =A8+40 -> 2023
A9: 1984 | E9: 250 | H9: =A9+40 -> 2024
A10: 1985 | F10: ='CLP Assets'!C7 -> 0 | H10: =A10+40 -> 2025 | L10: https://www.info.gov.hk/gia/general/201910/25/P2019102500191.htm?fontSize=1
A11: 1986 | H11: =A11+40 -> 2026 | L11: The Hongkong Electric Company, Limited (HEC) is building a new gas-fired generating unit for operation in 2023 while three existing coal-fired generation units will be decommissioned in succession. The increase in gas generation ratio and reduction in forecast electricity demand for 2024 and 2025 by the HEC will allow room for further reduction of its emission allowances.
A12: 1987 | H12: =A12+40 -> 2027
A13: 1988 | H13: =A13+40 -> 2028 | L13: CLP Power Hong Kong Limited (CLP) is also building a new gas-fired generating unit at its Black Point Power Station for expected commencement of operation in 2023. At its Castle Peak Power Station, two existing coal-fired generating units will be decommissioned in succession. CLP has completed upgrading three gas-fired generating units and will upgrade the remaining five units by 2023, which will further reduce its NOx emissions. Furthermore, CLP also forecasts a reduction in electricity demand for 2024 and 2025.
A14: 1989 | H14: =A14+40 -> 2029
A15: 1990 | H15: =A15+40 -> 2030
A16: 1991 | C16: ='HKE Asset'!#REF! -> #REF! | E16: ='HKE Asset'!#REF! -> #REF! | H16: =A16+40 -> 2031
A17: 1992 | D17: ='CLP Assets'!C9 -> 300 | H17: =A17+40 -> 2032
A18: 1993 | H18: =A18+40 -> 2033
A19: 1994 | H19: =A19+40 -> 2034
A20: 1995 | E20: ='HKE Asset'!#REF! -> #REF! | H20: =A20+40 -> 2035
A21: 1996 | B21: ='CLP Assets'!$C$8/8 -> 406.25 | H21: =A21+40 -> 2036
A22: 1997 | E22: ='HKE Asset'!#REF! -> #REF! | H22: =A22+40 -> 2037
A23: 1998 | B23: ='CLP Assets'!$C$8/8 -> 406.25 | H23: =A23+40 -> 2038
A24: 1999 | B24: ='CLP Assets'!$C$8/8 -> 406.25 | H24: =A24+40 -> 2039
A25: 2000 | B25: ='CLP Assets'!$C$8/8 -> 406.25 | H25: =A25+40 -> 2040
A26: 2001 | B26: ='CLP Assets'!$C$8/8 -> 406.25 | H26: =A26+40 -> 2041
A27: 2002 | H27: =A27+40 -> 2042
A28: 2003 | B28: ='CLP Assets'!$C$8/8 -> 406.25 | H28: =A28+40 -> 2043
A29: 2004 | B29: ='CLP Assets'!$C$8/8 -> 406.25 | H29: =A29+40 -> 2044
A30: 2005 | H30: =A30+40 -> 2045
A31: 2006 | B31: ='CLP Assets'!$C$8/8+'HKE Asset'!D9 -> 1501.25 | H31: =A31+40 -> 2046
A32: 2007 | H32: =A32+40 -> 2047
A33: 2008 | H33: =A33+40 -> 2048
A34: 2009 | H34: =A34+40 -> 2049
A35: 2010 | B35: ='HKE Asset'!#REF! -> #REF! | H35: =A35+40 -> 2050
A36: 2011 | H36: =A36+40 -> 2051
A37: 2012 | H37: =A37+40 -> 2052
A38: 2013 | H38: =A38+40 -> 2053
A39: 2014 | H39: =A39+40 -> 2054
A40: 2015 | H40: =A40+40 -> 2055
...

Sheet BCRbQ
A1: Year | B1: 2016 | C1: 2017 | D1: 2018 | E1: 2019 | F1: 2020 | G1: 2021 | H1: 2022 | I1: 2023 | J1: 2024 | K1: 2025 | L1: 2026 | M1: 2027 | N1: 2028 | O1: 2029 | P1: 2030 | Q1: 2031 | R1: 2032 | S1: 2033 | T1: 2034 | U1: 2035 | V1: 2036 | W1: 2037 | X1: 2038 | Y1: 2039 | Z1: 2040 | AA1: 2041 | AB1: 2042 | AC1: 2043 | AD1: 2044 | AE1: 2045 | AF1: 2046 | AG1: 2047 | AH1: 2048 | AI1: 2049 | AJ1: 2050
A2: hard coal | B2: 0 | C2: 0 | D2: 0 | E2: 0 | F2: 0 | G2: 0 | H2: 0 | I2: 0 | J2: 0 | K2: 0 | L2: 0 | M2: 0 | N2: 0 | O2: 0 | P2: 2000 | Q2: 0 | R2: 0 | S2: 0 | T2: 0 | U2: 2000 | V2: 0 | W2: 0 | X2: 0 | Y2: 0 | Z2: 0 | AA2: 0 | AB2: 0 | AC2: 0 | AD2: 0 | AE2: 0 | AF2: 0 | AG2: 0 | AH2: 0 | AI2: 0 | AJ2: 0
A3: natural gas nonpeaker | B3: 0 | C3: 0 | D3: 0 | E3: 0 | F3: 0 | G3: 0 | H3: 0 | I3: 0 | J3: 0 | K3: 0 | L3: 0 | M3: 0 | N3: 0 | O3: 0 | P3: 0 | Q3: =IFERROR(LOOKUP(Q1-'[1]Natural gas&Petroleum&Coal'!$J$3,'[1]Natural gas&Petroleum&Coal'!$A$1:$A$45,'[1]Natural gas&Petroleum&Coal'!$D$1:$D$45),0) -> 0 | R3: 0 | S3: 0 | T3: 0 | U3: 0 | V3: =IFERROR(LOOKUP(V1-'[1]Natural gas&Petroleum&Coal'!$J$2,'[1]Natural gas&Petroleum&Coal'!$A$1:$A$45,'[1]Natural gas&Petroleum&Coal'!$B$1:$B$45),0) -> 406.25 | W3: =IFERROR(LOOKUP(W1-'[1]Natural gas&Petroleum&Coal'!$J$2,'[1]Natural gas&Petroleum&Coal'!$A$1:$A$45,'[1]Natural gas&Petroleum&Coal'!$B$1:$B$45),0) -> 0 | X3: =IFERROR(LOOKUP(X1-'[1]Natural gas&Petroleum&Coal'!$J$2,'[1]Natural gas&Petroleum&Coal'!$A$1:$A$45,'[1]Natural gas&Petroleum&Coal'!$B$1:$B$45),0) -> 406.25 | Y3: =IFERROR(LOOKUP(Y1-'[1]Natural gas&Petroleum&Coal'!$J$2,'[1]Natural gas&Petroleum&Coal'!$A$1:$A$45,'[1]Natural gas&Petroleum&Coal'!$B$1:$B$45),0) -> 406.25 | Z3: =IFERROR(LOOKUP(Z1-'[1]Natural gas&Petroleum&Coal'!$J$2,'[1]Natural gas&Petroleum&Coal'!$A$1:$A$45,'[1]Natural gas&Petroleum&Coal'!$B$1:$B$45),0) -> 406.25 | AA3: =IFERROR(LOOKUP(AA1-'[1]Natural gas&Petroleum&Coal'!$J$2,'[1]Natural gas&Petroleum&Coal'!$A$1:$A$45,'[1]Natural gas&Petroleum&Coal'!$B$1:$B$45),0) -> 406.25 | AB3: =IFERROR(LOOKUP(AB1-'[1]Natural gas&Petroleum&Coal'!$J$2,'[1]Natural gas&Petroleum&Coal'!$A$1:$A$45,'[1]Natural gas&Petroleum&Coal'!$B$1:$B$45),0) -> 0 | AC3: =IFERROR(LOOKUP(AC1-'[1]Natural gas&Petroleum&Coal'!$J$2,'[1]Natural gas&Petroleum&Coal'!$A$1:$A$45,'[1]Natural gas&Petroleum&Coal'!$B$1:$B$45),0) -> 406.25 | ... AJ3: =IFERROR(LOOKUP(AJ1-'[1]Natural gas&Petroleum&Coal'!$J$2,'[1]Natural gas&Petroleum&Coal'!$A$1:$A$45,'[1]Natural gas&Petroleum&Coal'!$B$1:$B$45),0) -> 0
A4: nuclear | B4: =SUMIF([1]Nuclear!$G:$G,[1]BCR!B1,[1]Nuclear!$C:$C) -> #VALUE! | C4: =SUMIF([1]Nuclear!$G:$G,[1]BCR!C1,[1]Nuclear!$C:$C) -> #VALUE! | D4: =SUMIF([1]Nuclear!$G:$G,[1]BCR!D1,[1]Nuclear!$C:$C) -> #VALUE! | E4: =SUMIF([1]Nuclear!$G:$G,[1]BCR!E1,[1]Nuclear!$C:$C) -> #VALUE! | F4: =SUMIF([1]Nuclear!$G:$G,[1]BCR!F1,[1]Nuclear!$C:$C) -> #VALUE! | G4: =SUMIF([1]Nuclear!$G:$G,[1]BCR!G1,[1]Nuclear!$C:$C) -> #VALUE! | H4: =SUMIF([1]Nuclear!$G:$G,[1]BCR!H1,[1]Nuclear!$C:$C) -> #VALUE! | I4: =SUMIF([1]Nuclear!$G:$G,[1]BCR!I1,[1]Nuclear!$C:$C) -> #VALUE! | ... AJ4: =SUMIF([1]Nuclear!$G:$G,[1]BCR!AJ1,[1]Nuclear!$C:$C) -> #VALUE!
A5: hydro | B5: 0 | C5: 0 | D5: 0 | E5: 0 | F5: 0 | G5: 0 | H5: 0 | I5: 0 | J5: 0 | K5: 0 | L5: 0 | M5: 0 | N5: 0 | O5: 0 | P5: 0 | Q5: 0 | R5: 0 | S5: 0 | T5: 0 | U5: 0 | V5: 0 | W5: 0 | X5: 0 | Y5: 0 | Z5: 0 | AA5: 0 | AB5: 0 | AC5: 0 | AD5: 0 | AE5: 0 | AF5: 0 | AG5: 0.5 | AH5: 0 | AI5: 0 | AJ5: 0
A6: onshore wind | B6: =[1]Wind!B2 -> 0 | C6: =[1]Wind!C2 -> 0 | D6: =[1]Wind!D2 -> 0 | E6: =[1]Wind!E2 -> 0 | F6: =[1]Wind!F2 -> 0 | G6: =[1]Wind!G2 -> 0 | H6: =[1]Wind!H2 -> 0 | I6: =[1]Wind!I2 -> 0 | ... K6: =[1]Wind!K2 -> 0 | L6: =[1]Wind!V2 -> 0.8 | M6: =[1]Wind!M2 -> 0 | N6: =[1]Wind!N2 -> 0 | O6: =[1]Wind!O2 -> 0 | P6: =[1]Wind!P2 -> 0 | Q6: =[1]Wind!Q2 -> 0 | R6: =[1]Wind!R2 -> 0 | S6: =[1]Wind!S2 -> 0 | T6: =[1]Wind!T2 -> 0 | ... AJ6: =[1]Wind!AJ2 -> 0
A7: solar pv | B7: =LOOKUP(B1-'[1]Solar pv'!$G$1,'[1]Solar pv'!$A:$A,'[1]Solar pv'!$B:$B) -> 0 | C7: =LOOKUP(C1-'[1]Solar pv'!$G$1,'[1]Solar pv'!$A:$A,'[1]Solar pv'!$B:$B) -> 0 | D7: =LOOKUP(D1-'[1]Solar pv'!$G$1,'[1]Solar pv'!$A:$A,'[1]Solar pv'!$B:$B) -> 0 | E7: =LOOKUP(E1-'[1]Solar pv'!$G$1,'[1]Solar pv'!$A:$A,'[1]Solar pv'!$B:$B) -> 0 | F7: =LOOKUP(F1-'[1]Solar pv'!$G$1,'[1]Solar pv'!$A:$A,'[1]Solar pv'!$B:$B) -> 0 | G7: =LOOKUP(G1-'[1]Solar pv'!$G$1,'[1]Solar pv'!$A:$A,'[1]Solar pv'!$B:$B) -> 0 | H7: =LOOKUP(H1-'[1]Solar pv'!$G$1,'[1]Solar pv'!$A:$A,'[1]Solar pv'!$B:$B) -> 0 | I7: =LOOKUP(I1-'[1]Solar pv'!$G$1,'[1]Solar pv'!$A:$A,'[1]Solar pv'!$B:$B) -> 0 | ... AJ7: =LOOKUP(AJ1-'[1]Solar pv'!$G$1,'[1]Solar pv'!$A:$A,'[1]Solar pv'!$B:$B) -> 0
A8: solar thermal | B8: =SUMIF('[1]Solar thermal '!$E$2:$E$24,[1]BCR!B1-'[1]Solar thermal '!$I$1,'[1]Solar thermal '!$B$2:$B$24) -> #VALUE! | C8: =SUMIF('[1]Solar thermal '!$E$2:$E$24,[1]BCR!C1-'[1]Solar thermal '!$I$1,'[1]Solar thermal '!$B$2:$B$24) -> #VALUE! | D8: =SUMIF('[1]Solar thermal '!$E$2:$E$24,[1]BCR!D1-'[1]Solar thermal '!$I$1,'[1]Solar thermal '!$B$2:$B$24) -> #VALUE! | E8: =SUMIF('[1]Solar thermal '!$E$2:$E$24,[1]BCR!E1-'[1]Solar thermal '!$I$1,'[1]Solar thermal '!$B$2:$B$24) -> #VALUE! | F8: =SUMIF('[1]Solar thermal '!$E$2:$E$24,[1]BCR!F1-'[1]Solar thermal '!$I$1,'[1]Solar thermal '!$B$2:$B$24) -> #VALUE! | G8: =SUMIF('[1]Solar thermal '!$E$2:$E$24,[1]BCR!G1-'[1]Solar thermal '!$I$1,'[1]Solar thermal '!$B$2:$B$24) -> #VALUE! | H8: =SUMIF('[1]Solar thermal '!$E$2:$E$24,[1]BCR!H1-'[1]Solar thermal '!$I$1,'[1]Solar thermal '!$B$2:$B$24) -> #VALUE! | I8: =SUMIF('[1]Solar thermal '!$E$2:$E$24,[1]BCR!I1-'[1]Solar thermal '!$I$1,'[1]Solar thermal '!$B$2:$B$24) -> #VALUE! | ... AJ8: =SUMIF('[1]Solar thermal '!$E$2:$E$24,[1]BCR!AJ1-'[1]Solar thermal '!$I$1,'[1]Solar thermal '!$B$2:$B$24) -> #VALUE!
A9: biomass | B9: =IFERROR(LOOKUP(B1-[1]Biomass!$F$1,[1]Biomass!$A$3:$A$17,[1]Biomass!$C$3:$C$17),0) -> 0 | C9: =IFERROR(LOOKUP(C1-[1]Biomass!$F$1,[1]Biomass!$A$3:$A$17,[1]Biomass!$C$3:$C$17),0) -> 0 | D9: =IFERROR(LOOKUP(D1-[1]Biomass!$F$1,[1]Biomass!$A$3:$A$17,[1]Biomass!$C$3:$C$17),0) -> 0 | E9: =IFERROR(LOOKUP(E1-[1]Biomass!$F$1,[1]Biomass!$A$3:$A$17,[1]Biomass!$C$3:$C$17),0) -> 0 | F9: =IFERROR(LOOKUP(F1-[1]Biomass!$F$1,[1]Biomass!$A$3:$A$17,[1]Biomass!$C$3:$C$17),0) -> 0 | G9: =IFERROR(LOOKUP(G1-[1]Biomass!$F$1,[1]Biomass!$A$3:$A$17,[1]Biomass!$C$3:$C$17),0) -> 0 | H9: =IFERROR(LOOKUP(H1-[1]Biomass!$F$1,[1]Biomass!$A$3:$A$17,[1]Biomass!$C$3:$C$17),0) -> 0 | I9: =IFERROR(LOOKUP(I1-[1]Biomass!$F$1,[1]Biomass!$A$3:$A$17,[1]Biomass!$C$3:$C$17),0) -> 0 | ... AJ9: =IFERROR(LOOKUP(AJ1-[1]Biomass!$F$1,[1]Biomass!$A$3:$A$17,[1]Biomass!$C$3:$C$17),0) -> 0
A10: geothermal | B10: =SUMIF([1]Geothermal!$F$2:$F$16,[1]BCR!B1,[1]Geothermal!$C$2:$C$16) -> #VALUE! | C10: =SUMIF([1]Geothermal!$F$2:$F$16,[1]BCR!C1,[1]Geothermal!$C$2:$C$16) -> #VALUE! | D10: =SUMIF([1]Geothermal!$F$2:$F$16,[1]BCR!D1,[1]Geothermal!$C$2:$C$16) -> #VALUE! | E10: =SUMIF([1]Geothermal!$F$2:$F$16,[1]BCR!E1,[1]Geothermal!$C$2:$C$16) -> #VALUE! | F10: =SUMIF([1]Geothermal!$F$2:$F$16,[1]BCR!F1,[1]Geothermal!$C$2:$C$16) -> #VALUE! | G10: =SUMIF([1]Geothermal!$F$2:$F$16,[1]BCR!G1,[1]Geothermal!$C$2:$C$16) -> #VALUE! | H10: =SUMIF([1]Geothermal!$F$2:$F$16,[1]BCR!H1,[1]Geothermal!$C$2:$C$16) -> #VALUE! | I10: =SUMIF([1]Geothermal!$F$2:$F$16,[1]BCR!I1,[1]Geothermal!$C$2:$C$16) -> #VALUE! | ... AJ10: =SUMIF([1]Geothermal!$F$2:$F$16,[1]BCR!AJ1,[1]Geothermal!$C$2:$C$16) -> #VALUE!
A11: petroleum | B11: =IFERROR(LOOKUP(B1-'[1]Natural gas&Petroleum&Coal'!$J$3,'[1]Natural gas&Petroleum&Coal'!$A$1:$A$45,'[1]Natural gas&Petroleum&Coal'!$D$1:$D$45),0) -> 0 | C11: =IFERROR(LOOKUP(C1-'[1]Natural gas&Petroleum&Coal'!$J$3,'[1]Natural gas&Petroleum&Coal'!$A$1:$A$45,'[1]Natural gas&Petroleum&Coal'!$D$1:$D$45),0) -> 0 | D11: =IFERROR(LOOKUP(D1-'[1]Natural gas&Petroleum&Coal'!$J$3,'[1]Natural gas&Petroleum&Coal'!$A$1:$A$45,'[1]Natural gas&Petroleum&Coal'!$D$1:$D$45),0) -> 0 | E11: =IFERROR(LOOKUP(E1-'[1]Natural gas&Petroleum&Coal'!$J$3,'[1]Natural gas&Petroleum&Coal'!$A$1:$A$45,'[1]Natural gas&Petroleum&Coal'!$D$1:$D$45),0) -> 0 | F11: =IFERROR(LOOKUP(F1-'[1]Natural gas&Petroleum&Coal'!$J$3,'[1]Natural gas&Petroleum&Coal'!$A$1:$A$45,'[1]Natural gas&Petroleum&Coal'!$D$1:$D$45),0) -> 0 | G11: =IFERROR(LOOKUP(G1-'[1]Natural gas&Petroleum&Coal'!$J$3,'[1]Natural gas&Petroleum&Coal'!$A$1:$A$45,'[1]Natural gas&Petroleum&Coal'!$D$1:$D$45),0) -> 0 | H11: =IFERROR(LOOKUP(H1-'[1]Natural gas&Petroleum&Coal'!$J$3,'[1]Natural gas&Petroleum&Coal'!$A$1:$A$45,'[1]Natural gas&Petroleum&Coal'!$D$1:$D$45),0) -> 0 | I11: =IFERROR(LOOKUP(I1-'[1]Natural gas&Petroleum&Coal'!$J$3,'[1]Natural gas&Petroleum&Coal'!$A$1:$A$45,'[1]Natural gas&Petroleum&Coal'!$D$1:$D$45),0) -> 0 | ... P11: =IFERROR(LOOKUP(P1-'[1]Natural gas&Petroleum&Coal'!$J$3,'[1]Natural gas&Petroleum&Coal'!$A$1:$A$45,'[1]Natural gas&Petroleum&Coal'!$D$1:$D$45),0) -> 0 | Q11: 0 | R11: =IFERROR(LOOKUP(R1-'[1]Natural gas&Petroleum&Coal'!$J$3,'[1]Natural gas&Petroleum&Coal'!$A$1:$A$45,'[1]Natural gas&Petroleum&Coal'!$D$1:$D$45),0)-1 -> 299 | S11: =IFERROR(LOOKUP(S1-'[1]Natural gas&Petroleum&Coal'!$J$3,'[1]Natural gas&Petroleum&Coal'!$A$1:$A$45,'[1]Natural gas&Petroleum&Coal'!$D$1:$D$45),0) -> 0 | T11: =IFERROR(LOOKUP(T1-'[1]Natural gas&Petroleum&Coal'!$J$3,'[1]Natural gas&Petroleum&Coal'!$A$1:$A$45,'[1]Natural gas&Petroleum&Coal'!$D$1:$D$45),0) -> 0 | U11: =IFERROR(LOOKUP(U1-'[1]Natural gas&Petroleum&Coal'!$J$3,'[1]Natural gas&Petroleum&Coal'!$A$1:$A$45,'[1]Natural gas&Petroleum&Coal'!$D$1:$D$45),0) -> 0 | V11: =IFERROR(LOOKUP(V1-'[1]Natural gas&Petroleum&Coal'!$J$3,'[1]Natural gas&Petroleum&Coal'!$A$1:$A$45,'[1]Natural gas&Petroleum&Coal'!$D$1:$D$45),0) -> 0 | W11: =IFERROR(LOOKUP(W1-'[1]Natural gas&Petroleum&Coal'!$J$3,'[1]Natural gas&Petroleum&Coal'!$A$1:$A$45,'[1]Natural gas&Petroleum&Coal'!$D$1:$D$45),0) -> 0 | X11: =IFERROR(LOOKUP(X1-'[1]Natural gas&Petroleum&Coal'!$J$3,'[1]Natural gas&Petroleum&Coal'!$A$1:$A$45,'[1]Natural gas&Petroleum&Coal'!$D$1:$D$45),0) -> 0 | Y11: =IFERROR(LOOKUP(Y1-'[1]Natural gas&Petroleum&Coal'!$J$3,'[1]Natural gas&Petroleum&Coal'!$A$1:$A$45,'[1]Natural gas&Petroleum&Coal'!$D$1:$D$45),0) -> 0 | Z11: =IFERROR(LOOKUP(Z1-'[1]Natural gas&Petroleum&Coal'!$J$3,'[1]Natural gas&Petroleum&Coal'!$A$1:$A$45,'[1]Natural gas&Petroleum&Coal'!$D$1:$D$45),0) -> 0 | ... AJ11: =IFERROR(LOOKUP(AJ1-'[1]Natural gas&Petroleum&Coal'!$J$3,'[1]Natural gas&Petroleum&Coal'!$A$1:$A$45,'[1]Natural gas&Petroleum&Coal'!$D$1:$D$45),0) -> 0
A12: natural gas peaker | B12: =IFERROR(LOOKUP(B1-'[1]Natural gas&Petroleum&Coal'!$J$2,'[1]Natural gas&Petroleum&Coal'!$A$1:$A$45,'[1]Natural gas&Petroleum&Coal'!$B$1:$B$45),0) -> 0 | C12: =IFERROR(LOOKUP(C1-'[1]Natural gas&Petroleum&Coal'!$J$2,'[1]Natural gas&Petroleum&Coal'!$A$1:$A$45,'[1]Natural gas&Petroleum&Coal'!$B$1:$B$45),0) -> 0 | D12: =IFERROR(LOOKUP(D1-'[1]Natural gas&Petroleum&Coal'!$J$2,'[1]Natural gas&Petroleum&Coal'!$A$1:$A$45,'[1]Natural gas&Petroleum&Coal'!$B$1:$B$45),0) -> 0 | E12: =IFERROR(LOOKUP(E1-'[1]Natural gas&Petroleum&Coal'!$J$2,'[1]Natural gas&Petroleum&Coal'!$A$1:$A$45,'[1]Natural gas&Petroleum&Coal'!$B$1:$B$45),0) -> 0 | F12: =IFERROR(LOOKUP(F1-'[1]Natural gas&Petroleum&Coal'!$J$2,'[1]Natural gas&Petroleum&Coal'!$A$1:$A$45,'[1]Natural gas&Petroleum&Coal'!$B$1:$B$45),0) -> 0 | G12: =IFERROR(LOOKUP(G1-'[1]Natural gas&Petroleum&Coal'!$J$2,'[1]Natural gas&Petroleum&Coal'!$A$1:$A$45,'[1]Natural gas&Petroleum&Coal'!$B$1:$B$45),0) -> 0 | H12: =IFERROR(LOOKUP(H1-'[1]Natural gas&Petroleum&Coal'!$J$2,'[1]Natural gas&Petroleum&Coal'!$A$1:$A$45,'[1]Natural gas&Petroleum&Coal'!$B$1:$B$45),0) -> 0 | I12: =IFERROR(LOOKUP(I1-'[1]Natural gas&Petroleum&Coal'!$J$2,'[1]Natural gas&Petroleum&Coal'!$A$1:$A$45,'[1]Natural gas&Petroleum&Coal'!$B$1:$B$45),0) -> 0 | ... U12: =IFERROR(LOOKUP(U1-'[1]Natural gas&Petroleum&Coal'!$J$2,'[1]Natural gas&Petroleum&Coal'!$A$1:$A$45,'[1]Natural gas&Petroleum&Coal'!$B$1:$B$45),0) -> 0 | V12: 0 | W12: 0 | X12: 0 | Y12: 0 | Z12: 0 | AA12: 0 | AB12: 0 | AC12: 0 | AD12: 0 | AE12: 0 | AF12: 0 | AG12: 0 | AH12: 0 | AI12: 0 | AJ12: 0
A13: lignite | B13: 0 | C13: 0 | D13: 0 | E13: 0 | F13: 0 | G13: 0 | H13: 0 | I13: 0 | J13: 0 | K13: 0 | L13: 0 | M13: 0 | N13: 0 | O13: 0 | P13: 0 | Q13: 0 | R13: 0 | S13: 0 | T13: 0 | U13: 0 | V13: 0 | W13: 0 | X13: 0 | Y13: 0 | Z13: 0 | AA13: 0 | AB13: 0 | AC13: 0 | AD13: 0 | AE13: 0 | AF13: 0 | AG13: 0 | AH13: 0 | AI13: 0 | AJ13: 0
A14: offshore wind | B14: =[1]Wind!B3 -> 0 | C14: =[1]Wind!C3 -> 0 | D14: =[1]Wind!D3 -> 0 | E14: =[1]Wind!E3 -> 0 | F14: =[1]Wind!F3 -> 0 | G14: =[1]Wind!G3 -> 0 | H14: =[1]Wind!H3 -> 0 | I14: =[1]Wind!I3 -> 0 | ... AJ14: =[1]Wind!AJ3 -> 0

Sheet Wind
A1: Year | B1: 2016 | C1: 2017 | D1: 2018 | E1: 2019 | F1: 2020 | G1: 2021 | H1: 2022 | I1: 2023 | J1: 2024 | K1: 2025 | L1: 2026 | M1: 2027 | N1: 2028 | O1: 2029 | P1: 2030 | Q1: 2031 | R1: 2032 | S1: 2033 | T1: 2034 | U1: 2035 | V1: 2036 | W1: 2037 | X1: 2038 | Y1: 2039 | Z1: 2040 | AA1: 2041 | AB1: 2042 | AC1: 2043 | AD1: 2044 | AE1: 2045 | AF1: 2046 | AG1: 2047 | AH1: 2048 | AI1: 2049 | AJ1: 2050
A2: onshore | V2: ='HKE Asset'!D14 -> 0.8
A3: offshore | M3: 150
A7: Capacity Lifetime (yr) | B7: 30
A9: Note:
A10: Assume that the wind power station in HKE's Lamma Station is onshore.

Sheet Hydro
A1: Year | B1: New capacity(MW) | C1: Designed Retirement Year | F1: Capacity Lifetime(yr) | G1: 30
A2: 1986 | B2: 0 | C2: =A2+$G$1 -> 2016
A3: 1987 | B3: 0 | C3: =A3+$G$1 -> 2017
A4: 1988 | B4: 0 | C4: =A4+$G$1 -> 2018
A5: 1989 | B5: 0 | C5: =A5+$G$1 -> 2019
A6: 1990 | B6: 0 | C6: =A6+$G$1 -> 2020
A7: 1991 | B7: 0 | C7: =A7+$G$1 -> 2021
A8: 1992 | B8: 0 | C8: =A8+$G$1 -> 2022
A9: 1993 | B9: 0 | C9: =A9+$G$1 -> 2023
A10: 1994 | B10: 0 | C10: =A10+$G$1 -> 2024
A11: 1995 | B11: 0 | C11: =A11+$G$1 -> 2025
A12: 1996 | B12: 0 | C12: =A12+$G$1 -> 2026
A13: 1997 | B13: 0 | C13: =A13+$G$1 -> 2027
... A33: 2017 | B33: 0.5 | C33: =A33+$G$1 -> 2047
A34: 2018 | B34: 23 | C34: =A34+$G$1 -> 2048 | D34: NOTE: DSD installed a hydro-turbine at Stonecutters Island Sewage Treatment Work
A35: 2019 | B35: 0 | C35: =A35+$G$1 -> 2049
A36: 2020 | B36: 0 | C36: =A36+$G$1 -> 2050

Sheet Nuclear
A1: Utility Name | B1: Province | C1: Nameplate Capacity (MW) | D1: Operating Year | E1: Designed Lifetime | F1: Status | G1: Designed Retirement Year
A2: Daya Bay Nuclear Power Station | B2: Guangdong | C2: ='CLP Assets'!C12 -> 1577 | D2: 1994 | E2: 40 | F2: Operating
A5: Note: Nuclear not included in HK's capacity, as Daya Bay is in China.

Sheet Geothermal
A1: Plant | B1: Utility Number | C1: Capacity (MW) | D1: Operation Year | E1: Status | F1: Designed Retirement Year | H1: Capacity Lifetime(yr) | I1: 38
A2: Yangbajing | B2: 1 | C2: 0 | D2: 1977 | E2: Closed | F2: NA
B3: 2 | C3: 0 | D3: 1981 | E3: Operating | F3: =D3+$I$1 -> 2019
B4: 3 | C4: 0 | D4: 1982 | E4: Operating | F4: =D4+$I$1 -> 2020
B5: 4 | C5: 0 | D5: 1985 | E5: Operating | F5: =D5+$I$1 -> 2023
B6: 5 | C6: 0 | D6: 1986 | E6: Operating | F6: =D6+$I$1 -> 2024
B7: 6 | C7: 0 | D7: 1988 | E7: Operating | F7: =D7+$I$1 -> 2026
B8: 7 | C8: 0 | D8: 1989 | E8: Operating | F8: =D8+$I$1 -> 2027
B9: 8 | C9: 0 | D9: 1991 | E9: Operating | F9: =D9+$I$1 -> 2029
B10: 9 | C10: 0 | D10: 1991 | E10: Operating | F10: =D10+$I$1 -> 2029
A11: Fengshun | B11: 1 | C11: 0 | D11: 1970 | E11: Closed | F11: NA
B12: 2 | C12: 0 | D12: 1978 | E12: Closed | F12: NA
B13: 3 | C13: 0 | D13: 1984 | E13: Operating | F13: =D13+$I$1 -> 2022
A14: Yangbajing | C14: 0 | D14: 2009 | E14: Operating | F14: =D14+$I$1 -> 2047
A15: Huabei Oilfieled | C15: 0 | D15: 2011 | E15: Operating | F15: =D15+$I$1 -> 2049
A16: Yangyi | C16: 0 | D16: 2011 | E16: Operating | F16: =D16+$I$1 -> 2049

Sheet Biomass
A1: Year | B1: Total Capacity (MW) | C1: New Capacity (MW) | E1: Capacity Lifetime (yr) | F1: 30 | H1: Note:
A2: 2005 | B2: 0 | H2: Considering that the capacity lifetime of biomass is about 30 years,
A3: 2006 | B3: 0 | C3: =B3-B2 -> 0 | H3: we estimate the data in 2006-2008 by using the annual variation(assuming no retirements in these years).
A4: 2007 | B4: 0 | C4: =B4-B3 -> 0 | H4: For data in 2017-2020, we use the average results from 2011 to 2016.
A5: 2008 | B5: 0 | C5: =B5-B4 -> 0
A6: 2009 | C6: 0 | H6: Source:
A7: 2010 | C7: 0 | H7: -
A8: 2011 | C8: 0 | H8: -
A9: 2012 | C9: 0
A10: 2013 | C10: 0
A11: 2014 | C11: 0
A12: 2015 | C12: 0
A13: 2016 | C13: 0
A14: 2017 | C14: 0
A15: 2018 | C15: 0
A16: 2019 | C16: ='CLP Assets'!C10 -> 10
A17: 2020 | C17: 0

Sheet Solar thermal 
A1: Project | B1: Capacity (MW) | C1: Status Date | D1: Status | E1: Operational Year/ Expected Year | H1: Capacity Lifetime(yr) | I1: 30
A2: Chabei 64MW Molten Salt Parabolic Trough project | B2: 0 | D2: Under Development
A3: Dacheng Dunhuang 50MW Molten Salt Fresnel project | B3: 0 | D3: Under Development | H3: Source:
A4: Dahan Power Plant | B4: 0 | D4: Operational | E4: 2012 | H4: NREL
A5: Delingha 50MW Thermal Oil Parabolic Trough project | B5: 0 | D5: Under Construction | H5: CSP Plaza
A6: Gansu Akesai 50MW Molten Salt Trough project | B6: 0 | D6: Under Development | E6: 2019
A7: Golden Tower 100MW Molten Salt project | B7: 0 | D7: Under Development
A8: Golmud | B8: 0 | D8: Under Construction
A9: Gulang 100MW Thermal Oil Parabolic Trough project | B9: 0 | D9: Under Development
A10: Hami 50 MW CSP Project | B10: 0 | D10: Under Development | E10: 2019
A11: Huanghe Qinghai Delingha 135 MW DSG Tower CSP Project | B11: 0 | D11: Under Development
A12: Qinghai Gonghe 50 MW CSP Plant | B12: 0 | D12: Under Development | E12: 2019
A13: Rayspower Yumen 50MW Thermal Oil Trough project | B13: 0 | D13: Under Construction
A14: Shangyi 50MW DSG Tower CSP project | B14: 0 | D14: Under Development | E14: 2019
A15: SunCan Dunhuang 10 MW Phase I | B15: 0 | D15: Operational | E15: 2016
A16: SunCan Dunhuang 100 MW Phase II | B16: 0 | D16: Under Construction
A17: Supcon Solar Project | B17: 0 | D17: Under Construction
A18: Urat 50MW Fresnel CSP project | B18: 0 | D18: Under Development
A19: Urat Middle Banner 100MW Thermal Oil Parabolic Trough project | B19: 0 | D19: Under Construction | E19: 2019
A20: Yumen 100MW Molten Salt Tower CSP project | B20: 0 | D20: Under Development
A21: Yumen 50MW Molten Salt Tower CSP project | B21: 0 | D21: Under Development
A22: Yumen 50MW Thermal Oil Trough CSP project | B22: 0 | D22: Under Development | E22: 2019
A23: Zhangbei 50MW CSG Fresnel CSP project | B23: 0 | D23: Under Development
A24: Zhangjiakou 50MW CSG Fresnel project | B24: 0 | D24: Under Development | E24: 2019

Sheet Solar pv
A1: Year | B1: New Capacity (MW) | F1: Capacity Lifetime (yr) | G1: 20
A2: 1996
A3: 1997
A4: 1998
A5: 1999
A6: 2000
A7: 2001
A8: 2002
A9: 2003
A10: 2004
A11: 2005
A12: 2006 | B12: ='HKE Asset'!D12 -> 1.1
A13: 2007
A14: 2008 | B14: 3.8
A15: 2009
A16: 2010
A17: 2011
A18: 2012
A19: 2013 | B19: ='HKE Asset'!D13 -> 0.1
A20: 2014
A21: 2015
A22: 2016 | B22: 18.3 | D22: NOTE: DSD installed 4200 units of PVs, capable of generating 1.1 MkW per year at Siu Ho Wan Solar Farm
A23: 2017 | B23: 0.3 | D23: NOTE: Solar PVs installed at Shek Pik Reservoir, Plover Cove + Tai Lam Chung Reservoir have a generation capacity of 100kW each | P23: https://www.wsd.gov.hk/ecoexpoasia2022/index-en.html
A24: 2018 | B24: 0.9 | D24: NOTE: DSD installed solar PV on rooftops of plants at Sha Tin, yuen Long, Shek Wu Hui and Stone cotters island
A25: 2019
A26: 2020
A27: 2021
A28: 2022
A29: 2023 | B29: 0.15 | D29: solar system at Jordan Valley Landfill
A30: 2024
A31: 2025
A32: 2026
A33: 2027
A34: 2028
A35: 2029
A36: 2030
B39: note:
B40: 3.8 added in 2008 is rough summary of this information:
B41: https://re.emsd.gov.hk/english/solar/solar_ph/solar_ph_ep.html
